{"action": null, "capture_sequence": 1, "channel": "trades", "connection_sequence": 1, "event": "subscribe", "instId": "BTC-USDT-SWAP", "local_receive_ts": "2026-06-20T18:23:01Z", "monotonic_ns": 1607337635255257, "raw": "{\"event\":\"subscribe\",\"arg\":{\"channel\":\"trades\",\"instId\":\"BTC-USDT-SWAP\"},\"connId\":\"d058fd86\"}"}
{"action": null, "capture_sequence": 2, "channel": "books", "connection_sequence": 1, "event": "subscribe", "instId": "BTC-USDT-SWAP", "local_receive_ts": "2026-06-20T18:23:01Z", "monotonic_ns": 1607337635519448, "raw": "{\"event\":\"subscribe\",\"arg\":{\"channel\":\"books\",\"instId\":\"BTC-USDT-SWAP\"},\"connId\":\"d058fd86\"}"}
{"action": "snapshot", "capture_sequence": 3, "channel": "books", "connection_sequence": 1, "event": null, "instId": "BTC-USDT-SWAP", "local_receive_ts": "2026-06-20T18:23:02Z", "monotonic_ns": 1607337914031706, "raw": "{\"arg\":{\"channel\":\"books\",\"instId\":\"BTC-USDT-SWAP\"},\"action\":\"snapshot\",\"data\":[{\"asks\":[[\"63813.7\",\"45.13\",\"0\",\"23\"],[\"63813.8\",\"0.87\",\"0\",\"7\"],[\"63814\",\"0.01\",\"0\",\"1\"],[\"63814.1\",\"1.93\",\"0\",\"1\"],[\"63814.2\",\"0.01\",\"0\",\"1\"],[\"63814.3\",\"3.52\",\"0\",\"1\"],[\"63814.6\",\"0.02\",\"0\",\"2\"],[\"63814.7\",\"3.74\",\"0\",\"3\"],[\"63814.8\",\"1.9\",\"0\",\"2\"],[\"63815.7\",\"0.31\",\"0\",\"2\"],[\"63815.8\",\"0.4\",\"0\",\"2\"],[\"63815.9\",\"3.1\",\"0\",\"2\"],[\"63816\",\"3.43\",\"0\",\"2\"],[\"63816.2\",\"0.01\",\"0\",\"1\"],[\"63816.3\",\"33.76\",\"0\",\"2\"],[\"63816.4\",\"0.01\",\"0\",\"1\"],[\"63816.6\",\"0.03\",\"0\",\"3\"],[\"63816.7\",\"7.83\",\"0\",\"1\"],[\"63816.8\",\"0.4\",\"0\",\"2\"],[\"63817\",\"1.63\",\"0\",\"1\"],[\"63817.2\",\"0.01\",\"0\",\"1\"],[\"63817.4\",\"0.01\",\"0\",\"1\"],[\"63817.5\",\"0.01\",\"0\",\"1\"],[\"63817.7\",\"6.28\",\"0\",\"2\"],[\"63817.8\",\"32.4\",\"0\",\"1\"],[\"63818.2\",\"1.81\",\"0\",\"2\"],[\"63818.3\",\"11.87\",\"0\",\"8\"],[\"63818.4\",\"0.79\",\"0\",\"2\"],[\"63818.5\",\"0.01\",\"0\",\"1\"],[\"63818.6\",\"0.6\",\"0\",\"1\"],[\"63818.8\",\"0.02\",\"0\",\"2\"],[\"63818.9\",\"43.4\",\"0\",\"6\"],[\"63819.1\",\"0.03\",\"0\",\"1\"],[\"63819.2\",\"1.59\",\"0\",\"3\"],[\"63819.3\",\"1.27\",\"0\",\"2\"],[\"63819.5\",\"0.01\",\"0\",\"1\"],[\"63819.7\",\"0.02\",\"0\",\"2\"],[\"63819.8\",\"1.59\",\"0\",\"3\"],[\"63819.9\",\"0.48\",\"0\",\"2\"],[\"63820\",\"0.61\",\"0\",\"2\"],[\"63820.2\",\"1.89\",\"0\",\"3\"],[\"63820.3\",\"3.37\",\"0\",\"1\"],[\"63820.4\",\"6.29\",\"0\",\"3\"],[\"63820.5\",\"19.27\",\"0\",\"3\"],[\"63820.7\",\"2.47\",\"0\",\"2\"],[\"63820.8\",\"65.57\",\"0\",\"1\"],[\"63820.9\",\"66.52\",\"0\",\"1\"],[\"63821\",\"0.01\",\"0\",\"1\"],[\"63821.2\",\"5.57\",\"0\",\"2\"],[\"63821.3\",\"186.54\",\"0\",\"1\"],[\"63821.6\",\"0.17\",\"0\",\"2\"],[\"63821.7\",\"1.57\",\"0\",\"1\"],[\"63821.9\",\"0.01\",\"0\",\"1\"],[\"63822\",\"0.02\",\"0\",\"2\"],[\"63822.1\",\"0.22\",\"0\",\"1\"],[\"63822.2\",\"1.58\",\"0\",\"2\"],[\"63822.4\",\"0.01\",\"0\",\"1\"],[\"63822.5\",\"0.79\",\"0\",\"2\"],[\"63822.6\",\"24.5\",\"0\",\"3\"],[\"63822.8\",\"3.71\",\"0\",\"5\"],[\"63822.9\",\"3.59\",\"0\",\"2\"],[\"63823\",\"0.01\",\"0\",\"1\"],[\"63823.5\",\"2.23\",\"0\",\"3\"],[\"63823.6\",\"0.01\",\"0\",\"1\"],[\"63823.8\",\"2.1\",\"0\",\"1\"],[\"63823.9\",\"0.39\",\"0\",\"1\"],[\"63824\",\"0.04\",\"0\",\"4\"],[\"63824.2\",\"91.15\",\"0\",\"3\"],[\"63824.4\",\"26.6\",\"0\",\"2\"],[\"63824.5\",\"2.28\",\"0\",\"1\"],[\"63824.7\",\"2.76\",\"0\",\"1\"],[\"63824.9\",\"3.74\",\"0\",\"2\"],[\"63825\",\"0.02\",\"0\",\"2\"],[\"63825.1\",\"2.4\",\"0\",\"1\"],[\"63825.4\",\"1.88\",\"0\",\"3\"],[\"63825.5\",\"41.64\",\"0\",\"3\"],[\"63825.6\",\"68.19\",\"0\",\"1\"],[\"63825.7\",\"2.64\",\"0\",\"1\"],[\"63825.8\",\"0.01\",\"0\",\"1\"],[\"63825.9\",\"0.02\",\"0\",\"2\"],[\"63826\",\"62.69\",\"0\",\"3\"],[\"63826.1\",\"3.42\",\"0\",\"3\"],[\"63826.3\",\"200.37\",\"0\",\"6\"],[\"63826.5\",\"0.3\",\"0\",\"1\"],[\"63826.6\",\"2.07\",\"0\",\"2\"],[\"63826.7\",\"4.01\",\"0\",\"2\"],[\"63826.8\",\"3.25\",\"0\",\"1\"],[\"63826.9\",\"3.97\",\"0\",\"1\"],[\"63827\",\"8\",\"0\",\"1\"],[\"63827.2\",\"0.02\",\"0\",\"2\"],[\"63827.4\",\"256.23\",\"0\",\"3\"],[\"63827.5\",\"0.01\",\"0\",\"1\"],[\"63827.6\",\"0.02\",\"0\",\"2\"],[\"63827.8\",\"446.81\",\"0\",\"4\"],[\"63827.9\",\"55.89\",\"0\",\"6\"],[\"63828\",\"62.7\",\"0\",\"4\"],[\"63828.1\",\"0.02\",\"0\",\"2\"],[\"63828.3\",\"0.29\",\"0\",\"1\"],[\"63828.5\",\"0.52\",\"0\",\"2\"],[\"63828.6\",\"0.01\",\"0\",\"1\"],[\"63829\",\"0.04\",\"0\",\"4\"],[\"63829.4\",\"0.03\",\"0\",\"1\"],[\"63829.5\",\"16.13\",\"0\",\"1\"],[\"63829.6\",\"0.01\",\"0\",\"1\"],[\"63829.7\",\"4\",\"0\",\"1\"],[\"63829.8\",\"0.01\",\"0\",\"1\"],[\"63830\",\"0.01\",\"0\",\"1\"],[\"63830.1\",\"42.49\",\"0\",\"3\"],[\"63830.2\",\"62.67\",\"0\",\"1\"],[\"63830.3\",\"0.31\",\"0\",\"2\"],[\"63830.4\",\"0.01\",\"0\",\"1\"],[\"63830.5\",\"167.62\",\"0\",\"2\"],[\"63830.6\",\"0.01\",\"0\",\"1\"],[\"63830.7\",\"0.01\",\"0\",\"1\"],[\"63830.9\",\"0.01\",\"0\",\"1\"],[\"63831\",\"4\",\"0\",\"1\"],[\"63831.1\",\"0.31\",\"0\",\"1\"],[\"63831.2\",\"62.9\",\"0\",\"2\"],[\"63831.3\",\"1.44\",\"0\",\"5\"],[\"63831.6\",\"0.01\",\"0\",\"1\"],[\"63831.7\",\"8.07\",\"0\",\"2\"],[\"63831.9\",\"0.01\",\"0\",\"1\"],[\"63832\",\"3.32\",\"0\",\"3\"],[\"63832.1\",\"8.02\",\"0\",\"3\"],[\"63832.5\",\"0.02\",\"0\",\"2\"],[\"63832.8\",\"407.86\",\"0\",\"1\"],[\"63832.9\",\"0.01\",\"0\",\"1\"],[\"63833\",\"0.01\",\"0\",\"1\"],[\"63833.1\",\"15.87\",\"0\",\"1\"],[\"63833.3\",\"0.01\",\"0\",\"1\"],[\"63833.4\",\"16.18\",\"0\",\"3\"],[\"63833.5\",\"7.06\",\"0\",\"1\"],[\"63833.6\",\"441.38\",\"0\",\"2\"],[\"63833.7\",\"15.88\",\"0\",\"2\"],[\"63833.8\",\"10.5\",\"0\",\"1\"],[\"63833.9\",\"200.02\",\"0\",\"3\"],[\"63834\",\"55.11\",\"0\",\"4\"],[\"63834.1\",\"84.63\",\"0\",\"1\"],[\"63834.2\",\"0.02\",\"0\",\"2\"],[\"63834.3\",\"31.55\",\"0\",\"2\"],[\"63834.4\",\"62.68\",\"0\",\"2\"],[\"63834.5\",\"47.05\",\"0\",\"1\"],[\"63834.6\",\"15.88\",\"0\",\"2\"],[\"63834.7\",\"15.66\",\"0\",\"1\"],[\"63834.8\",\"39.21\",\"0\",\"1\"],[\"63834.9\",\"15.94\",\"0\",\"2\"],[\"63835\",\"31.38\",\"0\",\"2\"],[\"63835.1\",\"1.19\",\"0\",\"2\"],[\"63835.2\",\"15.9\",\"0\",\"4\"],[\"63835.3\",\"0.02\",\"0\",\"2\"],[\"63835.4\",\"15.88\",\"0\",\"2\"],[\"63835.5\",\"37.67\",\"0\",\"2\"],[\"63835.8\",\"86.25\",\"0\",\"2\"],[\"63835.9\",\"15.87\",\"0\",\"1\"],[\"63836\",\"0.01\",\"0\",\"1\"],[\"63836.1\",\"0.01\",\"0\",\"1\"],[\"63836.2\",\"0.01\",\"0\",\"1\"],[\"63836.3\",\"31.37\",\"0\",\"1\"],[\"63836.4\",\"15.87\",\"0\",\"1\"],[\"63836.5\",\"0.11\",\"0\",\"1\"],[\"63836.6\",\"65.51\",\"0\",\"3\"],[\"63836.7\",\"76.88\",\"0\",\"2\"],[\"63836.8\",\"423.74\",\"0\",\"3\"],[\"63836.9\",\"0.02\",\"0\",\"2\"],[\"63837\",\"176.74\",\"0\",\"1\"],[\"63837.1\",\"125.9\",\"0\",\"5\"],[\"63837.2\",\"15.87\",\"0\",\"1\"],[\"63837.3\",\"1\",\"0\",\"1\"],[\"63837.4\",\"0.01\",\"0\",\"1\"],[\"63837.5\",\"235.66\",\"0\",\"3\"],[\"63837.6\",\"15.87\",\"0\",\"1\"],[\"63837.7\",\"0.01\",\"0\",\"1\"],[\"63838\",\"86.46\",\"0\",\"4\"],[\"63838.1\",\"0.02\",\"0\",\"2\"],[\"63838.3\",\"0.02\",\"0\",\"2\"],[\"63838.4\",\"31.74\",\"0\",\"2\"],[\"63838.5\",\"59.56\",\"0\",\"3\"],[\"63838.7\",\"0.01\",\"0\",\"1\"],[\"63838.8\",\"31.74\",\"0\",\"2\"],[\"63838.9\",\"0.5\",\"0\",\"1\"],[\"63839.1\",\"0.05\",\"0\",\"3\"],[\"63839.2\",\"15.89\",\"0\",\"3\"],[\"63839.3\",\"0.81\",\"0\",\"2\"],[\"63839.4\",\"0.78\",\"0\",\"1\"],[\"63839.5\",\"2.94\",\"0\",\"1\"],[\"63839.6\",\"54.66\",\"0\",\"3\"],[\"63839.7\",\"0.03\",\"0\",\"1\"],[\"63839.8\",\"69.47\",\"0\",\"2\"],[\"63839.9\",\"79.03\",\"0\",\"3\"],[\"63840\",\"16.68\",\"0\",\"20\"],[\"63840.1\",\"7.07\",\"0\",\"2\"],[\"63840.2\",\"295.99\",\"0\",\"2\"],[\"63840.4\",\"67.77\",\"0\",\"2\"],[\"63840.5\",\"0.01\",\"0\",\"1\"],[\"63840.6\",\"0.01\",\"0\",\"1\"],[\"63840.7\",\"0.01\",\"0\",\"1\"],[\"63840.8\",\"40.65\",\"0\",\"3\"],[\"63840.9\",\"407.86\",\"0\",\"1\"],[\"63841\",\"195.24\",\"0\",\"4\"],[\"63841.1\",\"0.01\",\"0\",\"1\"],[\"63841.3\",\"1.33\",\"0\",\"2\"],[\"63841.4\",\"0.04\",\"0\",\"4\"],[\"63841.5\",\"20.29\",\"0\",\"2\"],[\"63841.6\",\"15.87\",\"0\",\"1\"],[\"63841.7\",\"0.04\",\"0\",\"1\"],[\"63842\",\"16.89\",\"0\",\"4\"],[\"63842.1\",\"0.07\",\"0\",\"1\"],[\"63842.3\",\"0.01\",\"0\",\"1\"],[\"63842.4\",\"39.21\",\"0\",\"1\"],[\"63842.6\",\"87.02\",\"0\",\"2\"],[\"63842.7\",\"150.37\",\"0\",\"1\"],[\"63842.8\",\"62.67\",\"0\",\"1\"],[\"63843\",\"10.68\",\"0\",\"1\"],[\"63843.1\",\"0.01\",\"0\",\"1\"],[\"63843.2\",\"39.23\",\"0\",\"2\"],[\"63843.3\",\"0.03\",\"0\",\"3\"],[\"63843.4\",\"0.01\",\"0\",\"1\"],[\"63843.5\",\"0.02\",\"0\",\"1\"],[\"63843.7\",\"62.75\",\"0\",\"1\"],[\"63843.8\",\"5.36\",\"0\",\"4\"],[\"63843.9\",\"0.78\",\"0\",\"3\"],[\"63844\",\"0.05\",\"0\",\"2\"],[\"63844.2\",\"0.01\",\"0\",\"1\"],[\"63844.4\",\"70.01\",\"0\",\"2\"],[\"63844.5\",\"74.42\",\"0\",\"4\"],[\"63844.6\",\"0.01\",\"0\",\"1\"],[\"63844.7\",\"1\",\"0\",\"1\"],[\"63844.8\",\"15.89\",\"0\",\"3\"],[\"63844.9\",\"257.79\",\"0\",\"3\"],[\"63845\",\"6.98\",\"0\",\"1\"],[\"63845.1\",\"5.1\",\"0\",\"2\"],[\"63845.2\",\"423.74\",\"0\",\"3\"],[\"63845.4\",\"1.2\",\"0\",\"1\"],[\"63845.5\",\"122.89\",\"0\",\"4\"],[\"63845.7\",\"1.2\",\"0\",\"1\"],[\"63845.8\",\"0.02\",\"0\",\"2\"],[\"63846\",\"1.22\",\"0\",\"3\"],[\"63846.3\",\"6.26\",\"0\",\"1\"],[\"63846.4\",\"294.5\",\"0\",\"4\"],[\"63846.6\",\"12.17\",\"0\",\"4\"],[\"63846.7\",\"0.01\",\"0\",\"1\"],[\"63846.8\",\"0.02\",\"0\",\"2\"],[\"63846.9\",\"10\",\"0\",\"1\"],[\"63847\",\"1.5\",\"0\",\"1\"],[\"63847.4\",\"0.01\",\"0\",\"1\"],[\"63847.5\",\"21.24\",\"0\",\"2\"],[\"63847.6\",\"0.56\",\"0\",\"4\"],[\"63847.7\",\"18.95\",\"0\",\"1\"],[\"63848\",\"30.3\",\"0\",\"6\"],[\"63848.1\",\"0.01\",\"0\",\"1\"],[\"63848.3\",\"0.01\",\"0\",\"1\"],[\"63848.4\",\"15.87\",\"0\",\"1\"],[\"63848.6\",\"0.02\",\"0\",\"2\"],[\"63848.7\",\"3.13\",\"0\",\"1\"],[\"63848.8\",\"13.71\",\"0\",\"1\"],[\"63848.9\",\"7.06\",\"0\",\"1\"],[\"63849\",\"149.46\",\"0\",\"5\"],[\"63849.1\",\"495.53\",\"0\",\"3\"],[\"63849.2\",\"62.67\",\"0\",\"1\"],[\"63849.4\",\"0.01\",\"0\",\"1\"],[\"63849.6\",\"0.01\",\"0\",\"1\"],[\"63849.8\",\"11.42\",\"0\",\"2\"],[\"63849.9\",\"117.02\",\"0\",\"2\"],[\"63850\",\"8.11\",\"0\",\"55\"],[\"63850.1\",\"21.15\",\"0\",\"2\"],[\"63850.2\",\"20\",\"0\",\"1\"],[\"63850.3\",\"0.01\",\"0\",\"1\"],[\"63850.5\",\"0.01\",\"0\",\"1\"],[\"63850.6\",\"0.01\",\"0\",\"1\"],[\"63850.7\",\"0.01\",\"0\",\"1\"],[\"63851\",\"200\",\"0\",\"1\"],[\"63851.1\",\"0.93\",\"0\",\"2\"],[\"63851.2\",\"15.89\",\"0\",\"3\"],[\"63851.4\",\"0.14\",\"0\",\"1\"],[\"63851.5\",\"0.01\",\"0\",\"1\"],[\"63851.6\",\"16.1\",\"0\",\"4\"],[\"63851.8\",\"0.01\",\"0\",\"1\"],[\"63852\",\"0.47\",\"0\",\"6\"],[\"63852.1\",\"62.67\",\"0\",\"1\"],[\"63852.4\",\"0.01\",\"0\",\"1\"],[\"63852.7\",\"0.02\",\"0\",\"2\"],[\"63852.8\",\"74.64\",\"0\",\"3\"],[\"63853\",\"10.64\",\"0\",\"1\"],[\"63853.2\",\"0.01\",\"0\",\"1\"],[\"63853.3\",\"0.02\",\"0\",\"2\"],[\"63853.6\",\"361.07\",\"0\",\"1\"],[\"63853.8\",\"0.05\",\"0\",\"4\"],[\"63854\",\"100.03\",\"0\",\"4\"],[\"63854.1\",\"124.57\",\"0\",\"3\"],[\"63854.3\",\"62.67\",\"0\",\"1\"],[\"63854.4\",\"15.87\",\"0\",\"1\"],[\"63854.5\",\"407.87\",\"0\",\"2\"],[\"63854.6\",\"0.79\",\"0\",\"2\"],[\"63854.8\",\"15.87\",\"0\",\"1\"],[\"63855.1\",\"14.3\",\"0\",\"1\"],[\"63855.2\",\"1.16\",\"0\",\"2\"],[\"63855.3\",\"0.06\",\"0\",\"3\"],[\"63855.4\",\"37.75\",\"0\",\"3\"],[\"63855.5\",\"0.01\",\"0\",\"1\"],[\"63855.6\",\"0.01\",\"0\",\"1\"],[\"63855.7\",\"0.04\",\"0\",\"2\"],[\"63855.8\",\"0.09\",\"0\",\"1\"],[\"63856\",\"75.57\",\"0\",\"8\"],[\"63856.1\",\"203.21\",\"0\",\"1\"],[\"63856.2\",\"0.01\",\"0\",\"1\"],[\"63856.4\",\"0.01\",\"0\",\"1\"],[\"63856.5\",\"1.38\",\"0\",\"6\"],[\"63856.6\",\"0.01\",\"0\",\"1\"],[\"63856.7\",\"62.67\",\"0\",\"1\"],[\"63857\",\"0.94\",\"0\",\"3\"],[\"63857.1\",\"0.07\",\"0\",\"2\"],[\"63857.2\",\"0.01\",\"0\",\"1\"],[\"63857.3\",\"0.02\",\"0\",\"1\"],[\"63857.4\",\"0.01\",\"0\",\"1\"],[\"63857.6\",\"46.97\",\"0\",\"1\"],[\"63857.8\",\"52.87\",\"0\",\"1\"],[\"63857.9\",\"77.14\",\"0\",\"2\"],[\"63858\",\"26.85\",\"0\",\"7\"],[\"63858.1\",\"0.02\",\"0\",\"1\"],[\"63858.2\",\"0.04\",\"0\",\"1\"],[\"63858.3\",\"7.87\",\"0\",\"4\"],[\"63858.4\",\"407.88\",\"0\",\"3\"],[\"63858.5\",\"0.11\",\"0\",\"1\"],[\"63858.7\",\"15.96\",\"0\",\"3\"],[\"63858.8\",\"1.87\",\"0\",\"2\"],[\"63858.9\",\"0.11\",\"0\",\"1\"],[\"63859\",\"0.02\",\"0\",\"2\"],[\"63859.1\",\"0.01\",\"0\",\"1\"],[\"63859.2\",\"0.02\",\"0\",\"2\"],[\"63859.3\",\"0.11\",\"0\",\"1\"],[\"63859.4\",\"4.68\",\"0\",\"2\"],[\"63859.5\",\"0.01\",\"0\",\"1\"],[\"63859.8\",\"0.05\",\"0\",\"1\"],[\"63859.9\",\"1.83\",\"0\",\"2\"],[\"63860\",\"1.06\",\"0\",\"14\"],[\"63860.1\",\"0.01\",\"0\",\"1\"],[\"63860.2\",\"242.47\",\"0\",\"4\"],[\"63860.3\",\"0.12\",\"0\",\"3\"],[\"63860.4\",\"82.67\",\"0\",\"2\"],[\"63860.5\",\"76.1\",\"0\",\"1\"],[\"63860.6\",\"2\",\"0\",\"1\"],[\"63860.7\",\"37.67\",\"0\",\"2\"],[\"63860.8\",\"0.01\",\"0\",\"1\"],[\"63861\",\"0.01\",\"0\",\"1\"],[\"63861.1\",\"74.6\",\"0\",\"4\"],[\"63861.2\",\"75.48\",\"0\",\"3\"],[\"63861.4\",\"0.01\",\"0\",\"1\"],[\"63861.5\",\"0.01\",\"0\",\"1\"],[\"63861.7\",\"0.01\",\"0\",\"1\"],[\"63861.9\",\"0.01\",\"0\",\"1\"],[\"63862.1\",\"0.01\",\"0\",\"1\"],[\"63862.2\",\"14.29\",\"0\",\"2\"],[\"63862.3\",\"407.87\",\"0\",\"2\"],[\"63862.4\",\"0.03\",\"0\",\"3\"],[\"63862.5\",\"2.04\",\"0\",\"4\"],[\"63862.6\",\"3.24\",\"0\",\"7\"],[\"63862.7\",\"0.02\",\"0\",\"2\"],[\"63862.8\",\"0.02\",\"0\",\"2\"],[\"63863.2\",\"0.71\",\"0\",\"1\"],[\"63863.5\",\"4.14\",\"0\",\"1\"],[\"63863.6\",\"0.02\",\"0\",\"2\"],[\"63863.7\",\"0.01\",\"0\",\"1\"],[\"63863.8\",\"8\",\"0\",\"1\"],[\"63863.9\",\"1.02\",\"0\",\"3\"],[\"63864\",\"0.02\",\"0\",\"2\"],[\"63864.2\",\"62.67\",\"0\",\"1\"],[\"63864.3\",\"77.15\",\"0\",\"3\"],[\"63864.4\",\"10.74\",\"0\",\"1\"],[\"63864.5\",\"0.78\",\"0\",\"1\"],[\"63864.6\",\"0.01\",\"0\",\"1\"],[\"63864.7\",\"1\",\"0\",\"1\"],[\"63864.8\",\"0.01\",\"0\",\"1\"],[\"63864.9\",\"0.06\",\"0\",\"1\"],[\"63865\",\"0.44\",\"0\",\"4\"],[\"63865.1\",\"0.09\",\"0\",\"1\"],[\"63865.2\",\"60.01\",\"0\",\"2\"],[\"63865.4\",\"1.04\",\"0\",\"4\"],[\"63865.5\",\"0.01\",\"0\",\"1\"],[\"63865.6\",\"0.01\",\"0\",\"1\"],[\"63865.7\",\"1.04\",\"0\",\"3\"],[\"63865.8\",\"0.01\",\"0\",\"1\"],[\"63865.9\",\"51.62\",\"0\",\"1\"],[\"63866\",\"4.2\",\"0\",\"2\"],[\"63866.1\",\"0.01\",\"0\",\"1\"],[\"63866.2\",\"7.07\",\"0\",\"2\"],[\"63866.3\",\"1.21\",\"0\",\"2\"],[\"63866.4\",\"0.08\",\"0\",\"2\"],[\"63866.5\",\"138.98\",\"0\",\"2\"],[\"63866.6\",\"43.86\",\"0\",\"3\"],[\"63866.7\",\"0.6\",\"0\",\"23\"],[\"63866.9\",\"0.01\",\"0\",\"1\"],[\"63867\",\"1.25\",\"0\",\"2\"],[\"63867.1\",\"62.74\",\"0\",\"2\"],[\"63867.2\",\"0.01\",\"0\",\"1\"],[\"63867.3\",\"409.07\",\"0\",\"3\"],[\"63867.4\",\"0.03\",\"0\",\"2\"],[\"63867.5\",\"1.2\",\"0\",\"1\"],[\"63867.6\",\"10.47\",\"0\",\"1\"],[\"63867.7\",\"0.01\",\"0\",\"1\"],[\"63867.8\",\"0.01\",\"0\",\"1\"]],\"bids\":[[\"63813.6\",\"1241.47\",\"0\",\"77\"],[\"63813.5\",\"1.21\",\"0\",\"4\"],[\"63813.3\",\"0.8\",\"0\",\"3\"],[\"63813.2\",\"32.47\",\"0\",\"3\"],[\"63813.1\",\"190.56\",\"0\",\"5\"],[\"63813\",\"153.69\",\"0\",\"5\"],[\"63812.9\",\"0.01\",\"0\",\"1\"],[\"63812.8\",\"0.01\",\"0\",\"1\"],[\"63812.7\",\"77.46\",\"0\",\"1\"],[\"63812.6\",\"0.01\",\"0\",\"1\"],[\"63812.5\",\"1.57\",\"0\",\"1\"],[\"63812.1\",\"0.01\",\"0\",\"1\"],[\"63812\",\"0.01\",\"0\",\"1\"],[\"63811.7\",\"0.06\",\"0\",\"3\"],[\"63811.6\",\"78.2\",\"0\",\"2\"],[\"63811.5\",\"80.74\",\"0\",\"3\"],[\"63811.4\",\"1.01\",\"0\",\"2\"],[\"63811.3\",\"0.01\",\"0\",\"1\"],[\"63811.2\",\"311.44\",\"0\",\"3\"],[\"63811.1\",\"76.64\",\"0\",\"2\"],[\"63811\",\"1.72\",\"0\",\"2\"],[\"63810.9\",\"84.64\",\"0\",\"2\"],[\"63810.7\",\"1\",\"0\",\"1\"],[\"63810.4\",\"11.56\",\"0\",\"5\"],[\"63810.3\",\"110.54\",\"0\",\"4\"],[\"63810.2\",\"0.01\",\"0\",\"1\"],[\"63810.1\",\"1.2\",\"0\",\"1\"],[\"63810\",\"0.03\",\"0\",\"3\"],[\"63809.7\",\"63.88\",\"0\",\"3\"],[\"63809.4\",\"457.87\",\"0\",\"3\"],[\"63809.3\",\"125.39\",\"0\",\"5\"],[\"63809.2\",\"67.14\",\"0\",\"7\"],[\"63809.1\",\"51.2\",\"0\",\"2\"],[\"63808.9\",\"0.01\",\"0\",\"1\"],[\"63808.8\",\"1.2\",\"0\",\"1\"],[\"63808.6\",\"50\",\"0\",\"1\"],[\"63808.5\",\"2.73\",\"0\",\"3\"],[\"63808.4\",\"1.21\",\"0\",\"2\"],[\"63808.1\",\"1.5\",\"0\",\"1\"],[\"63808\",\"0.02\",\"0\",\"2\"],[\"63807.9\",\"1.57\",\"0\",\"1\"],[\"63807.8\",\"112\",\"0\",\"3\"],[\"63807.7\",\"296.1\",\"0\",\"3\"],[\"63807.6\",\"16.06\",\"0\",\"1\"],[\"63807.4\",\"0.08\",\"0\",\"2\"],[\"63807.3\",\"79.45\",\"0\",\"4\"],[\"63807.2\",\"0.01\",\"0\",\"1\"],[\"63807.1\",\"12.12\",\"0\",\"4\"],[\"63807\",\"0.02\",\"0\",\"2\"],[\"63806.9\",\"28\",\"0\",\"3\"],[\"63806.8\",\"0.01\",\"0\",\"1\"],[\"63806.7\",\"0.01\",\"0\",\"1\"],[\"63806.5\",\"3.53\",\"0\",\"3\"],[\"63806.2\",\"80.01\",\"0\",\"2\"],[\"63806.1\",\"139.96\",\"0\",\"7\"],[\"63806\",\"16.11\",\"0\",\"2\"],[\"63805.8\",\"0.08\",\"0\",\"1\"],[\"63805.5\",\"0.01\",\"0\",\"1\"],[\"63805.3\",\"0.02\",\"0\",\"1\"],[\"63805.2\",\"407.87\",\"0\",\"2\"],[\"63804.9\",\"62.68\",\"0\",\"2\"],[\"63804.8\",\"69.03\",\"0\",\"2\"],[\"63804.7\",\"103.29\",\"0\",\"2\"],[\"63804.6\",\"0.01\",\"0\",\"1\"],[\"63804.4\",\"16.15\",\"0\",\"1\"],[\"63804.3\",\"0.03\",\"0\",\"3\"],[\"63804.2\",\"0.19\",\"0\",\"5\"],[\"63804\",\"0.1\",\"0\",\"5\"],[\"63803.9\",\"10.74\",\"0\",\"1\"],[\"63803.6\",\"0.01\",\"0\",\"1\"],[\"63803.4\",\"0.02\",\"0\",\"2\"],[\"63803.2\",\"6.29\",\"0\",\"3\"],[\"63802.8\",\"0.38\",\"0\",\"3\"],[\"63802.7\",\"0.17\",\"0\",\"1\"],[\"63802.5\",\"15.82\",\"0\",\"2\"],[\"63802.4\",\"7.08\",\"0\",\"3\"],[\"63802.3\",\"84.67\",\"0\",\"2\"],[\"63802\",\"200.02\",\"0\",\"3\"],[\"63801.9\",\"39.23\",\"0\",\"2\"],[\"63801.8\",\"0.08\",\"0\",\"2\"],[\"63801.7\",\"0.08\",\"0\",\"2\"],[\"63801.6\",\"4.91\",\"0\",\"4\"],[\"63801.4\",\"0.01\",\"0\",\"1\"],[\"63801.3\",\"393.65\",\"0\",\"1\"],[\"63801.2\",\"407.86\",\"0\",\"1\"],[\"63801.1\",\"215.8\",\"0\",\"7\"],[\"63801\",\"0.03\",\"0\",\"2\"],[\"63800.8\",\"1.09\",\"0\",\"3\"],[\"63800.7\",\"3.13\",\"0\",\"1\"],[\"63800.6\",\"0.01\",\"0\",\"1\"],[\"63800.5\",\"198.87\",\"0\",\"4\"],[\"63800.4\",\"10.63\",\"0\",\"2\"],[\"63800.3\",\"0.04\",\"0\",\"1\"],[\"63800.1\",\"70.79\",\"0\",\"3\"],[\"63800\",\"62.78\",\"0\",\"29\"],[\"63799.9\",\"3.91\",\"0\",\"2\"],[\"63799.7\",\"62.93\",\"0\",\"2\"],[\"63799.6\",\"0.01\",\"0\",\"1\"],[\"63799.4\",\"0.4\",\"0\",\"2\"],[\"63799.1\",\"0.31\",\"0\",\"1\"],[\"63799\",\"2.52\",\"0\",\"2\"],[\"63798.9\",\"235.35\",\"0\",\"2\"],[\"63798.8\",\"37.67\",\"0\",\"2\"],[\"63798.5\",\"4.83\",\"0\",\"2\"],[\"63798.4\",\"0.01\",\"0\",\"1\"],[\"63798.3\",\"39.22\",\"0\",\"2\"],[\"63798.2\",\"0.01\",\"0\",\"1\"],[\"63798.1\",\"34.17\",\"0\",\"1\"],[\"63798\",\"0.05\",\"0\",\"5\"],[\"63797.7\",\"0.01\",\"0\",\"1\"],[\"63797.5\",\"62.67\",\"0\",\"1\"],[\"63797.4\",\"205.55\",\"0\",\"1\"],[\"63797.3\",\"408.02\",\"0\",\"3\"],[\"63797.1\",\"0.01\",\"0\",\"1\"],[\"63797\",\"0.37\",\"0\",\"3\"],[\"63796.8\",\"1\",\"0\",\"1\"],[\"63796.5\",\"8.01\",\"0\",\"2\"],[\"63796.4\",\"0.01\",\"0\",\"1\"],[\"63796.3\",\"62.75\",\"0\",\"1\"],[\"63796.1\",\"0.02\",\"0\",\"2\"],[\"63796\",\"7.1\",\"0\",\"4\"],[\"63795.9\",\"48.45\",\"0\",\"2\"],[\"63795.7\",\"72.3\",\"0\",\"1\"],[\"63795.5\",\"0.01\",\"0\",\"1\"],[\"63795.4\",\"73.4\",\"0\",\"1\"],[\"63795.3\",\"0.15\",\"0\",\"2\"],[\"63795.2\",\"7\",\"0\",\"3\"],[\"63795.1\",\"73.52\",\"0\",\"2\"],[\"63795\",\"71.79\",\"0\",\"4\"],[\"63794.9\",\"0.03\",\"0\",\"3\"],[\"63794.6\",\"0.02\",\"0\",\"2\"],[\"63794.5\",\"87.08\",\"0\",\"1\"],[\"63794.4\",\"245.04\",\"0\",\"2\"],[\"63794.3\",\"1.89\",\"0\",\"2\"],[\"63794\",\"0.02\",\"0\",\"2\"],[\"63793.7\",\"0.14\",\"0\",\"3\"],[\"63793.5\",\"37.66\",\"0\",\"1\"],[\"63793.4\",\"0.01\",\"0\",\"1\"],[\"63793.1\",\"62.68\",\"0\",\"2\"],[\"63793\",\"0.42\",\"0\",\"1\"],[\"63792.9\",\"47.05\",\"0\",\"1\"],[\"63792.8\",\"407.87\",\"0\",\"2\"],[\"63792.7\",\"0.09\",\"0\",\"3\"],[\"63792.6\",\"20.67\",\"0\",\"2\"],[\"63792.5\",\"50.01\",\"0\",\"1\"],[\"63792.4\",\"0.14\",\"0\",\"1\"],[\"63792.3\",\"0.01\",\"0\",\"1\"],[\"63792.2\",\"0.05\",\"0\",\"1\"],[\"63792.1\",\"0.02\",\"0\",\"2\"],[\"63792\",\"58.95\",\"0\",\"7\"],[\"63791.9\",\"74.58\",\"0\",\"3\"],[\"63791.8\",\"0.04\",\"0\",\"4\"],[\"63791.7\",\"0.03\",\"0\",\"3\"],[\"63791.6\",\"0.29\",\"0\",\"1\"],[\"63791.5\",\"20.3\",\"0\",\"2\"],[\"63791.4\",\"0.03\",\"0\",\"2\"],[\"63791.3\",\"72.75\",\"0\",\"1\"],[\"63791.2\",\"226.59\",\"0\",\"2\"],[\"63791.1\",\"0.22\",\"0\",\"4\"],[\"63791\",\"0.01\",\"0\",\"1\"],[\"63790.9\",\"0.14\",\"0\",\"2\"],[\"63790.8\",\"2.2\",\"0\",\"5\"],[\"63790.7\",\"447.43\",\"0\",\"2\"],[\"63790.6\",\"62.67\",\"0\",\"1\"],[\"63790.5\",\"0.5\",\"0\",\"1\"],[\"63790.4\",\"0.01\",\"0\",\"1\"],[\"63790.1\",\"3.91\",\"0\",\"2\"],[\"63790\",\"4.13\",\"0\",\"14\"],[\"63789.8\",\"0.01\",\"0\",\"1\"],[\"63789.7\",\"2.99\",\"0\",\"2\"],[\"63789.5\",\"41.49\",\"0\",\"3\"],[\"63789.4\",\"15.87\",\"0\",\"1\"],[\"63789.2\",\"0.03\",\"0\",\"3\"],[\"63789.1\",\"7.9\",\"0\",\"2\"],[\"63789\",\"56.29\",\"0\",\"3\"],[\"63788.9\",\"1.5\",\"0\",\"2\"],[\"63788.8\",\"354.95\",\"0\",\"4\"],[\"63788.7\",\"408.26\",\"0\",\"8\"],[\"63788.6\",\"62.69\",\"0\",\"2\"],[\"63788.5\",\"0.01\",\"0\",\"1\"],[\"63788.4\",\"79.38\",\"0\",\"1\"],[\"63788.3\",\"8.02\",\"0\",\"3\"],[\"63788.2\",\"24.83\",\"0\",\"4\"],[\"63788.1\",\"47.04\",\"0\",\"2\"],[\"63788\",\"0.02\",\"0\",\"2\"],[\"63787.8\",\"39.21\",\"0\",\"1\"],[\"63787.7\",\"16.05\",\"0\",\"3\"],[\"63787.5\",\"39.97\",\"0\",\"4\"],[\"63787.4\",\"0.01\",\"0\",\"1\"],[\"63787.3\",\"0.51\",\"0\",\"1\"],[\"63787.2\",\"15.87\",\"0\",\"1\"],[\"63787\",\"0.01\",\"0\",\"1\"],[\"63786.9\",\"0.01\",\"0\",\"1\"],[\"63786.8\",\"211.31\",\"0\",\"5\"],[\"63786.7\",\"16.05\",\"0\",\"14\"],[\"63786.6\",\"0.24\",\"0\",\"1\"],[\"63786.5\",\"63.1\",\"0\",\"3\"],[\"63786.3\",\"155.92\",\"0\",\"2\"],[\"63786.2\",\"31.79\",\"0\",\"5\"],[\"63786.1\",\"1.02\",\"0\",\"2\"],[\"63786\",\"0.2\",\"0\",\"20\"],[\"63785.9\",\"0.01\",\"0\",\"1\"],[\"63785.8\",\"0.03\",\"0\",\"1\"],[\"63785.7\",\"31.75\",\"0\",\"3\"],[\"63785.6\",\"0.05\",\"0\",\"5\"],[\"63785.5\",\"4.04\",\"0\",\"1\"],[\"63785.3\",\"13.01\",\"0\",\"2\"],[\"63785.2\",\"325.16\",\"0\",\"2\"],[\"63785.1\",\"203.82\",\"0\",\"4\"],[\"63785\",\"0.04\",\"0\",\"1\"],[\"63784.9\",\"15.68\",\"0\",\"1\"],[\"63784.8\",\"0.02\",\"0\",\"1\"],[\"63784.7\",\"15.88\",\"0\",\"2\"],[\"63784.6\",\"0.01\",\"0\",\"1\"],[\"63784.5\",\"62.68\",\"0\",\"2\"],[\"63784.4\",\"2.22\",\"0\",\"2\"],[\"63784.3\",\"0.07\",\"0\",\"1\"],[\"63784.2\",\"15.87\",\"0\",\"1\"],[\"63784.1\",\"0.01\",\"0\",\"1\"],[\"63784\",\"0.02\",\"0\",\"2\"],[\"63783.9\",\"0.02\",\"0\",\"2\"],[\"63783.8\",\"0.01\",\"0\",\"1\"],[\"63783.7\",\"15.88\",\"0\",\"2\"],[\"63783.6\",\"11.49\",\"0\",\"2\"],[\"63783.5\",\"408.36\",\"0\",\"2\"],[\"63783.3\",\"213.31\",\"0\",\"5\"],[\"63783.1\",\"0.02\",\"0\",\"1\"],[\"63783\",\"17.44\",\"0\",\"2\"],[\"63782.9\",\"0.01\",\"0\",\"1\"],[\"63782.8\",\"0.03\",\"0\",\"3\"],[\"63782.7\",\"0.01\",\"0\",\"1\"],[\"63782.6\",\"0.15\",\"0\",\"6\"],[\"63782.5\",\"85.64\",\"0\",\"7\"],[\"63782.4\",\"0.01\",\"0\",\"1\"],[\"63782.3\",\"37.67\",\"0\",\"2\"],[\"63782.1\",\"10.71\",\"0\",\"8\"],[\"63782\",\"0.08\",\"0\",\"3\"],[\"63781.8\",\"0.01\",\"0\",\"1\"],[\"63781.7\",\"251.05\",\"0\",\"2\"],[\"63781.6\",\"39.21\",\"0\",\"1\"],[\"63781.3\",\"0.02\",\"0\",\"2\"],[\"63781.1\",\"0.01\",\"0\",\"1\"],[\"63781\",\"1.56\",\"0\",\"2\"],[\"63780.9\",\"0.02\",\"0\",\"2\"],[\"63780.7\",\"0.01\",\"0\",\"1\"],[\"63780.5\",\"72.3\",\"0\",\"1\"],[\"63780.4\",\"15.92\",\"0\",\"3\"],[\"63780.3\",\"0.03\",\"0\",\"3\"],[\"63780.2\",\"0.01\",\"0\",\"1\"],[\"63780.1\",\"0.01\",\"0\",\"1\"],[\"63780\",\"78.13\",\"0\",\"12\"],[\"63779.9\",\"63.46\",\"0\",\"2\"],[\"63779.8\",\"90.32\",\"0\",\"4\"],[\"63779.7\",\"14.21\",\"0\",\"1\"],[\"63779.6\",\"407.86\",\"0\",\"1\"],[\"63779.5\",\"0.03\",\"0\",\"2\"],[\"63779.4\",\"0.01\",\"0\",\"1\"],[\"63779.3\",\"15.89\",\"0\",\"3\"],[\"63779.2\",\"0.01\",\"0\",\"1\"],[\"63779.1\",\"0.26\",\"0\",\"1\"],[\"63778.9\",\"60.3\",\"0\",\"3\"],[\"63778.7\",\"0.01\",\"0\",\"1\"],[\"63778.5\",\"51.2\",\"0\",\"1\"],[\"63778.4\",\"0.01\",\"0\",\"1\"],[\"63778.3\",\"91.46\",\"0\",\"2\"],[\"63778.1\",\"3.9\",\"0\",\"1\"],[\"63778\",\"30.91\",\"0\",\"7\"],[\"63777.9\",\"6.36\",\"0\",\"5\"],[\"63777.8\",\"0.09\",\"0\",\"1\"],[\"63777.7\",\"0.01\",\"0\",\"1\"],[\"63777.6\",\"0.02\",\"0\",\"2\"],[\"63777.5\",\"0.01\",\"0\",\"1\"],[\"63777.4\",\"0.02\",\"0\",\"2\"],[\"63777.3\",\"75.21\",\"0\",\"1\"],[\"63777.2\",\"0.12\",\"0\",\"1\"],[\"63777.1\",\"59.31\",\"0\",\"4\"],[\"63777\",\"9\",\"0\",\"2\"],[\"63776.9\",\"0.45\",\"0\",\"2\"],[\"63776.8\",\"65.47\",\"0\",\"2\"],[\"63776.7\",\"0.23\",\"0\",\"3\"],[\"63776.6\",\"15.88\",\"0\",\"2\"],[\"63776.4\",\"0.03\",\"0\",\"1\"],[\"63776.3\",\"0.01\",\"0\",\"1\"],[\"63776.2\",\"37.67\",\"0\",\"2\"],[\"63776.1\",\"15.87\",\"0\",\"1\"],[\"63776\",\"0.05\",\"0\",\"5\"],[\"63775.9\",\"1.67\",\"0\",\"2\"],[\"63775.8\",\"69.73\",\"0\",\"2\"],[\"63775.7\",\"10.87\",\"0\",\"2\"],[\"63775.6\",\"407.89\",\"0\",\"3\"],[\"63775.5\",\"0.08\",\"0\",\"2\"],[\"63775.4\",\"1.31\",\"0\",\"4\"],[\"63775.3\",\"75.33\",\"0\",\"3\"],[\"63775.2\",\"23.51\",\"0\",\"2\"],[\"63775.1\",\"0.01\",\"0\",\"1\"],[\"63775\",\"1.98\",\"0\",\"10\"],[\"63774.9\",\"0.05\",\"0\",\"2\"],[\"63774.8\",\"1\",\"0\",\"3\"],[\"63774.7\",\"0.07\",\"0\",\"2\"],[\"63774.4\",\"0.01\",\"0\",\"1\"],[\"63774.3\",\"0.13\",\"0\",\"1\"],[\"63774.1\",\"0.02\",\"0\",\"2\"],[\"63774\",\"2.3\",\"0\",\"3\"],[\"63773.9\",\"19.62\",\"0\",\"3\"],[\"63773.8\",\"16.17\",\"0\",\"2\"],[\"63773.7\",\"0.01\",\"0\",\"1\"],[\"63773.5\",\"0.01\",\"0\",\"1\"],[\"63773.4\",\"15.88\",\"0\",\"2\"],[\"63773.2\",\"34.03\",\"0\",\"4\"],[\"63773.1\",\"19.03\",\"0\",\"2\"],[\"63773\",\"0.01\",\"0\",\"1\"],[\"63772.9\",\"0.01\",\"0\",\"1\"],[\"63772.8\",\"1395.22\",\"0\",\"3\"],[\"63772.7\",\"0.03\",\"0\",\"3\"],[\"63772.6\",\"73.95\",\"0\",\"2\"],[\"63772.5\",\"10.79\",\"0\",\"1\"],[\"63772.3\",\"0.02\",\"0\",\"2\"],[\"63772.2\",\"1.57\",\"0\",\"1\"],[\"63772.1\",\"0.01\",\"0\",\"1\"],[\"63772\",\"134.71\",\"0\",\"2\"],[\"63771.9\",\"50.98\",\"0\",\"1\"],[\"63771.8\",\"19.1\",\"0\",\"2\"],[\"63771.7\",\"0.01\",\"0\",\"1\"],[\"63771.4\",\"0.04\",\"0\",\"3\"],[\"63771.2\",\"0.02\",\"0\",\"2\"],[\"63771.1\",\"0.31\",\"0\",\"2\"],[\"63771\",\"0.02\",\"0\",\"2\"],[\"63770.9\",\"0.01\",\"0\",\"1\"],[\"63770.7\",\"470.54\",\"0\",\"3\"],[\"63770.6\",\"42.46\",\"0\",\"4\"],[\"63770.5\",\"31.76\",\"0\",\"3\"],[\"63770.4\",\"0.03\",\"0\",\"1\"],[\"63770.3\",\"1.48\",\"0\",\"2\"],[\"63770.2\",\"73.72\",\"0\",\"3\"],[\"63770.1\",\"15.88\",\"0\",\"2\"],[\"63770\",\"20.05\",\"0\",\"4\"],[\"63769.9\",\"0.01\",\"0\",\"1\"],[\"63769.8\",\"0.03\",\"0\",\"1\"],[\"63769.6\",\"16.01\",\"0\",\"7\"],[\"63769.5\",\"1\",\"0\",\"1\"],[\"63769.4\",\"0.02\",\"0\",\"2\"],[\"63769.3\",\"10.79\",\"0\",\"1\"],[\"63769.2\",\"0.02\",\"0\",\"2\"],[\"63769\",\"22.95\",\"0\",\"3\"],[\"63768.9\",\"41.08\",\"0\",\"4\"],[\"63768.8\",\"43.59\",\"0\",\"6\"],[\"63768.6\",\"0.01\",\"0\",\"1\"],[\"63768.5\",\"1.01\",\"0\",\"2\"],[\"63768.4\",\"3.41\",\"0\",\"2\"],[\"63768.3\",\"0.76\",\"0\",\"1\"],[\"63768.2\",\"1.22\",\"0\",\"3\"],[\"63768.1\",\"0.23\",\"0\",\"4\"],[\"63768\",\"62.69\",\"0\",\"3\"],[\"63767.9\",\"49.64\",\"0\",\"2\"],[\"63767.7\",\"0.02\",\"0\",\"1\"],[\"63767.6\",\"0.04\",\"0\",\"2\"],[\"63767.5\",\"18.79\",\"0\",\"4\"],[\"63767.2\",\"7.43\",\"0\",\"3\"],[\"63767.1\",\"0.01\",\"0\",\"1\"],[\"63767\",\"0.02\",\"0\",\"2\"],[\"63766.9\",\"17.09\",\"0\",\"3\"],[\"63766.8\",\"0.01\",\"0\",\"1\"],[\"63766.7\",\"0.56\",\"0\",\"4\"],[\"63766.6\",\"61.24\",\"0\",\"4\"],[\"63766.5\",\"407.89\",\"0\",\"4\"],[\"63766.4\",\"33.3\",\"0\",\"4\"],[\"63766.3\",\"1.86\",\"0\",\"2\"],[\"63766.2\",\"0.14\",\"0\",\"1\"],[\"63766.1\",\"83.33\",\"0\",\"2\"],[\"63766\",\"0.55\",\"0\",\"2\"],[\"63765.9\",\"76.24\",\"0\",\"1\"],[\"63765.8\",\"0.01\",\"0\",\"1\"],[\"63765.7\",\"802.87\",\"0\",\"1\"],[\"63765.6\",\"0.01\",\"0\",\"1\"],[\"63765.5\",\"1.04\",\"0\",\"2\"],[\"63765.3\",\"20\",\"0\",\"1\"],[\"63765.2\",\"62.67\",\"0\",\"1\"],[\"63765.1\",\"15.91\",\"0\",\"4\"],[\"63765\",\"0.01\",\"0\",\"1\"],[\"63764.9\",\"0.02\",\"0\",\"2\"],[\"63764.1\",\"3.9\",\"0\",\"1\"],[\"63764\",\"0.02\",\"0\",\"2\"],[\"63763.8\",\"73.6\",\"0\",\"3\"],[\"63763.7\",\"16.18\",\"0\",\"3\"],[\"63763.6\",\"1.09\",\"0\",\"10\"],[\"63763.4\",\"6.76\",\"0\",\"3\"],[\"63763.2\",\"15.9\",\"0\",\"4\"],[\"63763.1\",\"35.48\",\"0\",\"4\"],[\"63762.9\",\"10.84\",\"0\",\"3\"],[\"63762.8\",\"79.89\",\"0\",\"2\"],[\"63762.5\",\"62.68\",\"0\",\"2\"],[\"63762.4\",\"47.4\",\"0\",\"3\"],[\"63762.3\",\"27.92\",\"0\",\"3\"],[\"63762.2\",\"0.02\",\"0\",\"2\"],[\"63762.1\",\"0.01\",\"0\",\"1\"],[\"63761.6\",\"72.3\",\"0\",\"1\"],[\"63761.4\",\"0.01\",\"0\",\"1\"],[\"63761.3\",\"0.01\",\"0\",\"1\"],[\"63761.2\",\"0.02\",\"0\",\"1\"],[\"63761\",\"0.1\",\"0\",\"1\"]],\"ts\":\"1781979781808\",\"checksum\":200968489,\"seqId\":325026384749,\"prevSeqId\":-1}]}"}
{"action": "update", "capture_sequence": 4, "channel": "books", "connection_sequence": 1, "event": null, "instId": "BTC-USDT-SWAP", "local_receive_ts": "2026-06-20T18:23:02Z", "monotonic_ns": 1607337915728773, "raw": "{\"arg\":{\"channel\":\"books\",\"instId\":\"BTC-USDT-SWAP\"},\"action\":\"update\",\"data\":[{\"asks\":[[\"63813.7\",\"45.03\",\"0\",\"21\"],[\"63816.1\",\"0.05\",\"0\",\"1\"],[\"63816.8\",\"0.45\",\"0\",\"3\"],[\"63817.8\",\"44.97\",\"0\",\"2\"],[\"63818.8\",\"1.59\",\"0\",\"3\"],[\"63828.6\",\"0\",\"0\",\"0\"],[\"63830.9\",\"0.32\",\"0\",\"2\"],[\"63831.1\",\"0\",\"0\",\"0\"],[\"63834.4\",\"78.34\",\"0\",\"3\"],[\"63834.7\",\"0\",\"0\",\"0\"],[\"63839.1\",\"58.84\",\"0\",\"4\"],[\"63839.8\",\"10.68\",\"0\",\"1\"],[\"63868\",\"1.52\",\"0\",\"2\"],[\"63868.1\",\"0.09\",\"0\",\"1\"]],\"bids\":[[\"63802.5\",\"0.15\",\"0\",\"1\"],[\"63802.1\",\"15.67\",\"0\",\"1\"],[\"63799.1\",\"0\",\"0\",\"0\"],[\"63798.6\",\"0.31\",\"0\",\"1\"],[\"63794.5\",\"0\",\"0\",\"0\"],[\"63792.9\",\"134.13\",\"0\",\"2\"],[\"63792\",\"0.12\",\"0\",\"6\"],[\"63791.4\",\"58.87\",\"0\",\"3\"]],\"ts\":\"1781979781908\",\"checksum\":77990459,\"seqId\":325026384783,\"prevSeqId\":325026384749}]}"}
{"action": "update", "capture_sequence": 5, "channel": "books", "connection_sequence": 1, "event": null, "instId": "BTC-USDT-SWAP", "local_receive_ts": "2026-06-20T18:23:02Z", "monotonic_ns": 1607337966230472, "raw": "{\"arg\":{\"channel\":\"books\",\"instId\":\"BTC-USDT-SWAP\"},\"action\":\"update\",\"data\":[{\"asks\":[[\"63828.4\",\"0.01\",\"0\",\"1\"],[\"63830.9\",\"0.01\",\"0\",\"1\"],[\"63831.1\",\"0.31\",\"0\",\"1\"],[\"63834.3\",\"31.53\",\"0\",\"2\"],[\"63834.4\",\"78.36\",\"0\",\"3\"],[\"63836.4\",\"47.22\",\"0\",\"2\"],[\"63836.6\",\"0.01\",\"0\",\"1\"],[\"63836.7\",\"111.03\",\"0\",\"3\"],[\"63837.5\",\"0.47\",\"0\",\"2\"],[\"63837.9\",\"235.19\",\"0\",\"1\"],[\"63839.2\",\"15.91\",\"0\",\"4\"],[\"63839.4\",\"0\",\"0\",\"0\"],[\"63839.7\",\"0.81\",\"0\",\"2\"],[\"63839.9\",\"79.01\",\"0\",\"2\"],[\"63841.2\",\"20.28\",\"0\",\"1\"],[\"63841.5\",\"0.01\",\"0\",\"1\"],[\"63842.9\",\"0.02\",\"0\",\"1\"],[\"63843.8\",\"5.34\",\"0\",\"3\"],[\"63850\",\"8.13\",\"0\",\"56\"],[\"63851.1\",\"0.91\",\"0\",\"1\"],[\"63854.2\",\"0.01\",\"0\",\"1\"],[\"63867.6\",\"0\",\"0\",\"0\"],[\"63867.7\",\"0\",\"0\",\"0\"],[\"63867.8\",\"0\",\"0\",\"0\"],[\"63868\",\"0\",\"0\",\"0\"],[\"63868.1\",\"0\",\"0\",\"0\"]],\"bids\":[[\"63804.6\",\"0.02\",\"0\",\"2\"],[\"63804.3\",\"0.02\",\"0\",\"2\"],[\"63801.3\",\"394.43\",\"0\",\"2\"],[\"63800.8\",\"0.31\",\"0\",\"2\"],[\"63800.5\",\"167.5\",\"0\",\"3\"],[\"63800.2\",\"31.37\",\"0\",\"1\"],[\"63799.1\",\"235.64\",\"0\",\"2\"],[\"63798.9\",\"0.02\",\"0\",\"1\"],[\"63798.6\",\"0\",\"0\",\"0\"],[\"63794.5\",\"87.08\",\"0\",\"1\"],[\"63792.9\",\"47.05\",\"0\",\"1\"],[\"63791.6\",\"59.13\",\"0\",\"2\"],[\"63791.5\",\"0.01\",\"0\",\"1\"],[\"63791.4\",\"0.03\",\"0\",\"2\"],[\"63791.3\",\"93.04\",\"0\",\"2\"],[\"63790.8\",\"88.49\",\"0\",\"5\"],[\"63790.7\",\"361.13\",\"0\",\"1\"],[\"63790.6\",\"62.68\",\"0\",\"2\"],[\"63761.2\",\"0\",\"0\",\"0\"],[\"63761\",\"0\",\"0\",\"0\"]],\"ts\":\"1781979782008\",\"checksum\":77990459,\"seqId\":325026384833,\"prevSeqId\":325026384783}]}"}
{"action": null, "capture_sequence": 6, "channel": "trades", "connection_sequence": 1, "event": null, "instId": "BTC-USDT-SWAP", "local_receive_ts": "2026-06-20T18:23:02Z", "monotonic_ns": 1607337985934718, "raw": "{\"arg\":{\"channel\":\"trades\",\"instId\":\"BTC-USDT-SWAP\"},\"data\":[{\"instId\":\"BTC-USDT-SWAP\",\"tradeId\":\"2718372438\",\"px\":\"63813.6\",\"sz\":\"0.03\",\"side\":\"sell\",\"ts\":\"1781979782067\",\"count\":\"1\",\"source\":\"0\",\"seqId\":325026384843}]}"}
{"action": "update", "capture_sequence": 7, "channel": "books", "connection_sequence": 1, "event": null, "instId": "BTC-USDT-SWAP", "local_receive_ts": "2026-06-20T18:23:02Z", "monotonic_ns": 1607338026762268, "raw": "{\"arg\":{\"channel\":\"books\",\"instId\":\"BTC-USDT-SWAP\"},\"action\":\"update\",\"data\":[{\"asks\":[[\"63813.7\",\"45.06\",\"0\",\"22\"],[\"63837.5\",\"235.66\",\"0\",\"3\"],[\"63837.9\",\"0\",\"0\",\"0\"],[\"63854.2\",\"0\",\"0\",\"0\"],[\"63867.6\",\"10.82\",\"0\",\"2\"],[\"63867.7\",\"0.02\",\"0\",\"2\"]],\"bids\":[[\"63813.6\",\"1235.17\",\"0\",\"76\"],[\"63791.6\",\"0.29\",\"0\",\"1\"],[\"63791.4\",\"79.16\",\"0\",\"4\"],[\"63791.3\",\"72.75\",\"0\",\"1\"]],\"ts\":\"1781979782108\",\"checksum\":1441869972,\"seqId\":325026384868,\"prevSeqId\":325026384833}]}"}
{"action": "update", "capture_sequence": 8, "channel": "books", "connection_sequence": 1, "event": null, "instId": "BTC-USDT-SWAP", "local_receive_ts": "2026-06-20T18:23:02Z", "monotonic_ns": 1607338127391827, "raw": "{\"arg\":{\"channel\":\"books\",\"instId\":\"BTC-USDT-SWAP\"},\"action\":\"update\",\"data\":[{\"asks\":[[\"63813.7\",\"45.05\",\"0\",\"21\"],[\"63817.6\",\"1.57\",\"0\",\"1\"],[\"63820\",\"0.62\",\"0\",\"3\"],[\"63823.3\",\"10.81\",\"0\",\"1\"],[\"63841.2\",\"0\",\"0\",\"0\"],[\"63841.3\",\"21.61\",\"0\",\"3\"],[\"63860\",\"1.05\",\"0\",\"13\"],[\"63867.7\",\"0\",\"0\",\"0\"]],\"bids\":[[\"63804.6\",\"0\",\"0\",\"0\"],[\"63804.3\",\"0.04\",\"0\",\"4\"],[\"63790.7\",\"361.14\",\"0\",\"2\"],[\"63790.6\",\"62.67\",\"0\",\"1\"],[\"63761.2\",\"0.02\",\"0\",\"1\"]],\"ts\":\"1781979782208\",\"checksum\":738080373,\"seqId\":325026384883,\"prevSeqId\":325026384868}]}"}
{"action": "update", "capture_sequence": 9, "channel": "books", "connection_sequence": 1, "event": null, "instId": "BTC-USDT-SWAP", "local_receive_ts": "2026-06-20T18:23:02Z", "monotonic_ns": 1607338227379118, "raw": "{\"arg\":{\"channel\":\"books\",\"instId\":\"BTC-USDT-SWAP\"},\"action\":\"update\",\"data\":[{\"asks\":[[\"63817.6\",\"0\",\"0\",\"0\"],[\"63817.8\",\"46.54\",\"0\",\"3\"],[\"63828.4\",\"0\",\"0\",\"0\"],[\"63834.2\",\"15.7\",\"0\",\"3\"],[\"63834.4\",\"62.68\",\"0\",\"2\"],[\"63836.2\",\"31.36\",\"0\",\"2\"],[\"63836.4\",\"15.87\",\"0\",\"1\"],[\"63836.7\",\"76.88\",\"0\",\"2\"],[\"63836.9\",\"34.17\",\"0\",\"3\"],[\"63838.3\",\"58.81\",\"0\",\"3\"],[\"63839.1\",\"0.05\",\"0\",\"3\"],[\"63841.3\",\"1.33\",\"0\",\"2\"],[\"63841.5\",\"20.29\",\"0\",\"2\"],[\"63867.7\",\"0.01\",\"0\",\"1\"],[\"63868\",\"1.52\",\"0\",\"2\"]],\"bids\":[[\"63813.6\",\"1234.55\",\"0\",\"75\"],[\"63800.2\",\"0\",\"0\",\"0\"],[\"63800.1\",\"102.16\",\"0\",\"4\"],[\"63799.1\",\"0.31\",\"0\",\"1\"],[\"63798.9\",\"235.35\",\"0\",\"2\"],[\"63798.4\",\"34.18\",\"0\",\"2\"],[\"63798.1\",\"0\",\"0\",\"0\"],[\"63794.5\",\"87.07\",\"0\",\"1\"],[\"63791.5\",\"20.3\",\"0\",\"2\"],[\"63791.4\",\"0.03\",\"0\",\"2\"],[\"63790.9\",\"86.44\",\"0\",\"3\"],[\"63790.8\",\"2.19\",\"0\",\"4\"],[\"63790.2\",\"58.84\",\"0\",\"1\"],[\"63761\",\"0.1\",\"0\",\"1\"]],\"ts\":\"1781979782308\",\"checksum\":2086995275,\"seqId\":325026384979,\"prevSeqId\":325026384883}]}"}
{"action": null, "capture_sequence": 10, "channel": "trades", "connection_sequence": 1, "event": null, "instId": "BTC-USDT-SWAP", "local_receive_ts": "2026-06-20T18:23:02Z", "monotonic_ns": 1607338253712469, "raw": "{\"arg\":{\"channel\":\"trades\",\"instId\":\"BTC-USDT-SWAP\"},\"data\":[{\"instId\":\"BTC-USDT-SWAP\",\"tradeId\":\"2718372439\",\"px\":\"63813.6\",\"sz\":\"0.01\",\"side\":\"sell\",\"ts\":\"1781979782335\",\"count\":\"1\",\"source\":\"0\",\"seqId\":325026384986}]}"}
{"action": "update", "capture_sequence": 11, "channel": "books", "connection_sequence": 1, "event": null, "instId": "BTC-USDT-SWAP", "local_receive_ts": "2026-06-20T18:23:02Z", "monotonic_ns": 1607338327302078, "raw": "{\"arg\":{\"channel\":\"books\",\"instId\":\"BTC-USDT-SWAP\"},\"action\":\"update\",\"data\":[{\"asks\":[[\"63817.8\",\"44.97\",\"0\",\"2\"],[\"63828.4\",\"0.01\",\"0\",\"1\"],[\"63854.2\",\"0.01\",\"0\",\"1\"],[\"63867.7\",\"0\",\"0\",\"0\"],[\"63868\",\"0\",\"0\",\"0\"]],\"bids\":[[\"63813.6\",\"1240.98\",\"0\",\"76\"],[\"63804.6\",\"0.01\",\"0\",\"1\"],[\"63804.3\",\"0.03\",\"0\",\"3\"],[\"63790.8\",\"2.2\",\"0\",\"5\"],[\"63790.7\",\"361.13\",\"0\",\"1\"],[\"63761\",\"0\",\"0\",\"0\"]],\"ts\":\"1781979782408\",\"checksum\":1723606216,\"seqId\":325026385021,\"prevSeqId\":325026384979}]}"}
{"action": null, "capture_sequence": 12, "channel": "trades", "connection_sequence": 1, "event": null, "instId": "BTC-USDT-SWAP", "local_receive_ts": "2026-06-20T18:23:02Z", "monotonic_ns": 1607338368764471, "raw": "{\"arg\":{\"channel\":\"trades\",\"instId\":\"BTC-USDT-SWAP\"},\"data\":[{\"instId\":\"BTC-USDT-SWAP\",\"tradeId\":\"2718372440\",\"px\":\"63813.6\",\"sz\":\"0.04\",\"side\":\"sell\",\"ts\":\"1781979782450\",\"count\":\"1\",\"source\":\"0\",\"seqId\":325026385024}]}"}
{"action": "update", "capture_sequence": 13, "channel": "books", "connection_sequence": 1, "event": null, "instId": "BTC-USDT-SWAP", "local_receive_ts": "2026-06-20T18:23:02Z", "monotonic_ns": 1607338427449918, "raw": "{\"arg\":{\"channel\":\"books\",\"instId\":\"BTC-USDT-SWAP\"},\"action\":\"update\",\"data\":[{\"asks\":[[\"63813.7\",\"45.06\",\"0\",\"21\"],[\"63818.8\",\"0.02\",\"0\",\"2\"],[\"63819.2\",\"0.02\",\"0\",\"2\"],[\"63819.8\",\"0.02\",\"0\",\"2\"],[\"63820.2\",\"0.32\",\"0\",\"2\"],[\"63838.3\",\"0.02\",\"0\",\"2\"],[\"63838.7\",\"58.8\",\"0\",\"2\"],[\"63854.2\",\"0\",\"0\",\"0\"],[\"63867.7\",\"0.01\",\"0\",\"1\"]],\"bids\":[[\"63813.6\",\"1240.94\",\"0\",\"76\"],[\"63791\",\"58.85\",\"0\",\"2\"],[\"63790.2\",\"0\",\"0\",\"0\"],[\"63761\",\"0.1\",\"0\",\"1\"]],\"ts\":\"1781979782508\",\"checksum\":567707225,\"seqId\":325026385039,\"prevSeqId\":325026385021}]}"}
{"action": "update", "capture_sequence": 14, "channel": "books", "connection_sequence": 1, "event": null, "instId": "BTC-USDT-SWAP", "local_receive_ts": "2026-06-20T18:23:02Z", "monotonic_ns": 1607338526955927, "raw": "{\"arg\":{\"channel\":\"books\",\"instId\":\"BTC-USDT-SWAP\"},\"action\":\"update\",\"data\":[{\"asks\":[[\"63842.6\",\"0.01\",\"0\",\"1\"],[\"63844.4\",\"157.02\",\"0\",\"3\"]],\"bids\":[],\"ts\":\"1781979782608\",\"checksum\":567707225,\"seqId\":325026385044,\"prevSeqId\":325026385039}]}"}
{"action": "update", "capture_sequence": 15, "channel": "books", "connection_sequence": 1, "event": null, "instId": "BTC-USDT-SWAP", "local_receive_ts": "2026-06-20T18:23:02Z", "monotonic_ns": 1607338628165540, "raw": "{\"arg\":{\"channel\":\"books\",\"instId\":\"BTC-USDT-SWAP\"},\"action\":\"update\",\"data\":[{\"asks\":[[\"63828.4\",\"0\",\"0\",\"0\"],[\"63838.9\",\"0.52\",\"0\",\"2\"],[\"63839.2\",\"15.89\",\"0\",\"3\"],[\"63842.9\",\"0\",\"0\",\"0\"],[\"63843.8\",\"5.36\",\"0\",\"4\"],[\"63868\",\"1.52\",\"0\",\"2\"],[\"63868.1\",\"0.09\",\"0\",\"1\"]],\"bids\":[[\"63804.6\",\"0.02\",\"0\",\"2\"],[\"63804.3\",\"0.02\",\"0\",\"2\"]],\"ts\":\"1781979782708\",\"checksum\":567707225,\"seqId\":325026385061,\"prevSeqId\":325026385044}]}"}
{"action": "update", "capture_sequence": 16, "channel": "books", "connection_sequence": 1, "event": null, "instId": "BTC-USDT-SWAP", "local_receive_ts": "2026-06-20T18:23:02Z", "monotonic_ns": 1607338727197962, "raw": "{\"arg\":{\"channel\":\"books\",\"instId\":\"BTC-USDT-SWAP\"},\"action\":\"update\",\"data\":[{\"asks\":[[\"63820.7\",\"0.9\",\"0\",\"1\"],[\"63835.8\",\"0.01\",\"0\",\"1\"],[\"63836.1\",\"86.24\",\"0\",\"2\"],[\"63854.1\",\"124.58\",\"0\",\"4\"],[\"63854.7\",\"0.01\",\"0\",\"1\"],[\"63868.1\",\"0\",\"0\",\"0\"]],\"bids\":[[\"63813.6\",\"1241.04\",\"0\",\"77\"],[\"63791.1\",\"86.52\",\"0\",\"5\"],[\"63790.9\",\"0.14\",\"0\",\"2\"]],\"ts\":\"1781979782808\",\"checksum\":1166978427,\"seqId\":325026385079,\"prevSeqId\":325026385061}]}"}
{"action": "update", "capture_sequence": 17, "channel": "books", "connection_sequence": 1, "event": null, "instId": "BTC-USDT-SWAP", "local_receive_ts": "2026-06-20T18:23:03Z", "monotonic_ns": 1607338826959685, "raw": "{\"arg\":{\"channel\":\"books\",\"instId\":\"BTC-USDT-SWAP\"},\"action\":\"update\",\"data\":[{\"asks\":[[\"63819.6\",\"1.57\",\"0\",\"1\"],[\"63820\",\"2.19\",\"0\",\"4\"],[\"63820.5\",\"20.84\",\"0\",\"4\"],[\"63823.1\",\"1.57\",\"0\",\"1\"],[\"63854.7\",\"0\",\"0\",\"0\"],[\"63868\",\"0\",\"0\",\"0\"]],\"bids\":[],\"ts\":\"1781979782908\",\"checksum\":1166978427,\"seqId\":325026385098,\"prevSeqId\":325026385079}]}"}
{"action": "update", "capture_sequence": 18, "channel": "books", "connection_sequence": 1, "event": null, "instId": "BTC-USDT-SWAP", "local_receive_ts": "2026-06-20T18:23:03Z", "monotonic_ns": 1607338927506882, "raw": "{\"arg\":{\"channel\":\"books\",\"instId\":\"BTC-USDT-SWAP\"},\"action\":\"update\",\"data\":[{\"asks\":[[\"63819.6\",\"0\",\"0\",\"0\"],[\"63820\",\"0.62\",\"0\",\"3\"],[\"63826.8\",\"0\",\"0\",\"0\"],[\"63828.4\",\"0.01\",\"0\",\"1\"],[\"63831.2\",\"62.74\",\"0\",\"1\"],[\"63834.2\",\"0.02\",\"0\",\"2\"],[\"63834.3\",\"47.21\",\"0\",\"3\"],[\"63843.3\",\"0.05\",\"0\",\"4\"],[\"63843.8\",\"5.34\",\"0\",\"3\"],[\"63868\",\"1.52\",\"0\",\"2\"]],\"bids\":[[\"63813.6\",\"1234.77\",\"0\",\"76\"],[\"63804.6\",\"0\",\"0\",\"0\"],[\"63804.3\",\"0.04\",\"0\",\"4\"],[\"63799.7\",\"62.74\",\"0\",\"1\"],[\"63799\",\"0.01\",\"0\",\"1\"],[\"63791\",\"58.86\",\"0\",\"3\"],[\"63790.8\",\"2.19\",\"0\",\"4\"],[\"63760.9\",\"235.07\",\"0\",\"2\"]],\"ts\":\"1781979783008\",\"checksum\":721576893,\"seqId\":325026385144,\"prevSeqId\":325026385098}]}"}
{"action": "update", "capture_sequence": 19, "channel": "books", "connection_sequence": 1, "event": null, "instId": "BTC-USDT-SWAP", "local_receive_ts": "2026-06-20T18:23:03Z", "monotonic_ns": 1607339027240331, "raw": "{\"arg\":{\"channel\":\"books\",\"instId\":\"BTC-USDT-SWAP\"},\"action\":\"update\",\"data\":[{\"asks\":[[\"63818.6\",\"2.17\",\"0\",\"2\"],[\"63819.1\",\"1.6\",\"0\",\"2\"],[\"63819.6\",\"1.57\",\"0\",\"1\"],[\"63820\",\"2.19\",\"0\",\"4\"],[\"63826.8\",\"3.25\",\"0\",\"1\"],[\"63828.4\",\"0\",\"0\",\"0\"],[\"63831.2\",\"62.9\",\"0\",\"2\"],[\"63843.3\",\"0.03\",\"0\",\"3\"],[\"63843.8\",\"5.36\",\"0\",\"4\"],[\"63854.1\",\"124.57\",\"0\",\"3\"],[\"63868\",\"0\",\"0\",\"0\"]],\"bids\":[[\"63799.7\",\"62.94\",\"0\",\"2\"],[\"63799.1\",\"0\",\"0\",\"0\"],[\"63799\",\"2.92\",\"0\",\"3\"],[\"63760.8\",\"0.03\",\"0\",\"2\"]],\"ts\":\"1781979783108\",\"checksum\":721576893,\"seqId\":325026385158,\"prevSeqId\":325026385144}]}"}
{"action": "update", "capture_sequence": 20, "channel": "books", "connection_sequence": 1, "event": null, "instId": "BTC-USDT-SWAP", "local_receive_ts": "2026-06-20T18:23:03Z", "monotonic_ns": 1607339127099913, "raw": "{\"arg\":{\"channel\":\"books\",\"instId\":\"BTC-USDT-SWAP\"},\"action\":\"update\",\"data\":[{\"asks\":[[\"63818\",\"1.57\",\"0\",\"1\"],[\"63823.1\",\"0\",\"0\",\"0\"],[\"63828.4\",\"0.01\",\"0\",\"1\"],[\"63854.2\",\"0.01\",\"0\",\"1\"],[\"63867.6\",\"0\",\"0\",\"0\"],[\"63867.7\",\"0\",\"0\",\"0\"]],\"bids\":[[\"63813.6\",\"1234.86\",\"0\",\"76\"]],\"ts\":\"1781979783208\",\"checksum\":1899853228,\"seqId\":325026385178,\"prevSeqId\":325026385158}]}"}
{"action": "update", "capture_sequence": 21, "channel": "books", "connection_sequence": 1, "event": null, "instId": "BTC-USDT-SWAP", "local_receive_ts": "2026-06-20T18:23:03Z", "monotonic_ns": 1607339227773915, "raw": "{\"arg\":{\"channel\":\"books\",\"instId\":\"BTC-USDT-SWAP\"},\"action\":\"update\",\"data\":[{\"asks\":[[\"63818\",\"0\",\"0\",\"0\"],[\"63818.1\",\"1.57\",\"0\",\"1\"],[\"63818.6\",\"0.6\",\"0\",\"1\"],[\"63854.2\",\"0\",\"0\",\"0\"],[\"63867.6\",\"10.82\",\"0\",\"2\"]],\"bids\":[[\"63813.6\",\"1235.52\",\"0\",\"77\"]],\"ts\":\"1781979783308\",\"checksum\":-1909565323,\"seqId\":325026385199,\"prevSeqId\":325026385178}]}"}
{"action": "update", "capture_sequence": 22, "channel": "books", "connection_sequence": 1, "event": null, "instId": "BTC-USDT-SWAP", "local_receive_ts": "2026-06-20T18:23:03Z", "monotonic_ns": 1607339327191382, "raw": "{\"arg\":{\"channel\":\"books\",\"instId\":\"BTC-USDT-SWAP\"},\"action\":\"update\",\"data\":[{\"asks\":[[\"63818.1\",\"0\",\"0\",\"0\"],[\"63818.4\",\"2.36\",\"0\",\"3\"],[\"63819.5\",\"1.58\",\"0\",\"2\"],[\"63819.6\",\"0\",\"0\",\"0\"],[\"63823.1\",\"1.57\",\"0\",\"1\"],[\"63867.7\",\"0.01\",\"0\",\"1\"]],\"bids\":[[\"63813.6\",\"1235.54\",\"0\",\"77\"]],\"ts\":\"1781979783408\",\"checksum\":-702137752,\"seqId\":325026385216,\"prevSeqId\":325026385199}]}"}
{"action": "update", "capture_sequence": 23, "channel": "books", "connection_sequence": 1, "event": null, "instId": "BTC-USDT-SWAP", "local_receive_ts": "2026-06-20T18:23:03Z", "monotonic_ns": 1607339526908675, "raw": "{\"arg\":{\"channel\":\"books\",\"instId\":\"BTC-USDT-SWAP\"},\"action\":\"update\",\"data\":[{\"asks\":[[\"63813.7\",\"45.16\",\"0\",\"23\"],[\"63816.1\",\"0\",\"0\",\"0\"],[\"63816.8\",\"0.4\",\"0\",\"2\"],[\"63844.2\",\"70.01\",\"0\",\"2\"],[\"63844.4\",\"87.02\",\"0\",\"2\"],[\"63868\",\"1.52\",\"0\",\"2\"]],\"bids\":[],\"ts\":\"1781979783608\",\"checksum\":-664541771,\"seqId\":325026385241,\"prevSeqId\":325026385216}]}"}
{"action": null, "capture_sequence": 24, "channel": "trades", "connection_sequence": 1, "event": null, "instId": "BTC-USDT-SWAP", "local_receive_ts": "2026-06-20T18:23:03Z", "monotonic_ns": 1607339610511621, "raw": "{\"arg\":{\"channel\":\"trades\",\"instId\":\"BTC-USDT-SWAP\"},\"data\":[{\"instId\":\"BTC-USDT-SWAP\",\"tradeId\":\"2718372441\",\"px\":\"63813.7\",\"sz\":\"0.14\",\"side\":\"buy\",\"ts\":\"1781979783691\",\"count\":\"1\",\"source\":\"0\",\"seqId\":325026385336}]}"}
{"action": "update", "capture_sequence": 25, "channel": "books", "connection_sequence": 1, "event": null, "instId": "BTC-USDT-SWAP", "local_receive_ts": "2026-06-20T18:23:03Z", "monotonic_ns": 1607339627316502, "raw": "{\"arg\":{\"channel\":\"books\",\"instId\":\"BTC-USDT-SWAP\"},\"action\":\"update\",\"data\":[{\"asks\":[[\"63813.7\",\"44.92\",\"0\",\"21\"],[\"63816\",\"3.48\",\"0\",\"3\"],[\"63816.6\",\"0.08\",\"0\",\"4\"],[\"63818.4\",\"0.79\",\"0\",\"2\"],[\"63819.1\",\"0.03\",\"0\",\"1\"],[\"63836.9\",\"0.02\",\"0\",\"2\"],[\"63837.1\",\"160.05\",\"0\",\"6\"],[\"63838.7\",\"0.01\",\"0\",\"1\"],[\"63838.9\",\"0.5\",\"0\",\"1\"],[\"63839.1\",\"58.84\",\"0\",\"4\"],[\"63839.2\",\"15.91\",\"0\",\"4\"],[\"63841.5\",\"0.01\",\"0\",\"1\"],[\"63841.6\",\"36.15\",\"0\",\"2\"],[\"63843.3\",\"0.05\",\"0\",\"4\"],[\"63843.8\",\"5.34\",\"0\",\"3\"]],\"bids\":[[\"63798.6\",\"34.17\",\"0\",\"1\"],[\"63798.4\",\"0.01\",\"0\",\"1\"],[\"63792.4\",\"0\",\"0\",\"0\"],[\"63791.8\",\"20.33\",\"0\",\"5\"],[\"63791.5\",\"0.01\",\"0\",\"1\"],[\"63791.4\",\"58.87\",\"0\",\"3\"],[\"63791.1\",\"0.22\",\"0\",\"4\"],[\"63791\",\"86.32\",\"0\",\"3\"],[\"63761.5\",\"235.06\",\"0\",\"1\"],[\"63760.9\",\"0.01\",\"0\",\"1\"],[\"63760.8\",\"0\",\"0\",\"0\"]],\"ts\":\"1781979783708\",\"checksum\":-820647195,\"seqId\":325026385355,\"prevSeqId\":325026385241}]}"}
{"action": "update", "capture_sequence": 26, "channel": "books", "connection_sequence": 1, "event": null, "instId": "BTC-USDT-SWAP", "local_receive_ts": "2026-06-20T18:23:03Z", "monotonic_ns": 1607339727267141, "raw": "{\"arg\":{\"channel\":\"books\",\"instId\":\"BTC-USDT-SWAP\"},\"action\":\"update\",\"data\":[{\"asks\":[[\"63830.9\",\"0.32\",\"0\",\"2\"],[\"63831.1\",\"0\",\"0\",\"0\"],[\"63835.8\",\"86.24\",\"0\",\"2\"],[\"63836.1\",\"0.01\",\"0\",\"1\"],[\"63836.9\",\"34.17\",\"0\",\"3\"],[\"63837.1\",\"125.9\",\"0\",\"5\"],[\"63839.4\",\"0.78\",\"0\",\"1\"],[\"63839.7\",\"0.03\",\"0\",\"1\"],[\"63841.5\",\"20.29\",\"0\",\"2\"],[\"63841.6\",\"15.87\",\"0\",\"1\"]],\"bids\":[[\"63801.3\",\"393.65\",\"0\",\"1\"],[\"63800.8\",\"1.09\",\"0\",\"3\"],[\"63799\",\"2.61\",\"0\",\"2\"],[\"63798.6\",\"0.31\",\"0\",\"1\"],[\"63798.4\",\"34.18\",\"0\",\"2\"],[\"63791.8\",\"0.04\",\"0\",\"4\"],[\"63791.5\",\"20.3\",\"0\",\"2\"],[\"63791\",\"0.02\",\"0\",\"2\"],[\"63790.9\",\"86.44\",\"0\",\"3\"]],\"ts\":\"1781979783808\",\"checksum\":-820647195,\"seqId\":325026385392,\"prevSeqId\":325026385355}]}"}
{"action": "update", "capture_sequence": 27, "channel": "books", "connection_sequence": 1, "event": null, "instId": "BTC-USDT-SWAP", "local_receive_ts": "2026-06-20T18:23:04Z", "monotonic_ns": 1607339827413869, "raw": "{\"arg\":{\"channel\":\"books\",\"instId\":\"BTC-USDT-SWAP\"},\"action\":\"update\",\"data\":[{\"asks\":[[\"63819.5\",\"0.01\",\"0\",\"1\"]],\"bids\":[],\"ts\":\"1781979783908\",\"checksum\":-820647195,\"seqId\":325026385407,\"prevSeqId\":325026385392}]}"}
{"action": "update", "capture_sequence": 28, "channel": "books", "connection_sequence": 1, "event": null, "instId": "BTC-USDT-SWAP", "local_receive_ts": "2026-06-20T18:23:04Z", "monotonic_ns": 1607339927469931, "raw": "{\"arg\":{\"channel\":\"books\",\"instId\":\"BTC-USDT-SWAP\"},\"action\":\"update\",\"data\":[{\"asks\":[[\"63830.9\",\"0.01\",\"0\",\"1\"],[\"63831.1\",\"0.31\",\"0\",\"1\"],[\"63834.2\",\"31.36\",\"0\",\"4\"],[\"63834.3\",\"15.87\",\"0\",\"1\"],[\"63835.8\",\"0.01\",\"0\",\"1\"],[\"63836.1\",\"86.24\",\"0\",\"2\"],[\"63836.9\",\"0.02\",\"0\",\"2\"],[\"63837\",\"210.89\",\"0\",\"2\"],[\"63868\",\"0\",\"0\",\"0\"]],\"bids\":[[\"63800.2\",\"31.37\",\"0\",\"1\"],[\"63800.1\",\"70.79\",\"0\",\"3\"],[\"63799.1\",\"235.33\",\"0\",\"1\"],[\"63799\",\"2.92\",\"0\",\"3\"],[\"63798.9\",\"0.02\",\"0\",\"1\"],[\"63798.6\",\"34.17\",\"0\",\"1\"],[\"63798.4\",\"0.01\",\"0\",\"1\"],[\"63791.6\",\"59.13\",\"0\",\"2\"],[\"63791.4\",\"0.03\",\"0\",\"2\"],[\"63791\",\"0.01\",\"0\",\"1\"],[\"63790.8\",\"2.2\",\"0\",\"5\"],[\"63761\",\"0\",\"0\",\"0\"],[\"63760.9\",\"0\",\"0\",\"0\"]],\"ts\":\"1781979784008\",\"checksum\":-820647195,\"seqId\":325026385431,\"prevSeqId\":325026385407}]}"}
{"action": "update", "capture_sequence": 29, "channel": "books", "connection_sequence": 1, "event": null, "instId": "BTC-USDT-SWAP", "local_receive_ts": "2026-06-20T18:23:04Z", "monotonic_ns": 1607340027301060, "raw": "{\"arg\":{\"channel\":\"books\",\"instId\":\"BTC-USDT-SWAP\"},\"action\":\"update\",\"data\":[{\"asks\":[[\"63813.7\",\"44.97\",\"0\",\"22\"],[\"63813.9\",\"0.05\",\"0\",\"1\"],[\"63816\",\"3.43\",\"0\",\"2\"],[\"63816.6\",\"0.03\",\"0\",\"3\"],[\"63826.8\",\"0\",\"0\",\"0\"],[\"63831.2\",\"62.74\",\"0\",\"1\"],[\"63839.4\",\"0\",\"0\",\"0\"],[\"63839.7\",\"0.81\",\"0\",\"2\"],[\"63868\",\"1.52\",\"0\",\"2\"]],\"bids\":[[\"63813.6\",\"1235.64\",\"0\",\"78\"],[\"63801.3\",\"394.43\",\"0\",\"2\"],[\"63800.8\",\"0.31\",\"0\",\"2\"],[\"63799.7\",\"62.74\",\"0\",\"1\"],[\"63799\",\"0.01\",\"0\",\"1\"],[\"63798.9\",\"0.33\",\"0\",\"2\"]],\"ts\":\"1781979784108\",\"checksum\":-1630636119,\"seqId\":325026385450,\"prevSeqId\":325026385431}]}"}
{"action": "update", "capture_sequence": 30, "channel": "books", "connection_sequence": 1, "event": null, "instId": "BTC-USDT-SWAP", "local_receive_ts": "2026-06-20T18:23:04Z", "monotonic_ns": 1607340127185808, "raw": "{\"arg\":{\"channel\":\"books\",\"instId\":\"BTC-USDT-SWAP\"},\"action\":\"update\",\"data\":[{\"asks\":[[\"63813.7\",\"45.02\",\"0\",\"23\"],[\"63826.8\",\"3.23\",\"0\",\"1\"],[\"63828.4\",\"0\",\"0\",\"0\"],[\"63831.2\",\"62.89\",\"0\",\"2\"],[\"63843.3\",\"0.03\",\"0\",\"3\"],[\"63843.8\",\"5.36\",\"0\",\"4\"]],\"bids\":[[\"63813.6\",\"1235.66\",\"0\",\"78\"],[\"63799.6\",\"0.2\",\"0\",\"2\"],[\"63799\",\"2.58\",\"0\",\"2\"],[\"63791.6\",\"0.29\",\"0\",\"1\"],[\"63791.4\",\"58.87\",\"0\",\"3\"]],\"ts\":\"1781979784208\",\"checksum\":1737727615,\"seqId\":325026385488,\"prevSeqId\":325026385450}]}"}
{"action": "update", "capture_sequence": 31, "channel": "books", "connection_sequence": 1, "event": null, "instId": "BTC-USDT-SWAP", "local_receive_ts": "2026-06-20T18:23:04Z", "monotonic_ns": 1607340227858232, "raw": "{\"arg\":{\"channel\":\"books\",\"instId\":\"BTC-USDT-SWAP\"},\"action\":\"update\",\"data\":[{\"asks\":[[\"63813.7\",\"11.83\",\"0\",\"22\"],[\"63820\",\"0.62\",\"0\",\"3\"],[\"63834.2\",\"0.02\",\"0\",\"2\"],[\"63834.3\",\"47.21\",\"0\",\"3\"],[\"63836.1\",\"0.01\",\"0\",\"1\"],[\"63836.3\",\"117.6\",\"0\",\"2\"],[\"63837\",\"176.74\",\"0\",\"1\"],[\"63837.5\",\"269.81\",\"0\",\"4\"],[\"63839.1\",\"0.05\",\"0\",\"3\"],[\"63839.5\",\"61.73\",\"0\",\"2\"],[\"63839.7\",\"0.03\",\"0\",\"1\"],[\"63839.8\",\"11.46\",\"0\",\"2\"],[\"63841.5\",\"0.01\",\"0\",\"1\"],[\"63842\",\"37.17\",\"0\",\"5\"],[\"63854.1\",\"124.58\",\"0\",\"4\"],[\"63854.7\",\"0.01\",\"0\",\"1\"],[\"63868\",\"0\",\"0\",\"0\"]],\"bids\":[[\"63813.6\",\"1235\",\"0\",\"77\"],[\"63802.8\",\"0.31\",\"0\",\"2\"],[\"63801.4\",\"0.79\",\"0\",\"2\"],[\"63801.3\",\"393.65\",\"0\",\"1\"],[\"63799.1\",\"269.5\",\"0\",\"2\"],[\"63798.6\",\"0\",\"0\",\"0\"],[\"63792.1\",\"20.31\",\"0\",\"3\"],[\"63792\",\"58.96\",\"0\",\"7\"],[\"63791.5\",\"0.01\",\"0\",\"1\"],[\"63791.4\",\"86.32\",\"0\",\"3\"],[\"63790.9\",\"0.14\",\"0\",\"2\"],[\"63761\",\"0.1\",\"0\",\"1\"]],\"ts\":\"1781979784308\",\"checksum\":-296913316,\"seqId\":325026385524,\"prevSeqId\":325026385488}]}"}
{"action": "update", "capture_sequence": 32, "channel": "books", "connection_sequence": 1, "event": null, "instId": "BTC-USDT-SWAP", "local_receive_ts": "2026-06-20T18:23:04Z", "monotonic_ns": 1607340327416292, "raw": "{\"arg\":{\"channel\":\"books\",\"instId\":\"BTC-USDT-SWAP\"},\"action\":\"update\",\"data\":[{\"asks\":[[\"63819.5\",\"1.58\",\"0\",\"2\"],[\"63820\",\"2.19\",\"0\",\"4\"],[\"63828.6\",\"0.01\",\"0\",\"1\"],[\"63831.1\",\"0\",\"0\",\"0\"],[\"63831.6\",\"0.32\",\"0\",\"2\"],[\"63837.2\",\"50.02\",\"0\",\"2\"],[\"63837.5\",\"235.66\",\"0\",\"3\"],[\"63839.2\",\"74.68\",\"0\",\"4\"],[\"63839.5\",\"2.94\",\"0\",\"1\"],[\"63839.6\",\"54.68\",\"0\",\"4\"],[\"63839.8\",\"10.68\",\"0\",\"1\"],[\"63840\",\"17.46\",\"0\",\"21\"],[\"63841.9\",\"20.28\",\"0\",\"1\"],[\"63842\",\"16.89\",\"0\",\"4\"],[\"63854.7\",\"0\",\"0\",\"0\"],[\"63860.2\",\"250.47\",\"0\",\"5\"],[\"63863.8\",\"0\",\"0\",\"0\"],[\"63868\",\"1.52\",\"0\",\"2\"]],\"bids\":[[\"63799.2\",\"0.31\",\"0\",\"1\"],[\"63799.1\",\"0\",\"0\",\"0\"],[\"63798.9\",\"235.35\",\"0\",\"2\"],[\"63798.6\",\"34.17\",\"0\",\"1\"],[\"63797\",\"0.31\",\"0\",\"2\"],[\"63792.1\",\"0.02\",\"0\",\"2\"],[\"63792\",\"0.12\",\"0\",\"6\"],[\"63791.9\",\"94.87\",\"0\",\"4\"],[\"63791.5\",\"58.85\",\"0\",\"2\"],[\"63761\",\"0\",\"0\",\"0\"]],\"ts\":\"1781979784408\",\"checksum\":-296913316,\"seqId\":325026385571,\"prevSeqId\":325026385524}]}"}
{"action": "update", "capture_sequence": 33, "channel": "books", "connection_sequence": 1, "event": null, "instId": "BTC-USDT-SWAP", "local_receive_ts": "2026-06-20T18:23:04Z", "monotonic_ns": 1607340432522847, "raw": "{\"arg\":{\"channel\":\"books\",\"instId\":\"BTC-USDT-SWAP\"},\"action\":\"update\",\"data\":[{\"asks\":[[\"63817.7\",\"7.18\",\"0\",\"3\"],[\"63817.8\",\"62.45\",\"0\",\"1\"],[\"63818.8\",\"65.54\",\"0\",\"3\"],[\"63819\",\"1.57\",\"0\",\"1\"],[\"63820.2\",\"12.86\",\"0\",\"4\"],[\"63820.5\",\"8.3\",\"0\",\"2\"],[\"63820.7\",\"0\",\"0\",\"0\"],[\"63823.1\",\"0\",\"0\",\"0\"],[\"63830.3\",\"0.01\",\"0\",\"1\"],[\"63830.4\",\"0.31\",\"0\",\"2\"],[\"63831.1\",\"0.31\",\"0\",\"1\"],[\"63831.6\",\"0.01\",\"0\",\"1\"],[\"63834\",\"86.45\",\"0\",\"6\"],[\"63834.3\",\"15.87\",\"0\",\"1\"],[\"63836\",\"31.36\",\"0\",\"2\"],[\"63836.1\",\"86.24\",\"0\",\"2\"],[\"63836.2\",\"0.01\",\"0\",\"1\"],[\"63836.3\",\"31.37\",\"0\",\"1\"],[\"63836.7\",\"111.03\",\"0\",\"3\"],[\"63837.1\",\"361.09\",\"0\",\"6\"],[\"63837.2\",\"15.87\",\"0\",\"1\"],[\"63837.5\",\"0.47\",\"0\",\"2\"],[\"63838.7\",\"58.8\",\"0\",\"2\"],[\"63839.2\",\"15.89\",\"0\",\"3\"],[\"63839.7\",\"0.81\",\"0\",\"2\"],[\"63840\",\"16.68\",\"0\",\"20\"],[\"63841.5\",\"20.29\",\"0\",\"2\"],[\"63841.9\",\"0\",\"0\",\"0\"],[\"63842.6\",\"87.02\",\"0\",\"2\"],[\"63844.4\",\"0.01\",\"0\",\"1\"],[\"63854.1\",\"124.57\",\"0\",\"3\"],[\"63868.1\",\"0.09\",\"0\",\"1\"]],\"bids\":[[\"63810.4\",\"11.62\",\"0\",\"6\"],[\"63807.8\",\"12\",\"0\",\"2\"],[\"63807.5\",\"0.05\",\"0\",\"1\"],[\"63806.7\",\"100.01\",\"0\",\"2\"],[\"63802.1\",\"0\",\"0\",\"0\"],[\"63801.9\",\"39.26\",\"0\",\"3\"],[\"63801.7\",\"15.75\",\"0\",\"3\"],[\"63801.4\",\"0.01\",\"0\",\"1\"],[\"63801.3\",\"394.43\",\"0\",\"2\"],[\"63800.2\",\"0\",\"0\",\"0\"],[\"63800.1\",\"102.16\",\"0\",\"4\"],[\"63799.2\",\"0\",\"0\",\"0\"],[\"63799.1\",\"0.31\",\"0\",\"1\"],[\"63798.9\",\"0.02\",\"0\",\"1\"],[\"63798.6\",\"235.33\",\"0\",\"1\"],[\"63798.1\",\"34.17\",\"0\",\"1\"],[\"63797\",\"0.01\",\"0\",\"1\"],[\"63796.9\",\"0.3\",\"0\",\"1\"],[\"63791.9\",\"74.58\",\"0\",\"3\"],[\"63791.5\",\"20.3\",\"0\",\"2\"],[\"63791.4\",\"0.03\",\"0\",\"2\"],[\"63791\",\"58.85\",\"0\",\"2\"],[\"63790.9\",\"86.44\",\"0\",\"3\"],[\"63761.2\",\"0\",\"0\",\"0\"]],\"ts\":\"1781979784508\",\"checksum\":1570586764,\"seqId\":325026385676,\"prevSeqId\":325026385571}]}"}
{"action": "update", "capture_sequence": 34, "channel": "books", "connection_sequence": 1, "event": null, "instId": "BTC-USDT-SWAP", "local_receive_ts": "2026-06-20T18:23:04Z", "monotonic_ns": 1607340527253339, "raw": "{\"arg\":{\"channel\":\"books\",\"instId\":\"BTC-USDT-SWAP\"},\"action\":\"update\",\"data\":[{\"asks\":[[\"63813.7\",\"25.29\",\"0\",\"24\"],[\"63819\",\"0\",\"0\",\"0\"],[\"63819.5\",\"0.01\",\"0\",\"1\"],[\"63820.8\",\"0\",\"0\",\"0\"],[\"63823.1\",\"1.57\",\"0\",\"1\"],[\"63834\",\"55.11\",\"0\",\"4\"],[\"63834.2\",\"31.36\",\"0\",\"4\"],[\"63835.8\",\"86.25\",\"0\",\"2\"],[\"63836\",\"0.01\",\"0\",\"1\"],[\"63836.1\",\"0.01\",\"0\",\"1\"],[\"63836.2\",\"31.36\",\"0\",\"2\"],[\"63836.7\",\"76.88\",\"0\",\"2\"],[\"63837.1\",\"125.9\",\"0\",\"5\"],[\"63837.2\",\"50.02\",\"0\",\"2\"],[\"63837.5\",\"235.66\",\"0\",\"3\"],[\"63838.4\",\"90.53\",\"0\",\"3\"],[\"63838.7\",\"0.01\",\"0\",\"1\"],[\"63841.3\",\"21.61\",\"0\",\"3\"],[\"63841.5\",\"0.01\",\"0\",\"1\"],[\"63868.2\",\"0.05\",\"0\",\"3\"]],\"bids\":[[\"63802.1\",\"15.67\",\"0\",\"1\"],[\"63801.7\",\"0.08\",\"0\",\"2\"],[\"63800.2\",\"31.37\",\"0\",\"1\"],[\"63800.1\",\"70.79\",\"0\",\"3\"],[\"63798.9\",\"235.35\",\"0\",\"2\"],[\"63798.7\",\"34.17\",\"0\",\"1\"],[\"63798.6\",\"0\",\"0\",\"0\"],[\"63798.1\",\"0\",\"0\",\"0\"],[\"63791.5\",\"0.01\",\"0\",\"1\"],[\"63791.4\",\"20.32\",\"0\",\"3\"],[\"63791\",\"0.01\",\"0\",\"1\"],[\"63790.9\",\"145.28\",\"0\",\"4\"],[\"63761.3\",\"0\",\"0\",\"0\"]],\"ts\":\"1781979784608\",\"checksum\":197853322,\"seqId\":325026385757,\"prevSeqId\":325026385676}]}"}
{"action": "update", "capture_sequence": 35, "channel": "books", "connection_sequence": 1, "event": null, "instId": "BTC-USDT-SWAP", "local_receive_ts": "2026-06-20T18:23:04Z", "monotonic_ns": 1607340627058784, "raw": "{\"arg\":{\"channel\":\"books\",\"instId\":\"BTC-USDT-SWAP\"},\"action\":\"update\",\"data\":[{\"asks\":[[\"63813.7\",\"25.12\",\"0\",\"22\"],[\"63813.9\",\"0\",\"0\",\"0\"],[\"63815.8\",\"0.45\",\"0\",\"3\"],[\"63816.4\",\"0.06\",\"0\",\"2\"],[\"63826.8\",\"0\",\"0\",\"0\"],[\"63831.2\",\"62.74\",\"0\",\"1\"],[\"63842.6\",\"0.01\",\"0\",\"1\"],[\"63844.4\",\"87.02\",\"0\",\"2\"],[\"63868.4\",\"0.01\",\"0\",\"1\"],[\"63868.6\",\"0.01\",\"0\",\"1\"]],\"bids\":[[\"63813.6\",\"1234\",\"0\",\"76\"],[\"63799.6\",\"0.01\",\"0\",\"1\"],[\"63799\",\"0.01\",\"0\",\"1\"]],\"ts\":\"1781979784708\",\"checksum\":248384562,\"seqId\":325026385770,\"prevSeqId\":325026385757}]}"}
{"action": "update", "capture_sequence": 36, "channel": "books", "connection_sequence": 1, "event": null, "instId": "BTC-USDT-SWAP", "local_receive_ts": "2026-06-20T18:23:04Z", "monotonic_ns": 1607340727205389, "raw": "{\"arg\":{\"channel\":\"books\",\"instId\":\"BTC-USDT-SWAP\"},\"action\":\"update\",\"data\":[{\"asks\":[[\"63818.3\",\"11.68\",\"0\",\"7\"],[\"63819.3\",\"2.84\",\"0\",\"3\"],[\"63823.6\",\"1.58\",\"0\",\"2\"],[\"63826.8\",\"3.23\",\"0\",\"1\"],[\"63831.2\",\"62.89\",\"0\",\"2\"],[\"63839.5\",\"3.72\",\"0\",\"2\"],[\"63839.7\",\"0.03\",\"0\",\"1\"],[\"63868.6\",\"0\",\"0\",\"0\"]],\"bids\":[[\"63801.3\",\"393.65\",\"0\",\"1\"],[\"63800.8\",\"1.09\",\"0\",\"3\"],[\"63799.7\",\"62.93\",\"0\",\"2\"],[\"63799\",\"2.58\",\"0\",\"2\"]],\"ts\":\"1781979784808\",\"checksum\":248384562,\"seqId\":325026385781,\"prevSeqId\":325026385770}]}"}
{"action": "update", "capture_sequence": 37, "channel": "books", "connection_sequence": 1, "event": null, "instId": "BTC-USDT-SWAP", "local_receive_ts": "2026-06-20T18:23:05Z", "monotonic_ns": 1607340827956042, "raw": "{\"arg\":{\"channel\":\"books\",\"instId\":\"BTC-USDT-SWAP\"},\"action\":\"update\",\"data\":[{\"asks\":[[\"63813.7\",\"104.12\",\"0\",\"25\"],[\"63817.5\",\"1.58\",\"0\",\"2\"],[\"63818.4\",\"2.36\",\"0\",\"3\"],[\"63823.6\",\"0.01\",\"0\",\"1\"],[\"63833.8\",\"26.16\",\"0\",\"2\"],[\"63834.2\",\"15.7\",\"0\",\"3\"],[\"63834.7\",\"86.24\",\"0\",\"1\"],[\"63835.8\",\"34.16\",\"0\",\"2\"],[\"63837.2\",\"15.87\",\"0\",\"1\"],[\"63837.5\",\"294.45\",\"0\",\"4\"],[\"63838.4\",\"31.74\",\"0\",\"2\"],[\"63840.7\",\"20.29\",\"0\",\"2\"],[\"63841.3\",\"1.33\",\"0\",\"2\"],[\"63842.6\",\"87.02\",\"0\",\"2\"],[\"63844.4\",\"0.01\",\"0\",\"1\"],[\"63868.4\",\"0\",\"0\",\"0\"]],\"bids\":[[\"63802.1\",\"0\",\"0\",\"0\"],[\"63801.7\",\"15.75\",\"0\",\"3\"],[\"63800.2\",\"0\",\"0\",\"0\"],[\"63800\",\"94.15\",\"0\",\"30\"],[\"63798.7\",\"0\",\"0\",\"0\"],[\"63797.4\",\"239.72\",\"0\",\"2\"],[\"63794.5\",\"0\",\"0\",\"0\"],[\"63792.9\",\"134.13\",\"0\",\"2\"],[\"63791.4\",\"0.03\",\"0\",\"2\"],[\"63790.9\",\"0.14\",\"0\",\"2\"],[\"63790.2\",\"79.13\",\"0\",\"2\"],[\"63789.8\",\"86.31\",\"0\",\"2\"],[\"63771.8\",\"18.95\",\"0\",\"1\"],[\"63761.3\",\"0.01\",\"0\",\"1\"],[\"63761.2\",\"0.02\",\"0\",\"1\"],[\"63761\",\"0.1\",\"0\",\"1\"]],\"ts\":\"1781979784908\",\"checksum\":1566013570,\"seqId\":325026385833,\"prevSeqId\":325026385781}]}"}
{"action": "update", "capture_sequence": 38, "channel": "books", "connection_sequence": 1, "event": null, "instId": "BTC-USDT-SWAP", "local_receive_ts": "2026-06-20T18:23:05Z", "monotonic_ns": 1607340927686969, "raw": "{\"arg\":{\"channel\":\"books\",\"instId\":\"BTC-USDT-SWAP\"},\"action\":\"update\",\"data\":[{\"asks\":[[\"63817.3\",\"1.57\",\"0\",\"1\"],[\"63817.5\",\"0.01\",\"0\",\"1\"],[\"63819\",\"1.57\",\"0\",\"1\"],[\"63819.3\",\"1.27\",\"0\",\"2\"],[\"63819.5\",\"1.58\",\"0\",\"2\"],[\"63823.1\",\"0\",\"0\",\"0\"],[\"63830.4\",\"0.62\",\"0\",\"3\"],[\"63831.1\",\"0\",\"0\",\"0\"],[\"63833.7\",\"31.56\",\"0\",\"3\"],[\"63834.2\",\"0.02\",\"0\",\"2\"],[\"63834.7\",\"0\",\"0\",\"0\"],[\"63835.1\",\"87.43\",\"0\",\"3\"],[\"63835.7\",\"31.36\",\"0\",\"1\"],[\"63835.8\",\"0.01\",\"0\",\"1\"],[\"63836.2\",\"0.01\",\"0\",\"1\"],[\"63836.3\",\"65.52\",\"0\",\"2\"],[\"63836.9\",\"0.04\",\"0\",\"3\"],[\"63837.1\",\"125.88\",\"0\",\"4\"],[\"63837.5\",\"235.66\",\"0\",\"3\"],[\"63838.3\",\"58.81\",\"0\",\"3\"],[\"63838.5\",\"59.58\",\"0\",\"4\"],[\"63839.1\",\"0.83\",\"0\",\"4\"],[\"63839.5\",\"2.94\",\"0\",\"1\"],[\"63839.6\",\"54.66\",\"0\",\"3\"],[\"63840.7\",\"0.01\",\"0\",\"1\"],[\"63840.8\",\"60.93\",\"0\",\"4\"],[\"63842.8\",\"62.69\",\"0\",\"2\"],[\"63843.8\",\"5.34\",\"0\",\"3\"]],\"bids\":[[\"63800.8\",\"0.31\",\"0\",\"2\"],[\"63800.5\",\"168.28\",\"0\",\"4\"],[\"63800\",\"62.78\",\"0\",\"29\"],[\"63799.8\",\"31.37\",\"0\",\"1\"],[\"63799.1\",\"0\",\"0\",\"0\"],[\"63798.4\",\"0.32\",\"0\",\"2\"],[\"63797.6\",\"34.17\",\"0\",\"1\"],[\"63797.4\",\"205.55\",\"0\",\"1\"],[\"63791\",\"20.3\",\"0\",\"2\"],[\"63790.4\",\"58.85\",\"0\",\"2\"],[\"63790.3\",\"86.3\",\"0\",\"1\"],[\"63790.2\",\"0\",\"0\",\"0\"],[\"63789.8\",\"0.01\",\"0\",\"1\"],[\"63761\",\"0\",\"0\",\"0\"]],\"ts\":\"1781979785008\",\"checksum\":-1402903467,\"seqId\":325026385884,\"prevSeqId\":325026385833}]}"}
{"action": "update", "capture_sequence": 39, "channel": "books", "connection_sequence": 1, "event": null, "instId": "BTC-USDT-SWAP", "local_receive_ts": "2026-06-20T18:23:05Z", "monotonic_ns": 1607341030537782, "raw": "{\"arg\":{\"channel\":\"books\",\"instId\":\"BTC-USDT-SWAP\"},\"action\":\"update\",\"data\":[{\"asks\":[[\"63815.2\",\"0.01\",\"0\",\"1\"],[\"63815.8\",\"0.46\",\"0\",\"4\"],[\"63816.8\",\"1.97\",\"0\",\"3\"],[\"63822.6\",\"22.93\",\"0\",\"2\"],[\"63833.7\",\"15.88\",\"0\",\"2\"],[\"63833.9\",\"215.7\",\"0\",\"4\"],[\"63835.1\",\"1.19\",\"0\",\"2\"],[\"63835.6\",\"86.24\",\"0\",\"1\"],[\"63840.8\",\"40.65\",\"0\",\"3\"],[\"63841.2\",\"20.28\",\"0\",\"1\"],[\"63868\",\"0\",\"0\",\"0\"],[\"63868.1\",\"0\",\"0\",\"0\"],[\"63868.2\",\"0\",\"0\",\"0\"]],\"bids\":[[\"63813.6\",\"1233.65\",\"0\",\"75\"],[\"63790.7\",\"447.43\",\"0\",\"2\"],[\"63790.3\",\"0\",\"0\",\"0\"],[\"63775.3\",\"75.48\",\"0\",\"4\"],[\"63762.5\",\"62.83\",\"0\",\"3\"],[\"63761\",\"0.1\",\"0\",\"1\"]],\"ts\":\"1781979785108\",\"checksum\":-380828469,\"seqId\":325026385904,\"prevSeqId\":325026385884}]}"}
{"action": "update", "capture_sequence": 40, "channel": "books", "connection_sequence": 1, "event": null, "instId": "BTC-USDT-SWAP", "local_receive_ts": "2026-06-20T18:23:05Z", "monotonic_ns": 1607341127061178, "raw": "{\"arg\":{\"channel\":\"books\",\"instId\":\"BTC-USDT-SWAP\"},\"action\":\"update\",\"data\":[{\"asks\":[[\"63813.7\",\"104.11\",\"0\",\"25\"],[\"63816.8\",\"0.4\",\"0\",\"2\"],[\"63817.3\",\"0\",\"0\",\"0\"],[\"63817.6\",\"1.57\",\"0\",\"1\"],[\"63826.8\",\"0\",\"0\",\"0\"],[\"63831.2\",\"62.74\",\"0\",\"1\"],[\"63835.7\",\"0\",\"0\",\"0\"],[\"63836.2\",\"31.36\",\"0\",\"2\"],[\"63838.5\",\"59.56\",\"0\",\"3\"],[\"63838.6\",\"0.02\",\"0\",\"1\"],[\"63853.2\",\"0\",\"0\",\"0\"],[\"63853.8\",\"0.04\",\"0\",\"3\"],[\"63868\",\"1.52\",\"0\",\"2\"],[\"63868.1\",\"0.09\",\"0\",\"1\"]],\"bids\":[[\"63813.6\",\"1234.01\",\"0\",\"76\"],[\"63800\",\"94.15\",\"0\",\"30\"],[\"63799.8\",\"0\",\"0\",\"0\"],[\"63799.7\",\"62.74\",\"0\",\"1\"],[\"63799\",\"0.01\",\"0\",\"1\"],[\"63794.5\",\"87.08\",\"0\",\"1\"],[\"63792.9\",\"47.05\",\"0\",\"1\"]],\"ts\":\"1781979785208\",\"checksum\":1274113029,\"seqId\":325026385933,\"prevSeqId\":325026385904}]}"}
{"action": "update", "capture_sequence": 41, "channel": "books", "connection_sequence": 1, "event": null, "instId": "BTC-USDT-SWAP", "local_receive_ts": "2026-06-20T18:23:05Z", "monotonic_ns": 1607341227277311, "raw": "{\"arg\":{\"channel\":\"books\",\"instId\":\"BTC-USDT-SWAP\"},\"action\":\"update\",\"data\":[{\"asks\":[[\"63820.7\",\"78.51\",\"0\",\"2\"],[\"63821.6\",\"0.01\",\"0\",\"1\"],[\"63825.4\",\"0.01\",\"0\",\"1\"],[\"63826.8\",\"3.25\",\"0\",\"1\"],[\"63831.2\",\"62.89\",\"0\",\"2\"],[\"63832.7\",\"1.87\",\"0\",\"2\"],[\"63833.9\",\"200.02\",\"0\",\"3\"],[\"63834.2\",\"15.7\",\"0\",\"3\"],[\"63867.6\",\"10.83\",\"0\",\"3\"],[\"63867.7\",\"0\",\"0\",\"0\"],[\"63868\",\"0\",\"0\",\"0\"],[\"63868.1\",\"0\",\"0\",\"0\"]],\"bids\":[[\"63813.6\",\"1234.71\",\"0\",\"77\"],[\"63813.4\",\"0.01\",\"0\",\"1\"],[\"63813.3\",\"1.89\",\"0\",\"4\"],[\"63813.2\",\"31.38\",\"0\",\"2\"],[\"63813.1\",\"190.55\",\"0\",\"4\"],[\"63799.7\",\"62.94\",\"0\",\"2\"],[\"63799\",\"2.59\",\"0\",\"2\"],[\"63798.4\",\"0.01\",\"0\",\"1\"],[\"63797.7\",\"0.32\",\"0\",\"2\"],[\"63761\",\"0\",\"0\",\"0\"]],\"ts\":\"1781979785308\",\"checksum\":612039822,\"seqId\":325026385983,\"prevSeqId\":325026385933}]}"}
{"action": "update", "capture_sequence": 42, "channel": "books", "connection_sequence": 1, "event": null, "instId": "BTC-USDT-SWAP", "local_receive_ts": "2026-06-20T18:23:05Z", "monotonic_ns": 1607341333847104, "raw": "{\"arg\":{\"channel\":\"books\",\"instId\":\"BTC-USDT-SWAP\"},\"action\":\"update\",\"data\":[{\"asks\":[[\"63816.1\",\"14\",\"0\",\"1\"],[\"63816.5\",\"1.57\",\"0\",\"1\"],[\"63817.4\",\"1.58\",\"0\",\"2\"],[\"63817.6\",\"0\",\"0\",\"0\"],[\"63817.9\",\"1.57\",\"0\",\"1\"],[\"63818.4\",\"0.79\",\"0\",\"2\"],[\"63818.6\",\"2.17\",\"0\",\"2\"],[\"63818.8\",\"0.02\",\"0\",\"2\"],[\"63819\",\"0\",\"0\",\"0\"],[\"63819.1\",\"1.6\",\"0\",\"2\"],[\"63820.1\",\"10.81\",\"0\",\"1\"],[\"63820.2\",\"0.32\",\"0\",\"2\"],[\"63820.4\",\"0.02\",\"0\",\"2\"],[\"63820.5\",\"27.11\",\"0\",\"5\"],[\"63820.6\",\"74.31\",\"0\",\"1\"],[\"63822.2\",\"0.01\",\"0\",\"1\"],[\"63824.2\",\"129.28\",\"0\",\"4\"],[\"63825.5\",\"10.28\",\"0\",\"2\"],[\"63825.9\",\"31.38\",\"0\",\"3\"],[\"63827.5\",\"0.03\",\"0\",\"2\"],[\"63827.9\",\"55.87\",\"0\",\"5\"],[\"63835.1\",\"87.43\",\"0\",\"3\"],[\"63835.6\",\"0\",\"0\",\"0\"],[\"63836.9\",\"0.06\",\"0\",\"4\"],[\"63837.1\",\"125.86\",\"0\",\"3\"],[\"63838.1\",\"0.04\",\"0\",\"3\"],[\"63838.6\",\"0\",\"0\",\"0\"],[\"63840.5\",\"0.03\",\"0\",\"2\"],[\"63841\",\"195.22\",\"0\",\"3\"],[\"63842.7\",\"150.39\",\"0\",\"2\"],[\"63842.8\",\"62.67\",\"0\",\"1\"],[\"63847.9\",\"46.98\",\"0\",\"1\"],[\"63849.2\",\"62.69\",\"0\",\"2\"],[\"63850\",\"8.11\",\"0\",\"55\"],[\"63857.6\",\"0\",\"0\",\"0\"],[\"63867.6\",\"0\",\"0\",\"0\"]],\"bids\":[[\"63813.6\",\"1163.11\",\"0\",\"76\"],[\"63812.9\",\"0\",\"0\",\"0\"],[\"63812.6\",\"0.02\",\"0\",\"2\"],[\"63809.4\",\"407.87\",\"0\",\"2\"],[\"63809.3\",\"75.39\",\"0\",\"4\"],[\"63809.2\",\"17.14\",\"0\",\"6\"],[\"63809.1\",\"1.2\",\"0\",\"1\"],[\"63804.3\",\"0.02\",\"0\",\"2\"],[\"63802.2\",\"0.01\",\"0\",\"1\"],[\"63801.9\",\"39.27\",\"0\",\"4\"],[\"63800.4\",\"10.62\",\"0\",\"1\"],[\"63798.8\",\"37.68\",\"0\",\"3\"],[\"63797.3\",\"408.01\",\"0\",\"2\"],[\"63797.2\",\"0.01\",\"0\",\"1\"],[\"63794.5\",\"0\",\"0\",\"0\"],[\"63792.9\",\"134.13\",\"0\",\"2\"],[\"63790.8\",\"2.19\",\"0\",\"4\"],[\"63790.7\",\"361.13\",\"0\",\"1\"],[\"63790.6\",\"62.68\",\"0\",\"2\"],[\"63790.2\",\"86.3\",\"0\",\"1\"],[\"63761.2\",\"0\",\"0\",\"0\"]],\"ts\":\"1781979785408\",\"checksum\":1113024511,\"seqId\":325026386126,\"prevSeqId\":325026385983}]}"}
{"action": "update", "capture_sequence": 43, "channel": "books", "connection_sequence": 1, "event": null, "instId": "BTC-USDT-SWAP", "local_receive_ts": "2026-06-20T18:23:05Z", "monotonic_ns": 1607341427167483, "raw": "{\"arg\":{\"channel\":\"books\",\"instId\":\"BTC-USDT-SWAP\"},\"action\":\"update\",\"data\":[{\"asks\":[[\"63813.7\",\"104.15\",\"0\",\"25\"],[\"63816.5\",\"0\",\"0\",\"0\"],[\"63816.6\",\"1.6\",\"0\",\"4\"],[\"63830\",\"0.32\",\"0\",\"2\"],[\"63830.4\",\"0.31\",\"0\",\"2\"],[\"63835.1\",\"1.19\",\"0\",\"2\"],[\"63835.4\",\"102.12\",\"0\",\"3\"],[\"63836.3\",\"31.37\",\"0\",\"1\"],[\"63836.6\",\"34.16\",\"0\",\"2\"],[\"63867.6\",\"10.85\",\"0\",\"5\"]],\"bids\":[[\"63813.6\",\"1163.21\",\"0\",\"77\"],[\"63798.1\",\"34.17\",\"0\",\"1\"],[\"63797.6\",\"0\",\"0\",\"0\"],[\"63791.2\",\"246.88\",\"0\",\"3\"],[\"63791\",\"0.01\",\"0\",\"1\"],[\"63790.7\",\"447.43\",\"0\",\"2\"],[\"63790.2\",\"0\",\"0\",\"0\"],[\"63761.2\",\"0.02\",\"0\",\"1\"]],\"ts\":\"1781979785508\",\"checksum\":1866500058,\"seqId\":325026386169,\"prevSeqId\":325026386126}]}"}
{"action": "update", "capture_sequence": 44, "channel": "books", "connection_sequence": 1, "event": null, "instId": "BTC-USDT-SWAP", "local_receive_ts": "2026-06-20T18:23:05Z", "monotonic_ns": 1607341526738103, "raw": "{\"arg\":{\"channel\":\"books\",\"instId\":\"BTC-USDT-SWAP\"},\"action\":\"update\",\"data\":[{\"asks\":[[\"63816.6\",\"0.03\",\"0\",\"3\"],[\"63816.8\",\"1.97\",\"0\",\"3\"],[\"63867.6\",\"10.82\",\"0\",\"2\"]],\"bids\":[[\"63794.5\",\"87.08\",\"0\",\"1\"],[\"63792.9\",\"47.05\",\"0\",\"1\"],[\"63761.2\",\"0\",\"0\",\"0\"]],\"ts\":\"1781979785608\",\"checksum\":-1752974029,\"seqId\":325026386179,\"prevSeqId\":325026386169}]}"}
{"action": null, "capture_sequence": 45, "channel": "trades", "connection_sequence": 1, "event": null, "instId": "BTC-USDT-SWAP", "local_receive_ts": "2026-06-20T18:23:05Z", "monotonic_ns": 1607341564173234, "raw": "{\"arg\":{\"channel\":\"trades\",\"instId\":\"BTC-USDT-SWAP\"},\"data\":[{\"instId\":\"BTC-USDT-SWAP\",\"tradeId\":\"2718372444\",\"px\":\"63813.7\",\"sz\":\"0.08\",\"side\":\"buy\",\"ts\":\"1781979785645\",\"count\":\"3\",\"source\":\"0\",\"seqId\":325026386185}]}"}
{"action": "update", "capture_sequence": 46, "channel": "books", "connection_sequence": 1, "event": null, "instId": "BTC-USDT-SWAP", "local_receive_ts": "2026-06-20T18:23:05Z", "monotonic_ns": 1607341626507193, "raw": "{\"arg\":{\"channel\":\"books\",\"instId\":\"BTC-USDT-SWAP\"},\"action\":\"update\",\"data\":[{\"asks\":[[\"63813.7\",\"104.08\",\"0\",\"24\"],[\"63814.6\",\"0.01\",\"0\",\"1\"],[\"63814.7\",\"0.41\",\"0\",\"3\"],[\"63816.8\",\"0.4\",\"0\",\"2\"],[\"63817.4\",\"0.01\",\"0\",\"1\"]],\"bids\":[],\"ts\":\"1781979785708\",\"checksum\":627252371,\"seqId\":325026386204,\"prevSeqId\":325026386179}]}"}
{"action": null, "capture_sequence": 47, "channel": "trades", "connection_sequence": 1, "event": null, "instId": "BTC-USDT-SWAP", "local_receive_ts": "2026-06-20T18:23:05Z", "monotonic_ns": 1607341693899570, "raw": "{\"arg\":{\"channel\":\"trades\",\"instId\":\"BTC-USDT-SWAP\"},\"data\":[{\"instId\":\"BTC-USDT-SWAP\",\"tradeId\":\"2718372445\",\"px\":\"63813.6\",\"sz\":\"0.01\",\"side\":\"sell\",\"ts\":\"1781979785775\",\"count\":\"1\",\"source\":\"0\",\"seqId\":325026386216}]}"}
{"action": "update", "capture_sequence": 48, "channel": "books", "connection_sequence": 1, "event": null, "instId": "BTC-USDT-SWAP", "local_receive_ts": "2026-06-20T18:23:05Z", "monotonic_ns": 1607341726934953, "raw": "{\"arg\":{\"channel\":\"books\",\"instId\":\"BTC-USDT-SWAP\"},\"action\":\"update\",\"data\":[{\"asks\":[[\"63814\",\"0\",\"0\",\"0\"],[\"63814.1\",\"0\",\"0\",\"0\"],[\"63814.6\",\"0\",\"0\",\"0\"],[\"63815.8\",\"0.47\",\"0\",\"5\"],[\"63816\",\"3.44\",\"0\",\"3\"],[\"63816.8\",\"1.97\",\"0\",\"3\"],[\"63818.9\",\"40.35\",\"0\",\"5\"],[\"63820.5\",\"27.27\",\"0\",\"6\"],[\"63820.7\",\"78.35\",\"0\",\"1\"],[\"63847.9\",\"0\",\"0\",\"0\"],[\"63857.1\",\"47.04\",\"0\",\"3\"],[\"63867.7\",\"0.01\",\"0\",\"1\"],[\"63868\",\"1.52\",\"0\",\"2\"],[\"63868.1\",\"0.09\",\"0\",\"1\"],[\"63868.2\",\"0.05\",\"0\",\"3\"]],\"bids\":[[\"63813.6\",\"1163.2\",\"0\",\"77\"],[\"63800.1\",\"70.67\",\"0\",\"2\"],[\"63793.7\",\"0.02\",\"0\",\"2\"],[\"63777.2\",\"0\",\"0\",\"0\"],[\"63761.2\",\"0.02\",\"0\",\"1\"]],\"ts\":\"1781979785808\",\"checksum\":-898435616,\"seqId\":325026386220,\"prevSeqId\":325026386204}]}"}
{"action": "update", "capture_sequence": 49, "channel": "books", "connection_sequence": 1, "event": null, "instId": "BTC-USDT-SWAP", "local_receive_ts": "2026-06-20T18:23:06Z", "monotonic_ns": 1607341826744195, "raw": "{\"arg\":{\"channel\":\"books\",\"instId\":\"BTC-USDT-SWAP\"},\"action\":\"update\",\"data\":[{\"asks\":[[\"63816.8\",\"0.4\",\"0\",\"2\"],[\"63817.1\",\"1.57\",\"0\",\"1\"],[\"63820.1\",\"0\",\"0\",\"0\"]],\"bids\":[],\"ts\":\"1781979785908\",\"checksum\":418066376,\"seqId\":325026386225,\"prevSeqId\":325026386220}]}"}
{"action": "update", "capture_sequence": 50, "channel": "books", "connection_sequence": 1, "event": null, "instId": "BTC-USDT-SWAP", "local_receive_ts": "2026-06-20T18:23:06Z", "monotonic_ns": 1607341927461271, "raw": "{\"arg\":{\"channel\":\"books\",\"instId\":\"BTC-USDT-SWAP\"},\"action\":\"update\",\"data\":[{\"asks\":[[\"63825.5\",\"41.64\",\"0\",\"3\"],[\"63825.9\",\"0.02\",\"0\",\"2\"],[\"63833.8\",\"10.5\",\"0\",\"1\"],[\"63834\",\"86.45\",\"0\",\"6\"],[\"63834.2\",\"0.02\",\"0\",\"2\"],[\"63835.4\",\"15.88\",\"0\",\"2\"],[\"63835.8\",\"117.6\",\"0\",\"3\"],[\"63836.2\",\"0.01\",\"0\",\"1\"],[\"63836.6\",\"0.01\",\"0\",\"1\"],[\"63836.7\",\"111.03\",\"0\",\"3\"],[\"63837.1\",\"361.05\",\"0\",\"4\"],[\"63837.5\",\"0.47\",\"0\",\"2\"],[\"63839.1\",\"0.05\",\"0\",\"3\"],[\"63839.2\",\"16.67\",\"0\",\"4\"],[\"63840.5\",\"0.01\",\"0\",\"1\"],[\"63840.9\",\"407.88\",\"0\",\"2\"]],\"bids\":[[\"63813\",\"152.91\",\"0\",\"4\"],[\"63812.4\",\"0.78\",\"0\",\"1\"],[\"63800.8\",\"1.09\",\"0\",\"3\"],[\"63800.5\",\"167.5\",\"0\",\"3\"],[\"63798.9\",\"0.02\",\"0\",\"1\"],[\"63798.6\",\"235.33\",\"0\",\"1\"],[\"63797.7\",\"0.01\",\"0\",\"1\"],[\"63797.6\",\"0.31\",\"0\",\"1\"],[\"63791.3\",\"93.04\",\"0\",\"2\"],[\"63791.2\",\"226.59\",\"0\",\"2\"],[\"63790.9\",\"58.98\",\"0\",\"3\"],[\"63790.8\",\"88.49\",\"0\",\"5\"],[\"63790.7\",\"361.13\",\"0\",\"1\"],[\"63790.4\",\"0.01\",\"0\",\"1\"],[\"63761.4\",\"0\",\"0\",\"0\"],[\"63761.3\",\"0\",\"0\",\"0\"],[\"63761.2\",\"0\",\"0\",\"0\"]],\"ts\":\"1781979786008\",\"checksum\":1990887627,\"seqId\":325026386261,\"prevSeqId\":325026386225}]}"}
{"action": "update", "capture_sequence": 51, "channel": "books", "connection_sequence": 1, "event": null, "instId": "BTC-USDT-SWAP", "local_receive_ts": "2026-06-20T18:23:06Z", "monotonic_ns": 1607342026832546, "raw": "{\"arg\":{\"channel\":\"books\",\"instId\":\"BTC-USDT-SWAP\"},\"action\":\"update\",\"data\":[{\"asks\":[[\"63816.1\",\"15.93\",\"0\",\"2\"],[\"63816.4\",\"3.4\",\"0\",\"3\"],[\"63818.5\",\"3.06\",\"0\",\"2\"],[\"63835.7\",\"86.24\",\"0\",\"1\"],[\"63835.8\",\"31.36\",\"0\",\"2\"],[\"63857.1\",\"0.07\",\"0\",\"2\"],[\"63868.2\",\"0\",\"0\",\"0\"]],\"bids\":[[\"63802.2\",\"0\",\"0\",\"0\"],[\"63801.9\",\"39.28\",\"0\",\"5\"],[\"63790.8\",\"2.19\",\"0\",\"4\"],[\"63790.7\",\"447.43\",\"0\",\"2\"],[\"63761.4\",\"0.01\",\"0\",\"1\"]],\"ts\":\"1781979786108\",\"checksum\":404280942,\"seqId\":325026386271,\"prevSeqId\":325026386261}]}"}
{"action": null, "capture_sequence": 52, "channel": "trades", "connection_sequence": 1, "event": null, "instId": "BTC-USDT-SWAP", "local_receive_ts": "2026-06-20T18:23:06Z", "monotonic_ns": 1607342049627991, "raw": "{\"arg\":{\"channel\":\"trades\",\"instId\":\"BTC-USDT-SWAP\"},\"data\":[{\"instId\":\"BTC-USDT-SWAP\",\"tradeId\":\"2718372458\",\"px\":\"63813.7\",\"sz\":\"2.5\",\"side\":\"buy\",\"ts\":\"1781979786131\",\"count\":\"13\",\"source\":\"0\",\"seqId\":325026386301}]}"}
{"action": "update", "capture_sequence": 53, "channel": "books", "connection_sequence": 1, "event": null, "instId": "BTC-USDT-SWAP", "local_receive_ts": "2026-06-20T18:23:06Z", "monotonic_ns": 1607342133038544, "raw": "{\"arg\":{\"channel\":\"books\",\"instId\":\"BTC-USDT-SWAP\"},\"action\":\"update\",\"data\":[{\"asks\":[[\"63813.7\",\"442.38\",\"0\",\"21\"],[\"63813.9\",\"1.57\",\"0\",\"1\"],[\"63814.3\",\"3.53\",\"0\",\"2\"],[\"63814.4\",\"1.57\",\"0\",\"1\"],[\"63815.4\",\"1.57\",\"0\",\"1\"],[\"63815.8\",\"0.46\",\"0\",\"4\"],[\"63816.1\",\"17.5\",\"0\",\"3\"],[\"63816.6\",\"1.6\",\"0\",\"4\"],[\"63817.1\",\"0\",\"0\",\"0\"],[\"63817.4\",\"1.58\",\"0\",\"2\"],[\"63820\",\"0.62\",\"0\",\"3\"],[\"63820.1\",\"10.81\",\"0\",\"1\"],[\"63820.2\",\"25.86\",\"0\",\"6\"],[\"63820.3\",\"72.29\",\"0\",\"2\"],[\"63820.5\",\"0.16\",\"0\",\"1\"],[\"63820.6\",\"0\",\"0\",\"0\"],[\"63821.2\",\"4\",\"0\",\"1\"],[\"63821.7\",\"0\",\"0\",\"0\"],[\"63825.5\",\"10.28\",\"0\",\"2\"],[\"63825.6\",\"0\",\"0\",\"0\"],[\"63826.8\",\"0\",\"0\",\"0\"],[\"63827.3\",\"31.36\",\"0\",\"1\"],[\"63828.5\",\"3.65\",\"0\",\"3\"],[\"63830.5\",\"164.49\",\"0\",\"1\"],[\"63831.2\",\"62.74\",\"0\",\"1\"],[\"63831.9\",\"15.67\",\"0\",\"2\"],[\"63833.3\",\"15.69\",\"0\",\"2\"],[\"63834\",\"55.11\",\"0\",\"4\"],[\"63834.2\",\"86.26\",\"0\",\"3\"],[\"63834.7\",\"266.56\",\"0\",\"2\"],[\"63834.9\",\"50.09\",\"0\",\"3\"],[\"63835.7\",\"0\",\"0\",\"0\"],[\"63835.8\",\"0.01\",\"0\",\"1\"],[\"63836.2\",\"58.8\",\"0\",\"2\"],[\"63836.7\",\"76.88\",\"0\",\"2\"],[\"63837.1\",\"125.86\",\"0\",\"3\"],[\"63838.3\",\"0.02\",\"0\",\"2\"],[\"63839.1\",\"0.83\",\"0\",\"4\"],[\"63839.2\",\"15.89\",\"0\",\"3\"],[\"63839.6\",\"74.94\",\"0\",\"4\"],[\"63840.8\",\"127.66\",\"0\",\"4\"],[\"63841.2\",\"0\",\"0\",\"0\"],[\"63842.6\",\"0.01\",\"0\",\"1\"],[\"63868.2\",\"0.05\",\"0\",\"3\"]],\"bids\":[[\"63813.6\",\"1061.41\",\"0\",\"70\"],[\"63813.3\",\"0.8\",\"0\",\"3\"],[\"63813.1\",\"157.59\",\"0\",\"4\"],[\"63813\",\"151.34\",\"0\",\"3\"],[\"63812.5\",\"0\",\"0\",\"0\"],[\"63811.9\",\"1.57\",\"0\",\"1\"],[\"63811.7\",\"0.05\",\"0\",\"2\"],[\"63811.6\",\"1.1\",\"0\",\"2\"],[\"63811.5\",\"79.17\",\"0\",\"2\"],[\"63809.8\",\"1.57\",\"0\",\"1\"],[\"63809.2\",\"9.14\",\"0\",\"5\"],[\"63806.7\",\"1.58\",\"0\",\"2\"],[\"63805.1\",\"100\",\"0\",\"1\"],[\"63801.7\",\"0.08\",\"0\",\"2\"],[\"63800.8\",\"0.31\",\"0\",\"2\"],[\"63800.2\",\"0.78\",\"0\",\"1\"],[\"63800\",\"62.78\",\"0\",\"29\"],[\"63799.9\",\"19.58\",\"0\",\"3\"],[\"63799.7\",\"62.74\",\"0\",\"1\"],[\"63799\",\"0.01\",\"0\",\"1\"],[\"63798.7\",\"31.37\",\"0\",\"1\"],[\"63798.6\",\"0\",\"0\",\"0\"],[\"63798.1\",\"0\",\"0\",\"0\"],[\"63796.4\",\"34.18\",\"0\",\"2\"],[\"63796.1\",\"235.36\",\"0\",\"3\"],[\"63794.5\",\"0\",\"0\",\"0\"],[\"63792\",\"87.2\",\"0\",\"7\"],[\"63791.3\",\"72.75\",\"0\",\"1\"],[\"63790.9\",\"0.14\",\"0\",\"2\"],[\"63790.7\",\"361.13\",\"0\",\"1\"],[\"63789.6\",\"20.29\",\"0\",\"1\"],[\"63789.2\",\"86.33\",\"0\",\"4\"],[\"63788.7\",\"467.1\",\"0\",\"9\"],[\"63788.1\",\"0.01\",\"0\",\"1\"],[\"63761.5\",\"0\",\"0\",\"0\"],[\"63761.4\",\"0\",\"0\",\"0\"]],\"ts\":\"1781979786208\",\"checksum\":-254676675,\"seqId\":325026386567,\"prevSeqId\":325026386271}]}"}
{"action": "update", "capture_sequence": 54, "channel": "books", "connection_sequence": 1, "event": null, "instId": "BTC-USDT-SWAP", "local_receive_ts": "2026-06-20T18:23:06Z", "monotonic_ns": 1607342232968423, "raw": "{\"arg\":{\"channel\":\"books\",\"instId\":\"BTC-USDT-SWAP\"},\"action\":\"update\",\"data\":[{\"asks\":[[\"63813.7\",\"442.4\",\"0\",\"22\"],[\"63813.8\",\"0.88\",\"0\",\"8\"],[\"63814.7\",\"0.4\",\"0\",\"2\"],[\"63816.1\",\"17.9\",\"0\",\"4\"],[\"63816.6\",\"1.61\",\"0\",\"5\"],[\"63817.7\",\"6.28\",\"0\",\"2\"],[\"63817.8\",\"44.79\",\"0\",\"1\"],[\"63818\",\"0.01\",\"0\",\"1\"],[\"63818.6\",\"1.57\",\"0\",\"1\"],[\"63820.2\",\"1.22\",\"0\",\"3\"],[\"63820.7\",\"0\",\"0\",\"0\"],[\"63821.2\",\"29.54\",\"0\",\"5\"],[\"63821.3\",\"213.13\",\"0\",\"2\"],[\"63824.4\",\"26.67\",\"0\",\"2\"],[\"63825.8\",\"31.37\",\"0\",\"2\"],[\"63825.9\",\"1.89\",\"0\",\"4\"],[\"63826.1\",\"216.08\",\"0\",\"6\"],[\"63826.8\",\"3.2\",\"0\",\"1\"],[\"63827\",\"8.02\",\"0\",\"2\"],[\"63827.3\",\"0\",\"0\",\"0\"],[\"63827.5\",\"0.01\",\"0\",\"1\"],[\"63829.4\",\"0.34\",\"0\",\"2\"],[\"63830\",\"0.01\",\"0\",\"1\"],[\"63831.2\",\"62.9\",\"0\",\"2\"],[\"63831.5\",\"15.68\",\"0\",\"1\"],[\"63831.6\",\"15.67\",\"0\",\"2\"],[\"63831.9\",\"0.01\",\"0\",\"1\"],[\"63832.7\",\"0\",\"0\",\"0\"],[\"63833.3\",\"31.37\",\"0\",\"2\"],[\"63834.3\",\"251.07\",\"0\",\"2\"],[\"63834.4\",\"62.7\",\"0\",\"3\"],[\"63834.7\",\"0\",\"0\",\"0\"],[\"63834.9\",\"15.94\",\"0\",\"2\"],[\"63835.3\",\"34.17\",\"0\",\"3\"],[\"63835.5\",\"37.69\",\"0\",\"3\"],[\"63836.2\",\"0.01\",\"0\",\"1\"],[\"63836.9\",\"58.83\",\"0\",\"4\"],[\"63837.3\",\"0\",\"0\",\"0\"],[\"63838.1\",\"0.02\",\"0\",\"2\"],[\"63838.3\",\"0.8\",\"0\",\"3\"],[\"63839.1\",\"0.05\",\"0\",\"3\"],[\"63839.7\",\"0.05\",\"0\",\"2\"],[\"63840.8\",\"55.15\",\"0\",\"4\"],[\"63840.9\",\"494.87\",\"0\",\"2\"],[\"63841\",\"195.24\",\"0\",\"4\"],[\"63842.7\",\"150.37\",\"0\",\"1\"],[\"63844.5\",\"75.42\",\"0\",\"5\"],[\"63848.8\",\"0\",\"0\",\"0\"],[\"63857.6\",\"8\",\"0\",\"1\"],[\"63858\",\"26.84\",\"0\",\"6\"],[\"63860.2\",\"242.47\",\"0\",\"4\"],[\"63868.4\",\"0.01\",\"0\",\"1\"],[\"63868.6\",\"0.01\",\"0\",\"1\"]],\"bids\":[[\"63813.6\",\"1060.71\",\"0\",\"69\"],[\"63813.4\",\"0\",\"0\",\"0\"],[\"63813.1\",\"157.6\",\"0\",\"5\"],[\"63812.6\",\"0\",\"0\",\"0\"],[\"63812.5\",\"0.01\",\"0\",\"1\"],[\"63812.2\",\"15.68\",\"0\",\"1\"],[\"63812.1\",\"1.58\",\"0\",\"2\"],[\"63811.9\",\"0.01\",\"0\",\"1\"],[\"63811.6\",\"1.58\",\"0\",\"2\"],[\"63811.5\",\"79.18\",\"0\",\"3\"],[\"63811.1\",\"76.65\",\"0\",\"3\"],[\"63808.6\",\"0\",\"0\",\"0\"],[\"63807.2\",\"0\",\"0\",\"0\"],[\"63804.7\",\"49.05\",\"0\",\"1\"],[\"63802\",\"0.02\",\"0\",\"2\"],[\"63801.9\",\"39.26\",\"0\",\"3\"],[\"63801.4\",\"1.1\",\"0\",\"2\"],[\"63801.2\",\"407.87\",\"0\",\"2\"],[\"63800.2\",\"0\",\"0\",\"0\"],[\"63800\",\"62.79\",\"0\",\"30\"],[\"63799.9\",\"3.91\",\"0\",\"2\"],[\"63799.7\",\"62.93\",\"0\",\"2\"],[\"63799\",\"2.59\",\"0\",\"2\"],[\"63798.9\",\"16.47\",\"0\",\"3\"],[\"63798.8\",\"37.67\",\"0\",\"2\"],[\"63798.7\",\"0\",\"0\",\"0\"],[\"63797.6\",\"0\",\"0\",\"0\"],[\"63797\",\"31.38\",\"0\",\"2\"],[\"63796.6\",\"34.48\",\"0\",\"2\"],[\"63796.4\",\"0.01\",\"0\",\"1\"],[\"63796.1\",\"0.02\",\"0\",\"2\"],[\"63795.8\",\"235.34\",\"0\",\"1\"],[\"63795\",\"71.8\",\"0\",\"5\"],[\"63792.9\",\"134.13\",\"0\",\"2\"],[\"63792\",\"0.12\",\"0\",\"6\"],[\"63790.6\",\"62.67\",\"0\",\"1\"],[\"63789.5\",\"100.33\",\"0\",\"4\"],[\"63788.7\",\"408.27\",\"0\",\"9\"],[\"63761.5\",\"235.06\",\"0\",\"1\"],[\"63761.4\",\"0.01\",\"0\",\"1\"],[\"63761.3\",\"0.01\",\"0\",\"1\"]],\"ts\":\"1781979786308\",\"checksum\":1977967629,\"seqId\":325026386839,\"prevSeqId\":325026386567}]}"}
{"action": "update", "capture_sequence": 55, "channel": "books", "connection_sequence": 1, "event": null, "instId": "BTC-USDT-SWAP", "local_receive_ts": "2026-06-20T18:23:06Z", "monotonic_ns": 1607342327192580, "raw": "{\"arg\":{\"channel\":\"books\",\"instId\":\"BTC-USDT-SWAP\"},\"action\":\"update\",\"data\":[{\"asks\":[[\"63827.4\",\"229.61\",\"0\",\"2\"],[\"63834.3\",\"15.87\",\"0\",\"1\"],[\"63834.7\",\"269.35\",\"0\",\"2\"],[\"63835.3\",\"0.02\",\"0\",\"2\"],[\"63836.3\",\"90.16\",\"0\",\"2\"],[\"63836.9\",\"0.04\",\"0\",\"3\"],[\"63839.4\",\"20.28\",\"0\",\"1\"],[\"63839.6\",\"54.66\",\"0\",\"3\"],[\"63840.8\",\"142.16\",\"0\",\"5\"],[\"63840.9\",\"407.86\",\"0\",\"1\"],[\"63868.4\",\"0\",\"0\",\"0\"],[\"63868.6\",\"0\",\"0\",\"0\"]],\"bids\":[[\"63812.5\",\"1.58\",\"0\",\"2\"],[\"63812.1\",\"0.01\",\"0\",\"1\"],[\"63812\",\"1.58\",\"0\",\"2\"],[\"63811.6\",\"0.01\",\"0\",\"1\"],[\"63811.5\",\"80.75\",\"0\",\"4\"],[\"63806.7\",\"0.01\",\"0\",\"1\"],[\"63800\",\"262.79\",\"0\",\"31\"],[\"63796.6\",\"0.31\",\"0\",\"1\"],[\"63796.2\",\"34.17\",\"0\",\"1\"],[\"63796.1\",\"235.36\",\"0\",\"3\"],[\"63795.8\",\"0\",\"0\",\"0\"],[\"63792.9\",\"47.05\",\"0\",\"1\"],[\"63792\",\"87.2\",\"0\",\"7\"],[\"63789.6\",\"0\",\"0\",\"0\"],[\"63789.5\",\"41.49\",\"0\",\"3\"],[\"63789.3\",\"20.29\",\"0\",\"1\"],[\"63788.9\",\"60.34\",\"0\",\"3\"],[\"63775.3\",\"75.33\",\"0\",\"3\"],[\"63762.5\",\"62.68\",\"0\",\"2\"]],\"ts\":\"1781979786408\",\"checksum\":-2102409273,\"seqId\":325026386883,\"prevSeqId\":325026386839}]}"}
{"action": "update", "capture_sequence": 56, "channel": "books", "connection_sequence": 1, "event": null, "instId": "BTC-USDT-SWAP", "local_receive_ts": "2026-06-20T18:23:06Z", "monotonic_ns": 1607342427069077, "raw": "{\"arg\":{\"channel\":\"books\",\"instId\":\"BTC-USDT-SWAP\"},\"action\":\"update\",\"data\":[{\"asks\":[[\"63826.8\",\"0\",\"0\",\"0\"],[\"63830.4\",\"0.01\",\"0\",\"1\"],[\"63830.5\",\"164.79\",\"0\",\"2\"],[\"63831.2\",\"62.74\",\"0\",\"1\"],[\"63833.5\",\"93.3\",\"0\",\"2\"],[\"63834.2\",\"0.02\",\"0\",\"2\"],[\"63835.8\",\"58.81\",\"0\",\"2\"],[\"63836.3\",\"31.37\",\"0\",\"1\"],[\"63868.4\",\"0.01\",\"0\",\"1\"]],\"bids\":[[\"63812\",\"0.01\",\"0\",\"1\"],[\"63811.9\",\"1.58\",\"0\",\"2\"],[\"63811.5\",\"79.18\",\"0\",\"3\"],[\"63811.4\",\"2.58\",\"0\",\"3\"],[\"63799.7\",\"62.74\",\"0\",\"1\"],[\"63799\",\"0.01\",\"0\",\"1\"],[\"63796.9\",\"0\",\"0\",\"0\"],[\"63796.8\",\"1.3\",\"0\",\"2\"],[\"63790.1\",\"22.86\",\"0\",\"3\"],[\"63789.2\",\"0.03\",\"0\",\"3\"],[\"63788.9\",\"1.5\",\"0\",\"2\"],[\"63788.7\",\"494.57\",\"0\",\"10\"],[\"63787.9\",\"58.84\",\"0\",\"1\"],[\"63771.8\",\"0\",\"0\",\"0\"],[\"63761.2\",\"0.02\",\"0\",\"1\"]],\"ts\":\"1781979786508\",\"checksum\":1844504887,\"seqId\":325026386911,\"prevSeqId\":325026386883}]}"}
{"action": "update", "capture_sequence": 57, "channel": "books", "connection_sequence": 1, "event": null, "instId": "BTC-USDT-SWAP", "local_receive_ts": "2026-06-20T18:23:06Z", "monotonic_ns": 1607342527058856, "raw": "{\"arg\":{\"channel\":\"books\",\"instId\":\"BTC-USDT-SWAP\"},\"action\":\"update\",\"data\":[{\"asks\":[[\"63813.7\",\"442.5\",\"0\",\"24\"],[\"63815.8\",\"0.41\",\"0\",\"3\"],[\"63816.4\",\"3.35\",\"0\",\"2\"],[\"63826.8\",\"3.2\",\"0\",\"1\"],[\"63831.2\",\"62.9\",\"0\",\"2\"],[\"63831.5\",\"0\",\"0\",\"0\"],[\"63831.9\",\"15.69\",\"0\",\"2\"],[\"63851.5\",\"0.16\",\"0\",\"2\"]],\"bids\":[[\"63812.7\",\"93.14\",\"0\",\"2\"],[\"63812.2\",\"0\",\"0\",\"0\"],[\"63799.8\",\"0.78\",\"0\",\"1\"],[\"63799.7\",\"62.93\",\"0\",\"2\"],[\"63799\",\"2.59\",\"0\",\"2\"],[\"63798.9\",\"15.69\",\"0\",\"2\"]],\"ts\":\"1781979786608\",\"checksum\":-1684685804,\"seqId\":325026386930,\"prevSeqId\":325026386911}]}"}
{"action": null, "capture_sequence": 58, "channel": "trades", "connection_sequence": 1, "event": null, "instId": "BTC-USDT-SWAP", "local_receive_ts": "2026-06-20T18:23:06Z", "monotonic_ns": 1607342565447213, "raw": "{\"arg\":{\"channel\":\"trades\",\"instId\":\"BTC-USDT-SWAP\"},\"data\":[{\"instId\":\"BTC-USDT-SWAP\",\"tradeId\":\"2718372462\",\"px\":\"63813.7\",\"sz\":\"0.94\",\"side\":\"buy\",\"ts\":\"1781979786647\",\"count\":\"4\",\"source\":\"0\",\"seqId\":325026386947}]}"}
{"action": "update", "capture_sequence": 59, "channel": "books", "connection_sequence": 1, "event": null, "instId": "BTC-USDT-SWAP", "local_receive_ts": "2026-06-20T18:23:06Z", "monotonic_ns": 1607342626722215, "raw": "{\"arg\":{\"channel\":\"books\",\"instId\":\"BTC-USDT-SWAP\"},\"action\":\"update\",\"data\":[{\"asks\":[[\"63813.7\",\"441.46\",\"0\",\"19\"],[\"63813.8\",\"0.87\",\"0\",\"7\"],[\"63813.9\",\"0\",\"0\",\"0\"],[\"63814.3\",\"3.52\",\"0\",\"1\"],[\"63814.4\",\"0\",\"0\",\"0\"],[\"63814.7\",\"0.41\",\"0\",\"3\"],[\"63815.4\",\"0.01\",\"0\",\"1\"],[\"63815.5\",\"1.57\",\"0\",\"1\"],[\"63815.6\",\"0.05\",\"0\",\"1\"],[\"63816.3\",\"33.81\",\"0\",\"3\"],[\"63820\",\"2.19\",\"0\",\"4\"],[\"63838.3\",\"0.02\",\"0\",\"2\"],[\"63838.7\",\"0.79\",\"0\",\"2\"],[\"63839.3\",\"21.09\",\"0\",\"3\"],[\"63839.4\",\"0\",\"0\",\"0\"],[\"63868.6\",\"0.01\",\"0\",\"1\"]],\"bids\":[[\"63813.4\",\"0.01\",\"0\",\"1\"],[\"63813.3\",\"2.37\",\"0\",\"4\"],[\"63813.1\",\"157.59\",\"0\",\"4\"],[\"63812.6\",\"0.01\",\"0\",\"1\"],[\"63811.9\",\"1.57\",\"0\",\"1\"],[\"63807.1\",\"10.55\",\"0\",\"3\"],[\"63800.1\",\"71.45\",\"0\",\"3\"],[\"63799.8\",\"0\",\"0\",\"0\"],[\"63796.4\",\"34.18\",\"0\",\"2\"],[\"63796.2\",\"0\",\"0\",\"0\"],[\"63789.4\",\"36.16\",\"0\",\"2\"],[\"63789.3\",\"0\",\"0\",\"0\"],[\"63761\",\"0.1\",\"0\",\"1\"]],\"ts\":\"1781979786708\",\"checksum\":-371309439,\"seqId\":325026386987,\"prevSeqId\":325026386930}]}"}
{"action": "update", "capture_sequence": 60, "channel": "books", "connection_sequence": 1, "event": null, "instId": "BTC-USDT-SWAP", "local_receive_ts": "2026-06-20T18:23:06Z", "monotonic_ns": 1607342732364473, "raw": "{\"arg\":{\"channel\":\"books\",\"instId\":\"BTC-USDT-SWAP\"},\"action\":\"update\",\"data\":[{\"asks\":[[\"63813.7\",\"270.53\",\"0\",\"17\"],[\"63814.7\",\"0.02\",\"0\",\"2\"],[\"63815.4\",\"0\",\"0\",\"0\"],[\"63815.5\",\"0\",\"0\",\"0\"],[\"63815.8\",\"0.03\",\"0\",\"3\"],[\"63816.1\",\"16.33\",\"0\",\"3\"],[\"63816.8\",\"0.01\",\"0\",\"1\"],[\"63817.2\",\"1.58\",\"0\",\"2\"],[\"63817.4\",\"0.01\",\"0\",\"1\"],[\"63817.9\",\"0\",\"0\",\"0\"],[\"63820.5\",\"1.73\",\"0\",\"2\"],[\"63821\",\"1.58\",\"0\",\"2\"],[\"63821.2\",\"4\",\"0\",\"1\"],[\"63821.5\",\"1.57\",\"0\",\"1\"],[\"63821.9\",\"1.58\",\"0\",\"2\"],[\"63824\",\"25.58\",\"0\",\"8\"],[\"63825.9\",\"5.86\",\"0\",\"5\"],[\"63826.9\",\"0\",\"0\",\"0\"],[\"63829.4\",\"0.03\",\"0\",\"1\"],[\"63830\",\"0.32\",\"0\",\"2\"],[\"63831.6\",\"0.01\",\"0\",\"1\"],[\"63831.9\",\"0.01\",\"0\",\"1\"],[\"63832.7\",\"31.34\",\"0\",\"2\"],[\"63833.3\",\"0.01\",\"0\",\"1\"],[\"63834\",\"86.47\",\"0\",\"5\"],[\"63834.4\",\"62.68\",\"0\",\"2\"],[\"63834.7\",\"34.15\",\"0\",\"1\"],[\"63835.1\",\"236.39\",\"0\",\"3\"],[\"63835.3\",\"0.04\",\"0\",\"3\"],[\"63836.9\",\"0.02\",\"0\",\"2\"],[\"63837.1\",\"125.88\",\"0\",\"4\"],[\"63839.7\",\"0.03\",\"0\",\"1\"],[\"63840.3\",\"0.02\",\"0\",\"1\"],[\"63857.6\",\"0\",\"0\",\"0\"],[\"63859.9\",\"9.83\",\"0\",\"3\"],[\"63868.7\",\"0.01\",\"0\",\"1\"],[\"63868.8\",\"72.38\",\"0\",\"7\"]],\"bids\":[[\"63813.5\",\"1.22\",\"0\",\"5\"],[\"63813.4\",\"15.69\",\"0\",\"2\"],[\"63813.3\",\"1.59\",\"0\",\"3\"],[\"63813.2\",\"31.37\",\"0\",\"1\"],[\"63812.7\",\"77.46\",\"0\",\"1\"],[\"63801.4\",\"1.88\",\"0\",\"3\"],[\"63800.3\",\"0.05\",\"0\",\"2\"],[\"63800.1\",\"87.12\",\"0\",\"4\"],[\"63800\",\"262.78\",\"0\",\"30\"],[\"63798.9\",\"0.02\",\"0\",\"1\"],[\"63797.6\",\"31.68\",\"0\",\"2\"],[\"63797\",\"0.01\",\"0\",\"1\"],[\"63796.6\",\"235.34\",\"0\",\"1\"],[\"63796.1\",\"0.02\",\"0\",\"2\"],[\"63795.8\",\"0.01\",\"0\",\"1\"],[\"63795\",\"71.79\",\"0\",\"4\"],[\"63761.2\",\"0\",\"0\",\"0\"],[\"63761\",\"0\",\"0\",\"0\"]],\"ts\":\"1781979786808\",\"checksum\":-1436713113,\"seqId\":325026387073,\"prevSeqId\":325026386987}]}"}
{"action": "update", "capture_sequence": 61, "channel": "books", "connection_sequence": 1, "event": null, "instId": "BTC-USDT-SWAP", "local_receive_ts": "2026-06-20T18:23:07Z", "monotonic_ns": 1607342832045007, "raw": "{\"arg\":{\"channel\":\"books\",\"instId\":\"BTC-USDT-SWAP\"},\"action\":\"update\",\"data\":[{\"asks\":[[\"63815.6\",\"1.62\",\"0\",\"2\"],[\"63821.9\",\"0.01\",\"0\",\"1\"],[\"63822.9\",\"1.69\",\"0\",\"1\"],[\"63823.5\",\"0.43\",\"0\",\"2\"],[\"63823.8\",\"0\",\"0\",\"0\"],[\"63824.2\",\"127.12\",\"0\",\"3\"],[\"63824.5\",\"0\",\"0\",\"0\"],[\"63824.7\",\"0\",\"0\",\"0\"],[\"63825.1\",\"0\",\"0\",\"0\"],[\"63825.5\",\"8\",\"0\",\"1\"],[\"63825.7\",\"0\",\"0\",\"0\"],[\"63826.1\",\"214.43\",\"0\",\"5\"],[\"63834.7\",\"0\",\"0\",\"0\"],[\"63835.3\",\"34.19\",\"0\",\"4\"],[\"63838.7\",\"0.01\",\"0\",\"1\"],[\"63839.1\",\"0.83\",\"0\",\"4\"],[\"63843.8\",\"4.34\",\"0\",\"2\"],[\"63844.5\",\"74.42\",\"0\",\"4\"],[\"63844.7\",\"0\",\"0\",\"0\"],[\"63845.1\",\"3.9\",\"0\",\"1\"],[\"63845.4\",\"0\",\"0\",\"0\"],[\"63845.7\",\"0\",\"0\",\"0\"],[\"63846\",\"0.02\",\"0\",\"2\"],[\"63846.4\",\"293.3\",\"0\",\"3\"],[\"63846.6\",\"10.97\",\"0\",\"3\"],[\"63847\",\"0\",\"0\",\"0\"],[\"63864.7\",\"0\",\"0\",\"0\"],[\"63865.4\",\"0.04\",\"0\",\"3\"],[\"63865.7\",\"0.04\",\"0\",\"2\"],[\"63866\",\"3\",\"0\",\"1\"],[\"63866.3\",\"0.01\",\"0\",\"1\"],[\"63866.6\",\"42.66\",\"0\",\"2\"],[\"63867\",\"0.05\",\"0\",\"1\"],[\"63867.3\",\"407.87\",\"0\",\"2\"],[\"63867.5\",\"0\",\"0\",\"0\"],[\"63868\",\"0.02\",\"0\",\"1\"],[\"63869.1\",\"0.01\",\"0\",\"1\"],[\"63869.3\",\"0.77\",\"0\",\"3\"],[\"63869.4\",\"14.4\",\"0\",\"4\"],[\"63869.5\",\"24.83\",\"0\",\"2\"],[\"63869.6\",\"0.74\",\"0\",\"5\"],[\"63869.7\",\"0.04\",\"0\",\"1\"],[\"63869.8\",\"0.05\",\"0\",\"2\"],[\"63869.9\",\"50.15\",\"0\",\"2\"],[\"63870\",\"143.57\",\"0\",\"8\"],[\"63870.3\",\"0.36\",\"0\",\"1\"],[\"63870.5\",\"0.79\",\"0\",\"2\"],[\"63870.6\",\"0.04\",\"0\",\"2\"]],\"bids\":[[\"63813.6\",\"1060.81\",\"0\",\"70\"],[\"63811.4\",\"1.58\",\"0\",\"2\"],[\"63810.7\",\"0\",\"0\",\"0\"],[\"63810.4\",\"10.62\",\"0\",\"5\"],[\"63810.1\",\"0\",\"0\",\"0\"],[\"63809.7\",\"62.68\",\"0\",\"2\"],[\"63809.3\",\"74.19\",\"0\",\"3\"],[\"63809.1\",\"0\",\"0\",\"0\"],[\"63808.8\",\"0\",\"0\",\"0\"],[\"63808.4\",\"0.01\",\"0\",\"1\"],[\"63808.1\",\"0\",\"0\",\"0\"],[\"63801\",\"200.03\",\"0\",\"3\"],[\"63800.2\",\"0.78\",\"0\",\"1\"],[\"63800.1\",\"86.34\",\"0\",\"3\"],[\"63800\",\"62.78\",\"0\",\"29\"],[\"63796.9\",\"34.17\",\"0\",\"1\"],[\"63796.4\",\"0.01\",\"0\",\"1\"],[\"63769.5\",\"0\",\"0\",\"0\"],[\"63768.9\",\"40.08\",\"0\",\"3\"],[\"63768.5\",\"0.01\",\"0\",\"1\"],[\"63768.2\",\"0.02\",\"0\",\"2\"],[\"63767.9\",\"48.44\",\"0\",\"1\"],[\"63767.5\",\"17.59\",\"0\",\"3\"],[\"63767.2\",\"6.23\",\"0\",\"2\"],[\"63766.9\",\"15.89\",\"0\",\"2\"],[\"63766.6\",\"60.04\",\"0\",\"3\"],[\"63766.3\",\"0.36\",\"0\",\"1\"],[\"63761.2\",\"0.02\",\"0\",\"1\"],[\"63761\",\"0.1\",\"0\",\"1\"],[\"63760.9\",\"0.01\",\"0\",\"1\"],[\"63760.8\",\"0.03\",\"0\",\"2\"]],\"ts\":\"1781979786908\",\"checksum\":2041162647,\"seqId\":325026387166,\"prevSeqId\":325026387073}]}"}
{"action": "update", "capture_sequence": 62, "channel": "books", "connection_sequence": 1, "event": null, "instId": "BTC-USDT-SWAP", "local_receive_ts": "2026-06-20T18:23:07Z", "monotonic_ns": 1607342932034933, "raw": "{\"arg\":{\"channel\":\"books\",\"instId\":\"BTC-USDT-SWAP\"},\"action\":\"update\",\"data\":[{\"asks\":[[\"63815.6\",\"0.05\",\"0\",\"1\"],[\"63816.6\",\"0.04\",\"0\",\"4\"],[\"63817.2\",\"0.01\",\"0\",\"1\"],[\"63817.5\",\"1.58\",\"0\",\"2\"],[\"63818\",\"1.58\",\"0\",\"2\"],[\"63822.7\",\"1.9\",\"0\",\"1\"],[\"63823.4\",\"1.8\",\"0\",\"1\"],[\"63824\",\"27.74\",\"0\",\"9\"],[\"63825.3\",\"2.28\",\"0\",\"1\"],[\"63825.8\",\"0.01\",\"0\",\"1\"],[\"63825.9\",\"38.87\",\"0\",\"7\"],[\"63831.8\",\"15.68\",\"0\",\"1\"],[\"63831.9\",\"15.67\",\"0\",\"2\"],[\"63832.7\",\"0\",\"0\",\"0\"],[\"63833.5\",\"7.06\",\"0\",\"1\"],[\"63834.2\",\"86.26\",\"0\",\"3\"],[\"63835.2\",\"50.05\",\"0\",\"5\"],[\"63835.3\",\"0.04\",\"0\",\"3\"],[\"63840.8\",\"55.15\",\"0\",\"4\"],[\"63842.6\",\"87.02\",\"0\",\"2\"],[\"63843.6\",\"1\",\"0\",\"1\"],[\"63844.3\",\"1\",\"0\",\"1\"],[\"63844.9\",\"258.99\",\"0\",\"4\"],[\"63846.2\",\"1.2\",\"0\",\"1\"],[\"63846.9\",\"11.5\",\"0\",\"2\"],[\"63864.6\",\"1.01\",\"0\",\"2\"],[\"63865.2\",\"61.01\",\"0\",\"3\"],[\"63865.8\",\"1.21\",\"0\",\"2\"],[\"63867.2\",\"1.21\",\"0\",\"2\"],[\"63867.8\",\"1.5\",\"0\",\"1\"],[\"63869.7\",\"0\",\"0\",\"0\"],[\"63869.8\",\"0\",\"0\",\"0\"],[\"63869.9\",\"0\",\"0\",\"0\"],[\"63870\",\"0\",\"0\",\"0\"],[\"63870.3\",\"0\",\"0\",\"0\"],[\"63870.5\",\"0\",\"0\",\"0\"],[\"63870.6\",\"0\",\"0\",\"0\"]],\"bids\":[[\"63811\",\"2.72\",\"0\",\"3\"],[\"63810.4\",\"11.62\",\"0\",\"6\"],[\"63809.7\",\"63.88\",\"0\",\"3\"],[\"63808.4\",\"1.21\",\"0\",\"2\"],[\"63807.8\",\"13.5\",\"0\",\"3\"],[\"63800.1\",\"70.67\",\"0\",\"2\"],[\"63799.1\",\"15.67\",\"0\",\"1\"],[\"63796.9\",\"0\",\"0\",\"0\"],[\"63796.7\",\"34.17\",\"0\",\"1\"],[\"63792.9\",\"134.13\",\"0\",\"2\"],[\"63792\",\"0.12\",\"0\",\"6\"],[\"63790.1\",\"3.91\",\"0\",\"2\"],[\"63789.2\",\"86.33\",\"0\",\"4\"],[\"63788.7\",\"408.27\",\"0\",\"9\"],[\"63774.2\",\"18.95\",\"0\",\"1\"],[\"63769.1\",\"1\",\"0\",\"1\"],[\"63768.5\",\"1.01\",\"0\",\"2\"],[\"63767.8\",\"1.2\",\"0\",\"1\"],[\"63766.5\",\"409.09\",\"0\",\"5\"],[\"63765.9\",\"77.74\",\"0\",\"2\"],[\"63761.2\",\"0\",\"0\",\"0\"],[\"63761\",\"0\",\"0\",\"0\"],[\"63760.9\",\"0\",\"0\",\"0\"],[\"63760.8\",\"0\",\"0\",\"0\"]],\"ts\":\"1781979787008\",\"checksum\":-1532639561,\"seqId\":325026387232,\"prevSeqId\":325026387166}]}"}
{"action": "update", "capture_sequence": 63, "channel": "books", "connection_sequence": 1, "event": null, "instId": "BTC-USDT-SWAP", "local_receive_ts": "2026-06-20T18:23:07Z", "monotonic_ns": 1607343026804609, "raw": "{\"arg\":{\"channel\":\"books\",\"instId\":\"BTC-USDT-SWAP\"},\"action\":\"update\",\"data\":[{\"asks\":[[\"63817\",\"3.2\",\"0\",\"2\"],[\"63823.6\",\"2.11\",\"0\",\"2\"],[\"63824.3\",\"2.28\",\"0\",\"1\"],[\"63824.9\",\"6.14\",\"0\",\"3\"],[\"63825.5\",\"10.64\",\"0\",\"2\"],[\"63844.6\",\"1.01\",\"0\",\"2\"],[\"63845.2\",\"424.94\",\"0\",\"4\"],[\"63845.9\",\"1.2\",\"0\",\"1\"],[\"63846.4\",\"294.5\",\"0\",\"4\"],[\"63847.6\",\"0.55\",\"0\",\"3\"],[\"63847.9\",\"46.98\",\"0\",\"1\"],[\"63865.5\",\"1.01\",\"0\",\"2\"],[\"63866.2\",\"8.27\",\"0\",\"3\"],[\"63866.8\",\"1.2\",\"0\",\"1\"],[\"63867.4\",\"1.23\",\"0\",\"3\"],[\"63869.3\",\"0\",\"0\",\"0\"],[\"63869.4\",\"0\",\"0\",\"0\"],[\"63869.5\",\"0\",\"0\",\"0\"],[\"63869.6\",\"0\",\"0\",\"0\"]],\"bids\":[[\"63813\",\"152.12\",\"0\",\"4\"],[\"63812.4\",\"0\",\"0\",\"0\"],[\"63810\",\"1.03\",\"0\",\"4\"],[\"63809.4\",\"409.07\",\"0\",\"3\"],[\"63808.7\",\"1.2\",\"0\",\"1\"],[\"63808\",\"1.22\",\"0\",\"3\"],[\"63784.7\",\"62.91\",\"0\",\"3\"],[\"63768.1\",\"1.23\",\"0\",\"5\"],[\"63767.5\",\"18.79\",\"0\",\"4\"],[\"63766.8\",\"1.21\",\"0\",\"2\"],[\"63766.2\",\"1.34\",\"0\",\"2\"]],\"ts\":\"1781979787108\",\"checksum\":-353735493,\"seqId\":325026387264,\"prevSeqId\":325026387232}]}"}
{"action": "update", "capture_sequence": 64, "channel": "books", "connection_sequence": 1, "event": null, "instId": "BTC-USDT-SWAP", "local_receive_ts": "2026-06-20T18:23:07Z", "monotonic_ns": 1607343126945378, "raw": "{\"arg\":{\"channel\":\"books\",\"instId\":\"BTC-USDT-SWAP\"},\"action\":\"update\",\"data\":[{\"asks\":[[\"63815.9\",\"4.67\",\"0\",\"3\"],[\"63816.8\",\"1.58\",\"0\",\"2\"],[\"63817\",\"1.63\",\"0\",\"1\"],[\"63817.5\",\"0.01\",\"0\",\"1\"],[\"63824.5\",\"2.76\",\"0\",\"1\"],[\"63845.5\",\"124.09\",\"0\",\"5\"],[\"63866.4\",\"1.28\",\"0\",\"3\"],[\"63869.1\",\"0\",\"0\",\"0\"]],\"bids\":[[\"63808.9\",\"1.21\",\"0\",\"2\"],[\"63767.1\",\"1.21\",\"0\",\"2\"]],\"ts\":\"1781979787208\",\"checksum\":-1485925449,\"seqId\":325026387279,\"prevSeqId\":325026387264}]}"}
{"action": null, "capture_sequence": 65, "channel": "trades", "connection_sequence": 1, "event": null, "instId": "BTC-USDT-SWAP", "local_receive_ts": "2026-06-20T18:23:07Z", "monotonic_ns": 1607343146559616, "raw": "{\"arg\":{\"channel\":\"trades\",\"instId\":\"BTC-USDT-SWAP\"},\"data\":[{\"instId\":\"BTC-USDT-SWAP\",\"tradeId\":\"2718372463\",\"px\":\"63813.6\",\"sz\":\"0.05\",\"side\":\"sell\",\"ts\":\"1781979787227\",\"count\":\"1\",\"source\":\"0\",\"seqId\":325026387290}]}"}
{"action": "update", "capture_sequence": 66, "channel": "books", "connection_sequence": 1, "event": null, "instId": "BTC-USDT-SWAP", "local_receive_ts": "2026-06-20T18:23:07Z", "monotonic_ns": 1607343226915282, "raw": "{\"arg\":{\"channel\":\"books\",\"instId\":\"BTC-USDT-SWAP\"},\"action\":\"update\",\"data\":[{\"asks\":[[\"63814.5\",\"0.01\",\"0\",\"1\"],[\"63814.6\",\"1.57\",\"0\",\"1\"],[\"63815.2\",\"1.58\",\"0\",\"2\"],[\"63815.8\",\"0.02\",\"0\",\"2\"],[\"63821\",\"0.01\",\"0\",\"1\"],[\"63821.5\",\"0\",\"0\",\"0\"],[\"63826.8\",\"0\",\"0\",\"0\"],[\"63831.2\",\"62.74\",\"0\",\"1\"]],\"bids\":[[\"63813.6\",\"1061.49\",\"0\",\"71\"],[\"63812.5\",\"1.57\",\"0\",\"1\"],[\"63812\",\"0.02\",\"0\",\"2\"],[\"63799.7\",\"62.74\",\"0\",\"1\"],[\"63799\",\"0.01\",\"0\",\"1\"]],\"ts\":\"1781979787308\",\"checksum\":2146786172,\"seqId\":325026387313,\"prevSeqId\":325026387279}]}"}
{"action": "update", "capture_sequence": 67, "channel": "books", "connection_sequence": 1, "event": null, "instId": "BTC-USDT-SWAP", "local_receive_ts": "2026-06-20T18:23:07Z", "monotonic_ns": 1607343327260664, "raw": "{\"arg\":{\"channel\":\"books\",\"instId\":\"BTC-USDT-SWAP\"},\"action\":\"update\",\"data\":[{\"asks\":[[\"63814.5\",\"0\",\"0\",\"0\"],[\"63814.6\",\"0.01\",\"0\",\"1\"],[\"63814.7\",\"1.59\",\"0\",\"3\"],[\"63826.8\",\"3.21\",\"0\",\"1\"],[\"63831.2\",\"62.9\",\"0\",\"2\"]],\"bids\":[[\"63799.7\",\"62.94\",\"0\",\"2\"],[\"63799\",\"2.58\",\"0\",\"2\"]],\"ts\":\"1781979787408\",\"checksum\":1161054604,\"seqId\":325026387335,\"prevSeqId\":325026387313}]}"}
{"action": "update", "capture_sequence": 68, "channel": "books", "connection_sequence": 1, "event": null, "instId": "BTC-USDT-SWAP", "local_receive_ts": "2026-06-20T18:23:07Z", "monotonic_ns": 1607343427896250, "raw": "{\"arg\":{\"channel\":\"books\",\"instId\":\"BTC-USDT-SWAP\"},\"action\":\"update\",\"data\":[{\"asks\":[[\"63813.7\",\"270.57\",\"0\",\"17\"],[\"63814\",\"1.57\",\"0\",\"1\"],[\"63820.2\",\"67.26\",\"0\",\"4\"],[\"63820.5\",\"0.16\",\"0\",\"1\"],[\"63840.8\",\"142.16\",\"0\",\"5\"],[\"63842.6\",\"0.01\",\"0\",\"1\"],[\"63868.8\",\"0\",\"0\",\"0\"]],\"bids\":[],\"ts\":\"1781979787508\",\"checksum\":-1396420205,\"seqId\":325026387357,\"prevSeqId\":325026387335}]}"}
{"action": "update", "capture_sequence": 69, "channel": "books", "connection_sequence": 1, "event": null, "instId": "BTC-USDT-SWAP", "local_receive_ts": "2026-06-20T18:23:07Z", "monotonic_ns": 1607343526959431, "raw": "{\"arg\":{\"channel\":\"books\",\"instId\":\"BTC-USDT-SWAP\"},\"action\":\"update\",\"data\":[{\"asks\":[[\"63814\",\"0\",\"0\",\"0\"],[\"63814.6\",\"0\",\"0\",\"0\"],[\"63814.7\",\"0.02\",\"0\",\"2\"],[\"63814.9\",\"0.01\",\"0\",\"1\"],[\"63815\",\"1.57\",\"0\",\"1\"],[\"63815.2\",\"0.01\",\"0\",\"1\"],[\"63817.3\",\"1.57\",\"0\",\"1\"],[\"63820.2\",\"1.22\",\"0\",\"3\"],[\"63826\",\"0.02\",\"0\",\"2\"],[\"63840.8\",\"55.15\",\"0\",\"4\"],[\"63842.6\",\"87.02\",\"0\",\"2\"],[\"63868.7\",\"0\",\"0\",\"0\"]],\"bids\":[[\"63797.7\",\"0.32\",\"0\",\"2\"],[\"63797.6\",\"31.37\",\"0\",\"1\"],[\"63783\",\"15.87\",\"0\",\"1\"]],\"ts\":\"1781979787608\",\"checksum\":-2074529261,\"seqId\":325026387414,\"prevSeqId\":325026387357}]}"}
{"action": "update", "capture_sequence": 70, "channel": "books", "connection_sequence": 1, "event": null, "instId": "BTC-USDT-SWAP", "local_receive_ts": "2026-06-20T18:23:07Z", "monotonic_ns": 1607343627111580, "raw": "{\"arg\":{\"channel\":\"books\",\"instId\":\"BTC-USDT-SWAP\"},\"action\":\"update\",\"data\":[{\"asks\":[[\"63813.7\",\"197.81\",\"0\",\"16\"],[\"63814.9\",\"0\",\"0\",\"0\"],[\"63815\",\"0\",\"0\",\"0\"],[\"63815.8\",\"0.03\",\"0\",\"3\"],[\"63815.9\",\"3.1\",\"0\",\"2\"],[\"63816.2\",\"1.58\",\"0\",\"2\"],[\"63817.7\",\"7.18\",\"0\",\"3\"],[\"63817.8\",\"63.19\",\"0\",\"2\"],[\"63819.7\",\"78.37\",\"0\",\"3\"],[\"63820.2\",\"0.32\",\"0\",\"2\"],[\"63827\",\"8\",\"0\",\"1\"],[\"63827.5\",\"0.03\",\"0\",\"2\"],[\"63835.3\",\"0.02\",\"0\",\"2\"],[\"63835.5\",\"37.67\",\"0\",\"2\"],[\"63835.8\",\"0.01\",\"0\",\"1\"],[\"63836.6\",\"58.8\",\"0\",\"2\"],[\"63836.7\",\"76.92\",\"0\",\"4\"],[\"63837.1\",\"125.86\",\"0\",\"3\"],[\"63837.2\",\"15.89\",\"0\",\"2\"],[\"63839.3\",\"0.81\",\"0\",\"2\"],[\"63840\",\"36.96\",\"0\",\"21\"],[\"63841\",\"195.22\",\"0\",\"3\"],[\"63842.1\",\"0.09\",\"0\",\"2\"],[\"63868.7\",\"0.01\",\"0\",\"1\"],[\"63868.8\",\"72.38\",\"0\",\"7\"]],\"bids\":[[\"63811.4\",\"1.59\",\"0\",\"3\"],[\"63811.1\",\"76.64\",\"0\",\"2\"],[\"63801.2\",\"407.86\",\"0\",\"1\"],[\"63801.1\",\"215.81\",\"0\",\"8\"],[\"63800.9\",\"0.01\",\"0\",\"1\"],[\"63800.3\",\"0.04\",\"0\",\"1\"],[\"63797.3\",\"408.02\",\"0\",\"3\"],[\"63797.2\",\"0\",\"0\",\"0\"],[\"63790.2\",\"20.29\",\"0\",\"1\"],[\"63789.4\",\"15.87\",\"0\",\"1\"],[\"63789.1\",\"66.74\",\"0\",\"3\"],[\"63788.9\",\"1.51\",\"0\",\"3\"],[\"63788.7\",\"408.26\",\"0\",\"8\"],[\"63787.9\",\"0\",\"0\",\"0\"]],\"ts\":\"1781979787708\",\"checksum\":-30645933,\"seqId\":325026387480,\"prevSeqId\":325026387414}]}"}
{"action": "update", "capture_sequence": 71, "channel": "books", "connection_sequence": 1, "event": null, "instId": "BTC-USDT-SWAP", "local_receive_ts": "2026-06-20T18:23:08Z", "monotonic_ns": 1607343827099572, "raw": "{\"arg\":{\"channel\":\"books\",\"instId\":\"BTC-USDT-SWAP\"},\"action\":\"update\",\"data\":[{\"asks\":[[\"63816.2\",\"0.01\",\"0\",\"1\"],[\"63816.8\",\"0.01\",\"0\",\"1\"],[\"63817.3\",\"0\",\"0\",\"0\"],[\"63817.4\",\"1.58\",\"0\",\"2\"],[\"63820.5\",\"1.73\",\"0\",\"2\"],[\"63821\",\"1.58\",\"0\",\"2\"],[\"63869.1\",\"0.01\",\"0\",\"1\"]],\"bids\":[[\"63813.4\",\"15.68\",\"0\",\"1\"],[\"63813.3\",\"0.02\",\"0\",\"2\"],[\"63813.2\",\"31.38\",\"0\",\"2\"],[\"63813.1\",\"159.16\",\"0\",\"5\"]],\"ts\":\"1781979787908\",\"checksum\":134184188,\"seqId\":325026387538,\"prevSeqId\":325026387480}]}"}
{"action": "update", "capture_sequence": 72, "channel": "books", "connection_sequence": 1, "event": null, "instId": "BTC-USDT-SWAP", "local_receive_ts": "2026-06-20T18:23:08Z", "monotonic_ns": 1607343932131042, "raw": "{\"arg\":{\"channel\":\"books\",\"instId\":\"BTC-USDT-SWAP\"},\"action\":\"update\",\"data\":[{\"asks\":[[\"63813.7\",\"197.86\",\"0\",\"17\"],[\"63816.3\",\"33.76\",\"0\",\"2\"],[\"63817.4\",\"0.01\",\"0\",\"1\"],[\"63817.5\",\"1.58\",\"0\",\"2\"],[\"63821.5\",\"1.57\",\"0\",\"1\"],[\"63825.9\",\"7.51\",\"0\",\"6\"],[\"63826\",\"31.38\",\"0\",\"3\"],[\"63826.4\",\"0.02\",\"0\",\"1\"],[\"63827.5\",\"0.01\",\"0\",\"1\"],[\"63830\",\"0.01\",\"0\",\"1\"],[\"63830.4\",\"0.32\",\"0\",\"2\"],[\"63831.8\",\"0\",\"0\",\"0\"],[\"63831.9\",\"31.35\",\"0\",\"3\"],[\"63833.9\",\"231.38\",\"0\",\"4\"],[\"63834\",\"55.11\",\"0\",\"4\"],[\"63834.2\",\"0.02\",\"0\",\"2\"],[\"63834.8\",\"125.45\",\"0\",\"2\"],[\"63835.2\",\"15.9\",\"0\",\"4\"],[\"63835.6\",\"0.04\",\"0\",\"2\"],[\"63836.2\",\"34.16\",\"0\",\"2\"],[\"63836.7\",\"76.88\",\"0\",\"2\"],[\"63837.1\",\"125.88\",\"0\",\"4\"],[\"63837.2\",\"15.87\",\"0\",\"1\"],[\"63839.1\",\"0.05\",\"0\",\"3\"],[\"63839.2\",\"16.67\",\"0\",\"4\"],[\"63840\",\"16.68\",\"0\",\"20\"],[\"63840.7\",\"20.29\",\"0\",\"2\"],[\"63841.1\",\"0.03\",\"0\",\"2\"],[\"63842.1\",\"0.07\",\"0\",\"1\"],[\"63868.8\",\"0\",\"0\",\"0\"],[\"63869.1\",\"0\",\"0\",\"0\"]],\"bids\":[[\"63806.4\",\"100\",\"0\",\"1\"],[\"63805.1\",\"0\",\"0\",\"0\"],[\"63800.8\",\"1.09\",\"0\",\"3\"],[\"63800.2\",\"0\",\"0\",\"0\"],[\"63799.8\",\"15.67\",\"0\",\"1\"],[\"63799.1\",\"0\",\"0\",\"0\"],[\"63797.8\",\"31.37\",\"0\",\"1\"],[\"63797.6\",\"0\",\"0\",\"0\"],[\"63797.5\",\"96.84\",\"0\",\"2\"],[\"63796.7\",\"0\",\"0\",\"0\"],[\"63789.8\",\"86.31\",\"0\",\"2\"],[\"63789.2\",\"0.03\",\"0\",\"3\"],[\"63761.2\",\"0.02\",\"0\",\"1\"],[\"63761\",\"0.1\",\"0\",\"1\"]],\"ts\":\"1781979788008\",\"checksum\":-1937587038,\"seqId\":325026387593,\"prevSeqId\":325026387538}]}"}
{"action": "update", "capture_sequence": 73, "channel": "books", "connection_sequence": 1, "event": null, "instId": "BTC-USDT-SWAP", "local_receive_ts": "2026-06-20T18:23:08Z", "monotonic_ns": 1607344027975449, "raw": "{\"arg\":{\"channel\":\"books\",\"instId\":\"BTC-USDT-SWAP\"},\"action\":\"update\",\"data\":[{\"asks\":[[\"63813.8\",\"1.23\",\"0\",\"8\"],[\"63835.6\",\"0\",\"0\",\"0\"],[\"63836\",\"0.05\",\"0\",\"3\"],[\"63836.6\",\"0.01\",\"0\",\"1\"],[\"63837.1\",\"184.67\",\"0\",\"5\"],[\"63839.1\",\"0.83\",\"0\",\"4\"],[\"63839.2\",\"15.89\",\"0\",\"3\"],[\"63868.8\",\"72.38\",\"0\",\"7\"]],\"bids\":[[\"63800.8\",\"0.31\",\"0\",\"2\"],[\"63800.6\",\"0.79\",\"0\",\"2\"],[\"63797.9\",\"0.31\",\"0\",\"1\"],[\"63797.8\",\"0\",\"0\",\"0\"],[\"63797.7\",\"31.38\",\"0\",\"2\"],[\"63797.6\",\"34.17\",\"0\",\"1\"],[\"63797.5\",\"62.67\",\"0\",\"1\"],[\"63790.6\",\"82.96\",\"0\",\"2\"],[\"63790.2\",\"0\",\"0\",\"0\"],[\"63789.8\",\"145.15\",\"0\",\"3\"],[\"63789.1\",\"7.9\",\"0\",\"2\"]],\"ts\":\"1781979788108\",\"checksum\":-62037461,\"seqId\":325026387645,\"prevSeqId\":325026387593}]}"}
{"action": "update", "capture_sequence": 74, "channel": "books", "connection_sequence": 1, "event": null, "instId": "BTC-USDT-SWAP", "local_receive_ts": "2026-06-20T18:23:08Z", "monotonic_ns": 1607344127248688, "raw": "{\"arg\":{\"channel\":\"books\",\"instId\":\"BTC-USDT-SWAP\"},\"action\":\"update\",\"data\":[{\"asks\":[[\"63834.8\",\"39.21\",\"0\",\"1\"],[\"63835.1\",\"322.63\",\"0\",\"4\"],[\"63837.1\",\"125.88\",\"0\",\"4\"],[\"63837.5\",\"59.26\",\"0\",\"3\"]],\"bids\":[[\"63797.8\",\"34.17\",\"0\",\"1\"],[\"63797.6\",\"0\",\"0\",\"0\"],[\"63790.8\",\"22.48\",\"0\",\"5\"],[\"63790.6\",\"62.67\",\"0\",\"1\"],[\"63790.2\",\"86.3\",\"0\",\"1\"],[\"63789.8\",\"58.85\",\"0\",\"2\"],[\"63761\",\"0\",\"0\",\"0\"]],\"ts\":\"1781979788208\",\"checksum\":-62037461,\"seqId\":325026387656,\"prevSeqId\":325026387645}]}"}
{"action": "update", "capture_sequence": 75, "channel": "books", "connection_sequence": 1, "event": null, "instId": "BTC-USDT-SWAP", "local_receive_ts": "2026-06-20T18:23:08Z", "monotonic_ns": 1607344227202077, "raw": "{\"arg\":{\"channel\":\"books\",\"instId\":\"BTC-USDT-SWAP\"},\"action\":\"update\",\"data\":[{\"asks\":[[\"63816.2\",\"1.58\",\"0\",\"2\"],[\"63826.8\",\"0\",\"0\",\"0\"],[\"63831.2\",\"62.74\",\"0\",\"1\"],[\"63869.1\",\"0.01\",\"0\",\"1\"]],\"bids\":[[\"63813.6\",\"1060.74\",\"0\",\"70\"],[\"63799.7\",\"62.74\",\"0\",\"1\"],[\"63799\",\"0.01\",\"0\",\"1\"]],\"ts\":\"1781979788308\",\"checksum\":710377581,\"seqId\":325026387675,\"prevSeqId\":325026387656}]}"}
{"action": "update", "capture_sequence": 76, "channel": "books", "connection_sequence": 1, "event": null, "instId": "BTC-USDT-SWAP", "local_receive_ts": "2026-06-20T18:23:08Z", "monotonic_ns": 1607344326893279, "raw": "{\"arg\":{\"channel\":\"books\",\"instId\":\"BTC-USDT-SWAP\"},\"action\":\"update\",\"data\":[{\"asks\":[[\"63816.2\",\"0.01\",\"0\",\"1\"],[\"63826.8\",\"3.22\",\"0\",\"1\"],[\"63831.2\",\"62.9\",\"0\",\"2\"],[\"63869.1\",\"0\",\"0\",\"0\"]],\"bids\":[[\"63813.6\",\"1060.84\",\"0\",\"71\"],[\"63799.7\",\"62.94\",\"0\",\"2\"],[\"63799\",\"2.59\",\"0\",\"2\"]],\"ts\":\"1781979788408\",\"checksum\":2044486298,\"seqId\":325026387687,\"prevSeqId\":325026387675}]}"}
{"action": "update", "capture_sequence": 77, "channel": "books", "connection_sequence": 1, "event": null, "instId": "BTC-USDT-SWAP", "local_receive_ts": "2026-06-20T18:23:08Z", "monotonic_ns": 1607344427170174, "raw": "{\"arg\":{\"channel\":\"books\",\"instId\":\"BTC-USDT-SWAP\"},\"action\":\"update\",\"data\":[{\"asks\":[[\"63813.7\",\"195.82\",\"0\",\"16\"],[\"63816.9\",\"1.57\",\"0\",\"1\"],[\"63821.5\",\"0\",\"0\",\"0\"],[\"63837.5\",\"0.47\",\"0\",\"2\"],[\"63837.9\",\"58.79\",\"0\",\"1\"],[\"63868.8\",\"0\",\"0\",\"0\"]],\"bids\":[[\"63790.2\",\"145.14\",\"0\",\"2\"],[\"63789.8\",\"0.01\",\"0\",\"1\"]],\"ts\":\"1781979788508\",\"checksum\":-41962717,\"seqId\":325026387730,\"prevSeqId\":325026387687}]}"}
{"action": "update", "capture_sequence": 78, "channel": "books", "connection_sequence": 1, "event": null, "instId": "BTC-USDT-SWAP", "local_receive_ts": "2026-06-20T18:23:08Z", "monotonic_ns": 1607344526905315, "raw": "{\"arg\":{\"channel\":\"books\",\"instId\":\"BTC-USDT-SWAP\"},\"action\":\"update\",\"data\":[{\"asks\":[[\"63813.7\",\"197.85\",\"0\",\"17\"]],\"bids\":[],\"ts\":\"1781979788608\",\"checksum\":-111395453,\"seqId\":325026387731,\"prevSeqId\":325026387730}]}"}
{"action": null, "capture_sequence": 79, "channel": "trades", "connection_sequence": 1, "event": null, "instId": "BTC-USDT-SWAP", "local_receive_ts": "2026-06-20T18:23:08Z", "monotonic_ns": 1607344577988220, "raw": "{\"arg\":{\"channel\":\"trades\",\"instId\":\"BTC-USDT-SWAP\"},\"data\":[{\"instId\":\"BTC-USDT-SWAP\",\"tradeId\":\"2718372464\",\"px\":\"63813.7\",\"sz\":\"4\",\"side\":\"buy\",\"ts\":\"1781979788659\",\"count\":\"1\",\"source\":\"0\",\"seqId\":325026387743}]}"}
{"action": "update", "capture_sequence": 80, "channel": "books", "connection_sequence": 1, "event": null, "instId": "BTC-USDT-SWAP", "local_receive_ts": "2026-06-20T18:23:08Z", "monotonic_ns": 1607344627226898, "raw": "{\"arg\":{\"channel\":\"books\",\"instId\":\"BTC-USDT-SWAP\"},\"action\":\"update\",\"data\":[{\"asks\":[[\"63813.7\",\"193.8\",\"0\",\"16\"],[\"63815.8\",\"0.08\",\"0\",\"4\"],[\"63816.9\",\"0\",\"0\",\"0\"],[\"63817.5\",\"0.01\",\"0\",\"1\"],[\"63817.8\",\"64.76\",\"0\",\"3\"],[\"63818\",\"0.01\",\"0\",\"1\"],[\"63818.3\",\"13.25\",\"0\",\"8\"],[\"63818.6\",\"0\",\"0\",\"0\"],[\"63821.5\",\"1.57\",\"0\",\"1\"],[\"63821.9\",\"1.58\",\"0\",\"2\"],[\"63826.4\",\"0\",\"0\",\"0\"],[\"63826.6\",\"2.09\",\"0\",\"3\"],[\"63868.8\",\"72.38\",\"0\",\"7\"],[\"63869.1\",\"0.01\",\"0\",\"1\"]],\"bids\":[[\"63761.5\",\"0\",\"0\",\"0\"],[\"63761\",\"0.1\",\"0\",\"1\"]],\"ts\":\"1781979788708\",\"checksum\":138260699,\"seqId\":325026387768,\"prevSeqId\":325026387731}]}"}
{"action": null, "capture_sequence": 81, "channel": "trades", "connection_sequence": 1, "event": null, "instId": "BTC-USDT-SWAP", "local_receive_ts": "2026-06-20T18:23:08Z", "monotonic_ns": 1607344694437098, "raw": "{\"arg\":{\"channel\":\"trades\",\"instId\":\"BTC-USDT-SWAP\"},\"data\":[{\"instId\":\"BTC-USDT-SWAP\",\"tradeId\":\"2718372465\",\"px\":\"63813.6\",\"sz\":\"0.55\",\"side\":\"sell\",\"ts\":\"1781979788776\",\"count\":\"1\",\"source\":\"0\",\"seqId\":325026387803}]}"}
{"action": null, "capture_sequence": 82, "channel": "trades", "connection_sequence": 1, "event": null, "instId": "BTC-USDT-SWAP", "local_receive_ts": "2026-06-20T18:23:08Z", "monotonic_ns": 1607344695902843, "raw": "{\"arg\":{\"channel\":\"trades\",\"instId\":\"BTC-USDT-SWAP\"},\"data\":[{\"instId\":\"BTC-USDT-SWAP\",\"tradeId\":\"2718372466\",\"px\":\"63813.6\",\"sz\":\"0.05\",\"side\":\"sell\",\"ts\":\"1781979788777\",\"count\":\"1\",\"source\":\"0\",\"seqId\":325026387807}]}"}
{"action": "update", "capture_sequence": 83, "channel": "books", "connection_sequence": 1, "event": null, "instId": "BTC-USDT-SWAP", "local_receive_ts": "2026-06-20T18:23:08Z", "monotonic_ns": 1607344727397964, "raw": "{\"arg\":{\"channel\":\"books\",\"instId\":\"BTC-USDT-SWAP\"},\"action\":\"update\",\"data\":[{\"asks\":[[\"63813.7\",\"193.85\",\"0\",\"17\"],[\"63814.9\",\"0.02\",\"0\",\"2\"],[\"63815\",\"1.57\",\"0\",\"1\"],[\"63815.8\",\"0.02\",\"0\",\"2\"],[\"63816.2\",\"1.58\",\"0\",\"2\"],[\"63817\",\"3.2\",\"0\",\"2\"],[\"63818.5\",\"3.05\",\"0\",\"1\"],[\"63821.5\",\"0\",\"0\",\"0\"],[\"63821.9\",\"0.01\",\"0\",\"1\"],[\"63826.5\",\"3.43\",\"0\",\"2\"],[\"63826.6\",\"2.07\",\"0\",\"2\"],[\"63826.8\",\"3.24\",\"0\",\"2\"],[\"63828.5\",\"0.52\",\"0\",\"2\"],[\"63831.9\",\"0.01\",\"0\",\"1\"],[\"63832\",\"34.66\",\"0\",\"5\"],[\"63833.8\",\"41.86\",\"0\",\"2\"],[\"63833.9\",\"200.02\",\"0\",\"3\"],[\"63835\",\"266.58\",\"0\",\"3\"],[\"63835.1\",\"87.43\",\"0\",\"3\"],[\"63836.2\",\"0.01\",\"0\",\"1\"],[\"63836.3\",\"65.52\",\"0\",\"2\"],[\"63867.4\",\"25.3\",\"0\",\"4\"],[\"63869.1\",\"0\",\"0\",\"0\"]],\"bids\":[[\"63813.6\",\"1060.24\",\"0\",\"71\"],[\"63797.8\",\"0\",\"0\",\"0\"],[\"63797.6\",\"34.17\",\"0\",\"1\"],[\"63771.1\",\"24.41\",\"0\",\"3\"]],\"ts\":\"1781979788808\",\"checksum\":1593093312,\"seqId\":325026387832,\"prevSeqId\":325026387768}]}"}
{"action": "update", "capture_sequence": 84, "channel": "books", "connection_sequence": 1, "event": null, "instId": "BTC-USDT-SWAP", "local_receive_ts": "2026-06-20T18:23:09Z", "monotonic_ns": 1607344827054677, "raw": "{\"arg\":{\"channel\":\"books\",\"instId\":\"BTC-USDT-SWAP\"},\"action\":\"update\",\"data\":[{\"asks\":[[\"63814.9\",\"0.01\",\"0\",\"1\"],[\"63815\",\"0\",\"0\",\"0\"],[\"63815.8\",\"0.03\",\"0\",\"3\"],[\"63816.2\",\"0.01\",\"0\",\"1\"],[\"63817\",\"1.63\",\"0\",\"1\"],[\"63817.3\",\"1.57\",\"0\",\"1\"],[\"63833.8\",\"10.5\",\"0\",\"1\"],[\"63834\",\"86.47\",\"0\",\"5\"],[\"63835\",\"31.38\",\"0\",\"2\"],[\"63835.3\",\"235.22\",\"0\",\"3\"]],\"bids\":[[\"63798\",\"31.42\",\"0\",\"6\"],[\"63797.7\",\"0.01\",\"0\",\"1\"]],\"ts\":\"1781979788908\",\"checksum\":1026796424,\"seqId\":325026387863,\"prevSeqId\":325026387832}]}"}
{"action": "update", "capture_sequence": 85, "channel": "books", "connection_sequence": 1, "event": null, "instId": "BTC-USDT-SWAP", "local_receive_ts": "2026-06-20T18:23:09Z", "monotonic_ns": 1607344926815160, "raw": "{\"arg\":{\"channel\":\"books\",\"instId\":\"BTC-USDT-SWAP\"},\"action\":\"update\",\"data\":[{\"asks\":[[\"63837.1\",\"125.86\",\"0\",\"3\"],[\"63837.2\",\"15.89\",\"0\",\"2\"]],\"bids\":[[\"63800\",\"78.45\",\"0\",\"30\"],[\"63799.8\",\"0\",\"0\",\"0\"],[\"63798.1\",\"0.31\",\"0\",\"1\"],[\"63797.9\",\"0\",\"0\",\"0\"],[\"63760.9\",\"0.01\",\"0\",\"1\"]],\"ts\":\"1781979789008\",\"checksum\":1026796424,\"seqId\":325026387879,\"prevSeqId\":325026387863}]}"}
{"action": "update", "capture_sequence": 86, "channel": "books", "connection_sequence": 1, "event": null, "instId": "BTC-USDT-SWAP", "local_receive_ts": "2026-06-20T18:23:09Z", "monotonic_ns": 1607345027313197, "raw": "{\"arg\":{\"channel\":\"books\",\"instId\":\"BTC-USDT-SWAP\"},\"action\":\"update\",\"data\":[{\"asks\":[[\"63816.1\",\"17.9\",\"0\",\"4\"],[\"63833.9\",\"231.38\",\"0\",\"4\"],[\"63834\",\"55.11\",\"0\",\"4\"]],\"bids\":[[\"63798.1\",\"0\",\"0\",\"0\"],[\"63798\",\"0.05\",\"0\",\"5\"],[\"63797.8\",\"0.31\",\"0\",\"1\"],[\"63797.7\",\"31.38\",\"0\",\"2\"]],\"ts\":\"1781979789108\",\"checksum\":-1584577968,\"seqId\":325026387890,\"prevSeqId\":325026387879}]}"}
{"action": "update", "capture_sequence": 87, "channel": "books", "connection_sequence": 1, "event": null, "instId": "BTC-USDT-SWAP", "local_receive_ts": "2026-06-20T18:23:09Z", "monotonic_ns": 1607345126813499, "raw": "{\"arg\":{\"channel\":\"books\",\"instId\":\"BTC-USDT-SWAP\"},\"action\":\"update\",\"data\":[{\"asks\":[[\"63813.7\",\"193.8\",\"0\",\"16\"],[\"63815.9\",\"3.15\",\"0\",\"3\"],[\"63816.1\",\"16.33\",\"0\",\"3\"],[\"63816.3\",\"35.33\",\"0\",\"3\"]],\"bids\":[],\"ts\":\"1781979789208\",\"checksum\":-1321459257,\"seqId\":325026387895,\"prevSeqId\":325026387890}]}"}
{"action": "update", "capture_sequence": 88, "channel": "books", "connection_sequence": 1, "event": null, "instId": "BTC-USDT-SWAP", "local_receive_ts": "2026-06-20T18:23:09Z", "monotonic_ns": 1607345227414447, "raw": "{\"arg\":{\"channel\":\"books\",\"instId\":\"BTC-USDT-SWAP\"},\"action\":\"update\",\"data\":[{\"asks\":[[\"63813.8\",\"1.24\",\"0\",\"9\"],[\"63814.9\",\"0\",\"0\",\"0\"],[\"63816.3\",\"33.77\",\"0\",\"3\"],[\"63817.3\",\"0\",\"0\",\"0\"],[\"63817.8\",\"63.19\",\"0\",\"2\"],[\"63821.5\",\"1.57\",\"0\",\"1\"],[\"63821.9\",\"1.58\",\"0\",\"2\"],[\"63869.1\",\"0.01\",\"0\",\"1\"]],\"bids\":[[\"63813.6\",\"1061.02\",\"0\",\"72\"]],\"ts\":\"1781979789308\",\"checksum\":1512599620,\"seqId\":325026387943,\"prevSeqId\":325026387895}]}"}
{"action": "update", "capture_sequence": 89, "channel": "books", "connection_sequence": 1, "event": null, "instId": "BTC-USDT-SWAP", "local_receive_ts": "2026-06-20T18:23:09Z", "monotonic_ns": 1607345326825882, "raw": "{\"arg\":{\"channel\":\"books\",\"instId\":\"BTC-USDT-SWAP\"},\"action\":\"update\",\"data\":[{\"asks\":[[\"63817\",\"3.2\",\"0\",\"2\"],[\"63826.8\",\"3.27\",\"0\",\"2\"]],\"bids\":[[\"63800.6\",\"0.01\",\"0\",\"1\"],[\"63800.2\",\"0.78\",\"0\",\"1\"],[\"63760.9\",\"0\",\"0\",\"0\"]],\"ts\":\"1781979789408\",\"checksum\":-879954869,\"seqId\":325026387969,\"prevSeqId\":325026387943}]}"}
{"action": "update", "capture_sequence": 90, "channel": "books", "connection_sequence": 1, "event": null, "instId": "BTC-USDT-SWAP", "local_receive_ts": "2026-06-20T18:23:09Z", "monotonic_ns": 1607345426819945, "raw": "{\"arg\":{\"channel\":\"books\",\"instId\":\"BTC-USDT-SWAP\"},\"action\":\"update\",\"data\":[{\"asks\":[[\"63830.5\",\"164.49\",\"0\",\"1\"],[\"63830.6\",\"0.31\",\"0\",\"2\"]],\"bids\":[[\"63796.8\",\"1\",\"0\",\"1\"],[\"63796.7\",\"0.3\",\"0\",\"1\"],[\"63761\",\"0\",\"0\",\"0\"]],\"ts\":\"1781979789508\",\"checksum\":-879954869,\"seqId\":325026387981,\"prevSeqId\":325026387969}]}"}
{"action": "update", "capture_sequence": 91, "channel": "books", "connection_sequence": 1, "event": null, "instId": "BTC-USDT-SWAP", "local_receive_ts": "2026-06-20T18:23:09Z", "monotonic_ns": 1607345526942854, "raw": "{\"arg\":{\"channel\":\"books\",\"instId\":\"BTC-USDT-SWAP\"},\"action\":\"update\",\"data\":[{\"asks\":[[\"63813.7\",\"193.85\",\"0\",\"17\"],[\"63815.9\",\"3.1\",\"0\",\"2\"],[\"63816\",\"0.02\",\"0\",\"2\"],[\"63816.3\",\"35.34\",\"0\",\"4\"],[\"63818.3\",\"7.66\",\"0\",\"7\"],[\"63843.9\",\"70.78\",\"0\",\"4\"],[\"63844.2\",\"0.01\",\"0\",\"1\"]],\"bids\":[],\"ts\":\"1781979789608\",\"checksum\":-689243538,\"seqId\":325026387990,\"prevSeqId\":325026387981}]}"}
{"action": null, "capture_sequence": 92, "channel": "trades", "connection_sequence": 1, "event": null, "instId": "BTC-USDT-SWAP", "local_receive_ts": "2026-06-20T18:23:09Z", "monotonic_ns": 1607345535833737, "raw": "{\"arg\":{\"channel\":\"trades\",\"instId\":\"BTC-USDT-SWAP\"},\"data\":[{\"instId\":\"BTC-USDT-SWAP\",\"tradeId\":\"2718372467\",\"px\":\"63813.6\",\"sz\":\"0.01\",\"side\":\"sell\",\"ts\":\"1781979789617\",\"count\":\"1\",\"source\":\"0\",\"seqId\":325026387992}]}"}
{"action": "update", "capture_sequence": 93, "channel": "books", "connection_sequence": 1, "event": null, "instId": "BTC-USDT-SWAP", "local_receive_ts": "2026-06-20T18:23:09Z", "monotonic_ns": 1607345627440470, "raw": "{\"arg\":{\"channel\":\"books\",\"instId\":\"BTC-USDT-SWAP\"},\"action\":\"update\",\"data\":[{\"asks\":[[\"63814.8\",\"1.92\",\"0\",\"4\"],[\"63814.9\",\"3.42\",\"0\",\"1\"],[\"63815.8\",\"0.02\",\"0\",\"2\"],[\"63815.9\",\"3.09\",\"0\",\"1\"],[\"63816\",\"5.61\",\"0\",\"3\"],[\"63869.1\",\"0\",\"0\",\"0\"]],\"bids\":[[\"63813.6\",\"1061.01\",\"0\",\"72\"],[\"63802\",\"0.09\",\"0\",\"3\"]],\"ts\":\"1781979789708\",\"checksum\":-187055739,\"seqId\":325026388002,\"prevSeqId\":325026387990}]}"}
{"action": "update", "capture_sequence": 94, "channel": "books", "connection_sequence": 1, "event": null, "instId": "BTC-USDT-SWAP", "local_receive_ts": "2026-06-20T18:23:10Z", "monotonic_ns": 1607345826886233, "raw": "{\"arg\":{\"channel\":\"books\",\"instId\":\"BTC-USDT-SWAP\"},\"action\":\"update\",\"data\":[{\"asks\":[[\"63816.3\",\"33.77\",\"0\",\"3\"],[\"63816.5\",\"1.57\",\"0\",\"1\"],[\"63835.1\",\"1.19\",\"0\",\"2\"],[\"63835.3\",\"321.46\",\"0\",\"4\"],[\"63836.3\",\"31.37\",\"0\",\"1\"],[\"63836.4\",\"50.02\",\"0\",\"2\"],[\"63840.7\",\"0.01\",\"0\",\"1\"],[\"63840.9\",\"428.14\",\"0\",\"2\"],[\"63867.4\",\"1.23\",\"0\",\"3\"],[\"63868.8\",\"0\",\"0\",\"0\"]],\"bids\":[[\"63813.6\",\"1061.11\",\"0\",\"73\"],[\"63797.8\",\"34.48\",\"0\",\"2\"],[\"63797.6\",\"0\",\"0\",\"0\"],[\"63791\",\"20.3\",\"0\",\"2\"],[\"63790.8\",\"2.19\",\"0\",\"4\"],[\"63790.3\",\"86.3\",\"0\",\"1\"],[\"63790.2\",\"58.84\",\"0\",\"1\"]],\"ts\":\"1781979789908\",\"checksum\":496474346,\"seqId\":325026388077,\"prevSeqId\":325026388002}]}"}
{"action": null, "capture_sequence": 95, "channel": "trades", "connection_sequence": 1, "event": null, "instId": "BTC-USDT-SWAP", "local_receive_ts": "2026-06-20T18:23:10Z", "monotonic_ns": 1607345853821585, "raw": "{\"arg\":{\"channel\":\"trades\",\"instId\":\"BTC-USDT-SWAP\"},\"data\":[{\"instId\":\"BTC-USDT-SWAP\",\"tradeId\":\"2718372468\",\"px\":\"63813.7\",\"sz\":\"5.23\",\"side\":\"buy\",\"ts\":\"1781979789935\",\"count\":\"1\",\"source\":\"0\",\"seqId\":325026388080}]}"}
{"action": "update", "capture_sequence": 96, "channel": "books", "connection_sequence": 1, "event": null, "instId": "BTC-USDT-SWAP", "local_receive_ts": "2026-06-20T18:23:10Z", "monotonic_ns": 1607345927309185, "raw": "{\"arg\":{\"channel\":\"books\",\"instId\":\"BTC-USDT-SWAP\"},\"action\":\"update\",\"data\":[{\"asks\":[[\"63813.7\",\"188.62\",\"0\",\"17\"],[\"63816.5\",\"0\",\"0\",\"0\"],[\"63817\",\"1.63\",\"0\",\"1\"],[\"63818.3\",\"6.09\",\"0\",\"6\"],[\"63819.1\",\"0.03\",\"0\",\"1\"],[\"63822.4\",\"1.58\",\"0\",\"2\"],[\"63822.9\",\"3.26\",\"0\",\"2\"],[\"63831.9\",\"15.69\",\"0\",\"2\"],[\"63832\",\"18.98\",\"0\",\"4\"],[\"63833.8\",\"41.86\",\"0\",\"2\"],[\"63833.9\",\"200.02\",\"0\",\"3\"],[\"63835.1\",\"236.39\",\"0\",\"3\"],[\"63835.2\",\"102.14\",\"0\",\"5\"],[\"63835.3\",\"0.02\",\"0\",\"2\"],[\"63836\",\"0.03\",\"0\",\"2\"],[\"63836.3\",\"65.52\",\"0\",\"2\"],[\"63836.4\",\"15.89\",\"0\",\"2\"],[\"63868.8\",\"72.38\",\"0\",\"7\"]],\"bids\":[[\"63797.9\",\"65.54\",\"0\",\"2\"],[\"63797.8\",\"0.31\",\"0\",\"1\"],[\"63797.7\",\"0.01\",\"0\",\"1\"],[\"63761.2\",\"0\",\"0\",\"0\"]],\"ts\":\"1781979790008\",\"checksum\":-1784999005,\"seqId\":325026388109,\"prevSeqId\":325026388077}]}"}
{"action": "update", "capture_sequence": 97, "channel": "books", "connection_sequence": 1, "event": null, "instId": "BTC-USDT-SWAP", "local_receive_ts": "2026-06-20T18:23:10Z", "monotonic_ns": 1607346027464089, "raw": "{\"arg\":{\"channel\":\"books\",\"instId\":\"BTC-USDT-SWAP\"},\"action\":\"update\",\"data\":[{\"asks\":[[\"63813.7\",\"188.57\",\"0\",\"16\"],[\"63815.8\",\"0.07\",\"0\",\"3\"],[\"63818.5\",\"4.62\",\"0\",\"2\"],[\"63819\",\"1.57\",\"0\",\"1\"],[\"63831.9\",\"0.01\",\"0\",\"1\"],[\"63832\",\"34.66\",\"0\",\"5\"],[\"63833.8\",\"10.5\",\"0\",\"1\"],[\"63833.9\",\"231.38\",\"0\",\"4\"],[\"63835.1\",\"1.19\",\"0\",\"2\"],[\"63835.2\",\"251.1\",\"0\",\"5\"],[\"63835.3\",\"86.26\",\"0\",\"3\"],[\"63836\",\"0.05\",\"0\",\"3\"],[\"63836.4\",\"15.87\",\"0\",\"1\"],[\"63840.8\",\"75.43\",\"0\",\"5\"],[\"63840.9\",\"407.86\",\"0\",\"1\"],[\"63868.8\",\"0\",\"0\",\"0\"]],\"bids\":[[\"63798\",\"31.42\",\"0\",\"6\"],[\"63797.9\",\"0.31\",\"0\",\"1\"],[\"63797.8\",\"0\",\"0\",\"0\"],[\"63797.6\",\"34.17\",\"0\",\"1\"]],\"ts\":\"1781979790108\",\"checksum\":780281553,\"seqId\":325026388135,\"prevSeqId\":325026388109}]}"}
{"action": "update", "capture_sequence": 98, "channel": "books", "connection_sequence": 1, "event": null, "instId": "BTC-USDT-SWAP", "local_receive_ts": "2026-06-20T18:23:10Z", "monotonic_ns": 1607346127203618, "raw": "{\"arg\":{\"channel\":\"books\",\"instId\":\"BTC-USDT-SWAP\"},\"action\":\"update\",\"data\":[{\"asks\":[[\"63837.5\",\"59.26\",\"0\",\"3\"],[\"63837.9\",\"0\",\"0\",\"0\"],[\"63868.8\",\"72.38\",\"0\",\"7\"]],\"bids\":[[\"63790.2\",\"0\",\"0\",\"0\"],[\"63790.1\",\"62.75\",\"0\",\"3\"],[\"63761.2\",\"0.02\",\"0\",\"1\"]],\"ts\":\"1781979790208\",\"checksum\":780281553,\"seqId\":325026388144,\"prevSeqId\":325026388135}]}"}
{"action": "update", "capture_sequence": 99, "channel": "books", "connection_sequence": 1, "event": null, "instId": "BTC-USDT-SWAP", "local_receive_ts": "2026-06-20T18:23:10Z", "monotonic_ns": 1607346226724916, "raw": "{\"arg\":{\"channel\":\"books\",\"instId\":\"BTC-USDT-SWAP\"},\"action\":\"update\",\"data\":[{\"asks\":[[\"63818.5\",\"3.05\",\"0\",\"1\"]],\"bids\":[[\"63813.6\",\"1060.33\",\"0\",\"72\"]],\"ts\":\"1781979790308\",\"checksum\":977179612,\"seqId\":325026388157,\"prevSeqId\":325026388144}]}"}
{"action": "update", "capture_sequence": 100, "channel": "books", "connection_sequence": 1, "event": null, "instId": "BTC-USDT-SWAP", "local_receive_ts": "2026-06-20T18:23:10Z", "monotonic_ns": 1607346326863739, "raw": "{\"arg\":{\"channel\":\"books\",\"instId\":\"BTC-USDT-SWAP\"},\"action\":\"update\",\"data\":[{\"asks\":[[\"63813.7\",\"189.4\",\"0\",\"16\"],[\"63826.8\",\"0.02\",\"0\",\"1\"],[\"63831.2\",\"62.74\",\"0\",\"1\"],[\"63833.7\",\"47.24\",\"0\",\"3\"],[\"63833.9\",\"200.02\",\"0\",\"3\"],[\"63837.5\",\"0.47\",\"0\",\"2\"],[\"63837.8\",\"58.79\",\"0\",\"1\"],[\"63840.8\",\"55.15\",\"0\",\"4\"],[\"63840.9\",\"428.14\",\"0\",\"2\"],[\"63868.8\",\"0\",\"0\",\"0\"]],\"bids\":[[\"63799.7\",\"62.74\",\"0\",\"1\"],[\"63799\",\"0.01\",\"0\",\"1\"],[\"63798\",\"0.05\",\"0\",\"5\"],[\"63797.7\",\"31.38\",\"0\",\"2\"],[\"63790.2\",\"58.84\",\"0\",\"1\"],[\"63790.1\",\"3.91\",\"0\",\"2\"],[\"63761.2\",\"0\",\"0\",\"0\"]],\"ts\":\"1781979790408\",\"checksum\":605030764,\"seqId\":325026388180,\"prevSeqId\":325026388157}]}"}
{"action": "update", "capture_sequence": 101, "channel": "books", "connection_sequence": 1, "event": null, "instId": "BTC-USDT-SWAP", "local_receive_ts": "2026-06-20T18:23:10Z", "monotonic_ns": 1607346427107990, "raw": "{\"arg\":{\"channel\":\"books\",\"instId\":\"BTC-USDT-SWAP\"},\"action\":\"update\",\"data\":[{\"asks\":[[\"63813.7\",\"115.38\",\"0\",\"14\"],[\"63819\",\"0\",\"0\",\"0\"],[\"63826.8\",\"3.2\",\"0\",\"2\"],[\"63831.3\",\"1.6\",\"0\",\"6\"],[\"63836\",\"0.03\",\"0\",\"2\"],[\"63836.4\",\"15.89\",\"0\",\"2\"],[\"63868.8\",\"72.38\",\"0\",\"7\"]],\"bids\":[[\"63799.7\",\"62.94\",\"0\",\"2\"],[\"63799\",\"2.59\",\"0\",\"2\"],[\"63797.8\",\"34.17\",\"0\",\"1\"],[\"63797.6\",\"0\",\"0\",\"0\"]],\"ts\":\"1781979790508\",\"checksum\":-1530876225,\"seqId\":325026388204,\"prevSeqId\":325026388180}]}"}
{"action": "update", "capture_sequence": 102, "channel": "books", "connection_sequence": 1, "event": null, "instId": "BTC-USDT-SWAP", "local_receive_ts": "2026-06-20T18:23:10Z", "monotonic_ns": 1607346533542722, "raw": "{\"arg\":{\"channel\":\"books\",\"instId\":\"BTC-USDT-SWAP\"},\"action\":\"update\",\"data\":[{\"asks\":[[\"63813.7\",\"12.57\",\"0\",\"11\"],[\"63815.2\",\"0\",\"0\",\"0\"],[\"63816.1\",\"1.93\",\"0\",\"1\"],[\"63817.6\",\"0.4\",\"0\",\"1\"],[\"63817.7\",\"6.28\",\"0\",\"2\"],[\"63817.8\",\"43.03\",\"0\",\"2\"],[\"63819.5\",\"0.01\",\"0\",\"1\"],[\"63819.7\",\"0.02\",\"0\",\"2\"],[\"63820\",\"0.62\",\"0\",\"3\"],[\"63820.1\",\"0\",\"0\",\"0\"],[\"63820.3\",\"3.37\",\"0\",\"1\"],[\"63820.5\",\"25.7\",\"0\",\"5\"],[\"63820.7\",\"0.9\",\"0\",\"1\"],[\"63820.8\",\"67.12\",\"0\",\"1\"],[\"63821\",\"0.01\",\"0\",\"1\"],[\"63821.3\",\"186.54\",\"0\",\"1\"],[\"63821.5\",\"0\",\"0\",\"0\"],[\"63821.9\",\"0.01\",\"0\",\"1\"],[\"63822.4\",\"0.01\",\"0\",\"1\"],[\"63822.9\",\"1.69\",\"0\",\"1\"],[\"63823.3\",\"0\",\"0\",\"0\"],[\"63824\",\"2.2\",\"0\",\"5\"],[\"63824.4\",\"26.6\",\"0\",\"2\"],[\"63826.1\",\"1.77\",\"0\",\"2\"],[\"63826.3\",\"67.03\",\"0\",\"4\"],[\"63826.8\",\"3.18\",\"0\",\"1\"],[\"63827.9\",\"55.89\",\"0\",\"6\"],[\"63830.4\",\"0.01\",\"0\",\"1\"],[\"63831.6\",\"0.32\",\"0\",\"2\"],[\"63832\",\"3.32\",\"0\",\"3\"],[\"63833.3\",\"15.67\",\"0\",\"2\"],[\"63833.6\",\"457.06\",\"0\",\"3\"],[\"63833.7\",\"15.88\",\"0\",\"2\"],[\"63835.2\",\"15.9\",\"0\",\"4\"],[\"63835.3\",\"0.02\",\"0\",\"2\"],[\"63835.8\",\"31.37\",\"0\",\"2\"],[\"63836\",\"0.01\",\"0\",\"1\"],[\"63836.3\",\"31.37\",\"0\",\"1\"],[\"63836.4\",\"15.87\",\"0\",\"1\"],[\"63836.7\",\"398.3\",\"0\",\"4\"],[\"63836.9\",\"0.06\",\"0\",\"4\"],[\"63837.2\",\"15.87\",\"0\",\"1\"],[\"63837.8\",\"0\",\"0\",\"0\"],[\"63838.3\",\"34.16\",\"0\",\"3\"],[\"63838.6\",\"0.02\",\"0\",\"1\"],[\"63839.1\",\"0.05\",\"0\",\"3\"],[\"63839.9\",\"79.79\",\"0\",\"3\"],[\"63840.3\",\"0\",\"0\",\"0\"],[\"63840.7\",\"58.8\",\"0\",\"2\"],[\"63840.9\",\"407.86\",\"0\",\"1\"],[\"63841\",\"195.24\",\"0\",\"4\"],[\"63841.1\",\"0.01\",\"0\",\"1\"],[\"63842.6\",\"20.29\",\"0\",\"2\"],[\"63842.9\",\"0.02\",\"0\",\"1\"],[\"63844.5\",\"73.42\",\"0\",\"3\"],[\"63844.8\",\"102.9\",\"0\",\"4\"],[\"63847.9\",\"0\",\"0\",\"0\"],[\"63849.2\",\"62.67\",\"0\",\"1\"],[\"63850\",\"8.13\",\"0\",\"56\"],[\"63859.9\",\"1.83\",\"0\",\"2\"],[\"63863.1\",\"8\",\"0\",\"1\"],[\"63869.1\",\"0.01\",\"0\",\"1\"]],\"bids\":[[\"63813.3\",\"0.8\",\"0\",\"3\"],[\"63807.5\",\"100.05\",\"0\",\"2\"],[\"63806.4\",\"0\",\"0\",\"0\"],[\"63801.5\",\"0.78\",\"0\",\"1\"],[\"63801.4\",\"1.1\",\"0\",\"2\"],[\"63801.2\",\"423.53\",\"0\",\"2\"],[\"63800.2\",\"0\",\"0\",\"0\"],[\"63800\",\"62.78\",\"0\",\"29\"],[\"63799.6\",\"34.18\",\"0\",\"2\"],[\"63799.5\",\"31.37\",\"0\",\"1\"],[\"63799.1\",\"0.31\",\"0\",\"1\"],[\"63798.4\",\"235.34\",\"0\",\"2\"],[\"63797.9\",\"0\",\"0\",\"0\"],[\"63797.8\",\"0\",\"0\",\"0\"],[\"63797.7\",\"0.02\",\"0\",\"2\"],[\"63797.3\",\"408.01\",\"0\",\"2\"],[\"63796.8\",\"0\",\"0\",\"0\"],[\"63796.6\",\"0\",\"0\",\"0\"],[\"63794.5\",\"87.08\",\"0\",\"1\"],[\"63793.2\",\"58.83\",\"0\",\"1\"],[\"63792.9\",\"47.05\",\"0\",\"1\"],[\"63792.6\",\"40.96\",\"0\",\"3\"],[\"63791.5\",\"86.3\",\"0\",\"2\"],[\"63791\",\"0.01\",\"0\",\"1\"],[\"63790.3\",\"0\",\"0\",\"0\"],[\"63790.2\",\"0\",\"0\",\"0\"],[\"63766\",\"0.7\",\"0\",\"3\"],[\"63761.2\",\"0.02\",\"0\",\"1\"],[\"63761\",\"0.1\",\"0\",\"1\"],[\"63760.9\",\"0.01\",\"0\",\"1\"]],\"ts\":\"1781979790608\",\"checksum\":-665163209,\"seqId\":325026388451,\"prevSeqId\":325026388204}]}"}
