{"action": null, "capture_sequence": 1, "channel": "trades", "connection_sequence": 1, "event": "subscribe", "instId": "BTC-USDT-SWAP", "local_receive_ts": "2026-06-21T04:25:03Z", "monotonic_ns": 1643459513234925, "raw": "{\"event\":\"subscribe\",\"arg\":{\"channel\":\"trades\",\"instId\":\"BTC-USDT-SWAP\"},\"connId\":\"7657d774\"}"}
{"action": null, "capture_sequence": 2, "channel": "books", "connection_sequence": 1, "event": "subscribe", "instId": "BTC-USDT-SWAP", "local_receive_ts": "2026-06-21T04:25:03Z", "monotonic_ns": 1643459513471151, "raw": "{\"event\":\"subscribe\",\"arg\":{\"channel\":\"books\",\"instId\":\"BTC-USDT-SWAP\"},\"connId\":\"7657d774\"}"}
{"action": "snapshot", "capture_sequence": 3, "channel": "books", "connection_sequence": 1, "event": null, "instId": "BTC-USDT-SWAP", "local_receive_ts": "2026-06-21T04:25:04Z", "monotonic_ns": 1643459929660753, "raw": "{\"arg\":{\"channel\":\"books\",\"instId\":\"BTC-USDT-SWAP\"},\"action\":\"snapshot\",\"data\":[{\"asks\":[[\"64458\",\"1532.72\",\"0\",\"68\"],[\"64458.1\",\"0.01\",\"0\",\"1\"],[\"64458.3\",\"0.02\",\"0\",\"2\"],[\"64458.7\",\"0.01\",\"0\",\"1\"],[\"64458.8\",\"46.27\",\"0\",\"1\"],[\"64458.9\",\"0.02\",\"0\",\"1\"],[\"64459.2\",\"0.02\",\"0\",\"2\"],[\"64459.3\",\"151.03\",\"0\",\"5\"],[\"64459.9\",\"0.02\",\"0\",\"2\"],[\"64460\",\"2.01\",\"0\",\"2\"],[\"64460.1\",\"0.02\",\"0\",\"2\"],[\"64460.2\",\"0.78\",\"0\",\"2\"],[\"64461\",\"0.01\",\"0\",\"1\"],[\"64461.1\",\"0.02\",\"0\",\"2\"],[\"64461.2\",\"7.4\",\"0\",\"2\"],[\"64461.4\",\"0.04\",\"0\",\"4\"],[\"64461.5\",\"1.56\",\"0\",\"1\"],[\"64461.9\",\"0.16\",\"0\",\"2\"],[\"64462\",\"1.6\",\"0\",\"5\"],[\"64462.4\",\"0.01\",\"0\",\"1\"],[\"64462.5\",\"1.56\",\"0\",\"1\"],[\"64462.6\",\"0.01\",\"0\",\"1\"],[\"64462.9\",\"1.57\",\"0\",\"2\"],[\"64463.1\",\"0.01\",\"0\",\"1\"],[\"64463.2\",\"0.01\",\"0\",\"1\"],[\"64463.3\",\"0.9\",\"0\",\"1\"],[\"64463.4\",\"1.56\",\"0\",\"1\"],[\"64463.5\",\"0.01\",\"0\",\"1\"],[\"64463.7\",\"14.14\",\"0\",\"1\"],[\"64463.8\",\"0.01\",\"0\",\"1\"],[\"64463.9\",\"1.56\",\"0\",\"1\"],[\"64464\",\"1.56\",\"0\",\"4\"],[\"64464.1\",\"31.08\",\"0\",\"4\"],[\"64464.2\",\"307.82\",\"0\",\"3\"],[\"64464.3\",\"72.21\",\"0\",\"1\"],[\"64464.4\",\"1.86\",\"0\",\"2\"],[\"64464.5\",\"168.27\",\"0\",\"7\"],[\"64464.6\",\"0.01\",\"0\",\"1\"],[\"64464.7\",\"0.01\",\"0\",\"1\"],[\"64464.9\",\"65.64\",\"0\",\"1\"],[\"64465\",\"77.79\",\"0\",\"3\"],[\"64465.1\",\"1\",\"0\",\"1\"],[\"64465.2\",\"77.75\",\"0\",\"2\"],[\"64465.5\",\"11.01\",\"0\",\"3\"],[\"64465.6\",\"0.01\",\"0\",\"1\"],[\"64465.7\",\"75.12\",\"0\",\"2\"],[\"64465.8\",\"65.22\",\"0\",\"3\"],[\"64466\",\"10.01\",\"0\",\"2\"],[\"64466.1\",\"1.21\",\"0\",\"2\"],[\"64466.4\",\"68.06\",\"0\",\"3\"],[\"64466.6\",\"10.01\",\"0\",\"2\"],[\"64466.7\",\"0.01\",\"0\",\"1\"],[\"64466.8\",\"99.33\",\"0\",\"1\"],[\"64466.9\",\"1.2\",\"0\",\"1\"],[\"64467\",\"63.88\",\"0\",\"2\"],[\"64467.2\",\"1.2\",\"0\",\"1\"],[\"64467.3\",\"0.01\",\"0\",\"1\"],[\"64467.6\",\"1.6\",\"0\",\"4\"],[\"64467.7\",\"1.5\",\"0\",\"1\"],[\"64467.8\",\"253.56\",\"0\",\"2\"],[\"64467.9\",\"0.02\",\"0\",\"2\"],[\"64468\",\"0.02\",\"0\",\"2\"],[\"64468.2\",\"15.88\",\"0\",\"1\"],[\"64468.3\",\"56.84\",\"0\",\"4\"],[\"64468.4\",\"69.47\",\"0\",\"1\"],[\"64468.6\",\"1.74\",\"0\",\"1\"],[\"64468.7\",\"66.46\",\"0\",\"2\"],[\"64468.8\",\"574.01\",\"0\",\"7\"],[\"64468.9\",\"0.03\",\"0\",\"2\"],[\"64469\",\"22\",\"0\",\"1\"],[\"64469.1\",\"0.01\",\"0\",\"1\"],[\"64469.3\",\"4\",\"0\",\"1\"],[\"64469.4\",\"0.01\",\"0\",\"1\"],[\"64469.5\",\"10.86\",\"0\",\"2\"],[\"64469.6\",\"0.01\",\"0\",\"1\"],[\"64469.7\",\"37.75\",\"0\",\"3\"],[\"64469.8\",\"15.92\",\"0\",\"1\"],[\"64469.9\",\"0.01\",\"0\",\"1\"],[\"64470\",\"10.08\",\"0\",\"4\"],[\"64470.1\",\"0.01\",\"0\",\"1\"],[\"64470.2\",\"0.02\",\"0\",\"1\"],[\"64470.3\",\"0.01\",\"0\",\"1\"],[\"64470.4\",\"0.24\",\"0\",\"2\"],[\"64470.5\",\"7.81\",\"0\",\"1\"],[\"64470.6\",\"384.95\",\"0\",\"4\"],[\"64470.7\",\"46.56\",\"0\",\"3\"],[\"64470.8\",\"0.77\",\"0\",\"1\"],[\"64470.9\",\"179.71\",\"0\",\"8\"],[\"64471\",\"0.57\",\"0\",\"5\"],[\"64471.3\",\"99.34\",\"0\",\"2\"],[\"64471.4\",\"15.97\",\"0\",\"1\"],[\"64471.6\",\"0.04\",\"0\",\"2\"],[\"64471.8\",\"496.53\",\"0\",\"1\"],[\"64471.9\",\"0.02\",\"0\",\"2\"],[\"64472\",\"2.07\",\"0\",\"5\"],[\"64472.1\",\"11.42\",\"0\",\"1\"],[\"64472.2\",\"0.01\",\"0\",\"1\"],[\"64472.6\",\"0.01\",\"0\",\"1\"],[\"64472.7\",\"24\",\"0\",\"2\"],[\"64472.8\",\"19.52\",\"0\",\"2\"],[\"64472.9\",\"12.05\",\"0\",\"4\"],[\"64473.2\",\"0.01\",\"0\",\"1\"],[\"64473.3\",\"1.24\",\"0\",\"1\"],[\"64473.6\",\"52.77\",\"0\",\"3\"],[\"64473.7\",\"277.86\",\"0\",\"4\"],[\"64473.8\",\"84.98\",\"0\",\"7\"],[\"64474\",\"0.03\",\"0\",\"3\"],[\"64474.2\",\"0.29\",\"0\",\"1\"],[\"64474.3\",\"18.95\",\"0\",\"1\"],[\"64474.4\",\"0.02\",\"0\",\"2\"],[\"64474.5\",\"0.03\",\"0\",\"1\"],[\"64474.7\",\"8.01\",\"0\",\"2\"],[\"64474.8\",\"0.11\",\"0\",\"1\"],[\"64474.9\",\"37.23\",\"0\",\"1\"],[\"64475\",\"263.06\",\"0\",\"9\"],[\"64475.3\",\"0.01\",\"0\",\"1\"],[\"64475.6\",\"25.23\",\"0\",\"6\"],[\"64475.7\",\"496.55\",\"0\",\"3\"],[\"64475.8\",\"46.54\",\"0\",\"1\"],[\"64475.9\",\"0.9\",\"0\",\"1\"],[\"64476\",\"0.03\",\"0\",\"3\"],[\"64476.2\",\"0.02\",\"0\",\"2\"],[\"64476.5\",\"31.19\",\"0\",\"2\"],[\"64476.7\",\"232.87\",\"0\",\"1\"],[\"64476.8\",\"318.1\",\"0\",\"5\"],[\"64476.9\",\"0.02\",\"0\",\"2\"],[\"64477\",\"2.62\",\"0\",\"2\"],[\"64477.3\",\"1.01\",\"0\",\"2\"],[\"64477.4\",\"0.09\",\"0\",\"3\"],[\"64477.5\",\"14.77\",\"0\",\"2\"],[\"64477.6\",\"0.07\",\"0\",\"1\"],[\"64477.8\",\"46.54\",\"0\",\"1\"],[\"64478\",\"0.02\",\"0\",\"2\"],[\"64478.3\",\"0.01\",\"0\",\"1\"],[\"64478.5\",\"1.55\",\"0\",\"1\"],[\"64478.6\",\"3.11\",\"0\",\"2\"],[\"64478.8\",\"0.01\",\"0\",\"1\"],[\"64479\",\"0.01\",\"0\",\"1\"],[\"64479.2\",\"15.81\",\"0\",\"4\"],[\"64479.6\",\"102.93\",\"0\",\"2\"],[\"64479.8\",\"496.54\",\"0\",\"2\"],[\"64479.9\",\"62.2\",\"0\",\"3\"],[\"64480\",\"55.67\",\"0\",\"44\"],[\"64480.1\",\"0.01\",\"0\",\"1\"],[\"64480.2\",\"37.23\",\"0\",\"1\"],[\"64480.4\",\"0.01\",\"0\",\"1\"],[\"64480.8\",\"6.22\",\"0\",\"1\"],[\"64481\",\"171.94\",\"0\",\"5\"],[\"64481.1\",\"62.3\",\"0\",\"2\"],[\"64481.2\",\"0.68\",\"0\",\"1\"],[\"64481.6\",\"0.01\",\"0\",\"1\"],[\"64481.8\",\"0.04\",\"0\",\"3\"],[\"64481.9\",\"0.01\",\"0\",\"1\"],[\"64482\",\"0.04\",\"0\",\"2\"],[\"64482.1\",\"0.01\",\"0\",\"1\"],[\"64482.5\",\"0.02\",\"0\",\"1\"],[\"64482.6\",\"0.78\",\"0\",\"2\"],[\"64482.7\",\"3.91\",\"0\",\"2\"],[\"64482.8\",\"0.41\",\"0\",\"2\"],[\"64482.9\",\"110.9\",\"0\",\"2\"],[\"64483\",\"200.31\",\"0\",\"2\"],[\"64483.1\",\"134.1\",\"0\",\"5\"],[\"64483.2\",\"114.69\",\"0\",\"3\"],[\"64483.3\",\"0.05\",\"0\",\"2\"],[\"64483.4\",\"312.16\",\"0\",\"1\"],[\"64483.5\",\"2.28\",\"0\",\"1\"],[\"64483.7\",\"0.01\",\"0\",\"1\"],[\"64483.9\",\"11.07\",\"0\",\"2\"],[\"64484\",\"0.02\",\"0\",\"2\"],[\"64484.1\",\"0.02\",\"0\",\"1\"],[\"64484.2\",\"15.65\",\"0\",\"1\"],[\"64484.3\",\"9.88\",\"0\",\"1\"],[\"64484.4\",\"16.25\",\"0\",\"2\"],[\"64484.5\",\"0.08\",\"0\",\"4\"],[\"64484.6\",\"1.21\",\"0\",\"2\"],[\"64484.7\",\"28.42\",\"0\",\"2\"],[\"64484.8\",\"496.53\",\"0\",\"1\"],[\"64484.9\",\"15.65\",\"0\",\"1\"],[\"64485\",\"41.95\",\"0\",\"2\"],[\"64485.1\",\"38.83\",\"0\",\"2\"],[\"64485.2\",\"0.01\",\"0\",\"1\"],[\"64485.5\",\"0.01\",\"0\",\"1\"],[\"64485.6\",\"15.65\",\"0\",\"1\"],[\"64485.7\",\"0.35\",\"0\",\"5\"],[\"64485.8\",\"0.4\",\"0\",\"2\"],[\"64485.9\",\"5.42\",\"0\",\"1\"],[\"64486\",\"101.09\",\"0\",\"7\"],[\"64486.2\",\"0.17\",\"0\",\"6\"],[\"64486.3\",\"179.9\",\"0\",\"4\"],[\"64486.4\",\"59.47\",\"0\",\"3\"],[\"64486.5\",\"15.65\",\"0\",\"1\"],[\"64486.6\",\"47.53\",\"0\",\"2\"],[\"64486.7\",\"0.01\",\"0\",\"1\"],[\"64486.8\",\"37.42\",\"0\",\"4\"],[\"64486.9\",\"0.12\",\"0\",\"2\"],[\"64487\",\"51.82\",\"0\",\"5\"],[\"64487.1\",\"0.53\",\"0\",\"4\"],[\"64487.2\",\"0.03\",\"0\",\"2\"],[\"64487.3\",\"0.04\",\"0\",\"2\"],[\"64487.4\",\"0.49\",\"0\",\"5\"],[\"64487.5\",\"43.47\",\"0\",\"6\"],[\"64487.6\",\"301.45\",\"0\",\"1\"],[\"64487.7\",\"130.34\",\"0\",\"4\"],[\"64487.8\",\"0.09\",\"0\",\"3\"],[\"64487.9\",\"0.01\",\"0\",\"1\"],[\"64488\",\"57.87\",\"0\",\"27\"],[\"64488.1\",\"86.04\",\"0\",\"3\"],[\"64488.2\",\"3.96\",\"0\",\"2\"],[\"64488.3\",\"38.84\",\"0\",\"2\"],[\"64488.4\",\"21.02\",\"0\",\"6\"],[\"64488.6\",\"0.02\",\"0\",\"2\"],[\"64488.7\",\"496.58\",\"0\",\"3\"],[\"64488.8\",\"50\",\"0\",\"1\"],[\"64488.9\",\"0.32\",\"0\",\"5\"],[\"64489\",\"57.94\",\"0\",\"9\"],[\"64489.1\",\"26.75\",\"0\",\"5\"],[\"64489.2\",\"69.9\",\"0\",\"1\"],[\"64489.3\",\"23.26\",\"0\",\"6\"],[\"64489.4\",\"2.91\",\"0\",\"4\"],[\"64489.5\",\"0.01\",\"0\",\"1\"],[\"64489.6\",\"0.13\",\"0\",\"3\"],[\"64489.7\",\"47.34\",\"0\",\"2\"],[\"64489.8\",\"31.34\",\"0\",\"5\"],[\"64489.9\",\"143.6\",\"0\",\"1\"],[\"64490\",\"55.77\",\"0\",\"19\"],[\"64490.1\",\"0.01\",\"0\",\"1\"],[\"64490.3\",\"1\",\"0\",\"1\"],[\"64490.4\",\"0.02\",\"0\",\"2\"],[\"64490.5\",\"17.16\",\"0\",\"3\"],[\"64490.6\",\"1.08\",\"0\",\"3\"],[\"64490.7\",\"0.07\",\"0\",\"3\"],[\"64490.9\",\"0.07\",\"0\",\"2\"],[\"64491\",\"80.13\",\"0\",\"2\"],[\"64491.2\",\"1.01\",\"0\",\"2\"],[\"64491.3\",\"0.02\",\"0\",\"2\"],[\"64491.4\",\"0.02\",\"0\",\"2\"],[\"64491.5\",\"0.1\",\"0\",\"1\"],[\"64491.6\",\"0.09\",\"0\",\"3\"],[\"64491.7\",\"0.02\",\"0\",\"2\"],[\"64491.8\",\"0.05\",\"0\",\"1\"],[\"64491.9\",\"0.31\",\"0\",\"5\"],[\"64492\",\"0.03\",\"0\",\"3\"],[\"64492.2\",\"1.9\",\"0\",\"7\"],[\"64492.3\",\"0.03\",\"0\",\"1\"],[\"64492.4\",\"11.35\",\"0\",\"5\"],[\"64492.5\",\"0.06\",\"0\",\"4\"],[\"64492.6\",\"106.92\",\"0\",\"2\"],[\"64492.7\",\"99.88\",\"0\",\"3\"],[\"64492.8\",\"0.13\",\"0\",\"7\"],[\"64492.9\",\"0.01\",\"0\",\"1\"],[\"64493\",\"13.72\",\"0\",\"4\"],[\"64493.1\",\"32.76\",\"0\",\"6\"],[\"64493.2\",\"399.82\",\"0\",\"8\"],[\"64493.3\",\"580.33\",\"0\",\"6\"],[\"64493.4\",\"0.32\",\"0\",\"5\"],[\"64493.5\",\"87.22\",\"0\",\"5\"],[\"64493.6\",\"148.86\",\"0\",\"1\"],[\"64493.7\",\"358.87\",\"0\",\"4\"],[\"64493.8\",\"0.04\",\"0\",\"3\"],[\"64494\",\"1.04\",\"0\",\"3\"],[\"64494.2\",\"20.07\",\"0\",\"1\"],[\"64494.3\",\"15.73\",\"0\",\"5\"],[\"64494.4\",\"0.23\",\"0\",\"6\"],[\"64494.6\",\"6.24\",\"0\",\"5\"],[\"64494.7\",\"24.55\",\"0\",\"6\"],[\"64494.8\",\"203.46\",\"0\",\"3\"],[\"64494.9\",\"1.27\",\"0\",\"4\"],[\"64495\",\"1.5\",\"0\",\"9\"],[\"64495.1\",\"0.07\",\"0\",\"3\"],[\"64495.2\",\"0.01\",\"0\",\"1\"],[\"64495.3\",\"1.46\",\"0\",\"3\"],[\"64495.4\",\"0.06\",\"0\",\"3\"],[\"64495.5\",\"6.32\",\"0\",\"4\"],[\"64495.6\",\"0.02\",\"0\",\"2\"],[\"64495.7\",\"27\",\"0\",\"4\"],[\"64495.8\",\"0.03\",\"0\",\"2\"],[\"64495.9\",\"4.74\",\"0\",\"4\"],[\"64496\",\"104.13\",\"0\",\"6\"],[\"64496.1\",\"0.06\",\"0\",\"3\"],[\"64496.2\",\"0.01\",\"0\",\"1\"],[\"64496.3\",\"0.3\",\"0\",\"4\"],[\"64496.4\",\"21.88\",\"0\",\"3\"],[\"64496.5\",\"46.51\",\"0\",\"1\"],[\"64496.6\",\"31.68\",\"0\",\"2\"],[\"64496.7\",\"22.72\",\"0\",\"2\"],[\"64496.8\",\"75.94\",\"0\",\"5\"],[\"64496.9\",\"449.69\",\"0\",\"2\"],[\"64497\",\"34.46\",\"0\",\"6\"],[\"64497.1\",\"0.01\",\"0\",\"1\"],[\"64497.2\",\"0.84\",\"0\",\"3\"],[\"64497.3\",\"41.14\",\"0\",\"4\"],[\"64497.4\",\"0.09\",\"0\",\"2\"],[\"64497.5\",\"0.33\",\"0\",\"3\"],[\"64497.6\",\"15.77\",\"0\",\"3\"],[\"64497.8\",\"0.01\",\"0\",\"1\"],[\"64497.9\",\"0.01\",\"0\",\"1\"],[\"64498\",\"497.29\",\"0\",\"3\"],[\"64498.1\",\"0.06\",\"0\",\"5\"],[\"64498.2\",\"0.03\",\"0\",\"2\"],[\"64498.3\",\"100.42\",\"0\",\"7\"],[\"64498.5\",\"4.51\",\"0\",\"5\"],[\"64498.6\",\"0.27\",\"0\",\"4\"],[\"64498.7\",\"2.36\",\"0\",\"3\"],[\"64498.8\",\"20.4\",\"0\",\"3\"],[\"64498.9\",\"40.65\",\"0\",\"3\"],[\"64499\",\"333.41\",\"0\",\"22\"],[\"64499.1\",\"0.15\",\"0\",\"3\"],[\"64499.2\",\"0.01\",\"0\",\"1\"],[\"64499.4\",\"1.72\",\"0\",\"2\"],[\"64499.5\",\"2.28\",\"0\",\"1\"],[\"64499.6\",\"74.53\",\"0\",\"4\"],[\"64499.7\",\"35.37\",\"0\",\"5\"],[\"64499.8\",\"19.95\",\"0\",\"3\"],[\"64499.9\",\"1162.28\",\"0\",\"3\"],[\"64500\",\"3472.47\",\"0\",\"1034\"],[\"64500.1\",\"0.05\",\"0\",\"4\"],[\"64500.2\",\"0.01\",\"0\",\"1\"],[\"64500.3\",\"2.77\",\"0\",\"4\"],[\"64500.4\",\"0.04\",\"0\",\"4\"],[\"64500.5\",\"2.49\",\"0\",\"2\"],[\"64500.6\",\"0.38\",\"0\",\"2\"],[\"64500.7\",\"3.92\",\"0\",\"2\"],[\"64500.8\",\"0.36\",\"0\",\"1\"],[\"64500.9\",\"73.16\",\"0\",\"6\"],[\"64501\",\"0.27\",\"0\",\"3\"],[\"64501.1\",\"0.05\",\"0\",\"2\"],[\"64501.2\",\"0.02\",\"0\",\"2\"],[\"64501.3\",\"0.02\",\"0\",\"1\"],[\"64501.4\",\"0.01\",\"0\",\"1\"],[\"64501.5\",\"4.67\",\"0\",\"5\"],[\"64501.6\",\"1.89\",\"0\",\"3\"],[\"64501.7\",\"0.53\",\"0\",\"2\"],[\"64501.8\",\"59\",\"0\",\"5\"],[\"64501.9\",\"0.08\",\"0\",\"1\"],[\"64502\",\"3.11\",\"0\",\"6\"],[\"64502.1\",\"0.01\",\"0\",\"1\"],[\"64502.2\",\"15.76\",\"0\",\"4\"],[\"64502.3\",\"11.33\",\"0\",\"3\"],[\"64502.4\",\"0.18\",\"0\",\"5\"],[\"64502.5\",\"0.2\",\"0\",\"3\"],[\"64502.6\",\"0.01\",\"0\",\"1\"],[\"64502.7\",\"0.03\",\"0\",\"3\"],[\"64502.8\",\"10.53\",\"0\",\"2\"],[\"64502.9\",\"0.99\",\"0\",\"4\"],[\"64503\",\"15.94\",\"0\",\"2\"],[\"64503.1\",\"0.86\",\"0\",\"7\"],[\"64503.2\",\"16.37\",\"0\",\"4\"],[\"64503.3\",\"0.02\",\"0\",\"2\"],[\"64503.5\",\"63.72\",\"0\",\"6\"],[\"64503.6\",\"17.98\",\"0\",\"3\"],[\"64503.7\",\"0.29\",\"0\",\"2\"],[\"64503.9\",\"20.45\",\"0\",\"1\"],[\"64504\",\"17.31\",\"0\",\"6\"],[\"64504.1\",\"581.2\",\"0\",\"8\"],[\"64504.2\",\"16.06\",\"0\",\"3\"],[\"64504.3\",\"0.04\",\"0\",\"2\"],[\"64504.4\",\"1.13\",\"0\",\"4\"],[\"64504.5\",\"73.8\",\"0\",\"6\"],[\"64504.7\",\"0.01\",\"0\",\"1\"],[\"64504.8\",\"0.08\",\"0\",\"2\"],[\"64504.9\",\"0.1\",\"0\",\"3\"],[\"64505\",\"0.82\",\"0\",\"3\"],[\"64505.1\",\"0.02\",\"0\",\"2\"],[\"64505.3\",\"1.16\",\"0\",\"2\"],[\"64505.4\",\"59.22\",\"0\",\"3\"],[\"64505.5\",\"3.91\",\"0\",\"2\"],[\"64505.6\",\"11.43\",\"0\",\"3\"],[\"64505.7\",\"0.56\",\"0\",\"1\"],[\"64505.8\",\"21.95\",\"0\",\"3\"],[\"64505.9\",\"0.01\",\"0\",\"1\"],[\"64506\",\"10.05\",\"0\",\"3\"],[\"64506.1\",\"0.06\",\"0\",\"1\"],[\"64506.2\",\"0.03\",\"0\",\"2\"],[\"64506.4\",\"0.03\",\"0\",\"3\"],[\"64506.5\",\"0.07\",\"0\",\"1\"],[\"64506.6\",\"10.15\",\"0\",\"3\"],[\"64506.7\",\"0.19\",\"0\",\"15\"],[\"64506.8\",\"1.05\",\"0\",\"4\"],[\"64506.9\",\"0.01\",\"0\",\"1\"],[\"64507\",\"46.6\",\"0\",\"2\"],[\"64507.1\",\"0.06\",\"0\",\"4\"],[\"64507.2\",\"14.03\",\"0\",\"2\"],[\"64507.3\",\"0.03\",\"0\",\"2\"],[\"64507.4\",\"27.31\",\"0\",\"5\"],[\"64507.5\",\"15.77\",\"0\",\"6\"],[\"64507.6\",\"0.03\",\"0\",\"2\"],[\"64507.7\",\"0.07\",\"0\",\"4\"],[\"64507.8\",\"2.83\",\"0\",\"3\"],[\"64507.9\",\"0.25\",\"0\",\"2\"],[\"64508\",\"13.54\",\"0\",\"7\"],[\"64508.1\",\"21.31\",\"0\",\"3\"],[\"64508.2\",\"59.01\",\"0\",\"5\"],[\"64508.4\",\"1.62\",\"0\",\"5\"],[\"64508.5\",\"42.46\",\"0\",\"3\"],[\"64508.6\",\"0.01\",\"0\",\"1\"],[\"64508.7\",\"42.88\",\"0\",\"9\"],[\"64508.8\",\"0.04\",\"0\",\"2\"],[\"64508.9\",\"11.24\",\"0\",\"3\"],[\"64509\",\"155.92\",\"0\",\"2\"],[\"64509.1\",\"0.02\",\"0\",\"2\"]],\"bids\":[[\"64457.9\",\"348.13\",\"0\",\"15\"],[\"64457.8\",\"0.14\",\"0\",\"2\"],[\"64457.7\",\"0.32\",\"0\",\"1\"],[\"64457.1\",\"0.32\",\"0\",\"1\"],[\"64457\",\"0.01\",\"0\",\"1\"],[\"64456.6\",\"0.07\",\"0\",\"1\"],[\"64456.4\",\"0.01\",\"0\",\"1\"],[\"64456.1\",\"0.01\",\"0\",\"1\"],[\"64456\",\"0.01\",\"0\",\"1\"],[\"64455.9\",\"0.01\",\"0\",\"1\"],[\"64455.7\",\"0.02\",\"0\",\"2\"],[\"64455.6\",\"37.41\",\"0\",\"1\"],[\"64455.3\",\"0.01\",\"0\",\"1\"],[\"64455.2\",\"0.04\",\"0\",\"4\"],[\"64455\",\"0.01\",\"0\",\"1\"],[\"64454.8\",\"0.02\",\"0\",\"2\"],[\"64454.7\",\"37.26\",\"0\",\"3\"],[\"64454.6\",\"0.82\",\"0\",\"3\"],[\"64454.5\",\"46.55\",\"0\",\"2\"],[\"64454.4\",\"145.71\",\"0\",\"9\"],[\"64454.3\",\"0.01\",\"0\",\"1\"],[\"64454.2\",\"0.01\",\"0\",\"1\"],[\"64454.1\",\"4.02\",\"0\",\"3\"],[\"64454\",\"8.01\",\"0\",\"2\"],[\"64453.9\",\"0.01\",\"0\",\"1\"],[\"64453.8\",\"0.77\",\"0\",\"1\"],[\"64453.6\",\"0.01\",\"0\",\"1\"],[\"64453.5\",\"0.01\",\"0\",\"1\"],[\"64453.2\",\"0.31\",\"0\",\"1\"],[\"64453.1\",\"1.57\",\"0\",\"2\"],[\"64452.9\",\"0.01\",\"0\",\"1\"],[\"64452.8\",\"0.05\",\"0\",\"1\"],[\"64452.7\",\"0.3\",\"0\",\"1\"],[\"64452.6\",\"1.56\",\"0\",\"1\"],[\"64452.3\",\"0.01\",\"0\",\"1\"],[\"64452.2\",\"0.01\",\"0\",\"1\"],[\"64452.1\",\"2.36\",\"0\",\"5\"],[\"64452\",\"44.31\",\"0\",\"7\"],[\"64451.9\",\"47.94\",\"0\",\"2\"],[\"64451.7\",\"98.53\",\"0\",\"2\"],[\"64451.6\",\"69.69\",\"0\",\"2\"],[\"64451.5\",\"15.9\",\"0\",\"1\"],[\"64451.4\",\"35.37\",\"0\",\"3\"],[\"64451.3\",\"93.14\",\"0\",\"9\"],[\"64451.2\",\"359.95\",\"0\",\"4\"],[\"64451\",\"0.02\",\"0\",\"2\"],[\"64450.9\",\"1.6\",\"0\",\"1\"],[\"64450.8\",\"31.54\",\"0\",\"3\"],[\"64450.7\",\"0.04\",\"0\",\"2\"],[\"64450.6\",\"1.56\",\"0\",\"1\"],[\"64450.5\",\"4.9\",\"0\",\"3\"],[\"64450.4\",\"0.62\",\"0\",\"2\"],[\"64450.3\",\"42.63\",\"0\",\"2\"],[\"64450.2\",\"33.92\",\"0\",\"3\"],[\"64450.1\",\"40.77\",\"0\",\"1\"],[\"64450\",\"2.19\",\"0\",\"4\"],[\"64449.9\",\"15.94\",\"0\",\"1\"],[\"64449.8\",\"2.89\",\"0\",\"2\"],[\"64449.7\",\"46.58\",\"0\",\"2\"],[\"64449.6\",\"512.53\",\"0\",\"4\"],[\"64449.5\",\"37.23\",\"0\",\"1\"],[\"64449.4\",\"18.93\",\"0\",\"3\"],[\"64449.3\",\"16.22\",\"0\",\"2\"],[\"64449.2\",\"3.01\",\"0\",\"2\"],[\"64449.1\",\"0.01\",\"0\",\"1\"],[\"64449\",\"0.03\",\"0\",\"3\"],[\"64448.7\",\"2.4\",\"0\",\"1\"],[\"64448.6\",\"0.01\",\"0\",\"1\"],[\"64448.3\",\"16.01\",\"0\",\"3\"],[\"64448.2\",\"247.83\",\"0\",\"3\"],[\"64448.1\",\"10.01\",\"0\",\"2\"],[\"64448\",\"321.71\",\"0\",\"10\"],[\"64447.9\",\"8\",\"0\",\"1\"],[\"64447.8\",\"0.39\",\"0\",\"2\"],[\"64447.4\",\"10.77\",\"0\",\"2\"],[\"64447.3\",\"42.48\",\"0\",\"3\"],[\"64447.2\",\"0.38\",\"0\",\"1\"],[\"64447.1\",\"0.3\",\"0\",\"1\"],[\"64447\",\"83.8\",\"0\",\"1\"],[\"64446.9\",\"21.3\",\"0\",\"3\"],[\"64446.8\",\"0.01\",\"0\",\"1\"],[\"64446.4\",\"46.54\",\"0\",\"1\"],[\"64446.3\",\"48.85\",\"0\",\"3\"],[\"64446.2\",\"0.07\",\"0\",\"1\"],[\"64446\",\"0.04\",\"0\",\"2\"],[\"64445.9\",\"0.03\",\"0\",\"3\"],[\"64445.8\",\"1.51\",\"0\",\"2\"],[\"64445.7\",\"506.54\",\"0\",\"3\"],[\"64445.6\",\"3.9\",\"0\",\"2\"],[\"64445.4\",\"0.15\",\"0\",\"1\"],[\"64445.1\",\"184.61\",\"0\",\"4\"],[\"64445\",\"134.03\",\"0\",\"6\"],[\"64444.9\",\"10.54\",\"0\",\"2\"],[\"64444.8\",\"0.02\",\"0\",\"2\"],[\"64444.4\",\"10\",\"0\",\"1\"],[\"64444.3\",\"37.23\",\"0\",\"1\"],[\"64444.2\",\"0.01\",\"0\",\"1\"],[\"64444.1\",\"0.01\",\"0\",\"1\"],[\"64444\",\"33.84\",\"0\",\"3\"],[\"64443.8\",\"20.86\",\"0\",\"2\"],[\"64443.7\",\"123.83\",\"0\",\"5\"],[\"64443.6\",\"0.01\",\"0\",\"1\"],[\"64443.4\",\"405.22\",\"0\",\"2\"],[\"64443.3\",\"133.31\",\"0\",\"3\"],[\"64443.2\",\"135.69\",\"0\",\"7\"],[\"64443\",\"0.02\",\"0\",\"2\"],[\"64442.8\",\"0.03\",\"0\",\"3\"],[\"64442.7\",\"85.42\",\"0\",\"1\"],[\"64442.6\",\"15.65\",\"0\",\"1\"],[\"64442.4\",\"0.01\",\"0\",\"1\"],[\"64442.3\",\"18.13\",\"0\",\"2\"],[\"64442.1\",\"6.22\",\"0\",\"1\"],[\"64442\",\"77.63\",\"0\",\"4\"],[\"64441.9\",\"36.94\",\"0\",\"2\"],[\"64441.8\",\"535.35\",\"0\",\"2\"],[\"64441.7\",\"0.02\",\"0\",\"1\"],[\"64441.6\",\"278.86\",\"0\",\"5\"],[\"64441.5\",\"61.29\",\"0\",\"2\"],[\"64441.4\",\"50.02\",\"0\",\"3\"],[\"64441.3\",\"50\",\"0\",\"1\"],[\"64441.1\",\"13.9\",\"0\",\"2\"],[\"64441\",\"3.11\",\"0\",\"2\"],[\"64440.9\",\"0.01\",\"0\",\"1\"],[\"64440.6\",\"10.01\",\"0\",\"2\"],[\"64440.5\",\"7.73\",\"0\",\"1\"],[\"64440.4\",\"0.01\",\"0\",\"1\"],[\"64440.3\",\"0.04\",\"0\",\"2\"],[\"64440.2\",\"0.01\",\"0\",\"1\"],[\"64440.1\",\"113.31\",\"0\",\"3\"],[\"64440\",\"99.43\",\"0\",\"5\"],[\"64439.9\",\"62.17\",\"0\",\"2\"],[\"64439.7\",\"15.67\",\"0\",\"3\"],[\"64439.5\",\"0.01\",\"0\",\"1\"],[\"64439.4\",\"0.01\",\"0\",\"1\"],[\"64439.3\",\"99.78\",\"0\",\"1\"],[\"64439\",\"0.01\",\"0\",\"1\"],[\"64438.9\",\"37.23\",\"0\",\"1\"],[\"64438.7\",\"4.99\",\"0\",\"2\"],[\"64438.6\",\"12.78\",\"0\",\"4\"],[\"64438.5\",\"16.46\",\"0\",\"3\"],[\"64438.4\",\"0.01\",\"0\",\"1\"],[\"64438.3\",\"0.01\",\"0\",\"1\"],[\"64438.2\",\"58.26\",\"0\",\"2\"],[\"64438.1\",\"15.69\",\"0\",\"2\"],[\"64438\",\"0.01\",\"0\",\"1\"],[\"64437.9\",\"15.65\",\"0\",\"1\"],[\"64437.8\",\"0.01\",\"0\",\"1\"],[\"64437.7\",\"0.01\",\"0\",\"1\"],[\"64437.6\",\"0.01\",\"0\",\"1\"],[\"64437.4\",\"31.06\",\"0\",\"1\"],[\"64437.3\",\"15.65\",\"0\",\"1\"],[\"64437.2\",\"37.27\",\"0\",\"4\"],[\"64437.1\",\"0.3\",\"0\",\"2\"],[\"64437\",\"236.94\",\"0\",\"2\"],[\"64436.9\",\"354.24\",\"0\",\"2\"],[\"64436.8\",\"0.02\",\"0\",\"1\"],[\"64436.7\",\"31.39\",\"0\",\"3\"],[\"64436.6\",\"10.03\",\"0\",\"4\"],[\"64436.5\",\"11.31\",\"0\",\"3\"],[\"64436.4\",\"15.84\",\"0\",\"2\"],[\"64436.3\",\"101.03\",\"0\",\"3\"],[\"64436.1\",\"25.65\",\"0\",\"2\"],[\"64436\",\"201.01\",\"0\",\"3\"],[\"64435.9\",\"0.01\",\"0\",\"1\"],[\"64435.8\",\"0.07\",\"0\",\"1\"],[\"64435.6\",\"28.42\",\"0\",\"2\"],[\"64435.5\",\"512.2\",\"0\",\"3\"],[\"64435.4\",\"262.87\",\"0\",\"3\"],[\"64435.3\",\"0.01\",\"0\",\"1\"],[\"64435.2\",\"0.02\",\"0\",\"2\"],[\"64435.1\",\"0.01\",\"0\",\"1\"],[\"64434.9\",\"15.7\",\"0\",\"2\"],[\"64434.8\",\"54.47\",\"0\",\"2\"],[\"64434.7\",\"10.01\",\"0\",\"2\"],[\"64434.6\",\"0.5\",\"0\",\"1\"],[\"64434.3\",\"3.11\",\"0\",\"2\"],[\"64434.2\",\"0.02\",\"0\",\"2\"],[\"64434.1\",\"0.35\",\"0\",\"2\"],[\"64434\",\"15.66\",\"0\",\"2\"],[\"64433.9\",\"80.95\",\"0\",\"2\"],[\"64433.8\",\"6.23\",\"0\",\"2\"],[\"64433.7\",\"47.23\",\"0\",\"2\"],[\"64433.5\",\"0.02\",\"0\",\"2\"],[\"64433.4\",\"46.56\",\"0\",\"3\"],[\"64433.3\",\"17.97\",\"0\",\"4\"],[\"64433.2\",\"21.29\",\"0\",\"2\"],[\"64433.1\",\"15.65\",\"0\",\"1\"],[\"64433\",\"4.07\",\"0\",\"2\"],[\"64432.8\",\"0.01\",\"0\",\"1\"],[\"64432.6\",\"15.71\",\"0\",\"4\"],[\"64432.5\",\"0.01\",\"0\",\"1\"],[\"64432.3\",\"0.02\",\"0\",\"2\"],[\"64432.2\",\"46.57\",\"0\",\"2\"],[\"64432.1\",\"0.08\",\"0\",\"1\"],[\"64432\",\"64.4\",\"0\",\"5\"],[\"64431.9\",\"17.93\",\"0\",\"2\"],[\"64431.8\",\"15.87\",\"0\",\"2\"],[\"64431.7\",\"321.87\",\"0\",\"2\"],[\"64431.6\",\"496.54\",\"0\",\"2\"],[\"64431.5\",\"15.65\",\"0\",\"1\"],[\"64431.4\",\"198.51\",\"0\",\"3\"],[\"64431.3\",\"15.66\",\"0\",\"2\"],[\"64431.2\",\"46.54\",\"0\",\"1\"],[\"64431.1\",\"0.01\",\"0\",\"1\"],[\"64431\",\"4.06\",\"0\",\"17\"],[\"64430.7\",\"15.65\",\"0\",\"1\"],[\"64430.4\",\"0.04\",\"0\",\"4\"],[\"64430.3\",\"1.01\",\"0\",\"2\"],[\"64430.1\",\"15.67\",\"0\",\"3\"],[\"64430\",\"7.12\",\"0\",\"5\"],[\"64429.9\",\"12.37\",\"0\",\"4\"],[\"64429.8\",\"35.67\",\"0\",\"4\"],[\"64429.4\",\"155.94\",\"0\",\"3\"],[\"64429.2\",\"46.65\",\"0\",\"2\"],[\"64429.1\",\"0.02\",\"0\",\"1\"],[\"64428.9\",\"16.49\",\"0\",\"1\"],[\"64428.8\",\"0.02\",\"0\",\"2\"],[\"64428.6\",\"0.04\",\"0\",\"2\"],[\"64428.4\",\"37.23\",\"0\",\"1\"],[\"64428.2\",\"15.66\",\"0\",\"2\"],[\"64428.1\",\"0.65\",\"0\",\"2\"],[\"64428\",\"15.75\",\"0\",\"5\"],[\"64427.9\",\"3.88\",\"0\",\"1\"],[\"64427.8\",\"1.06\",\"0\",\"1\"],[\"64427.7\",\"387.46\",\"0\",\"4\"],[\"64427.6\",\"0.01\",\"0\",\"1\"],[\"64427.3\",\"255.84\",\"0\",\"5\"],[\"64427.2\",\"496.54\",\"0\",\"2\"],[\"64427\",\"266.25\",\"0\",\"5\"],[\"64426.8\",\"0.06\",\"0\",\"1\"],[\"64426.7\",\"46.66\",\"0\",\"13\"],[\"64426.6\",\"0.01\",\"0\",\"1\"],[\"64426.5\",\"15.69\",\"0\",\"2\"],[\"64426.4\",\"0.01\",\"0\",\"1\"],[\"64426.1\",\"0.77\",\"0\",\"1\"],[\"64426\",\"0.03\",\"0\",\"2\"],[\"64425.9\",\"15.65\",\"0\",\"1\"],[\"64425.8\",\"0.01\",\"0\",\"1\"],[\"64425.7\",\"4.01\",\"0\",\"2\"],[\"64425.6\",\"3.91\",\"0\",\"2\"],[\"64425.5\",\"11.06\",\"0\",\"1\"],[\"64425.4\",\"6.27\",\"0\",\"2\"],[\"64425.2\",\"0.79\",\"0\",\"3\"],[\"64425\",\"17.21\",\"0\",\"8\"],[\"64424.9\",\"15.66\",\"0\",\"2\"],[\"64424.6\",\"0.02\",\"0\",\"2\"],[\"64424.3\",\"46.54\",\"0\",\"1\"],[\"64424.2\",\"0.01\",\"0\",\"1\"],[\"64424.1\",\"42.31\",\"0\",\"1\"],[\"64424\",\"1.38\",\"0\",\"6\"],[\"64423.9\",\"0.05\",\"0\",\"1\"],[\"64423.8\",\"17.49\",\"0\",\"3\"],[\"64423.4\",\"198.67\",\"0\",\"2\"],[\"64423.3\",\"496.84\",\"0\",\"2\"],[\"64423.2\",\"52.88\",\"0\",\"2\"],[\"64423.1\",\"0.01\",\"0\",\"1\"],[\"64423\",\"1.59\",\"0\",\"6\"],[\"64422.8\",\"0.02\",\"0\",\"2\"],[\"64422.7\",\"0.02\",\"0\",\"1\"],[\"64422.6\",\"98.94\",\"0\",\"3\"],[\"64422.4\",\"326.23\",\"0\",\"4\"],[\"64422.2\",\"11.09\",\"0\",\"4\"],[\"64422\",\"0.03\",\"0\",\"3\"],[\"64421.9\",\"0.16\",\"0\",\"2\"],[\"64421.8\",\"0.03\",\"0\",\"2\"],[\"64421.7\",\"15.65\",\"0\",\"1\"],[\"64421.6\",\"15.66\",\"0\",\"2\"],[\"64421.5\",\"0.8\",\"0\",\"2\"],[\"64421.4\",\"46.54\",\"0\",\"1\"],[\"64421.3\",\"0.03\",\"0\",\"2\"],[\"64421.2\",\"0.01\",\"0\",\"1\"],[\"64421.1\",\"21.53\",\"0\",\"4\"],[\"64421\",\"0.01\",\"0\",\"1\"],[\"64420.9\",\"19.81\",\"0\",\"3\"],[\"64420.7\",\"0.03\",\"0\",\"1\"],[\"64420.6\",\"100.58\",\"0\",\"1\"],[\"64420.5\",\"0.02\",\"0\",\"2\"],[\"64420.4\",\"0.27\",\"0\",\"2\"],[\"64420.3\",\"1\",\"0\",\"1\"],[\"64420.2\",\"80.61\",\"0\",\"3\"],[\"64420\",\"29.55\",\"0\",\"22\"],[\"64419.9\",\"18.91\",\"0\",\"3\"],[\"64419.8\",\"0.02\",\"0\",\"2\"],[\"64419.7\",\"20.01\",\"0\",\"2\"],[\"64419.6\",\"0.03\",\"0\",\"3\"],[\"64419.5\",\"212.33\",\"0\",\"3\"],[\"64419.4\",\"33.02\",\"0\",\"2\"],[\"64419.3\",\"552.33\",\"0\",\"4\"],[\"64419.2\",\"46.56\",\"0\",\"3\"],[\"64419.1\",\"0.02\",\"0\",\"2\"],[\"64419\",\"0.03\",\"0\",\"3\"],[\"64418.9\",\"11.06\",\"0\",\"1\"],[\"64418.8\",\"0.02\",\"0\",\"1\"],[\"64418.7\",\"0.01\",\"0\",\"1\"],[\"64418.6\",\"0.3\",\"0\",\"2\"],[\"64418.5\",\"0.05\",\"0\",\"1\"],[\"64418.4\",\"0.97\",\"0\",\"1\"],[\"64418.3\",\"15.65\",\"0\",\"1\"],[\"64418.1\",\"15.31\",\"0\",\"1\"],[\"64418\",\"20.53\",\"0\",\"4\"],[\"64417.9\",\"2.28\",\"0\",\"1\"],[\"64417.8\",\"0.02\",\"0\",\"2\"],[\"64417.7\",\"0.04\",\"0\",\"1\"],[\"64417.6\",\"0.02\",\"0\",\"2\"],[\"64417.5\",\"0.02\",\"0\",\"2\"],[\"64417.4\",\"0.35\",\"0\",\"8\"],[\"64417.2\",\"0.02\",\"0\",\"2\"],[\"64417.1\",\"3.9\",\"0\",\"1\"],[\"64417\",\"0.12\",\"0\",\"1\"],[\"64416.9\",\"68.68\",\"0\",\"4\"],[\"64416.8\",\"0.01\",\"0\",\"1\"],[\"64416.7\",\"45.2\",\"0\",\"3\"],[\"64416.6\",\"15.66\",\"0\",\"2\"],[\"64416.5\",\"0.08\",\"0\",\"1\"],[\"64416.3\",\"47.19\",\"0\",\"6\"],[\"64416.2\",\"101.76\",\"0\",\"4\"],[\"64416\",\"298.13\",\"0\",\"7\"],[\"64415.7\",\"1.18\",\"0\",\"1\"],[\"64415.6\",\"30.86\",\"0\",\"3\"],[\"64415.5\",\"20\",\"0\",\"1\"],[\"64415.4\",\"0.01\",\"0\",\"1\"],[\"64415.3\",\"581.08\",\"0\",\"5\"],[\"64415.2\",\"0.02\",\"0\",\"2\"],[\"64415.1\",\"6.91\",\"0\",\"2\"],[\"64415\",\"15.88\",\"0\",\"4\"],[\"64414.9\",\"2.32\",\"0\",\"2\"],[\"64414.8\",\"19.02\",\"0\",\"1\"],[\"64414.7\",\"26.09\",\"0\",\"3\"],[\"64414.6\",\"0.31\",\"0\",\"1\"],[\"64414.5\",\"1365.58\",\"0\",\"1\"],[\"64414.4\",\"99.09\",\"0\",\"1\"],[\"64414.2\",\"0.02\",\"0\",\"2\"],[\"64414.1\",\"0.11\",\"0\",\"2\"],[\"64414\",\"0.01\",\"0\",\"1\"],[\"64413.9\",\"23.27\",\"0\",\"1\"],[\"64413.8\",\"0.01\",\"0\",\"1\"],[\"64413.3\",\"15.69\",\"0\",\"4\"],[\"64413.1\",\"64.55\",\"0\",\"2\"],[\"64412.9\",\"0.01\",\"0\",\"1\"],[\"64412.8\",\"0.01\",\"0\",\"1\"],[\"64412.7\",\"0.09\",\"0\",\"3\"],[\"64412.4\",\"0.01\",\"0\",\"1\"],[\"64412.3\",\"11.43\",\"0\",\"2\"],[\"64412.2\",\"99.58\",\"0\",\"1\"],[\"64412.1\",\"50\",\"0\",\"1\"],[\"64412\",\"0.02\",\"0\",\"1\"],[\"64411.8\",\"0.01\",\"0\",\"1\"],[\"64411.7\",\"15.68\",\"0\",\"2\"],[\"64411.5\",\"0.01\",\"0\",\"1\"],[\"64411.4\",\"3.38\",\"0\",\"2\"],[\"64411.3\",\"0.01\",\"0\",\"1\"],[\"64411.2\",\"15.33\",\"0\",\"1\"],[\"64411.1\",\"0.06\",\"0\",\"2\"],[\"64410.9\",\"2.08\",\"0\",\"3\"],[\"64410.8\",\"0.03\",\"0\",\"2\"],[\"64410.6\",\"0.39\",\"0\",\"2\"],[\"64410.5\",\"46.54\",\"0\",\"1\"],[\"64410.4\",\"0.32\",\"0\",\"2\"],[\"64410.3\",\"0.06\",\"0\",\"2\"],[\"64410.2\",\"6.23\",\"0\",\"2\"],[\"64410.1\",\"0.81\",\"0\",\"4\"],[\"64410\",\"1.56\",\"0\",\"5\"],[\"64409.9\",\"0.1\",\"0\",\"4\"],[\"64409.8\",\"106.39\",\"0\",\"1\"],[\"64409.7\",\"0.03\",\"0\",\"3\"],[\"64409.6\",\"0.24\",\"0\",\"2\"],[\"64409.1\",\"0.85\",\"0\",\"4\"],[\"64409\",\"11.42\",\"0\",\"1\"],[\"64408.9\",\"69.14\",\"0\",\"5\"],[\"64408.8\",\"0.01\",\"0\",\"1\"],[\"64408.7\",\"5.45\",\"0\",\"4\"],[\"64408.4\",\"7.93\",\"0\",\"5\"],[\"64408.3\",\"0.03\",\"0\",\"1\"],[\"64408.2\",\"83.77\",\"0\",\"2\"],[\"64408.1\",\"0.01\",\"0\",\"1\"],[\"64408\",\"4.48\",\"0\",\"6\"],[\"64407.9\",\"0.04\",\"0\",\"4\"],[\"64407.6\",\"0.02\",\"0\",\"2\"],[\"64407.5\",\"496.53\",\"0\",\"1\"],[\"64407.4\",\"0.51\",\"0\",\"1\"],[\"64407.3\",\"99.78\",\"0\",\"1\"],[\"64407.2\",\"0.05\",\"0\",\"1\"],[\"64407\",\"0.37\",\"0\",\"4\"],[\"64406.9\",\"0.01\",\"0\",\"1\"],[\"64406.7\",\"11.06\",\"0\",\"3\"],[\"64406.6\",\"3.92\",\"0\",\"2\"],[\"64406.4\",\"0.12\",\"0\",\"2\"],[\"64406.3\",\"0.32\",\"0\",\"1\"],[\"64406.1\",\"0.02\",\"0\",\"2\"],[\"64405.9\",\"1.93\",\"0\",\"1\"],[\"64405.7\",\"15.85\",\"0\",\"2\"],[\"64405.6\",\"0.01\",\"0\",\"1\"],[\"64405.5\",\"0.02\",\"0\",\"2\"],[\"64405.4\",\"0.04\",\"0\",\"4\"],[\"64405.3\",\"46.54\",\"0\",\"1\"],[\"64405.2\",\"239.07\",\"0\",\"5\"],[\"64405.1\",\"0.07\",\"0\",\"3\"],[\"64405\",\"13.52\",\"0\",\"15\"],[\"64404.8\",\"0.04\",\"0\",\"1\"],[\"64404.7\",\"0.77\",\"0\",\"1\"]],\"ts\":\"1782015903905\",\"checksum\":-1542200443,\"seqId\":325069852478,\"prevSeqId\":-1}]}"}
{"action": "update", "capture_sequence": 4, "channel": "books", "connection_sequence": 1, "event": null, "instId": "BTC-USDT-SWAP", "local_receive_ts": "2026-06-21T04:25:04Z", "monotonic_ns": 1643459930750371, "raw": "{\"arg\":{\"channel\":\"books\",\"instId\":\"BTC-USDT-SWAP\"},\"action\":\"update\",\"data\":[{\"asks\":[[\"64458\",\"1534.28\",\"0\",\"69\"],[\"64472.7\",\"39.52\",\"0\",\"3\"],[\"64472.8\",\"4\",\"0\",\"1\"],[\"64476.4\",\"232.87\",\"0\",\"1\"],[\"64476.7\",\"0\",\"0\",\"0\"],[\"64482.6\",\"0.01\",\"0\",\"1\"],[\"64482.9\",\"111.67\",\"0\",\"3\"],[\"64483.1\",\"100.3\",\"0\",\"4\"],[\"64483.2\",\"148.49\",\"0\",\"4\"],[\"64493.1\",\"118.89\",\"0\",\"7\"],[\"64493.5\",\"1.09\",\"0\",\"4\"]],\"bids\":[[\"64453.8\",\"2.33\",\"0\",\"2\"],[\"64451.2\",\"361.51\",\"0\",\"5\"],[\"64450.7\",\"1.6\",\"0\",\"3\"],[\"64450.2\",\"35.48\",\"0\",\"4\"],[\"64445\",\"2.03\",\"0\",\"4\"],[\"64444.4\",\"43.82\",\"0\",\"2\"],[\"64444.1\",\"0.78\",\"0\",\"2\"],[\"64444\",\"0.02\",\"0\",\"2\"],[\"64443.8\",\"20.09\",\"0\",\"1\"],[\"64443.7\",\"37.63\",\"0\",\"4\"],[\"64443.5\",\"86.2\",\"0\",\"1\"],[\"64438.6\",\"71.03\",\"0\",\"5\"],[\"64438.2\",\"0.01\",\"0\",\"1\"],[\"64437.1\",\"233.31\",\"0\",\"3\"],[\"64437\",\"3.93\",\"0\",\"1\"],[\"64404.7\",\"0\",\"0\",\"0\"]],\"ts\":\"1782015904005\",\"checksum\":938746838,\"seqId\":325069852527,\"prevSeqId\":325069852478}]}"}
{"action": "update", "capture_sequence": 5, "channel": "books", "connection_sequence": 1, "event": null, "instId": "BTC-USDT-SWAP", "local_receive_ts": "2026-06-21T04:25:04Z", "monotonic_ns": 1643460037666152, "raw": "{\"arg\":{\"channel\":\"books\",\"instId\":\"BTC-USDT-SWAP\"},\"action\":\"update\",\"data\":[{\"asks\":[[\"64458\",\"1534.29\",\"0\",\"69\"],[\"64471.9\",\"15.54\",\"0\",\"3\"],[\"64472.7\",\"24\",\"0\",\"2\"],[\"64474.9\",\"68.27\",\"0\",\"2\"],[\"64475.5\",\"232.87\",\"0\",\"1\"],[\"64475.7\",\"496.54\",\"0\",\"2\"],[\"64475.8\",\"46.55\",\"0\",\"2\"],[\"64476.4\",\"0\",\"0\",\"0\"],[\"64476.5\",\"0.15\",\"0\",\"1\"],[\"64477.7\",\"1.55\",\"0\",\"1\"],[\"64478.5\",\"0\",\"0\",\"0\"],[\"64483\",\"200\",\"0\",\"1\"],[\"64483.1\",\"134.41\",\"0\",\"6\"],[\"64483.2\",\"114.69\",\"0\",\"3\"],[\"64494.2\",\"0\",\"0\",\"0\"],[\"64494.3\",\"35.8\",\"0\",\"6\"],[\"64509.3\",\"0.28\",\"0\",\"5\"]],\"bids\":[[\"64457.9\",\"316.06\",\"0\",\"14\"],[\"64453.8\",\"0.77\",\"0\",\"1\"],[\"64453.6\",\"1.57\",\"0\",\"2\"],[\"64453.2\",\"0\",\"0\",\"0\"],[\"64452.7\",\"0.61\",\"0\",\"2\"],[\"64452.1\",\"1.59\",\"0\",\"4\"],[\"64451.3\",\"15.57\",\"0\",\"8\"],[\"64450.9\",\"2.37\",\"0\",\"2\"],[\"64450.8\",\"109.11\",\"0\",\"4\"],[\"64445\",\"134.03\",\"0\",\"6\"],[\"64444.4\",\"10\",\"0\",\"1\"],[\"64444.1\",\"0.01\",\"0\",\"1\"],[\"64444\",\"33.84\",\"0\",\"3\"],[\"64443.9\",\"0.77\",\"0\",\"1\"],[\"64443.2\",\"135.66\",\"0\",\"5\"],[\"64443.1\",\"0.03\",\"0\",\"2\"],[\"64439.9\",\"62.15\",\"0\",\"1\"],[\"64439.6\",\"0.02\",\"0\",\"1\"],[\"64438.6\",\"12.78\",\"0\",\"4\"],[\"64438.3\",\"58.26\",\"0\",\"2\"],[\"64437.4\",\"0\",\"0\",\"0\"],[\"64437.1\",\"0.3\",\"0\",\"2\"],[\"64436.7\",\"62.45\",\"0\",\"4\"],[\"64436.2\",\"233.01\",\"0\",\"1\"],[\"64431.6\",\"496.53\",\"0\",\"1\"],[\"64431.5\",\"15.66\",\"0\",\"2\"],[\"64405.4\",\"0\",\"0\",\"0\"],[\"64404.8\",\"0\",\"0\",\"0\"]],\"ts\":\"1782015904105\",\"checksum\":709453270,\"seqId\":325069852641,\"prevSeqId\":325069852527}]}"}
{"action": "update", "capture_sequence": 6, "channel": "books", "connection_sequence": 1, "event": null, "instId": "BTC-USDT-SWAP", "local_receive_ts": "2026-06-21T04:25:04Z", "monotonic_ns": 1643460110787210, "raw": "{\"arg\":{\"channel\":\"books\",\"instId\":\"BTC-USDT-SWAP\"},\"action\":\"update\",\"data\":[{\"asks\":[[\"64471.9\",\"0.02\",\"0\",\"2\"],[\"64472.6\",\"15.53\",\"0\",\"2\"],[\"64474.9\",\"37.23\",\"0\",\"1\"],[\"64475.5\",\"31.04\",\"0\",\"1\"],[\"64475.6\",\"25.24\",\"0\",\"7\"],[\"64475.8\",\"46.54\",\"0\",\"1\"],[\"64475.9\",\"0.91\",\"0\",\"2\"],[\"64476.7\",\"232.87\",\"0\",\"1\"],[\"64476.8\",\"318.09\",\"0\",\"4\"],[\"64477.7\",\"0\",\"0\",\"0\"],[\"64477.9\",\"1.55\",\"0\",\"1\"],[\"64482.9\",\"110.9\",\"0\",\"2\"],[\"64483\",\"200.77\",\"0\",\"2\"],[\"64492.6\",\"193.05\",\"0\",\"3\"],[\"64493.1\",\"32.76\",\"0\",\"6\"],[\"64509.3\",\"0\",\"0\",\"0\"]],\"bids\":[[\"64453\",\"0.31\",\"0\",\"1\"],[\"64452.7\",\"0.3\",\"0\",\"1\"],[\"64451.8\",\"0.77\",\"0\",\"1\"],[\"64451\",\"77.59\",\"0\",\"3\"],[\"64450.9\",\"1.6\",\"0\",\"1\"],[\"64450.8\",\"31.54\",\"0\",\"3\"],[\"64450.2\",\"35.49\",\"0\",\"5\"],[\"64450\",\"2.18\",\"0\",\"3\"],[\"64449.7\",\"48.14\",\"0\",\"3\"],[\"64449.2\",\"4.57\",\"0\",\"3\"],[\"64443.2\",\"135.67\",\"0\",\"6\"],[\"64443.1\",\"0.02\",\"0\",\"1\"],[\"64439.9\",\"62.17\",\"0\",\"2\"],[\"64439.6\",\"0\",\"0\",\"0\"],[\"64437.4\",\"31.06\",\"0\",\"1\"],[\"64437\",\"236.94\",\"0\",\"2\"],[\"64436.7\",\"31.39\",\"0\",\"3\"],[\"64436.2\",\"0\",\"0\",\"0\"],[\"64431.6\",\"496.54\",\"0\",\"2\"],[\"64431.5\",\"15.65\",\"0\",\"1\"],[\"64405\",\"0\",\"0\",\"0\"]],\"ts\":\"1782015904205\",\"checksum\":709453270,\"seqId\":325069852724,\"prevSeqId\":325069852641}]}"}
{"action": "update", "capture_sequence": 7, "channel": "books", "connection_sequence": 1, "event": null, "instId": "BTC-USDT-SWAP", "local_receive_ts": "2026-06-21T04:25:04Z", "monotonic_ns": 1643460210879854, "raw": "{\"arg\":{\"channel\":\"books\",\"instId\":\"BTC-USDT-SWAP\"},\"action\":\"update\",\"data\":[{\"asks\":[[\"64466.3\",\"46.54\",\"0\",\"1\"],[\"64475.6\",\"25.23\",\"0\",\"6\"],[\"64475.7\",\"729.42\",\"0\",\"4\"],[\"64476.7\",\"0\",\"0\",\"0\"],[\"64477.9\",\"0\",\"0\",\"0\"],[\"64478.5\",\"1.55\",\"0\",\"1\"],[\"64492.6\",\"106.92\",\"0\",\"2\"],[\"64493.1\",\"118.89\",\"0\",\"7\"]],\"bids\":[[\"64453.6\",\"0.01\",\"0\",\"1\"],[\"64453.1\",\"0.01\",\"0\",\"1\"],[\"64452.1\",\"0.03\",\"0\",\"3\"],[\"64452\",\"45.87\",\"0\",\"8\"],[\"64451.6\",\"68.13\",\"0\",\"1\"],[\"64450.2\",\"35.48\",\"0\",\"4\"],[\"64449.6\",\"512.54\",\"0\",\"5\"],[\"64448.8\",\"1.56\",\"0\",\"1\"],[\"64448.3\",\"17.57\",\"0\",\"4\"],[\"64443.2\",\"135.66\",\"0\",\"5\"],[\"64443.1\",\"0.03\",\"0\",\"2\"],[\"64431.6\",\"496.53\",\"0\",\"1\"],[\"64431.5\",\"15.66\",\"0\",\"2\"],[\"64405.1\",\"0\",\"0\",\"0\"]],\"ts\":\"1782015904305\",\"checksum\":709453270,\"seqId\":325069852797,\"prevSeqId\":325069852724}]}"}
{"action": "update", "capture_sequence": 8, "channel": "books", "connection_sequence": 1, "event": null, "instId": "BTC-USDT-SWAP", "local_receive_ts": "2026-06-21T04:25:04Z", "monotonic_ns": 1643460310949448, "raw": "{\"arg\":{\"channel\":\"books\",\"instId\":\"BTC-USDT-SWAP\"},\"action\":\"update\",\"data\":[{\"asks\":[[\"64458\",\"1536.39\",\"0\",\"71\"],[\"64459.9\",\"0.01\",\"0\",\"1\"],[\"64460\",\"0.01\",\"0\",\"1\"],[\"64461.1\",\"0.03\",\"0\",\"3\"],[\"64466.3\",\"0\",\"0\",\"0\"],[\"64468.3\",\"10.3\",\"0\",\"3\"],[\"64468.6\",\"48.28\",\"0\",\"2\"],[\"64472.8\",\"4.01\",\"0\",\"2\"],[\"64473.7\",\"277.85\",\"0\",\"3\"],[\"64475.1\",\"0.01\",\"0\",\"1\"],[\"64475.7\",\"729.41\",\"0\",\"3\"],[\"64475.8\",\"46.55\",\"0\",\"2\"],[\"64475.9\",\"0.9\",\"0\",\"1\"],[\"64476.5\",\"0\",\"0\",\"0\"],[\"64482.6\",\"0.78\",\"0\",\"2\"],[\"64483\",\"200\",\"0\",\"1\"],[\"64483.5\",\"2.3\",\"0\",\"2\"],[\"64484.5\",\"0.06\",\"0\",\"3\"],[\"64487.9\",\"85.38\",\"0\",\"2\"],[\"64488.1\",\"0.67\",\"0\",\"2\"],[\"64494.2\",\"20.07\",\"0\",\"1\"],[\"64494.3\",\"15.73\",\"0\",\"5\"]],\"bids\":[[\"64452.2\",\"31.07\",\"0\",\"2\"],[\"64452\",\"14.81\",\"0\",\"7\"],[\"64443.8\",\"0\",\"0\",\"0\"],[\"64443.6\",\"20.1\",\"0\",\"2\"],[\"64443.3\",\"130.09\",\"0\",\"2\"],[\"64442.7\",\"0\",\"0\",\"0\"],[\"64442.4\",\"85.44\",\"0\",\"2\"],[\"64436.4\",\"15.65\",\"0\",\"1\"],[\"64405.1\",\"0.07\",\"0\",\"3\"],[\"64405\",\"13.52\",\"0\",\"15\"]],\"ts\":\"1782015904405\",\"checksum\":-502059421,\"seqId\":325069852880,\"prevSeqId\":325069852797}]}"}
{"action": "update", "capture_sequence": 9, "channel": "books", "connection_sequence": 1, "event": null, "instId": "BTC-USDT-SWAP", "local_receive_ts": "2026-06-21T04:25:04Z", "monotonic_ns": 1643460422258797, "raw": "{\"arg\":{\"channel\":\"books\",\"instId\":\"BTC-USDT-SWAP\"},\"action\":\"update\",\"data\":[{\"asks\":[[\"64464.4\",\"39.09\",\"0\",\"3\"],[\"64471.7\",\"15.52\",\"0\",\"1\"],[\"64472.6\",\"0.01\",\"0\",\"1\"],[\"64474.6\",\"31.05\",\"0\",\"1\"],[\"64475.1\",\"0\",\"0\",\"0\"],[\"64475.5\",\"232.87\",\"0\",\"1\"],[\"64475.6\",\"25.24\",\"0\",\"7\"],[\"64475.7\",\"496.54\",\"0\",\"2\"],[\"64476.5\",\"0.15\",\"0\",\"1\"],[\"64477.5\",\"16.32\",\"0\",\"3\"],[\"64478.5\",\"0\",\"0\",\"0\"],[\"64482.4\",\"0.77\",\"0\",\"1\"],[\"64482.5\",\"0.33\",\"0\",\"2\"],[\"64482.6\",\"0.01\",\"0\",\"1\"],[\"64483\",\"233.8\",\"0\",\"2\"],[\"64483.1\",\"100.3\",\"0\",\"4\"],[\"64483.5\",\"2.28\",\"0\",\"1\"],[\"64484.5\",\"0.08\",\"0\",\"4\"],[\"64485.8\",\"58.6\",\"0\",\"3\"],[\"64486.4\",\"1.27\",\"0\",\"2\"],[\"64487.4\",\"85.86\",\"0\",\"6\"],[\"64487.9\",\"0.01\",\"0\",\"1\"],[\"64493.5\",\"21.16\",\"0\",\"5\"],[\"64494.2\",\"0\",\"0\",\"0\"],[\"64509.1\",\"0\",\"0\",\"0\"]],\"bids\":[[\"64455.6\",\"15.19\",\"0\",\"1\"],[\"64454.6\",\"0.81\",\"0\",\"2\"],[\"64454.5\",\"0.02\",\"0\",\"2\"],[\"64453\",\"0\",\"0\",\"0\"],[\"64452.8\",\"1.61\",\"0\",\"2\"],[\"64452.6\",\"0\",\"0\",\"0\"],[\"64452.4\",\"0.31\",\"0\",\"1\"],[\"64452.2\",\"1.57\",\"0\",\"2\"],[\"64452.1\",\"31.09\",\"0\",\"4\"],[\"64452\",\"13.25\",\"0\",\"6\"],[\"64451.8\",\"0\",\"0\",\"0\"],[\"64451.7\",\"100.09\",\"0\",\"3\"],[\"64451\",\"0.02\",\"0\",\"2\"],[\"64450.7\",\"77.61\",\"0\",\"3\"],[\"64450.6\",\"3.12\",\"0\",\"2\"],[\"64450.4\",\"1.08\",\"0\",\"2\"],[\"64450.2\",\"33.92\",\"0\",\"3\"],[\"64449.7\",\"48.45\",\"0\",\"4\"],[\"64444\",\"0.02\",\"0\",\"2\"],[\"64443.9\",\"0\",\"0\",\"0\"],[\"64443.8\",\"33.82\",\"0\",\"1\"],[\"64443.6\",\"0.01\",\"0\",\"1\"],[\"64443.3\",\"133.99\",\"0\",\"4\"],[\"64442.9\",\"20.09\",\"0\",\"1\"],[\"64442.4\",\"0.01\",\"0\",\"1\"],[\"64441.9\",\"122.37\",\"0\",\"3\"],[\"64439.9\",\"62.15\",\"0\",\"1\"],[\"64439.8\",\"0.02\",\"0\",\"1\"],[\"64438.3\",\"0.01\",\"0\",\"1\"],[\"64437.4\",\"58.25\",\"0\",\"1\"],[\"64437\",\"3.93\",\"0\",\"1\"],[\"64436.5\",\"42.37\",\"0\",\"4\"],[\"64436.4\",\"15.84\",\"0\",\"2\"],[\"64436.2\",\"233.01\",\"0\",\"1\"],[\"64405.5\",\"0.03\",\"0\",\"3\"],[\"64405\",\"0\",\"0\",\"0\"]],\"ts\":\"1782015904505\",\"checksum\":-1607933352,\"seqId\":325069853075,\"prevSeqId\":325069852880}]}"}
{"action": "update", "capture_sequence": 10, "channel": "books", "connection_sequence": 1, "event": null, "instId": "BTC-USDT-SWAP", "local_receive_ts": "2026-06-21T04:25:04Z", "monotonic_ns": 1643460515951669, "raw": "{\"arg\":{\"channel\":\"books\",\"instId\":\"BTC-USDT-SWAP\"},\"action\":\"update\",\"data\":[{\"asks\":[[\"64461.2\",\"10.26\",\"0\",\"3\"],[\"64461.3\",\"11.2\",\"0\",\"1\"],[\"64471.6\",\"2.04\",\"0\",\"3\"],[\"64473.7\",\"275.99\",\"0\",\"2\"],[\"64474.5\",\"263.95\",\"0\",\"3\"],[\"64474.6\",\"0\",\"0\",\"0\"],[\"64475.1\",\"0.01\",\"0\",\"1\"],[\"64475.5\",\"0\",\"0\",\"0\"],[\"64475.6\",\"25.23\",\"0\",\"6\"],[\"64477.2\",\"1.55\",\"0\",\"1\"],[\"64477.5\",\"14.77\",\"0\",\"2\"],[\"64481.7\",\"33.8\",\"0\",\"1\"],[\"64482.3\",\"0.31\",\"0\",\"1\"],[\"64482.4\",\"0\",\"0\",\"0\"],[\"64482.5\",\"0.02\",\"0\",\"1\"],[\"64482.6\",\"0.78\",\"0\",\"2\"],[\"64483\",\"200\",\"0\",\"1\"],[\"64483.5\",\"2.3\",\"0\",\"2\"],[\"64484.5\",\"58.26\",\"0\",\"4\"],[\"64485.8\",\"0.4\",\"0\",\"2\"],[\"64486.5\",\"101.02\",\"0\",\"2\"],[\"64487.4\",\"0.49\",\"0\",\"5\"],[\"64492.5\",\"86.2\",\"0\",\"5\"],[\"64492.9\",\"20.08\",\"0\",\"2\"],[\"64493.1\",\"32.76\",\"0\",\"6\"],[\"64493.5\",\"1.09\",\"0\",\"4\"],[\"64508.9\",\"0\",\"0\",\"0\"],[\"64509\",\"0\",\"0\",\"0\"]],\"bids\":[[\"64454.4\",\"103.62\",\"0\",\"8\"],[\"64452.8\",\"0.05\",\"0\",\"1\"],[\"64452.4\",\"0\",\"0\",\"0\"],[\"64452.2\",\"0.32\",\"0\",\"2\"],[\"64451.7\",\"3.94\",\"0\",\"2\"],[\"64451.4\",\"167.37\",\"0\",\"5\"],[\"64451.3\",\"4.37\",\"0\",\"7\"],[\"64451.2\",\"359.95\",\"0\",\"4\"],[\"64450.7\",\"0.04\",\"0\",\"2\"],[\"64450.3\",\"120.2\",\"0\",\"3\"],[\"64450.2\",\"32.01\",\"0\",\"2\"],[\"64449.7\",\"48.14\",\"0\",\"3\"],[\"64449.6\",\"512.53\",\"0\",\"4\"],[\"64449.5\",\"37.24\",\"0\",\"2\"],[\"64449.3\",\"16.53\",\"0\",\"3\"],[\"64447.8\",\"2.39\",\"0\",\"3\"],[\"64445\",\"2.03\",\"0\",\"4\"],[\"64443.8\",\"0\",\"0\",\"0\"],[\"64443.5\",\"0\",\"0\",\"0\"],[\"64443.3\",\"133.22\",\"0\",\"3\"],[\"64443.1\",\"0\",\"0\",\"0\"],[\"64443\",\"0.79\",\"0\",\"3\"],[\"64442.9\",\"0\",\"0\",\"0\"],[\"64442.7\",\"33.83\",\"0\",\"1\"],[\"64442.4\",\"20.1\",\"0\",\"2\"],[\"64442.1\",\"92.42\",\"0\",\"2\"],[\"64442\",\"77.66\",\"0\",\"6\"],[\"64441.9\",\"36.94\",\"0\",\"2\"],[\"64441.7\",\"0\",\"0\",\"0\"],[\"64441.5\",\"61.31\",\"0\",\"3\"],[\"64441.2\",\"85.43\",\"0\",\"1\"],[\"64439.8\",\"0\",\"0\",\"0\"],[\"64439.2\",\"0.02\",\"0\",\"1\"],[\"64437.4\",\"0\",\"0\",\"0\"],[\"64437\",\"0\",\"0\",\"0\"],[\"64436.8\",\"0\",\"0\",\"0\"],[\"64436.7\",\"89.64\",\"0\",\"4\"],[\"64436.5\",\"11.31\",\"0\",\"3\"],[\"64436.2\",\"31.08\",\"0\",\"2\"],[\"64435.7\",\"233.01\",\"0\",\"1\"],[\"64405.5\",\"0.02\",\"0\",\"2\"],[\"64405\",\"13.52\",\"0\",\"15\"],[\"64404.8\",\"0.04\",\"0\",\"1\"],[\"64404.7\",\"0.77\",\"0\",\"1\"],[\"64404.5\",\"0.16\",\"0\",\"2\"],[\"64404.4\",\"15.36\",\"0\",\"1\"],[\"64404.3\",\"0.04\",\"0\",\"3\"]],\"ts\":\"1782015904605\",\"checksum\":527336933,\"seqId\":325069853183,\"prevSeqId\":325069853075}]}"}
{"action": "update", "capture_sequence": 11, "channel": "books", "connection_sequence": 1, "event": null, "instId": "BTC-USDT-SWAP", "local_receive_ts": "2026-06-21T04:25:04Z", "monotonic_ns": 1643460611088682, "raw": "{\"arg\":{\"channel\":\"books\",\"instId\":\"BTC-USDT-SWAP\"},\"action\":\"update\",\"data\":[{\"asks\":[[\"64459.9\",\"0\",\"0\",\"0\"],[\"64461.2\",\"10.27\",\"0\",\"4\"],[\"64475\",\"263.07\",\"0\",\"10\"],[\"64475.1\",\"0\",\"0\",\"0\"],[\"64481.7\",\"0\",\"0\",\"0\"],[\"64482.2\",\"33.8\",\"0\",\"1\"],[\"64484.5\",\"0.06\",\"0\",\"3\"],[\"64485\",\"100.15\",\"0\",\"3\"],[\"64486.5\",\"15.65\",\"0\",\"1\"],[\"64487.4\",\"85.86\",\"0\",\"6\"],[\"64492.9\",\"0.01\",\"0\",\"1\"],[\"64493.3\",\"600.4\",\"0\",\"7\"],[\"64508.9\",\"11.24\",\"0\",\"3\"],[\"64509\",\"155.92\",\"0\",\"2\"]],\"bids\":[[\"64457.9\",\"316.6\",\"0\",\"15\"],[\"64454.6\",\"0.8\",\"0\",\"1\"],[\"64452.2\",\"0.33\",\"0\",\"3\"],[\"64451.4\",\"35.37\",\"0\",\"3\"],[\"64450.6\",\"1.56\",\"0\",\"1\"],[\"64449.7\",\"46.58\",\"0\",\"2\"],[\"64449.2\",\"3.01\",\"0\",\"2\"],[\"64445\",\"134.03\",\"0\",\"6\"],[\"64443.3\",\"253.24\",\"0\",\"5\"],[\"64442.9\",\"20.09\",\"0\",\"1\"],[\"64442.7\",\"0\",\"0\",\"0\"],[\"64442.4\",\"0.01\",\"0\",\"1\"],[\"64442.1\",\"6.22\",\"0\",\"1\"],[\"64442\",\"77.64\",\"0\",\"5\"],[\"64441.7\",\"85.45\",\"0\",\"2\"],[\"64441.5\",\"61.29\",\"0\",\"2\"],[\"64441.4\",\"50.04\",\"0\",\"4\"],[\"64441.2\",\"0\",\"0\",\"0\"],[\"64439.2\",\"0\",\"0\",\"0\"],[\"64437.2\",\"37.29\",\"0\",\"5\"],[\"64437\",\"58.25\",\"0\",\"1\"],[\"64436.7\",\"31.39\",\"0\",\"3\"],[\"64436.2\",\"31.06\",\"0\",\"1\"],[\"64435.9\",\"0.03\",\"0\",\"2\"],[\"64424.2\",\"0.02\",\"0\",\"2\"]],\"ts\":\"1782015904705\",\"checksum\":1231381345,\"seqId\":325069853235,\"prevSeqId\":325069853183}]}"}
{"action": "update", "capture_sequence": 12, "channel": "books", "connection_sequence": 1, "event": null, "instId": "BTC-USDT-SWAP", "local_receive_ts": "2026-06-21T04:25:04Z", "monotonic_ns": 1643460712234490, "raw": "{\"arg\":{\"channel\":\"books\",\"instId\":\"BTC-USDT-SWAP\"},\"action\":\"update\",\"data\":[{\"asks\":[[\"64482.2\",\"0\",\"0\",\"0\"],[\"64482.3\",\"0\",\"0\",\"0\"],[\"64482.5\",\"0.33\",\"0\",\"2\"],[\"64483.2\",\"148.49\",\"0\",\"4\"],[\"64485\",\"41.95\",\"0\",\"2\"],[\"64485.8\",\"58.6\",\"0\",\"3\"],[\"64487.4\",\"0.49\",\"0\",\"5\"],[\"64488.1\",\"86.03\",\"0\",\"3\"],[\"64492.5\",\"0.06\",\"0\",\"4\"],[\"64493.1\",\"118.89\",\"0\",\"7\"],[\"64493.3\",\"580.33\",\"0\",\"6\"],[\"64494.5\",\"20.07\",\"0\",\"1\"],[\"64509.1\",\"0.02\",\"0\",\"2\"]],\"bids\":[[\"64449.9\",\"16.25\",\"0\",\"2\"],[\"64449.3\",\"16.22\",\"0\",\"2\"],[\"64444.5\",\"33.82\",\"0\",\"1\"],[\"64443.8\",\"20.86\",\"0\",\"2\"],[\"64443.5\",\"86.2\",\"0\",\"1\"],[\"64443.3\",\"133.22\",\"0\",\"3\"],[\"64443\",\"0.02\",\"0\",\"2\"],[\"64442.9\",\"0\",\"0\",\"0\"],[\"64442.7\",\"85.42\",\"0\",\"1\"],[\"64441.7\",\"0.02\",\"0\",\"1\"],[\"64437.4\",\"58.25\",\"0\",\"1\"],[\"64437\",\"0\",\"0\",\"0\"],[\"64404.5\",\"0\",\"0\",\"0\"],[\"64404.4\",\"0\",\"0\",\"0\"],[\"64404.3\",\"0\",\"0\",\"0\"]],\"ts\":\"1782015904805\",\"checksum\":1231381345,\"seqId\":325069853269,\"prevSeqId\":325069853235}]}"}
{"action": "update", "capture_sequence": 13, "channel": "books", "connection_sequence": 1, "event": null, "instId": "BTC-USDT-SWAP", "local_receive_ts": "2026-06-21T04:25:05Z", "monotonic_ns": 1643460810767291, "raw": "{\"arg\":{\"channel\":\"books\",\"instId\":\"BTC-USDT-SWAP\"},\"action\":\"update\",\"data\":[{\"asks\":[[\"64493.7\",\"378.94\",\"0\",\"5\"],[\"64494.5\",\"0\",\"0\",\"0\"],[\"64509.3\",\"0.28\",\"0\",\"5\"]],\"bids\":[[\"64449.9\",\"15.94\",\"0\",\"1\"],[\"64449.6\",\"512.84\",\"0\",\"5\"],[\"64443.8\",\"0.77\",\"0\",\"1\"],[\"64443.3\",\"153.31\",\"0\",\"4\"]],\"ts\":\"1782015904905\",\"checksum\":1231381345,\"seqId\":325069853282,\"prevSeqId\":325069853269}]}"}
{"action": null, "capture_sequence": 14, "channel": "trades", "connection_sequence": 1, "event": null, "instId": "BTC-USDT-SWAP", "local_receive_ts": "2026-06-21T04:25:05Z", "monotonic_ns": 1643460854086221, "raw": "{\"arg\":{\"channel\":\"trades\",\"instId\":\"BTC-USDT-SWAP\"},\"data\":[{\"instId\":\"BTC-USDT-SWAP\",\"tradeId\":\"2718748817\",\"px\":\"64457.9\",\"sz\":\"5\",\"side\":\"sell\",\"ts\":\"1782015904948\",\"count\":\"1\",\"source\":\"0\",\"seqId\":325069853300}]}"}
{"action": "update", "capture_sequence": 15, "channel": "books", "connection_sequence": 1, "event": null, "instId": "BTC-USDT-SWAP", "local_receive_ts": "2026-06-21T04:25:05Z", "monotonic_ns": 1643460910796665, "raw": "{\"arg\":{\"channel\":\"books\",\"instId\":\"BTC-USDT-SWAP\"},\"action\":\"update\",\"data\":[{\"asks\":[[\"64471.5\",\"15.52\",\"0\",\"1\"],[\"64471.7\",\"0\",\"0\",\"0\"],[\"64487.4\",\"85.86\",\"0\",\"6\"],[\"64488.1\",\"0.67\",\"0\",\"2\"]],\"bids\":[[\"64457.9\",\"311.6\",\"0\",\"15\"],[\"64450.3\",\"42.63\",\"0\",\"2\"],[\"64450.1\",\"118.34\",\"0\",\"2\"],[\"64442.7\",\"0\",\"0\",\"0\"],[\"64442.1\",\"91.65\",\"0\",\"2\"],[\"64404.5\",\"0.16\",\"0\",\"2\"]],\"ts\":\"1782015905005\",\"checksum\":-1236326693,\"seqId\":325069853305,\"prevSeqId\":325069853282}]}"}
{"action": "update", "capture_sequence": 16, "channel": "books", "connection_sequence": 1, "event": null, "instId": "BTC-USDT-SWAP", "local_receive_ts": "2026-06-21T04:25:05Z", "monotonic_ns": 1643461011260049, "raw": "{\"arg\":{\"channel\":\"books\",\"instId\":\"BTC-USDT-SWAP\"},\"action\":\"update\",\"data\":[{\"asks\":[[\"64482.4\",\"33.8\",\"0\",\"1\"],[\"64483.2\",\"114.69\",\"0\",\"3\"],[\"64509.3\",\"0\",\"0\",\"0\"]],\"bids\":[[\"64453.2\",\"1.56\",\"0\",\"1\"],[\"64452.2\",\"0.02\",\"0\",\"2\"],[\"64452.1\",\"32.96\",\"0\",\"6\"],[\"64449.6\",\"512.53\",\"0\",\"4\"],[\"64449.5\",\"37.55\",\"0\",\"3\"],[\"64448.8\",\"0\",\"0\",\"0\"],[\"64444.5\",\"0\",\"0\",\"0\"],[\"64443.8\",\"0\",\"0\",\"0\"],[\"64443.5\",\"86.97\",\"0\",\"2\"],[\"64443.4\",\"439.04\",\"0\",\"3\"],[\"64442.1\",\"6.22\",\"0\",\"1\"],[\"64441.7\",\"85.45\",\"0\",\"2\"],[\"64404.4\",\"15.36\",\"0\",\"1\"],[\"64404.3\",\"0.04\",\"0\",\"3\"]],\"ts\":\"1782015905105\",\"checksum\":-1236326693,\"seqId\":325069853354,\"prevSeqId\":325069853305}]}"}
{"action": "update", "capture_sequence": 17, "channel": "books", "connection_sequence": 1, "event": null, "instId": "BTC-USDT-SWAP", "local_receive_ts": "2026-06-21T04:25:05Z", "monotonic_ns": 1643461110615500, "raw": "{\"arg\":{\"channel\":\"books\",\"instId\":\"BTC-USDT-SWAP\"},\"action\":\"update\",\"data\":[{\"asks\":[[\"64482.6\",\"0.01\",\"0\",\"1\"],[\"64482.9\",\"111.67\",\"0\",\"3\"]],\"bids\":[[\"64457.9\",\"311.55\",\"0\",\"15\"],[\"64453.2\",\"0\",\"0\",\"0\"],[\"64452.9\",\"77.59\",\"0\",\"2\"],[\"64452.3\",\"1.57\",\"0\",\"2\"],[\"64452.1\",\"31.4\",\"0\",\"5\"],[\"64451.8\",\"1.56\",\"0\",\"1\"],[\"64451.3\",\"5.93\",\"0\",\"8\"],[\"64450.7\",\"1.6\",\"0\",\"3\"],[\"64450.2\",\"33.57\",\"0\",\"3\"],[\"64449.7\",\"48.14\",\"0\",\"3\"],[\"64449.2\",\"4.57\",\"0\",\"3\"],[\"64443.8\",\"0.77\",\"0\",\"1\"],[\"64443.5\",\"86.2\",\"0\",\"1\"],[\"64404.3\",\"0\",\"0\",\"0\"]],\"ts\":\"1782015905205\",\"checksum\":491364425,\"seqId\":325069853383,\"prevSeqId\":325069853354}]}"}
{"action": null, "capture_sequence": 18, "channel": "trades", "connection_sequence": 1, "event": null, "instId": "BTC-USDT-SWAP", "local_receive_ts": "2026-06-21T04:25:05Z", "monotonic_ns": 1643461177366457, "raw": "{\"arg\":{\"channel\":\"trades\",\"instId\":\"BTC-USDT-SWAP\"},\"data\":[{\"instId\":\"BTC-USDT-SWAP\",\"tradeId\":\"2718748818\",\"px\":\"64457.9\",\"sz\":\"5\",\"side\":\"sell\",\"ts\":\"1782015905272\",\"count\":\"1\",\"source\":\"0\",\"seqId\":325069853403}]}"}
{"action": "update", "capture_sequence": 19, "channel": "books", "connection_sequence": 1, "event": null, "instId": "BTC-USDT-SWAP", "local_receive_ts": "2026-06-21T04:25:05Z", "monotonic_ns": 1643461210775555, "raw": "{\"arg\":{\"channel\":\"books\",\"instId\":\"BTC-USDT-SWAP\"},\"action\":\"update\",\"data\":[{\"asks\":[[\"64458\",\"1536.41\",\"0\",\"71\"]],\"bids\":[[\"64457.9\",\"306.55\",\"0\",\"15\"],[\"64452.3\",\"0.01\",\"0\",\"1\"],[\"64451.8\",\"0\",\"0\",\"0\"],[\"64451.3\",\"4.37\",\"0\",\"7\"],[\"64450.7\",\"0.04\",\"0\",\"2\"],[\"64447.8\",\"3.95\",\"0\",\"4\"],[\"64404.3\",\"0.04\",\"0\",\"3\"]],\"ts\":\"1782015905305\",\"checksum\":556229879,\"seqId\":325069853423,\"prevSeqId\":325069853383}]}"}
{"action": null, "capture_sequence": 20, "channel": "trades", "connection_sequence": 1, "event": null, "instId": "BTC-USDT-SWAP", "local_receive_ts": "2026-06-21T04:25:05Z", "monotonic_ns": 1643461258381739, "raw": "{\"arg\":{\"channel\":\"trades\",\"instId\":\"BTC-USDT-SWAP\"},\"data\":[{\"instId\":\"BTC-USDT-SWAP\",\"tradeId\":\"2718748819\",\"px\":\"64457.9\",\"sz\":\"0.18\",\"side\":\"sell\",\"ts\":\"1782015905353\",\"count\":\"1\",\"source\":\"0\",\"seqId\":325069853472}]}"}
{"action": "update", "capture_sequence": 21, "channel": "books", "connection_sequence": 1, "event": null, "instId": "BTC-USDT-SWAP", "local_receive_ts": "2026-06-21T04:25:05Z", "monotonic_ns": 1643461311131052, "raw": "{\"arg\":{\"channel\":\"books\",\"instId\":\"BTC-USDT-SWAP\"},\"action\":\"update\",\"data\":[{\"asks\":[[\"64476.5\",\"0\",\"0\",\"0\"],[\"64483.5\",\"0.02\",\"0\",\"1\"],[\"64492.5\",\"86.2\",\"0\",\"5\"],[\"64493.1\",\"52.83\",\"0\",\"7\"],[\"64493.7\",\"358.87\",\"0\",\"4\"],[\"64509.3\",\"0.28\",\"0\",\"5\"]],\"bids\":[[\"64457.9\",\"306.37\",\"0\",\"15\"],[\"64452.9\",\"79.15\",\"0\",\"3\"],[\"64452.1\",\"31.09\",\"0\",\"4\"],[\"64452\",\"13.56\",\"0\",\"7\"],[\"64450.2\",\"32.01\",\"0\",\"2\"],[\"64449.7\",\"46.58\",\"0\",\"2\"],[\"64449.2\",\"3.01\",\"0\",\"2\"],[\"64443.5\",\"0\",\"0\",\"0\"],[\"64443.3\",\"130.09\",\"0\",\"2\"],[\"64442.7\",\"20.09\",\"0\",\"1\"],[\"64442.1\",\"92.42\",\"0\",\"2\"],[\"64436.4\",\"15.65\",\"0\",\"1\"]],\"ts\":\"1782015905405\",\"checksum\":2074781450,\"seqId\":325069853479,\"prevSeqId\":325069853423}]}"}
{"action": "update", "capture_sequence": 22, "channel": "books", "connection_sequence": 1, "event": null, "instId": "BTC-USDT-SWAP", "local_receive_ts": "2026-06-21T04:25:05Z", "monotonic_ns": 1643461410973851, "raw": "{\"arg\":{\"channel\":\"books\",\"instId\":\"BTC-USDT-SWAP\"},\"action\":\"update\",\"data\":[{\"asks\":[[\"64476.5\",\"0.15\",\"0\",\"1\"],[\"64509.3\",\"0\",\"0\",\"0\"]],\"bids\":[[\"64452.9\",\"77.59\",\"0\",\"2\"],[\"64443.3\",\"133.22\",\"0\",\"3\"],[\"64436.4\",\"15.84\",\"0\",\"2\"]],\"ts\":\"1782015905505\",\"checksum\":2074781450,\"seqId\":325069853513,\"prevSeqId\":325069853479}]}"}
{"action": null, "capture_sequence": 23, "channel": "trades", "connection_sequence": 1, "event": null, "instId": "BTC-USDT-SWAP", "local_receive_ts": "2026-06-21T04:25:05Z", "monotonic_ns": 1643461454793326, "raw": "{\"arg\":{\"channel\":\"trades\",\"instId\":\"BTC-USDT-SWAP\"},\"data\":[{\"instId\":\"BTC-USDT-SWAP\",\"tradeId\":\"2718748820\",\"px\":\"64457.9\",\"sz\":\"5\",\"side\":\"sell\",\"ts\":\"1782015905549\",\"count\":\"1\",\"source\":\"0\",\"seqId\":325069853546}]}"}
{"action": "update", "capture_sequence": 24, "channel": "books", "connection_sequence": 1, "event": null, "instId": "BTC-USDT-SWAP", "local_receive_ts": "2026-06-21T04:25:05Z", "monotonic_ns": 1643461511214983, "raw": "{\"arg\":{\"channel\":\"books\",\"instId\":\"BTC-USDT-SWAP\"},\"action\":\"update\",\"data\":[{\"asks\":[[\"64464.5\",\"167.27\",\"0\",\"6\"],[\"64465.1\",\"0\",\"0\",\"0\"],[\"64465.5\",\"10.01\",\"0\",\"2\"],[\"64466.4\",\"66.86\",\"0\",\"2\"],[\"64467.2\",\"0\",\"0\",\"0\"],[\"64467.6\",\"0.4\",\"0\",\"3\"],[\"64467.7\",\"0\",\"0\",\"0\"],[\"64486.2\",\"85.54\",\"0\",\"7\"],[\"64487.4\",\"0.49\",\"0\",\"5\"],[\"64490.9\",\"86.21\",\"0\",\"3\"],[\"64492.2\",\"0.9\",\"0\",\"6\"],[\"64492.5\",\"0.06\",\"0\",\"4\"],[\"64493.1\",\"51.83\",\"0\",\"6\"],[\"64494.9\",\"0.07\",\"0\",\"3\"],[\"64495.3\",\"0.26\",\"0\",\"2\"],[\"64509.3\",\"0.28\",\"0\",\"5\"],[\"64509.6\",\"0.03\",\"0\",\"2\"],[\"64509.8\",\"0.01\",\"0\",\"1\"]],\"bids\":[[\"64457.9\",\"301.37\",\"0\",\"15\"],[\"64452.7\",\"1.86\",\"0\",\"2\"],[\"64452.2\",\"1.58\",\"0\",\"3\"],[\"64451.9\",\"46.54\",\"0\",\"1\"],[\"64451.7\",\"5.5\",\"0\",\"3\"],[\"64451.3\",\"2.47\",\"0\",\"6\"],[\"64451.2\",\"361.51\",\"0\",\"5\"],[\"64450.9\",\"0\",\"0\",\"0\"],[\"64450.7\",\"1.6\",\"0\",\"3\"],[\"64450.3\",\"44.19\",\"0\",\"3\"],[\"64450\",\"0.02\",\"0\",\"2\"],[\"64449.8\",\"4.45\",\"0\",\"3\"],[\"64449.4\",\"16.17\",\"0\",\"2\"],[\"64449.2\",\"0.01\",\"0\",\"1\"],[\"64448.7\",\"0\",\"0\",\"0\"],[\"64441.7\",\"0.02\",\"0\",\"1\"],[\"64440.7\",\"85.43\",\"0\",\"1\"],[\"64434.3\",\"0.01\",\"0\",\"1\"],[\"64431.6\",\"499.63\",\"0\",\"2\"],[\"64404\",\"0.04\",\"0\",\"2\"]],\"ts\":\"1782015905605\",\"checksum\":1356978141,\"seqId\":325069853617,\"prevSeqId\":325069853513}]}"}
{"action": "update", "capture_sequence": 25, "channel": "books", "connection_sequence": 1, "event": null, "instId": "BTC-USDT-SWAP", "local_receive_ts": "2026-06-21T04:25:05Z", "monotonic_ns": 1643461611511244, "raw": "{\"arg\":{\"channel\":\"books\",\"instId\":\"BTC-USDT-SWAP\"},\"action\":\"update\",\"data\":[{\"asks\":[[\"64464.5\",\"168.27\",\"0\",\"7\"],[\"64466.1\",\"0.01\",\"0\",\"1\"],[\"64466.9\",\"0\",\"0\",\"0\"],[\"64467.8\",\"255.06\",\"0\",\"3\"],[\"64471.5\",\"0\",\"0\",\"0\"],[\"64471.7\",\"15.52\",\"0\",\"1\"],[\"64484.5\",\"58.27\",\"0\",\"4\"],[\"64485.8\",\"0.4\",\"0\",\"2\"],[\"64486.2\",\"0.17\",\"0\",\"6\"],[\"64487.4\",\"85.86\",\"0\",\"6\"],[\"64490.9\",\"0.07\",\"0\",\"2\"],[\"64492.2\",\"1.9\",\"0\",\"7\"],[\"64492.5\",\"86.2\",\"0\",\"5\"],[\"64493.1\",\"31.76\",\"0\",\"5\"],[\"64493.2\",\"419.89\",\"0\",\"9\"],[\"64493.5\",\"2.29\",\"0\",\"5\"],[\"64494.6\",\"5.04\",\"0\",\"4\"],[\"64495.4\",\"1.56\",\"0\",\"4\"],[\"64499.5\",\"0\",\"0\",\"0\"],[\"64509.9\",\"1.2\",\"0\",\"2\"],[\"64510\",\"554.22\",\"0\",\"28\"]],\"bids\":[[\"64457.9\",\"256.78\",\"0\",\"13\"],[\"64452.7\",\"0.3\",\"0\",\"1\"],[\"64452.2\",\"0.02\",\"0\",\"2\"],[\"64451.7\",\"3.94\",\"0\",\"2\"],[\"64451.2\",\"359.95\",\"0\",\"4\"],[\"64450.6\",\"0\",\"0\",\"0\"],[\"64450.5\",\"6.3\",\"0\",\"4\"],[\"64450.3\",\"42.39\",\"0\",\"2\"],[\"64449.8\",\"1.57\",\"0\",\"2\"],[\"64449.2\",\"1.57\",\"0\",\"2\"],[\"64447.2\",\"2.78\",\"0\",\"2\"],[\"64441.9\",\"122.37\",\"0\",\"3\"],[\"64440.7\",\"0\",\"0\",\"0\"],[\"64437.4\",\"0\",\"0\",\"0\"],[\"64436.7\",\"89.64\",\"0\",\"4\"],[\"64403.6\",\"6.25\",\"0\",\"3\"],[\"64403.5\",\"6.24\",\"0\",\"2\"],[\"64403.4\",\"164.81\",\"0\",\"7\"]],\"ts\":\"1782015905705\",\"checksum\":2061320526,\"seqId\":325069853690,\"prevSeqId\":325069853617}]}"}
{"action": "update", "capture_sequence": 26, "channel": "books", "connection_sequence": 1, "event": null, "instId": "BTC-USDT-SWAP", "local_receive_ts": "2026-06-21T04:25:05Z", "monotonic_ns": 1643461710970009, "raw": "{\"arg\":{\"channel\":\"books\",\"instId\":\"BTC-USDT-SWAP\"},\"action\":\"update\",\"data\":[{\"asks\":[[\"64458\",\"1536.51\",\"0\",\"72\"],[\"64465.2\",\"78.75\",\"0\",\"3\"],[\"64466.2\",\"1.2\",\"0\",\"1\"],[\"64466.9\",\"1.2\",\"0\",\"1\"],[\"64467.6\",\"1.6\",\"0\",\"4\"],[\"64492.9\",\"1.01\",\"0\",\"2\"],[\"64493.8\",\"1.24\",\"0\",\"4\"],[\"64494.6\",\"6.24\",\"0\",\"5\"],[\"64495.3\",\"1.46\",\"0\",\"3\"],[\"64509.9\",\"0\",\"0\",\"0\"],[\"64510\",\"0\",\"0\",\"0\"]],\"bids\":[[\"64452\",\"15.12\",\"0\",\"8\"],[\"64449.8\",\"3.47\",\"0\",\"3\"],[\"64448.8\",\"1.8\",\"0\",\"1\"],[\"64448.3\",\"20.45\",\"0\",\"5\"],[\"64447.7\",\"3\",\"0\",\"1\"],[\"64403.5\",\"0\",\"0\",\"0\"],[\"64403.4\",\"0\",\"0\",\"0\"]],\"ts\":\"1782015905805\",\"checksum\":-303907391,\"seqId\":325069853717,\"prevSeqId\":325069853690}]}"}
{"action": null, "capture_sequence": 27, "channel": "trades", "connection_sequence": 1, "event": null, "instId": "BTC-USDT-SWAP", "local_receive_ts": "2026-06-21T04:25:05Z", "monotonic_ns": 1643461721274389, "raw": "{\"arg\":{\"channel\":\"trades\",\"instId\":\"BTC-USDT-SWAP\"},\"data\":[{\"instId\":\"BTC-USDT-SWAP\",\"tradeId\":\"2718748821\",\"px\":\"64457.9\",\"sz\":\"5\",\"side\":\"sell\",\"ts\":\"1782015905816\",\"count\":\"1\",\"source\":\"0\",\"seqId\":325069853719}]}"}
{"action": "update", "capture_sequence": 28, "channel": "books", "connection_sequence": 1, "event": null, "instId": "BTC-USDT-SWAP", "local_receive_ts": "2026-06-21T04:25:06Z", "monotonic_ns": 1643461810808251, "raw": "{\"arg\":{\"channel\":\"books\",\"instId\":\"BTC-USDT-SWAP\"},\"action\":\"update\",\"data\":[{\"asks\":[[\"64465.5\",\"11.01\",\"0\",\"3\"],[\"64466.5\",\"1.2\",\"0\",\"1\"],[\"64467.2\",\"1.2\",\"0\",\"1\"],[\"64476.5\",\"0\",\"0\",\"0\"],[\"64493.2\",\"420.89\",\"0\",\"10\"],[\"64494.1\",\"1.2\",\"0\",\"1\"],[\"64494.9\",\"1.27\",\"0\",\"4\"],[\"64509.6\",\"0\",\"0\",\"0\"],[\"64509.8\",\"0\",\"0\",\"0\"]],\"bids\":[[\"64457.9\",\"251.78\",\"0\",\"13\"],[\"64452\",\"13.56\",\"0\",\"7\"],[\"64450.7\",\"0.04\",\"0\",\"2\"],[\"64449.5\",\"39.15\",\"0\",\"4\"],[\"64448.5\",\"2.16\",\"0\",\"1\"],[\"64448\",\"324.47\",\"0\",\"11\"],[\"64443.3\",\"130.09\",\"0\",\"2\"],[\"64436.4\",\"15.65\",\"0\",\"1\"],[\"64403.6\",\"0\",\"0\",\"0\"]],\"ts\":\"1782015905905\",\"checksum\":-961950442,\"seqId\":325069853744,\"prevSeqId\":325069853717}]}"}
{"action": "update", "capture_sequence": 29, "channel": "books", "connection_sequence": 1, "event": null, "instId": "BTC-USDT-SWAP", "local_receive_ts": "2026-06-21T04:25:06Z", "monotonic_ns": 1643461911274198, "raw": "{\"arg\":{\"channel\":\"books\",\"instId\":\"BTC-USDT-SWAP\"},\"action\":\"update\",\"data\":[{\"asks\":[[\"64471.5\",\"15.52\",\"0\",\"1\"],[\"64471.7\",\"0\",\"0\",\"0\"],[\"64474.4\",\"31.07\",\"0\",\"3\"],[\"64474.5\",\"232.9\",\"0\",\"2\"],[\"64476.5\",\"0.16\",\"0\",\"1\"],[\"64476.9\",\"1.57\",\"0\",\"3\"],[\"64477.2\",\"0\",\"0\",\"0\"],[\"64482.5\",\"0.02\",\"0\",\"1\"],[\"64482.6\",\"0.32\",\"0\",\"2\"],[\"64484.5\",\"0.06\",\"0\",\"3\"],[\"64485\",\"100.15\",\"0\",\"3\"],[\"64493.2\",\"400.82\",\"0\",\"9\"],[\"64493.3\",\"600.4\",\"0\",\"7\"]],\"bids\":[[\"64450.3\",\"40.83\",\"0\",\"1\"],[\"64450.1\",\"40.77\",\"0\",\"1\"],[\"64450\",\"77.59\",\"0\",\"3\"],[\"64449.8\",\"3.78\",\"0\",\"4\"],[\"64449.5\",\"38.84\",\"0\",\"3\"],[\"64443.5\",\"33.82\",\"0\",\"1\"],[\"64443.4\",\"405.22\",\"0\",\"2\"],[\"64443.3\",\"219.49\",\"0\",\"4\"],[\"64442.9\",\"20.09\",\"0\",\"1\"],[\"64442.7\",\"0\",\"0\",\"0\"],[\"64442.1\",\"6.22\",\"0\",\"1\"],[\"64441.9\",\"122.39\",\"0\",\"4\"],[\"64441.7\",\"0\",\"0\",\"0\"],[\"64441.5\",\"61.31\",\"0\",\"3\"],[\"64441.4\",\"50.02\",\"0\",\"3\"],[\"64439.2\",\"0.02\",\"0\",\"1\"],[\"64437.2\",\"37.27\",\"0\",\"4\"],[\"64437\",\"58.25\",\"0\",\"1\"],[\"64436.7\",\"31.39\",\"0\",\"3\"],[\"64436.4\",\"15.85\",\"0\",\"2\"],[\"64436.1\",\"25.67\",\"0\",\"3\"],[\"64435.9\",\"0.01\",\"0\",\"1\"],[\"64431.6\",\"496.53\",\"0\",\"1\"],[\"64404.3\",\"0\",\"0\",\"0\"],[\"64404\",\"0\",\"0\",\"0\"]],\"ts\":\"1782015906005\",\"checksum\":-961950442,\"seqId\":325069853793,\"prevSeqId\":325069853744}]}"}
{"action": null, "capture_sequence": 30, "channel": "trades", "connection_sequence": 1, "event": null, "instId": "BTC-USDT-SWAP", "local_receive_ts": "2026-06-21T04:25:06Z", "monotonic_ns": 1643461954567955, "raw": "{\"arg\":{\"channel\":\"trades\",\"instId\":\"BTC-USDT-SWAP\"},\"data\":[{\"instId\":\"BTC-USDT-SWAP\",\"tradeId\":\"2718748823\",\"px\":\"64457.9\",\"sz\":\"5\",\"side\":\"sell\",\"ts\":\"1782015906049\",\"count\":\"2\",\"source\":\"0\",\"seqId\":325069853895}]}"}
{"action": "update", "capture_sequence": 31, "channel": "books", "connection_sequence": 1, "event": null, "instId": "BTC-USDT-SWAP", "local_receive_ts": "2026-06-21T04:25:06Z", "monotonic_ns": 1643462015984518, "raw": "{\"arg\":{\"channel\":\"books\",\"instId\":\"BTC-USDT-SWAP\"},\"action\":\"update\",\"data\":[{\"asks\":[[\"64458.1\",\"13.12\",\"0\",\"2\"],[\"64463.7\",\"4\",\"0\",\"1\"],[\"64470.4\",\"0.25\",\"0\",\"3\"],[\"64470.6\",\"380.95\",\"0\",\"3\"],[\"64470.8\",\"16.29\",\"0\",\"2\"],[\"64471.5\",\"0\",\"0\",\"0\"],[\"64474.1\",\"31.05\",\"0\",\"1\"],[\"64474.4\",\"0.02\",\"0\",\"2\"],[\"64474.5\",\"0.03\",\"0\",\"1\"],[\"64474.6\",\"232.87\",\"0\",\"1\"],[\"64476.1\",\"1.55\",\"0\",\"1\"],[\"64476.9\",\"0.02\",\"0\",\"2\"],[\"64481.6\",\"0.78\",\"0\",\"2\"],[\"64482.4\",\"0\",\"0\",\"0\"],[\"64482.9\",\"110.9\",\"0\",\"2\"],[\"64483.1\",\"134.1\",\"0\",\"5\"],[\"64483.3\",\"58.26\",\"0\",\"3\"],[\"64485\",\"41.95\",\"0\",\"2\"],[\"64486.9\",\"85.49\",\"0\",\"3\"],[\"64487.4\",\"0.49\",\"0\",\"5\"],[\"64492.9\",\"21.08\",\"0\",\"3\"],[\"64493.3\",\"580.33\",\"0\",\"6\"],[\"64509.3\",\"0\",\"0\",\"0\"]],\"bids\":[[\"64457.9\",\"220.48\",\"0\",\"11\"],[\"64452\",\"13.25\",\"0\",\"6\"],[\"64451.6\",\"0\",\"0\",\"0\"],[\"64451.4\",\"35.68\",\"0\",\"4\"],[\"64450.8\",\"19.54\",\"0\",\"1\"],[\"64450\",\"0.02\",\"0\",\"2\"],[\"64449.8\",\"1.91\",\"0\",\"2\"],[\"64449.6\",\"520.53\",\"0\",\"5\"],[\"64449.3\",\"94.11\",\"0\",\"4\"],[\"64448.3\",\"18.89\",\"0\",\"4\"],[\"64447.9\",\"12\",\"0\",\"2\"],[\"64443.8\",\"33.82\",\"0\",\"1\"],[\"64443.5\",\"0\",\"0\",\"0\"],[\"64443.3\",\"133.29\",\"0\",\"3\"],[\"64442.9\",\"0\",\"0\",\"0\"],[\"64442.8\",\"0.8\",\"0\",\"4\"],[\"64442.4\",\"20.1\",\"0\",\"2\"],[\"64442.1\",\"92.42\",\"0\",\"2\"],[\"64442\",\"77.63\",\"0\",\"4\"],[\"64441.9\",\"36.97\",\"0\",\"4\"],[\"64441.5\",\"146.74\",\"0\",\"4\"],[\"64439.2\",\"0\",\"0\",\"0\"],[\"64438.8\",\"0.02\",\"0\",\"1\"],[\"64437\",\"0\",\"0\",\"0\"],[\"64436.7\",\"15.66\",\"0\",\"2\"],[\"64436.2\",\"0\",\"0\",\"0\"],[\"64436.1\",\"25.65\",\"0\",\"2\"],[\"64435.9\",\"0.03\",\"0\",\"2\"],[\"64435.8\",\"31.13\",\"0\",\"2\"],[\"64435\",\"58.25\",\"0\",\"1\"],[\"64431.5\",\"18.76\",\"0\",\"3\"],[\"64404.3\",\"0.04\",\"0\",\"3\"],[\"64404\",\"0.04\",\"0\",\"2\"],[\"64403.6\",\"6.25\",\"0\",\"3\"],[\"64403.5\",\"6.24\",\"0\",\"2\"]],\"ts\":\"1782015906105\",\"checksum\":-1504190739,\"seqId\":325069853973,\"prevSeqId\":325069853793}]}"}
{"action": "update", "capture_sequence": 32, "channel": "books", "connection_sequence": 1, "event": null, "instId": "BTC-USDT-SWAP", "local_receive_ts": "2026-06-21T04:25:06Z", "monotonic_ns": 1643462116058741, "raw": "{\"arg\":{\"channel\":\"books\",\"instId\":\"BTC-USDT-SWAP\"},\"action\":\"update\",\"data\":[{\"asks\":[[\"64458\",\"1541.51\",\"0\",\"73\"],[\"64458.2\",\"0.02\",\"0\",\"1\"],[\"64458.4\",\"0.01\",\"0\",\"1\"],[\"64458.5\",\"5\",\"0\",\"1\"],[\"64458.9\",\"0\",\"0\",\"0\"],[\"64461.1\",\"0.02\",\"0\",\"2\"],[\"64462.2\",\"8\",\"0\",\"1\"],[\"64466.7\",\"0.25\",\"0\",\"3\"],[\"64469.2\",\"2.1\",\"0\",\"1\"],[\"64470.4\",\"0.01\",\"0\",\"1\"],[\"64470.6\",\"372.95\",\"0\",\"2\"],[\"64470.8\",\"0.77\",\"0\",\"1\"],[\"64471.6\",\"0.04\",\"0\",\"2\"],[\"64471.7\",\"15.52\",\"0\",\"1\"],[\"64471.9\",\"0.03\",\"0\",\"3\"],[\"64472.8\",\"4\",\"0\",\"1\"],[\"64474.2\",\"233.16\",\"0\",\"2\"],[\"64474.6\",\"0\",\"0\",\"0\"],[\"64481.6\",\"0.01\",\"0\",\"1\"],[\"64481.7\",\"33.8\",\"0\",\"1\"],[\"64482.5\",\"0.33\",\"0\",\"2\"],[\"64482.6\",\"0.78\",\"0\",\"2\"],[\"64483.1\",\"100.3\",\"0\",\"4\"],[\"64483.3\",\"0.05\",\"0\",\"2\"],[\"64484.5\",\"58.26\",\"0\",\"4\"],[\"64492.9\",\"1.01\",\"0\",\"2\"],[\"64493\",\"33.79\",\"0\",\"5\"],[\"64493.7\",\"359.29\",\"0\",\"5\"],[\"64496.5\",\"0\",\"0\",\"0\"],[\"64503.2\",\"15.95\",\"0\",\"3\"],[\"64508.8\",\"0\",\"0\",\"0\"],[\"64508.9\",\"0\",\"0\",\"0\"],[\"64509\",\"0\",\"0\",\"0\"],[\"64509.1\",\"0\",\"0\",\"0\"]],\"bids\":[[\"64455.2\",\"0.03\",\"0\",\"3\"],[\"64454.4\",\"47.12\",\"0\",\"8\"],[\"64452.9\",\"0.01\",\"0\",\"1\"],[\"64452.2\",\"0.01\",\"0\",\"1\"],[\"64452.1\",\"0.03\",\"0\",\"3\"],[\"64452\",\"12.47\",\"0\",\"4\"],[\"64451.9\",\"0\",\"0\",\"0\"],[\"64451.8\",\"31.07\",\"0\",\"2\"],[\"64451.7\",\"50.49\",\"0\",\"4\"],[\"64451.6\",\"0.77\",\"0\",\"1\"],[\"64451.4\",\"35.37\",\"0\",\"3\"],[\"64451.2\",\"260.87\",\"0\",\"3\"],[\"64450.9\",\"0.31\",\"0\",\"1\"],[\"64450.4\",\"0.31\",\"0\",\"1\"],[\"64449.6\",\"12\",\"0\",\"2\"],[\"64449.5\",\"38.83\",\"0\",\"2\"],[\"64449.3\",\"16.22\",\"0\",\"2\"],[\"64449\",\"0.34\",\"0\",\"4\"],[\"64448.9\",\"77.58\",\"0\",\"1\"],[\"64448.7\",\"4\",\"0\",\"1\"],[\"64448.4\",\"0.77\",\"0\",\"1\"],[\"64447.9\",\"4.01\",\"0\",\"2\"],[\"64447.8\",\"0.39\",\"0\",\"2\"],[\"64445.9\",\"8.03\",\"0\",\"4\"],[\"64445.7\",\"514.54\",\"0\",\"4\"],[\"64445.5\",\"2.1\",\"0\",\"1\"],[\"64443.8\",\"0\",\"0\",\"0\"],[\"64442.7\",\"33.83\",\"0\",\"1\"],[\"64441.9\",\"36.94\",\"0\",\"2\"],[\"64441.5\",\"146.75\",\"0\",\"5\"],[\"64438.8\",\"0\",\"0\",\"0\"],[\"64438\",\"0.03\",\"0\",\"2\"],[\"64436.7\",\"73.91\",\"0\",\"3\"],[\"64435.7\",\"0\",\"0\",\"0\"],[\"64435.3\",\"0.03\",\"0\",\"2\"],[\"64435\",\"233.01\",\"0\",\"1\"],[\"64433.9\",\"0\",\"0\",\"0\"],[\"64431.5\",\"18.75\",\"0\",\"2\"],[\"64427.6\",\"0.02\",\"0\",\"2\"],[\"64415.2\",\"0.01\",\"0\",\"1\"],[\"64414.4\",\"99.1\",\"0\",\"2\"],[\"64410.6\",\"21.12\",\"0\",\"3\"],[\"64404\",\"0\",\"0\",\"0\"],[\"64403.6\",\"0\",\"0\",\"0\"],[\"64403.5\",\"0\",\"0\",\"0\"]],\"ts\":\"1782015906205\",\"checksum\":-1021308335,\"seqId\":325069854207,\"prevSeqId\":325069853973}]}"}
{"action": "update", "capture_sequence": 33, "channel": "books", "connection_sequence": 1, "event": null, "instId": "BTC-USDT-SWAP", "local_receive_ts": "2026-06-21T04:25:06Z", "monotonic_ns": 1643462211404049, "raw": "{\"arg\":{\"channel\":\"books\",\"instId\":\"BTC-USDT-SWAP\"},\"action\":\"update\",\"data\":[{\"asks\":[[\"64471.2\",\"15.52\",\"0\",\"1\"],[\"64471.7\",\"0\",\"0\",\"0\"],[\"64471.9\",\"0.02\",\"0\",\"2\"],[\"64472.2\",\"0.02\",\"0\",\"2\"],[\"64482.5\",\"1.1\",\"0\",\"3\"],[\"64482.6\",\"0.01\",\"0\",\"1\"],[\"64486.4\",\"86.64\",\"0\",\"3\"],[\"64486.9\",\"0.12\",\"0\",\"2\"]],\"bids\":[[\"64454.4\",\"92.14\",\"0\",\"9\"],[\"64452.6\",\"1.56\",\"0\",\"1\"],[\"64452.2\",\"1.57\",\"0\",\"2\"],[\"64452.1\",\"31.86\",\"0\",\"5\"],[\"64451.9\",\"119.02\",\"0\",\"1\"],[\"64451.8\",\"0.01\",\"0\",\"1\"],[\"64451.7\",\"52.05\",\"0\",\"5\"],[\"64451.6\",\"0\",\"0\",\"0\"],[\"64451.2\",\"397.62\",\"0\",\"5\"],[\"64450.7\",\"1.6\",\"0\",\"3\"],[\"64450.2\",\"33.57\",\"0\",\"3\"],[\"64449.8\",\"4.24\",\"0\",\"4\"],[\"64449.6\",\"508.53\",\"0\",\"3\"],[\"64449.5\",\"38.84\",\"0\",\"3\"],[\"64449.3\",\"17.78\",\"0\",\"3\"],[\"64448.4\",\"0\",\"0\",\"0\"],[\"64447.9\",\"4\",\"0\",\"1\"],[\"64446.7\",\"76.53\",\"0\",\"1\"],[\"64443.5\",\"0.77\",\"0\",\"1\"],[\"64442.8\",\"0.03\",\"0\",\"3\"],[\"64441.9\",\"36.97\",\"0\",\"4\"],[\"64441.5\",\"61.31\",\"0\",\"3\"],[\"64441.1\",\"99.33\",\"0\",\"3\"],[\"64439.2\",\"0.02\",\"0\",\"1\"],[\"64438\",\"0.01\",\"0\",\"1\"],[\"64435.3\",\"0.01\",\"0\",\"1\"],[\"64431.5\",\"18.76\",\"0\",\"3\"],[\"64427.6\",\"0.01\",\"0\",\"1\"],[\"64414.6\",\"0.32\",\"0\",\"2\"],[\"64414.4\",\"99.09\",\"0\",\"1\"],[\"64410.4\",\"0.31\",\"0\",\"1\"],[\"64404.5\",\"0\",\"0\",\"0\"],[\"64404.4\",\"0\",\"0\",\"0\"],[\"64404.3\",\"0\",\"0\",\"0\"]],\"ts\":\"1782015906305\",\"checksum\":-1959976262,\"seqId\":325069854297,\"prevSeqId\":325069854207}]}"}
{"action": null, "capture_sequence": 34, "channel": "trades", "connection_sequence": 1, "event": null, "instId": "BTC-USDT-SWAP", "local_receive_ts": "2026-06-21T04:25:06Z", "monotonic_ns": 1643462239594100, "raw": "{\"arg\":{\"channel\":\"trades\",\"instId\":\"BTC-USDT-SWAP\"},\"data\":[{\"instId\":\"BTC-USDT-SWAP\",\"tradeId\":\"2718748824\",\"px\":\"64457.9\",\"sz\":\"5\",\"side\":\"sell\",\"ts\":\"1782015906334\",\"count\":\"1\",\"source\":\"0\",\"seqId\":325069854327}]}"}
{"action": "update", "capture_sequence": 35, "channel": "books", "connection_sequence": 1, "event": null, "instId": "BTC-USDT-SWAP", "local_receive_ts": "2026-06-21T04:25:06Z", "monotonic_ns": 1643462310958943, "raw": "{\"arg\":{\"channel\":\"books\",\"instId\":\"BTC-USDT-SWAP\"},\"action\":\"update\",\"data\":[{\"asks\":[[\"64473.5\",\"31.05\",\"0\",\"1\"],[\"64474.1\",\"0\",\"0\",\"0\"],[\"64483.8\",\"58.21\",\"0\",\"1\"],[\"64484.5\",\"0.06\",\"0\",\"3\"],[\"64490.9\",\"86.21\",\"0\",\"3\"],[\"64492.1\",\"20.07\",\"0\",\"1\"],[\"64492.5\",\"0.06\",\"0\",\"4\"],[\"64493\",\"13.72\",\"0\",\"4\"],[\"64508.6\",\"0\",\"0\",\"0\"],[\"64508.7\",\"0\",\"0\",\"0\"]],\"bids\":[[\"64457.9\",\"215.48\",\"0\",\"11\"],[\"64453.7\",\"1.56\",\"0\",\"1\"],[\"64452.6\",\"0\",\"0\",\"0\"],[\"64452.2\",\"0.01\",\"0\",\"1\"],[\"64452.1\",\"32.65\",\"0\",\"5\"],[\"64451.8\",\"0.78\",\"0\",\"2\"],[\"64451.7\",\"50.49\",\"0\",\"4\"],[\"64451.2\",\"396.06\",\"0\",\"4\"],[\"64450.7\",\"0.04\",\"0\",\"2\"],[\"64442.4\",\"0.01\",\"0\",\"1\"],[\"64441.9\",\"36.95\",\"0\",\"3\"],[\"64441.7\",\"0.02\",\"0\",\"1\"],[\"64441.6\",\"298.95\",\"0\",\"6\"],[\"64441.5\",\"61.29\",\"0\",\"2\"],[\"64441.4\",\"50.04\",\"0\",\"4\"],[\"64439.2\",\"0\",\"0\",\"0\"],[\"64437.2\",\"37.29\",\"0\",\"5\"],[\"64436.7\",\"15.66\",\"0\",\"2\"],[\"64435.9\",\"58.28\",\"0\",\"3\"],[\"64435.8\",\"0.07\",\"0\",\"1\"],[\"64435.1\",\"31.07\",\"0\",\"2\"]],\"ts\":\"1782015906405\",\"checksum\":-1867070288,\"seqId\":325069854360,\"prevSeqId\":325069854297}]}"}
{"action": "update", "capture_sequence": 36, "channel": "books", "connection_sequence": 1, "event": null, "instId": "BTC-USDT-SWAP", "local_receive_ts": "2026-06-21T04:25:06Z", "monotonic_ns": 1643462415807942, "raw": "{\"arg\":{\"channel\":\"books\",\"instId\":\"BTC-USDT-SWAP\"},\"action\":\"update\",\"data\":[{\"asks\":[[\"64469.5\",\"4.77\",\"0\",\"1\"],[\"64476.5\",\"0\",\"0\",\"0\"],[\"64480.7\",\"33.81\",\"0\",\"1\"],[\"64481.7\",\"0\",\"0\",\"0\"],[\"64483.3\",\"58.26\",\"0\",\"3\"],[\"64483.8\",\"0\",\"0\",\"0\"],[\"64485.8\",\"85.77\",\"0\",\"3\"],[\"64486.4\",\"1.27\",\"0\",\"2\"],[\"64490.9\",\"94.21\",\"0\",\"4\"],[\"64492.6\",\"98.92\",\"0\",\"1\"],[\"64508.6\",\"0.01\",\"0\",\"1\"],[\"64508.7\",\"42.88\",\"0\",\"9\"]],\"bids\":[[\"64455.6\",\"49.72\",\"0\",\"2\"],[\"64454.9\",\"0.01\",\"0\",\"1\"],[\"64454.8\",\"119.04\",\"0\",\"3\"],[\"64454.5\",\"0.01\",\"0\",\"1\"],[\"64454.4\",\"95.34\",\"0\",\"9\"],[\"64453.7\",\"0\",\"0\",\"0\"],[\"64452.1\",\"0.03\",\"0\",\"3\"],[\"64452\",\"14.03\",\"0\",\"5\"],[\"64451.9\",\"0\",\"0\",\"0\"],[\"64451.8\",\"31.84\",\"0\",\"3\"],[\"64451.3\",\"2.78\",\"0\",\"7\"],[\"64450.9\",\"0\",\"0\",\"0\"],[\"64450.2\",\"32.01\",\"0\",\"2\"],[\"64449.8\",\"2.68\",\"0\",\"3\"],[\"64449.3\",\"95.36\",\"0\",\"4\"],[\"64448.9\",\"0\",\"0\",\"0\"],[\"64448\",\"321.27\",\"0\",\"11\"],[\"64447.8\",\"2.51\",\"0\",\"3\"],[\"64445.5\",\"0\",\"0\",\"0\"],[\"64443.3\",\"130.09\",\"0\",\"2\"],[\"64442.7\",\"0\",\"0\",\"0\"],[\"64442.1\",\"6.22\",\"0\",\"1\"],[\"64441.9\",\"70.8\",\"0\",\"5\"],[\"64441.7\",\"86.2\",\"0\",\"1\"],[\"64441.5\",\"61.31\",\"0\",\"3\"],[\"64441.4\",\"50.02\",\"0\",\"3\"],[\"64441.1\",\"13.9\",\"0\",\"2\"],[\"64440.2\",\"85.44\",\"0\",\"2\"],[\"64439.2\",\"0.02\",\"0\",\"1\"],[\"64437.2\",\"37.27\",\"0\",\"4\"],[\"64436.4\",\"15.65\",\"0\",\"1\"],[\"64435.9\",\"0.03\",\"0\",\"2\"],[\"64435.2\",\"58.27\",\"0\",\"3\"],[\"64404.5\",\"0.16\",\"0\",\"2\"],[\"64404.4\",\"15.36\",\"0\",\"1\"],[\"64404.3\",\"0.04\",\"0\",\"3\"],[\"64404\",\"0.04\",\"0\",\"2\"]],\"ts\":\"1782015906505\",\"checksum\":109458671,\"seqId\":325069854444,\"prevSeqId\":325069854360}]}"}
{"action": "update", "capture_sequence": 37, "channel": "books", "connection_sequence": 1, "event": null, "instId": "BTC-USDT-SWAP", "local_receive_ts": "2026-06-21T04:25:06Z", "monotonic_ns": 1643462516572291, "raw": "{\"arg\":{\"channel\":\"books\",\"instId\":\"BTC-USDT-SWAP\"},\"action\":\"update\",\"data\":[{\"asks\":[[\"64458\",\"1539.95\",\"0\",\"72\"],[\"64458.7\",\"0.02\",\"0\",\"2\"],[\"64459\",\"0.01\",\"0\",\"1\"],[\"64459.2\",\"0.01\",\"0\",\"1\"],[\"64459.4\",\"1.56\",\"0\",\"1\"],[\"64459.9\",\"1.56\",\"0\",\"1\"],[\"64461.2\",\"3.64\",\"0\",\"2\"],[\"64461.3\",\"0\",\"0\",\"0\"],[\"64462.2\",\"0\",\"0\",\"0\"],[\"64463.7\",\"0\",\"0\",\"0\"],[\"64466.4\",\"70.86\",\"0\",\"3\"],[\"64467.8\",\"263.06\",\"0\",\"4\"],[\"64469.2\",\"0\",\"0\",\"0\"],[\"64471.6\",\"2.16\",\"0\",\"3\"],[\"64472.2\",\"0.01\",\"0\",\"1\"],[\"64472.8\",\"4.01\",\"0\",\"2\"],[\"64473.2\",\"31.06\",\"0\",\"2\"],[\"64473.5\",\"0\",\"0\",\"0\"],[\"64475\",\"263.06\",\"0\",\"9\"],[\"64475.1\",\"0.01\",\"0\",\"1\"],[\"64476.1\",\"0\",\"0\",\"0\"],[\"64476.5\",\"1.55\",\"0\",\"1\"],[\"64476.6\",\"0.15\",\"0\",\"1\"],[\"64480.7\",\"0\",\"0\",\"0\"],[\"64481.7\",\"33.8\",\"0\",\"1\"],[\"64482.5\",\"0.02\",\"0\",\"1\"],[\"64482.7\",\"4.22\",\"0\",\"3\"],[\"64483.2\",\"115.46\",\"0\",\"4\"],[\"64483.3\",\"0.05\",\"0\",\"2\"],[\"64484.2\",\"73.86\",\"0\",\"2\"],[\"64485.8\",\"0.4\",\"0\",\"2\"],[\"64486.7\",\"85.38\",\"0\",\"2\"],[\"64490.9\",\"8.07\",\"0\",\"3\"],[\"64492.1\",\"0\",\"0\",\"0\"],[\"64492.5\",\"86.2\",\"0\",\"5\"],[\"64492.6\",\"118.99\",\"0\",\"2\"],[\"64497.4\",\"2.37\",\"0\",\"3\"],[\"64508.8\",\"0.04\",\"0\",\"2\"]],\"bids\":[[\"64457.9\",\"227.58\",\"0\",\"15\"],[\"64457.7\",\"0.33\",\"0\",\"2\"],[\"64457.2\",\"0.01\",\"0\",\"1\"],[\"64457.1\",\"1.88\",\"0\",\"2\"],[\"64456.7\",\"0.02\",\"0\",\"2\"],[\"64456.6\",\"1.63\",\"0\",\"2\"],[\"64456.1\",\"66.97\",\"0\",\"3\"],[\"64455.8\",\"1.56\",\"0\",\"1\"],[\"64455.7\",\"0\",\"0\",\"0\"],[\"64455.6\",\"0\",\"0\",\"0\"],[\"64455.2\",\"0.04\",\"0\",\"4\"],[\"64455.1\",\"1.56\",\"0\",\"1\"],[\"64454.9\",\"46.54\",\"0\",\"1\"],[\"64454.8\",\"0.01\",\"0\",\"1\"],[\"64454.6\",\"2.36\",\"0\",\"2\"],[\"64454.1\",\"5.58\",\"0\",\"4\"],[\"64453.3\",\"1.56\",\"0\",\"1\"],[\"64452.6\",\"1.56\",\"0\",\"1\"],[\"64451.7\",\"50.48\",\"0\",\"3\"],[\"64451.6\",\"0.31\",\"0\",\"1\"],[\"64451.3\",\"13.68\",\"0\",\"7\"],[\"64450.2\",\"32.32\",\"0\",\"3\"],[\"64449.8\",\"79.48\",\"0\",\"3\"],[\"64449.7\",\"47.35\",\"0\",\"3\"],[\"64449.3\",\"16.22\",\"0\",\"2\"],[\"64449\",\"0.03\",\"0\",\"3\"],[\"64444.4\",\"10.77\",\"0\",\"2\"],[\"64443.5\",\"0\",\"0\",\"0\"],[\"64443.2\",\"138.77\",\"0\",\"6\"],[\"64442.7\",\"33.83\",\"0\",\"1\"],[\"64442.2\",\"20.1\",\"0\",\"2\"],[\"64442.1\",\"92.42\",\"0\",\"2\"],[\"64441.9\",\"36.96\",\"0\",\"3\"],[\"64441.7\",\"0\",\"0\",\"0\"],[\"64441.6\",\"278.86\",\"0\",\"5\"],[\"64441.4\",\"135.45\",\"0\",\"4\"],[\"64440.2\",\"0.01\",\"0\",\"1\"],[\"64436.4\",\"74.1\",\"0\",\"3\"],[\"64436\",\"201.03\",\"0\",\"4\"],[\"64435.9\",\"0.01\",\"0\",\"1\"],[\"64435.2\",\"0.02\",\"0\",\"2\"],[\"64435.1\",\"0.01\",\"0\",\"1\"],[\"64435\",\"264.07\",\"0\",\"2\"],[\"64415.2\",\"0.02\",\"0\",\"2\"],[\"64414.6\",\"0.31\",\"0\",\"1\"],[\"64404.7\",\"0\",\"0\",\"0\"],[\"64404.5\",\"0\",\"0\",\"0\"],[\"64404.4\",\"0\",\"0\",\"0\"],[\"64404.3\",\"0\",\"0\",\"0\"],[\"64404\",\"0\",\"0\",\"0\"]],\"ts\":\"1782015906605\",\"checksum\":-1492621881,\"seqId\":325069854665,\"prevSeqId\":325069854444}]}"}
{"action": null, "capture_sequence": 38, "channel": "trades", "connection_sequence": 1, "event": null, "instId": "BTC-USDT-SWAP", "local_receive_ts": "2026-06-21T04:25:06Z", "monotonic_ns": 1643462535201900, "raw": "{\"arg\":{\"channel\":\"trades\",\"instId\":\"BTC-USDT-SWAP\"},\"data\":[{\"instId\":\"BTC-USDT-SWAP\",\"tradeId\":\"2718748825\",\"px\":\"64457.9\",\"sz\":\"5\",\"side\":\"sell\",\"ts\":\"1782015906629\",\"count\":\"1\",\"source\":\"0\",\"seqId\":325069854702}]}"}
{"action": "update", "capture_sequence": 39, "channel": "books", "connection_sequence": 1, "event": null, "instId": "BTC-USDT-SWAP", "local_receive_ts": "2026-06-21T04:25:06Z", "monotonic_ns": 1643462611108765, "raw": "{\"arg\":{\"channel\":\"books\",\"instId\":\"BTC-USDT-SWAP\"},\"action\":\"update\",\"data\":[{\"asks\":[[\"64458.3\",\"0.03\",\"0\",\"3\"],[\"64458.4\",\"1.57\",\"0\",\"2\"],[\"64458.9\",\"1.56\",\"0\",\"1\"],[\"64459\",\"0\",\"0\",\"0\"],[\"64464.4\",\"37.53\",\"0\",\"2\"],[\"64467.4\",\"2.92\",\"0\",\"1\"],[\"64473.2\",\"0.01\",\"0\",\"1\"],[\"64474.1\",\"31.05\",\"0\",\"1\"],[\"64490.9\",\"86.21\",\"0\",\"3\"],[\"64492.2\",\"21.97\",\"0\",\"8\"],[\"64492.5\",\"0.06\",\"0\",\"4\"],[\"64492.6\",\"98.92\",\"0\",\"1\"],[\"64492.9\",\"9.01\",\"0\",\"3\"],[\"64508.7\",\"0\",\"0\",\"0\"],[\"64508.8\",\"0\",\"0\",\"0\"]],\"bids\":[[\"64457.9\",\"211.35\",\"0\",\"13\"],[\"64457.7\",\"0.32\",\"0\",\"1\"],[\"64457.2\",\"0\",\"0\",\"0\"],[\"64457.1\",\"0.32\",\"0\",\"1\"],[\"64456.7\",\"0.01\",\"0\",\"1\"],[\"64456.6\",\"0.07\",\"0\",\"1\"],[\"64456.3\",\"0.01\",\"0\",\"1\"],[\"64456.2\",\"59.96\",\"0\",\"2\"],[\"64456.1\",\"0.02\",\"0\",\"2\"],[\"64455.8\",\"0\",\"0\",\"0\"],[\"64455.2\",\"0.05\",\"0\",\"5\"],[\"64455.1\",\"0.01\",\"0\",\"1\"],[\"64455\",\"109.04\",\"0\",\"2\"],[\"64454.6\",\"79.94\",\"0\",\"3\"],[\"64452.8\",\"19.59\",\"0\",\"2\"],[\"64451.5\",\"17.46\",\"0\",\"2\"],[\"64450.8\",\"0\",\"0\",\"0\"],[\"64442.2\",\"0.01\",\"0\",\"1\"],[\"64441.7\",\"20.09\",\"0\",\"1\"],[\"64436.3\",\"117.15\",\"0\",\"4\"],[\"64435.7\",\"31.06\",\"0\",\"1\"],[\"64435\",\"233.01\",\"0\",\"1\"],[\"64404.8\",\"0\",\"0\",\"0\"]],\"ts\":\"1782015906705\",\"checksum\":498300604,\"seqId\":325069854783,\"prevSeqId\":325069854665}]}"}
{"action": "update", "capture_sequence": 40, "channel": "books", "connection_sequence": 1, "event": null, "instId": "BTC-USDT-SWAP", "local_receive_ts": "2026-06-21T04:25:06Z", "monotonic_ns": 1643462710642130, "raw": "{\"arg\":{\"channel\":\"books\",\"instId\":\"BTC-USDT-SWAP\"},\"action\":\"update\",\"data\":[{\"asks\":[[\"64483.1\",\"101.07\",\"0\",\"5\"],[\"64483.2\",\"114.69\",\"0\",\"3\"]],\"bids\":[[\"64455.2\",\"0.04\",\"0\",\"4\"],[\"64455\",\"109.05\",\"0\",\"3\"],[\"64454.6\",\"78.38\",\"0\",\"2\"],[\"64454.1\",\"4.02\",\"0\",\"3\"],[\"64453.3\",\"0\",\"0\",\"0\"],[\"64444.4\",\"10\",\"0\",\"1\"],[\"64443.8\",\"0.77\",\"0\",\"1\"],[\"64442.6\",\"15.66\",\"0\",\"2\"],[\"64442.2\",\"0\",\"0\",\"0\"],[\"64404.8\",\"0.04\",\"0\",\"1\"]],\"ts\":\"1782015906805\",\"checksum\":1161154194,\"seqId\":325069854798,\"prevSeqId\":325069854783}]}"}
{"action": "update", "capture_sequence": 41, "channel": "books", "connection_sequence": 1, "event": null, "instId": "BTC-USDT-SWAP", "local_receive_ts": "2026-06-21T04:25:07Z", "monotonic_ns": 1643462811277293, "raw": "{\"arg\":{\"channel\":\"books\",\"instId\":\"BTC-USDT-SWAP\"},\"action\":\"update\",\"data\":[{\"asks\":[[\"64480.7\",\"33.81\",\"0\",\"1\"],[\"64481.7\",\"0\",\"0\",\"0\"],[\"64482.6\",\"0.32\",\"0\",\"2\"],[\"64482.7\",\"3.91\",\"0\",\"2\"],[\"64485.8\",\"85.77\",\"0\",\"3\"],[\"64486.7\",\"0.01\",\"0\",\"1\"],[\"64491.4\",\"20.09\",\"0\",\"3\"],[\"64492.2\",\"1.9\",\"0\",\"7\"],[\"64497.4\",\"0.09\",\"0\",\"2\"]],\"bids\":[[\"64456.2\",\"58.26\",\"0\",\"1\"],[\"64455\",\"20.88\",\"0\",\"3\"],[\"64454.4\",\"91.44\",\"0\",\"9\"],[\"64450.2\",\"32.01\",\"0\",\"2\"],[\"64449.6\",\"524.65\",\"0\",\"8\"],[\"64449.4\",\"16.48\",\"0\",\"3\"],[\"64448\",\"284.79\",\"0\",\"11\"],[\"64446.7\",\"79.93\",\"0\",\"6\"],[\"64442.7\",\"0\",\"0\",\"0\"],[\"64442.6\",\"15.65\",\"0\",\"1\"],[\"64442.2\",\"0.01\",\"0\",\"1\"],[\"64442.1\",\"6.22\",\"0\",\"1\"],[\"64441.7\",\"0\",\"0\",\"0\"],[\"64441.5\",\"95.14\",\"0\",\"4\"],[\"64441.4\",\"50.02\",\"0\",\"3\"],[\"64440.7\",\"20.09\",\"0\",\"1\"],[\"64440.3\",\"86.24\",\"0\",\"3\"],[\"64440.2\",\"85.44\",\"0\",\"2\"],[\"64424.2\",\"0.01\",\"0\",\"1\"]],\"ts\":\"1782015906905\",\"checksum\":647850525,\"seqId\":325069854859,\"prevSeqId\":325069854798}]}"}
{"action": null, "capture_sequence": 42, "channel": "trades", "connection_sequence": 1, "event": null, "instId": "BTC-USDT-SWAP", "local_receive_ts": "2026-06-21T04:25:07Z", "monotonic_ns": 1643462873776988, "raw": "{\"arg\":{\"channel\":\"trades\",\"instId\":\"BTC-USDT-SWAP\"},\"data\":[{\"instId\":\"BTC-USDT-SWAP\",\"tradeId\":\"2718748826\",\"px\":\"64457.9\",\"sz\":\"5\",\"side\":\"sell\",\"ts\":\"1782015906968\",\"count\":\"1\",\"source\":\"0\",\"seqId\":325069854865}]}"}
{"action": "update", "capture_sequence": 43, "channel": "books", "connection_sequence": 1, "event": null, "instId": "BTC-USDT-SWAP", "local_receive_ts": "2026-06-21T04:25:07Z", "monotonic_ns": 1643462910905674, "raw": "{\"arg\":{\"channel\":\"books\",\"instId\":\"BTC-USDT-SWAP\"},\"action\":\"update\",\"data\":[{\"asks\":[[\"64491.4\",\"0.02\",\"0\",\"2\"],[\"64492.1\",\"20.07\",\"0\",\"1\"],[\"64508.6\",\"0\",\"0\",\"0\"]],\"bids\":[[\"64457.9\",\"206.35\",\"0\",\"13\"],[\"64456.7\",\"0\",\"0\",\"0\"],[\"64456.3\",\"0.02\",\"0\",\"2\"],[\"64456.1\",\"0.01\",\"0\",\"1\"],[\"64455.1\",\"0.02\",\"0\",\"2\"],[\"64454.1\",\"5.58\",\"0\",\"4\"],[\"64453.6\",\"1.57\",\"0\",\"2\"],[\"64453.1\",\"1.57\",\"0\",\"2\"],[\"64451.1\",\"1.56\",\"0\",\"1\"],[\"64450.6\",\"1.56\",\"0\",\"1\"],[\"64441.9\",\"123.16\",\"0\",\"4\"],[\"64441.6\",\"298.95\",\"0\",\"6\"],[\"64440.7\",\"0\",\"0\",\"0\"],[\"64440.3\",\"0.04\",\"0\",\"2\"],[\"64410.6\",\"20.74\",\"0\",\"2\"],[\"64410.5\",\"46.92\",\"0\",\"2\"]],\"ts\":\"1782015907005\",\"checksum\":-656880656,\"seqId\":325069854883,\"prevSeqId\":325069854859}]}"}
{"action": "update", "capture_sequence": 44, "channel": "books", "connection_sequence": 1, "event": null, "instId": "BTC-USDT-SWAP", "local_receive_ts": "2026-06-21T04:25:07Z", "monotonic_ns": 1643463011124827, "raw": "{\"arg\":{\"channel\":\"books\",\"instId\":\"BTC-USDT-SWAP\"},\"action\":\"update\",\"data\":[{\"asks\":[[\"64467.8\",\"346.86\",\"0\",\"5\"],[\"64473.8\",\"1.18\",\"0\",\"6\"],[\"64492.4\",\"57.86\",\"0\",\"6\"],[\"64495.2\",\"2.29\",\"0\",\"2\"]],\"bids\":[[\"64455.6\",\"0.01\",\"0\",\"1\"],[\"64455\",\"20.87\",\"0\",\"2\"],[\"64454.4\",\"93\",\"0\",\"10\"],[\"64454.1\",\"4.02\",\"0\",\"3\"],[\"64453.7\",\"1.56\",\"0\",\"1\"],[\"64453.6\",\"0.01\",\"0\",\"1\"],[\"64451.8\",\"32.15\",\"0\",\"4\"],[\"64451.6\",\"0\",\"0\",\"0\"],[\"64450.4\",\"1.08\",\"0\",\"2\"],[\"64450.1\",\"42.33\",\"0\",\"2\"],[\"64449.7\",\"46.58\",\"0\",\"2\"],[\"64434.3\",\"3.11\",\"0\",\"2\"],[\"64431.5\",\"15.66\",\"0\",\"2\"],[\"64404.8\",\"0\",\"0\",\"0\"]],\"ts\":\"1782015907105\",\"checksum\":1148626605,\"seqId\":325069854924,\"prevSeqId\":325069854883}]}"}
{"action": "update", "capture_sequence": 45, "channel": "books", "connection_sequence": 1, "event": null, "instId": "BTC-USDT-SWAP", "local_receive_ts": "2026-06-21T04:25:07Z", "monotonic_ns": 1643463110889915, "raw": "{\"arg\":{\"channel\":\"books\",\"instId\":\"BTC-USDT-SWAP\"},\"action\":\"update\",\"data\":[{\"asks\":[[\"64458\",\"1540.05\",\"0\",\"73\"]],\"bids\":[[\"64455.6\",\"0\",\"0\",\"0\"],[\"64455\",\"20.88\",\"0\",\"3\"],[\"64454.4\",\"91.44\",\"0\",\"9\"],[\"64453.1\",\"0.01\",\"0\",\"1\"],[\"64453\",\"1.56\",\"0\",\"1\"],[\"64449.6\",\"526.21\",\"0\",\"9\"],[\"64449.2\",\"3.13\",\"0\",\"3\"],[\"64435.1\",\"184.68\",\"0\",\"2\"]],\"ts\":\"1782015907205\",\"checksum\":267860251,\"seqId\":325069854949,\"prevSeqId\":325069854924}]}"}
{"action": null, "capture_sequence": 46, "channel": "trades", "connection_sequence": 1, "event": null, "instId": "BTC-USDT-SWAP", "local_receive_ts": "2026-06-21T04:25:07Z", "monotonic_ns": 1643463191312581, "raw": "{\"arg\":{\"channel\":\"trades\",\"instId\":\"BTC-USDT-SWAP\"},\"data\":[{\"instId\":\"BTC-USDT-SWAP\",\"tradeId\":\"2718748827\",\"px\":\"64457.9\",\"sz\":\"5\",\"side\":\"sell\",\"ts\":\"1782015907286\",\"count\":\"1\",\"source\":\"0\",\"seqId\":325069854959}]}"}
{"action": "update", "capture_sequence": 47, "channel": "books", "connection_sequence": 1, "event": null, "instId": "BTC-USDT-SWAP", "local_receive_ts": "2026-06-21T04:25:07Z", "monotonic_ns": 1643463210859911, "raw": "{\"arg\":{\"channel\":\"books\",\"instId\":\"BTC-USDT-SWAP\"},\"action\":\"update\",\"data\":[{\"asks\":[[\"64500\",\"3479.31\",\"0\",\"1035\"]],\"bids\":[[\"64457.9\",\"201.35\",\"0\",\"13\"],[\"64453.7\",\"0\",\"0\",\"0\"],[\"64453.1\",\"1.57\",\"0\",\"2\"],[\"64453\",\"0\",\"0\",\"0\"],[\"64404.8\",\"0.04\",\"0\",\"1\"],[\"64404.7\",\"0.77\",\"0\",\"1\"]],\"ts\":\"1782015907305\",\"checksum\":-1853149004,\"seqId\":325069854971,\"prevSeqId\":325069854949}]}"}
{"action": "update", "capture_sequence": 48, "channel": "books", "connection_sequence": 1, "event": null, "instId": "BTC-USDT-SWAP", "local_receive_ts": "2026-06-21T04:25:07Z", "monotonic_ns": 1643463311156852, "raw": "{\"arg\":{\"channel\":\"books\",\"instId\":\"BTC-USDT-SWAP\"},\"action\":\"update\",\"data\":[{\"asks\":[[\"64480.7\",\"0\",\"0\",\"0\"],[\"64481.9\",\"33.81\",\"0\",\"2\"],[\"64483.3\",\"58.26\",\"0\",\"3\"],[\"64484.2\",\"15.65\",\"0\",\"1\"],[\"64485.8\",\"0.4\",\"0\",\"2\"],[\"64486.7\",\"85.38\",\"0\",\"2\"],[\"64490.9\",\"0.07\",\"0\",\"2\"],[\"64492.1\",\"0\",\"0\",\"0\"],[\"64492.5\",\"86.2\",\"0\",\"5\"],[\"64492.9\",\"29.08\",\"0\",\"4\"],[\"64508.4\",\"1367.19\",\"0\",\"6\"],[\"64508.6\",\"0.01\",\"0\",\"1\"],[\"64508.7\",\"42.88\",\"0\",\"9\"]],\"bids\":[[\"64453.3\",\"1.56\",\"0\",\"1\"],[\"64453.1\",\"0.01\",\"0\",\"1\"],[\"64452.1\",\"1.59\",\"0\",\"4\"],[\"64452\",\"12.47\",\"0\",\"4\"],[\"64451.8\",\"31.84\",\"0\",\"3\"],[\"64451.6\",\"0.31\",\"0\",\"1\"],[\"64449.4\",\"16.17\",\"0\",\"2\"],[\"64448.9\",\"0.31\",\"0\",\"1\"],[\"64448.7\",\"5.56\",\"0\",\"2\"],[\"64442.7\",\"33.83\",\"0\",\"1\"],[\"64442.4\",\"20.1\",\"0\",\"2\"],[\"64442.1\",\"92.42\",\"0\",\"2\"],[\"64441.9\",\"36.96\",\"0\",\"3\"],[\"64441.6\",\"278.86\",\"0\",\"5\"],[\"64441.5\",\"61.31\",\"0\",\"3\"],[\"64441.4\",\"135.45\",\"0\",\"4\"],[\"64440.2\",\"0.01\",\"0\",\"1\"],[\"64436.4\",\"15.85\",\"0\",\"2\"],[\"64435.5\",\"570.45\",\"0\",\"4\"],[\"64405.1\",\"0\",\"0\",\"0\"],[\"64405\",\"0\",\"0\",\"0\"],[\"64404.8\",\"0\",\"0\",\"0\"],[\"64404.7\",\"0\",\"0\",\"0\"]],\"ts\":\"1782015907405\",\"checksum\":-1853149004,\"seqId\":325069855031,\"prevSeqId\":325069854971}]}"}
{"action": "update", "capture_sequence": 49, "channel": "books", "connection_sequence": 1, "event": null, "instId": "BTC-USDT-SWAP", "local_receive_ts": "2026-06-21T04:25:07Z", "monotonic_ns": 1643463410514960, "raw": "{\"arg\":{\"channel\":\"books\",\"instId\":\"BTC-USDT-SWAP\"},\"action\":\"update\",\"data\":[{\"asks\":[[\"64467.4\",\"0\",\"0\",\"0\"],[\"64490.9\",\"86.21\",\"0\",\"3\"],[\"64492.1\",\"20.07\",\"0\",\"1\"],[\"64492.5\",\"0.06\",\"0\",\"4\"],[\"64492.9\",\"9.01\",\"0\",\"3\"]],\"bids\":[[\"64453.3\",\"0\",\"0\",\"0\"],[\"64453\",\"1.56\",\"0\",\"1\"],[\"64449.7\",\"46.89\",\"0\",\"3\"],[\"64448.9\",\"0\",\"0\",\"0\"],[\"64442.4\",\"0.01\",\"0\",\"1\"],[\"64442.1\",\"6.22\",\"0\",\"1\"],[\"64441.9\",\"123.16\",\"0\",\"4\"],[\"64441.6\",\"298.95\",\"0\",\"6\"],[\"64405.1\",\"0.07\",\"0\",\"3\"]],\"ts\":\"1782015907505\",\"checksum\":-1853149004,\"seqId\":325069855063,\"prevSeqId\":325069855031}]}"}
{"action": null, "capture_sequence": 50, "channel": "trades", "connection_sequence": 1, "event": null, "instId": "BTC-USDT-SWAP", "local_receive_ts": "2026-06-21T04:25:07Z", "monotonic_ns": 1643463423123469, "raw": "{\"arg\":{\"channel\":\"trades\",\"instId\":\"BTC-USDT-SWAP\"},\"data\":[{\"instId\":\"BTC-USDT-SWAP\",\"tradeId\":\"2718748828\",\"px\":\"64457.9\",\"sz\":\"0.65\",\"side\":\"sell\",\"ts\":\"1782015907517\",\"count\":\"1\",\"source\":\"0\",\"seqId\":325069855068}]}"}
{"action": null, "capture_sequence": 51, "channel": "trades", "connection_sequence": 1, "event": null, "instId": "BTC-USDT-SWAP", "local_receive_ts": "2026-06-21T04:25:07Z", "monotonic_ns": 1643463467929272, "raw": "{\"arg\":{\"channel\":\"trades\",\"instId\":\"BTC-USDT-SWAP\"},\"data\":[{\"instId\":\"BTC-USDT-SWAP\",\"tradeId\":\"2718748829\",\"px\":\"64457.9\",\"sz\":\"5\",\"side\":\"sell\",\"ts\":\"1782015907562\",\"count\":\"1\",\"source\":\"0\",\"seqId\":325069855105}]}"}
{"action": "update", "capture_sequence": 52, "channel": "books", "connection_sequence": 1, "event": null, "instId": "BTC-USDT-SWAP", "local_receive_ts": "2026-06-21T04:25:07Z", "monotonic_ns": 1643463520675361, "raw": "{\"arg\":{\"channel\":\"books\",\"instId\":\"BTC-USDT-SWAP\"},\"action\":\"update\",\"data\":[{\"asks\":[[\"64458\",\"550.55\",\"0\",\"66\"],[\"64458.1\",\"0.01\",\"0\",\"1\"],[\"64458.3\",\"4.54\",\"0\",\"3\"],[\"64458.4\",\"0.01\",\"0\",\"1\"],[\"64458.7\",\"0\",\"0\",\"0\"],[\"64458.8\",\"0\",\"0\",\"0\"],[\"64458.9\",\"0\",\"0\",\"0\"],[\"64459.3\",\"1.03\",\"0\",\"4\"],[\"64459.4\",\"0.6\",\"0\",\"1\"],[\"64459.7\",\"0.01\",\"0\",\"1\"],[\"64459.8\",\"1.56\",\"0\",\"1\"],[\"64459.9\",\"0\",\"0\",\"0\"],[\"64460.5\",\"1.56\",\"0\",\"1\"],[\"64461\",\"1.57\",\"0\",\"2\"],[\"64461.2\",\"47.95\",\"0\",\"3\"],[\"64461.3\",\"150\",\"0\",\"1\"],[\"64461.4\",\"0.03\",\"0\",\"3\"],[\"64464.1\",\"37.29\",\"0\",\"5\"],[\"64464.2\",\"209.9\",\"0\",\"2\"],[\"64464.4\",\"0.3\",\"0\",\"1\"],[\"64465\",\"67.79\",\"0\",\"2\"],[\"64465.5\",\"1.01\",\"0\",\"2\"],[\"64466\",\"0.01\",\"0\",\"1\"],[\"64466.8\",\"0\",\"0\",\"0\"],[\"64471.2\",\"0\",\"0\",\"0\"],[\"64471.6\",\"0.04\",\"0\",\"2\"],[\"64472.6\",\"15.53\",\"0\",\"2\"],[\"64474.1\",\"0\",\"0\",\"0\"],[\"64474.2\",\"0.29\",\"0\",\"1\"],[\"64475.5\",\"263.91\",\"0\",\"2\"],[\"64475.6\",\"0.39\",\"0\",\"2\"],[\"64476.3\",\"2.19\",\"0\",\"1\"],[\"64476.5\",\"0\",\"0\",\"0\"],[\"64476.6\",\"0\",\"0\",\"0\"],[\"64478.5\",\"1.55\",\"0\",\"1\"],[\"64479.6\",\"115.35\",\"0\",\"4\"],[\"64479.9\",\"68.41\",\"0\",\"4\"],[\"64481.9\",\"0.01\",\"0\",\"1\"],[\"64482.6\",\"0.01\",\"0\",\"1\"],[\"64483.1\",\"100.61\",\"0\",\"5\"],[\"64483.3\",\"0.05\",\"0\",\"2\"],[\"64483.8\",\"34.57\",\"0\",\"2\"],[\"64486.7\",\"0.01\",\"0\",\"1\"],[\"64487.4\",\"58.69\",\"0\",\"6\"],[\"64487.9\",\"85.38\",\"0\",\"2\"],[\"64490.9\",\"0.07\",\"0\",\"2\"],[\"64492.1\",\"0\",\"0\",\"0\"],[\"64493.1\",\"117.89\",\"0\",\"6\"],[\"64495\",\"21.57\",\"0\",\"10\"],[\"64508.8\",\"0.04\",\"0\",\"2\"],[\"64508.9\",\"11.25\",\"0\",\"3\"]],\"bids\":[[\"64457.9\",\"532.86\",\"0\",\"18\"],[\"64457.5\",\"0.01\",\"0\",\"1\"],[\"64457.4\",\"1.56\",\"0\",\"1\"],[\"64456.7\",\"0.01\",\"0\",\"1\"],[\"64456.6\",\"2.33\",\"0\",\"3\"],[\"64456.2\",\"84.9\",\"0\",\"2\"],[\"64455.6\",\"1.56\",\"0\",\"1\"],[\"64455.1\",\"111.07\",\"0\",\"2\"],[\"64455\",\"20.87\",\"0\",\"2\"],[\"64454.8\",\"1.57\",\"0\",\"2\"],[\"64454.7\",\"37.25\",\"0\",\"2\"],[\"64454.6\",\"0\",\"0\",\"0\"],[\"64454.4\",\"151.56\",\"0\",\"8\"],[\"64454.2\",\"1.57\",\"0\",\"2\"],[\"64453.2\",\"0.31\",\"0\",\"1\"],[\"64453.1\",\"2.2\",\"0\",\"2\"],[\"64453\",\"0\",\"0\",\"0\"],[\"64452.8\",\"21.15\",\"0\",\"3\"],[\"64452.6\",\"0\",\"0\",\"0\"],[\"64452.3\",\"1.57\",\"0\",\"2\"],[\"64452.1\",\"0.03\",\"0\",\"3\"],[\"64451.9\",\"1.56\",\"0\",\"1\"],[\"64451.7\",\"210.21\",\"0\",\"5\"],[\"64451.6\",\"0\",\"0\",\"0\"],[\"64451.5\",\"15.9\",\"0\",\"1\"],[\"64451.4\",\"167.37\",\"0\",\"5\"],[\"64451.3\",\"92.02\",\"0\",\"9\"],[\"64450.5\",\"6.61\",\"0\",\"5\"],[\"64450.4\",\"0.31\",\"0\",\"1\"],[\"64450.1\",\"40.77\",\"0\",\"1\"],[\"64449.8\",\"1.91\",\"0\",\"2\"],[\"64449.7\",\"46.58\",\"0\",\"2\"],[\"64449.6\",\"524.65\",\"0\",\"8\"],[\"64449.2\",\"1.57\",\"0\",\"2\"],[\"64448.7\",\"4\",\"0\",\"1\"],[\"64447.8\",\"0.39\",\"0\",\"2\"],[\"64445\",\"2.03\",\"0\",\"4\"],[\"64444.5\",\"54.68\",\"0\",\"3\"],[\"64443.8\",\"0\",\"0\",\"0\"],[\"64443.5\",\"86.2\",\"0\",\"1\"],[\"64443.2\",\"135.66\",\"0\",\"5\"],[\"64442.7\",\"0\",\"0\",\"0\"],[\"64442.4\",\"85.44\",\"0\",\"2\"],[\"64441.9\",\"36.96\",\"0\",\"3\"],[\"64441.6\",\"278.86\",\"0\",\"5\"],[\"64441.4\",\"50.02\",\"0\",\"3\"],[\"64439\",\"58.26\",\"0\",\"2\"],[\"64438.2\",\"37.27\",\"0\",\"4\"],[\"64437.2\",\"0.01\",\"0\",\"1\"],[\"64437\",\"31.06\",\"0\",\"1\"],[\"64436.6\",\"243.04\",\"0\",\"5\"],[\"64436.4\",\"15.65\",\"0\",\"1\"],[\"64435.7\",\"0\",\"0\",\"0\"],[\"64435.5\",\"512.2\",\"0\",\"3\"],[\"64435.1\",\"0.01\",\"0\",\"1\"],[\"64435\",\"0\",\"0\",\"0\"],[\"64405.1\",\"0\",\"0\",\"0\"]],\"ts\":\"1782015907605\",\"checksum\":-1958762109,\"seqId\":325069855339,\"prevSeqId\":325069855063}]}"}
{"action": "update", "capture_sequence": 53, "channel": "books", "connection_sequence": 1, "event": null, "instId": "BTC-USDT-SWAP", "local_receive_ts": "2026-06-21T04:25:07Z", "monotonic_ns": 1643463615867931, "raw": "{\"arg\":{\"channel\":\"books\",\"instId\":\"BTC-USDT-SWAP\"},\"action\":\"update\",\"data\":[{\"asks\":[[\"64458\",\"529.5\",\"0\",\"62\"],[\"64458.2\",\"0.01\",\"0\",\"1\"],[\"64458.3\",\"2.25\",\"0\",\"3\"],[\"64459.3\",\"1.04\",\"0\",\"5\"],[\"64459.7\",\"0\",\"0\",\"0\"],[\"64459.8\",\"0\",\"0\",\"0\"],[\"64460.5\",\"0\",\"0\",\"0\"],[\"64460.9\",\"0.01\",\"0\",\"1\"],[\"64461\",\"49.97\",\"0\",\"3\"],[\"64461.2\",\"0.02\",\"0\",\"1\"],[\"64461.4\",\"0.04\",\"0\",\"4\"],[\"64463.9\",\"2.33\",\"0\",\"2\"],[\"64464\",\"0.79\",\"0\",\"3\"],[\"64466.5\",\"1.22\",\"0\",\"2\"],[\"64471\",\"0.54\",\"0\",\"3\"],[\"64472.4\",\"15.52\",\"0\",\"1\"],[\"64472.6\",\"0.01\",\"0\",\"1\"],[\"64472.8\",\"4\",\"0\",\"1\"],[\"64475\",\"263.07\",\"0\",\"10\"],[\"64475.1\",\"0.02\",\"0\",\"1\"],[\"64476.5\",\"0.15\",\"0\",\"1\"],[\"64477.9\",\"1.55\",\"0\",\"1\"],[\"64478.5\",\"0\",\"0\",\"0\"],[\"64479.7\",\"6.22\",\"0\",\"2\"],[\"64479.9\",\"62.2\",\"0\",\"3\"],[\"64481.1\",\"62.31\",\"0\",\"3\"],[\"64483.1\",\"100.3\",\"0\",\"4\"],[\"64483.5\",\"0\",\"0\",\"0\"],[\"64483.7\",\"0.32\",\"0\",\"2\"],[\"64487.7\",\"130.36\",\"0\",\"5\"],[\"64487.9\",\"0.01\",\"0\",\"1\"],[\"64488.6\",\"85.38\",\"0\",\"3\"],[\"64492.5\",\"86.2\",\"0\",\"5\"],[\"64493.1\",\"31.76\",\"0\",\"5\"],[\"64493.5\",\"22.36\",\"0\",\"6\"],[\"64495\",\"1.5\",\"0\",\"9\"],[\"64498.1\",\"0.04\",\"0\",\"4\"],[\"64500\",\"3479.33\",\"0\",\"1036\"]],\"bids\":[[\"64457.9\",\"482.65\",\"0\",\"19\"],[\"64457.5\",\"0\",\"0\",\"0\"],[\"64457.4\",\"0\",\"0\",\"0\"],[\"64456.6\",\"0.77\",\"0\",\"2\"],[\"64456.2\",\"58.26\",\"0\",\"1\"],[\"64455.7\",\"0.01\",\"0\",\"1\"],[\"64455.1\",\"0.02\",\"0\",\"2\"],[\"64454.4\",\"212.51\",\"0\",\"9\"],[\"64453.2\",\"0\",\"0\",\"0\"],[\"64452.8\",\"1.61\",\"0\",\"2\"],[\"64452.4\",\"0.31\",\"0\",\"1\"],[\"64451.7\",\"308.15\",\"0\",\"6\"],[\"64451.3\",\"13.68\",\"0\",\"7\"],[\"64451.2\",\"396.07\",\"0\",\"5\"],[\"64450.7\",\"77.92\",\"0\",\"4\"],[\"64450.5\",\"6.3\",\"0\",\"4\"],[\"64449.8\",\"2.68\",\"0\",\"3\"],[\"64449.5\",\"38.83\",\"0\",\"2\"],[\"64444.5\",\"34.59\",\"0\",\"2\"],[\"64443.5\",\"0\",\"0\",\"0\"],[\"64443.3\",\"130.12\",\"0\",\"4\"],[\"64443.1\",\"3.22\",\"0\",\"1\"],[\"64442.9\",\"20.09\",\"0\",\"1\"],[\"64442.8\",\"86.23\",\"0\",\"4\"],[\"64442.7\",\"85.42\",\"0\",\"1\"],[\"64442.4\",\"0.01\",\"0\",\"1\"],[\"64442.2\",\"0\",\"0\",\"0\"],[\"64439.4\",\"37.27\",\"0\",\"4\"],[\"64439.2\",\"0\",\"0\",\"0\"],[\"64438.8\",\"0.02\",\"0\",\"1\"],[\"64438.7\",\"3.99\",\"0\",\"1\"],[\"64438.2\",\"0.01\",\"0\",\"1\"],[\"64436.8\",\"1\",\"0\",\"1\"],[\"64436.3\",\"117.34\",\"0\",\"5\"],[\"64436\",\"201.01\",\"0\",\"3\"],[\"64431.9\",\"17.94\",\"0\",\"3\"],[\"64431.5\",\"15.65\",\"0\",\"1\"],[\"64415.9\",\"0.01\",\"0\",\"1\"],[\"64415.2\",\"0.01\",\"0\",\"1\"],[\"64405.6\",\"0.02\",\"0\",\"2\"],[\"64405.3\",\"0\",\"0\",\"0\"],[\"64405.2\",\"0\",\"0\",\"0\"]],\"ts\":\"1782015907705\",\"checksum\":-566422517,\"seqId\":325069855628,\"prevSeqId\":325069855339}]}"}
{"action": "update", "capture_sequence": 54, "channel": "books", "connection_sequence": 1, "event": null, "instId": "BTC-USDT-SWAP", "local_receive_ts": "2026-06-21T04:25:07Z", "monotonic_ns": 1643463715668121, "raw": "{\"arg\":{\"channel\":\"books\",\"instId\":\"BTC-USDT-SWAP\"},\"action\":\"update\",\"data\":[{\"asks\":[[\"64461\",\"48.41\",\"0\",\"2\"],[\"64461.5\",\"0\",\"0\",\"0\"],[\"64463.6\",\"14.45\",\"0\",\"1\"],[\"64463.9\",\"1.56\",\"0\",\"1\"],[\"64464\",\"1.56\",\"0\",\"4\"],[\"64465.8\",\"65.24\",\"0\",\"4\"],[\"64466.5\",\"1.2\",\"0\",\"1\"],[\"64475\",\"263.09\",\"0\",\"11\"],[\"64475.1\",\"0\",\"0\",\"0\"],[\"64477.3\",\"2.56\",\"0\",\"3\"],[\"64477.9\",\"0\",\"0\",\"0\"],[\"64481.9\",\"33.81\",\"0\",\"2\"],[\"64483.8\",\"0.77\",\"0\",\"1\"],[\"64485.5\",\"58.21\",\"0\",\"2\"],[\"64486.9\",\"85.49\",\"0\",\"3\"],[\"64487.4\",\"0.49\",\"0\",\"5\"],[\"64488.6\",\"0.02\",\"0\",\"2\"],[\"64509\",\"155.92\",\"0\",\"2\"],[\"64509.1\",\"0.02\",\"0\",\"2\"]],\"bids\":[[\"64457.9\",\"472.65\",\"0\",\"18\"],[\"64457.6\",\"0.47\",\"0\",\"2\"],[\"64456.2\",\"81.82\",\"0\",\"2\"],[\"64455.2\",\"31.87\",\"0\",\"7\"],[\"64455.1\",\"119.03\",\"0\",\"2\"],[\"64452.1\",\"12.45\",\"0\",\"4\"],[\"64452\",\"76.66\",\"0\",\"4\"],[\"64451.8\",\"0.01\",\"0\",\"1\"],[\"64451.2\",\"396.06\",\"0\",\"4\"],[\"64451.1\",\"1.57\",\"0\",\"2\"],[\"64450.7\",\"0.35\",\"0\",\"3\"],[\"64450.5\",\"7.07\",\"0\",\"5\"],[\"64450.4\",\"77.88\",\"0\",\"2\"],[\"64449.8\",\"1.91\",\"0\",\"2\"],[\"64446.7\",\"3.4\",\"0\",\"5\"],[\"64444.5\",\"0.77\",\"0\",\"1\"],[\"64443\",\"33.85\",\"0\",\"3\"],[\"64442.8\",\"0.03\",\"0\",\"3\"],[\"64442.7\",\"0\",\"0\",\"0\"],[\"64442.1\",\"92.42\",\"0\",\"2\"],[\"64441.5\",\"146.74\",\"0\",\"4\"],[\"64439.5\",\"37.27\",\"0\",\"4\"],[\"64439.4\",\"0.01\",\"0\",\"1\"],[\"64439\",\"0.01\",\"0\",\"1\"],[\"64437.4\",\"58.25\",\"0\",\"1\"],[\"64431.9\",\"17.93\",\"0\",\"2\"],[\"64431.6\",\"496.54\",\"0\",\"2\"],[\"64415.9\",\"0\",\"0\",\"0\"],[\"64415.5\",\"20.01\",\"0\",\"2\"],[\"64405.5\",\"0.01\",\"0\",\"1\"]],\"ts\":\"1782015907805\",\"checksum\":2145253646,\"seqId\":325069855772,\"prevSeqId\":325069855628}]}"}
{"action": "update", "capture_sequence": 55, "channel": "books", "connection_sequence": 1, "event": null, "instId": "BTC-USDT-SWAP", "local_receive_ts": "2026-06-21T04:25:08Z", "monotonic_ns": 1643463810771495, "raw": "{\"arg\":{\"channel\":\"books\",\"instId\":\"BTC-USDT-SWAP\"},\"action\":\"update\",\"data\":[{\"asks\":[[\"64461.1\",\"0.01\",\"0\",\"1\"],[\"64461.4\",\"0.03\",\"0\",\"3\"],[\"64466.7\",\"0.01\",\"0\",\"1\"],[\"64468.9\",\"0.15\",\"0\",\"3\"],[\"64470\",\"10.2\",\"0\",\"5\"],[\"64474.2\",\"2.5\",\"0\",\"2\"],[\"64476.3\",\"0\",\"0\",\"0\"],[\"64483.7\",\"0.01\",\"0\",\"1\"],[\"64484.2\",\"15.96\",\"0\",\"2\"],[\"64485.5\",\"0.01\",\"0\",\"1\"],[\"64485.8\",\"58.6\",\"0\",\"3\"],[\"64509.3\",\"0.28\",\"0\",\"5\"]],\"bids\":[[\"64456.2\",\"32.21\",\"0\",\"1\"],[\"64455.2\",\"0.05\",\"0\",\"5\"],[\"64455.1\",\"0.01\",\"0\",\"1\"],[\"64453.1\",\"0.01\",\"0\",\"1\"],[\"64452.1\",\"44.28\",\"0\",\"6\"],[\"64451.6\",\"0.31\",\"0\",\"1\"],[\"64451\",\"2.23\",\"0\",\"3\"],[\"64450.7\",\"0.04\",\"0\",\"2\"],[\"64440\",\"136.69\",\"0\",\"8\"],[\"64439.5\",\"0.01\",\"0\",\"1\"],[\"64405.5\",\"0\",\"0\",\"0\"]],\"ts\":\"1782015907905\",\"checksum\":-2103998269,\"seqId\":325069855887,\"prevSeqId\":325069855772}]}"}
{"action": null, "capture_sequence": 56, "channel": "trades", "connection_sequence": 1, "event": null, "instId": "BTC-USDT-SWAP", "local_receive_ts": "2026-06-21T04:25:08Z", "monotonic_ns": 1643463819762578, "raw": "{\"arg\":{\"channel\":\"trades\",\"instId\":\"BTC-USDT-SWAP\"},\"data\":[{\"instId\":\"BTC-USDT-SWAP\",\"tradeId\":\"2718748830\",\"px\":\"64457.9\",\"sz\":\"5\",\"side\":\"sell\",\"ts\":\"1782015907914\",\"count\":\"1\",\"source\":\"0\",\"seqId\":325069855895}]}"}
{"action": "update", "capture_sequence": 57, "channel": "books", "connection_sequence": 1, "event": null, "instId": "BTC-USDT-SWAP", "local_receive_ts": "2026-06-21T04:25:08Z", "monotonic_ns": 1643463911414455, "raw": "{\"arg\":{\"channel\":\"books\",\"instId\":\"BTC-USDT-SWAP\"},\"action\":\"update\",\"data\":[{\"asks\":[[\"64459.1\",\"1.56\",\"0\",\"1\"],[\"64459.6\",\"1.56\",\"0\",\"1\"],[\"64460.1\",\"1.58\",\"0\",\"3\"],[\"64460.9\",\"0.02\",\"0\",\"2\"],[\"64461.2\",\"0.03\",\"0\",\"2\"],[\"64465.8\",\"65.22\",\"0\",\"3\"],[\"64465.9\",\"0.02\",\"0\",\"1\"],[\"64475.4\",\"232.87\",\"0\",\"1\"],[\"64475.5\",\"31.04\",\"0\",\"1\"],[\"64477.2\",\"1.55\",\"0\",\"1\"],[\"64477.3\",\"1.01\",\"0\",\"2\"],[\"64481.9\",\"0.01\",\"0\",\"1\"],[\"64482.6\",\"33.81\",\"0\",\"2\"],[\"64485.8\",\"0.4\",\"0\",\"2\"],[\"64485.9\",\"63.62\",\"0\",\"2\"],[\"64486.9\",\"0.12\",\"0\",\"2\"],[\"64487.4\",\"85.86\",\"0\",\"6\"],[\"64487.6\",\"301.47\",\"0\",\"2\"],[\"64487.7\",\"130.34\",\"0\",\"4\"],[\"64493.3\",\"600.4\",\"0\",\"7\"],[\"64493.5\",\"2.29\",\"0\",\"5\"],[\"64508.8\",\"0\",\"0\",\"0\"],[\"64508.9\",\"0\",\"0\",\"0\"],[\"64509\",\"0\",\"0\",\"0\"],[\"64509.1\",\"0\",\"0\",\"0\"],[\"64509.3\",\"0\",\"0\",\"0\"]],\"bids\":[[\"64457.9\",\"469.21\",\"0\",\"19\"],[\"64455.2\",\"0.04\",\"0\",\"4\"],[\"64455.1\",\"0.02\",\"0\",\"2\"],[\"64443.5\",\"33.82\",\"0\",\"1\"],[\"64443.3\",\"216.32\",\"0\",\"5\"],[\"64443\",\"0.02\",\"0\",\"2\"],[\"64442.1\",\"6.22\",\"0\",\"1\"],[\"64441.9\",\"122.39\",\"0\",\"4\"],[\"64441.5\",\"61.31\",\"0\",\"3\"],[\"64438\",\"58.26\",\"0\",\"2\"],[\"64437.4\",\"0\",\"0\",\"0\"],[\"64436.6\",\"10.03\",\"0\",\"4\"],[\"64436.2\",\"233.01\",\"0\",\"1\"],[\"64415.5\",\"20\",\"0\",\"1\"],[\"64415.2\",\"0.02\",\"0\",\"2\"],[\"64405.6\",\"0\",\"0\",\"0\"]],\"ts\":\"1782015908005\",\"checksum\":1684880215,\"seqId\":325069856001,\"prevSeqId\":325069855887}]}"}
{"action": "update", "capture_sequence": 58, "channel": "books", "connection_sequence": 1, "event": null, "instId": "BTC-USDT-SWAP", "local_receive_ts": "2026-06-21T04:25:08Z", "monotonic_ns": 1643464015933822, "raw": "{\"arg\":{\"channel\":\"books\",\"instId\":\"BTC-USDT-SWAP\"},\"action\":\"update\",\"data\":[{\"asks\":[[\"64458.2\",\"0\",\"0\",\"0\"],[\"64458.3\",\"0.03\",\"0\",\"3\"],[\"64458.4\",\"3.63\",\"0\",\"2\"],[\"64458.7\",\"0.01\",\"0\",\"1\"],[\"64459.1\",\"0\",\"0\",\"0\"],[\"64459.5\",\"1.56\",\"0\",\"1\"],[\"64459.6\",\"0\",\"0\",\"0\"],[\"64460.1\",\"0.02\",\"0\",\"2\"],[\"64460.2\",\"2.34\",\"0\",\"3\"],[\"64460.7\",\"1.56\",\"0\",\"1\"],[\"64460.9\",\"0.01\",\"0\",\"1\"],[\"64461.2\",\"1.59\",\"0\",\"3\"],[\"64471.9\",\"15.54\",\"0\",\"3\"],[\"64472.4\",\"0\",\"0\",\"0\"],[\"64474.6\",\"31.05\",\"0\",\"1\"],[\"64474.7\",\"8.04\",\"0\",\"4\"],[\"64474.9\",\"270.1\",\"0\",\"2\"],[\"64475\",\"263.06\",\"0\",\"9\"],[\"64475.4\",\"0\",\"0\",\"0\"],[\"64475.5\",\"0\",\"0\",\"0\"],[\"64483.8\",\"1.08\",\"0\",\"2\"],[\"64484.2\",\"15.65\",\"0\",\"1\"],[\"64485.9\",\"5.42\",\"0\",\"1\"],[\"64486.2\",\"58.37\",\"0\",\"7\"],[\"64486.9\",\"85.49\",\"0\",\"3\"],[\"64487.4\",\"0.49\",\"0\",\"5\"],[\"64487.5\",\"43.49\",\"0\",\"7\"],[\"64487.6\",\"301.45\",\"0\",\"1\"],[\"64493.1\",\"51.83\",\"0\",\"6\"],[\"64493.3\",\"580.33\",\"0\",\"6\"],[\"64508.8\",\"0.04\",\"0\",\"2\"],[\"64508.9\",\"0.04\",\"0\",\"2\"]],\"bids\":[[\"64457.9\",\"467.65\",\"0\",\"18\"],[\"64457.8\",\"0.15\",\"0\",\"3\"],[\"64457.7\",\"1.88\",\"0\",\"2\"],[\"64455.1\",\"0.01\",\"0\",\"1\"],[\"64452.4\",\"0\",\"0\",\"0\"],[\"64452.2\",\"0.32\",\"0\",\"2\"],[\"64451.6\",\"0\",\"0\",\"0\"],[\"64451.2\",\"396.37\",\"0\",\"5\"],[\"64450.4\",\"0.31\",\"0\",\"1\"],[\"64450.3\",\"118.4\",\"0\",\"2\"],[\"64443.5\",\"0\",\"0\",\"0\"],[\"64443.3\",\"163.94\",\"0\",\"5\"],[\"64442.9\",\"0\",\"0\",\"0\"],[\"64442.7\",\"20.09\",\"0\",\"1\"],[\"64442.1\",\"92.42\",\"0\",\"2\"],[\"64441.9\",\"36.94\",\"0\",\"2\"],[\"64441.7\",\"85.45\",\"0\",\"2\"],[\"64438.8\",\"0\",\"0\",\"0\"],[\"64438.2\",\"58.26\",\"0\",\"2\"],[\"64438\",\"0.01\",\"0\",\"1\"],[\"64437.3\",\"15.67\",\"0\",\"2\"],[\"64437\",\"0\",\"0\",\"0\"],[\"64436.5\",\"42.37\",\"0\",\"4\"],[\"64436.2\",\"0\",\"0\",\"0\"],[\"64436.1\",\"258.66\",\"0\",\"3\"],[\"64405.6\",\"0.02\",\"0\",\"2\"],[\"64405.5\",\"0.01\",\"0\",\"1\"],[\"64405.3\",\"46.54\",\"0\",\"1\"],[\"64405.2\",\"239.07\",\"0\",\"5\"],[\"64405.1\",\"0.07\",\"0\",\"3\"]],\"ts\":\"1782015908105\",\"checksum\":582076336,\"seqId\":325069856252,\"prevSeqId\":325069856001}]}"}
{"action": "update", "capture_sequence": 59, "channel": "books", "connection_sequence": 1, "event": null, "instId": "BTC-USDT-SWAP", "local_receive_ts": "2026-06-21T04:25:08Z", "monotonic_ns": 1643464111147274, "raw": "{\"arg\":{\"channel\":\"books\",\"instId\":\"BTC-USDT-SWAP\"},\"action\":\"update\",\"data\":[{\"asks\":[[\"64458.7\",\"0\",\"0\",\"0\"],[\"64459.1\",\"0.01\",\"0\",\"1\"],[\"64459.2\",\"1.57\",\"0\",\"2\"],[\"64459.5\",\"0\",\"0\",\"0\"],[\"64459.7\",\"1.56\",\"0\",\"1\"],[\"64463.9\",\"0\",\"0\",\"0\"],[\"64487.1\",\"0.55\",\"0\",\"5\"],[\"64487.5\",\"43.47\",\"0\",\"6\"],[\"64508.9\",\"11.25\",\"0\",\"3\"],[\"64509\",\"155.92\",\"0\",\"2\"]],\"bids\":[[\"64457.8\",\"1.7\",\"0\",\"3\"],[\"64457.7\",\"0.32\",\"0\",\"1\"],[\"64457.3\",\"1.56\",\"0\",\"1\"],[\"64456.8\",\"0.01\",\"0\",\"1\"],[\"64456.7\",\"1.57\",\"0\",\"2\"],[\"64456.2\",\"54.83\",\"0\",\"2\"],[\"64456.1\",\"0.02\",\"0\",\"2\"],[\"64456\",\"1.58\",\"0\",\"3\"],[\"64455.7\",\"0\",\"0\",\"0\"],[\"64455.6\",\"0\",\"0\",\"0\"],[\"64455.2\",\"1.6\",\"0\",\"5\"],[\"64455\",\"98.45\",\"0\",\"3\"],[\"64454.8\",\"0.01\",\"0\",\"1\"],[\"64454.7\",\"38.81\",\"0\",\"3\"],[\"64453.7\",\"1.56\",\"0\",\"1\"],[\"64451.9\",\"0\",\"0\",\"0\"],[\"64451.3\",\"13.69\",\"0\",\"8\"],[\"64451.1\",\"0\",\"0\",\"0\"],[\"64450.6\",\"0\",\"0\",\"0\"],[\"64438.1\",\"15.71\",\"0\",\"3\"],[\"64437.3\",\"15.65\",\"0\",\"1\"],[\"64434.8\",\"148.64\",\"0\",\"3\"],[\"64433\",\"4.08\",\"0\",\"3\"],[\"64431.6\",\"496.53\",\"0\",\"1\"],[\"64416\",\"298.12\",\"0\",\"6\"],[\"64415.9\",\"0.01\",\"0\",\"1\"],[\"64415.2\",\"0.01\",\"0\",\"1\"],[\"64405\",\"13.52\",\"0\",\"15\"]],\"ts\":\"1782015908205\",\"checksum\":1272046626,\"seqId\":325069856451,\"prevSeqId\":325069856252}]}"}
{"action": null, "capture_sequence": 60, "channel": "trades", "connection_sequence": 1, "event": null, "instId": "BTC-USDT-SWAP", "local_receive_ts": "2026-06-21T04:25:08Z", "monotonic_ns": 1643464134907901, "raw": "{\"arg\":{\"channel\":\"trades\",\"instId\":\"BTC-USDT-SWAP\"},\"data\":[{\"instId\":\"BTC-USDT-SWAP\",\"tradeId\":\"2718748831\",\"px\":\"64457.9\",\"sz\":\"5\",\"side\":\"sell\",\"ts\":\"1782015908229\",\"count\":\"1\",\"source\":\"0\",\"seqId\":325069856502}]}"}
{"action": null, "capture_sequence": 61, "channel": "trades", "connection_sequence": 1, "event": null, "instId": "BTC-USDT-SWAP", "local_receive_ts": "2026-06-21T04:25:08Z", "monotonic_ns": 1643464137181211, "raw": "{\"arg\":{\"channel\":\"trades\",\"instId\":\"BTC-USDT-SWAP\"},\"data\":[{\"instId\":\"BTC-USDT-SWAP\",\"tradeId\":\"2718748832\",\"px\":\"64458\",\"sz\":\"0.32\",\"side\":\"buy\",\"ts\":\"1782015908231\",\"count\":\"1\",\"source\":\"0\",\"seqId\":325069856507}]}"}
{"action": null, "capture_sequence": 62, "channel": "trades", "connection_sequence": 1, "event": null, "instId": "BTC-USDT-SWAP", "local_receive_ts": "2026-06-21T04:25:08Z", "monotonic_ns": 1643464138326891, "raw": "{\"arg\":{\"channel\":\"trades\",\"instId\":\"BTC-USDT-SWAP\"},\"data\":[{\"instId\":\"BTC-USDT-SWAP\",\"tradeId\":\"2718748833\",\"px\":\"64457.9\",\"sz\":\"0.31\",\"side\":\"sell\",\"ts\":\"1782015908233\",\"count\":\"1\",\"source\":\"0\",\"seqId\":325069856512}]}"}
{"action": null, "capture_sequence": 63, "channel": "trades", "connection_sequence": 1, "event": null, "instId": "BTC-USDT-SWAP", "local_receive_ts": "2026-06-21T04:25:08Z", "monotonic_ns": 1643464203364062, "raw": "{\"arg\":{\"channel\":\"trades\",\"instId\":\"BTC-USDT-SWAP\"},\"data\":[{\"instId\":\"BTC-USDT-SWAP\",\"tradeId\":\"2718748834\",\"px\":\"64458\",\"sz\":\"0.07\",\"side\":\"buy\",\"ts\":\"1782015908298\",\"count\":\"1\",\"source\":\"0\",\"seqId\":325069856587}]}"}
{"action": "update", "capture_sequence": 64, "channel": "books", "connection_sequence": 1, "event": null, "instId": "BTC-USDT-SWAP", "local_receive_ts": "2026-06-21T04:25:08Z", "monotonic_ns": 1643464211062951, "raw": "{\"arg\":{\"channel\":\"books\",\"instId\":\"BTC-USDT-SWAP\"},\"action\":\"update\",\"data\":[{\"asks\":[[\"64458\",\"529.11\",\"0\",\"62\"],[\"64459.2\",\"0.01\",\"0\",\"1\"],[\"64493\",\"33.79\",\"0\",\"5\"],[\"64493.1\",\"31.76\",\"0\",\"5\"],[\"64495.2\",\"0.01\",\"0\",\"1\"]],\"bids\":[[\"64457.9\",\"462.34\",\"0\",\"18\"],[\"64457.8\",\"0.14\",\"0\",\"2\"],[\"64457.3\",\"0\",\"0\",\"0\"],[\"64456.8\",\"0\",\"0\",\"0\"],[\"64456.7\",\"0.01\",\"0\",\"1\"],[\"64456.1\",\"0.01\",\"0\",\"1\"],[\"64456\",\"0.02\",\"0\",\"2\"],[\"64455.2\",\"0.04\",\"0\",\"4\"],[\"64455.1\",\"0.02\",\"0\",\"2\"],[\"64455\",\"98.46\",\"0\",\"4\"],[\"64454.7\",\"37.25\",\"0\",\"2\"],[\"64454.2\",\"0.01\",\"0\",\"1\"],[\"64453.7\",\"0\",\"0\",\"0\"],[\"64443.3\",\"130.12\",\"0\",\"4\"],[\"64443.2\",\"169.48\",\"0\",\"6\"],[\"64442.7\",\"0\",\"0\",\"0\"],[\"64442.4\",\"20.1\",\"0\",\"2\"],[\"64433\",\"4.07\",\"0\",\"2\"],[\"64432.5\",\"0.02\",\"0\",\"2\"],[\"64404.8\",\"0.04\",\"0\",\"1\"],[\"64404.7\",\"0.77\",\"0\",\"1\"],[\"64404.5\",\"0.16\",\"0\",\"2\"],[\"64404.4\",\"15.36\",\"0\",\"1\"]],\"ts\":\"1782015908305\",\"checksum\":-1202170865,\"seqId\":325069856597,\"prevSeqId\":325069856451}]}"}
{"action": "update", "capture_sequence": 65, "channel": "books", "connection_sequence": 1, "event": null, "instId": "BTC-USDT-SWAP", "local_receive_ts": "2026-06-21T04:25:08Z", "monotonic_ns": 1643464312198468, "raw": "{\"arg\":{\"channel\":\"books\",\"instId\":\"BTC-USDT-SWAP\"},\"action\":\"update\",\"data\":[{\"asks\":[[\"64459.1\",\"0\",\"0\",\"0\"],[\"64459.6\",\"0.01\",\"0\",\"1\"],[\"64459.7\",\"0\",\"0\",\"0\"],[\"64464.1\",\"37.45\",\"0\",\"6\"],[\"64474.9\",\"37.23\",\"0\",\"1\"],[\"64475.6\",\"233.26\",\"0\",\"3\"],[\"64485.8\",\"58.6\",\"0\",\"3\"],[\"64486.2\",\"0.17\",\"0\",\"6\"],[\"64486.7\",\"85.38\",\"0\",\"2\"],[\"64486.9\",\"0.12\",\"0\",\"2\"],[\"64509.1\",\"0.02\",\"0\",\"2\"]],\"bids\":[[\"64457.9\",\"472.5\",\"0\",\"20\"],[\"64452.4\",\"0.31\",\"0\",\"1\"],[\"64452.2\",\"0.01\",\"0\",\"1\"],[\"64451.4\",\"35.37\",\"0\",\"3\"],[\"64451.3\",\"13.68\",\"0\",\"7\"],[\"64451.1\",\"0.01\",\"0\",\"1\"],[\"64445\",\"134.03\",\"0\",\"6\"],[\"64441.8\",\"535.37\",\"0\",\"3\"],[\"64441.7\",\"0\",\"0\",\"0\"],[\"64441.4\",\"135.45\",\"0\",\"4\"],[\"64438.8\",\"0.02\",\"0\",\"1\"],[\"64438.2\",\"0.01\",\"0\",\"1\"],[\"64438.1\",\"15.69\",\"0\",\"2\"],[\"64437.4\",\"58.25\",\"0\",\"1\"],[\"64436.7\",\"46.72\",\"0\",\"3\"],[\"64436.5\",\"11.31\",\"0\",\"3\"],[\"64436.2\",\"233.01\",\"0\",\"1\"],[\"64436.1\",\"25.65\",\"0\",\"2\"],[\"64432.5\",\"0.01\",\"0\",\"1\"],[\"64431.8\",\"15.88\",\"0\",\"3\"],[\"64415.9\",\"0\",\"0\",\"0\"],[\"64415.5\",\"20.01\",\"0\",\"2\"],[\"64404.7\",\"0\",\"0\",\"0\"],[\"64404.5\",\"0\",\"0\",\"0\"],[\"64404.4\",\"0\",\"0\",\"0\"]],\"ts\":\"1782015908405\",\"checksum\":-1417753625,\"seqId\":325069856728,\"prevSeqId\":325069856597}]}"}
{"action": "update", "capture_sequence": 66, "channel": "books", "connection_sequence": 1, "event": null, "instId": "BTC-USDT-SWAP", "local_receive_ts": "2026-06-21T04:25:08Z", "monotonic_ns": 1643464411591568, "raw": "{\"arg\":{\"channel\":\"books\",\"instId\":\"BTC-USDT-SWAP\"},\"action\":\"update\",\"data\":[{\"asks\":[[\"64459.6\",\"0\",\"0\",\"0\"],[\"64460.1\",\"0.03\",\"0\",\"3\"],[\"64509.3\",\"0.28\",\"0\",\"5\"]],\"bids\":[[\"64452.4\",\"0\",\"0\",\"0\"],[\"64452.3\",\"1.88\",\"0\",\"3\"],[\"64404.7\",\"0.77\",\"0\",\"1\"]],\"ts\":\"1782015908505\",\"checksum\":-1661610886,\"seqId\":325069856798,\"prevSeqId\":325069856728}]}"}
{"action": null, "capture_sequence": 67, "channel": "trades", "connection_sequence": 1, "event": null, "instId": "BTC-USDT-SWAP", "local_receive_ts": "2026-06-21T04:25:08Z", "monotonic_ns": 1643464453480691, "raw": "{\"arg\":{\"channel\":\"trades\",\"instId\":\"BTC-USDT-SWAP\"},\"data\":[{\"instId\":\"BTC-USDT-SWAP\",\"tradeId\":\"2718748835\",\"px\":\"64457.9\",\"sz\":\"5\",\"side\":\"sell\",\"ts\":\"1782015908548\",\"count\":\"1\",\"source\":\"0\",\"seqId\":325069856837}]}"}
{"action": "update", "capture_sequence": 68, "channel": "books", "connection_sequence": 1, "event": null, "instId": "BTC-USDT-SWAP", "local_receive_ts": "2026-06-21T04:25:08Z", "monotonic_ns": 1643464510828656, "raw": "{\"arg\":{\"channel\":\"books\",\"instId\":\"BTC-USDT-SWAP\"},\"action\":\"update\",\"data\":[{\"asks\":[[\"64458\",\"529.21\",\"0\",\"63\"],[\"64474.9\",\"270.1\",\"0\",\"2\"],[\"64475.6\",\"0.39\",\"0\",\"2\"],[\"64476.5\",\"0\",\"0\",\"0\"],[\"64509.6\",\"0.03\",\"0\",\"2\"]],\"bids\":[[\"64457.9\",\"467.5\",\"0\",\"20\"],[\"64443.1\",\"0\",\"0\",\"0\"],[\"64436.3\",\"117.15\",\"0\",\"4\"],[\"64404.5\",\"0.16\",\"0\",\"2\"]],\"ts\":\"1782015908605\",\"checksum\":279131836,\"seqId\":325069856881,\"prevSeqId\":325069856798}]}"}
{"action": "update", "capture_sequence": 69, "channel": "books", "connection_sequence": 1, "event": null, "instId": "BTC-USDT-SWAP", "local_receive_ts": "2026-06-21T04:25:08Z", "monotonic_ns": 1643464610474771, "raw": "{\"arg\":{\"channel\":\"books\",\"instId\":\"BTC-USDT-SWAP\"},\"action\":\"update\",\"data\":[{\"asks\":[[\"64474.9\",\"37.23\",\"0\",\"1\"],[\"64475.5\",\"232.87\",\"0\",\"1\"],[\"64476.5\",\"0.15\",\"0\",\"1\"],[\"64483.1\",\"101.07\",\"0\",\"5\"],[\"64483.8\",\"0.31\",\"0\",\"1\"],[\"64509.3\",\"0\",\"0\",\"0\"],[\"64509.6\",\"0\",\"0\",\"0\"]],\"bids\":[[\"64457.9\",\"467.89\",\"0\",\"21\"],[\"64444.5\",\"0\",\"0\",\"0\"],[\"64443.8\",\"0.77\",\"0\",\"1\"],[\"64443.1\",\"3.1\",\"0\",\"1\"],[\"64436.3\",\"117.34\",\"0\",\"5\"],[\"64404.5\",\"0\",\"0\",\"0\"]],\"ts\":\"1782015908705\",\"checksum\":1975780409,\"seqId\":325069856982,\"prevSeqId\":325069856881}]}"}
{"action": "update", "capture_sequence": 70, "channel": "books", "connection_sequence": 1, "event": null, "instId": "BTC-USDT-SWAP", "local_receive_ts": "2026-06-21T04:25:08Z", "monotonic_ns": 1643464710608431, "raw": "{\"arg\":{\"channel\":\"books\",\"instId\":\"BTC-USDT-SWAP\"},\"action\":\"update\",\"data\":[{\"asks\":[[\"64458.1\",\"0.02\",\"0\",\"2\"],[\"64458.4\",\"2.71\",\"0\",\"2\"],[\"64460.1\",\"0.02\",\"0\",\"2\"],[\"64460.2\",\"0.78\",\"0\",\"2\"],[\"64460.6\",\"0.01\",\"0\",\"1\"],[\"64477.2\",\"0\",\"0\",\"0\"],[\"64477.3\",\"2.56\",\"0\",\"3\"]],\"bids\":[[\"64457.9\",\"542.69\",\"0\",\"22\"],[\"64450.6\",\"77.57\",\"0\",\"1\"],[\"64450.5\",\"6.3\",\"0\",\"4\"],[\"64450.3\",\"40.83\",\"0\",\"1\"],[\"64449.8\",\"2.68\",\"0\",\"3\"],[\"64404.7\",\"0\",\"0\",\"0\"]],\"ts\":\"1782015908805\",\"checksum\":-248628095,\"seqId\":325069857071,\"prevSeqId\":325069856982}]}"}
{"action": null, "capture_sequence": 71, "channel": "trades", "connection_sequence": 1, "event": null, "instId": "BTC-USDT-SWAP", "local_receive_ts": "2026-06-21T04:25:08Z", "monotonic_ns": 1643464791323912, "raw": "{\"arg\":{\"channel\":\"trades\",\"instId\":\"BTC-USDT-SWAP\"},\"data\":[{\"instId\":\"BTC-USDT-SWAP\",\"tradeId\":\"2718748836\",\"px\":\"64457.9\",\"sz\":\"5\",\"side\":\"sell\",\"ts\":\"1782015908886\",\"count\":\"1\",\"source\":\"0\",\"seqId\":325069857100}]}"}
{"action": "update", "capture_sequence": 72, "channel": "books", "connection_sequence": 1, "event": null, "instId": "BTC-USDT-SWAP", "local_receive_ts": "2026-06-21T04:25:09Z", "monotonic_ns": 1643464810888176, "raw": "{\"arg\":{\"channel\":\"books\",\"instId\":\"BTC-USDT-SWAP\"},\"action\":\"update\",\"data\":[{\"asks\":[[\"64460.7\",\"0\",\"0\",\"0\"],[\"64474.7\",\"8.02\",\"0\",\"3\"],[\"64474.8\",\"0.13\",\"0\",\"2\"],[\"64476.5\",\"0\",\"0\",\"0\"],[\"64477.2\",\"1.55\",\"0\",\"1\"],[\"64477.3\",\"1.01\",\"0\",\"2\"],[\"64483.8\",\"0\",\"0\",\"0\"],[\"64484.1\",\"0.33\",\"0\",\"2\"],[\"64487.1\",\"0.53\",\"0\",\"4\"],[\"64487.6\",\"301.47\",\"0\",\"2\"],[\"64495.2\",\"2.29\",\"0\",\"2\"],[\"64509.3\",\"0.28\",\"0\",\"5\"],[\"64509.6\",\"0.03\",\"0\",\"2\"]],\"bids\":[[\"64457.9\",\"541.69\",\"0\",\"23\"],[\"64451.3\",\"13.99\",\"0\",\"8\"],[\"64451.2\",\"396.06\",\"0\",\"4\"],[\"64450.6\",\"0\",\"0\",\"0\"],[\"64450.5\",\"7.07\",\"0\",\"5\"],[\"64450.4\",\"77.88\",\"0\",\"2\"],[\"64449.8\",\"1.91\",\"0\",\"2\"],[\"64443.1\",\"0\",\"0\",\"0\"],[\"64436.3\",\"117.15\",\"0\",\"4\"],[\"64433.2\",\"21.3\",\"0\",\"3\"],[\"64431.8\",\"15.87\",\"0\",\"2\"],[\"64415.9\",\"0.01\",\"0\",\"1\"],[\"64415.5\",\"20\",\"0\",\"1\"],[\"64404.7\",\"0.77\",\"0\",\"1\"]],\"ts\":\"1782015908905\",\"checksum\":-1258669798,\"seqId\":325069857100,\"prevSeqId\":325069857071}]}"}
{"action": "update", "capture_sequence": 73, "channel": "books", "connection_sequence": 1, "event": null, "instId": "BTC-USDT-SWAP", "local_receive_ts": "2026-06-21T04:25:09Z", "monotonic_ns": 1643464910865820, "raw": "{\"arg\":{\"channel\":\"books\",\"instId\":\"BTC-USDT-SWAP\"},\"action\":\"update\",\"data\":[{\"asks\":[[\"64461\",\"49.97\",\"0\",\"3\"],[\"64461.2\",\"0.03\",\"0\",\"2\"],[\"64461.5\",\"1.56\",\"0\",\"1\"],[\"64463.9\",\"1.56\",\"0\",\"1\"],[\"64464.4\",\"1.86\",\"0\",\"2\"],[\"64474.8\",\"233\",\"0\",\"3\"],[\"64475.5\",\"0\",\"0\",\"0\"],[\"64476.5\",\"0.15\",\"0\",\"1\"],[\"64509.3\",\"0\",\"0\",\"0\"],[\"64509.6\",\"0\",\"0\",\"0\"]],\"bids\":[[\"64457.9\",\"543.25\",\"0\",\"24\"],[\"64457.4\",\"1.56\",\"0\",\"1\"],[\"64456.9\",\"1.56\",\"0\",\"1\"],[\"64456.4\",\"1.57\",\"0\",\"2\"],[\"64455.9\",\"1.57\",\"0\",\"2\"],[\"64455.5\",\"1.56\",\"0\",\"1\"],[\"64443.1\",\"3.1\",\"0\",\"1\"],[\"64438\",\"58.26\",\"0\",\"2\"],[\"64437.4\",\"0\",\"0\",\"0\"],[\"64436.7\",\"15.66\",\"0\",\"2\"],[\"64436.5\",\"42.37\",\"0\",\"4\"],[\"64436.3\",\"117.34\",\"0\",\"5\"],[\"64436.2\",\"0\",\"0\",\"0\"],[\"64435.7\",\"233.01\",\"0\",\"1\"],[\"64405\",\"0\",\"0\",\"0\"],[\"64404.8\",\"0\",\"0\",\"0\"],[\"64404.7\",\"0\",\"0\",\"0\"]],\"ts\":\"1782015909005\",\"checksum\":-1332141495,\"seqId\":325069857134,\"prevSeqId\":325069857100}]}"}
{"action": "update", "capture_sequence": 74, "channel": "books", "connection_sequence": 1, "event": null, "instId": "BTC-USDT-SWAP", "local_receive_ts": "2026-06-21T04:25:09Z", "monotonic_ns": 1643465015743617, "raw": "{\"arg\":{\"channel\":\"books\",\"instId\":\"BTC-USDT-SWAP\"},\"action\":\"update\",\"data\":[{\"asks\":[[\"64458\",\"451.2\",\"0\",\"68\"],[\"64458.4\",\"4.27\",\"0\",\"3\"],[\"64458.8\",\"0.01\",\"0\",\"1\"],[\"64458.9\",\"1.56\",\"0\",\"1\"],[\"64459.6\",\"1.56\",\"0\",\"1\"],[\"64460\",\"0.02\",\"0\",\"2\"],[\"64460.1\",\"1.58\",\"0\",\"3\"],[\"64460.7\",\"1.56\",\"0\",\"1\"],[\"64461\",\"48.41\",\"0\",\"2\"],[\"64461.2\",\"1.59\",\"0\",\"3\"],[\"64461.5\",\"0\",\"0\",\"0\"],[\"64461.7\",\"1.56\",\"0\",\"1\"],[\"64461.9\",\"0.15\",\"0\",\"1\"],[\"64462\",\"0.04\",\"0\",\"4\"],[\"64462.4\",\"1.56\",\"0\",\"1\"],[\"64462.5\",\"0\",\"0\",\"0\"],[\"64463.9\",\"0\",\"0\",\"0\"],[\"64464.4\",\"0.3\",\"0\",\"1\"],[\"64464.5\",\"36.27\",\"0\",\"5\"],[\"64465.9\",\"0\",\"0\",\"0\"],[\"64467.7\",\"0.02\",\"0\",\"1\"],[\"64470.9\",\"311.71\",\"0\",\"10\"],[\"64474.7\",\"8.01\",\"0\",\"2\"],[\"64474.8\",\"0.11\",\"0\",\"1\"],[\"64475.1\",\"0.03\",\"0\",\"2\"],[\"64475.6\",\"233.26\",\"0\",\"3\"],[\"64479.7\",\"6.21\",\"0\",\"1\"],[\"64479.9\",\"62.21\",\"0\",\"4\"],[\"64487.6\",\"301.45\",\"0\",\"1\"],[\"64487.7\",\"130.36\",\"0\",\"5\"],[\"64508.9\",\"0\",\"0\",\"0\"],[\"64509\",\"0\",\"0\",\"0\"],[\"64509.1\",\"0\",\"0\",\"0\"]],\"bids\":[[\"64457.9\",\"541.69\",\"0\",\"23\"],[\"64457.5\",\"0.01\",\"0\",\"1\"],[\"64457\",\"0.02\",\"0\",\"2\"],[\"64456.5\",\"0.01\",\"0\",\"1\"],[\"64456.3\",\"0.01\",\"0\",\"1\"],[\"64455.1\",\"0.01\",\"0\",\"1\"],[\"64455\",\"100.01\",\"0\",\"4\"],[\"64452.4\",\"0.31\",\"0\",\"1\"],[\"64452.3\",\"1.57\",\"0\",\"2\"],[\"64441.9\",\"36.96\",\"0\",\"3\"],[\"64441.8\",\"535.35\",\"0\",\"2\"],[\"64439.2\",\"0.02\",\"0\",\"1\"],[\"64438.8\",\"0\",\"0\",\"0\"],[\"64436.8\",\"32.06\",\"0\",\"2\"],[\"64436.5\",\"11.31\",\"0\",\"3\"],[\"64436.2\",\"233.01\",\"0\",\"1\"],[\"64435.7\",\"0\",\"0\",\"0\"],[\"64433.3\",\"17.98\",\"0\",\"5\"],[\"64433.2\",\"21.29\",\"0\",\"2\"],[\"64405.3\",\"0\",\"0\",\"0\"],[\"64405.2\",\"0\",\"0\",\"0\"],[\"64405.1\",\"0\",\"0\",\"0\"]],\"ts\":\"1782015909105\",\"checksum\":1430258839,\"seqId\":325069857257,\"prevSeqId\":325069857134}]}"}
{"action": null, "capture_sequence": 75, "channel": "trades", "connection_sequence": 1, "event": null, "instId": "BTC-USDT-SWAP", "local_receive_ts": "2026-06-21T04:25:09Z", "monotonic_ns": 1643465107438635, "raw": "{\"arg\":{\"channel\":\"trades\",\"instId\":\"BTC-USDT-SWAP\"},\"data\":[{\"instId\":\"BTC-USDT-SWAP\",\"tradeId\":\"2718748837\",\"px\":\"64457.9\",\"sz\":\"5\",\"side\":\"sell\",\"ts\":\"1782015909201\",\"count\":\"1\",\"source\":\"0\",\"seqId\":325069857348}]}"}
{"action": "update", "capture_sequence": 76, "channel": "books", "connection_sequence": 1, "event": null, "instId": "BTC-USDT-SWAP", "local_receive_ts": "2026-06-21T04:25:09Z", "monotonic_ns": 1643465111187921, "raw": "{\"arg\":{\"channel\":\"books\",\"instId\":\"BTC-USDT-SWAP\"},\"action\":\"update\",\"data\":[{\"asks\":[[\"64458\",\"452.78\",\"0\",\"70\"],[\"64458.4\",\"2.71\",\"0\",\"2\"],[\"64458.6\",\"0.01\",\"0\",\"1\"],[\"64458.7\",\"1.56\",\"0\",\"1\"],[\"64458.8\",\"0\",\"0\",\"0\"],[\"64458.9\",\"0\",\"0\",\"0\"],[\"64459.2\",\"1.57\",\"0\",\"2\"],[\"64459.6\",\"0\",\"0\",\"0\"],[\"64459.7\",\"1.56\",\"0\",\"1\"],[\"64460.1\",\"0.02\",\"0\",\"2\"],[\"64460.2\",\"2.34\",\"0\",\"3\"],[\"64463.4\",\"0\",\"0\",\"0\"],[\"64464.5\",\"1.32\",\"0\",\"4\"],[\"64508.9\",\"11.25\",\"0\",\"3\"]],\"bids\":[[\"64457.9\",\"536.69\",\"0\",\"23\"],[\"64457.5\",\"0\",\"0\",\"0\"],[\"64457.4\",\"0\",\"0\",\"0\"],[\"64457\",\"0.01\",\"0\",\"1\"],[\"64456.9\",\"0\",\"0\",\"0\"],[\"64456.5\",\"0\",\"0\",\"0\"],[\"64456.4\",\"0.01\",\"0\",\"1\"],[\"64456.3\",\"0.02\",\"0\",\"2\"],[\"64455.9\",\"0.01\",\"0\",\"1\"],[\"64455.8\",\"0.01\",\"0\",\"1\"],[\"64455.7\",\"1.56\",\"0\",\"1\"],[\"64455.5\",\"0\",\"0\",\"0\"],[\"64455.3\",\"0.02\",\"0\",\"2\"],[\"64455.2\",\"1.6\",\"0\",\"5\"],[\"64455\",\"98.45\",\"0\",\"3\"],[\"64454.7\",\"38.81\",\"0\",\"3\"],[\"64454.2\",\"1.57\",\"0\",\"2\"],[\"64453.7\",\"1.56\",\"0\",\"1\"],[\"64451.4\",\"0.42\",\"0\",\"2\"],[\"64405.3\",\"46.54\",\"0\",\"1\"],[\"64405.2\",\"239.07\",\"0\",\"5\"]],\"ts\":\"1782015909205\",\"checksum\":-745813818,\"seqId\":325069857350,\"prevSeqId\":325069857257}]}"}
{"action": null, "capture_sequence": 77, "channel": "trades", "connection_sequence": 1, "event": null, "instId": "BTC-USDT-SWAP", "local_receive_ts": "2026-06-21T04:25:09Z", "monotonic_ns": 1643465127569143, "raw": "{\"arg\":{\"channel\":\"trades\",\"instId\":\"BTC-USDT-SWAP\"},\"data\":[{\"instId\":\"BTC-USDT-SWAP\",\"tradeId\":\"2718748838\",\"px\":\"64458\",\"sz\":\"0.28\",\"side\":\"buy\",\"ts\":\"1782015909222\",\"count\":\"1\",\"source\":\"0\",\"seqId\":325069857361}]}"}
{"action": "update", "capture_sequence": 78, "channel": "books", "connection_sequence": 1, "event": null, "instId": "BTC-USDT-SWAP", "local_receive_ts": "2026-06-21T04:25:09Z", "monotonic_ns": 1643465211328256, "raw": "{\"arg\":{\"channel\":\"books\",\"instId\":\"BTC-USDT-SWAP\"},\"action\":\"update\",\"data\":[{\"asks\":[[\"64458\",\"451.32\",\"0\",\"70\"],[\"64458.6\",\"0\",\"0\",\"0\"],[\"64458.7\",\"0\",\"0\",\"0\"],[\"64459.2\",\"0.01\",\"0\",\"1\"],[\"64459.5\",\"0.01\",\"0\",\"1\"],[\"64459.6\",\"1.56\",\"0\",\"1\"],[\"64459.7\",\"0\",\"0\",\"0\"],[\"64460.2\",\"0.78\",\"0\",\"2\"],[\"64460.3\",\"1.56\",\"0\",\"1\"],[\"64463.4\",\"1.56\",\"0\",\"1\"],[\"64463.9\",\"1.56\",\"0\",\"1\"],[\"64470.9\",\"346.66\",\"0\",\"11\"],[\"64501.5\",\"1.57\",\"0\",\"4\"],[\"64508.8\",\"0\",\"0\",\"0\"],[\"64508.9\",\"0\",\"0\",\"0\"]],\"bids\":[[\"64457.8\",\"1.7\",\"0\",\"3\"],[\"64457.1\",\"0.33\",\"0\",\"2\"],[\"64457\",\"1.57\",\"0\",\"2\"],[\"64455.3\",\"0.01\",\"0\",\"1\"],[\"64451.9\",\"1.56\",\"0\",\"1\"],[\"64445\",\"168.98\",\"0\",\"7\"],[\"64405.2\",\"0\",\"0\",\"0\"]],\"ts\":\"1782015909305\",\"checksum\":-810268410,\"seqId\":325069857423,\"prevSeqId\":325069857350}]}"}
{"action": "update", "capture_sequence": 79, "channel": "books", "connection_sequence": 1, "event": null, "instId": "BTC-USDT-SWAP", "local_receive_ts": "2026-06-21T04:25:09Z", "monotonic_ns": 1643465310802142, "raw": "{\"arg\":{\"channel\":\"books\",\"instId\":\"BTC-USDT-SWAP\"},\"action\":\"update\",\"data\":[{\"asks\":[[\"64501.6\",\"4.99\",\"0\",\"4\"]],\"bids\":[[\"64457.8\",\"0.14\",\"0\",\"2\"],[\"64457.1\",\"0.32\",\"0\",\"1\"],[\"64457\",\"0.01\",\"0\",\"1\"],[\"64455.3\",\"0.02\",\"0\",\"2\"],[\"64410.6\",\"0.01\",\"0\",\"1\"]],\"ts\":\"1782015909405\",\"checksum\":-80275295,\"seqId\":325069857449,\"prevSeqId\":325069857423}]}"}
{"action": null, "capture_sequence": 80, "channel": "trades", "connection_sequence": 1, "event": null, "instId": "BTC-USDT-SWAP", "local_receive_ts": "2026-06-21T04:25:09Z", "monotonic_ns": 1643465354618387, "raw": "{\"arg\":{\"channel\":\"trades\",\"instId\":\"BTC-USDT-SWAP\"},\"data\":[{\"instId\":\"BTC-USDT-SWAP\",\"tradeId\":\"2718748839\",\"px\":\"64457.9\",\"sz\":\"5\",\"side\":\"sell\",\"ts\":\"1782015909448\",\"count\":\"1\",\"source\":\"0\",\"seqId\":325069857467}]}"}
{"action": null, "capture_sequence": 81, "channel": "trades", "connection_sequence": 2, "event": "subscribe", "instId": "BTC-USDT-SWAP", "local_receive_ts": "2026-06-21T04:25:11Z", "monotonic_ns": 1643466817476994, "raw": "{\"event\":\"subscribe\",\"arg\":{\"channel\":\"trades\",\"instId\":\"BTC-USDT-SWAP\"},\"connId\":\"d8734a15\"}"}
{"action": null, "capture_sequence": 82, "channel": "books", "connection_sequence": 2, "event": "subscribe", "instId": "BTC-USDT-SWAP", "local_receive_ts": "2026-06-21T04:25:11Z", "monotonic_ns": 1643466817679594, "raw": "{\"event\":\"subscribe\",\"arg\":{\"channel\":\"books\",\"instId\":\"BTC-USDT-SWAP\"},\"connId\":\"d8734a15\"}"}
{"action": null, "capture_sequence": 83, "channel": "trades", "connection_sequence": 2, "event": null, "instId": "BTC-USDT-SWAP", "local_receive_ts": "2026-06-21T04:25:11Z", "monotonic_ns": 1643466886678045, "raw": "{\"arg\":{\"channel\":\"trades\",\"instId\":\"BTC-USDT-SWAP\"},\"data\":[{\"instId\":\"BTC-USDT-SWAP\",\"tradeId\":\"2718748848\",\"px\":\"64457.9\",\"sz\":\"0.23\",\"side\":\"sell\",\"ts\":\"1782015910969\",\"count\":\"1\",\"source\":\"0\",\"seqId\":325069859748}]}"}
{"action": null, "capture_sequence": 84, "channel": "trades", "connection_sequence": 2, "event": null, "instId": "BTC-USDT-SWAP", "local_receive_ts": "2026-06-21T04:25:11Z", "monotonic_ns": 1643466914850094, "raw": "{\"arg\":{\"channel\":\"trades\",\"instId\":\"BTC-USDT-SWAP\"},\"data\":[{\"instId\":\"BTC-USDT-SWAP\",\"tradeId\":\"2718748849\",\"px\":\"64457.9\",\"sz\":\"5\",\"side\":\"sell\",\"ts\":\"1782015910997\",\"count\":\"1\",\"source\":\"0\",\"seqId\":325069859773}]}"}
{"action": null, "capture_sequence": 85, "channel": "trades", "connection_sequence": 2, "event": null, "instId": "BTC-USDT-SWAP", "local_receive_ts": "2026-06-21T04:25:11Z", "monotonic_ns": 1643467014274564, "raw": "{\"arg\":{\"channel\":\"trades\",\"instId\":\"BTC-USDT-SWAP\"},\"data\":[{\"instId\":\"BTC-USDT-SWAP\",\"tradeId\":\"2718748850\",\"px\":\"64458\",\"sz\":\"0.39\",\"side\":\"buy\",\"ts\":\"1782015911097\",\"count\":\"1\",\"source\":\"0\",\"seqId\":325069860031}]}"}
{"action": "snapshot", "capture_sequence": 86, "channel": "books", "connection_sequence": 2, "event": null, "instId": "BTC-USDT-SWAP", "local_receive_ts": "2026-06-21T04:25:11Z", "monotonic_ns": 1643467147743009, "raw": "{\"arg\":{\"channel\":\"books\",\"instId\":\"BTC-USDT-SWAP\"},\"action\":\"snapshot\",\"data\":[{\"asks\":[[\"64458\",\"531.28\",\"0\",\"73\"],[\"64458.1\",\"0.02\",\"0\",\"2\"],[\"64458.2\",\"0.01\",\"0\",\"1\"],[\"64458.3\",\"42.76\",\"0\",\"3\"],[\"64458.4\",\"0.01\",\"0\",\"1\"],[\"64458.5\",\"20.53\",\"0\",\"2\"],[\"64459.2\",\"0.01\",\"0\",\"1\"],[\"64459.3\",\"1.04\",\"0\",\"5\"],[\"64459.4\",\"0.6\",\"0\",\"1\"],[\"64459.6\",\"0.02\",\"0\",\"2\"],[\"64459.7\",\"1.56\",\"0\",\"1\"],[\"64460\",\"0.01\",\"0\",\"1\"],[\"64460.1\",\"0.02\",\"0\",\"2\"],[\"64460.2\",\"119.81\",\"0\",\"4\"],[\"64460.3\",\"1.56\",\"0\",\"1\"],[\"64460.6\",\"0.01\",\"0\",\"1\"],[\"64460.7\",\"1.56\",\"0\",\"1\"],[\"64460.8\",\"52.72\",\"0\",\"1\"],[\"64461\",\"0.01\",\"0\",\"1\"],[\"64461.1\",\"0.01\",\"0\",\"1\"],[\"64461.2\",\"1.59\",\"0\",\"3\"],[\"64461.3\",\"150\",\"0\",\"1\"],[\"64461.4\",\"0.03\",\"0\",\"3\"],[\"64461.7\",\"1.56\",\"0\",\"1\"],[\"64461.9\",\"0.15\",\"0\",\"1\"],[\"64462\",\"0.04\",\"0\",\"4\"],[\"64462.4\",\"1.56\",\"0\",\"1\"],[\"64462.6\",\"0.01\",\"0\",\"1\"],[\"64462.9\",\"1.57\",\"0\",\"2\"],[\"64463.1\",\"0.01\",\"0\",\"1\"],[\"64463.2\",\"0.01\",\"0\",\"1\"],[\"64463.3\",\"0.9\",\"0\",\"1\"],[\"64463.4\",\"1.56\",\"0\",\"1\"],[\"64463.5\",\"6.22\",\"0\",\"2\"],[\"64463.6\",\"14.45\",\"0\",\"1\"],[\"64463.8\",\"0.01\",\"0\",\"1\"],[\"64464\",\"1.56\",\"0\",\"4\"],[\"64464.1\",\"31.08\",\"0\",\"4\"],[\"64464.2\",\"306.28\",\"0\",\"3\"],[\"64464.3\",\"72.21\",\"0\",\"1\"],[\"64464.4\",\"0.3\",\"0\",\"1\"],[\"64464.5\",\"1.32\",\"0\",\"4\"],[\"64464.6\",\"0.01\",\"0\",\"1\"],[\"64464.7\",\"0.01\",\"0\",\"1\"],[\"64464.9\",\"65.64\",\"0\",\"1\"],[\"64465\",\"67.79\",\"0\",\"2\"],[\"64465.2\",\"78.75\",\"0\",\"3\"],[\"64465.3\",\"0.02\",\"0\",\"1\"],[\"64465.5\",\"1.01\",\"0\",\"2\"],[\"64465.6\",\"0.01\",\"0\",\"1\"],[\"64465.7\",\"75.12\",\"0\",\"2\"],[\"64465.8\",\"65.22\",\"0\",\"3\"],[\"64466\",\"0.01\",\"0\",\"1\"],[\"64466.1\",\"0.01\",\"0\",\"1\"],[\"64466.2\",\"1.2\",\"0\",\"1\"],[\"64466.4\",\"70.86\",\"0\",\"3\"],[\"64466.5\",\"1.2\",\"0\",\"1\"],[\"64466.6\",\"10.01\",\"0\",\"2\"],[\"64466.7\",\"0.01\",\"0\",\"1\"],[\"64466.9\",\"1.2\",\"0\",\"1\"],[\"64467\",\"63.88\",\"0\",\"2\"],[\"64467.2\",\"1.2\",\"0\",\"1\"],[\"64467.3\",\"0.01\",\"0\",\"1\"],[\"64467.6\",\"1.6\",\"0\",\"4\"],[\"64467.8\",\"346.86\",\"0\",\"5\"],[\"64467.9\",\"0.02\",\"0\",\"2\"],[\"64468\",\"0.02\",\"0\",\"2\"],[\"64468.2\",\"15.88\",\"0\",\"1\"],[\"64468.3\",\"10.3\",\"0\",\"3\"],[\"64468.4\",\"69.47\",\"0\",\"1\"],[\"64468.6\",\"48.28\",\"0\",\"2\"],[\"64468.7\",\"66.46\",\"0\",\"2\"],[\"64468.8\",\"574.01\",\"0\",\"7\"],[\"64468.9\",\"0.15\",\"0\",\"3\"],[\"64469\",\"22\",\"0\",\"1\"],[\"64469.1\",\"0.01\",\"0\",\"1\"],[\"64469.3\",\"4\",\"0\",\"1\"],[\"64469.4\",\"0.01\",\"0\",\"1\"],[\"64469.5\",\"4.77\",\"0\",\"1\"],[\"64469.6\",\"0.01\",\"0\",\"1\"],[\"64469.7\",\"37.75\",\"0\",\"3\"],[\"64469.8\",\"15.92\",\"0\",\"1\"],[\"64469.9\",\"0.01\",\"0\",\"1\"],[\"64470\",\"10.2\",\"0\",\"5\"],[\"64470.1\",\"0.01\",\"0\",\"1\"],[\"64470.2\",\"0.02\",\"0\",\"1\"],[\"64470.3\",\"0.01\",\"0\",\"1\"],[\"64470.4\",\"0.01\",\"0\",\"1\"],[\"64470.5\",\"7.81\",\"0\",\"1\"],[\"64470.6\",\"372.95\",\"0\",\"2\"],[\"64470.7\",\"46.56\",\"0\",\"3\"],[\"64470.8\",\"0.77\",\"0\",\"1\"],[\"64470.9\",\"346.66\",\"0\",\"11\"],[\"64471\",\"0.54\",\"0\",\"3\"],[\"64471.3\",\"99.34\",\"0\",\"2\"],[\"64471.4\",\"15.97\",\"0\",\"1\"],[\"64471.6\",\"0.04\",\"0\",\"2\"],[\"64471.7\",\"15.52\",\"0\",\"1\"],[\"64471.8\",\"498.96\",\"0\",\"2\"],[\"64471.9\",\"0.02\",\"0\",\"2\"],[\"64472\",\"2.07\",\"0\",\"5\"],[\"64472.1\",\"11.42\",\"0\",\"1\"],[\"64472.2\",\"0.01\",\"0\",\"1\"],[\"64472.6\",\"0.01\",\"0\",\"1\"],[\"64472.7\",\"24\",\"0\",\"2\"],[\"64472.8\",\"4\",\"0\",\"1\"],[\"64472.9\",\"12.05\",\"0\",\"4\"],[\"64473.2\",\"0.01\",\"0\",\"1\"],[\"64473.3\",\"1.24\",\"0\",\"1\"],[\"64473.6\",\"52.77\",\"0\",\"3\"],[\"64473.7\",\"275.99\",\"0\",\"2\"],[\"64473.8\",\"1.21\",\"0\",\"8\"],[\"64474\",\"0.03\",\"0\",\"3\"],[\"64474.2\",\"0.29\",\"0\",\"1\"],[\"64474.3\",\"18.95\",\"0\",\"1\"],[\"64474.4\",\"0.02\",\"0\",\"2\"],[\"64474.5\",\"0.03\",\"0\",\"1\"],[\"64474.6\",\"31.05\",\"0\",\"1\"],[\"64474.7\",\"8.01\",\"0\",\"2\"],[\"64474.8\",\"232.98\",\"0\",\"2\"],[\"64474.9\",\"37.23\",\"0\",\"1\"],[\"64475\",\"263.06\",\"0\",\"9\"],[\"64475.1\",\"0.01\",\"0\",\"1\"],[\"64475.3\",\"0.01\",\"0\",\"1\"],[\"64475.6\",\"0.39\",\"0\",\"2\"],[\"64475.7\",\"496.54\",\"0\",\"2\"],[\"64475.8\",\"46.54\",\"0\",\"1\"],[\"64475.9\",\"0.9\",\"0\",\"1\"],[\"64476\",\"0.03\",\"0\",\"3\"],[\"64476.2\",\"0.02\",\"0\",\"2\"],[\"64476.4\",\"0.16\",\"0\",\"1\"],[\"64476.7\",\"1.55\",\"0\",\"1\"],[\"64476.8\",\"318.09\",\"0\",\"4\"],[\"64476.9\",\"0.03\",\"0\",\"3\"],[\"64477\",\"2.62\",\"0\",\"2\"],[\"64477.3\",\"1.01\",\"0\",\"2\"],[\"64477.4\",\"0.09\",\"0\",\"3\"],[\"64477.5\",\"14.77\",\"0\",\"2\"],[\"64477.6\",\"0.07\",\"0\",\"1\"],[\"64477.8\",\"46.54\",\"0\",\"1\"],[\"64478\",\"0.02\",\"0\",\"2\"],[\"64478.3\",\"0.01\",\"0\",\"1\"],[\"64478.6\",\"3.11\",\"0\",\"2\"],[\"64478.8\",\"0.01\",\"0\",\"1\"],[\"64479\",\"0.01\",\"0\",\"1\"],[\"64479.2\",\"15.81\",\"0\",\"4\"],[\"64479.6\",\"115.35\",\"0\",\"4\"],[\"64479.7\",\"6.21\",\"0\",\"1\"],[\"64479.8\",\"496.54\",\"0\",\"2\"],[\"64479.9\",\"62.21\",\"0\",\"4\"],[\"64480\",\"55.67\",\"0\",\"44\"],[\"64480.1\",\"0.01\",\"0\",\"1\"],[\"64480.2\",\"37.23\",\"0\",\"1\"],[\"64480.4\",\"0.01\",\"0\",\"1\"],[\"64480.7\",\"33.81\",\"0\",\"1\"],[\"64480.8\",\"6.22\",\"0\",\"1\"],[\"64481\",\"171.94\",\"0\",\"5\"],[\"64481.1\",\"62.3\",\"0\",\"2\"],[\"64481.2\",\"0.68\",\"0\",\"1\"],[\"64481.6\",\"0.01\",\"0\",\"1\"],[\"64481.8\",\"0.04\",\"0\",\"3\"],[\"64481.9\",\"0.01\",\"0\",\"1\"],[\"64482\",\"0.04\",\"0\",\"2\"],[\"64482.1\",\"0.01\",\"0\",\"1\"],[\"64482.4\",\"0.77\",\"0\",\"1\"],[\"64482.5\",\"0.02\",\"0\",\"1\"],[\"64482.6\",\"0.01\",\"0\",\"1\"],[\"64482.7\",\"4.22\",\"0\",\"3\"],[\"64482.8\",\"0.41\",\"0\",\"2\"],[\"64482.9\",\"110.9\",\"0\",\"2\"],[\"64483\",\"200\",\"0\",\"1\"],[\"64483.1\",\"100.3\",\"0\",\"4\"],[\"64483.2\",\"114.69\",\"0\",\"3\"],[\"64483.3\",\"0.05\",\"0\",\"2\"],[\"64483.4\",\"312.16\",\"0\",\"1\"],[\"64483.5\",\"2.28\",\"0\",\"1\"],[\"64483.7\",\"0.01\",\"0\",\"1\"],[\"64483.9\",\"11.07\",\"0\",\"2\"],[\"64484\",\"0.02\",\"0\",\"2\"],[\"64484.1\",\"58.23\",\"0\",\"2\"],[\"64484.2\",\"15.65\",\"0\",\"1\"],[\"64484.3\",\"9.88\",\"0\",\"1\"],[\"64484.4\",\"16.25\",\"0\",\"2\"],[\"64484.5\",\"0.06\",\"0\",\"3\"],[\"64484.6\",\"1.21\",\"0\",\"2\"],[\"64484.7\",\"28.42\",\"0\",\"2\"],[\"64484.8\",\"496.53\",\"0\",\"1\"],[\"64484.9\",\"15.65\",\"0\",\"1\"],[\"64485\",\"41.95\",\"0\",\"2\"],[\"64485.1\",\"38.83\",\"0\",\"2\"],[\"64485.2\",\"0.01\",\"0\",\"1\"],[\"64485.5\",\"85.38\",\"0\",\"2\"],[\"64485.6\",\"15.65\",\"0\",\"1\"],[\"64485.7\",\"0.35\",\"0\",\"5\"],[\"64485.8\",\"0.4\",\"0\",\"2\"],[\"64485.9\",\"5.42\",\"0\",\"1\"],[\"64486\",\"101.09\",\"0\",\"7\"],[\"64486.2\",\"0.17\",\"0\",\"6\"],[\"64486.3\",\"179.9\",\"0\",\"4\"],[\"64486.4\",\"1.29\",\"0\",\"3\"],[\"64486.5\",\"15.65\",\"0\",\"1\"],[\"64486.6\",\"47.53\",\"0\",\"2\"],[\"64486.7\",\"0.01\",\"0\",\"1\"],[\"64486.8\",\"37.42\",\"0\",\"4\"],[\"64486.9\",\"0.12\",\"0\",\"2\"],[\"64487\",\"51.82\",\"0\",\"5\"],[\"64487.1\",\"0.53\",\"0\",\"4\"],[\"64487.2\",\"0.03\",\"0\",\"2\"],[\"64487.3\",\"0.04\",\"0\",\"2\"],[\"64487.4\",\"0.49\",\"0\",\"5\"],[\"64487.5\",\"43.47\",\"0\",\"6\"],[\"64487.6\",\"301.45\",\"0\",\"1\"],[\"64487.7\",\"130.34\",\"0\",\"4\"],[\"64487.8\",\"0.09\",\"0\",\"3\"],[\"64487.9\",\"0.01\",\"0\",\"1\"],[\"64488\",\"57.87\",\"0\",\"27\"],[\"64488.1\",\"0.67\",\"0\",\"2\"],[\"64488.2\",\"3.96\",\"0\",\"2\"],[\"64488.3\",\"38.84\",\"0\",\"2\"],[\"64488.4\",\"21.02\",\"0\",\"6\"],[\"64488.6\",\"0.02\",\"0\",\"2\"],[\"64488.7\",\"496.58\",\"0\",\"3\"],[\"64488.8\",\"50\",\"0\",\"1\"],[\"64488.9\",\"0.32\",\"0\",\"5\"],[\"64489\",\"57.94\",\"0\",\"9\"],[\"64489.1\",\"26.75\",\"0\",\"5\"],[\"64489.2\",\"69.9\",\"0\",\"1\"],[\"64489.3\",\"23.26\",\"0\",\"6\"],[\"64489.4\",\"2.91\",\"0\",\"4\"],[\"64489.5\",\"0.01\",\"0\",\"1\"],[\"64489.6\",\"0.13\",\"0\",\"3\"],[\"64489.7\",\"47.34\",\"0\",\"2\"],[\"64489.8\",\"31.34\",\"0\",\"5\"],[\"64489.9\",\"143.6\",\"0\",\"1\"],[\"64490\",\"55.77\",\"0\",\"19\"],[\"64490.1\",\"0.01\",\"0\",\"1\"],[\"64490.3\",\"1\",\"0\",\"1\"],[\"64490.4\",\"0.02\",\"0\",\"2\"],[\"64490.5\",\"17.16\",\"0\",\"3\"],[\"64490.6\",\"1.08\",\"0\",\"3\"],[\"64490.7\",\"0.07\",\"0\",\"3\"],[\"64490.9\",\"86.21\",\"0\",\"3\"],[\"64491\",\"80.13\",\"0\",\"2\"],[\"64491.2\",\"1.01\",\"0\",\"2\"],[\"64491.3\",\"0.02\",\"0\",\"2\"],[\"64491.4\",\"20.09\",\"0\",\"3\"],[\"64491.5\",\"0.1\",\"0\",\"1\"],[\"64491.6\",\"0.09\",\"0\",\"3\"],[\"64491.7\",\"0.02\",\"0\",\"2\"],[\"64491.8\",\"0.05\",\"0\",\"1\"],[\"64491.9\",\"0.31\",\"0\",\"5\"],[\"64492\",\"0.03\",\"0\",\"3\"],[\"64492.2\",\"1.9\",\"0\",\"7\"],[\"64492.3\",\"0.03\",\"0\",\"1\"],[\"64492.4\",\"57.86\",\"0\",\"6\"],[\"64492.5\",\"0.06\",\"0\",\"4\"],[\"64492.6\",\"98.92\",\"0\",\"1\"],[\"64492.7\",\"99.88\",\"0\",\"3\"],[\"64492.8\",\"0.13\",\"0\",\"7\"],[\"64492.9\",\"9.01\",\"0\",\"3\"],[\"64493\",\"13.72\",\"0\",\"4\"],[\"64493.1\",\"31.76\",\"0\",\"5\"],[\"64493.2\",\"400.82\",\"0\",\"9\"],[\"64493.3\",\"580.33\",\"0\",\"6\"],[\"64493.4\",\"0.32\",\"0\",\"5\"],[\"64493.5\",\"2.29\",\"0\",\"5\"],[\"64493.6\",\"148.86\",\"0\",\"1\"],[\"64493.7\",\"359.29\",\"0\",\"5\"],[\"64493.8\",\"1.24\",\"0\",\"4\"],[\"64494\",\"1.04\",\"0\",\"3\"],[\"64494.1\",\"1.2\",\"0\",\"1\"],[\"64494.3\",\"15.73\",\"0\",\"5\"],[\"64494.4\",\"0.23\",\"0\",\"6\"],[\"64494.6\",\"6.24\",\"0\",\"5\"],[\"64494.7\",\"24.55\",\"0\",\"6\"],[\"64494.8\",\"203.46\",\"0\",\"3\"],[\"64494.9\",\"1.27\",\"0\",\"4\"],[\"64495\",\"1.5\",\"0\",\"9\"],[\"64495.1\",\"0.07\",\"0\",\"3\"],[\"64495.2\",\"0.01\",\"0\",\"1\"],[\"64495.3\",\"1.46\",\"0\",\"3\"],[\"64495.4\",\"1.56\",\"0\",\"4\"],[\"64495.5\",\"6.32\",\"0\",\"4\"],[\"64495.6\",\"0.02\",\"0\",\"2\"],[\"64495.7\",\"27\",\"0\",\"4\"],[\"64495.8\",\"0.03\",\"0\",\"2\"],[\"64495.9\",\"4.74\",\"0\",\"4\"],[\"64496\",\"104.13\",\"0\",\"6\"],[\"64496.1\",\"0.06\",\"0\",\"3\"],[\"64496.2\",\"0.01\",\"0\",\"1\"],[\"64496.3\",\"0.3\",\"0\",\"4\"],[\"64496.4\",\"21.88\",\"0\",\"3\"],[\"64496.6\",\"31.68\",\"0\",\"2\"],[\"64496.7\",\"22.72\",\"0\",\"2\"],[\"64496.8\",\"75.94\",\"0\",\"5\"],[\"64496.9\",\"449.69\",\"0\",\"2\"],[\"64497\",\"34.46\",\"0\",\"6\"],[\"64497.1\",\"0.01\",\"0\",\"1\"],[\"64497.2\",\"0.84\",\"0\",\"3\"],[\"64497.3\",\"41.14\",\"0\",\"4\"],[\"64497.4\",\"0.09\",\"0\",\"2\"],[\"64497.5\",\"0.33\",\"0\",\"3\"],[\"64497.6\",\"15.77\",\"0\",\"3\"],[\"64497.8\",\"0.01\",\"0\",\"1\"],[\"64497.9\",\"0.01\",\"0\",\"1\"],[\"64498\",\"497.29\",\"0\",\"3\"],[\"64498.1\",\"0.04\",\"0\",\"4\"],[\"64498.2\",\"0.03\",\"0\",\"2\"],[\"64498.3\",\"100.42\",\"0\",\"7\"],[\"64498.5\",\"4.51\",\"0\",\"5\"],[\"64498.6\",\"0.27\",\"0\",\"4\"],[\"64498.7\",\"2.36\",\"0\",\"3\"],[\"64498.8\",\"20.4\",\"0\",\"3\"],[\"64498.9\",\"40.65\",\"0\",\"3\"],[\"64499\",\"333.41\",\"0\",\"22\"],[\"64499.1\",\"0.15\",\"0\",\"3\"],[\"64499.2\",\"0.01\",\"0\",\"1\"],[\"64499.4\",\"1.72\",\"0\",\"2\"],[\"64499.6\",\"74.53\",\"0\",\"4\"],[\"64499.7\",\"35.37\",\"0\",\"5\"],[\"64499.8\",\"19.95\",\"0\",\"3\"],[\"64499.9\",\"1162.28\",\"0\",\"3\"],[\"64500\",\"3479.33\",\"0\",\"1036\"],[\"64500.1\",\"0.05\",\"0\",\"4\"],[\"64500.2\",\"0.01\",\"0\",\"1\"],[\"64500.3\",\"2.77\",\"0\",\"4\"],[\"64500.4\",\"0.04\",\"0\",\"4\"],[\"64500.5\",\"2.49\",\"0\",\"2\"],[\"64500.6\",\"0.38\",\"0\",\"2\"],[\"64500.7\",\"3.92\",\"0\",\"2\"],[\"64500.8\",\"0.36\",\"0\",\"1\"],[\"64500.9\",\"73.16\",\"0\",\"6\"],[\"64501\",\"0.27\",\"0\",\"3\"],[\"64501.1\",\"0.05\",\"0\",\"2\"],[\"64501.2\",\"0.02\",\"0\",\"2\"],[\"64501.3\",\"0.02\",\"0\",\"1\"],[\"64501.4\",\"0.01\",\"0\",\"1\"],[\"64501.5\",\"1.57\",\"0\",\"4\"],[\"64501.6\",\"4.99\",\"0\",\"4\"],[\"64501.7\",\"0.53\",\"0\",\"2\"],[\"64501.8\",\"59\",\"0\",\"5\"],[\"64501.9\",\"0.08\",\"0\",\"1\"],[\"64502\",\"3.11\",\"0\",\"6\"],[\"64502.1\",\"0.01\",\"0\",\"1\"],[\"64502.2\",\"15.76\",\"0\",\"4\"],[\"64502.3\",\"11.33\",\"0\",\"3\"],[\"64502.4\",\"0.18\",\"0\",\"5\"],[\"64502.5\",\"0.2\",\"0\",\"3\"],[\"64502.6\",\"0.01\",\"0\",\"1\"],[\"64502.7\",\"0.03\",\"0\",\"3\"],[\"64502.8\",\"10.53\",\"0\",\"2\"],[\"64502.9\",\"0.99\",\"0\",\"4\"],[\"64503\",\"15.94\",\"0\",\"2\"],[\"64503.1\",\"0.86\",\"0\",\"7\"],[\"64503.2\",\"15.95\",\"0\",\"3\"],[\"64503.3\",\"0.02\",\"0\",\"2\"],[\"64503.5\",\"63.72\",\"0\",\"6\"],[\"64503.6\",\"17.98\",\"0\",\"3\"],[\"64503.7\",\"0.29\",\"0\",\"2\"],[\"64503.9\",\"20.45\",\"0\",\"1\"],[\"64504\",\"17.31\",\"0\",\"6\"],[\"64504.1\",\"581.2\",\"0\",\"8\"],[\"64504.2\",\"16.06\",\"0\",\"3\"],[\"64504.3\",\"0.04\",\"0\",\"2\"],[\"64504.4\",\"1.13\",\"0\",\"4\"],[\"64504.5\",\"73.8\",\"0\",\"6\"],[\"64504.7\",\"0.01\",\"0\",\"1\"],[\"64504.8\",\"0.08\",\"0\",\"2\"],[\"64504.9\",\"0.1\",\"0\",\"3\"],[\"64505\",\"0.82\",\"0\",\"3\"],[\"64505.1\",\"0.02\",\"0\",\"2\"],[\"64505.3\",\"1.16\",\"0\",\"2\"],[\"64505.4\",\"59.22\",\"0\",\"3\"],[\"64505.5\",\"3.91\",\"0\",\"2\"],[\"64505.6\",\"11.43\",\"0\",\"3\"],[\"64505.7\",\"0.56\",\"0\",\"1\"],[\"64505.8\",\"21.95\",\"0\",\"3\"],[\"64505.9\",\"0.01\",\"0\",\"1\"],[\"64506\",\"10.05\",\"0\",\"3\"],[\"64506.1\",\"0.06\",\"0\",\"1\"],[\"64506.2\",\"0.03\",\"0\",\"2\"],[\"64506.4\",\"0.03\",\"0\",\"3\"],[\"64506.5\",\"0.07\",\"0\",\"1\"],[\"64506.6\",\"10.15\",\"0\",\"3\"],[\"64506.7\",\"0.19\",\"0\",\"15\"],[\"64506.8\",\"1.05\",\"0\",\"4\"],[\"64506.9\",\"0.01\",\"0\",\"1\"],[\"64507\",\"46.6\",\"0\",\"2\"],[\"64507.1\",\"0.06\",\"0\",\"4\"],[\"64507.2\",\"14.03\",\"0\",\"2\"],[\"64507.3\",\"0.03\",\"0\",\"2\"],[\"64507.4\",\"27.31\",\"0\",\"5\"],[\"64507.5\",\"15.77\",\"0\",\"6\"],[\"64507.6\",\"0.03\",\"0\",\"2\"],[\"64507.7\",\"0.07\",\"0\",\"4\"],[\"64507.8\",\"2.83\",\"0\",\"3\"],[\"64507.9\",\"0.25\",\"0\",\"2\"],[\"64508\",\"13.54\",\"0\",\"7\"],[\"64508.1\",\"21.31\",\"0\",\"3\"],[\"64508.2\",\"59.01\",\"0\",\"5\"]],\"bids\":[[\"64457.9\",\"351.22\",\"0\",\"20\"],[\"64457.8\",\"0.14\",\"0\",\"2\"],[\"64457.7\",\"0.32\",\"0\",\"1\"],[\"64457.6\",\"0.47\",\"0\",\"2\"],[\"64457.1\",\"0.32\",\"0\",\"1\"],[\"64457\",\"0.01\",\"0\",\"1\"],[\"64456.7\",\"0.01\",\"0\",\"1\"],[\"64456.6\",\"0.77\",\"0\",\"2\"],[\"64456.4\",\"0.01\",\"0\",\"1\"],[\"64456.3\",\"0.02\",\"0\",\"2\"],[\"64456.2\",\"54.83\",\"0\",\"2\"],[\"64456.1\",\"0.01\",\"0\",\"1\"],[\"64456\",\"0.02\",\"0\",\"2\"],[\"64455.9\",\"0.01\",\"0\",\"1\"],[\"64455.3\",\"0.01\",\"0\",\"1\"],[\"64455.2\",\"0.05\",\"0\",\"5\"],[\"64455.1\",\"31.84\",\"0\",\"4\"],[\"64455\",\"98.45\",\"0\",\"3\"],[\"64454.9\",\"48.1\",\"0\",\"2\"],[\"64454.8\",\"0.01\",\"0\",\"1\"],[\"64454.7\",\"37.25\",\"0\",\"2\"],[\"64454.5\",\"0.01\",\"0\",\"1\"],[\"64454.4\",\"212.51\",\"0\",\"9\"],[\"64454.3\",\"1.57\",\"0\",\"2\"],[\"64454.2\",\"0.01\",\"0\",\"1\"],[\"64454.1\",\"4.02\",\"0\",\"3\"],[\"64454\",\"8.01\",\"0\",\"2\"],[\"64453.9\",\"0.01\",\"0\",\"1\"],[\"64453.8\",\"0.77\",\"0\",\"1\"],[\"64453.6\",\"0.01\",\"0\",\"1\"],[\"64453.5\",\"1.57\",\"0\",\"2\"],[\"64453.1\",\"19.55\",\"0\",\"2\"],[\"64453\",\"1.56\",\"0\",\"1\"],[\"64452.9\",\"0.01\",\"0\",\"1\"],[\"64452.8\",\"0.05\",\"0\",\"1\"],[\"64452.7\",\"0.3\",\"0\",\"1\"],[\"64452.5\",\"1.56\",\"0\",\"1\"],[\"64452.3\",\"0.01\",\"0\",\"1\"],[\"64452.2\",\"0.32\",\"0\",\"2\"],[\"64452.1\",\"12.45\",\"0\",\"4\"],[\"64452\",\"76.66\",\"0\",\"4\"],[\"64451.9\",\"1.56\",\"0\",\"1\"],[\"64451.8\",\"0.01\",\"0\",\"1\"],[\"64451.7\",\"308.15\",\"0\",\"6\"],[\"64451.5\",\"15.9\",\"0\",\"1\"],[\"64451.4\",\"1.98\",\"0\",\"3\"],[\"64451.3\",\"13.68\",\"0\",\"7\"],[\"64451.2\",\"396.06\",\"0\",\"4\"],[\"64451.1\",\"0.01\",\"0\",\"1\"],[\"64451\",\"2.23\",\"0\",\"3\"],[\"64450.9\",\"1.56\",\"0\",\"1\"],[\"64450.7\",\"0.04\",\"0\",\"2\"],[\"64450.5\",\"7.07\",\"0\",\"5\"],[\"64450.4\",\"1.87\",\"0\",\"2\"],[\"64450.3\",\"40.83\",\"0\",\"1\"],[\"64450.2\",\"32.32\",\"0\",\"3\"],[\"64450.1\",\"40.77\",\"0\",\"1\"],[\"64450\",\"77.59\",\"0\",\"3\"],[\"64449.9\",\"17.5\",\"0\",\"2\"],[\"64449.8\",\"1.91\",\"0\",\"2\"],[\"64449.7\",\"46.58\",\"0\",\"2\"],[\"64449.6\",\"524.65\",\"0\",\"8\"],[\"64449.5\",\"38.83\",\"0\",\"2\"],[\"64449.4\",\"16.17\",\"0\",\"2\"],[\"64449.3\",\"16.22\",\"0\",\"2\"],[\"64449.2\",\"1.57\",\"0\",\"2\"],[\"64449.1\",\"0.01\",\"0\",\"1\"],[\"64449\",\"0.03\",\"0\",\"3\"],[\"64448.8\",\"1.8\",\"0\",\"1\"],[\"64448.7\",\"4\",\"0\",\"1\"],[\"64448.6\",\"0.01\",\"0\",\"1\"],[\"64448.5\",\"2.16\",\"0\",\"1\"],[\"64448.3\",\"18.89\",\"0\",\"4\"],[\"64448.2\",\"247.83\",\"0\",\"3\"],[\"64448.1\",\"10.01\",\"0\",\"2\"],[\"64448\",\"284.79\",\"0\",\"11\"],[\"64447.9\",\"4\",\"0\",\"1\"],[\"64447.8\",\"0.39\",\"0\",\"2\"],[\"64447.7\",\"3\",\"0\",\"1\"],[\"64447.4\",\"10.77\",\"0\",\"2\"],[\"64447.3\",\"42.48\",\"0\",\"3\"],[\"64447.2\",\"2.78\",\"0\",\"2\"],[\"64447.1\",\"0.3\",\"0\",\"1\"],[\"64447\",\"83.8\",\"0\",\"1\"],[\"64446.9\",\"21.3\",\"0\",\"3\"],[\"64446.8\",\"0.01\",\"0\",\"1\"],[\"64446.7\",\"3.4\",\"0\",\"5\"],[\"64446.4\",\"46.54\",\"0\",\"1\"],[\"64446.3\",\"48.85\",\"0\",\"3\"],[\"64446.2\",\"0.07\",\"0\",\"1\"],[\"64446\",\"0.04\",\"0\",\"2\"],[\"64445.9\",\"8.03\",\"0\",\"4\"],[\"64445.8\",\"1.51\",\"0\",\"2\"],[\"64445.7\",\"514.54\",\"0\",\"4\"],[\"64445.6\",\"3.9\",\"0\",\"2\"],[\"64445.4\",\"0.15\",\"0\",\"1\"],[\"64445.1\",\"184.61\",\"0\",\"4\"],[\"64445\",\"168.98\",\"0\",\"7\"],[\"64444.9\",\"10.54\",\"0\",\"2\"],[\"64444.8\",\"0.02\",\"0\",\"2\"],[\"64444.4\",\"10\",\"0\",\"1\"],[\"64444.3\",\"37.23\",\"0\",\"1\"],[\"64444.2\",\"0.01\",\"0\",\"1\"],[\"64444.1\",\"0.01\",\"0\",\"1\"],[\"64444\",\"0.02\",\"0\",\"2\"],[\"64443.7\",\"37.63\",\"0\",\"4\"],[\"64443.6\",\"0.01\",\"0\",\"1\"],[\"64443.4\",\"405.22\",\"0\",\"2\"],[\"64443.3\",\"130.89\",\"0\",\"5\"],[\"64443.2\",\"135.66\",\"0\",\"5\"],[\"64443.1\",\"3.19\",\"0\",\"1\"],[\"64443\",\"0.02\",\"0\",\"2\"],[\"64442.8\",\"0.03\",\"0\",\"3\"],[\"64442.6\",\"15.65\",\"0\",\"1\"],[\"64442.4\",\"0.01\",\"0\",\"1\"],[\"64442.3\",\"18.13\",\"0\",\"2\"],[\"64442.1\",\"6.22\",\"0\",\"1\"],[\"64442\",\"77.63\",\"0\",\"4\"],[\"64441.9\",\"70.77\",\"0\",\"3\"],[\"64441.8\",\"535.35\",\"0\",\"2\"],[\"64441.7\",\"0.02\",\"0\",\"1\"],[\"64441.6\",\"278.86\",\"0\",\"5\"],[\"64441.5\",\"61.31\",\"0\",\"3\"],[\"64441.4\",\"50.02\",\"0\",\"3\"],[\"64441.3\",\"50\",\"0\",\"1\"],[\"64441.1\",\"13.9\",\"0\",\"2\"],[\"64441\",\"3.11\",\"0\",\"2\"],[\"64440.9\",\"0.01\",\"0\",\"1\"],[\"64440.8\",\"20.09\",\"0\",\"1\"],[\"64440.6\",\"10.01\",\"0\",\"2\"],[\"64440.5\",\"7.73\",\"0\",\"1\"],[\"64440.4\",\"0.01\",\"0\",\"1\"],[\"64440.3\",\"0.04\",\"0\",\"2\"],[\"64440.2\",\"86.21\",\"0\",\"2\"],[\"64440.1\",\"113.31\",\"0\",\"3\"],[\"64440\",\"136.69\",\"0\",\"8\"],[\"64439.9\",\"62.15\",\"0\",\"1\"],[\"64439.8\",\"85.43\",\"0\",\"1\"],[\"64439.7\",\"15.67\",\"0\",\"3\"],[\"64439.5\",\"0.01\",\"0\",\"1\"],[\"64439.4\",\"0.01\",\"0\",\"1\"],[\"64439.3\",\"99.78\",\"0\",\"1\"],[\"64439\",\"0.01\",\"0\",\"1\"],[\"64438.9\",\"37.23\",\"0\",\"1\"],[\"64438.7\",\"3.99\",\"0\",\"1\"],[\"64438.6\",\"12.78\",\"0\",\"4\"],[\"64438.5\",\"16.46\",\"0\",\"3\"],[\"64438.4\",\"0.03\",\"0\",\"2\"],[\"64438.3\",\"0.01\",\"0\",\"1\"],[\"64438.2\",\"0.01\",\"0\",\"1\"],[\"64438.1\",\"15.69\",\"0\",\"2\"],[\"64438\",\"0.01\",\"0\",\"1\"],[\"64437.9\",\"15.65\",\"0\",\"1\"],[\"64437.8\",\"0.01\",\"0\",\"1\"],[\"64437.7\",\"0.01\",\"0\",\"1\"],[\"64437.6\",\"0.01\",\"0\",\"1\"],[\"64437.3\",\"15.65\",\"0\",\"1\"],[\"64437.2\",\"0.01\",\"0\",\"1\"],[\"64437.1\",\"0.3\",\"0\",\"2\"],[\"64436.9\",\"354.24\",\"0\",\"2\"],[\"64436.8\",\"1\",\"0\",\"1\"],[\"64436.7\",\"15.66\",\"0\",\"2\"],[\"64436.6\",\"41.09\",\"0\",\"5\"],[\"64436.5\",\"11.31\",\"0\",\"3\"],[\"64436.4\",\"15.65\",\"0\",\"1\"],[\"64436.3\",\"117.35\",\"0\",\"5\"],[\"64436.2\",\"58.25\",\"0\",\"1\"],[\"64436.1\",\"25.65\",\"0\",\"2\"],[\"64436\",\"201.01\",\"0\",\"3\"],[\"64435.9\",\"0.01\",\"0\",\"1\"],[\"64435.8\",\"0.07\",\"0\",\"1\"],[\"64435.7\",\"233.01\",\"0\",\"1\"],[\"64435.6\",\"28.42\",\"0\",\"2\"],[\"64435.5\",\"512.2\",\"0\",\"3\"],[\"64435.4\",\"262.87\",\"0\",\"3\"],[\"64435.3\",\"0.01\",\"0\",\"1\"],[\"64435.2\",\"0.02\",\"0\",\"2\"],[\"64435.1\",\"0.01\",\"0\",\"1\"],[\"64434.9\",\"15.7\",\"0\",\"2\"],[\"64434.8\",\"148.64\",\"0\",\"3\"],[\"64434.7\",\"10.01\",\"0\",\"2\"],[\"64434.6\",\"0.5\",\"0\",\"1\"],[\"64434.3\",\"3.11\",\"0\",\"2\"],[\"64434.2\",\"0.02\",\"0\",\"2\"],[\"64434.1\",\"0.35\",\"0\",\"2\"],[\"64434\",\"15.66\",\"0\",\"2\"],[\"64433.8\",\"6.23\",\"0\",\"2\"],[\"64433.7\",\"47.23\",\"0\",\"2\"],[\"64433.5\",\"0.02\",\"0\",\"2\"],[\"64433.4\",\"46.56\",\"0\",\"3\"],[\"64433.3\",\"17.97\",\"0\",\"4\"],[\"64433.2\",\"21.29\",\"0\",\"2\"],[\"64433.1\",\"15.65\",\"0\",\"1\"],[\"64433\",\"4.07\",\"0\",\"2\"],[\"64432.8\",\"0.01\",\"0\",\"1\"],[\"64432.6\",\"15.71\",\"0\",\"4\"],[\"64432.5\",\"0.01\",\"0\",\"1\"],[\"64432.3\",\"0.02\",\"0\",\"2\"],[\"64432.2\",\"46.57\",\"0\",\"2\"],[\"64432.1\",\"0.09\",\"0\",\"2\"],[\"64432\",\"64.4\",\"0\",\"5\"],[\"64431.9\",\"17.93\",\"0\",\"2\"],[\"64431.8\",\"15.87\",\"0\",\"2\"],[\"64431.7\",\"321.87\",\"0\",\"2\"],[\"64431.6\",\"496.53\",\"0\",\"1\"],[\"64431.5\",\"15.65\",\"0\",\"1\"],[\"64431.4\",\"198.51\",\"0\",\"3\"],[\"64431.3\",\"15.66\",\"0\",\"2\"],[\"64431.2\",\"46.54\",\"0\",\"1\"],[\"64431.1\",\"0.01\",\"0\",\"1\"],[\"64431\",\"4.06\",\"0\",\"17\"],[\"64430.7\",\"15.65\",\"0\",\"1\"],[\"64430.4\",\"0.04\",\"0\",\"4\"],[\"64430.3\",\"1.01\",\"0\",\"2\"],[\"64430.1\",\"15.67\",\"0\",\"3\"],[\"64430\",\"7.12\",\"0\",\"5\"],[\"64429.9\",\"12.37\",\"0\",\"4\"],[\"64429.8\",\"35.67\",\"0\",\"4\"],[\"64429.4\",\"155.94\",\"0\",\"3\"],[\"64429.2\",\"46.65\",\"0\",\"2\"],[\"64429.1\",\"0.02\",\"0\",\"1\"],[\"64428.9\",\"16.49\",\"0\",\"1\"],[\"64428.8\",\"0.02\",\"0\",\"2\"],[\"64428.6\",\"0.04\",\"0\",\"2\"],[\"64428.4\",\"37.23\",\"0\",\"1\"],[\"64428.2\",\"15.66\",\"0\",\"2\"],[\"64428.1\",\"0.65\",\"0\",\"2\"],[\"64428\",\"15.75\",\"0\",\"5\"],[\"64427.9\",\"3.88\",\"0\",\"1\"],[\"64427.8\",\"1.06\",\"0\",\"1\"],[\"64427.7\",\"387.46\",\"0\",\"4\"],[\"64427.6\",\"0.01\",\"0\",\"1\"],[\"64427.3\",\"255.84\",\"0\",\"5\"],[\"64427.2\",\"496.54\",\"0\",\"2\"],[\"64427\",\"266.25\",\"0\",\"5\"],[\"64426.8\",\"0.06\",\"0\",\"1\"],[\"64426.7\",\"46.66\",\"0\",\"13\"],[\"64426.6\",\"0.01\",\"0\",\"1\"],[\"64426.5\",\"15.69\",\"0\",\"2\"],[\"64426.4\",\"0.01\",\"0\",\"1\"],[\"64426.1\",\"0.77\",\"0\",\"1\"],[\"64426\",\"0.03\",\"0\",\"2\"],[\"64425.9\",\"15.65\",\"0\",\"1\"],[\"64425.8\",\"0.01\",\"0\",\"1\"],[\"64425.7\",\"4.01\",\"0\",\"2\"],[\"64425.6\",\"3.91\",\"0\",\"2\"],[\"64425.5\",\"11.06\",\"0\",\"1\"],[\"64425.4\",\"6.27\",\"0\",\"2\"],[\"64425.2\",\"0.79\",\"0\",\"3\"],[\"64425\",\"17.21\",\"0\",\"8\"],[\"64424.9\",\"15.66\",\"0\",\"2\"],[\"64424.6\",\"0.02\",\"0\",\"2\"],[\"64424.3\",\"46.54\",\"0\",\"1\"],[\"64424.2\",\"0.01\",\"0\",\"1\"],[\"64424.1\",\"42.31\",\"0\",\"1\"],[\"64424\",\"1.38\",\"0\",\"6\"],[\"64423.9\",\"0.05\",\"0\",\"1\"],[\"64423.8\",\"17.49\",\"0\",\"3\"],[\"64423.4\",\"198.67\",\"0\",\"2\"],[\"64423.3\",\"496.84\",\"0\",\"2\"],[\"64423.2\",\"52.88\",\"0\",\"2\"],[\"64423.1\",\"0.01\",\"0\",\"1\"],[\"64423\",\"1.59\",\"0\",\"6\"],[\"64422.8\",\"0.02\",\"0\",\"2\"],[\"64422.7\",\"0.02\",\"0\",\"1\"],[\"64422.6\",\"98.94\",\"0\",\"3\"],[\"64422.4\",\"326.23\",\"0\",\"4\"],[\"64422.2\",\"11.09\",\"0\",\"4\"],[\"64422\",\"0.03\",\"0\",\"3\"],[\"64421.9\",\"0.16\",\"0\",\"2\"],[\"64421.8\",\"0.03\",\"0\",\"2\"],[\"64421.7\",\"15.65\",\"0\",\"1\"],[\"64421.6\",\"15.66\",\"0\",\"2\"],[\"64421.5\",\"0.8\",\"0\",\"2\"],[\"64421.4\",\"46.54\",\"0\",\"1\"],[\"64421.3\",\"0.03\",\"0\",\"2\"],[\"64421.2\",\"0.01\",\"0\",\"1\"],[\"64421.1\",\"21.53\",\"0\",\"4\"],[\"64421\",\"0.01\",\"0\",\"1\"],[\"64420.9\",\"19.81\",\"0\",\"3\"],[\"64420.7\",\"0.03\",\"0\",\"1\"],[\"64420.6\",\"100.58\",\"0\",\"1\"],[\"64420.5\",\"0.02\",\"0\",\"2\"],[\"64420.4\",\"0.27\",\"0\",\"2\"],[\"64420.3\",\"1\",\"0\",\"1\"],[\"64420.2\",\"80.61\",\"0\",\"3\"],[\"64420\",\"29.55\",\"0\",\"22\"],[\"64419.9\",\"18.91\",\"0\",\"3\"],[\"64419.8\",\"0.02\",\"0\",\"2\"],[\"64419.7\",\"20.01\",\"0\",\"2\"],[\"64419.6\",\"0.03\",\"0\",\"3\"],[\"64419.5\",\"212.33\",\"0\",\"3\"],[\"64419.4\",\"33.02\",\"0\",\"2\"],[\"64419.3\",\"552.33\",\"0\",\"4\"],[\"64419.2\",\"46.56\",\"0\",\"3\"],[\"64419.1\",\"0.02\",\"0\",\"2\"],[\"64419\",\"0.03\",\"0\",\"3\"],[\"64418.9\",\"11.06\",\"0\",\"1\"],[\"64418.8\",\"0.02\",\"0\",\"1\"],[\"64418.7\",\"0.01\",\"0\",\"1\"],[\"64418.6\",\"0.3\",\"0\",\"2\"],[\"64418.5\",\"0.05\",\"0\",\"1\"],[\"64418.4\",\"0.97\",\"0\",\"1\"],[\"64418.3\",\"15.65\",\"0\",\"1\"],[\"64418.1\",\"15.31\",\"0\",\"1\"],[\"64418\",\"20.53\",\"0\",\"4\"],[\"64417.9\",\"2.28\",\"0\",\"1\"],[\"64417.8\",\"0.02\",\"0\",\"2\"],[\"64417.7\",\"0.04\",\"0\",\"1\"],[\"64417.6\",\"0.02\",\"0\",\"2\"],[\"64417.5\",\"0.02\",\"0\",\"2\"],[\"64417.4\",\"0.35\",\"0\",\"8\"],[\"64417.2\",\"0.02\",\"0\",\"2\"],[\"64417.1\",\"3.9\",\"0\",\"1\"],[\"64417\",\"0.12\",\"0\",\"1\"],[\"64416.9\",\"68.68\",\"0\",\"4\"],[\"64416.8\",\"0.01\",\"0\",\"1\"],[\"64416.7\",\"45.2\",\"0\",\"3\"],[\"64416.6\",\"15.66\",\"0\",\"2\"],[\"64416.5\",\"0.08\",\"0\",\"1\"],[\"64416.3\",\"47.19\",\"0\",\"6\"],[\"64416.2\",\"101.76\",\"0\",\"4\"],[\"64416\",\"298.12\",\"0\",\"6\"],[\"64415.9\",\"0.01\",\"0\",\"1\"],[\"64415.7\",\"1.18\",\"0\",\"1\"],[\"64415.6\",\"30.86\",\"0\",\"3\"],[\"64415.5\",\"20\",\"0\",\"1\"],[\"64415.4\",\"0.01\",\"0\",\"1\"],[\"64415.3\",\"581.08\",\"0\",\"5\"],[\"64415.2\",\"0.01\",\"0\",\"1\"],[\"64415.1\",\"6.91\",\"0\",\"2\"],[\"64415\",\"15.88\",\"0\",\"4\"],[\"64414.9\",\"2.32\",\"0\",\"2\"],[\"64414.8\",\"19.02\",\"0\",\"1\"],[\"64414.7\",\"26.09\",\"0\",\"3\"],[\"64414.6\",\"0.31\",\"0\",\"1\"],[\"64414.5\",\"1365.58\",\"0\",\"1\"],[\"64414.4\",\"99.09\",\"0\",\"1\"],[\"64414.2\",\"0.02\",\"0\",\"2\"],[\"64414.1\",\"0.11\",\"0\",\"2\"],[\"64414\",\"0.01\",\"0\",\"1\"],[\"64413.9\",\"23.27\",\"0\",\"1\"],[\"64413.8\",\"0.01\",\"0\",\"1\"],[\"64413.3\",\"15.69\",\"0\",\"4\"],[\"64413.1\",\"64.55\",\"0\",\"2\"],[\"64412.9\",\"0.01\",\"0\",\"1\"],[\"64412.8\",\"0.01\",\"0\",\"1\"],[\"64412.7\",\"0.09\",\"0\",\"3\"],[\"64412.4\",\"0.01\",\"0\",\"1\"],[\"64412.3\",\"11.43\",\"0\",\"2\"],[\"64412.2\",\"99.58\",\"0\",\"1\"],[\"64412.1\",\"50\",\"0\",\"1\"],[\"64412\",\"0.02\",\"0\",\"1\"],[\"64411.8\",\"0.01\",\"0\",\"1\"],[\"64411.7\",\"15.68\",\"0\",\"2\"],[\"64411.5\",\"0.01\",\"0\",\"1\"],[\"64411.4\",\"3.38\",\"0\",\"2\"],[\"64411.3\",\"0.01\",\"0\",\"1\"],[\"64411.2\",\"15.33\",\"0\",\"1\"],[\"64411.1\",\"0.06\",\"0\",\"2\"],[\"64410.9\",\"2.08\",\"0\",\"3\"],[\"64410.8\",\"0.03\",\"0\",\"2\"],[\"64410.6\",\"0.01\",\"0\",\"1\"],[\"64410.5\",\"46.54\",\"0\",\"1\"],[\"64410.4\",\"0.69\",\"0\",\"2\"],[\"64410.3\",\"0.06\",\"0\",\"2\"],[\"64410.2\",\"6.23\",\"0\",\"2\"],[\"64410.1\",\"0.81\",\"0\",\"4\"],[\"64410\",\"1.56\",\"0\",\"5\"],[\"64409.9\",\"0.1\",\"0\",\"4\"],[\"64409.8\",\"106.39\",\"0\",\"1\"],[\"64409.7\",\"0.03\",\"0\",\"3\"],[\"64409.6\",\"0.24\",\"0\",\"2\"],[\"64409.1\",\"0.85\",\"0\",\"4\"],[\"64409\",\"11.42\",\"0\",\"1\"],[\"64408.9\",\"69.14\",\"0\",\"5\"],[\"64408.8\",\"0.01\",\"0\",\"1\"],[\"64408.7\",\"5.45\",\"0\",\"4\"],[\"64408.4\",\"7.93\",\"0\",\"5\"],[\"64408.3\",\"0.03\",\"0\",\"1\"],[\"64408.2\",\"83.77\",\"0\",\"2\"],[\"64408.1\",\"0.01\",\"0\",\"1\"],[\"64408\",\"4.48\",\"0\",\"6\"],[\"64407.9\",\"0.04\",\"0\",\"4\"],[\"64407.6\",\"0.02\",\"0\",\"2\"],[\"64407.5\",\"496.53\",\"0\",\"1\"],[\"64407.4\",\"0.51\",\"0\",\"1\"],[\"64407.3\",\"99.78\",\"0\",\"1\"],[\"64407.2\",\"0.05\",\"0\",\"1\"],[\"64407\",\"0.37\",\"0\",\"4\"],[\"64406.9\",\"0.01\",\"0\",\"1\"],[\"64406.7\",\"11.06\",\"0\",\"3\"],[\"64406.6\",\"3.92\",\"0\",\"2\"],[\"64406.4\",\"0.12\",\"0\",\"2\"],[\"64406.3\",\"0.32\",\"0\",\"1\"],[\"64406.1\",\"0.02\",\"0\",\"2\"],[\"64405.9\",\"1.93\",\"0\",\"1\"],[\"64405.7\",\"15.86\",\"0\",\"2\"],[\"64405.6\",\"0.02\",\"0\",\"2\"],[\"64405.5\",\"0.01\",\"0\",\"1\"]],\"ts\":\"1782015911105\",\"checksum\":1905628490,\"seqId\":325069860050,\"prevSeqId\":-1}]}"}
{"action": "update", "capture_sequence": 87, "channel": "books", "connection_sequence": 2, "event": null, "instId": "BTC-USDT-SWAP", "local_receive_ts": "2026-06-21T04:25:11Z", "monotonic_ns": 1643467149157830, "raw": "{\"arg\":{\"channel\":\"books\",\"instId\":\"BTC-USDT-SWAP\"},\"action\":\"update\",\"data\":[{\"asks\":[[\"64464.2\",\"404.07\",\"0\",\"4\"],[\"64474.1\",\"31.05\",\"0\",\"1\"],[\"64474.6\",\"0\",\"0\",\"0\"]],\"bids\":[[\"64457.9\",\"341.22\",\"0\",\"19\"],[\"64455.3\",\"0.02\",\"0\",\"2\"],[\"64455.1\",\"31.83\",\"0\",\"3\"],[\"64455\",\"100.01\",\"0\",\"4\"],[\"64454.9\",\"46.54\",\"0\",\"1\"],[\"64452.2\",\"0.01\",\"0\",\"1\"],[\"64452\",\"76.97\",\"0\",\"5\"],[\"64450.2\",\"32.01\",\"0\",\"2\"],[\"64450.1\",\"118.34\",\"0\",\"2\"],[\"64450\",\"0.33\",\"0\",\"3\"],[\"64449.9\",\"15.94\",\"0\",\"1\"],[\"64441.7\",\"86.22\",\"0\",\"2\"],[\"64441.5\",\"61.29\",\"0\",\"2\"],[\"64441\",\"3.13\",\"0\",\"3\"],[\"64440.2\",\"0.01\",\"0\",\"1\"],[\"64438.4\",\"0.01\",\"0\",\"1\"],[\"64436.8\",\"0.02\",\"0\",\"1\"],[\"64436.6\",\"10.03\",\"0\",\"4\"],[\"64436.4\",\"46.71\",\"0\",\"2\"]],\"ts\":\"1782015911205\",\"checksum\":1377225908,\"seqId\":325069860218,\"prevSeqId\":325069860050}]}"}
{"action": null, "capture_sequence": 88, "channel": "trades", "connection_sequence": 2, "event": null, "instId": "BTC-USDT-SWAP", "local_receive_ts": "2026-06-21T04:25:11Z", "monotonic_ns": 1643467243532232, "raw": "{\"arg\":{\"channel\":\"trades\",\"instId\":\"BTC-USDT-SWAP\"},\"data\":[{\"instId\":\"BTC-USDT-SWAP\",\"tradeId\":\"2718748851\",\"px\":\"64457.9\",\"sz\":\"5\",\"side\":\"sell\",\"ts\":\"1782015911297\",\"count\":\"1\",\"source\":\"0\",\"seqId\":325069860371}]}"}
{"action": "update", "capture_sequence": 89, "channel": "books", "connection_sequence": 2, "event": null, "instId": "BTC-USDT-SWAP", "local_receive_ts": "2026-06-21T04:25:11Z", "monotonic_ns": 1643467243974453, "raw": "{\"arg\":{\"channel\":\"books\",\"instId\":\"BTC-USDT-SWAP\"},\"action\":\"update\",\"data\":[{\"asks\":[[\"64458\",\"531.38\",\"0\",\"74\"],[\"64474.1\",\"0\",\"0\",\"0\"],[\"64474.6\",\"31.05\",\"0\",\"1\"],[\"64482.4\",\"0\",\"0\",\"0\"],[\"64482.6\",\"1.09\",\"0\",\"3\"],[\"64482.7\",\"3.91\",\"0\",\"2\"],[\"64491.4\",\"0.02\",\"0\",\"2\"],[\"64492.6\",\"118.99\",\"0\",\"2\"],[\"64508.4\",\"1367.19\",\"0\",\"6\"]],\"bids\":[[\"64457.9\",\"336.21\",\"0\",\"19\"],[\"64455.3\",\"0.01\",\"0\",\"1\"],[\"64455.1\",\"31.84\",\"0\",\"4\"],[\"64455\",\"98.45\",\"0\",\"3\"],[\"64454.3\",\"0.01\",\"0\",\"1\"],[\"64452.2\",\"0.32\",\"0\",\"2\"],[\"64452\",\"76.66\",\"0\",\"4\"],[\"64443.3\",\"130.12\",\"0\",\"4\"],[\"64442.7\",\"0.77\",\"0\",\"1\"],[\"64442.2\",\"20.09\",\"0\",\"1\"],[\"64440.8\",\"0\",\"0\",\"0\"],[\"64440.2\",\"85.44\",\"0\",\"2\"],[\"64439.8\",\"0\",\"0\",\"0\"],[\"64438.6\",\"13.78\",\"0\",\"5\"],[\"64436.6\",\"41.09\",\"0\",\"5\"],[\"64436.4\",\"15.65\",\"0\",\"1\"]],\"ts\":\"1782015911305\",\"checksum\":-915488621,\"seqId\":325069860376,\"prevSeqId\":325069860218}]}"}
{"action": "update", "capture_sequence": 90, "channel": "books", "connection_sequence": 2, "event": null, "instId": "BTC-USDT-SWAP", "local_receive_ts": "2026-06-21T04:25:11Z", "monotonic_ns": 1643467331459448, "raw": "{\"arg\":{\"channel\":\"books\",\"instId\":\"BTC-USDT-SWAP\"},\"action\":\"update\",\"data\":[{\"asks\":[[\"64458\",\"529.82\",\"0\",\"73\"],[\"64458.3\",\"8.29\",\"0\",\"3\"],[\"64460.2\",\"0.79\",\"0\",\"3\"],[\"64471.7\",\"0\",\"0\",\"0\"],[\"64471.9\",\"15.54\",\"0\",\"3\"],[\"64474.8\",\"0.11\",\"0\",\"1\"],[\"64475.6\",\"233.26\",\"0\",\"3\"],[\"64476.7\",\"0\",\"0\",\"0\"],[\"64476.9\",\"1.58\",\"0\",\"4\"],[\"64480.7\",\"0\",\"0\",\"0\"],[\"64482.5\",\"33.82\",\"0\",\"2\"],[\"64482.6\",\"0.01\",\"0\",\"1\"],[\"64483\",\"200.77\",\"0\",\"2\"],[\"64483.4\",\"312.47\",\"0\",\"2\"],[\"64484.1\",\"0.02\",\"0\",\"1\"],[\"64485\",\"100.15\",\"0\",\"3\"],[\"64485.5\",\"0.01\",\"0\",\"1\"],[\"64486.9\",\"85.49\",\"0\",\"3\"],[\"64490.9\",\"0.07\",\"0\",\"2\"],[\"64492.5\",\"86.2\",\"0\",\"5\"],[\"64508.5\",\"42.46\",\"0\",\"3\"],[\"64508.6\",\"0.01\",\"0\",\"1\"],[\"64508.7\",\"42.88\",\"0\",\"9\"]],\"bids\":[[\"64457.9\",\"346.21\",\"0\",\"20\"],[\"64456.5\",\"0.01\",\"0\",\"1\"],[\"64456.4\",\"67.31\",\"0\",\"2\"],[\"64456.3\",\"0.01\",\"0\",\"1\"],[\"64456.2\",\"0\",\"0\",\"0\"],[\"64455.3\",\"31.84\",\"0\",\"4\"],[\"64455.2\",\"0.04\",\"0\",\"4\"],[\"64455.1\",\"0.02\",\"0\",\"2\"],[\"64453.5\",\"0.01\",\"0\",\"1\"],[\"64453\",\"0\",\"0\",\"0\"],[\"64450.6\",\"0.31\",\"0\",\"1\"],[\"64450.4\",\"79.44\",\"0\",\"3\"],[\"64450.1\",\"40.77\",\"0\",\"1\"],[\"64450\",\"0.02\",\"0\",\"2\"],[\"64443.8\",\"0.77\",\"0\",\"1\"],[\"64443.3\",\"163.94\",\"0\",\"5\"],[\"64442.7\",\"0\",\"0\",\"0\"],[\"64442.1\",\"92.42\",\"0\",\"2\"],[\"64441.9\",\"36.94\",\"0\",\"2\"],[\"64441.7\",\"85.45\",\"0\",\"2\"],[\"64440.2\",\"0.01\",\"0\",\"1\"],[\"64437\",\"58.25\",\"0\",\"1\"],[\"64436.2\",\"233.01\",\"0\",\"1\"],[\"64435.7\",\"0\",\"0\",\"0\"]],\"ts\":\"1782015911405\",\"checksum\":164410687,\"seqId\":325069860526,\"prevSeqId\":325069860376}]}"}
{"action": "update", "capture_sequence": 91, "channel": "books", "connection_sequence": 2, "event": null, "instId": "BTC-USDT-SWAP", "local_receive_ts": "2026-06-21T04:25:11Z", "monotonic_ns": 1643467429497739, "raw": "{\"arg\":{\"channel\":\"books\",\"instId\":\"BTC-USDT-SWAP\"},\"action\":\"update\",\"data\":[{\"asks\":[[\"64460.8\",\"79.94\",\"0\",\"2\"],[\"64464\",\"110.69\",\"0\",\"5\"],[\"64465.3\",\"0\",\"0\",\"0\"],[\"64465.8\",\"65.24\",\"0\",\"4\"],[\"64492.4\",\"144\",\"0\",\"7\"],[\"64492.5\",\"0.06\",\"0\",\"4\"],[\"64508.8\",\"0.04\",\"0\",\"2\"]],\"bids\":[[\"64456.3\",\"0\",\"0\",\"0\"],[\"64455.3\",\"0.02\",\"0\",\"2\"],[\"64455.1\",\"31.84\",\"0\",\"4\"],[\"64432.1\",\"0.08\",\"0\",\"1\"],[\"64431.9\",\"17.94\",\"0\",\"3\"],[\"64405.3\",\"46.54\",\"0\",\"1\"]],\"ts\":\"1782015911505\",\"checksum\":342036890,\"seqId\":325069860611,\"prevSeqId\":325069860526}]}"}
{"action": "update", "capture_sequence": 92, "channel": "books", "connection_sequence": 2, "event": null, "instId": "BTC-USDT-SWAP", "local_receive_ts": "2026-06-21T04:25:11Z", "monotonic_ns": 1643467522898785, "raw": "{\"arg\":{\"channel\":\"books\",\"instId\":\"BTC-USDT-SWAP\"},\"action\":\"update\",\"data\":[{\"asks\":[[\"64460.8\",\"52.72\",\"0\",\"1\"],[\"64464\",\"1.56\",\"0\",\"4\"],[\"64464.5\",\"0.32\",\"0\",\"3\"],[\"64465.2\",\"77.75\",\"0\",\"2\"],[\"64465.8\",\"64.04\",\"0\",\"3\"],[\"64466.5\",\"0\",\"0\",\"0\"],[\"64467.2\",\"0\",\"0\",\"0\"],[\"64467.6\",\"0.4\",\"0\",\"3\"],[\"64492.2\",\"0.9\",\"0\",\"6\"],[\"64492.9\",\"8.01\",\"0\",\"2\"],[\"64493.5\",\"1.09\",\"0\",\"4\"],[\"64494.1\",\"0\",\"0\",\"0\"],[\"64494.9\",\"0.07\",\"0\",\"3\"],[\"64495.3\",\"0.26\",\"0\",\"2\"],[\"64508.9\",\"11.25\",\"0\",\"3\"],[\"64509\",\"155.92\",\"0\",\"2\"],[\"64509.1\",\"0.02\",\"0\",\"2\"]],\"bids\":[[\"64457.9\",\"365.75\",\"0\",\"21\"],[\"64453.1\",\"0.01\",\"0\",\"1\"],[\"64452.5\",\"0\",\"0\",\"0\"],[\"64450.5\",\"5.67\",\"0\",\"4\"],[\"64449.8\",\"0.01\",\"0\",\"1\"],[\"64449.2\",\"0.01\",\"0\",\"1\"],[\"64448.5\",\"0\",\"0\",\"0\"],[\"64448\",\"282.03\",\"0\",\"10\"],[\"64447.7\",\"0\",\"0\",\"0\"],[\"64405.2\",\"239.07\",\"0\",\"5\"],[\"64405.1\",\"0.07\",\"0\",\"3\"],[\"64405\",\"13.52\",\"0\",\"15\"]],\"ts\":\"1782015911605\",\"checksum\":-1306973919,\"seqId\":325069860729,\"prevSeqId\":325069860611}]}"}
{"action": "update", "capture_sequence": 93, "channel": "books", "connection_sequence": 2, "event": null, "instId": "BTC-USDT-SWAP", "local_receive_ts": "2026-06-21T04:25:11Z", "monotonic_ns": 1643467622948050, "raw": "{\"arg\":{\"channel\":\"books\",\"instId\":\"BTC-USDT-SWAP\"},\"action\":\"update\",\"data\":[{\"asks\":[[\"64464.6\",\"1.01\",\"0\",\"2\"],[\"64465.5\",\"0.01\",\"0\",\"1\"],[\"64466.2\",\"0\",\"0\",\"0\"],[\"64466.5\",\"1.2\",\"0\",\"1\"],[\"64466.9\",\"0\",\"0\",\"0\"],[\"64476.4\",\"0.15\",\"0\",\"1\"],[\"64492.2\",\"1.9\",\"0\",\"7\"],[\"64493.2\",\"399.82\",\"0\",\"8\"],[\"64493.8\",\"0.04\",\"0\",\"3\"],[\"64494.2\",\"1.2\",\"0\",\"1\"],[\"64494.6\",\"5.04\",\"0\",\"4\"],[\"64495.4\",\"0.06\",\"0\",\"3\"],[\"64495.5\",\"7.82\",\"0\",\"5\"]],\"bids\":[[\"64457.9\",\"365.21\",\"0\",\"20\"],[\"64450.1\",\"42.17\",\"0\",\"2\"],[\"64449.5\",\"37.23\",\"0\",\"1\"],[\"64448.8\",\"0\",\"0\",\"0\"],[\"64448.3\",\"16.01\",\"0\",\"3\"],[\"64448.2\",\"249.99\",\"0\",\"4\"],[\"64447.2\",\"0.38\",\"0\",\"1\"],[\"64446.9\",\"23.7\",\"0\",\"4\"],[\"64436.3\",\"117.34\",\"0\",\"5\"],[\"64404.8\",\"0.04\",\"0\",\"1\"]],\"ts\":\"1782015911705\",\"checksum\":-730840370,\"seqId\":325069860852,\"prevSeqId\":325069860729}]}"}
{"action": null, "capture_sequence": 94, "channel": "trades", "connection_sequence": 2, "event": null, "instId": "BTC-USDT-SWAP", "local_receive_ts": "2026-06-21T04:25:11Z", "monotonic_ns": 1643467634669737, "raw": "{\"arg\":{\"channel\":\"trades\",\"instId\":\"BTC-USDT-SWAP\"},\"data\":[{\"instId\":\"BTC-USDT-SWAP\",\"tradeId\":\"2718748852\",\"px\":\"64457.9\",\"sz\":\"5\",\"side\":\"sell\",\"ts\":\"1782015911717\",\"count\":\"1\",\"source\":\"0\",\"seqId\":325069860863}]}"}
{"action": "update", "capture_sequence": 95, "channel": "books", "connection_sequence": 2, "event": null, "instId": "BTC-USDT-SWAP", "local_receive_ts": "2026-06-21T04:25:11Z", "monotonic_ns": 1643467722673057, "raw": "{\"arg\":{\"channel\":\"books\",\"instId\":\"BTC-USDT-SWAP\"},\"action\":\"update\",\"data\":[{\"asks\":[[\"64465.2\",\"78.75\",\"0\",\"3\"],[\"64465.9\",\"1.2\",\"0\",\"1\"],[\"64466.2\",\"1.2\",\"0\",\"1\"],[\"64483.5\",\"0\",\"0\",\"0\"],[\"64492.9\",\"9.01\",\"0\",\"3\"],[\"64493.5\",\"2.29\",\"0\",\"5\"],[\"64493.9\",\"1.2\",\"0\",\"1\"],[\"64509\",\"0\",\"0\",\"0\"],[\"64509.1\",\"0\",\"0\",\"0\"]],\"bids\":[[\"64457.9\",\"360.21\",\"0\",\"20\"],[\"64456.5\",\"0.02\",\"0\",\"2\"],[\"64449.4\",\"18.07\",\"0\",\"3\"],[\"64448.8\",\"1.56\",\"0\",\"1\"],[\"64448.5\",\"1.8\",\"0\",\"1\"],[\"64405\",\"0\",\"0\",\"0\"],[\"64404.8\",\"0\",\"0\",\"0\"]],\"ts\":\"1782015911805\",\"checksum\":-469422732,\"seqId\":325069860966,\"prevSeqId\":325069860852}]}"}
{"action": "update", "capture_sequence": 96, "channel": "books", "connection_sequence": 2, "event": null, "instId": "BTC-USDT-SWAP", "local_receive_ts": "2026-06-21T04:25:12Z", "monotonic_ns": 1643467822781578, "raw": "{\"arg\":{\"channel\":\"books\",\"instId\":\"BTC-USDT-SWAP\"},\"action\":\"update\",\"data\":[{\"asks\":[[\"64460.8\",\"82.89\",\"0\",\"2\"],[\"64463.9\",\"0.77\",\"0\",\"1\"],[\"64464\",\"119.81\",\"0\",\"4\"],[\"64465.6\",\"1.01\",\"0\",\"2\"],[\"64467\",\"65.08\",\"0\",\"3\"],[\"64467.3\",\"1.21\",\"0\",\"2\"],[\"64467.7\",\"1.2\",\"0\",\"1\"],[\"64471.9\",\"0.02\",\"0\",\"2\"],[\"64472.6\",\"15.53\",\"0\",\"2\"],[\"64476.4\",\"0\",\"0\",\"0\"],[\"64494.7\",\"25.75\",\"0\",\"7\"],[\"64495\",\"2.7\",\"0\",\"10\"],[\"64495.3\",\"1.46\",\"0\",\"3\"],[\"64508.9\",\"0\",\"0\",\"0\"]],\"bids\":[[\"64457.9\",\"350.21\",\"0\",\"19\"],[\"64451.3\",\"14.45\",\"0\",\"8\"],[\"64450.5\",\"4.9\",\"0\",\"3\"],[\"64449.1\",\"1.61\",\"0\",\"2\"],[\"64448\",\"284.91\",\"0\",\"11\"],[\"64447.6\",\"2.76\",\"0\",\"1\"],[\"64447.4\",\"13.77\",\"0\",\"3\"],[\"64436.3\",\"117.15\",\"0\",\"4\"],[\"64410.6\",\"21.32\",\"0\",\"2\"],[\"64405.1\",\"0\",\"0\",\"0\"]],\"ts\":\"1782015911905\",\"checksum\":1174027194,\"seqId\":325069861089,\"prevSeqId\":325069860966}]}"}
{"action": "update", "capture_sequence": 97, "channel": "books", "connection_sequence": 2, "event": null, "instId": "BTC-USDT-SWAP", "local_receive_ts": "2026-06-21T04:25:12Z", "monotonic_ns": 1643467927864430, "raw": "{\"arg\":{\"channel\":\"books\",\"instId\":\"BTC-USDT-SWAP\"},\"action\":\"update\",\"data\":[{\"asks\":[[\"64458.9\",\"1.56\",\"0\",\"1\"],[\"64464\",\"0.02\",\"0\",\"2\"],[\"64464.1\",\"31.85\",\"0\",\"5\"],[\"64471.7\",\"15.52\",\"0\",\"1\"],[\"64472.6\",\"0.01\",\"0\",\"1\"],[\"64474.8\",\"232.98\",\"0\",\"2\"],[\"64475.6\",\"0.39\",\"0\",\"2\"],[\"64476.4\",\"0.15\",\"0\",\"1\"],[\"64476.9\",\"0.03\",\"0\",\"3\"],[\"64477.2\",\"1.55\",\"0\",\"1\"],[\"64481.7\",\"33.81\",\"0\",\"1\"],[\"64482.5\",\"0.02\",\"0\",\"1\"],[\"64482.8\",\"1.18\",\"0\",\"3\"],[\"64483\",\"200\",\"0\",\"1\"],[\"64483.3\",\"0.36\",\"0\",\"3\"],[\"64483.4\",\"312.16\",\"0\",\"1\"],[\"64486.2\",\"85.54\",\"0\",\"7\"],[\"64486.9\",\"0.12\",\"0\",\"2\"],[\"64490.9\",\"86.21\",\"0\",\"3\"],[\"64492.4\",\"77.93\",\"0\",\"7\"],[\"64492.6\",\"98.92\",\"0\",\"1\"],[\"64508.4\",\"0\",\"0\",\"0\"],[\"64508.5\",\"0\",\"0\",\"0\"],[\"64508.6\",\"0\",\"0\",\"0\"],[\"64508.7\",\"0\",\"0\",\"0\"],[\"64508.8\",\"0\",\"0\",\"0\"]],\"bids\":[[\"64457.9\",\"413.38\",\"0\",\"24\"],[\"64457.4\",\"1.56\",\"0\",\"1\"],[\"64456.9\",\"1.56\",\"0\",\"1\"],[\"64456.4\",\"50.55\",\"0\",\"3\"],[\"64455.3\",\"0.01\",\"0\",\"1\"],[\"64455.1\",\"0.02\",\"0\",\"2\"],[\"64455\",\"77.6\",\"0\",\"3\"],[\"64454.4\",\"203.07\",\"0\",\"5\"],[\"64452.1\",\"44.28\",\"0\",\"6\"],[\"64451.3\",\"13.68\",\"0\",\"7\"],[\"64450.5\",\"83.24\",\"0\",\"5\"],[\"64450.4\",\"1.87\",\"0\",\"2\"],[\"64449.6\",\"508.65\",\"0\",\"7\"],[\"64448\",\"272.98\",\"0\",\"6\"],[\"64446.7\",\"0\",\"0\",\"0\"],[\"64443.3\",\"130.12\",\"0\",\"4\"],[\"64442.4\",\"33.84\",\"0\",\"2\"],[\"64442.2\",\"0\",\"0\",\"0\"],[\"64442\",\"97.72\",\"0\",\"5\"],[\"64441.7\",\"0.02\",\"0\",\"1\"],[\"64440.7\",\"85.43\",\"0\",\"1\"],[\"64436.3\",\"117.34\",\"0\",\"5\"],[\"64436.2\",\"0\",\"0\",\"0\"],[\"64436.1\",\"258.66\",\"0\",\"3\"]],\"ts\":\"1782015912005\",\"checksum\":253072853,\"seqId\":325069861257,\"prevSeqId\":325069861089}]}"}
{"action": "update", "capture_sequence": 98, "channel": "books", "connection_sequence": 2, "event": null, "instId": "BTC-USDT-SWAP", "local_receive_ts": "2026-06-21T04:25:12Z", "monotonic_ns": 1643468032783728, "raw": "{\"arg\":{\"channel\":\"books\",\"instId\":\"BTC-USDT-SWAP\"},\"action\":\"update\",\"data\":[{\"asks\":[[\"64458\",\"661.3\",\"0\",\"76\"],[\"64458.3\",\"47.84\",\"0\",\"3\"],[\"64458.5\",\"5\",\"0\",\"1\"],[\"64458.9\",\"0\",\"0\",\"0\"],[\"64459.1\",\"0.01\",\"0\",\"1\"],[\"64459.2\",\"1.57\",\"0\",\"2\"],[\"64459.6\",\"150.01\",\"0\",\"2\"],[\"64460.8\",\"88.87\",\"0\",\"1\"],[\"64461.3\",\"11.21\",\"0\",\"1\"],[\"64462.4\",\"120.58\",\"0\",\"2\"],[\"64463.5\",\"0.01\",\"0\",\"1\"],[\"64463.9\",\"31.05\",\"0\",\"1\"],[\"64464\",\"7.83\",\"0\",\"3\"],[\"64464.1\",\"1.57\",\"0\",\"5\"],[\"64464.3\",\"72.23\",\"0\",\"2\"],[\"64465.8\",\"64.02\",\"0\",\"2\"],[\"64469.5\",\"7.29\",\"0\",\"2\"],[\"64470.5\",\"15.52\",\"0\",\"1\"],[\"64471.7\",\"0\",\"0\",\"0\"],[\"64471.8\",\"496.53\",\"0\",\"1\"],[\"64471.9\",\"0.04\",\"0\",\"3\"],[\"64472.6\",\"31.06\",\"0\",\"2\"],[\"64473.5\",\"232.88\",\"0\",\"1\"],[\"64473.8\",\"1.19\",\"0\",\"7\"],[\"64474.6\",\"0\",\"0\",\"0\"],[\"64474.8\",\"0.11\",\"0\",\"1\"],[\"64475.1\",\"0\",\"0\",\"0\"],[\"64475.5\",\"1.55\",\"0\",\"1\"],[\"64475.8\",\"46.55\",\"0\",\"2\"],[\"64477.2\",\"0\",\"0\",\"0\"],[\"64479.5\",\"58.65\",\"0\",\"5\"],[\"64479.6\",\"102.93\",\"0\",\"2\"],[\"64479.7\",\"0\",\"0\",\"0\"],[\"64481.7\",\"0\",\"0\",\"0\"],[\"64482.6\",\"59.3\",\"0\",\"4\"],[\"64482.8\",\"0.41\",\"0\",\"2\"],[\"64483.3\",\"0.05\",\"0\",\"2\"],[\"64484.3\",\"12.16\",\"0\",\"2\"],[\"64484.6\",\"86.58\",\"0\",\"3\"],[\"64485\",\"41.97\",\"0\",\"3\"],[\"64486.2\",\"0.17\",\"0\",\"6\"],[\"64486.4\",\"1.27\",\"0\",\"2\"],[\"64489.8\",\"117.48\",\"0\",\"6\"],[\"64490.4\",\"20.09\",\"0\",\"3\"],[\"64490.9\",\"0.07\",\"0\",\"2\"],[\"64492.4\",\"57.86\",\"0\",\"6\"],[\"64499.1\",\"0.17\",\"0\",\"4\"],[\"64500\",\"3479.31\",\"0\",\"1035\"],[\"64508.4\",\"1367.19\",\"0\",\"6\"],[\"64508.5\",\"42.46\",\"0\",\"3\"],[\"64508.6\",\"0.01\",\"0\",\"1\"]],\"bids\":[[\"64457.9\",\"191.32\",\"0\",\"20\"],[\"64457.4\",\"0\",\"0\",\"0\"],[\"64456.9\",\"0\",\"0\",\"0\"],[\"64456.4\",\"48.99\",\"0\",\"2\"],[\"64455\",\"0.02\",\"0\",\"2\"],[\"64454.4\",\"63.52\",\"0\",\"4\"],[\"64452.9\",\"19.55\",\"0\",\"2\"],[\"64452.2\",\"31.84\",\"0\",\"3\"],[\"64452.1\",\"12.45\",\"0\",\"4\"],[\"64451.9\",\"0\",\"0\",\"0\"],[\"64451.7\",\"50.48\",\"0\",\"3\"],[\"64451.3\",\"2.47\",\"0\",\"6\"],[\"64451\",\"0.02\",\"0\",\"2\"],[\"64450.5\",\"4.9\",\"0\",\"3\"],[\"64449.9\",\"17.5\",\"0\",\"2\"],[\"64449.7\",\"46.89\",\"0\",\"3\"],[\"64449.5\",\"38.79\",\"0\",\"2\"],[\"64449\",\"1.59\",\"0\",\"4\"],[\"64448.9\",\"2.52\",\"0\",\"1\"],[\"64448.6\",\"77.59\",\"0\",\"2\"],[\"64448.5\",\"3.36\",\"0\",\"2\"],[\"64448.3\",\"16.78\",\"0\",\"4\"],[\"64443.8\",\"0\",\"0\",\"0\"],[\"64442.7\",\"0.77\",\"0\",\"1\"],[\"64442.4\",\"0.01\",\"0\",\"1\"],[\"64442.1\",\"6.22\",\"0\",\"1\"],[\"64442\",\"77.63\",\"0\",\"4\"],[\"64441.3\",\"50.02\",\"0\",\"2\"],[\"64441\",\"3.11\",\"0\",\"2\"],[\"64440.7\",\"0\",\"0\",\"0\"],[\"64440.4\",\"33.84\",\"0\",\"2\"],[\"64440.2\",\"86.21\",\"0\",\"2\"],[\"64440\",\"99.43\",\"0\",\"5\"],[\"64439.8\",\"20.09\",\"0\",\"1\"],[\"64439\",\"85.44\",\"0\",\"2\"],[\"64438.6\",\"12.78\",\"0\",\"4\"],[\"64437\",\"0\",\"0\",\"0\"],[\"64436.9\",\"354.26\",\"0\",\"3\"],[\"64436.8\",\"0\",\"0\",\"0\"],[\"64436.6\",\"10.03\",\"0\",\"4\"],[\"64436.1\",\"25.65\",\"0\",\"2\"],[\"64436\",\"1.01\",\"0\",\"2\"],[\"64435.8\",\"37.33\",\"0\",\"4\"],[\"64434.9\",\"213.07\",\"0\",\"3\"],[\"64434.8\",\"287.48\",\"0\",\"3\"],[\"64434.7\",\"41.07\",\"0\",\"3\"],[\"64434.4\",\"58.25\",\"0\",\"1\"],[\"64431.9\",\"17.93\",\"0\",\"2\"],[\"64431.6\",\"496.54\",\"0\",\"2\"],[\"64415.9\",\"0\",\"0\",\"0\"],[\"64415.4\",\"0.02\",\"0\",\"2\"],[\"64405.1\",\"0.07\",\"0\",\"3\"],[\"64405\",\"13.52\",\"0\",\"15\"],[\"64404.8\",\"0.04\",\"0\",\"1\"],[\"64404.7\",\"0.77\",\"0\",\"1\"]],\"ts\":\"1782015912105\",\"checksum\":9083370,\"seqId\":325069861753,\"prevSeqId\":325069861257}]}"}
{"action": "update", "capture_sequence": 99, "channel": "books", "connection_sequence": 2, "event": null, "instId": "BTC-USDT-SWAP", "local_receive_ts": "2026-06-21T04:25:12Z", "monotonic_ns": 1643468132891635, "raw": "{\"arg\":{\"channel\":\"books\",\"instId\":\"BTC-USDT-SWAP\"},\"action\":\"update\",\"data\":[{\"asks\":[[\"64458\",\"661.9\",\"0\",\"77\"],[\"64459.1\",\"0.02\",\"0\",\"2\"],[\"64459.3\",\"1.03\",\"0\",\"4\"],[\"64459.4\",\"0\",\"0\",\"0\"],[\"64460.8\",\"0\",\"0\",\"0\"],[\"64462.1\",\"8.33\",\"0\",\"1\"],[\"64462.4\",\"1.56\",\"0\",\"1\"],[\"64463.9\",\"0\",\"0\",\"0\"],[\"64464\",\"126.85\",\"0\",\"4\"],[\"64464.1\",\"32.62\",\"0\",\"6\"],[\"64464.3\",\"72.21\",\"0\",\"1\"],[\"64464.5\",\"132.32\",\"0\",\"5\"],[\"64465.1\",\"0.02\",\"0\",\"1\"],[\"64466.9\",\"1.16\",\"0\",\"1\"],[\"64470\",\"0.2\",\"0\",\"4\"],[\"64470.5\",\"0\",\"0\",\"0\"],[\"64470.9\",\"214.66\",\"0\",\"9\"],[\"64471.2\",\"15.52\",\"0\",\"1\"],[\"64471.9\",\"0.02\",\"0\",\"2\"],[\"64472.6\",\"0.01\",\"0\",\"1\"],[\"64472.8\",\"4.02\",\"0\",\"2\"],[\"64473\",\"0.01\",\"0\",\"1\"],[\"64473.2\",\"31.06\",\"0\",\"2\"],[\"64473.8\",\"0.05\",\"0\",\"5\"],[\"64475.1\",\"0.01\",\"0\",\"1\"],[\"64475.8\",\"46.54\",\"0\",\"1\"],[\"64479.5\",\"18.63\",\"0\",\"3\"],[\"64479.6\",\"109.14\",\"0\",\"3\"],[\"64479.9\",\"96.02\",\"0\",\"5\"],[\"64482.5\",\"0.79\",\"0\",\"2\"],[\"64482.6\",\"58.53\",\"0\",\"3\"],[\"64484.3\",\"9.88\",\"0\",\"1\"],[\"64484.6\",\"1.21\",\"0\",\"2\"],[\"64484.9\",\"101.02\",\"0\",\"2\"],[\"64485\",\"41.95\",\"0\",\"2\"],[\"64486.1\",\"0.02\",\"0\",\"1\"],[\"64490.4\",\"0.02\",\"0\",\"2\"],[\"64491.1\",\"20.07\",\"0\",\"1\"],[\"64499.1\",\"0.15\",\"0\",\"3\"],[\"64499.8\",\"19.97\",\"0\",\"4\"],[\"64508.2\",\"0\",\"0\",\"0\"],[\"64508.4\",\"0\",\"0\",\"0\"],[\"64508.5\",\"0\",\"0\",\"0\"],[\"64508.6\",\"0\",\"0\",\"0\"]],\"bids\":[[\"64457.9\",\"183.49\",\"0\",\"19\"],[\"64456.7\",\"0\",\"0\",\"0\"],[\"64456.6\",\"0.07\",\"0\",\"1\"],[\"64456.5\",\"0\",\"0\",\"0\"],[\"64456.4\",\"0.01\",\"0\",\"1\"],[\"64456\",\"0.01\",\"0\",\"1\"],[\"64455.2\",\"0.05\",\"0\",\"5\"],[\"64455.1\",\"0.7\",\"0\",\"1\"],[\"64455\",\"0.01\",\"0\",\"1\"],[\"64454.9\",\"0.02\",\"0\",\"2\"],[\"64454.8\",\"11.15\",\"0\",\"3\"],[\"64454.5\",\"0.02\",\"0\",\"2\"],[\"64454.4\",\"60.97\",\"0\",\"3\"],[\"64453\",\"0.01\",\"0\",\"1\"],[\"64451.4\",\"0.42\",\"0\",\"2\"],[\"64451.2\",\"260.87\",\"0\",\"3\"],[\"64451.1\",\"0\",\"0\",\"0\"],[\"64450.9\",\"0\",\"0\",\"0\"],[\"64450.4\",\"0.31\",\"0\",\"1\"],[\"64449.9\",\"15.94\",\"0\",\"1\"],[\"64449.7\",\"46.58\",\"0\",\"2\"],[\"64449.6\",\"20.63\",\"0\",\"7\"],[\"64449.5\",\"37.24\",\"0\",\"2\"],[\"64449.4\",\"18.38\",\"0\",\"4\"],[\"64449\",\"0.03\",\"0\",\"3\"],[\"64448.9\",\"0\",\"0\",\"0\"],[\"64448\",\"274.69\",\"0\",\"7\"],[\"64446.9\",\"26.23\",\"0\",\"5\"],[\"64443.3\",\"130.09\",\"0\",\"2\"],[\"64441.7\",\"0.03\",\"0\",\"2\"],[\"64441.3\",\"50\",\"0\",\"1\"],[\"64441.2\",\"0.02\",\"0\",\"1\"],[\"64441.1\",\"47.73\",\"0\",\"3\"],[\"64440.6\",\"30.1\",\"0\",\"3\"],[\"64440.4\",\"0.01\",\"0\",\"1\"],[\"64439.8\",\"0\",\"0\",\"0\"],[\"64439.4\",\"85.44\",\"0\",\"2\"],[\"64439\",\"0.01\",\"0\",\"1\"],[\"64437.2\",\"0.03\",\"0\",\"2\"],[\"64436.9\",\"354.24\",\"0\",\"2\"],[\"64435.4\",\"262.89\",\"0\",\"4\"],[\"64435\",\"31.06\",\"0\",\"1\"],[\"64434.9\",\"15.7\",\"0\",\"2\"],[\"64434.8\",\"54.47\",\"0\",\"2\"],[\"64434.7\",\"10.01\",\"0\",\"2\"],[\"64434.4\",\"291.27\",\"0\",\"2\"],[\"64431.6\",\"496.53\",\"0\",\"1\"],[\"64431.5\",\"15.66\",\"0\",\"2\"],[\"64424.2\",\"0.02\",\"0\",\"2\"],[\"64416\",\"298.13\",\"0\",\"7\"],[\"64415.4\",\"0.01\",\"0\",\"1\"],[\"64414.9\",\"2.33\",\"0\",\"3\"],[\"64404.5\",\"0.16\",\"0\",\"2\"],[\"64404.4\",\"15.36\",\"0\",\"1\"],[\"64404.3\",\"0.04\",\"0\",\"3\"]],\"ts\":\"1782015912205\",\"checksum\":2119550935,\"seqId\":325069862008,\"prevSeqId\":325069861753}]}"}
{"action": "update", "capture_sequence": 100, "channel": "books", "connection_sequence": 2, "event": null, "instId": "BTC-USDT-SWAP", "local_receive_ts": "2026-06-21T04:25:12Z", "monotonic_ns": 1643468222932475, "raw": "{\"arg\":{\"channel\":\"books\",\"instId\":\"BTC-USDT-SWAP\"},\"action\":\"update\",\"data\":[{\"asks\":[[\"64462.1\",\"42.8\",\"0\",\"2\"],[\"64463.8\",\"6.99\",\"0\",\"3\"],[\"64463.9\",\"31.05\",\"0\",\"1\"],[\"64464.1\",\"0.8\",\"0\",\"4\"],[\"64464.4\",\"0.32\",\"0\",\"2\"],[\"64465.1\",\"0\",\"0\",\"0\"],[\"64471.9\",\"0.05\",\"0\",\"4\"],[\"64472.8\",\"4\",\"0\",\"1\"],[\"64473\",\"0\",\"0\",\"0\"],[\"64475.9\",\"0.91\",\"0\",\"2\"],[\"64476.9\",\"0.02\",\"0\",\"2\"],[\"64479.6\",\"102.93\",\"0\",\"2\"],[\"64484.9\",\"15.65\",\"0\",\"1\"],[\"64485.5\",\"85.38\",\"0\",\"2\"],[\"64485.6\",\"15.67\",\"0\",\"2\"],[\"64486.1\",\"0\",\"0\",\"0\"],[\"64489.8\",\"31.34\",\"0\",\"5\"],[\"64490.9\",\"86.21\",\"0\",\"3\"],[\"64499.7\",\"35.39\",\"0\",\"6\"],[\"64499.8\",\"19.95\",\"0\",\"3\"],[\"64508.2\",\"59.01\",\"0\",\"5\"],[\"64508.4\",\"1367.19\",\"0\",\"6\"]],\"bids\":[[\"64454.8\",\"23.62\",\"0\",\"4\"],[\"64454.6\",\"0.01\",\"0\",\"1\"],[\"64454.5\",\"46.55\",\"0\",\"2\"],[\"64454.4\",\"112.8\",\"0\",\"4\"],[\"64452.7\",\"12.72\",\"0\",\"2\"],[\"64452.2\",\"0.01\",\"0\",\"1\"],[\"64452.1\",\"31.86\",\"0\",\"5\"],[\"64451.2\",\"377.55\",\"0\",\"4\"],[\"64449.6\",\"517.16\",\"0\",\"8\"],[\"64441.4\",\"50.04\",\"0\",\"4\"],[\"64441.2\",\"0\",\"0\",\"0\"],[\"64439.8\",\"85.43\",\"0\",\"1\"],[\"64439.4\",\"0.01\",\"0\",\"1\"],[\"64439.2\",\"0.02\",\"0\",\"1\"],[\"64437.2\",\"0.01\",\"0\",\"1\"],[\"64435.9\",\"37.27\",\"0\",\"4\"],[\"64435.8\",\"0.07\",\"0\",\"1\"],[\"64435\",\"231.06\",\"0\",\"2\"],[\"64414.9\",\"2.32\",\"0\",\"2\"],[\"64414.4\",\"99.1\",\"0\",\"2\"],[\"64404.4\",\"0\",\"0\",\"0\"],[\"64404.3\",\"0\",\"0\",\"0\"]],\"ts\":\"1782015912305\",\"checksum\":2123479678,\"seqId\":325069862129,\"prevSeqId\":325069862008}]}"}
{"action": "update", "capture_sequence": 101, "channel": "books", "connection_sequence": 2, "event": null, "instId": "BTC-USDT-SWAP", "local_receive_ts": "2026-06-21T04:25:12Z", "monotonic_ns": 1643468327895907, "raw": "{\"arg\":{\"channel\":\"books\",\"instId\":\"BTC-USDT-SWAP\"},\"action\":\"update\",\"data\":[{\"asks\":[[\"64458\",\"547.47\",\"0\",\"76\"],[\"64461.9\",\"77.65\",\"0\",\"2\"],[\"64462\",\"105.71\",\"0\",\"5\"],[\"64462.1\",\"0\",\"0\",\"0\"],[\"64463.5\",\"6.22\",\"0\",\"2\"],[\"64463.7\",\"0.77\",\"0\",\"1\"],[\"64463.8\",\"0.01\",\"0\",\"1\"],[\"64463.9\",\"0\",\"0\",\"0\"],[\"64464\",\"7.83\",\"0\",\"3\"],[\"64464.1\",\"31.85\",\"0\",\"5\"],[\"64464.4\",\"0.3\",\"0\",\"1\"],[\"64465\",\"67.81\",\"0\",\"3\"],[\"64471.9\",\"0.02\",\"0\",\"2\"],[\"64473.5\",\"0\",\"0\",\"0\"],[\"64473.6\",\"52.8\",\"0\",\"5\"],[\"64474.2\",\"233.16\",\"0\",\"2\"],[\"64475.5\",\"0\",\"0\",\"0\"],[\"64475.8\",\"48.09\",\"0\",\"2\"],[\"64475.9\",\"0.9\",\"0\",\"1\"],[\"64476.9\",\"0.03\",\"0\",\"3\"],[\"64479.9\",\"62.21\",\"0\",\"4\"],[\"64481.7\",\"33.81\",\"0\",\"1\"],[\"64482.6\",\"0.32\",\"0\",\"2\"],[\"64483.8\",\"58.21\",\"0\",\"1\"],[\"64485.5\",\"0.01\",\"0\",\"1\"],[\"64485.6\",\"15.65\",\"0\",\"1\"],[\"64486.2\",\"85.54\",\"0\",\"7\"],[\"64486.4\",\"1.29\",\"0\",\"3\"],[\"64491.1\",\"0\",\"0\",\"0\"],[\"64492.2\",\"21.97\",\"0\",\"8\"],[\"64499.7\",\"35.37\",\"0\",\"5\"],[\"64500\",\"3479.33\",\"0\",\"1036\"],[\"64508.5\",\"42.46\",\"0\",\"3\"],[\"64508.6\",\"0.01\",\"0\",\"1\"]],\"bids\":[[\"64457.9\",\"195.99\",\"0\",\"15\"],[\"64455.1\",\"0.71\",\"0\",\"2\"],[\"64455\",\"60.58\",\"0\",\"3\"],[\"64454.9\",\"119.03\",\"0\",\"2\"],[\"64454.8\",\"0.02\",\"0\",\"2\"],[\"64454.6\",\"46.54\",\"0\",\"1\"],[\"64454.5\",\"0.01\",\"0\",\"1\"],[\"64453.7\",\"1.56\",\"0\",\"1\"],[\"64453.1\",\"1.57\",\"0\",\"2\"],[\"64452.4\",\"1.56\",\"0\",\"1\"],[\"64452.2\",\"0.78\",\"0\",\"2\"],[\"64452.1\",\"31.09\",\"0\",\"4\"],[\"64451.2\",\"379.11\",\"0\",\"5\"],[\"64451.1\",\"0.31\",\"0\",\"1\"],[\"64450.7\",\"1.6\",\"0\",\"3\"],[\"64450.6\",\"0\",\"0\",\"0\"],[\"64450.3\",\"42.39\",\"0\",\"2\"],[\"64449.8\",\"2.34\",\"0\",\"3\"],[\"64449.2\",\"77.59\",\"0\",\"2\"],[\"64448.6\",\"0.01\",\"0\",\"1\"],[\"64448.5\",\"1.8\",\"0\",\"1\"],[\"64448.3\",\"16.01\",\"0\",\"3\"],[\"64448\",\"275.24\",\"0\",\"11\"],[\"64442.4\",\"33.84\",\"0\",\"2\"],[\"64442.1\",\"92.42\",\"0\",\"2\"],[\"64441.8\",\"555.44\",\"0\",\"3\"],[\"64441.4\",\"50.02\",\"0\",\"3\"],[\"64441.2\",\"0.02\",\"0\",\"1\"],[\"64441.1\",\"13.9\",\"0\",\"2\"],[\"64440.7\",\"85.43\",\"0\",\"1\"],[\"64440.6\",\"10.01\",\"0\",\"2\"],[\"64440.2\",\"0.01\",\"0\",\"1\"],[\"64439.8\",\"0\",\"0\",\"0\"],[\"64439.2\",\"0\",\"0\",\"0\"],[\"64438\",\"0.03\",\"0\",\"2\"],[\"64436.4\",\"52.91\",\"0\",\"4\"],[\"64435.9\",\"0.01\",\"0\",\"1\"],[\"64435.6\",\"86.67\",\"0\",\"3\"],[\"64435\",\"464.07\",\"0\",\"3\"],[\"64434.4\",\"0\",\"0\",\"0\"],[\"64404.5\",\"0\",\"0\",\"0\"]],\"ts\":\"1782015912405\",\"checksum\":790427287,\"seqId\":325069862355,\"prevSeqId\":325069862129}]}"}
{"action": "update", "capture_sequence": 102, "channel": "books", "connection_sequence": 2, "event": null, "instId": "BTC-USDT-SWAP", "local_receive_ts": "2026-06-21T04:25:12Z", "monotonic_ns": 1643468422750604, "raw": "{\"arg\":{\"channel\":\"books\",\"instId\":\"BTC-USDT-SWAP\"},\"action\":\"update\",\"data\":[{\"asks\":[[\"64459.5\",\"119.02\",\"0\",\"1\"],[\"64461.9\",\"44.12\",\"0\",\"3\"],[\"64462\",\"0.04\",\"0\",\"4\"],[\"64463.5\",\"0.01\",\"0\",\"1\"],[\"64463.8\",\"6.22\",\"0\",\"2\"],[\"64467.4\",\"4.03\",\"0\",\"1\"],[\"64475.7\",\"498.09\",\"0\",\"3\"],[\"64475.8\",\"46.54\",\"0\",\"1\"],[\"64508.5\",\"0\",\"0\",\"0\"],[\"64508.6\",\"0\",\"0\",\"0\"]],\"bids\":[[\"64455.1\",\"25.74\",\"0\",\"3\"],[\"64455\",\"0.01\",\"0\",\"1\"],[\"64454.9\",\"0\",\"0\",\"0\"],[\"64454.7\",\"37.26\",\"0\",\"3\"],[\"64449.2\",\"0.01\",\"0\",\"1\"],[\"64448.9\",\"77.58\",\"0\",\"1\"]],\"ts\":\"1782015912505\",\"checksum\":-1142515823,\"seqId\":325069862462,\"prevSeqId\":325069862355}]}"}
{"action": "update", "capture_sequence": 103, "channel": "books", "connection_sequence": 2, "event": null, "instId": "BTC-USDT-SWAP", "local_receive_ts": "2026-06-21T04:25:12Z", "monotonic_ns": 1643468529024900, "raw": "{\"arg\":{\"channel\":\"books\",\"instId\":\"BTC-USDT-SWAP\"},\"action\":\"update\",\"data\":[{\"asks\":[[\"64458\",\"530.48\",\"0\",\"75\"],[\"64459.1\",\"0\",\"0\",\"0\"],[\"64459.2\",\"0.01\",\"0\",\"1\"],[\"64459.5\",\"0.02\",\"0\",\"2\"],[\"64459.6\",\"165.54\",\"0\",\"3\"],[\"64461.2\",\"15.84\",\"0\",\"4\"],[\"64461.9\",\"0.15\",\"0\",\"1\"],[\"64463.7\",\"0\",\"0\",\"0\"],[\"64464\",\"9.37\",\"0\",\"5\"],[\"64464.1\",\"31.08\",\"0\",\"4\"],[\"64464.2\",\"209.9\",\"0\",\"2\"],[\"64464.5\",\"0.32\",\"0\",\"3\"],[\"64465\",\"67.79\",\"0\",\"2\"],[\"64465.8\",\"64.04\",\"0\",\"3\"],[\"64469.5\",\"4.77\",\"0\",\"1\"],[\"64470.9\",\"346.66\",\"0\",\"11\"],[\"64471.2\",\"0\",\"0\",\"0\"],[\"64471.7\",\"2.56\",\"0\",\"1\"],[\"64472\",\"17.59\",\"0\",\"6\"],[\"64473.2\",\"0.01\",\"0\",\"1\"],[\"64473.6\",\"52.78\",\"0\",\"4\"],[\"64473.8\",\"0.07\",\"0\",\"6\"],[\"64474.1\",\"31.05\",\"0\",\"1\"],[\"64474.2\",\"0.29\",\"0\",\"1\"],[\"64474.8\",\"232.98\",\"0\",\"2\"],[\"64475.7\",\"496.54\",\"0\",\"2\"],[\"64477.7\",\"1.55\",\"0\",\"1\"],[\"64481.7\",\"0\",\"0\",\"0\"],[\"64482.5\",\"0.02\",\"0\",\"1\"],[\"64482.6\",\"0.01\",\"0\",\"1\"],[\"64483.7\",\"0.78\",\"0\",\"2\"],[\"64483.8\",\"34.11\",\"0\",\"2\"],[\"64486.2\",\"58.37\",\"0\",\"7\"],[\"64486.4\",\"1.27\",\"0\",\"2\"],[\"64486.9\",\"0.14\",\"0\",\"3\"],[\"64487.6\",\"386.82\",\"0\",\"2\"],[\"64490.9\",\"0.07\",\"0\",\"2\"],[\"64492.2\",\"1.9\",\"0\",\"7\"],[\"64493.1\",\"117.89\",\"0\",\"6\"],[\"64494.1\",\"20.07\",\"0\",\"1\"]],\"bids\":[[\"64457.9\",\"456.84\",\"0\",\"18\"],[\"64456.6\",\"0.08\",\"0\",\"2\"],[\"64456.5\",\"0.6\",\"0\",\"1\"],[\"64456\",\"0.02\",\"0\",\"2\"],[\"64455.9\",\"25.06\",\"0\",\"3\"],[\"64455.8\",\"0.01\",\"0\",\"1\"],[\"64455.2\",\"0.04\",\"0\",\"4\"],[\"64455.1\",\"0\",\"0\",\"0\"],[\"64453\",\"0.32\",\"0\",\"2\"],[\"64451.7\",\"307.29\",\"0\",\"6\"],[\"64451.3\",\"13.68\",\"0\",\"7\"],[\"64451.1\",\"0\",\"0\",\"0\"],[\"64450.8\",\"77.88\",\"0\",\"2\"],[\"64449.6\",\"517.17\",\"0\",\"9\"],[\"64449.5\",\"37.23\",\"0\",\"1\"],[\"64449.4\",\"18.07\",\"0\",\"3\"],[\"64448.9\",\"2.56\",\"0\",\"1\"],[\"64446.9\",\"23.7\",\"0\",\"4\"],[\"64445\",\"170.28\",\"0\",\"8\"],[\"64444.5\",\"34.59\",\"0\",\"2\"],[\"64443.5\",\"106.29\",\"0\",\"2\"],[\"64443.1\",\"3.2\",\"0\",\"2\"],[\"64442.7\",\"0\",\"0\",\"0\"],[\"64442.4\",\"85.44\",\"0\",\"2\"],[\"64442.1\",\"6.22\",\"0\",\"1\"],[\"64441.8\",\"535.35\",\"0\",\"2\"],[\"64441.7\",\"0.02\",\"0\",\"1\"],[\"64440.7\",\"0\",\"0\",\"0\"],[\"64438.2\",\"58.26\",\"0\",\"2\"],[\"64437.1\",\"37.56\",\"0\",\"5\"],[\"64436.4\",\"15.65\",\"0\",\"1\"],[\"64436.1\",\"56.71\",\"0\",\"3\"],[\"64435.7\",\"233.01\",\"0\",\"1\"],[\"64435.6\",\"28.42\",\"0\",\"2\"],[\"64435\",\"200\",\"0\",\"1\"],[\"64424.2\",\"0.01\",\"0\",\"1\"],[\"64416\",\"298.12\",\"0\",\"6\"],[\"64415.2\",\"0.02\",\"0\",\"2\"],[\"64414.4\",\"99.09\",\"0\",\"1\"],[\"64404.8\",\"0\",\"0\",\"0\"],[\"64404.7\",\"0\",\"0\",\"0\"]],\"ts\":\"1782015912605\",\"checksum\":-1658197426,\"seqId\":325069862792,\"prevSeqId\":325069862462}]}"}
{"action": "update", "capture_sequence": 104, "channel": "books", "connection_sequence": 2, "event": null, "instId": "BTC-USDT-SWAP", "local_receive_ts": "2026-06-21T04:25:12Z", "monotonic_ns": 1643468628174013, "raw": "{\"arg\":{\"channel\":\"books\",\"instId\":\"BTC-USDT-SWAP\"},\"action\":\"update\",\"data\":[{\"asks\":[[\"64458\",\"529.88\",\"0\",\"74\"],[\"64458.2\",\"0\",\"0\",\"0\"],[\"64458.3\",\"0.02\",\"0\",\"2\"],[\"64459.2\",\"0.02\",\"0\",\"2\"],[\"64459.3\",\"16.56\",\"0\",\"5\"],[\"64459.5\",\"0.01\",\"0\",\"1\"],[\"64459.6\",\"0.6\",\"0\",\"1\"],[\"64459.7\",\"0\",\"0\",\"0\"],[\"64460.2\",\"0.8\",\"0\",\"4\"],[\"64461.2\",\"55.68\",\"0\",\"5\"],[\"64461.3\",\"150\",\"0\",\"1\"],[\"64465.8\",\"64.02\",\"0\",\"2\"],[\"64466.7\",\"0.03\",\"0\",\"2\"],[\"64473.6\",\"52.77\",\"0\",\"3\"],[\"64473.8\",\"0.05\",\"0\",\"5\"],[\"64474.4\",\"0.05\",\"0\",\"4\"],[\"64475.1\",\"0\",\"0\",\"0\"],[\"64475.8\",\"46.55\",\"0\",\"2\"],[\"64476.3\",\"0.15\",\"0\",\"1\"],[\"64476.4\",\"0\",\"0\",\"0\"],[\"64476.9\",\"0.02\",\"0\",\"2\"],[\"64479.7\",\"0.01\",\"0\",\"1\"],[\"64479.9\",\"62.2\",\"0\",\"3\"],[\"64481.1\",\"62.31\",\"0\",\"3\"],[\"64486.9\",\"0.12\",\"0\",\"2\"],[\"64487.7\",\"130.36\",\"0\",\"5\"],[\"64508.5\",\"42.46\",\"0\",\"3\"],[\"64508.6\",\"0.01\",\"0\",\"1\"]],\"bids\":[[\"64457.9\",\"476.94\",\"0\",\"21\"],[\"64456\",\"0.03\",\"0\",\"3\"],[\"64455.9\",\"25.05\",\"0\",\"2\"],[\"64453\",\"0\",\"0\",\"0\"],[\"64452.9\",\"0.01\",\"0\",\"1\"],[\"64452.5\",\"0.31\",\"0\",\"1\"],[\"64450.7\",\"1.61\",\"0\",\"4\"],[\"64449.6\",\"517.16\",\"0\",\"8\"],[\"64443.3\",\"130.12\",\"0\",\"4\"],[\"64443.1\",\"0\",\"0\",\"0\"],[\"64441.2\",\"0\",\"0\",\"0\"],[\"64441\",\"3.13\",\"0\",\"3\"],[\"64438.7\",\"4.99\",\"0\",\"2\"],[\"64438\",\"0.01\",\"0\",\"1\"],[\"64436.8\",\"0.02\",\"0\",\"1\"],[\"64436.3\",\"117.35\",\"0\",\"5\"],[\"64436\",\"201.01\",\"0\",\"3\"],[\"64435.4\",\"262.87\",\"0\",\"3\"],[\"64435\",\"0\",\"0\",\"0\"],[\"64431.6\",\"496.54\",\"0\",\"2\"],[\"64431.5\",\"15.65\",\"0\",\"1\"],[\"64404.8\",\"0.04\",\"0\",\"1\"],[\"64404.7\",\"0.77\",\"0\",\"1\"]],\"ts\":\"1782015912705\",\"checksum\":342094251,\"seqId\":325069862922,\"prevSeqId\":325069862792}]}"}
{"action": "update", "capture_sequence": 105, "channel": "books", "connection_sequence": 2, "event": null, "instId": "BTC-USDT-SWAP", "local_receive_ts": "2026-06-21T04:25:12Z", "monotonic_ns": 1643468722689787, "raw": "{\"arg\":{\"channel\":\"books\",\"instId\":\"BTC-USDT-SWAP\"},\"action\":\"update\",\"data\":[{\"asks\":[[\"64477.2\",\"1.55\",\"0\",\"1\"],[\"64477.7\",\"0\",\"0\",\"0\"]],\"bids\":[[\"64450.8\",\"0.31\",\"0\",\"1\"],[\"64450.5\",\"5.67\",\"0\",\"4\"],[\"64450.4\",\"77.88\",\"0\",\"2\"],[\"64449.8\",\"1.57\",\"0\",\"2\"],[\"64443.1\",\"3.15\",\"0\",\"1\"],[\"64404.7\",\"0\",\"0\",\"0\"]],\"ts\":\"1782015912805\",\"checksum\":342094251,\"seqId\":325069863008,\"prevSeqId\":325069862922}]}"}
{"action": "update", "capture_sequence": 106, "channel": "books", "connection_sequence": 2, "event": null, "instId": "BTC-USDT-SWAP", "local_receive_ts": "2026-06-21T04:25:13Z", "monotonic_ns": 1643468822795145, "raw": "{\"arg\":{\"channel\":\"books\",\"instId\":\"BTC-USDT-SWAP\"},\"action\":\"update\",\"data\":[{\"asks\":[[\"64460.3\",\"0\",\"0\",\"0\"],[\"64474.8\",\"0.11\",\"0\",\"1\"],[\"64475.6\",\"233.26\",\"0\",\"3\"],[\"64486.2\",\"0.17\",\"0\",\"6\"],[\"64487.4\",\"58.69\",\"0\",\"6\"],[\"64508.7\",\"42.88\",\"0\",\"9\"]],\"bids\":[[\"64457.9\",\"466.94\",\"0\",\"20\"],[\"64439.4\",\"58.26\",\"0\",\"2\"],[\"64438.2\",\"0.01\",\"0\",\"1\"],[\"64436.2\",\"233.01\",\"0\",\"1\"],[\"64435.7\",\"0\",\"0\",\"0\"]],\"ts\":\"1782015912905\",\"checksum\":-281506159,\"seqId\":325069863097,\"prevSeqId\":325069863008}]}"}
{"action": "update", "capture_sequence": 107, "channel": "books", "connection_sequence": 2, "event": null, "instId": "BTC-USDT-SWAP", "local_receive_ts": "2026-06-21T04:25:13Z", "monotonic_ns": 1643468923049287, "raw": "{\"arg\":{\"channel\":\"books\",\"instId\":\"BTC-USDT-SWAP\"},\"action\":\"update\",\"data\":[{\"asks\":[[\"64460\",\"1.57\",\"0\",\"2\"],[\"64460.2\",\"0.79\",\"0\",\"3\"],[\"64460.5\",\"1.56\",\"0\",\"1\"],[\"64460.7\",\"0\",\"0\",\"0\"],[\"64461.1\",\"0.02\",\"0\",\"2\"],[\"64463.9\",\"1.56\",\"0\",\"1\"],[\"64483.8\",\"33.8\",\"0\",\"1\"],[\"64484.2\",\"15.96\",\"0\",\"2\"],[\"64508.7\",\"0\",\"0\",\"0\"]],\"bids\":[[\"64457.9\",\"468.66\",\"0\",\"22\"],[\"64455.9\",\"45.02\",\"0\",\"3\"],[\"64454.9\",\"0.01\",\"0\",\"1\"],[\"64454.8\",\"77.6\",\"0\",\"3\"],[\"64454.7\",\"37.25\",\"0\",\"2\"],[\"64452.5\",\"0\",\"0\",\"0\"],[\"64452.3\",\"0.32\",\"0\",\"2\"],[\"64451.6\",\"0.31\",\"0\",\"1\"],[\"64450.8\",\"0\",\"0\",\"0\"],[\"64438.6\",\"50.04\",\"0\",\"7\"],[\"64437.1\",\"0.3\",\"0\",\"2\"]],\"ts\":\"1782015913005\",\"checksum\":-1310090584,\"seqId\":325069863247,\"prevSeqId\":325069863097}]}"}
{"action": "update", "capture_sequence": 108, "channel": "books", "connection_sequence": 2, "event": null, "instId": "BTC-USDT-SWAP", "local_receive_ts": "2026-06-21T04:25:13Z", "monotonic_ns": 1643469022852305, "raw": "{\"arg\":{\"channel\":\"books\",\"instId\":\"BTC-USDT-SWAP\"},\"action\":\"update\",\"data\":[{\"asks\":[[\"64458\",\"529.87\",\"0\",\"73\"],[\"64459.6\",\"0.62\",\"0\",\"3\"],[\"64460\",\"0.01\",\"0\",\"1\"],[\"64460.2\",\"2.34\",\"0\",\"3\"],[\"64460.4\",\"0.01\",\"0\",\"1\"],[\"64460.5\",\"0\",\"0\",\"0\"],[\"64460.6\",\"0\",\"0\",\"0\"],[\"64460.7\",\"1.56\",\"0\",\"1\"],[\"64464.4\",\"1.86\",\"0\",\"2\"],[\"64498\",\"497.3\",\"0\",\"4\"]],\"bids\":[[\"64457.9\",\"467.1\",\"0\",\"21\"],[\"64457.7\",\"0.33\",\"0\",\"2\"],[\"64457.6\",\"2.03\",\"0\",\"3\"],[\"64457.2\",\"0.01\",\"0\",\"1\"],[\"64457.1\",\"1.88\",\"0\",\"2\"],[\"64456\",\"0.04\",\"0\",\"4\"],[\"64455.8\",\"0\",\"0\",\"0\"],[\"64454.8\",\"77.59\",\"0\",\"2\"],[\"64438.7\",\"42.25\",\"0\",\"5\"],[\"64438.6\",\"12.78\",\"0\",\"4\"]],\"ts\":\"1782015913105\",\"checksum\":415897378,\"seqId\":325069863430,\"prevSeqId\":325069863247}]}"}
{"action": null, "capture_sequence": 109, "channel": "trades", "connection_sequence": 2, "event": null, "instId": "BTC-USDT-SWAP", "local_receive_ts": "2026-06-21T04:25:13Z", "monotonic_ns": 1643469087044908, "raw": "{\"arg\":{\"channel\":\"trades\",\"instId\":\"BTC-USDT-SWAP\"},\"data\":[{\"instId\":\"BTC-USDT-SWAP\",\"tradeId\":\"2718748854\",\"px\":\"64457.9\",\"sz\":\"6.52\",\"side\":\"sell\",\"ts\":\"1782015913169\",\"count\":\"2\",\"source\":\"0\",\"seqId\":325069863534}]}"}
{"action": "update", "capture_sequence": 110, "channel": "books", "connection_sequence": 2, "event": null, "instId": "BTC-USDT-SWAP", "local_receive_ts": "2026-06-21T04:25:13Z", "monotonic_ns": 1643469123443542, "raw": "{\"arg\":{\"channel\":\"books\",\"instId\":\"BTC-USDT-SWAP\"},\"action\":\"update\",\"data\":[{\"asks\":[[\"64458\",\"529.84\",\"0\",\"73\"],[\"64458.6\",\"0.01\",\"0\",\"1\"],[\"64458.8\",\"1.56\",\"0\",\"1\"],[\"64459.1\",\"0.01\",\"0\",\"1\"],[\"64459.2\",\"6.32\",\"0\",\"2\"],[\"64459.5\",\"1.57\",\"0\",\"2\"],[\"64459.6\",\"0.61\",\"0\",\"2\"],[\"64464.4\",\"0.3\",\"0\",\"1\"],[\"64481.7\",\"33.8\",\"0\",\"1\"],[\"64483.7\",\"0.01\",\"0\",\"1\"],[\"64483.8\",\"0\",\"0\",\"0\"],[\"64484.1\",\"0.79\",\"0\",\"2\"],[\"64484.2\",\"15.65\",\"0\",\"1\"],[\"64484.6\",\"1.52\",\"0\",\"3\"],[\"64486.7\",\"85.38\",\"0\",\"2\"],[\"64487.6\",\"301.45\",\"0\",\"1\"],[\"64492.5\",\"86.2\",\"0\",\"5\"],[\"64492.8\",\"20.2\",\"0\",\"8\"],[\"64493.1\",\"31.76\",\"0\",\"5\"],[\"64494.1\",\"0\",\"0\",\"0\"],[\"64500\",\"3472.81\",\"0\",\"1035\"],[\"64508.5\",\"0\",\"0\",\"0\"],[\"64508.6\",\"0\",\"0\",\"0\"]],\"bids\":[[\"64457.9\",\"460.58\",\"0\",\"20\"],[\"64457.7\",\"0.32\",\"0\",\"1\"],[\"64457.6\",\"0.47\",\"0\",\"2\"],[\"64457.5\",\"0.01\",\"0\",\"1\"],[\"64457.4\",\"1.56\",\"0\",\"1\"],[\"64457.2\",\"0\",\"0\",\"0\"],[\"64457.1\",\"0.32\",\"0\",\"1\"],[\"64456.7\",\"0.01\",\"0\",\"1\"],[\"64456.6\",\"1.64\",\"0\",\"3\"],[\"64452.1\",\"31.4\",\"0\",\"5\"],[\"64451.6\",\"0\",\"0\",\"0\"],[\"64445.2\",\"0.77\",\"0\",\"1\"],[\"64445\",\"168.98\",\"0\",\"7\"],[\"64444.5\",\"0\",\"0\",\"0\"],[\"64443.5\",\"0\",\"0\",\"0\"],[\"64442.7\",\"33.83\",\"0\",\"1\"],[\"64442.5\",\"86.2\",\"0\",\"1\"],[\"64442.4\",\"20.1\",\"0\",\"2\"],[\"64441.4\",\"135.45\",\"0\",\"4\"],[\"64434.8\",\"148.64\",\"0\",\"3\"],[\"64405\",\"0\",\"0\",\"0\"],[\"64404.8\",\"0\",\"0\",\"0\"]],\"ts\":\"1782015913205\",\"checksum\":-1977442053,\"seqId\":325069863623,\"prevSeqId\":325069863430}]}"}
{"action": "update", "capture_sequence": 111, "channel": "books", "connection_sequence": 2, "event": null, "instId": "BTC-USDT-SWAP", "local_receive_ts": "2026-06-21T04:25:13Z", "monotonic_ns": 1643469224576193, "raw": "{\"arg\":{\"channel\":\"books\",\"instId\":\"BTC-USDT-SWAP\"},\"action\":\"update\",\"data\":[{\"asks\":[[\"64458.6\",\"0\",\"0\",\"0\"],[\"64458.8\",\"0\",\"0\",\"0\"],[\"64459.2\",\"6.33\",\"0\",\"3\"],[\"64459.5\",\"0.01\",\"0\",\"1\"],[\"64460.2\",\"0.78\",\"0\",\"2\"],[\"64460.7\",\"0\",\"0\",\"0\"],[\"64461.2\",\"54.12\",\"0\",\"4\"],[\"64464.4\",\"1.86\",\"0\",\"2\"],[\"64464.9\",\"67.2\",\"0\",\"2\"],[\"64468.8\",\"576.01\",\"0\",\"8\"],[\"64483.7\",\"0.78\",\"0\",\"2\"],[\"64484.1\",\"0.02\",\"0\",\"1\"],[\"64484.2\",\"15.96\",\"0\",\"2\"],[\"64484.6\",\"1.21\",\"0\",\"2\"],[\"64486.7\",\"0.01\",\"0\",\"1\"],[\"64487.5\",\"128.84\",\"0\",\"7\"],[\"64492.8\",\"0.13\",\"0\",\"7\"],[\"64493.7\",\"379.36\",\"0\",\"6\"],[\"64508.5\",\"42.46\",\"0\",\"3\"],[\"64508.6\",\"0.01\",\"0\",\"1\"],[\"64508.7\",\"42.88\",\"0\",\"9\"]],\"bids\":[[\"64452.1\",\"31.09\",\"0\",\"4\"],[\"64451.6\",\"0.31\",\"0\",\"1\"],[\"64445.2\",\"0\",\"0\",\"0\"],[\"64444.6\",\"0.77\",\"0\",\"1\"],[\"64443.3\",\"150.21\",\"0\",\"5\"],[\"64442.4\",\"0.01\",\"0\",\"1\"],[\"64442.2\",\"85.43\",\"0\",\"1\"],[\"64441.4\",\"50.02\",\"0\",\"3\"],[\"64405.2\",\"0\",\"0\",\"0\"],[\"64405.1\",\"0\",\"0\",\"0\"]],\"ts\":\"1782015913305\",\"checksum\":-876231640,\"seqId\":325069863731,\"prevSeqId\":325069863623}]}"}
