{"action": "snapshot", "capture_sequence": 245, "channel": "books", "connection_sequence": 4, "event": null, "instId": "BTC-USDT-SWAP", "local_receive_ts": "2026-06-21T04:25:27Z", "monotonic_ns": 1643483030661544, "raw": "{\"arg\":{\"channel\":\"books\",\"instId\":\"BTC-USDT-SWAP\"},\"action\":\"snapshot\",\"data\":[{\"asks\":[[\"64458\",\"486.12\",\"0\",\"64\"],[\"64458.1\",\"0.03\",\"0\",\"3\"],[\"64458.2\",\"0.01\",\"0\",\"1\"],[\"64458.3\",\"7.54\",\"0\",\"4\"],[\"64458.4\",\"0.01\",\"0\",\"1\"],[\"64458.5\",\"6.56\",\"0\",\"2\"],[\"64458.6\",\"0.02\",\"0\",\"2\"],[\"64458.7\",\"15.53\",\"0\",\"1\"],[\"64459\",\"1.56\",\"0\",\"1\"],[\"64459.2\",\"0.01\",\"0\",\"1\"],[\"64459.3\",\"1.03\",\"0\",\"4\"],[\"64459.5\",\"1.57\",\"0\",\"2\"],[\"64459.6\",\"0.6\",\"0\",\"1\"],[\"64460\",\"1.57\",\"0\",\"2\"],[\"64460.1\",\"0.02\",\"0\",\"2\"],[\"64460.2\",\"0.78\",\"0\",\"2\"],[\"64460.4\",\"1.56\",\"0\",\"1\"],[\"64460.7\",\"0.01\",\"0\",\"1\"],[\"64460.8\",\"50.68\",\"0\",\"2\"],[\"64460.9\",\"1.56\",\"0\",\"1\"],[\"64461\",\"0.01\",\"0\",\"1\"],[\"64461.1\",\"0.01\",\"0\",\"1\"],[\"64461.4\",\"1.59\",\"0\",\"4\"],[\"64461.6\",\"0.01\",\"0\",\"1\"],[\"64461.7\",\"150\",\"0\",\"1\"],[\"64461.9\",\"0.15\",\"0\",\"1\"],[\"64462\",\"0.04\",\"0\",\"4\"],[\"64462.6\",\"0.01\",\"0\",\"1\"],[\"64462.9\",\"0.01\",\"0\",\"1\"],[\"64463.1\",\"6.22\",\"0\",\"2\"],[\"64463.2\",\"0.01\",\"0\",\"1\"],[\"64463.3\",\"0.9\",\"0\",\"1\"],[\"64463.5\",\"0.02\",\"0\",\"2\"],[\"64463.6\",\"14.45\",\"0\",\"1\"],[\"64463.8\",\"0.01\",\"0\",\"1\"],[\"64464\",\"0.79\",\"0\",\"3\"],[\"64464.1\",\"31.85\",\"0\",\"5\"],[\"64464.2\",\"209.9\",\"0\",\"2\"],[\"64464.3\",\"72.21\",\"0\",\"1\"],[\"64464.4\",\"0.3\",\"0\",\"1\"],[\"64464.5\",\"1.32\",\"0\",\"4\"],[\"64464.6\",\"0.01\",\"0\",\"1\"],[\"64464.7\",\"0.01\",\"0\",\"1\"],[\"64464.9\",\"65.64\",\"0\",\"1\"],[\"64465\",\"67.79\",\"0\",\"2\"],[\"64465.1\",\"1\",\"0\",\"1\"],[\"64465.2\",\"77.75\",\"0\",\"2\"],[\"64465.5\",\"1.01\",\"0\",\"2\"],[\"64465.6\",\"0.01\",\"0\",\"1\"],[\"64465.7\",\"63.7\",\"0\",\"1\"],[\"64465.8\",\"65.22\",\"0\",\"3\"],[\"64466\",\"0.01\",\"0\",\"1\"],[\"64466.1\",\"1.21\",\"0\",\"2\"],[\"64466.3\",\"46.54\",\"0\",\"1\"],[\"64466.4\",\"72.06\",\"0\",\"4\"],[\"64466.6\",\"0.01\",\"0\",\"1\"],[\"64466.7\",\"0.01\",\"0\",\"1\"],[\"64466.9\",\"2.36\",\"0\",\"2\"],[\"64467\",\"63.88\",\"0\",\"2\"],[\"64467.1\",\"0.02\",\"0\",\"1\"],[\"64467.2\",\"1.2\",\"0\",\"1\"],[\"64467.3\",\"0.01\",\"0\",\"1\"],[\"64467.6\",\"1.6\",\"0\",\"4\"],[\"64467.7\",\"147.75\",\"0\",\"3\"],[\"64467.8\",\"91.8\",\"0\",\"2\"],[\"64467.9\",\"11.24\",\"0\",\"3\"],[\"64468\",\"0.02\",\"0\",\"2\"],[\"64468.2\",\"15.88\",\"0\",\"1\"],[\"64468.3\",\"0.3\",\"0\",\"2\"],[\"64468.4\",\"69.47\",\"0\",\"1\"],[\"64468.5\",\"46.54\",\"0\",\"1\"],[\"64468.6\",\"1.74\",\"0\",\"1\"],[\"64468.7\",\"66.46\",\"0\",\"2\"],[\"64468.8\",\"66.01\",\"0\",\"6\"],[\"64468.9\",\"0.12\",\"0\",\"1\"],[\"64469\",\"22\",\"0\",\"1\"],[\"64469.1\",\"0.01\",\"0\",\"1\"],[\"64469.3\",\"4\",\"0\",\"1\"],[\"64469.4\",\"0.01\",\"0\",\"1\"],[\"64469.5\",\"4.77\",\"0\",\"1\"],[\"64469.6\",\"0.01\",\"0\",\"1\"],[\"64469.7\",\"37.75\",\"0\",\"3\"],[\"64469.8\",\"15.92\",\"0\",\"1\"],[\"64469.9\",\"0.01\",\"0\",\"1\"],[\"64470\",\"0.2\",\"0\",\"4\"],[\"64470.1\",\"0.01\",\"0\",\"1\"],[\"64470.2\",\"0.02\",\"0\",\"1\"],[\"64470.3\",\"0.01\",\"0\",\"1\"],[\"64470.4\",\"0.01\",\"0\",\"1\"],[\"64470.6\",\"372.95\",\"0\",\"2\"],[\"64470.7\",\"46.56\",\"0\",\"3\"],[\"64470.8\",\"0.77\",\"0\",\"1\"],[\"64470.9\",\"346.66\",\"0\",\"11\"],[\"64471\",\"0.54\",\"0\",\"3\"],[\"64471.3\",\"99.34\",\"0\",\"2\"],[\"64471.4\",\"15.97\",\"0\",\"1\"],[\"64471.6\",\"0.04\",\"0\",\"2\"],[\"64471.7\",\"2.56\",\"0\",\"1\"],[\"64471.8\",\"496.53\",\"0\",\"1\"],[\"64471.9\",\"0.02\",\"0\",\"2\"],[\"64472\",\"2.07\",\"0\",\"5\"],[\"64472.1\",\"11.42\",\"0\",\"1\"],[\"64472.2\",\"0.01\",\"0\",\"1\"],[\"64472.6\",\"0.01\",\"0\",\"1\"],[\"64472.7\",\"24\",\"0\",\"2\"],[\"64472.8\",\"4\",\"0\",\"1\"],[\"64472.9\",\"12.05\",\"0\",\"4\"],[\"64473.2\",\"0.01\",\"0\",\"1\"],[\"64473.3\",\"1.24\",\"0\",\"1\"],[\"64473.5\",\"15.52\",\"0\",\"1\"],[\"64473.6\",\"52.77\",\"0\",\"3\"],[\"64473.7\",\"275.99\",\"0\",\"2\"],[\"64473.8\",\"0.05\",\"0\",\"5\"],[\"64474\",\"0.03\",\"0\",\"3\"],[\"64474.2\",\"0.29\",\"0\",\"1\"],[\"64474.3\",\"18.95\",\"0\",\"1\"],[\"64474.4\",\"0.02\",\"0\",\"2\"],[\"64474.5\",\"0.03\",\"0\",\"1\"],[\"64474.7\",\"8.01\",\"0\",\"2\"],[\"64474.8\",\"0.11\",\"0\",\"1\"],[\"64474.9\",\"37.23\",\"0\",\"1\"],[\"64475\",\"263.06\",\"0\",\"9\"],[\"64475.3\",\"0.01\",\"0\",\"1\"],[\"64475.5\",\"31.04\",\"0\",\"1\"],[\"64475.6\",\"0.39\",\"0\",\"2\"],[\"64475.7\",\"496.54\",\"0\",\"2\"],[\"64475.8\",\"46.58\",\"0\",\"4\"],[\"64475.9\",\"0.9\",\"0\",\"1\"],[\"64476\",\"0.03\",\"0\",\"3\"],[\"64476.2\",\"0.02\",\"0\",\"2\"],[\"64476.6\",\"0.15\",\"0\",\"1\"],[\"64476.7\",\"232.86\",\"0\",\"1\"],[\"64476.8\",\"318.09\",\"0\",\"4\"],[\"64476.9\",\"0.02\",\"0\",\"2\"],[\"64477\",\"2.62\",\"0\",\"2\"],[\"64477.3\",\"1.01\",\"0\",\"2\"],[\"64477.4\",\"0.1\",\"0\",\"4\"],[\"64477.5\",\"14.77\",\"0\",\"2\"],[\"64477.6\",\"0.07\",\"0\",\"1\"],[\"64477.8\",\"46.54\",\"0\",\"1\"],[\"64478\",\"0.02\",\"0\",\"2\"],[\"64478.3\",\"0.01\",\"0\",\"1\"],[\"64478.5\",\"1.55\",\"0\",\"1\"],[\"64478.6\",\"3.11\",\"0\",\"2\"],[\"64478.8\",\"0.01\",\"0\",\"1\"],[\"64479\",\"0.01\",\"0\",\"1\"],[\"64479.2\",\"15.81\",\"0\",\"4\"],[\"64479.5\",\"18.63\",\"0\",\"3\"],[\"64479.6\",\"102.93\",\"0\",\"2\"],[\"64479.8\",\"496.54\",\"0\",\"2\"],[\"64479.9\",\"62.2\",\"0\",\"3\"],[\"64480\",\"55.83\",\"0\",\"45\"],[\"64480.1\",\"0.02\",\"0\",\"2\"],[\"64480.2\",\"37.23\",\"0\",\"1\"],[\"64480.4\",\"0.01\",\"0\",\"1\"],[\"64480.8\",\"6.22\",\"0\",\"1\"],[\"64481\",\"171.94\",\"0\",\"5\"],[\"64481.1\",\"62.34\",\"0\",\"3\"],[\"64481.2\",\"0.68\",\"0\",\"1\"],[\"64481.6\",\"0.01\",\"0\",\"1\"],[\"64481.8\",\"0.04\",\"0\",\"3\"],[\"64481.9\",\"0.01\",\"0\",\"1\"],[\"64482\",\"0.04\",\"0\",\"2\"],[\"64482.1\",\"0.01\",\"0\",\"1\"],[\"64482.5\",\"0.02\",\"0\",\"1\"],[\"64482.6\",\"0.01\",\"0\",\"1\"],[\"64482.7\",\"3.91\",\"0\",\"2\"],[\"64482.8\",\"0.41\",\"0\",\"2\"],[\"64482.9\",\"110.9\",\"0\",\"2\"],[\"64483\",\"200\",\"0\",\"1\"],[\"64483.1\",\"100.3\",\"0\",\"4\"],[\"64483.2\",\"114.69\",\"0\",\"3\"],[\"64483.3\",\"33.86\",\"0\",\"4\"],[\"64483.4\",\"312.16\",\"0\",\"1\"],[\"64483.7\",\"0.01\",\"0\",\"1\"],[\"64483.8\",\"0.77\",\"0\",\"1\"],[\"64483.9\",\"11.07\",\"0\",\"2\"],[\"64484\",\"0.02\",\"0\",\"2\"],[\"64484.1\",\"0.02\",\"0\",\"1\"],[\"64484.2\",\"15.65\",\"0\",\"1\"],[\"64484.3\",\"0.31\",\"0\",\"1\"],[\"64484.4\",\"16.25\",\"0\",\"2\"],[\"64484.5\",\"0.06\",\"0\",\"3\"],[\"64484.6\",\"1.21\",\"0\",\"2\"],[\"64484.7\",\"28.42\",\"0\",\"2\"],[\"64484.8\",\"496.53\",\"0\",\"1\"],[\"64484.9\",\"15.65\",\"0\",\"1\"],[\"64485\",\"41.95\",\"0\",\"2\"],[\"64485.1\",\"38.83\",\"0\",\"2\"],[\"64485.2\",\"0.01\",\"0\",\"1\"],[\"64485.5\",\"0.01\",\"0\",\"1\"],[\"64485.6\",\"15.65\",\"0\",\"1\"],[\"64485.7\",\"0.35\",\"0\",\"5\"],[\"64485.8\",\"0.4\",\"0\",\"2\"],[\"64485.9\",\"5.42\",\"0\",\"1\"],[\"64486\",\"101.09\",\"0\",\"7\"],[\"64486.2\",\"0.17\",\"0\",\"6\"],[\"64486.3\",\"179.9\",\"0\",\"4\"],[\"64486.4\",\"1.27\",\"0\",\"2\"],[\"64486.5\",\"15.65\",\"0\",\"1\"],[\"64486.6\",\"47.53\",\"0\",\"2\"],[\"64486.7\",\"0.01\",\"0\",\"1\"],[\"64486.8\",\"37.42\",\"0\",\"4\"],[\"64486.9\",\"0.12\",\"0\",\"2\"],[\"64487\",\"51.82\",\"0\",\"5\"],[\"64487.1\",\"0.53\",\"0\",\"4\"],[\"64487.2\",\"0.03\",\"0\",\"2\"],[\"64487.3\",\"0.04\",\"0\",\"2\"],[\"64487.4\",\"58.69\",\"0\",\"6\"],[\"64487.5\",\"43.47\",\"0\",\"6\"],[\"64487.6\",\"301.45\",\"0\",\"1\"],[\"64487.7\",\"130.34\",\"0\",\"4\"],[\"64487.8\",\"0.09\",\"0\",\"3\"],[\"64487.9\",\"0.01\",\"0\",\"1\"],[\"64488\",\"57.87\",\"0\",\"27\"],[\"64488.1\",\"0.67\",\"0\",\"2\"],[\"64488.2\",\"3.96\",\"0\",\"2\"],[\"64488.3\",\"38.84\",\"0\",\"2\"],[\"64488.4\",\"21.02\",\"0\",\"6\"],[\"64488.6\",\"85.38\",\"0\",\"3\"],[\"64488.7\",\"496.58\",\"0\",\"3\"],[\"64488.8\",\"50.02\",\"0\",\"2\"],[\"64488.9\",\"0.32\",\"0\",\"5\"],[\"64489\",\"57.94\",\"0\",\"9\"],[\"64489.1\",\"26.75\",\"0\",\"5\"],[\"64489.2\",\"69.9\",\"0\",\"1\"],[\"64489.3\",\"23.26\",\"0\",\"6\"],[\"64489.4\",\"2.91\",\"0\",\"4\"],[\"64489.5\",\"0.01\",\"0\",\"1\"],[\"64489.6\",\"0.13\",\"0\",\"3\"],[\"64489.7\",\"47.34\",\"0\",\"2\"],[\"64489.8\",\"31.34\",\"0\",\"5\"],[\"64489.9\",\"143.6\",\"0\",\"1\"],[\"64490\",\"55.77\",\"0\",\"19\"],[\"64490.1\",\"0.01\",\"0\",\"1\"],[\"64490.3\",\"1\",\"0\",\"1\"],[\"64490.4\",\"0.02\",\"0\",\"2\"],[\"64490.5\",\"17.16\",\"0\",\"3\"],[\"64490.6\",\"1.08\",\"0\",\"3\"],[\"64490.7\",\"0.07\",\"0\",\"3\"],[\"64490.9\",\"0.07\",\"0\",\"2\"],[\"64491\",\"80.13\",\"0\",\"2\"],[\"64491.1\",\"1\",\"0\",\"1\"],[\"64491.2\",\"1.01\",\"0\",\"2\"],[\"64491.3\",\"0.02\",\"0\",\"2\"],[\"64491.4\",\"0.02\",\"0\",\"2\"],[\"64491.5\",\"0.1\",\"0\",\"1\"],[\"64491.6\",\"0.09\",\"0\",\"3\"],[\"64491.7\",\"1.02\",\"0\",\"3\"],[\"64491.8\",\"0.05\",\"0\",\"1\"],[\"64491.9\",\"0.31\",\"0\",\"5\"],[\"64492\",\"1.03\",\"0\",\"4\"],[\"64492.2\",\"0.9\",\"0\",\"6\"],[\"64492.3\",\"1.23\",\"0\",\"2\"],[\"64492.4\",\"57.86\",\"0\",\"6\"],[\"64492.5\",\"0.06\",\"0\",\"4\"],[\"64492.6\",\"98.92\",\"0\",\"1\"],[\"64492.7\",\"101.08\",\"0\",\"4\"],[\"64492.8\",\"0.13\",\"0\",\"7\"],[\"64492.9\",\"8.01\",\"0\",\"2\"],[\"64493\",\"14.92\",\"0\",\"5\"],[\"64493.1\",\"117.89\",\"0\",\"6\"],[\"64493.2\",\"399.82\",\"0\",\"8\"],[\"64493.3\",\"580.33\",\"0\",\"6\"],[\"64493.4\",\"0.32\",\"0\",\"5\"],[\"64493.5\",\"2.29\",\"0\",\"5\"],[\"64493.6\",\"148.86\",\"0\",\"1\"],[\"64493.7\",\"359.29\",\"0\",\"5\"],[\"64493.8\",\"1.24\",\"0\",\"4\"],[\"64494\",\"205.23\",\"0\",\"4\"],[\"64494.1\",\"1.2\",\"0\",\"1\"],[\"64494.3\",\"17.23\",\"0\",\"6\"],[\"64494.4\",\"0.23\",\"0\",\"6\"],[\"64494.6\",\"5.04\",\"0\",\"4\"],[\"64494.7\",\"44.62\",\"0\",\"7\"],[\"64494.8\",\"1.2\",\"0\",\"2\"],[\"64494.9\",\"0.07\",\"0\",\"3\"],[\"64495\",\"1.5\",\"0\",\"9\"],[\"64495.1\",\"0.07\",\"0\",\"3\"],[\"64495.2\",\"0.01\",\"0\",\"1\"],[\"64495.3\",\"0.26\",\"0\",\"2\"],[\"64495.4\",\"0.06\",\"0\",\"3\"],[\"64495.5\",\"6.32\",\"0\",\"4\"],[\"64495.6\",\"0.02\",\"0\",\"2\"],[\"64495.7\",\"27\",\"0\",\"4\"],[\"64495.8\",\"0.03\",\"0\",\"2\"],[\"64495.9\",\"4.74\",\"0\",\"4\"],[\"64496\",\"104.13\",\"0\",\"6\"],[\"64496.1\",\"0.06\",\"0\",\"3\"],[\"64496.2\",\"0.01\",\"0\",\"1\"],[\"64496.3\",\"0.3\",\"0\",\"4\"],[\"64496.4\",\"21.88\",\"0\",\"3\"],[\"64496.6\",\"31.68\",\"0\",\"2\"],[\"64496.7\",\"22.72\",\"0\",\"2\"],[\"64496.8\",\"75.94\",\"0\",\"5\"],[\"64496.9\",\"449.69\",\"0\",\"2\"],[\"64497\",\"34.46\",\"0\",\"6\"],[\"64497.1\",\"0.01\",\"0\",\"1\"],[\"64497.2\",\"0.84\",\"0\",\"3\"],[\"64497.3\",\"41.14\",\"0\",\"4\"],[\"64497.4\",\"0.09\",\"0\",\"2\"],[\"64497.5\",\"0.33\",\"0\",\"3\"],[\"64497.6\",\"15.77\",\"0\",\"3\"],[\"64497.8\",\"0.01\",\"0\",\"1\"],[\"64497.9\",\"0.01\",\"0\",\"1\"],[\"64498\",\"497.3\",\"0\",\"4\"],[\"64498.1\",\"0.04\",\"0\",\"4\"],[\"64498.2\",\"0.03\",\"0\",\"2\"],[\"64498.3\",\"100.42\",\"0\",\"7\"],[\"64498.5\",\"4.51\",\"0\",\"5\"],[\"64498.6\",\"0.27\",\"0\",\"4\"],[\"64498.7\",\"2.36\",\"0\",\"3\"],[\"64498.8\",\"20.4\",\"0\",\"3\"],[\"64498.9\",\"40.65\",\"0\",\"3\"],[\"64499\",\"333.41\",\"0\",\"22\"],[\"64499.1\",\"0.15\",\"0\",\"3\"],[\"64499.2\",\"0.01\",\"0\",\"1\"],[\"64499.4\",\"1.72\",\"0\",\"2\"],[\"64499.6\",\"74.53\",\"0\",\"4\"],[\"64499.7\",\"35.37\",\"0\",\"5\"],[\"64499.8\",\"19.95\",\"0\",\"3\"],[\"64499.9\",\"1162.28\",\"0\",\"3\"],[\"64500\",\"3472.69\",\"0\",\"1034\"],[\"64500.1\",\"0.05\",\"0\",\"4\"],[\"64500.2\",\"0.01\",\"0\",\"1\"],[\"64500.3\",\"2.77\",\"0\",\"4\"],[\"64500.4\",\"0.04\",\"0\",\"4\"],[\"64500.5\",\"2.49\",\"0\",\"2\"],[\"64500.6\",\"0.38\",\"0\",\"2\"],[\"64500.7\",\"3.92\",\"0\",\"2\"],[\"64500.8\",\"0.36\",\"0\",\"1\"],[\"64500.9\",\"73.16\",\"0\",\"6\"],[\"64501\",\"0.27\",\"0\",\"3\"],[\"64501.1\",\"0.05\",\"0\",\"2\"],[\"64501.2\",\"0.02\",\"0\",\"2\"],[\"64501.3\",\"0.02\",\"0\",\"1\"],[\"64501.4\",\"0.01\",\"0\",\"1\"],[\"64501.5\",\"1.57\",\"0\",\"4\"],[\"64501.6\",\"4.99\",\"0\",\"4\"],[\"64501.7\",\"0.53\",\"0\",\"2\"],[\"64501.8\",\"59\",\"0\",\"5\"],[\"64501.9\",\"0.08\",\"0\",\"1\"],[\"64502\",\"3.11\",\"0\",\"6\"],[\"64502.1\",\"0.01\",\"0\",\"1\"],[\"64502.2\",\"15.76\",\"0\",\"4\"],[\"64502.3\",\"11.33\",\"0\",\"3\"],[\"64502.4\",\"0.18\",\"0\",\"5\"],[\"64502.5\",\"0.2\",\"0\",\"3\"],[\"64502.6\",\"0.01\",\"0\",\"1\"],[\"64502.7\",\"0.03\",\"0\",\"3\"],[\"64502.8\",\"10.53\",\"0\",\"2\"],[\"64502.9\",\"0.99\",\"0\",\"4\"],[\"64503\",\"15.94\",\"0\",\"2\"],[\"64503.1\",\"0.86\",\"0\",\"7\"],[\"64503.2\",\"15.95\",\"0\",\"3\"],[\"64503.3\",\"0.02\",\"0\",\"2\"],[\"64503.5\",\"63.72\",\"0\",\"6\"],[\"64503.6\",\"17.98\",\"0\",\"3\"],[\"64503.7\",\"0.29\",\"0\",\"2\"],[\"64503.9\",\"20.45\",\"0\",\"1\"],[\"64504\",\"17.31\",\"0\",\"6\"],[\"64504.1\",\"581.2\",\"0\",\"8\"],[\"64504.2\",\"16.06\",\"0\",\"3\"],[\"64504.3\",\"0.04\",\"0\",\"2\"],[\"64504.4\",\"1.13\",\"0\",\"4\"],[\"64504.5\",\"73.8\",\"0\",\"6\"],[\"64504.7\",\"0.01\",\"0\",\"1\"],[\"64504.8\",\"0.08\",\"0\",\"2\"],[\"64504.9\",\"0.1\",\"0\",\"3\"],[\"64505\",\"0.82\",\"0\",\"3\"],[\"64505.1\",\"0.02\",\"0\",\"2\"],[\"64505.3\",\"1.16\",\"0\",\"2\"],[\"64505.4\",\"59.22\",\"0\",\"3\"],[\"64505.5\",\"3.91\",\"0\",\"2\"],[\"64505.6\",\"11.43\",\"0\",\"3\"],[\"64505.7\",\"0.56\",\"0\",\"1\"],[\"64505.8\",\"21.95\",\"0\",\"3\"],[\"64505.9\",\"0.01\",\"0\",\"1\"],[\"64506\",\"10.05\",\"0\",\"3\"],[\"64506.1\",\"0.06\",\"0\",\"1\"],[\"64506.2\",\"0.03\",\"0\",\"2\"],[\"64506.4\",\"0.03\",\"0\",\"3\"],[\"64506.5\",\"0.07\",\"0\",\"1\"],[\"64506.6\",\"10.15\",\"0\",\"3\"],[\"64506.7\",\"0.19\",\"0\",\"15\"],[\"64506.8\",\"1.05\",\"0\",\"4\"],[\"64506.9\",\"0.01\",\"0\",\"1\"],[\"64507\",\"46.6\",\"0\",\"2\"],[\"64507.1\",\"0.06\",\"0\",\"4\"],[\"64507.2\",\"14.03\",\"0\",\"2\"],[\"64507.3\",\"0.03\",\"0\",\"2\"],[\"64507.4\",\"27.31\",\"0\",\"5\"],[\"64507.5\",\"15.77\",\"0\",\"6\"],[\"64507.6\",\"0.03\",\"0\",\"2\"],[\"64507.7\",\"0.07\",\"0\",\"4\"],[\"64507.8\",\"2.83\",\"0\",\"3\"],[\"64507.9\",\"0.25\",\"0\",\"2\"],[\"64508\",\"13.54\",\"0\",\"7\"],[\"64508.1\",\"21.31\",\"0\",\"3\"],[\"64508.2\",\"59.01\",\"0\",\"5\"]],\"bids\":[[\"64457.9\",\"552.49\",\"0\",\"29\"],[\"64457.8\",\"0.14\",\"0\",\"2\"],[\"64457.6\",\"0.47\",\"0\",\"2\"],[\"64457.4\",\"0.31\",\"0\",\"1\"],[\"64457.1\",\"0.01\",\"0\",\"1\"],[\"64457\",\"5.01\",\"0\",\"2\"],[\"64456.8\",\"1.87\",\"0\",\"2\"],[\"64456.6\",\"0.07\",\"0\",\"1\"],[\"64456.4\",\"0.01\",\"0\",\"1\"],[\"64456.3\",\"1.56\",\"0\",\"1\"],[\"64456.1\",\"0.01\",\"0\",\"1\"],[\"64456\",\"0.02\",\"0\",\"2\"],[\"64455.9\",\"0.01\",\"0\",\"1\"],[\"64455.8\",\"1.56\",\"0\",\"1\"],[\"64455.4\",\"0.02\",\"0\",\"2\"],[\"64455.3\",\"50.24\",\"0\",\"4\"],[\"64455.2\",\"77.62\",\"0\",\"5\"],[\"64455\",\"0.01\",\"0\",\"1\"],[\"64454.8\",\"0.01\",\"0\",\"1\"],[\"64454.7\",\"37.26\",\"0\",\"3\"],[\"64454.6\",\"57.76\",\"0\",\"2\"],[\"64454.5\",\"1.56\",\"0\",\"1\"],[\"64454.4\",\"0.02\",\"0\",\"2\"],[\"64454.3\",\"0.01\",\"0\",\"1\"],[\"64454.2\",\"0.01\",\"0\",\"1\"],[\"64454.1\",\"4.02\",\"0\",\"3\"],[\"64454\",\"9.57\",\"0\",\"3\"],[\"64453.9\",\"0.01\",\"0\",\"1\"],[\"64453.8\",\"0.77\",\"0\",\"1\"],[\"64453.7\",\"0.31\",\"0\",\"1\"],[\"64453.6\",\"0.01\",\"0\",\"1\"],[\"64453.5\",\"1.57\",\"0\",\"2\"],[\"64453.2\",\"3.1\",\"0\",\"1\"],[\"64453.1\",\"0.01\",\"0\",\"1\"],[\"64453\",\"1.56\",\"0\",\"1\"],[\"64452.9\",\"0.01\",\"0\",\"1\"],[\"64452.8\",\"0.05\",\"0\",\"1\"],[\"64452.7\",\"0.3\",\"0\",\"1\"],[\"64452.5\",\"1.57\",\"0\",\"2\"],[\"64452.4\",\"13.2\",\"0\",\"3\"],[\"64452.3\",\"31.07\",\"0\",\"2\"],[\"64452.2\",\"169.41\",\"0\",\"3\"],[\"64452.1\",\"0.8\",\"0\",\"4\"],[\"64452\",\"76.66\",\"0\",\"4\"],[\"64451.8\",\"77.89\",\"0\",\"3\"],[\"64451.7\",\"303.36\",\"0\",\"5\"],[\"64451.5\",\"15.9\",\"0\",\"1\"],[\"64451.4\",\"0.42\",\"0\",\"2\"],[\"64451.3\",\"13.68\",\"0\",\"7\"],[\"64451.2\",\"377.55\",\"0\",\"4\"],[\"64451.1\",\"0.01\",\"0\",\"1\"],[\"64451\",\"0.02\",\"0\",\"2\"],[\"64450.7\",\"0.04\",\"0\",\"2\"],[\"64450.6\",\"1.4\",\"0\",\"1\"],[\"64450.5\",\"4.9\",\"0\",\"3\"],[\"64450.4\",\"0.69\",\"0\",\"2\"],[\"64450.3\",\"40.83\",\"0\",\"1\"],[\"64450.2\",\"32.01\",\"0\",\"2\"],[\"64450.1\",\"40.77\",\"0\",\"1\"],[\"64450\",\"1.92\",\"0\",\"3\"],[\"64449.9\",\"15.94\",\"0\",\"1\"],[\"64449.8\",\"0.01\",\"0\",\"1\"],[\"64449.7\",\"48.18\",\"0\",\"3\"],[\"64449.6\",\"517.16\",\"0\",\"8\"],[\"64449.5\",\"37.23\",\"0\",\"1\"],[\"64449.4\",\"16.17\",\"0\",\"2\"],[\"64449.3\",\"17.78\",\"0\",\"3\"],[\"64449.2\",\"0.01\",\"0\",\"1\"],[\"64449.1\",\"0.01\",\"0\",\"1\"],[\"64449\",\"1.83\",\"0\",\"4\"],[\"64448.7\",\"6.16\",\"0\",\"2\"],[\"64448.6\",\"0.01\",\"0\",\"1\"],[\"64448.5\",\"2.88\",\"0\",\"1\"],[\"64448.3\",\"16.01\",\"0\",\"3\"],[\"64448.2\",\"250.59\",\"0\",\"4\"],[\"64448.1\",\"10.01\",\"0\",\"2\"],[\"64448\",\"272.36\",\"0\",\"10\"],[\"64447.9\",\"7\",\"0\",\"2\"],[\"64447.8\",\"0.39\",\"0\",\"2\"],[\"64447.4\",\"13.17\",\"0\",\"3\"],[\"64447.3\",\"42.48\",\"0\",\"3\"],[\"64447.1\",\"0.3\",\"0\",\"1\"],[\"64447\",\"83.8\",\"0\",\"1\"],[\"64446.9\",\"21.3\",\"0\",\"3\"],[\"64446.8\",\"0.01\",\"0\",\"1\"],[\"64446.4\",\"46.54\",\"0\",\"1\"],[\"64446.3\",\"48.85\",\"0\",\"3\"],[\"64446.2\",\"0.07\",\"0\",\"1\"],[\"64446\",\"0.04\",\"0\",\"2\"],[\"64445.9\",\"8.03\",\"0\",\"4\"],[\"64445.8\",\"1.51\",\"0\",\"2\"],[\"64445.7\",\"514.54\",\"0\",\"4\"],[\"64445.6\",\"3.9\",\"0\",\"2\"],[\"64445.5\",\"22\",\"0\",\"1\"],[\"64445.4\",\"0.15\",\"0\",\"1\"],[\"64445.1\",\"184.61\",\"0\",\"4\"],[\"64445\",\"168.98\",\"0\",\"7\"],[\"64444.9\",\"10.54\",\"0\",\"2\"],[\"64444.8\",\"0.02\",\"0\",\"2\"],[\"64444.5\",\"34.59\",\"0\",\"2\"],[\"64444.4\",\"10\",\"0\",\"1\"],[\"64444.3\",\"37.23\",\"0\",\"1\"],[\"64444.2\",\"0.01\",\"0\",\"1\"],[\"64444.1\",\"0.01\",\"0\",\"1\"],[\"64444\",\"0.02\",\"0\",\"2\"],[\"64443.8\",\"20.09\",\"0\",\"1\"],[\"64443.7\",\"37.63\",\"0\",\"4\"],[\"64443.6\",\"0.01\",\"0\",\"1\"],[\"64443.5\",\"86.2\",\"0\",\"1\"],[\"64443.4\",\"403.67\",\"0\",\"1\"],[\"64443.3\",\"130.12\",\"0\",\"4\"],[\"64443.2\",\"135.66\",\"0\",\"5\"],[\"64443\",\"0.02\",\"0\",\"2\"],[\"64442.8\",\"0.03\",\"0\",\"3\"],[\"64442.7\",\"85.42\",\"0\",\"1\"],[\"64442.6\",\"15.65\",\"0\",\"1\"],[\"64442.4\",\"3.14\",\"0\",\"2\"],[\"64442.3\",\"18.13\",\"0\",\"2\"],[\"64442.1\",\"6.22\",\"0\",\"1\"],[\"64442\",\"77.63\",\"0\",\"4\"],[\"64441.9\",\"36.96\",\"0\",\"3\"],[\"64441.8\",\"535.35\",\"0\",\"2\"],[\"64441.6\",\"278.86\",\"0\",\"5\"],[\"64441.5\",\"61.31\",\"0\",\"3\"],[\"64441.4\",\"50.02\",\"0\",\"3\"],[\"64441.3\",\"50\",\"0\",\"1\"],[\"64441.1\",\"13.9\",\"0\",\"2\"],[\"64441\",\"3.11\",\"0\",\"2\"],[\"64440.9\",\"0.01\",\"0\",\"1\"],[\"64440.6\",\"10.01\",\"0\",\"2\"],[\"64440.5\",\"7.73\",\"0\",\"1\"],[\"64440.4\",\"0.01\",\"0\",\"1\"],[\"64440.3\",\"0.04\",\"0\",\"2\"],[\"64440.2\",\"0.01\",\"0\",\"1\"],[\"64440.1\",\"150.57\",\"0\",\"6\"],[\"64440\",\"99.43\",\"0\",\"5\"],[\"64439.9\",\"62.15\",\"0\",\"1\"],[\"64439.7\",\"15.67\",\"0\",\"3\"],[\"64439.5\",\"0.01\",\"0\",\"1\"],[\"64439.4\",\"0.01\",\"0\",\"1\"],[\"64439.3\",\"99.78\",\"0\",\"1\"],[\"64439\",\"58.26\",\"0\",\"2\"],[\"64438.9\",\"37.25\",\"0\",\"2\"],[\"64438.7\",\"3.99\",\"0\",\"1\"],[\"64438.6\",\"43.84\",\"0\",\"5\"],[\"64438.5\",\"16.46\",\"0\",\"3\"],[\"64438.4\",\"0.01\",\"0\",\"1\"],[\"64438.3\",\"0.01\",\"0\",\"1\"],[\"64438.2\",\"0.01\",\"0\",\"1\"],[\"64438.1\",\"15.69\",\"0\",\"2\"],[\"64438\",\"0.01\",\"0\",\"1\"],[\"64437.9\",\"15.65\",\"0\",\"1\"],[\"64437.8\",\"0.01\",\"0\",\"1\"],[\"64437.7\",\"0.01\",\"0\",\"1\"],[\"64437.6\",\"0.01\",\"0\",\"1\"],[\"64437.4\",\"233\",\"0\",\"1\"],[\"64437.3\",\"15.65\",\"0\",\"1\"],[\"64437.2\",\"0.01\",\"0\",\"1\"],[\"64437.1\",\"0.3\",\"0\",\"2\"],[\"64436.9\",\"354.24\",\"0\",\"2\"],[\"64436.8\",\"1\",\"0\",\"1\"],[\"64436.7\",\"15.66\",\"0\",\"2\"],[\"64436.6\",\"10.03\",\"0\",\"4\"],[\"64436.5\",\"11.31\",\"0\",\"3\"],[\"64436.4\",\"15.65\",\"0\",\"1\"],[\"64436.3\",\"117.15\",\"0\",\"4\"],[\"64436.1\",\"25.65\",\"0\",\"2\"],[\"64436\",\"201.01\",\"0\",\"3\"],[\"64435.9\",\"0.01\",\"0\",\"1\"],[\"64435.8\",\"0.07\",\"0\",\"1\"],[\"64435.6\",\"28.42\",\"0\",\"2\"],[\"64435.5\",\"512.4\",\"0\",\"4\"],[\"64435.4\",\"262.87\",\"0\",\"3\"],[\"64435.3\",\"0.01\",\"0\",\"1\"],[\"64435.2\",\"0.02\",\"0\",\"2\"],[\"64435.1\",\"0.01\",\"0\",\"1\"],[\"64434.9\",\"15.7\",\"0\",\"2\"],[\"64434.8\",\"148.64\",\"0\",\"3\"],[\"64434.7\",\"10.01\",\"0\",\"2\"],[\"64434.6\",\"0.5\",\"0\",\"1\"],[\"64434.3\",\"3.11\",\"0\",\"2\"],[\"64434.2\",\"0.02\",\"0\",\"2\"],[\"64434.1\",\"0.35\",\"0\",\"2\"],[\"64434\",\"15.66\",\"0\",\"2\"],[\"64433.8\",\"6.23\",\"0\",\"2\"],[\"64433.7\",\"47.23\",\"0\",\"2\"],[\"64433.5\",\"0.02\",\"0\",\"2\"],[\"64433.4\",\"46.56\",\"0\",\"3\"],[\"64433.3\",\"17.97\",\"0\",\"4\"],[\"64433.2\",\"21.29\",\"0\",\"2\"],[\"64433.1\",\"15.65\",\"0\",\"1\"],[\"64433\",\"4.07\",\"0\",\"2\"],[\"64432.8\",\"0.01\",\"0\",\"1\"],[\"64432.6\",\"15.71\",\"0\",\"4\"],[\"64432.5\",\"0.02\",\"0\",\"2\"],[\"64432.3\",\"0.02\",\"0\",\"2\"],[\"64432.2\",\"46.57\",\"0\",\"2\"],[\"64432.1\",\"0.08\",\"0\",\"1\"],[\"64432\",\"64.4\",\"0\",\"5\"],[\"64431.9\",\"17.93\",\"0\",\"2\"],[\"64431.8\",\"15.87\",\"0\",\"2\"],[\"64431.7\",\"321.87\",\"0\",\"2\"],[\"64431.6\",\"496.53\",\"0\",\"1\"],[\"64431.5\",\"15.65\",\"0\",\"1\"],[\"64431.4\",\"198.51\",\"0\",\"3\"],[\"64431.3\",\"15.66\",\"0\",\"2\"],[\"64431.2\",\"46.54\",\"0\",\"1\"],[\"64431.1\",\"0.01\",\"0\",\"1\"],[\"64431\",\"4.06\",\"0\",\"17\"],[\"64430.7\",\"15.65\",\"0\",\"1\"],[\"64430.4\",\"0.04\",\"0\",\"4\"],[\"64430.3\",\"1.01\",\"0\",\"2\"],[\"64430.1\",\"15.67\",\"0\",\"3\"],[\"64430\",\"6.59\",\"0\",\"4\"],[\"64429.9\",\"12.37\",\"0\",\"4\"],[\"64429.8\",\"35.67\",\"0\",\"4\"],[\"64429.4\",\"155.94\",\"0\",\"3\"],[\"64429.2\",\"46.65\",\"0\",\"2\"],[\"64429.1\",\"0.02\",\"0\",\"1\"],[\"64428.9\",\"16.49\",\"0\",\"1\"],[\"64428.8\",\"0.02\",\"0\",\"2\"],[\"64428.6\",\"0.04\",\"0\",\"2\"],[\"64428.4\",\"37.23\",\"0\",\"1\"],[\"64428.2\",\"15.66\",\"0\",\"2\"],[\"64428.1\",\"0.65\",\"0\",\"2\"],[\"64428\",\"15.75\",\"0\",\"5\"],[\"64427.9\",\"3.88\",\"0\",\"1\"],[\"64427.8\",\"1.06\",\"0\",\"1\"],[\"64427.7\",\"387.46\",\"0\",\"4\"],[\"64427.6\",\"0.01\",\"0\",\"1\"],[\"64427.3\",\"255.84\",\"0\",\"5\"],[\"64427.2\",\"496.54\",\"0\",\"2\"],[\"64427\",\"266.25\",\"0\",\"5\"],[\"64426.8\",\"0.06\",\"0\",\"1\"],[\"64426.7\",\"46.66\",\"0\",\"13\"],[\"64426.6\",\"0.01\",\"0\",\"1\"],[\"64426.5\",\"15.69\",\"0\",\"2\"],[\"64426.4\",\"0.01\",\"0\",\"1\"],[\"64426.1\",\"0.77\",\"0\",\"1\"],[\"64426\",\"0.03\",\"0\",\"2\"],[\"64425.9\",\"15.65\",\"0\",\"1\"],[\"64425.8\",\"0.01\",\"0\",\"1\"],[\"64425.7\",\"4.01\",\"0\",\"2\"],[\"64425.6\",\"3.91\",\"0\",\"2\"],[\"64425.5\",\"11.06\",\"0\",\"1\"],[\"64425.4\",\"6.27\",\"0\",\"2\"],[\"64425.2\",\"0.79\",\"0\",\"3\"],[\"64425\",\"17.21\",\"0\",\"8\"],[\"64424.9\",\"15.66\",\"0\",\"2\"],[\"64424.6\",\"0.02\",\"0\",\"2\"],[\"64424.3\",\"46.54\",\"0\",\"1\"],[\"64424.2\",\"0.01\",\"0\",\"1\"],[\"64424.1\",\"42.31\",\"0\",\"1\"],[\"64424\",\"1.38\",\"0\",\"6\"],[\"64423.9\",\"0.05\",\"0\",\"1\"],[\"64423.8\",\"17.49\",\"0\",\"3\"],[\"64423.4\",\"198.67\",\"0\",\"2\"],[\"64423.3\",\"496.84\",\"0\",\"2\"],[\"64423.2\",\"52.88\",\"0\",\"2\"],[\"64423.1\",\"0.01\",\"0\",\"1\"],[\"64423\",\"1.59\",\"0\",\"6\"],[\"64422.8\",\"0.02\",\"0\",\"2\"],[\"64422.7\",\"0.02\",\"0\",\"1\"],[\"64422.6\",\"98.94\",\"0\",\"3\"],[\"64422.4\",\"326.23\",\"0\",\"4\"],[\"64422.2\",\"11.09\",\"0\",\"4\"],[\"64422\",\"0.03\",\"0\",\"3\"],[\"64421.9\",\"0.16\",\"0\",\"2\"],[\"64421.8\",\"0.03\",\"0\",\"2\"],[\"64421.7\",\"15.65\",\"0\",\"1\"],[\"64421.6\",\"15.66\",\"0\",\"2\"],[\"64421.5\",\"0.8\",\"0\",\"2\"],[\"64421.4\",\"46.54\",\"0\",\"1\"],[\"64421.3\",\"0.03\",\"0\",\"2\"],[\"64421.2\",\"0.01\",\"0\",\"1\"],[\"64421.1\",\"21.53\",\"0\",\"4\"],[\"64421\",\"0.01\",\"0\",\"1\"],[\"64420.9\",\"19.81\",\"0\",\"3\"],[\"64420.7\",\"0.03\",\"0\",\"1\"],[\"64420.6\",\"100.58\",\"0\",\"1\"],[\"64420.5\",\"0.02\",\"0\",\"2\"],[\"64420.4\",\"0.27\",\"0\",\"2\"],[\"64420.3\",\"212.64\",\"0\",\"2\"],[\"64420.2\",\"80.61\",\"0\",\"3\"],[\"64420\",\"5.83\",\"0\",\"21\"],[\"64419.9\",\"18.91\",\"0\",\"3\"],[\"64419.8\",\"0.02\",\"0\",\"2\"],[\"64419.7\",\"20.01\",\"0\",\"2\"],[\"64419.6\",\"0.03\",\"0\",\"3\"],[\"64419.5\",\"0.27\",\"0\",\"2\"],[\"64419.4\",\"33.02\",\"0\",\"2\"],[\"64419.3\",\"552.33\",\"0\",\"4\"],[\"64419.2\",\"47.09\",\"0\",\"4\"],[\"64419.1\",\"0.02\",\"0\",\"2\"],[\"64419\",\"0.03\",\"0\",\"3\"],[\"64418.9\",\"11.06\",\"0\",\"1\"],[\"64418.8\",\"0.02\",\"0\",\"1\"],[\"64418.7\",\"0.01\",\"0\",\"1\"],[\"64418.6\",\"0.3\",\"0\",\"2\"],[\"64418.5\",\"0.05\",\"0\",\"1\"],[\"64418.4\",\"0.97\",\"0\",\"1\"],[\"64418.3\",\"15.65\",\"0\",\"1\"],[\"64418.1\",\"15.31\",\"0\",\"1\"],[\"64418\",\"20.53\",\"0\",\"4\"],[\"64417.9\",\"2.28\",\"0\",\"1\"],[\"64417.8\",\"0.02\",\"0\",\"2\"],[\"64417.7\",\"0.04\",\"0\",\"1\"],[\"64417.6\",\"0.02\",\"0\",\"2\"],[\"64417.5\",\"0.02\",\"0\",\"2\"],[\"64417.4\",\"23.41\",\"0\",\"9\"],[\"64417.2\",\"0.02\",\"0\",\"2\"],[\"64417.1\",\"3.9\",\"0\",\"1\"],[\"64417\",\"0.12\",\"0\",\"1\"],[\"64416.9\",\"68.68\",\"0\",\"4\"],[\"64416.8\",\"0.01\",\"0\",\"1\"],[\"64416.7\",\"45.2\",\"0\",\"3\"],[\"64416.6\",\"15.66\",\"0\",\"2\"],[\"64416.5\",\"0.08\",\"0\",\"1\"],[\"64416.3\",\"47.19\",\"0\",\"6\"],[\"64416.2\",\"101.76\",\"0\",\"4\"],[\"64416\",\"298.12\",\"0\",\"6\"],[\"64415.9\",\"0.01\",\"0\",\"1\"],[\"64415.7\",\"1.18\",\"0\",\"1\"],[\"64415.6\",\"30.86\",\"0\",\"3\"],[\"64415.5\",\"20\",\"0\",\"1\"],[\"64415.4\",\"0.01\",\"0\",\"1\"],[\"64415.3\",\"581.08\",\"0\",\"5\"],[\"64415.2\",\"0.01\",\"0\",\"1\"],[\"64415.1\",\"6.91\",\"0\",\"2\"],[\"64415\",\"15.88\",\"0\",\"4\"],[\"64414.9\",\"2.32\",\"0\",\"2\"],[\"64414.8\",\"19.02\",\"0\",\"1\"],[\"64414.7\",\"26.09\",\"0\",\"3\"],[\"64414.6\",\"0.31\",\"0\",\"1\"],[\"64414.5\",\"1365.58\",\"0\",\"1\"],[\"64414.4\",\"99.09\",\"0\",\"1\"],[\"64414.2\",\"0.02\",\"0\",\"2\"],[\"64414.1\",\"0.11\",\"0\",\"2\"],[\"64414\",\"0.01\",\"0\",\"1\"],[\"64413.9\",\"23.27\",\"0\",\"1\"],[\"64413.8\",\"0.01\",\"0\",\"1\"],[\"64413.3\",\"15.69\",\"0\",\"4\"],[\"64413.1\",\"64.55\",\"0\",\"2\"],[\"64412.9\",\"0.01\",\"0\",\"1\"],[\"64412.8\",\"0.01\",\"0\",\"1\"],[\"64412.7\",\"0.09\",\"0\",\"3\"],[\"64412.4\",\"0.01\",\"0\",\"1\"],[\"64412.3\",\"11.43\",\"0\",\"2\"],[\"64412.2\",\"99.58\",\"0\",\"1\"],[\"64412.1\",\"50\",\"0\",\"1\"],[\"64412\",\"0.02\",\"0\",\"1\"],[\"64411.8\",\"0.01\",\"0\",\"1\"],[\"64411.7\",\"15.68\",\"0\",\"2\"],[\"64411.5\",\"0.01\",\"0\",\"1\"],[\"64411.4\",\"3.38\",\"0\",\"2\"],[\"64411.3\",\"0.01\",\"0\",\"1\"],[\"64411.2\",\"15.33\",\"0\",\"1\"],[\"64411.1\",\"0.06\",\"0\",\"2\"],[\"64410.9\",\"2.08\",\"0\",\"3\"],[\"64410.8\",\"0.03\",\"0\",\"2\"],[\"64410.6\",\"21.32\",\"0\",\"2\"],[\"64410.5\",\"46.54\",\"0\",\"1\"],[\"64410.4\",\"0.31\",\"0\",\"1\"],[\"64410.3\",\"0.06\",\"0\",\"2\"],[\"64410.2\",\"6.23\",\"0\",\"2\"],[\"64410.1\",\"0.81\",\"0\",\"4\"],[\"64410\",\"1.56\",\"0\",\"5\"],[\"64409.9\",\"0.1\",\"0\",\"4\"],[\"64409.8\",\"106.39\",\"0\",\"1\"],[\"64409.7\",\"0.03\",\"0\",\"3\"],[\"64409.6\",\"0.24\",\"0\",\"2\"],[\"64409.1\",\"0.85\",\"0\",\"4\"],[\"64409\",\"11.42\",\"0\",\"1\"],[\"64408.9\",\"69.14\",\"0\",\"5\"],[\"64408.8\",\"0.01\",\"0\",\"1\"],[\"64408.7\",\"5.45\",\"0\",\"4\"],[\"64408.5\",\"0.38\",\"0\",\"1\"],[\"64408.4\",\"7.93\",\"0\",\"5\"],[\"64408.3\",\"0.03\",\"0\",\"1\"],[\"64408.2\",\"83.77\",\"0\",\"2\"],[\"64408.1\",\"0.01\",\"0\",\"1\"],[\"64408\",\"4.48\",\"0\",\"6\"],[\"64407.9\",\"0.04\",\"0\",\"4\"],[\"64407.6\",\"0.02\",\"0\",\"2\"],[\"64407.5\",\"496.53\",\"0\",\"1\"],[\"64407.4\",\"0.51\",\"0\",\"1\"],[\"64407.3\",\"99.78\",\"0\",\"1\"],[\"64407.2\",\"0.05\",\"0\",\"1\"],[\"64407\",\"0.37\",\"0\",\"4\"],[\"64406.9\",\"0.01\",\"0\",\"1\"],[\"64406.7\",\"11.06\",\"0\",\"3\"],[\"64406.6\",\"3.92\",\"0\",\"2\"],[\"64406.4\",\"0.12\",\"0\",\"2\"],[\"64406.3\",\"0.33\",\"0\",\"2\"],[\"64406.1\",\"0.02\",\"0\",\"2\"],[\"64405.9\",\"1.93\",\"0\",\"1\"],[\"64405.7\",\"15.87\",\"0\",\"2\"],[\"64405.6\",\"0.01\",\"0\",\"1\"],[\"64405.5\",\"0.01\",\"0\",\"1\"],[\"64405.3\",\"46.54\",\"0\",\"1\"]],\"ts\":\"1782015927005\",\"checksum\":-2129522576,\"seqId\":325069872370,\"prevSeqId\":-1}]}"}
{"action": "update", "capture_sequence": 246, "channel": "books", "connection_sequence": 4, "event": null, "instId": "BTC-USDT-SWAP", "local_receive_ts": "2026-06-21T04:25:27Z", "monotonic_ns": 1643483033501494, "raw": "{\"arg\":{\"channel\":\"books\",\"instId\":\"BTC-USDT-SWAP\"},\"action\":\"update\",\"data\":[{\"asks\":[[\"64458\",\"484.56\",\"0\",\"63\"],[\"64458.3\",\"7.55\",\"0\",\"5\"],[\"64458.5\",\"5\",\"0\",\"1\"],[\"64458.6\",\"0.01\",\"0\",\"1\"],[\"64459\",\"0\",\"0\",\"0\"],[\"64461.9\",\"1.71\",\"0\",\"2\"],[\"64462.4\",\"1.56\",\"0\",\"1\"],[\"64462.8\",\"1.56\",\"0\",\"1\"],[\"64463.3\",\"2.46\",\"0\",\"2\"],[\"64477.1\",\"0.01\",\"0\",\"1\"],[\"64477.4\",\"0.09\",\"0\",\"3\"],[\"64483.8\",\"0\",\"0\",\"0\"],[\"64484.1\",\"0.79\",\"0\",\"2\"],[\"64508.2\",\"0\",\"0\",\"0\"]],\"bids\":[[\"64457.6\",\"0.48\",\"0\",\"3\"],[\"64457.5\",\"1.56\",\"0\",\"1\"],[\"64457\",\"5.02\",\"0\",\"3\"],[\"64456.9\",\"1.56\",\"0\",\"1\"],[\"64456.8\",\"0.31\",\"0\",\"1\"],[\"64456.3\",\"0\",\"0\",\"0\"],[\"64456\",\"1.58\",\"0\",\"3\"],[\"64455.8\",\"0\",\"0\",\"0\"],[\"64455.5\",\"1.56\",\"0\",\"1\"],[\"64455.4\",\"0.01\",\"0\",\"1\"],[\"64455.3\",\"48.67\",\"0\",\"2\"],[\"64455\",\"1.57\",\"0\",\"2\"],[\"64445.1\",\"185.38\",\"0\",\"5\"],[\"64444.5\",\"33.82\",\"0\",\"1\"],[\"64408.5\",\"0\",\"0\",\"0\"],[\"64408.4\",\"8.31\",\"0\",\"6\"]],\"ts\":\"1782015927105\",\"checksum\":-1312432732,\"seqId\":325069872456,\"prevSeqId\":325069872370}]}"}
{"action": "update", "capture_sequence": 247, "channel": "books", "connection_sequence": 4, "event": null, "instId": "BTC-USDT-SWAP", "local_receive_ts": "2026-06-21T04:25:27Z", "monotonic_ns": 1643483109107104, "raw": "{\"arg\":{\"channel\":\"books\",\"instId\":\"BTC-USDT-SWAP\"},\"action\":\"update\",\"data\":[{\"asks\":[[\"64458.3\",\"7.54\",\"0\",\"4\"],[\"64458.6\",\"0.02\",\"0\",\"2\"],[\"64469.2\",\"8.68\",\"0\",\"1\"],[\"64487.4\",\"0.49\",\"0\",\"5\"],[\"64488.3\",\"97.04\",\"0\",\"3\"],[\"64508.1\",\"0\",\"0\",\"0\"]],\"bids\":[[\"64440.2\",\"58.25\",\"0\",\"2\"],[\"64439\",\"0.01\",\"0\",\"1\"]],\"ts\":\"1782015927205\",\"checksum\":1646823127,\"seqId\":325069872479,\"prevSeqId\":325069872456}]}"}
{"action": "update", "capture_sequence": 248, "channel": "books", "connection_sequence": 4, "event": null, "instId": "BTC-USDT-SWAP", "local_receive_ts": "2026-06-21T04:25:27Z", "monotonic_ns": 1643483207555475, "raw": "{\"arg\":{\"channel\":\"books\",\"instId\":\"BTC-USDT-SWAP\"},\"action\":\"update\",\"data\":[{\"asks\":[[\"64459.5\",\"0.01\",\"0\",\"1\"],[\"64460\",\"0.01\",\"0\",\"1\"],[\"64460.3\",\"1.56\",\"0\",\"1\"],[\"64460.4\",\"0\",\"0\",\"0\"],[\"64463.8\",\"1.57\",\"0\",\"2\"],[\"64464.3\",\"73.77\",\"0\",\"2\"],[\"64464.7\",\"1.57\",\"0\",\"2\"]],\"bids\":[[\"64457.9\",\"554.02\",\"0\",\"30\"],[\"64457.6\",\"0.47\",\"0\",\"2\"],[\"64457.5\",\"0\",\"0\",\"0\"],[\"64457.3\",\"1.56\",\"0\",\"1\"],[\"64457.2\",\"0.01\",\"0\",\"1\"],[\"64457\",\"5.01\",\"0\",\"2\"],[\"64456.9\",\"0\",\"0\",\"0\"],[\"64456.7\",\"0.01\",\"0\",\"1\"],[\"64456.6\",\"1.63\",\"0\",\"2\"],[\"64453.9\",\"0.32\",\"0\",\"2\"],[\"64453.7\",\"0\",\"0\",\"0\"],[\"64452.5\",\"0.01\",\"0\",\"1\"]],\"ts\":\"1782015927305\",\"checksum\":542972974,\"seqId\":325069872538,\"prevSeqId\":325069872479}]}"}
{"action": "update", "capture_sequence": 249, "channel": "books", "connection_sequence": 4, "event": null, "instId": "BTC-USDT-SWAP", "local_receive_ts": "2026-06-21T04:25:27Z", "monotonic_ns": 1643483307588085, "raw": "{\"arg\":{\"channel\":\"books\",\"instId\":\"BTC-USDT-SWAP\"},\"action\":\"update\",\"data\":[{\"asks\":[[\"64460.1\",\"1.58\",\"0\",\"3\"],[\"64460.3\",\"0\",\"0\",\"0\"],[\"64476.6\",\"0\",\"0\",\"0\"],[\"64508.1\",\"21.31\",\"0\",\"3\"],[\"64508.2\",\"59.01\",\"0\",\"5\"]],\"bids\":[[\"64445.2\",\"0.77\",\"0\",\"1\"],[\"64445.1\",\"184.61\",\"0\",\"4\"],[\"64442.4\",\"0.01\",\"0\",\"1\"],[\"64435.5\",\"512.2\",\"0\",\"3\"],[\"64405.3\",\"0\",\"0\",\"0\"]],\"ts\":\"1782015927405\",\"checksum\":1528076356,\"seqId\":325069872573,\"prevSeqId\":325069872538}]}"}
{"action": "update", "capture_sequence": 250, "channel": "books", "connection_sequence": 4, "event": null, "instId": "BTC-USDT-SWAP", "local_receive_ts": "2026-06-21T04:25:27Z", "monotonic_ns": 1643483408156664, "raw": "{\"arg\":{\"channel\":\"books\",\"instId\":\"BTC-USDT-SWAP\"},\"action\":\"update\",\"data\":[{\"asks\":[[\"64459.9\",\"1.56\",\"0\",\"1\"],[\"64460.1\",\"0.02\",\"0\",\"2\"],[\"64460.4\",\"1.56\",\"0\",\"1\"],[\"64464.7\",\"0.01\",\"0\",\"1\"],[\"64476.6\",\"0.15\",\"0\",\"1\"],[\"64508\",\"0\",\"0\",\"0\"],[\"64508.1\",\"0\",\"0\",\"0\"],[\"64508.2\",\"0\",\"0\",\"0\"]],\"bids\":[[\"64457.9\",\"554.03\",\"0\",\"30\"],[\"64442.4\",\"3.2\",\"0\",\"2\"],[\"64435.5\",\"512.39\",\"0\",\"4\"]],\"ts\":\"1782015927505\",\"checksum\":-54738287,\"seqId\":325069872595,\"prevSeqId\":325069872573}]}"}
{"action": "update", "capture_sequence": 251, "channel": "books", "connection_sequence": 4, "event": null, "instId": "BTC-USDT-SWAP", "local_receive_ts": "2026-06-21T04:25:27Z", "monotonic_ns": 1643483508560510, "raw": "{\"arg\":{\"channel\":\"books\",\"instId\":\"BTC-USDT-SWAP\"},\"action\":\"update\",\"data\":[{\"asks\":[[\"64459.9\",\"0\",\"0\",\"0\"],[\"64483.8\",\"1.08\",\"0\",\"2\"],[\"64484.1\",\"0.02\",\"0\",\"1\"],[\"64484.3\",\"0\",\"0\",\"0\"],[\"64487.4\",\"58.69\",\"0\",\"6\"],[\"64488.2\",\"89.32\",\"0\",\"3\"],[\"64488.3\",\"38.84\",\"0\",\"2\"],[\"64488.6\",\"0.02\",\"0\",\"2\"],[\"64494.7\",\"24.55\",\"0\",\"6\"],[\"64495.3\",\"20.33\",\"0\",\"3\"],[\"64508\",\"13.54\",\"0\",\"7\"]],\"bids\":[[\"64457.9\",\"552.47\",\"0\",\"29\"],[\"64457.3\",\"0\",\"0\",\"0\"],[\"64456.6\",\"0.07\",\"0\",\"1\"],[\"64456\",\"0.02\",\"0\",\"2\"],[\"64455.5\",\"0\",\"0\",\"0\"],[\"64455\",\"0.01\",\"0\",\"1\"],[\"64453.9\",\"0.01\",\"0\",\"1\"],[\"64453.7\",\"0.31\",\"0\",\"1\"],[\"64451.8\",\"77.58\",\"0\",\"2\"],[\"64451.3\",\"13.99\",\"0\",\"8\"],[\"64445.2\",\"0\",\"0\",\"0\"],[\"64444.6\",\"20.86\",\"0\",\"2\"],[\"64444\",\"86.22\",\"0\",\"3\"],[\"64443.8\",\"0\",\"0\",\"0\"],[\"64443.5\",\"0\",\"0\",\"0\"],[\"64440.2\",\"0.01\",\"0\",\"1\"],[\"64439\",\"58.26\",\"0\",\"2\"],[\"64405.3\",\"46.54\",\"0\",\"1\"],[\"64405.2\",\"6.39\",\"0\",\"4\"],[\"64405.1\",\"0.07\",\"0\",\"3\"]],\"ts\":\"1782015927605\",\"checksum\":-2101450053,\"seqId\":325069872659,\"prevSeqId\":325069872595}]}"}
{"action": "update", "capture_sequence": 252, "channel": "books", "connection_sequence": 4, "event": null, "instId": "BTC-USDT-SWAP", "local_receive_ts": "2026-06-21T04:25:27Z", "monotonic_ns": 1643483607847671, "raw": "{\"arg\":{\"channel\":\"books\",\"instId\":\"BTC-USDT-SWAP\"},\"action\":\"update\",\"data\":[{\"asks\":[[\"64476.6\",\"0\",\"0\",\"0\"],[\"64477.9\",\"1.55\",\"0\",\"1\"],[\"64478.5\",\"0\",\"0\",\"0\"],[\"64483.8\",\"0.77\",\"0\",\"1\"],[\"64484.3\",\"0.31\",\"0\",\"1\"],[\"64488.1\",\"86.03\",\"0\",\"3\"],[\"64488.2\",\"3.96\",\"0\",\"2\"],[\"64493.1\",\"31.76\",\"0\",\"5\"],[\"64493.5\",\"88.42\",\"0\",\"6\"],[\"64494.3\",\"37.3\",\"0\",\"7\"],[\"64495.3\",\"0.26\",\"0\",\"2\"]],\"bids\":[[\"64457.9\",\"552\",\"0\",\"29\"],[\"64457.2\",\"0\",\"0\",\"0\"],[\"64456.7\",\"0\",\"0\",\"0\"],[\"64455.4\",\"0.02\",\"0\",\"2\"],[\"64455.3\",\"48.68\",\"0\",\"3\"],[\"64451.6\",\"0.31\",\"0\",\"1\"],[\"64451.3\",\"13.68\",\"0\",\"7\"],[\"64444.6\",\"0.77\",\"0\",\"1\"],[\"64444\",\"0.02\",\"0\",\"2\"],[\"64443.8\",\"20.09\",\"0\",\"1\"],[\"64443.6\",\"86.21\",\"0\",\"2\"],[\"64442.4\",\"0.01\",\"0\",\"1\"],[\"64435.5\",\"512.2\",\"0\",\"3\"]],\"ts\":\"1782015927705\",\"checksum\":-1658816628,\"seqId\":325069872703,\"prevSeqId\":325069872659}]}"}
{"action": "update", "capture_sequence": 253, "channel": "books", "connection_sequence": 4, "event": null, "instId": "BTC-USDT-SWAP", "local_receive_ts": "2026-06-21T04:25:27Z", "monotonic_ns": 1643483707541407, "raw": "{\"arg\":{\"channel\":\"books\",\"instId\":\"BTC-USDT-SWAP\"},\"action\":\"update\",\"data\":[{\"asks\":[[\"64476.6\",\"0.15\",\"0\",\"1\"],[\"64508\",\"0\",\"0\",\"0\"]],\"bids\":[[\"64442.3\",\"21.32\",\"0\",\"3\"],[\"64435.5\",\"512.39\",\"0\",\"4\"]],\"ts\":\"1782015927805\",\"checksum\":-1658816628,\"seqId\":325069872708,\"prevSeqId\":325069872703}]}"}
{"action": "update", "capture_sequence": 254, "channel": "books", "connection_sequence": 4, "event": null, "instId": "BTC-USDT-SWAP", "local_receive_ts": "2026-06-21T04:25:28Z", "monotonic_ns": 1643483807578334, "raw": "{\"arg\":{\"channel\":\"books\",\"instId\":\"BTC-USDT-SWAP\"},\"action\":\"update\",\"data\":[{\"asks\":[[\"64483.8\",\"0\",\"0\",\"0\"],[\"64484.3\",\"1.08\",\"0\",\"2\"],[\"64508\",\"13.54\",\"0\",\"7\"]],\"bids\":[[\"64445.2\",\"0.77\",\"0\",\"1\"],[\"64444.6\",\"0\",\"0\",\"0\"]],\"ts\":\"1782015927905\",\"checksum\":-1658816628,\"seqId\":325069872729,\"prevSeqId\":325069872708}]}"}
{"action": "update", "capture_sequence": 255, "channel": "books", "connection_sequence": 4, "event": null, "instId": "BTC-USDT-SWAP", "local_receive_ts": "2026-06-21T04:25:28Z", "monotonic_ns": 1643483907995473, "raw": "{\"arg\":{\"channel\":\"books\",\"instId\":\"BTC-USDT-SWAP\"},\"action\":\"update\",\"data\":[{\"asks\":[[\"64458\",\"484.66\",\"0\",\"64\"],[\"64459\",\"1.56\",\"0\",\"1\"],[\"64483.3\",\"0.06\",\"0\",\"3\"],[\"64483.8\",\"33.8\",\"0\",\"1\"],[\"64487.4\",\"0.49\",\"0\",\"5\"],[\"64487.9\",\"58.21\",\"0\",\"2\"],[\"64488.1\",\"0.67\",\"0\",\"2\"],[\"64488.3\",\"124.2\",\"0\",\"3\"],[\"64493.1\",\"117.89\",\"0\",\"6\"],[\"64493.5\",\"2.29\",\"0\",\"5\"],[\"64494.3\",\"17.23\",\"0\",\"6\"],[\"64494.5\",\"20.07\",\"0\",\"1\"],[\"64507.8\",\"0\",\"0\",\"0\"],[\"64507.9\",\"0\",\"0\",\"0\"],[\"64508\",\"0\",\"0\",\"0\"]],\"bids\":[[\"64457.9\",\"553.56\",\"0\",\"30\"],[\"64457.4\",\"1.87\",\"0\",\"2\"],[\"64456.9\",\"1.56\",\"0\",\"1\"],[\"64456.4\",\"1.57\",\"0\",\"2\"],[\"64451.8\",\"77.89\",\"0\",\"3\"],[\"64451.6\",\"0\",\"0\",\"0\"],[\"64443.6\",\"0.01\",\"0\",\"1\"],[\"64443.5\",\"86.2\",\"0\",\"1\"],[\"64439.8\",\"58.25\",\"0\",\"1\"],[\"64439\",\"0.01\",\"0\",\"1\"],[\"64438.7\",\"35.05\",\"0\",\"2\"],[\"64438.6\",\"12.78\",\"0\",\"4\"],[\"64405.2\",\"0\",\"0\",\"0\"],[\"64405.1\",\"0\",\"0\",\"0\"]],\"ts\":\"1782015928005\",\"checksum\":1132095191,\"seqId\":325069872769,\"prevSeqId\":325069872729}]}"}
{"action": "update", "capture_sequence": 256, "channel": "books", "connection_sequence": 4, "event": null, "instId": "BTC-USDT-SWAP", "local_receive_ts": "2026-06-21T04:25:28Z", "monotonic_ns": 1643484007367019, "raw": "{\"arg\":{\"channel\":\"books\",\"instId\":\"BTC-USDT-SWAP\"},\"action\":\"update\",\"data\":[{\"asks\":[[\"64459\",\"0\",\"0\",\"0\"],[\"64459.9\",\"1.56\",\"0\",\"1\"],[\"64463.8\",\"0.01\",\"0\",\"1\"],[\"64464.3\",\"72.21\",\"0\",\"1\"],[\"64476.9\",\"0.03\",\"0\",\"3\"],[\"64477.1\",\"0\",\"0\",\"0\"],[\"64507.8\",\"2.83\",\"0\",\"3\"]],\"bids\":[[\"64457.5\",\"0.01\",\"0\",\"1\"],[\"64457\",\"5.02\",\"0\",\"3\"],[\"64455.4\",\"0.01\",\"0\",\"1\"],[\"64455.3\",\"48.67\",\"0\",\"2\"],[\"64432.9\",\"0.01\",\"0\",\"1\"],[\"64432.5\",\"0.01\",\"0\",\"1\"],[\"64405.5\",\"0\",\"0\",\"0\"],[\"64405.3\",\"0\",\"0\",\"0\"]],\"ts\":\"1782015928105\",\"checksum\":1533220098,\"seqId\":325069872797,\"prevSeqId\":325069872769}]}"}
{"action": "update", "capture_sequence": 257, "channel": "books", "connection_sequence": 4, "event": null, "instId": "BTC-USDT-SWAP", "local_receive_ts": "2026-06-21T04:25:28Z", "monotonic_ns": 1643484108517852, "raw": "{\"arg\":{\"channel\":\"books\",\"instId\":\"BTC-USDT-SWAP\"},\"action\":\"update\",\"data\":[{\"asks\":[[\"64459.3\",\"2.59\",\"0\",\"5\"],[\"64459.9\",\"0\",\"0\",\"0\"],[\"64463.8\",\"1.57\",\"0\",\"2\"],[\"64483.3\",\"33.86\",\"0\",\"4\"],[\"64483.8\",\"0\",\"0\",\"0\"],[\"64484.1\",\"0.79\",\"0\",\"2\"],[\"64484.3\",\"0.31\",\"0\",\"1\"],[\"64487.5\",\"101.67\",\"0\",\"7\"],[\"64487.9\",\"0.01\",\"0\",\"1\"],[\"64507.9\",\"0.25\",\"0\",\"2\"],[\"64508\",\"13.54\",\"0\",\"7\"]],\"bids\":[[\"64457.9\",\"552\",\"0\",\"29\"],[\"64455.9\",\"1.57\",\"0\",\"2\"],[\"64455.5\",\"1.56\",\"0\",\"1\"],[\"64439.8\",\"0\",\"0\",\"0\"],[\"64439.4\",\"58.26\",\"0\",\"2\"]],\"ts\":\"1782015928205\",\"checksum\":-212856763,\"seqId\":325069872867,\"prevSeqId\":325069872797}]}"}
{"action": null, "capture_sequence": 258, "channel": "trades", "connection_sequence": 4, "event": null, "instId": "BTC-USDT-SWAP", "local_receive_ts": "2026-06-21T04:25:28Z", "monotonic_ns": 1643484177122195, "raw": "{\"arg\":{\"channel\":\"trades\",\"instId\":\"BTC-USDT-SWAP\"},\"data\":[{\"instId\":\"BTC-USDT-SWAP\",\"tradeId\":\"2718748899\",\"px\":\"64457.9\",\"sz\":\"5\",\"side\":\"sell\",\"ts\":\"1782015928275\",\"count\":\"1\",\"source\":\"0\",\"seqId\":325069872910}]}"}
{"action": null, "capture_sequence": 259, "channel": "trades", "connection_sequence": 4, "event": null, "instId": "BTC-USDT-SWAP", "local_receive_ts": "2026-06-21T04:25:28Z", "monotonic_ns": 1643484182378333, "raw": "{\"arg\":{\"channel\":\"trades\",\"instId\":\"BTC-USDT-SWAP\"},\"data\":[{\"instId\":\"BTC-USDT-SWAP\",\"tradeId\":\"2718748900\",\"px\":\"64457.9\",\"sz\":\"0.01\",\"side\":\"sell\",\"ts\":\"1782015928280\",\"count\":\"1\",\"source\":\"0\",\"seqId\":325069872916}]}"}
{"action": "update", "capture_sequence": 260, "channel": "books", "connection_sequence": 4, "event": null, "instId": "BTC-USDT-SWAP", "local_receive_ts": "2026-06-21T04:25:28Z", "monotonic_ns": 1643484207579368, "raw": "{\"arg\":{\"channel\":\"books\",\"instId\":\"BTC-USDT-SWAP\"},\"action\":\"update\",\"data\":[{\"asks\":[[\"64458.5\",\"6.56\",\"0\",\"2\"],[\"64464.6\",\"11.01\",\"0\",\"2\"],[\"64484.1\",\"0.02\",\"0\",\"1\"],[\"64484.3\",\"1.08\",\"0\",\"2\"],[\"64488.1\",\"86.03\",\"0\",\"3\"],[\"64488.3\",\"38.84\",\"0\",\"2\"],[\"64494.3\",\"37.3\",\"0\",\"7\"],[\"64494.5\",\"0\",\"0\",\"0\"],[\"64508.1\",\"21.31\",\"0\",\"3\"]],\"bids\":[[\"64457.9\",\"546.74\",\"0\",\"29\"],[\"64457.5\",\"0\",\"0\",\"0\"],[\"64457.4\",\"0.31\",\"0\",\"1\"],[\"64457\",\"5.01\",\"0\",\"2\"],[\"64456.9\",\"0\",\"0\",\"0\"],[\"64456.4\",\"0.01\",\"0\",\"1\"],[\"64456\",\"0.03\",\"0\",\"3\"],[\"64455.9\",\"0.01\",\"0\",\"1\"],[\"64455.7\",\"1.56\",\"0\",\"1\"],[\"64455.6\",\"0.01\",\"0\",\"1\"],[\"64455.5\",\"0\",\"0\",\"0\"],[\"64455.2\",\"79.18\",\"0\",\"6\"],[\"64452.5\",\"1.57\",\"0\",\"2\"],[\"64405.5\",\"0.01\",\"0\",\"1\"]],\"ts\":\"1782015928305\",\"checksum\":1817092963,\"seqId\":325069872940,\"prevSeqId\":325069872867}]}"}
{"action": null, "capture_sequence": 261, "channel": "trades", "connection_sequence": 4, "event": null, "instId": "BTC-USDT-SWAP", "local_receive_ts": "2026-06-21T04:25:28Z", "monotonic_ns": 1643484263513991, "raw": "{\"arg\":{\"channel\":\"trades\",\"instId\":\"BTC-USDT-SWAP\"},\"data\":[{\"instId\":\"BTC-USDT-SWAP\",\"tradeId\":\"2718748901\",\"px\":\"64458\",\"sz\":\"0.29\",\"side\":\"buy\",\"ts\":\"1782015928361\",\"count\":\"1\",\"source\":\"0\",\"seqId\":325069872979}]}"}
{"action": null, "capture_sequence": 262, "channel": "trades", "connection_sequence": 4, "event": null, "instId": "BTC-USDT-SWAP", "local_receive_ts": "2026-06-21T04:25:28Z", "monotonic_ns": 1643484286264337, "raw": "{\"arg\":{\"channel\":\"trades\",\"instId\":\"BTC-USDT-SWAP\"},\"data\":[{\"instId\":\"BTC-USDT-SWAP\",\"tradeId\":\"2718748902\",\"px\":\"64458\",\"sz\":\"35.77\",\"side\":\"buy\",\"ts\":\"1782015928384\",\"count\":\"1\",\"source\":\"0\",\"seqId\":325069873002}]}"}
{"action": "update", "capture_sequence": 263, "channel": "books", "connection_sequence": 4, "event": null, "instId": "BTC-USDT-SWAP", "local_receive_ts": "2026-06-21T04:25:28Z", "monotonic_ns": 1643484308393119, "raw": "{\"arg\":{\"channel\":\"books\",\"instId\":\"BTC-USDT-SWAP\"},\"action\":\"update\",\"data\":[{\"asks\":[[\"64458\",\"461.5\",\"0\",\"65\"],[\"64458.5\",\"5\",\"0\",\"1\"],[\"64459.3\",\"1.03\",\"0\",\"4\"],[\"64460.4\",\"0\",\"0\",\"0\"],[\"64460.9\",\"0\",\"0\",\"0\"],[\"64461.1\",\"1.57\",\"0\",\"2\"],[\"64461.4\",\"0.03\",\"0\",\"3\"],[\"64461.5\",\"1.56\",\"0\",\"1\"],[\"64461.9\",\"0.15\",\"0\",\"1\"],[\"64462.2\",\"1.56\",\"0\",\"1\"],[\"64462.4\",\"0\",\"0\",\"0\"],[\"64464.3\",\"73.77\",\"0\",\"2\"],[\"64464.6\",\"0.01\",\"0\",\"1\"],[\"64464.7\",\"1.57\",\"0\",\"2\"],[\"64477.9\",\"0\",\"0\",\"0\"],[\"64478.5\",\"1.55\",\"0\",\"1\"],[\"64487.5\",\"43.47\",\"0\",\"6\"],[\"64487.9\",\"58.21\",\"0\",\"2\"],[\"64494.3\",\"17.23\",\"0\",\"6\"],[\"64494.5\",\"20.07\",\"0\",\"1\"]],\"bids\":[[\"64457.9\",\"548.3\",\"0\",\"30\"],[\"64457.2\",\"0.01\",\"0\",\"1\"],[\"64457.1\",\"1.57\",\"0\",\"2\"],[\"64456\",\"0.02\",\"0\",\"2\"],[\"64455.8\",\"0.01\",\"0\",\"1\"],[\"64455.6\",\"0\",\"0\",\"0\"],[\"64453.9\",\"0.32\",\"0\",\"2\"],[\"64453.7\",\"0\",\"0\",\"0\"],[\"64439.8\",\"58.25\",\"0\",\"1\"],[\"64439.4\",\"0.01\",\"0\",\"1\"],[\"64433\",\"4.08\",\"0\",\"3\"],[\"64432.9\",\"0\",\"0\",\"0\"]],\"ts\":\"1782015928405\",\"checksum\":1717140133,\"seqId\":325069873027,\"prevSeqId\":325069872940}]}"}
{"action": "update", "capture_sequence": 264, "channel": "books", "connection_sequence": 4, "event": null, "instId": "BTC-USDT-SWAP", "local_receive_ts": "2026-06-21T04:25:28Z", "monotonic_ns": 1643484408551295, "raw": "{\"arg\":{\"channel\":\"books\",\"instId\":\"BTC-USDT-SWAP\"},\"action\":\"update\",\"data\":[{\"asks\":[[\"64460.6\",\"1.56\",\"0\",\"1\"],[\"64464.6\",\"11.01\",\"0\",\"2\"],[\"64476.5\",\"0.15\",\"0\",\"1\"],[\"64476.6\",\"0\",\"0\",\"0\"],[\"64476.9\",\"0.02\",\"0\",\"2\"],[\"64477.9\",\"0.01\",\"0\",\"1\"],[\"64508\",\"0\",\"0\",\"0\"],[\"64508.1\",\"0\",\"0\",\"0\"]],\"bids\":[[\"64457.9\",\"548.31\",\"0\",\"30\"],[\"64442.4\",\"3.23\",\"0\",\"2\"],[\"64442.3\",\"18.13\",\"0\",\"2\"],[\"64439.2\",\"0.02\",\"0\",\"1\"],[\"64438.9\",\"37.23\",\"0\",\"1\"],[\"64405.5\",\"0\",\"0\",\"0\"]],\"ts\":\"1782015928505\",\"checksum\":1493711884,\"seqId\":325069873051,\"prevSeqId\":325069873027}]}"}
{"action": null, "capture_sequence": 265, "channel": "trades", "connection_sequence": 4, "event": null, "instId": "BTC-USDT-SWAP", "local_receive_ts": "2026-06-21T04:25:28Z", "monotonic_ns": 1643484450217760, "raw": "{\"arg\":{\"channel\":\"trades\",\"instId\":\"BTC-USDT-SWAP\"},\"data\":[{\"instId\":\"BTC-USDT-SWAP\",\"tradeId\":\"2718748903\",\"px\":\"64457.9\",\"sz\":\"4.65\",\"side\":\"sell\",\"ts\":\"1782015928548\",\"count\":\"1\",\"source\":\"0\",\"seqId\":325069873055}]}"}
{"action": null, "capture_sequence": 266, "channel": "trades", "connection_sequence": 4, "event": null, "instId": "BTC-USDT-SWAP", "local_receive_ts": "2026-06-21T04:25:28Z", "monotonic_ns": 1643484458441469, "raw": "{\"arg\":{\"channel\":\"trades\",\"instId\":\"BTC-USDT-SWAP\"},\"data\":[{\"instId\":\"BTC-USDT-SWAP\",\"tradeId\":\"2718748913\",\"px\":\"64457.9\",\"sz\":\"74.17\",\"side\":\"sell\",\"ts\":\"1782015928556\",\"count\":\"10\",\"source\":\"0\",\"seqId\":325069873081}]}"}
{"action": "update", "capture_sequence": 267, "channel": "books", "connection_sequence": 4, "event": null, "instId": "BTC-USDT-SWAP", "local_receive_ts": "2026-06-21T04:25:28Z", "monotonic_ns": 1643484507694682, "raw": "{\"arg\":{\"channel\":\"books\",\"instId\":\"BTC-USDT-SWAP\"},\"action\":\"update\",\"data\":[{\"asks\":[[\"64458.3\",\"58.29\",\"0\",\"3\"],[\"64459.5\",\"150.01\",\"0\",\"2\"],[\"64460.8\",\"9.56\",\"0\",\"1\"],[\"64461.6\",\"0\",\"0\",\"0\"],[\"64461.7\",\"0\",\"0\",\"0\"],[\"64464.7\",\"0.01\",\"0\",\"1\"],[\"64477.9\",\"1.56\",\"0\",\"2\"],[\"64478.5\",\"0\",\"0\",\"0\"],[\"64508\",\"13.54\",\"0\",\"7\"],[\"64508.1\",\"21.31\",\"0\",\"3\"],[\"64508.2\",\"59.01\",\"0\",\"5\"]],\"bids\":[[\"64457.9\",\"467.94\",\"0\",\"21\"],[\"64457.2\",\"0\",\"0\",\"0\"],[\"64457.1\",\"0.01\",\"0\",\"1\"],[\"64455.8\",\"0\",\"0\",\"0\"],[\"64455.7\",\"0\",\"0\",\"0\"],[\"64455.4\",\"0.02\",\"0\",\"2\"],[\"64455.3\",\"48.68\",\"0\",\"3\"],[\"64455.2\",\"77.62\",\"0\",\"5\"],[\"64455.1\",\"1.56\",\"0\",\"1\"],[\"64454.6\",\"46.54\",\"0\",\"1\"],[\"64454.5\",\"0\",\"0\",\"0\"],[\"64454.4\",\"1.58\",\"0\",\"3\"],[\"64454\",\"8.01\",\"0\",\"2\"],[\"64453.9\",\"0.01\",\"0\",\"1\"],[\"64453.7\",\"0.31\",\"0\",\"1\"],[\"64452\",\"78.22\",\"0\",\"5\"],[\"64451.5\",\"17.46\",\"0\",\"2\"],[\"64451\",\"1.58\",\"0\",\"3\"],[\"64450.6\",\"2.96\",\"0\",\"2\"],[\"64450.1\",\"42.33\",\"0\",\"2\"],[\"64433\",\"4.07\",\"0\",\"2\"],[\"64431.9\",\"17.94\",\"0\",\"3\"],[\"64405.5\",\"0.01\",\"0\",\"1\"],[\"64405.3\",\"46.54\",\"0\",\"1\"]],\"ts\":\"1782015928605\",\"checksum\":571172478,\"seqId\":325069873141,\"prevSeqId\":325069873051}]}"}
{"action": "update", "capture_sequence": 268, "channel": "books", "connection_sequence": 4, "event": null, "instId": "BTC-USDT-SWAP", "local_receive_ts": "2026-06-21T04:25:28Z", "monotonic_ns": 1643484607629712, "raw": "{\"arg\":{\"channel\":\"books\",\"instId\":\"BTC-USDT-SWAP\"},\"action\":\"update\",\"data\":[{\"asks\":[[\"64476.9\",\"0.03\",\"0\",\"3\"],[\"64477.9\",\"1.55\",\"0\",\"1\"],[\"64479.9\",\"62.21\",\"0\",\"4\"],[\"64480.1\",\"0.01\",\"0\",\"1\"],[\"64483.2\",\"148.5\",\"0\",\"5\"],[\"64483.3\",\"0.05\",\"0\",\"2\"]],\"bids\":[[\"64457.9\",\"468.48\",\"0\",\"22\"],[\"64444.5\",\"0\",\"0\",\"0\"],[\"64444.4\",\"43.82\",\"0\",\"2\"],[\"64441.9\",\"36.94\",\"0\",\"2\"],[\"64441.8\",\"535.37\",\"0\",\"3\"],[\"64439.2\",\"0\",\"0\",\"0\"],[\"64438.6\",\"12.8\",\"0\",\"5\"],[\"64405.2\",\"6.39\",\"0\",\"4\"],[\"64405.1\",\"0.07\",\"0\",\"3\"]],\"ts\":\"1782015928705\",\"checksum\":-8474040,\"seqId\":325069873186,\"prevSeqId\":325069873141}]}"}
{"action": null, "capture_sequence": 269, "channel": "trades", "connection_sequence": 4, "event": null, "instId": "BTC-USDT-SWAP", "local_receive_ts": "2026-06-21T04:25:28Z", "monotonic_ns": 1643484642359123, "raw": "{\"arg\":{\"channel\":\"trades\",\"instId\":\"BTC-USDT-SWAP\"},\"data\":[{\"instId\":\"BTC-USDT-SWAP\",\"tradeId\":\"2718748914\",\"px\":\"64458\",\"sz\":\"0.1\",\"side\":\"buy\",\"ts\":\"1782015928740\",\"count\":\"1\",\"source\":\"0\",\"seqId\":325069873190}]}"}
{"action": "update", "capture_sequence": 270, "channel": "books", "connection_sequence": 4, "event": null, "instId": "BTC-USDT-SWAP", "local_receive_ts": "2026-06-21T04:25:28Z", "monotonic_ns": 1643484707490312, "raw": "{\"arg\":{\"channel\":\"books\",\"instId\":\"BTC-USDT-SWAP\"},\"action\":\"update\",\"data\":[{\"asks\":[[\"64458\",\"461.9\",\"0\",\"66\"],[\"64459.4\",\"0.01\",\"0\",\"1\"],[\"64460.6\",\"0\",\"0\",\"0\"],[\"64461.1\",\"0.01\",\"0\",\"1\"],[\"64461.5\",\"0\",\"0\",\"0\"],[\"64462.2\",\"0\",\"0\",\"0\"],[\"64508.4\",\"1367.19\",\"0\",\"6\"],[\"64508.5\",\"42.46\",\"0\",\"3\"]],\"bids\":[[\"64455.3\",\"51.45\",\"0\",\"7\"],[\"64449.6\",\"514.94\",\"0\",\"4\"],[\"64448\",\"271.81\",\"0\",\"6\"]],\"ts\":\"1782015928805\",\"checksum\":1492131549,\"seqId\":325069873214,\"prevSeqId\":325069873186}]}"}
{"action": "update", "capture_sequence": 271, "channel": "books", "connection_sequence": 4, "event": null, "instId": "BTC-USDT-SWAP", "local_receive_ts": "2026-06-21T04:25:29Z", "monotonic_ns": 1643484807324199, "raw": "{\"arg\":{\"channel\":\"books\",\"instId\":\"BTC-USDT-SWAP\"},\"action\":\"update\",\"data\":[{\"asks\":[],\"bids\":[[\"64442.4\",\"0.01\",\"0\",\"1\"]],\"ts\":\"1782015928905\",\"checksum\":1492131549,\"seqId\":325069873219,\"prevSeqId\":325069873214}]}"}
{"action": null, "capture_sequence": 272, "channel": "trades", "connection_sequence": 4, "event": null, "instId": "BTC-USDT-SWAP", "local_receive_ts": "2026-06-21T04:25:29Z", "monotonic_ns": 1643484896224653, "raw": "{\"arg\":{\"channel\":\"trades\",\"instId\":\"BTC-USDT-SWAP\"},\"data\":[{\"instId\":\"BTC-USDT-SWAP\",\"tradeId\":\"2718748915\",\"px\":\"64457.9\",\"sz\":\"5\",\"side\":\"sell\",\"ts\":\"1782015928994\",\"count\":\"1\",\"source\":\"0\",\"seqId\":325069873290}]}"}
{"action": "update", "capture_sequence": 273, "channel": "books", "connection_sequence": 4, "event": null, "instId": "BTC-USDT-SWAP", "local_receive_ts": "2026-06-21T04:25:29Z", "monotonic_ns": 1643484912251886, "raw": "{\"arg\":{\"channel\":\"books\",\"instId\":\"BTC-USDT-SWAP\"},\"action\":\"update\",\"data\":[{\"asks\":[[\"64458\",\"463.46\",\"0\",\"67\"],[\"64458.5\",\"6.56\",\"0\",\"2\"],[\"64459\",\"1.56\",\"0\",\"1\"],[\"64459.5\",\"151.57\",\"0\",\"3\"],[\"64464.5\",\"0.32\",\"0\",\"3\"],[\"64465.1\",\"0\",\"0\",\"0\"],[\"64465.5\",\"0.01\",\"0\",\"1\"],[\"64465.8\",\"64.02\",\"0\",\"2\"],[\"64466.1\",\"0.01\",\"0\",\"1\"],[\"64466.4\",\"70.86\",\"0\",\"3\"],[\"64466.9\",\"1.16\",\"0\",\"1\"],[\"64467.2\",\"0\",\"0\",\"0\"],[\"64467.6\",\"0.4\",\"0\",\"3\"],[\"64467.7\",\"146.25\",\"0\",\"2\"],[\"64476.5\",\"0\",\"0\",\"0\"],[\"64476.9\",\"0.02\",\"0\",\"2\"],[\"64477.6\",\"0.08\",\"0\",\"2\"],[\"64479.9\",\"62.2\",\"0\",\"3\"],[\"64480.1\",\"0.02\",\"0\",\"2\"],[\"64483.2\",\"148.49\",\"0\",\"4\"],[\"64483.3\",\"0.06\",\"0\",\"3\"],[\"64491.1\",\"0\",\"0\",\"0\"],[\"64491.7\",\"0.02\",\"0\",\"2\"],[\"64492\",\"0.03\",\"0\",\"3\"],[\"64492.3\",\"0.03\",\"0\",\"1\"],[\"64492.7\",\"99.88\",\"0\",\"3\"],[\"64493\",\"13.72\",\"0\",\"4\"],[\"64493.5\",\"1.09\",\"0\",\"4\"],[\"64493.8\",\"0.04\",\"0\",\"3\"],[\"64494.1\",\"0\",\"0\",\"0\"],[\"64494.3\",\"15.73\",\"0\",\"5\"],[\"64508.6\",\"0.01\",\"0\",\"1\"],[\"64508.7\",\"42.88\",\"0\",\"9\"],[\"64508.8\",\"0.04\",\"0\",\"2\"],[\"64508.9\",\"11.04\",\"0\",\"3\"]],\"bids\":[[\"64457.9\",\"463.48\",\"0\",\"22\"],[\"64455.1\",\"0\",\"0\",\"0\"],[\"64450.6\",\"1.56\",\"0\",\"1\"],[\"64450\",\"0.02\",\"0\",\"2\"],[\"64449.7\",\"46.58\",\"0\",\"2\"],[\"64449.3\",\"16.22\",\"0\",\"2\"],[\"64449\",\"0.03\",\"0\",\"3\"],[\"64448.7\",\"4\",\"0\",\"1\"],[\"64448.5\",\"0\",\"0\",\"0\"],[\"64448.2\",\"247.83\",\"0\",\"3\"],[\"64447.9\",\"4\",\"0\",\"1\"],[\"64447.4\",\"10.77\",\"0\",\"2\"],[\"64442.4\",\"3.23\",\"0\",\"2\"],[\"64441.8\",\"535.35\",\"0\",\"2\"],[\"64441.7\",\"0.02\",\"0\",\"1\"],[\"64435.5\",\"512.2\",\"0\",\"3\"],[\"64405\",\"13.52\",\"0\",\"15\"]],\"ts\":\"1782015929005\",\"checksum\":2108847573,\"seqId\":325069873307,\"prevSeqId\":325069873219}]}"}
{"action": "update", "capture_sequence": 274, "channel": "books", "connection_sequence": 4, "event": null, "instId": "BTC-USDT-SWAP", "local_receive_ts": "2026-06-21T04:25:29Z", "monotonic_ns": 1643485007901784, "raw": "{\"arg\":{\"channel\":\"books\",\"instId\":\"BTC-USDT-SWAP\"},\"action\":\"update\",\"data\":[{\"asks\":[[\"64465\",\"68.79\",\"0\",\"3\"],[\"64466\",\"1.21\",\"0\",\"2\"],[\"64466.8\",\"1.2\",\"0\",\"1\"],[\"64467.5\",\"1.2\",\"0\",\"1\"],[\"64476.5\",\"0.15\",\"0\",\"1\"],[\"64484.2\",\"15.96\",\"0\",\"2\"],[\"64484.3\",\"0.77\",\"0\",\"1\"],[\"64490.7\",\"1.07\",\"0\",\"4\"],[\"64491.7\",\"1.22\",\"0\",\"3\"],[\"64492.5\",\"1.26\",\"0\",\"5\"],[\"64493.2\",\"401.02\",\"0\",\"9\"],[\"64494\",\"1.04\",\"0\",\"3\"],[\"64508.7\",\"0\",\"0\",\"0\"],[\"64508.8\",\"0\",\"0\",\"0\"],[\"64508.9\",\"0\",\"0\",\"0\"]],\"bids\":[[\"64457.9\",\"468.48\",\"0\",\"23\"],[\"64457.3\",\"0.01\",\"0\",\"1\"],[\"64457.2\",\"1.56\",\"0\",\"1\"],[\"64456.7\",\"0.01\",\"0\",\"1\"],[\"64456.6\",\"1.63\",\"0\",\"2\"],[\"64455.9\",\"1.57\",\"0\",\"2\"],[\"64455.4\",\"1.57\",\"0\",\"2\"],[\"64455.3\",\"51.44\",\"0\",\"6\"],[\"64454.9\",\"1.56\",\"0\",\"1\"],[\"64451.8\",\"77.58\",\"0\",\"2\"],[\"64451.6\",\"0.31\",\"0\",\"1\"],[\"64451.5\",\"15.9\",\"0\",\"1\"],[\"64451\",\"0.02\",\"0\",\"2\"],[\"64450.6\",\"0\",\"0\",\"0\"],[\"64450.2\",\"33.91\",\"0\",\"3\"],[\"64450.1\",\"40.77\",\"0\",\"1\"],[\"64449.2\",\"1.81\",\"0\",\"2\"],[\"64448.7\",\"6.88\",\"0\",\"2\"],[\"64448.1\",\"13.01\",\"0\",\"3\"],[\"64435.5\",\"512.39\",\"0\",\"4\"],[\"64420.3\",\"1\",\"0\",\"1\"],[\"64405.3\",\"0\",\"0\",\"0\"],[\"64405.2\",\"0\",\"0\",\"0\"],[\"64405.1\",\"0\",\"0\",\"0\"],[\"64405\",\"0\",\"0\",\"0\"]],\"ts\":\"1782015929105\",\"checksum\":-268990737,\"seqId\":325069873374,\"prevSeqId\":325069873307}]}"}
{"action": "update", "capture_sequence": 275, "channel": "books", "connection_sequence": 4, "event": null, "instId": "BTC-USDT-SWAP", "local_receive_ts": "2026-06-21T04:25:29Z", "monotonic_ns": 1643485111830616, "raw": "{\"arg\":{\"channel\":\"books\",\"instId\":\"BTC-USDT-SWAP\"},\"action\":\"update\",\"data\":[{\"asks\":[[\"64458.5\",\"5\",\"0\",\"1\"],[\"64458.9\",\"1.56\",\"0\",\"1\"],[\"64459\",\"0\",\"0\",\"0\"],[\"64460\",\"1.57\",\"0\",\"2\"],[\"64460.4\",\"1.56\",\"0\",\"1\"],[\"64460.9\",\"1.56\",\"0\",\"1\"],[\"64464.4\",\"1.3\",\"0\",\"2\"],[\"64465.4\",\"1\",\"0\",\"1\"],[\"64465.7\",\"64.9\",\"0\",\"2\"],[\"64466.3\",\"47.74\",\"0\",\"2\"],[\"64467.1\",\"1.22\",\"0\",\"2\"],[\"64467.6\",\"1.9\",\"0\",\"4\"],[\"64477.1\",\"0.01\",\"0\",\"1\"],[\"64477.6\",\"0.07\",\"0\",\"1\"],[\"64483.2\",\"114.69\",\"0\",\"3\"],[\"64483.3\",\"33.86\",\"0\",\"4\"],[\"64490.1\",\"1.01\",\"0\",\"2\"],[\"64491.1\",\"1\",\"0\",\"1\"],[\"64491.4\",\"1.22\",\"0\",\"3\"],[\"64492\",\"1.23\",\"0\",\"4\"],[\"64492.8\",\"1.33\",\"0\",\"8\"],[\"64493.3\",\"581.83\",\"0\",\"7\"],[\"64493.9\",\"210.43\",\"0\",\"1\"],[\"64500\",\"3472.67\",\"0\",\"1033\"],[\"64500.1\",\"0.07\",\"0\",\"5\"],[\"64508\",\"0\",\"0\",\"0\"],[\"64508.1\",\"0\",\"0\",\"0\"],[\"64508.2\",\"0\",\"0\",\"0\"],[\"64508.4\",\"0\",\"0\",\"0\"],[\"64508.5\",\"0\",\"0\",\"0\"],[\"64508.6\",\"0\",\"0\",\"0\"]],\"bids\":[[\"64457.2\",\"0\",\"0\",\"0\"],[\"64456.6\",\"0.07\",\"0\",\"1\"],[\"64456.4\",\"1.57\",\"0\",\"2\"],[\"64452\",\"76.66\",\"0\",\"4\"],[\"64450.8\",\"1.4\",\"0\",\"1\"],[\"64449.8\",\"1.61\",\"0\",\"2\"],[\"64449.5\",\"38.79\",\"0\",\"2\"],[\"64448.9\",\"2.16\",\"0\",\"1\"],[\"64448.3\",\"18.77\",\"0\",\"4\"],[\"64447.6\",\"2.4\",\"0\",\"1\"],[\"64444.5\",\"33.82\",\"0\",\"1\"],[\"64444.4\",\"10\",\"0\",\"1\"],[\"64441.8\",\"535.37\",\"0\",\"3\"],[\"64441.7\",\"0\",\"0\",\"0\"],[\"64421.9\",\"203.13\",\"0\",\"3\"],[\"64415.9\",\"0\",\"0\",\"0\"],[\"64415.2\",\"0.02\",\"0\",\"2\"],[\"64405.5\",\"0\",\"0\",\"0\"]],\"ts\":\"1782015929205\",\"checksum\":-595306992,\"seqId\":325069873441,\"prevSeqId\":325069873374}]}"}
{"action": "update", "capture_sequence": 276, "channel": "books", "connection_sequence": 4, "event": null, "instId": "BTC-USDT-SWAP", "local_receive_ts": "2026-06-21T04:25:29Z", "monotonic_ns": 1643485207476310, "raw": "{\"arg\":{\"channel\":\"books\",\"instId\":\"BTC-USDT-SWAP\"},\"action\":\"update\",\"data\":[{\"asks\":[[\"64458\",\"461.9\",\"0\",\"66\"],[\"64461.4\",\"1.59\",\"0\",\"4\"],[\"64461.9\",\"1.71\",\"0\",\"2\"],[\"64464.3\",\"72.21\",\"0\",\"1\"],[\"64483.1\",\"134.1\",\"0\",\"5\"],[\"64483.3\",\"0.06\",\"0\",\"3\"],[\"64488.1\",\"0.67\",\"0\",\"2\"],[\"64488.3\",\"124.2\",\"0\",\"3\"],[\"64492.6\",\"185.05\",\"0\",\"2\"],[\"64493.1\",\"31.76\",\"0\",\"5\"]],\"bids\":[[\"64457.8\",\"0.15\",\"0\",\"3\"],[\"64457.7\",\"1.56\",\"0\",\"1\"],[\"64457.3\",\"0\",\"0\",\"0\"],[\"64456.7\",\"0\",\"0\",\"0\"],[\"64456.5\",\"0.01\",\"0\",\"1\"],[\"64453.9\",\"1.57\",\"0\",\"2\"],[\"64444.5\",\"0\",\"0\",\"0\"],[\"64443.9\",\"33.82\",\"0\",\"1\"]],\"ts\":\"1782015929305\",\"checksum\":406569635,\"seqId\":325069873503,\"prevSeqId\":325069873441}]}"}
{"action": "update", "capture_sequence": 277, "channel": "books", "connection_sequence": 4, "event": null, "instId": "BTC-USDT-SWAP", "local_receive_ts": "2026-06-21T04:25:29Z", "monotonic_ns": 1643485308405873, "raw": "{\"arg\":{\"channel\":\"books\",\"instId\":\"BTC-USDT-SWAP\"},\"action\":\"update\",\"data\":[{\"asks\":[[\"64458\",\"463.56\",\"0\",\"68\"],[\"64463.8\",\"0.01\",\"0\",\"1\"],[\"64487.9\",\"143.58\",\"0\",\"3\"],[\"64488.3\",\"38.84\",\"0\",\"2\"],[\"64493.9\",\"230.5\",\"0\",\"2\"],[\"64494.5\",\"0\",\"0\",\"0\"],[\"64508\",\"13.54\",\"0\",\"7\"]],\"bids\":[[\"64457.8\",\"0.14\",\"0\",\"2\"],[\"64457.7\",\"0\",\"0\",\"0\"],[\"64456.5\",\"0\",\"0\",\"0\"],[\"64456\",\"0.03\",\"0\",\"3\"],[\"64455.5\",\"0.01\",\"0\",\"1\"],[\"64452\",\"78.22\",\"0\",\"5\"],[\"64443.8\",\"0\",\"0\",\"0\"],[\"64443.5\",\"106.29\",\"0\",\"2\"],[\"64405.5\",\"0.01\",\"0\",\"1\"],[\"64405.3\",\"46.54\",\"0\",\"1\"]],\"ts\":\"1782015929405\",\"checksum\":89016564,\"seqId\":325069873543,\"prevSeqId\":325069873503}]}"}
{"action": "update", "capture_sequence": 278, "channel": "books", "connection_sequence": 4, "event": null, "instId": "BTC-USDT-SWAP", "local_receive_ts": "2026-06-21T04:25:29Z", "monotonic_ns": 1643485407507359, "raw": "{\"arg\":{\"channel\":\"books\",\"instId\":\"BTC-USDT-SWAP\"},\"action\":\"update\",\"data\":[{\"asks\":[[\"64458\",\"462\",\"0\",\"67\"],[\"64458.3\",\"59.85\",\"0\",\"4\"],[\"64460.8\",\"43.4\",\"0\",\"2\"],[\"64463.9\",\"31.05\",\"0\",\"1\"],[\"64464\",\"119.81\",\"0\",\"4\"],[\"64464.1\",\"0.8\",\"0\",\"4\"],[\"64476.5\",\"0\",\"0\",\"0\"],[\"64487.4\",\"58.69\",\"0\",\"6\"],[\"64487.9\",\"85.38\",\"0\",\"2\"],[\"64492.5\",\"87.4\",\"0\",\"6\"],[\"64492.6\",\"98.92\",\"0\",\"1\"],[\"64493.5\",\"21.16\",\"0\",\"5\"],[\"64493.9\",\"210.43\",\"0\",\"1\"]],\"bids\":[[\"64456.8\",\"0.32\",\"0\",\"2\"],[\"64456.7\",\"1.56\",\"0\",\"1\"],[\"64456.4\",\"0.01\",\"0\",\"1\"],[\"64456\",\"0.02\",\"0\",\"2\"],[\"64455.9\",\"0.01\",\"0\",\"1\"],[\"64443.6\",\"86.21\",\"0\",\"2\"],[\"64443.5\",\"0\",\"0\",\"0\"],[\"64442.9\",\"20.09\",\"0\",\"1\"],[\"64442.7\",\"0\",\"0\",\"0\"],[\"64442.4\",\"85.44\",\"0\",\"2\"],[\"64439.8\",\"0\",\"0\",\"0\"],[\"64439\",\"58.26\",\"0\",\"2\"],[\"64435.5\",\"512.2\",\"0\",\"3\"],[\"64405.2\",\"6.39\",\"0\",\"4\"]],\"ts\":\"1782015929505\",\"checksum\":2091545182,\"seqId\":325069873655,\"prevSeqId\":325069873543}]}"}
{"action": "update", "capture_sequence": 279, "channel": "books", "connection_sequence": 4, "event": null, "instId": "BTC-USDT-SWAP", "local_receive_ts": "2026-06-21T04:25:29Z", "monotonic_ns": 1643485507365110, "raw": "{\"arg\":{\"channel\":\"books\",\"instId\":\"BTC-USDT-SWAP\"},\"action\":\"update\",\"data\":[{\"asks\":[[\"64465.9\",\"0.02\",\"0\",\"1\"],[\"64467.1\",\"1.2\",\"0\",\"1\"],[\"64476.5\",\"0.15\",\"0\",\"1\"],[\"64488\",\"57.89\",\"0\",\"28\"],[\"64488.8\",\"50\",\"0\",\"1\"],[\"64500\",\"3472.69\",\"0\",\"1034\"],[\"64500.1\",\"0.05\",\"0\",\"4\"],[\"64507.9\",\"0\",\"0\",\"0\"],[\"64508\",\"0\",\"0\",\"0\"]],\"bids\":[[\"64442.4\",\"88.66\",\"0\",\"3\"],[\"64435.5\",\"512.39\",\"0\",\"4\"],[\"64415.9\",\"0.01\",\"0\",\"1\"],[\"64415.2\",\"0.01\",\"0\",\"1\"],[\"64405.2\",\"0\",\"0\",\"0\"]],\"ts\":\"1782015929605\",\"checksum\":2091545182,\"seqId\":325069873673,\"prevSeqId\":325069873655}]}"}
{"action": "update", "capture_sequence": 280, "channel": "books", "connection_sequence": 4, "event": null, "instId": "BTC-USDT-SWAP", "local_receive_ts": "2026-06-21T04:25:29Z", "monotonic_ns": 1643485607998879, "raw": "{\"arg\":{\"channel\":\"books\",\"instId\":\"BTC-USDT-SWAP\"},\"action\":\"update\",\"data\":[{\"asks\":[[\"64458.1\",\"0.04\",\"0\",\"4\"],[\"64458.3\",\"58.3\",\"0\",\"4\"],[\"64458.4\",\"1.57\",\"0\",\"2\"],[\"64458.6\",\"0.01\",\"0\",\"1\"],[\"64458.9\",\"0\",\"0\",\"0\"],[\"64459\",\"1.56\",\"0\",\"1\"],[\"64460.8\",\"41.74\",\"0\",\"2\"],[\"64464\",\"114.04\",\"0\",\"4\"],[\"64465.9\",\"0\",\"0\",\"0\"],[\"64466.4\",\"70.88\",\"0\",\"4\"],[\"64488\",\"57.87\",\"0\",\"27\"],[\"64488.1\",\"0.69\",\"0\",\"3\"],[\"64507.9\",\"0.25\",\"0\",\"2\"]],\"bids\":[[\"64457.9\",\"467.96\",\"0\",\"22\"],[\"64456.8\",\"0.31\",\"0\",\"1\"],[\"64456.7\",\"0\",\"0\",\"0\"],[\"64456.1\",\"0.02\",\"0\",\"2\"],[\"64452.7\",\"0.45\",\"0\",\"2\"],[\"64452\",\"76.66\",\"0\",\"4\"],[\"64443.6\",\"0.01\",\"0\",\"1\"],[\"64443.3\",\"216.32\",\"0\",\"5\"],[\"64405.2\",\"6.39\",\"0\",\"4\"]],\"ts\":\"1782015929705\",\"checksum\":1227355030,\"seqId\":325069873831,\"prevSeqId\":325069873673}]}"}
{"action": null, "capture_sequence": 281, "channel": "trades", "connection_sequence": 4, "event": null, "instId": "BTC-USDT-SWAP", "local_receive_ts": "2026-06-21T04:25:29Z", "monotonic_ns": 1643485612055333, "raw": "{\"arg\":{\"channel\":\"trades\",\"instId\":\"BTC-USDT-SWAP\"},\"data\":[{\"instId\":\"BTC-USDT-SWAP\",\"tradeId\":\"2718748916\",\"px\":\"64458\",\"sz\":\"7\",\"side\":\"buy\",\"ts\":\"1782015929710\",\"count\":\"1\",\"source\":\"0\",\"seqId\":325069873839}]}"}
{"action": "update", "capture_sequence": 282, "channel": "books", "connection_sequence": 4, "event": null, "instId": "BTC-USDT-SWAP", "local_receive_ts": "2026-06-21T04:25:29Z", "monotonic_ns": 1643485707437384, "raw": "{\"arg\":{\"channel\":\"books\",\"instId\":\"BTC-USDT-SWAP\"},\"action\":\"update\",\"data\":[{\"asks\":[[\"64458\",\"455\",\"0\",\"67\"],[\"64458.3\",\"58.29\",\"0\",\"3\"],[\"64458.4\",\"0.01\",\"0\",\"1\"],[\"64458.6\",\"0.02\",\"0\",\"2\"],[\"64459\",\"0\",\"0\",\"0\"],[\"64459.5\",\"150.01\",\"0\",\"2\"],[\"64460\",\"0.01\",\"0\",\"1\"],[\"64460.4\",\"0\",\"0\",\"0\"],[\"64460.9\",\"0\",\"0\",\"0\"],[\"64508\",\"13.54\",\"0\",\"7\"],[\"64508.1\",\"21.31\",\"0\",\"3\"],[\"64508.2\",\"59.01\",\"0\",\"5\"]],\"bids\":[[\"64456.1\",\"0.01\",\"0\",\"1\"],[\"64455.4\",\"1.58\",\"0\",\"3\"]],\"ts\":\"1782015929805\",\"checksum\":-1885305917,\"seqId\":325069873857,\"prevSeqId\":325069873831}]}"}
{"action": "update", "capture_sequence": 283, "channel": "books", "connection_sequence": 4, "event": null, "instId": "BTC-USDT-SWAP", "local_receive_ts": "2026-06-21T04:25:30Z", "monotonic_ns": 1643485807416537, "raw": "{\"arg\":{\"channel\":\"books\",\"instId\":\"BTC-USDT-SWAP\"},\"action\":\"update\",\"data\":[{\"asks\":[[\"64487.4\",\"144.06\",\"0\",\"7\"],[\"64487.9\",\"0.01\",\"0\",\"1\"]],\"bids\":[[\"64457.9\",\"468.48\",\"0\",\"22\"],[\"64455.3\",\"48.67\",\"0\",\"2\"],[\"64454.7\",\"47.63\",\"0\",\"8\"],[\"64449.6\",\"508.53\",\"0\",\"3\"],[\"64448\",\"270.1\",\"0\",\"5\"],[\"64442.4\",\"3.23\",\"0\",\"2\"],[\"64442.1\",\"91.65\",\"0\",\"2\"],[\"64440.5\",\"0\",\"0\",\"0\"],[\"64405.1\",\"0.07\",\"0\",\"3\"]],\"ts\":\"1782015929905\",\"checksum\":-2120536925,\"seqId\":325069873879,\"prevSeqId\":325069873857}]}"}
{"action": "update", "capture_sequence": 284, "channel": "books", "connection_sequence": 4, "event": null, "instId": "BTC-USDT-SWAP", "local_receive_ts": "2026-06-21T04:25:30Z", "monotonic_ns": 1643485907980380, "raw": "{\"arg\":{\"channel\":\"books\",\"instId\":\"BTC-USDT-SWAP\"},\"action\":\"update\",\"data\":[{\"asks\":[[\"64458\",\"456.56\",\"0\",\"68\"],[\"64458.5\",\"6.56\",\"0\",\"2\"],[\"64459\",\"1.56\",\"0\",\"1\"],[\"64459.5\",\"151.57\",\"0\",\"3\"],[\"64476.5\",\"0\",\"0\",\"0\"],[\"64482.6\",\"33.81\",\"0\",\"2\"],[\"64483.1\",\"100.3\",\"0\",\"4\"],[\"64486.5\",\"73.85\",\"0\",\"2\"],[\"64487.3\",\"85.41\",\"0\",\"3\"],[\"64487.4\",\"0.49\",\"0\",\"5\"],[\"64492.5\",\"1.26\",\"0\",\"5\"],[\"64492.6\",\"86.14\",\"0\",\"1\"]],\"bids\":[[\"64456.5\",\"1.56\",\"0\",\"1\"],[\"64443.9\",\"0\",\"0\",\"0\"],[\"64443.5\",\"33.82\",\"0\",\"1\"],[\"64443.3\",\"117.29\",\"0\",\"4\"],[\"64439\",\"0.01\",\"0\",\"1\"],[\"64438.7\",\"93.3\",\"0\",\"3\"],[\"64435.5\",\"512.2\",\"0\",\"3\"],[\"64405.1\",\"0\",\"0\",\"0\"]],\"ts\":\"1782015930005\",\"checksum\":-2056465448,\"seqId\":325069873915,\"prevSeqId\":325069873879}]}"}
{"action": null, "capture_sequence": 285, "channel": "trades", "connection_sequence": 4, "event": null, "instId": "BTC-USDT-SWAP", "local_receive_ts": "2026-06-21T04:25:30Z", "monotonic_ns": 1643485980710271, "raw": "{\"arg\":{\"channel\":\"trades\",\"instId\":\"BTC-USDT-SWAP\"},\"data\":[{\"instId\":\"BTC-USDT-SWAP\",\"tradeId\":\"2718748917\",\"px\":\"64458\",\"sz\":\"0.77\",\"side\":\"buy\",\"ts\":\"1782015930078\",\"count\":\"1\",\"source\":\"0\",\"seqId\":325069873978}]}"}
{"action": null, "capture_sequence": 286, "channel": "trades", "connection_sequence": 4, "event": null, "instId": "BTC-USDT-SWAP", "local_receive_ts": "2026-06-21T04:25:30Z", "monotonic_ns": 1643485980976451, "raw": "{\"arg\":{\"channel\":\"trades\",\"instId\":\"BTC-USDT-SWAP\"},\"data\":[{\"instId\":\"BTC-USDT-SWAP\",\"tradeId\":\"2718748918\",\"px\":\"64458\",\"sz\":\"0.67\",\"side\":\"buy\",\"ts\":\"1782015930078\",\"count\":\"1\",\"source\":\"0\",\"seqId\":325069873980}]}"}
{"action": null, "capture_sequence": 287, "channel": "trades", "connection_sequence": 4, "event": null, "instId": "BTC-USDT-SWAP", "local_receive_ts": "2026-06-21T04:25:30Z", "monotonic_ns": 1643485981803288, "raw": "{\"arg\":{\"channel\":\"trades\",\"instId\":\"BTC-USDT-SWAP\"},\"data\":[{\"instId\":\"BTC-USDT-SWAP\",\"tradeId\":\"2718748919\",\"px\":\"64458\",\"sz\":\"0.85\",\"side\":\"buy\",\"ts\":\"1782015930079\",\"count\":\"1\",\"source\":\"0\",\"seqId\":325069873982}]}"}
{"action": "update", "capture_sequence": 288, "channel": "books", "connection_sequence": 4, "event": null, "instId": "BTC-USDT-SWAP", "local_receive_ts": "2026-06-21T04:25:30Z", "monotonic_ns": 1643486011937973, "raw": "{\"arg\":{\"channel\":\"books\",\"instId\":\"BTC-USDT-SWAP\"},\"action\":\"update\",\"data\":[{\"asks\":[[\"64458\",\"452.71\",\"0\",\"67\"],[\"64458.3\",\"8.29\",\"0\",\"3\"],[\"64458.5\",\"5\",\"0\",\"1\"],[\"64459\",\"0\",\"0\",\"0\"],[\"64459.5\",\"1.57\",\"0\",\"2\"],[\"64460\",\"1.57\",\"0\",\"2\"],[\"64460.4\",\"1.56\",\"0\",\"1\"],[\"64460.8\",\"91.14\",\"0\",\"1\"],[\"64460.9\",\"1.56\",\"0\",\"1\"],[\"64461.3\",\"150\",\"0\",\"1\"],[\"64476.5\",\"0.15\",\"0\",\"1\"],[\"64476.9\",\"0.03\",\"0\",\"3\"],[\"64477.1\",\"0\",\"0\",\"0\"],[\"64479.9\",\"62.21\",\"0\",\"4\"],[\"64480.1\",\"0.01\",\"0\",\"1\"],[\"64483.1\",\"100.31\",\"0\",\"5\"],[\"64483.3\",\"0.05\",\"0\",\"2\"],[\"64484.1\",\"1.1\",\"0\",\"3\"],[\"64484.2\",\"15.65\",\"0\",\"1\"],[\"64484.3\",\"0\",\"0\",\"0\"],[\"64486.4\",\"59.47\",\"0\",\"3\"],[\"64486.5\",\"15.65\",\"0\",\"1\"],[\"64487.3\",\"0.04\",\"0\",\"2\"],[\"64487.4\",\"85.86\",\"0\",\"6\"],[\"64508.2\",\"0\",\"0\",\"0\"]],\"bids\":[[\"64457.6\",\"0.48\",\"0\",\"3\"],[\"64457.5\",\"1.56\",\"0\",\"1\"],[\"64457.2\",\"0.01\",\"0\",\"1\"],[\"64457.1\",\"1.57\",\"0\",\"2\"],[\"64456.6\",\"1.63\",\"0\",\"2\"],[\"64456.5\",\"0\",\"0\",\"0\"],[\"64456.1\",\"1.57\",\"0\",\"2\"],[\"64455.5\",\"0\",\"0\",\"0\"],[\"64455.4\",\"1.57\",\"0\",\"2\"],[\"64452.5\",\"0.01\",\"0\",\"1\"],[\"64451.6\",\"0\",\"0\",\"0\"],[\"64451.5\",\"16.21\",\"0\",\"2\"],[\"64451.3\",\"11.39\",\"0\",\"4\"],[\"64441.8\",\"535.35\",\"0\",\"2\"],[\"64441.7\",\"0.02\",\"0\",\"1\"],[\"64441.5\",\"61.29\",\"0\",\"2\"],[\"64441.4\",\"50.04\",\"0\",\"4\"],[\"64438.8\",\"31.06\",\"0\",\"1\"],[\"64438.7\",\"3.99\",\"0\",\"1\"],[\"64438.6\",\"71.03\",\"0\",\"5\"],[\"64437.3\",\"15.67\",\"0\",\"2\"],[\"64435.5\",\"512.39\",\"0\",\"4\"],[\"64431.9\",\"17.93\",\"0\",\"2\"],[\"64431.6\",\"496.54\",\"0\",\"2\"],[\"64415.9\",\"0\",\"0\",\"0\"],[\"64415.2\",\"0.02\",\"0\",\"2\"]],\"ts\":\"1782015930105\",\"checksum\":-1687682346,\"seqId\":325069874015,\"prevSeqId\":325069873915}]}"}
{"action": "update", "capture_sequence": 289, "channel": "books", "connection_sequence": 4, "event": null, "instId": "BTC-USDT-SWAP", "local_receive_ts": "2026-06-21T04:25:30Z", "monotonic_ns": 1643486107180582, "raw": "{\"arg\":{\"channel\":\"books\",\"instId\":\"BTC-USDT-SWAP\"},\"action\":\"update\",\"data\":[{\"asks\":[[\"64458.3\",\"21.98\",\"0\",\"4\"],[\"64458.9\",\"1.56\",\"0\",\"1\"],[\"64465.9\",\"0.02\",\"0\",\"1\"],[\"64466.4\",\"70.86\",\"0\",\"3\"],[\"64483.1\",\"100.3\",\"0\",\"4\"],[\"64483.2\",\"114.7\",\"0\",\"4\"],[\"64508\",\"0\",\"0\",\"0\"],[\"64508.1\",\"0\",\"0\",\"0\"]],\"bids\":[],\"ts\":\"1782015930205\",\"checksum\":1623046692,\"seqId\":325069874043,\"prevSeqId\":325069874015}]}"}
{"action": "update", "capture_sequence": 290, "channel": "books", "connection_sequence": 4, "event": null, "instId": "BTC-USDT-SWAP", "local_receive_ts": "2026-06-21T04:25:30Z", "monotonic_ns": 1643486207599880, "raw": "{\"arg\":{\"channel\":\"books\",\"instId\":\"BTC-USDT-SWAP\"},\"action\":\"update\",\"data\":[{\"asks\":[[\"64458.5\",\"6.56\",\"0\",\"2\"],[\"64458.9\",\"0\",\"0\",\"0\"],[\"64459.3\",\"1.04\",\"0\",\"5\"],[\"64459.4\",\"1.56\",\"0\",\"1\"],[\"64459.5\",\"0.01\",\"0\",\"1\"],[\"64463.8\",\"1.57\",\"0\",\"2\"],[\"64508\",\"13.54\",\"0\",\"7\"]],\"bids\":[[\"64457.6\",\"0.47\",\"0\",\"2\"],[\"64457.1\",\"0.01\",\"0\",\"1\"],[\"64457\",\"6.57\",\"0\",\"3\"],[\"64456.7\",\"0.01\",\"0\",\"1\"],[\"64447.1\",\"0\",\"0\",\"0\"],[\"64445.5\",\"22.3\",\"0\",\"2\"],[\"64445.2\",\"0\",\"0\",\"0\"],[\"64445.1\",\"185.38\",\"0\",\"5\"],[\"64405.1\",\"0.07\",\"0\",\"3\"]],\"ts\":\"1782015930305\",\"checksum\":-342795597,\"seqId\":325069874082,\"prevSeqId\":325069874043}]}"}
{"action": "update", "capture_sequence": 291, "channel": "books", "connection_sequence": 4, "event": null, "instId": "BTC-USDT-SWAP", "local_receive_ts": "2026-06-21T04:25:30Z", "monotonic_ns": 1643486314778258, "raw": "{\"arg\":{\"channel\":\"books\",\"instId\":\"BTC-USDT-SWAP\"},\"action\":\"update\",\"data\":[{\"asks\":[[\"64458.5\",\"5\",\"0\",\"1\"],[\"64458.9\",\"1.56\",\"0\",\"1\"],[\"64460\",\"0.01\",\"0\",\"1\"],[\"64460.3\",\"1.56\",\"0\",\"1\"],[\"64460.4\",\"0\",\"0\",\"0\"],[\"64464.2\",\"211.46\",\"0\",\"3\"],[\"64476.5\",\"0\",\"0\",\"0\"]],\"bids\":[[\"64457.9\",\"467.31\",\"0\",\"21\"],[\"64457.6\",\"0.48\",\"0\",\"3\"],[\"64457.2\",\"0\",\"0\",\"0\"],[\"64442.4\",\"0.01\",\"0\",\"1\"],[\"64435.5\",\"512.2\",\"0\",\"3\"],[\"64405\",\"13.52\",\"0\",\"15\"]],\"ts\":\"1782015930405\",\"checksum\":-963813986,\"seqId\":325069874128,\"prevSeqId\":325069874082}]}"}
{"action": "update", "capture_sequence": 292, "channel": "books", "connection_sequence": 4, "event": null, "instId": "BTC-USDT-SWAP", "local_receive_ts": "2026-06-21T04:25:30Z", "monotonic_ns": 1643486407919268, "raw": "{\"arg\":{\"channel\":\"books\",\"instId\":\"BTC-USDT-SWAP\"},\"action\":\"update\",\"data\":[{\"asks\":[[\"64458\",\"452.75\",\"0\",\"68\"],[\"64458.3\",\"8.29\",\"0\",\"3\"],[\"64458.9\",\"0\",\"0\",\"0\"],[\"64459.4\",\"0\",\"0\",\"0\"],[\"64465.9\",\"0\",\"0\",\"0\"],[\"64466.4\",\"70.88\",\"0\",\"4\"],[\"64476.5\",\"0.15\",\"0\",\"1\"],[\"64483.8\",\"0.77\",\"0\",\"1\"],[\"64484\",\"0.33\",\"0\",\"3\"],[\"64484.1\",\"0.02\",\"0\",\"1\"],[\"64486.4\",\"1.27\",\"0\",\"2\"],[\"64486.7\",\"58.21\",\"0\",\"2\"],[\"64505.3\",\"2.16\",\"0\",\"3\"],[\"64508.1\",\"21.31\",\"0\",\"3\"]],\"bids\":[[\"64457.9\",\"468.87\",\"0\",\"22\"],[\"64457.6\",\"0.47\",\"0\",\"2\"],[\"64457.5\",\"0\",\"0\",\"0\"],[\"64456.7\",\"0\",\"0\",\"0\"],[\"64456.6\",\"0.07\",\"0\",\"1\"],[\"64456.5\",\"0.01\",\"0\",\"1\"],[\"64456.4\",\"1.57\",\"0\",\"2\"],[\"64456.1\",\"0.01\",\"0\",\"1\"],[\"64456\",\"0.03\",\"0\",\"3\"],[\"64455.9\",\"1.57\",\"0\",\"2\"],[\"64442.4\",\"3.23\",\"0\",\"2\"],[\"64438.8\",\"89.31\",\"0\",\"2\"],[\"64438.6\",\"12.78\",\"0\",\"4\"],[\"64435.5\",\"512.39\",\"0\",\"4\"],[\"64404.8\",\"0.04\",\"0\",\"1\"]],\"ts\":\"1782015930505\",\"checksum\":-1197224162,\"seqId\":325069874187,\"prevSeqId\":325069874128}]}"}
{"action": "update", "capture_sequence": 293, "channel": "books", "connection_sequence": 4, "event": null, "instId": "BTC-USDT-SWAP", "local_receive_ts": "2026-06-21T04:25:30Z", "monotonic_ns": 1643486507929822, "raw": "{\"arg\":{\"channel\":\"books\",\"instId\":\"BTC-USDT-SWAP\"},\"action\":\"update\",\"data\":[{\"asks\":[[\"64459.1\",\"0.01\",\"0\",\"1\"],[\"64459.2\",\"1.57\",\"0\",\"2\"],[\"64459.3\",\"1.03\",\"0\",\"4\"],[\"64460.3\",\"0\",\"0\",\"0\"],[\"64460.4\",\"1.56\",\"0\",\"1\"],[\"64460.8\",\"63.6\",\"0\",\"1\"],[\"64463.9\",\"0\",\"0\",\"0\"],[\"64464\",\"0.79\",\"0\",\"3\"],[\"64464.1\",\"31.85\",\"0\",\"5\"],[\"64464.7\",\"1.57\",\"0\",\"2\"]],\"bids\":[[\"64457.9\",\"467.31\",\"0\",\"21\"],[\"64457.8\",\"0.15\",\"0\",\"3\"],[\"64457.7\",\"1.56\",\"0\",\"1\"],[\"64457.2\",\"0.01\",\"0\",\"1\"],[\"64457.1\",\"1.57\",\"0\",\"2\"],[\"64457\",\"5.01\",\"0\",\"2\"],[\"64456.5\",\"1.56\",\"0\",\"1\"],[\"64456.4\",\"0.01\",\"0\",\"1\"],[\"64456\",\"0.02\",\"0\",\"2\"],[\"64405\",\"0\",\"0\",\"0\"],[\"64404.8\",\"0\",\"0\",\"0\"]],\"ts\":\"1782015930605\",\"checksum\":-393156022,\"seqId\":325069874234,\"prevSeqId\":325069874187}]}"}
{"action": "update", "capture_sequence": 294, "channel": "books", "connection_sequence": 4, "event": null, "instId": "BTC-USDT-SWAP", "local_receive_ts": "2026-06-21T04:25:30Z", "monotonic_ns": 1643486607793397, "raw": "{\"arg\":{\"channel\":\"books\",\"instId\":\"BTC-USDT-SWAP\"},\"action\":\"update\",\"data\":[{\"asks\":[[\"64459.2\",\"0.01\",\"0\",\"1\"],[\"64460.8\",\"91\",\"0\",\"2\"],[\"64463.9\",\"31.05\",\"0\",\"1\"],[\"64464\",\"119.81\",\"0\",\"4\"],[\"64464.1\",\"0.8\",\"0\",\"4\"],[\"64476.5\",\"0\",\"0\",\"0\"],[\"64484\",\"0.02\",\"0\",\"2\"],[\"64484.1\",\"0.33\",\"0\",\"2\"],[\"64488.1\",\"0.67\",\"0\",\"2\"],[\"64488.2\",\"3.98\",\"0\",\"3\"],[\"64493.3\",\"601.9\",\"0\",\"8\"],[\"64493.5\",\"1.09\",\"0\",\"4\"]],\"bids\":[[\"64457.9\",\"468.03\",\"0\",\"23\"],[\"64457.4\",\"0.18\",\"0\",\"1\"],[\"64456.8\",\"0\",\"0\",\"0\"],[\"64445.1\",\"184.61\",\"0\",\"4\"],[\"64444.5\",\"0.77\",\"0\",\"1\"],[\"64443.5\",\"0\",\"0\",\"0\"],[\"64443.4\",\"437.49\",\"0\",\"2\"],[\"64442.4\",\"0.01\",\"0\",\"1\"],[\"64442.1\",\"6.22\",\"0\",\"1\"],[\"64441.7\",\"85.45\",\"0\",\"2\"],[\"64438.8\",\"58.25\",\"0\",\"1\"],[\"64438.7\",\"35.05\",\"0\",\"2\"],[\"64435.5\",\"512.2\",\"0\",\"3\"],[\"64405\",\"13.52\",\"0\",\"15\"]],\"ts\":\"1782015930705\",\"checksum\":-1617131683,\"seqId\":325069874323,\"prevSeqId\":325069874234}]}"}
{"action": "update", "capture_sequence": 295, "channel": "books", "connection_sequence": 4, "event": null, "instId": "BTC-USDT-SWAP", "local_receive_ts": "2026-06-21T04:25:30Z", "monotonic_ns": 1643486707792091, "raw": "{\"arg\":{\"channel\":\"books\",\"instId\":\"BTC-USDT-SWAP\"},\"action\":\"update\",\"data\":[{\"asks\":[[\"64458\",\"452.85\",\"0\",\"69\"],[\"64460.4\",\"0\",\"0\",\"0\"],[\"64460.9\",\"0\",\"0\",\"0\"],[\"64476.4\",\"0.16\",\"0\",\"1\"],[\"64508.2\",\"59.01\",\"0\",\"5\"]],\"bids\":[[\"64442.3\",\"21.24\",\"0\",\"3\"],[\"64435.5\",\"512.39\",\"0\",\"4\"]],\"ts\":\"1782015930805\",\"checksum\":952789831,\"seqId\":325069874329,\"prevSeqId\":325069874323}]}"}
{"action": null, "capture_sequence": 296, "channel": "trades", "connection_sequence": 4, "event": null, "instId": "BTC-USDT-SWAP", "local_receive_ts": "2026-06-21T04:25:30Z", "monotonic_ns": 1643486768887209, "raw": "{\"arg\":{\"channel\":\"trades\",\"instId\":\"BTC-USDT-SWAP\"},\"data\":[{\"instId\":\"BTC-USDT-SWAP\",\"tradeId\":\"2718748922\",\"px\":\"64458\",\"sz\":\"22.93\",\"side\":\"buy\",\"ts\":\"1782015930865\",\"count\":\"3\",\"source\":\"0\",\"seqId\":325069874361}]}"}
{"action": "update", "capture_sequence": 297, "channel": "books", "connection_sequence": 4, "event": null, "instId": "BTC-USDT-SWAP", "local_receive_ts": "2026-06-21T04:25:31Z", "monotonic_ns": 1643486808531757, "raw": "{\"arg\":{\"channel\":\"books\",\"instId\":\"BTC-USDT-SWAP\"},\"action\":\"update\",\"data\":[{\"asks\":[[\"64458\",\"452.38\",\"0\",\"68\"],[\"64459.1\",\"0\",\"0\",\"0\"],[\"64460.8\",\"63.6\",\"0\",\"1\"],[\"64461.2\",\"0.01\",\"0\",\"1\"],[\"64463.9\",\"0\",\"0\",\"0\"],[\"64464\",\"0.95\",\"0\",\"4\"],[\"64464.1\",\"31.85\",\"0\",\"5\"],[\"64466.4\",\"70.86\",\"0\",\"3\"],[\"64467.1\",\"1.22\",\"0\",\"2\"],[\"64486.3\",\"238.1\",\"0\",\"5\"],[\"64486.7\",\"0.01\",\"0\",\"1\"],[\"64488.2\",\"3.96\",\"0\",\"2\"],[\"64488.8\",\"50.02\",\"0\",\"2\"],[\"64508.4\",\"1367.19\",\"0\",\"6\"]],\"bids\":[[\"64457.9\",\"435.1\",\"0\",\"21\"],[\"64457.8\",\"0.14\",\"0\",\"2\"],[\"64457.7\",\"0\",\"0\",\"0\"],[\"64457.2\",\"0\",\"0\",\"0\"],[\"64457.1\",\"0.01\",\"0\",\"1\"],[\"64456.5\",\"0\",\"0\",\"0\"],[\"64455.9\",\"0.01\",\"0\",\"1\"],[\"64455.4\",\"0.02\",\"0\",\"2\"],[\"64455.3\",\"48.68\",\"0\",\"3\"],[\"64443.5\",\"33.82\",\"0\",\"1\"],[\"64443.4\",\"403.67\",\"0\",\"1\"],[\"64438.8\",\"0\",\"0\",\"0\"],[\"64438.2\",\"58.26\",\"0\",\"2\"],[\"64404.8\",\"0.04\",\"0\",\"1\"],[\"64404.7\",\"0.77\",\"0\",\"1\"],[\"64404.5\",\"0.16\",\"0\",\"2\"]],\"ts\":\"1782015930905\",\"checksum\":-1890878,\"seqId\":325069874393,\"prevSeqId\":325069874329}]}"}
{"action": "update", "capture_sequence": 298, "channel": "books", "connection_sequence": 4, "event": null, "instId": "BTC-USDT-SWAP", "local_receive_ts": "2026-06-21T04:25:31Z", "monotonic_ns": 1643486908081219, "raw": "{\"arg\":{\"channel\":\"books\",\"instId\":\"BTC-USDT-SWAP\"},\"action\":\"update\",\"data\":[{\"asks\":[[\"64461.4\",\"0.03\",\"0\",\"3\"],[\"64461.6\",\"1.56\",\"0\",\"1\"],[\"64461.9\",\"0.15\",\"0\",\"1\"],[\"64462\",\"1.6\",\"0\",\"5\"],[\"64462.5\",\"1.56\",\"0\",\"1\"],[\"64462.8\",\"0\",\"0\",\"0\"],[\"64464\",\"1.72\",\"0\",\"5\"],[\"64464.1\",\"31.08\",\"0\",\"4\"],[\"64465.2\",\"79.31\",\"0\",\"3\"],[\"64483.8\",\"0\",\"0\",\"0\"],[\"64484.1\",\"1.1\",\"0\",\"3\"],[\"64486.3\",\"179.9\",\"0\",\"4\"],[\"64487.3\",\"58.24\",\"0\",\"3\"],[\"64493.3\",\"581.83\",\"0\",\"7\"],[\"64493.6\",\"168.93\",\"0\",\"2\"]],\"bids\":[[\"64457.9\",\"446.66\",\"0\",\"23\"],[\"64457.4\",\"1.74\",\"0\",\"2\"],[\"64456.9\",\"1.56\",\"0\",\"1\"],[\"64455.9\",\"0.02\",\"0\",\"2\"],[\"64455.8\",\"87.77\",\"0\",\"2\"],[\"64455.7\",\"119.02\",\"0\",\"1\"],[\"64455.4\",\"0.01\",\"0\",\"1\"],[\"64455.3\",\"0.01\",\"0\",\"1\"],[\"64452.4\",\"12.43\",\"0\",\"2\"],[\"64452.3\",\"31.84\",\"0\",\"3\"],[\"64445.1\",\"185.38\",\"0\",\"5\"],[\"64444.5\",\"0\",\"0\",\"0\"],[\"64442.2\",\"85.43\",\"0\",\"1\"],[\"64441.7\",\"0.02\",\"0\",\"1\"],[\"64439.4\",\"58.26\",\"0\",\"2\"],[\"64438.2\",\"0.01\",\"0\",\"1\"],[\"64431.4\",\"99.59\",\"0\",\"2\"],[\"64404.8\",\"0\",\"0\",\"0\"],[\"64404.7\",\"0\",\"0\",\"0\"],[\"64404.5\",\"0\",\"0\",\"0\"]],\"ts\":\"1782015931005\",\"checksum\":-300902149,\"seqId\":325069874513,\"prevSeqId\":325069874393}]}"}
{"action": null, "capture_sequence": 299, "channel": "trades", "connection_sequence": 4, "event": null, "instId": "BTC-USDT-SWAP", "local_receive_ts": "2026-06-21T04:25:31Z", "monotonic_ns": 1643486931287175, "raw": "{\"arg\":{\"channel\":\"trades\",\"instId\":\"BTC-USDT-SWAP\"},\"data\":[{\"instId\":\"BTC-USDT-SWAP\",\"tradeId\":\"2718748923\",\"px\":\"64458\",\"sz\":\"0.69\",\"side\":\"buy\",\"ts\":\"1782015931029\",\"count\":\"1\",\"source\":\"0\",\"seqId\":325069874581}]}"}
{"action": null, "capture_sequence": 300, "channel": "trades", "connection_sequence": 4, "event": null, "instId": "BTC-USDT-SWAP", "local_receive_ts": "2026-06-21T04:25:31Z", "monotonic_ns": 1643486932192627, "raw": "{\"arg\":{\"channel\":\"trades\",\"instId\":\"BTC-USDT-SWAP\"},\"data\":[{\"instId\":\"BTC-USDT-SWAP\",\"tradeId\":\"2718748924\",\"px\":\"64457.9\",\"sz\":\"0.73\",\"side\":\"sell\",\"ts\":\"1782015931030\",\"count\":\"1\",\"source\":\"0\",\"seqId\":325069874583}]}"}
{"action": "update", "capture_sequence": 301, "channel": "books", "connection_sequence": 4, "event": null, "instId": "BTC-USDT-SWAP", "local_receive_ts": "2026-06-21T04:25:31Z", "monotonic_ns": 1643487007880697, "raw": "{\"arg\":{\"channel\":\"books\",\"instId\":\"BTC-USDT-SWAP\"},\"action\":\"update\",\"data\":[{\"asks\":[[\"64458\",\"451.69\",\"0\",\"68\"],[\"64459\",\"1.56\",\"0\",\"1\"],[\"64459.7\",\"1.56\",\"0\",\"1\"],[\"64460.4\",\"1.56\",\"0\",\"1\"],[\"64461.2\",\"1.57\",\"0\",\"2\"],[\"64461.6\",\"0\",\"0\",\"0\"],[\"64462\",\"0.04\",\"0\",\"4\"],[\"64463.2\",\"1.57\",\"0\",\"2\"],[\"64463.3\",\"0.9\",\"0\",\"1\"],[\"64463.7\",\"1.56\",\"0\",\"1\"],[\"64463.8\",\"0.01\",\"0\",\"1\"],[\"64479.9\",\"62.2\",\"0\",\"3\"],[\"64480.1\",\"0.02\",\"0\",\"2\"],[\"64483.8\",\"0.77\",\"0\",\"1\"],[\"64484.1\",\"0.33\",\"0\",\"2\"],[\"64508\",\"0\",\"0\",\"0\"],[\"64508.1\",\"0\",\"0\",\"0\"],[\"64508.2\",\"0\",\"0\",\"0\"],[\"64508.4\",\"0\",\"0\",\"0\"]],\"bids\":[[\"64457.9\",\"445.93\",\"0\",\"23\"],[\"64457.5\",\"0.01\",\"0\",\"1\"],[\"64457.1\",\"0.02\",\"0\",\"2\"],[\"64457\",\"5.02\",\"0\",\"3\"],[\"64455.9\",\"52.24\",\"0\",\"2\"],[\"64455.8\",\"0\",\"0\",\"0\"],[\"64455.7\",\"0\",\"0\",\"0\"],[\"64455.4\",\"0\",\"0\",\"0\"],[\"64445.1\",\"184.61\",\"0\",\"4\"],[\"64445\",\"169.75\",\"0\",\"8\"],[\"64438.8\",\"31.06\",\"0\",\"1\"],[\"64438.7\",\"3.99\",\"0\",\"1\"],[\"64431.9\",\"17.94\",\"0\",\"3\"],[\"64431.6\",\"496.53\",\"0\",\"1\"],[\"64404.8\",\"0.04\",\"0\",\"1\"]],\"ts\":\"1782015931105\",\"checksum\":-385502701,\"seqId\":325069874716,\"prevSeqId\":325069874513}]}"}
{"action": "update", "capture_sequence": 302, "channel": "books", "connection_sequence": 4, "event": null, "instId": "BTC-USDT-SWAP", "local_receive_ts": "2026-06-21T04:25:31Z", "monotonic_ns": 1643487107540259, "raw": "{\"arg\":{\"channel\":\"books\",\"instId\":\"BTC-USDT-SWAP\"},\"action\":\"update\",\"data\":[{\"asks\":[[\"64459\",\"0\",\"0\",\"0\"],[\"64459.1\",\"1.56\",\"0\",\"1\"],[\"64465.2\",\"77.75\",\"0\",\"2\"]],\"bids\":[[\"64457.9\",\"434.37\",\"0\",\"21\"],[\"64457.7\",\"0.01\",\"0\",\"1\"],[\"64457.5\",\"1.56\",\"0\",\"1\"],[\"64457.4\",\"0.18\",\"0\",\"1\"],[\"64457\",\"6.57\",\"0\",\"3\"],[\"64456.9\",\"0\",\"0\",\"0\"],[\"64456.4\",\"0.02\",\"0\",\"2\"],[\"64456.3\",\"1.56\",\"0\",\"1\"],[\"64455.8\",\"1.56\",\"0\",\"1\"],[\"64452.5\",\"1.57\",\"0\",\"2\"],[\"64405\",\"0\",\"0\",\"0\"],[\"64404.8\",\"0\",\"0\",\"0\"]],\"ts\":\"1782015931205\",\"checksum\":362844269,\"seqId\":325069874867,\"prevSeqId\":325069874716}]}"}
{"action": "update", "capture_sequence": 303, "channel": "books", "connection_sequence": 4, "event": null, "instId": "BTC-USDT-SWAP", "local_receive_ts": "2026-06-21T04:25:31Z", "monotonic_ns": 1643487207651588, "raw": "{\"arg\":{\"channel\":\"books\",\"instId\":\"BTC-USDT-SWAP\"},\"action\":\"update\",\"data\":[{\"asks\":[[\"64459.1\",\"0\",\"0\",\"0\"],[\"64459.7\",\"0\",\"0\",\"0\"],[\"64460.3\",\"1.56\",\"0\",\"1\"],[\"64460.4\",\"0\",\"0\",\"0\"],[\"64461.7\",\"1.56\",\"0\",\"1\"],[\"64465.2\",\"79.31\",\"0\",\"3\"],[\"64486.7\",\"58.21\",\"0\",\"2\"],[\"64487.3\",\"0.04\",\"0\",\"2\"],[\"64489.9\",\"96.96\",\"0\",\"1\"],[\"64492.6\",\"0\",\"0\",\"0\"],[\"64493.1\",\"117.89\",\"0\",\"6\"],[\"64493.4\",\"20.39\",\"0\",\"6\"],[\"64493.6\",\"148.86\",\"0\",\"1\"],[\"64508\",\"13.54\",\"0\",\"7\"],[\"64508.1\",\"21.31\",\"0\",\"3\"]],\"bids\":[[\"64457.9\",\"444.36\",\"0\",\"22\"],[\"64451.6\",\"0.31\",\"0\",\"1\"],[\"64451.5\",\"15.9\",\"0\",\"1\"],[\"64443.5\",\"120.02\",\"0\",\"2\"],[\"64443.4\",\"300.08\",\"0\",\"1\"],[\"64443.3\",\"31.09\",\"0\",\"3\"],[\"64442.2\",\"0\",\"0\",\"0\"],[\"64441.9\",\"122.37\",\"0\",\"3\"],[\"64439.4\",\"0.01\",\"0\",\"1\"],[\"64438.8\",\"89.31\",\"0\",\"2\"]],\"ts\":\"1782015931305\",\"checksum\":-642467539,\"seqId\":325069875022,\"prevSeqId\":325069874867}]}"}
{"action": "update", "capture_sequence": 304, "channel": "books", "connection_sequence": 4, "event": null, "instId": "BTC-USDT-SWAP", "local_receive_ts": "2026-06-21T04:25:31Z", "monotonic_ns": 1643487307622203, "raw": "{\"arg\":{\"channel\":\"books\",\"instId\":\"BTC-USDT-SWAP\"},\"action\":\"update\",\"data\":[{\"asks\":[[\"64458.3\",\"8.3\",\"0\",\"4\"],[\"64458.4\",\"15.54\",\"0\",\"2\"],[\"64458.6\",\"0\",\"0\",\"0\"],[\"64458.7\",\"0\",\"0\",\"0\"],[\"64460.2\",\"0.79\",\"0\",\"3\"],[\"64483.2\",\"114.69\",\"0\",\"3\"],[\"64483.3\",\"0.06\",\"0\",\"3\"],[\"64508.2\",\"59.01\",\"0\",\"5\"],[\"64508.4\",\"1367.19\",\"0\",\"6\"]],\"bids\":[[\"64457.7\",\"0\",\"0\",\"0\"],[\"64457.5\",\"0\",\"0\",\"0\"],[\"64457\",\"5.01\",\"0\",\"2\"],[\"64456.4\",\"0.01\",\"0\",\"1\"],[\"64456.3\",\"0\",\"0\",\"0\"],[\"64456\",\"0.03\",\"0\",\"3\"],[\"64455.8\",\"0\",\"0\",\"0\"],[\"64455.3\",\"0.02\",\"0\",\"2\"],[\"64441.4\",\"50.02\",\"0\",\"3\"],[\"64440.5\",\"0.02\",\"0\",\"1\"],[\"64405\",\"13.52\",\"0\",\"15\"],[\"64404.8\",\"0.04\",\"0\",\"1\"],[\"64404.7\",\"0.77\",\"0\",\"1\"]],\"ts\":\"1782015931405\",\"checksum\":67485725,\"seqId\":325069875109,\"prevSeqId\":325069875022}]}"}
{"action": "update", "capture_sequence": 305, "channel": "books", "connection_sequence": 4, "event": null, "instId": "BTC-USDT-SWAP", "local_receive_ts": "2026-06-21T04:25:31Z", "monotonic_ns": 1643487407521762, "raw": "{\"arg\":{\"channel\":\"books\",\"instId\":\"BTC-USDT-SWAP\"},\"action\":\"update\",\"data\":[{\"asks\":[[\"64458\",\"451.71\",\"0\",\"69\"],[\"64458.3\",\"41.84\",\"0\",\"5\"],[\"64460.7\",\"119.03\",\"0\",\"2\"],[\"64476.3\",\"0.16\",\"0\",\"1\"],[\"64476.4\",\"0\",\"0\",\"0\"]],\"bids\":[[\"64457.9\",\"434.36\",\"0\",\"21\"],[\"64445\",\"168.98\",\"0\",\"7\"],[\"64444.5\",\"0.77\",\"0\",\"1\"],[\"64442.3\",\"18.13\",\"0\",\"2\"],[\"64442.2\",\"3.2\",\"0\",\"1\"],[\"64435.5\",\"512.2\",\"0\",\"3\"],[\"64435.3\",\"0.2\",\"0\",\"2\"],[\"64404.8\",\"0\",\"0\",\"0\"],[\"64404.7\",\"0\",\"0\",\"0\"]],\"ts\":\"1782015931505\",\"checksum\":1171835049,\"seqId\":325069875199,\"prevSeqId\":325069875109}]}"}
{"action": null, "capture_sequence": 306, "channel": "trades", "connection_sequence": 4, "event": null, "instId": "BTC-USDT-SWAP", "local_receive_ts": "2026-06-21T04:25:31Z", "monotonic_ns": 1643487417945144, "raw": "{\"arg\":{\"channel\":\"trades\",\"instId\":\"BTC-USDT-SWAP\"},\"data\":[{\"instId\":\"BTC-USDT-SWAP\",\"tradeId\":\"2718748925\",\"px\":\"64457.9\",\"sz\":\"0.05\",\"side\":\"sell\",\"ts\":\"1782015931516\",\"count\":\"1\",\"source\":\"0\",\"seqId\":325069875209}]}"}
{"action": "update", "capture_sequence": 307, "channel": "books", "connection_sequence": 4, "event": null, "instId": "BTC-USDT-SWAP", "local_receive_ts": "2026-06-21T04:25:31Z", "monotonic_ns": 1643487507988708, "raw": "{\"arg\":{\"channel\":\"books\",\"instId\":\"BTC-USDT-SWAP\"},\"action\":\"update\",\"data\":[{\"asks\":[[\"64458.3\",\"8.3\",\"0\",\"4\"],[\"64460.3\",\"0\",\"0\",\"0\"],[\"64460.7\",\"0.01\",\"0\",\"1\"],[\"64466.4\",\"70.88\",\"0\",\"4\"],[\"64467.1\",\"1.2\",\"0\",\"1\"],[\"64488.1\",\"0.69\",\"0\",\"3\"],[\"64488.8\",\"50\",\"0\",\"1\"],[\"64508.5\",\"42.46\",\"0\",\"3\"]],\"bids\":[[\"64457.9\",\"434.31\",\"0\",\"21\"],[\"64457.8\",\"0.19\",\"0\",\"3\"],[\"64431.9\",\"17.93\",\"0\",\"2\"],[\"64431.6\",\"496.54\",\"0\",\"2\"]],\"ts\":\"1782015931605\",\"checksum\":-1660690292,\"seqId\":325069875275,\"prevSeqId\":325069875199}]}"}
{"action": "update", "capture_sequence": 308, "channel": "books", "connection_sequence": 4, "event": null, "instId": "BTC-USDT-SWAP", "local_receive_ts": "2026-06-21T04:25:31Z", "monotonic_ns": 1643487607839469, "raw": "{\"arg\":{\"channel\":\"books\",\"instId\":\"BTC-USDT-SWAP\"},\"action\":\"update\",\"data\":[{\"asks\":[[\"64458.3\",\"6.61\",\"0\",\"4\"],[\"64458.4\",\"0.01\",\"0\",\"1\"],[\"64458.7\",\"0.01\",\"0\",\"1\"],[\"64458.8\",\"15.53\",\"0\",\"1\"],[\"64460.2\",\"0.78\",\"0\",\"2\"],[\"64466.4\",\"70.86\",\"0\",\"3\"],[\"64467.1\",\"1.22\",\"0\",\"2\"],[\"64476.9\",\"0.02\",\"0\",\"2\"],[\"64477.6\",\"0.08\",\"0\",\"2\"],[\"64488.1\",\"0.67\",\"0\",\"2\"],[\"64488.8\",\"50.02\",\"0\",\"2\"],[\"64508.4\",\"0\",\"0\",\"0\"],[\"64508.5\",\"0\",\"0\",\"0\"]],\"bids\":[[\"64457.9\",\"433.77\",\"0\",\"20\"],[\"64440.5\",\"0\",\"0\",\"0\"],[\"64440\",\"99.45\",\"0\",\"6\"],[\"64404.8\",\"0.04\",\"0\",\"1\"]],\"ts\":\"1782015931705\",\"checksum\":-780339600,\"seqId\":325069875366,\"prevSeqId\":325069875275}]}"}
{"action": null, "capture_sequence": 309, "channel": "trades", "connection_sequence": 4, "event": null, "instId": "BTC-USDT-SWAP", "local_receive_ts": "2026-06-21T04:25:32Z", "monotonic_ns": 1643487888204568, "raw": "{\"arg\":{\"channel\":\"trades\",\"instId\":\"BTC-USDT-SWAP\"},\"data\":[{\"instId\":\"BTC-USDT-SWAP\",\"tradeId\":\"2718748926\",\"px\":\"64458\",\"sz\":\"1.45\",\"side\":\"buy\",\"ts\":\"1782015931986\",\"count\":\"1\",\"source\":\"0\",\"seqId\":325069875574}]}"}
{"action": "update", "capture_sequence": 310, "channel": "books", "connection_sequence": 4, "event": null, "instId": "BTC-USDT-SWAP", "local_receive_ts": "2026-06-21T04:25:32Z", "monotonic_ns": 1643487907838863, "raw": "{\"arg\":{\"channel\":\"books\",\"instId\":\"BTC-USDT-SWAP\"},\"action\":\"update\",\"data\":[{\"asks\":[[\"64458\",\"450.26\",\"0\",\"69\"],[\"64458.7\",\"0.02\",\"0\",\"2\"],[\"64461.2\",\"0.01\",\"0\",\"1\"],[\"64461.7\",\"0\",\"0\",\"0\"],[\"64463.9\",\"31.05\",\"0\",\"1\"],[\"64464\",\"110.83\",\"0\",\"6\"],[\"64464.1\",\"0.03\",\"0\",\"3\"],[\"64466.2\",\"1.56\",\"0\",\"1\"],[\"64477.1\",\"0.01\",\"0\",\"1\"],[\"64477.6\",\"0.07\",\"0\",\"1\"],[\"64486.5\",\"73.85\",\"0\",\"2\"],[\"64486.7\",\"0.01\",\"0\",\"1\"],[\"64492.6\",\"86.14\",\"0\",\"1\"],[\"64493.1\",\"31.76\",\"0\",\"5\"],[\"64493.4\",\"0.32\",\"0\",\"5\"],[\"64493.5\",\"21.16\",\"0\",\"5\"],[\"64508\",\"0\",\"0\",\"0\"],[\"64508.1\",\"0\",\"0\",\"0\"],[\"64508.2\",\"0\",\"0\",\"0\"]],\"bids\":[[\"64457.9\",\"435.33\",\"0\",\"21\"],[\"64457.4\",\"1.74\",\"0\",\"2\"],[\"64453.9\",\"1.88\",\"0\",\"3\"],[\"64453.7\",\"0\",\"0\",\"0\"],[\"64451.6\",\"0\",\"0\",\"0\"],[\"64451.5\",\"16.21\",\"0\",\"2\"],[\"64443.6\",\"33.83\",\"0\",\"2\"],[\"64443.5\",\"0\",\"0\",\"0\"],[\"64443.3\",\"117.29\",\"0\",\"4\"],[\"64442\",\"163.06\",\"0\",\"5\"],[\"64441.9\",\"36.94\",\"0\",\"2\"],[\"64438.9\",\"68.29\",\"0\",\"2\"],[\"64438.8\",\"0\",\"0\",\"0\"],[\"64438.7\",\"62.24\",\"0\",\"2\"],[\"64404.7\",\"0.77\",\"0\",\"1\"],[\"64404.5\",\"0.16\",\"0\",\"2\"],[\"64404.4\",\"15.36\",\"0\",\"1\"],[\"64404.3\",\"0.05\",\"0\",\"4\"]],\"ts\":\"1782015932005\",\"checksum\":-645099273,\"seqId\":325069875635,\"prevSeqId\":325069875366}]}"}
{"action": "update", "capture_sequence": 311, "channel": "books", "connection_sequence": 4, "event": null, "instId": "BTC-USDT-SWAP", "local_receive_ts": "2026-06-21T04:25:32Z", "monotonic_ns": 1643488012223478, "raw": "{\"arg\":{\"channel\":\"books\",\"instId\":\"BTC-USDT-SWAP\"},\"action\":\"update\",\"data\":[{\"asks\":[[\"64458.1\",\"0.05\",\"0\",\"5\"],[\"64458.2\",\"1.57\",\"0\",\"2\"],[\"64458.3\",\"74.26\",\"0\",\"4\"],[\"64458.7\",\"0.01\",\"0\",\"1\"],[\"64458.8\",\"17.09\",\"0\",\"2\"],[\"64459.4\",\"1.56\",\"0\",\"1\"],[\"64460.1\",\"1.58\",\"0\",\"3\"],[\"64460.2\",\"119.8\",\"0\",\"3\"],[\"64460.8\",\"65.16\",\"0\",\"2\"],[\"64461.2\",\"1.57\",\"0\",\"2\"],[\"64462\",\"1.6\",\"0\",\"5\"],[\"64463.9\",\"0\",\"0\",\"0\"],[\"64464\",\"1.72\",\"0\",\"5\"],[\"64464.1\",\"31.08\",\"0\",\"4\"],[\"64464.2\",\"209.9\",\"0\",\"2\"],[\"64464.7\",\"0.01\",\"0\",\"1\"],[\"64465.2\",\"77.75\",\"0\",\"2\"],[\"64466.2\",\"0\",\"0\",\"0\"],[\"64476.9\",\"0.03\",\"0\",\"3\"],[\"64477.1\",\"0\",\"0\",\"0\"],[\"64480\",\"55.84\",\"0\",\"46\"],[\"64480.1\",\"0.01\",\"0\",\"1\"],[\"64483.2\",\"114.7\",\"0\",\"4\"],[\"64483.3\",\"0.05\",\"0\",\"2\"],[\"64486.5\",\"15.65\",\"0\",\"1\"],[\"64486.9\",\"58.32\",\"0\",\"3\"],[\"64493.5\",\"1.09\",\"0\",\"4\"],[\"64493.6\",\"168.93\",\"0\",\"2\"],[\"64508\",\"13.54\",\"0\",\"7\"],[\"64508.1\",\"21.31\",\"0\",\"3\"]],\"bids\":[[\"64457.9\",\"433.77\",\"0\",\"20\"],[\"64457.6\",\"0.48\",\"0\",\"3\"],[\"64457.4\",\"0.18\",\"0\",\"1\"],[\"64457\",\"5.02\",\"0\",\"3\"],[\"64456.9\",\"1.56\",\"0\",\"1\"],[\"64456.4\",\"1.57\",\"0\",\"2\"],[\"64456\",\"0.02\",\"0\",\"2\"],[\"64455.3\",\"0.01\",\"0\",\"1\"],[\"64453.9\",\"1.57\",\"0\",\"2\"],[\"64453.7\",\"0.31\",\"0\",\"1\"],[\"64443.6\",\"0.01\",\"0\",\"1\"],[\"64443.5\",\"120.02\",\"0\",\"2\"],[\"64443.3\",\"31.09\",\"0\",\"3\"],[\"64440.9\",\"0.03\",\"0\",\"2\"],[\"64440\",\"99.43\",\"0\",\"5\"],[\"64439\",\"58.26\",\"0\",\"2\"],[\"64438.9\",\"37.23\",\"0\",\"1\"],[\"64438.8\",\"31.06\",\"0\",\"1\"],[\"64438.7\",\"3.99\",\"0\",\"1\"],[\"64408.4\",\"7.93\",\"0\",\"5\"],[\"64408.3\",\"0.41\",\"0\",\"2\"],[\"64404.7\",\"0\",\"0\",\"0\"],[\"64404.5\",\"0\",\"0\",\"0\"],[\"64404.4\",\"0\",\"0\",\"0\"],[\"64404.3\",\"0\",\"0\",\"0\"]],\"ts\":\"1782015932105\",\"checksum\":1886254026,\"seqId\":325069875975,\"prevSeqId\":325069875635}]}"}
{"action": null, "capture_sequence": 312, "channel": "trades", "connection_sequence": 4, "event": null, "instId": "BTC-USDT-SWAP", "local_receive_ts": "2026-06-21T04:25:32Z", "monotonic_ns": 1643488101330091, "raw": "{\"arg\":{\"channel\":\"trades\",\"instId\":\"BTC-USDT-SWAP\"},\"data\":[{\"instId\":\"BTC-USDT-SWAP\",\"tradeId\":\"2718748927\",\"px\":\"64457.9\",\"sz\":\"2\",\"side\":\"sell\",\"ts\":\"1782015932199\",\"count\":\"1\",\"source\":\"0\",\"seqId\":325069876180}]}"}
{"action": "update", "capture_sequence": 313, "channel": "books", "connection_sequence": 4, "event": null, "instId": "BTC-USDT-SWAP", "local_receive_ts": "2026-06-21T04:25:32Z", "monotonic_ns": 1643488112063341, "raw": "{\"arg\":{\"channel\":\"books\",\"instId\":\"BTC-USDT-SWAP\"},\"action\":\"update\",\"data\":[{\"asks\":[[\"64458\",\"450.36\",\"0\",\"70\"],[\"64458.1\",\"0.04\",\"0\",\"4\"],[\"64458.2\",\"0.01\",\"0\",\"1\"],[\"64458.3\",\"43.44\",\"0\",\"3\"],[\"64458.5\",\"6.56\",\"0\",\"2\"],[\"64458.7\",\"0.02\",\"0\",\"2\"],[\"64458.8\",\"15.53\",\"0\",\"1\"],[\"64459\",\"1.56\",\"0\",\"1\"],[\"64459.4\",\"0\",\"0\",\"0\"],[\"64459.6\",\"2.16\",\"0\",\"2\"],[\"64465.8\",\"64.04\",\"0\",\"3\"],[\"64467.1\",\"1.2\",\"0\",\"1\"],[\"64479.9\",\"62.21\",\"0\",\"4\"],[\"64480\",\"55.83\",\"0\",\"45\"],[\"64483.1\",\"100.31\",\"0\",\"5\"],[\"64483.2\",\"114.69\",\"0\",\"3\"],[\"64483.7\",\"0.32\",\"0\",\"2\"],[\"64484.1\",\"0.02\",\"0\",\"1\"],[\"64485.8\",\"58.6\",\"0\",\"3\"],[\"64486.5\",\"101.02\",\"0\",\"2\"],[\"64486.9\",\"0.12\",\"0\",\"2\"],[\"64487.4\",\"0.49\",\"0\",\"5\"],[\"64487.8\",\"0.11\",\"0\",\"4\"],[\"64488.8\",\"50\",\"0\",\"1\"],[\"64492.7\",\"119.95\",\"0\",\"4\"],[\"64493.6\",\"148.86\",\"0\",\"1\"]],\"bids\":[[\"64457.9\",\"431.77\",\"0\",\"20\"],[\"64457.6\",\"0.47\",\"0\",\"2\"],[\"64457\",\"5.01\",\"0\",\"2\"],[\"64456.9\",\"0\",\"0\",\"0\"],[\"64456.5\",\"0.01\",\"0\",\"1\"],[\"64456.4\",\"0.01\",\"0\",\"1\"],[\"64456\",\"0.03\",\"0\",\"3\"],[\"64454.9\",\"0\",\"0\",\"0\"],[\"64454.4\",\"0.02\",\"0\",\"2\"],[\"64453.8\",\"1.08\",\"0\",\"2\"],[\"64453.7\",\"0\",\"0\",\"0\"],[\"64451.5\",\"15.9\",\"0\",\"1\"],[\"64450.9\",\"0.31\",\"0\",\"1\"],[\"64443.5\",\"0\",\"0\",\"0\"],[\"64442.9\",\"0\",\"0\",\"0\"],[\"64442.8\",\"33.85\",\"0\",\"4\"],[\"64442.4\",\"86.21\",\"0\",\"2\"],[\"64442.3\",\"38.22\",\"0\",\"3\"],[\"64442\",\"77.63\",\"0\",\"4\"],[\"64441.2\",\"85.43\",\"0\",\"1\"],[\"64440.9\",\"0.01\",\"0\",\"1\"],[\"64440\",\"99.45\",\"0\",\"6\"],[\"64439\",\"0.01\",\"0\",\"1\"],[\"64437.5\",\"58.25\",\"0\",\"1\"],[\"64404.7\",\"0.77\",\"0\",\"1\"]],\"ts\":\"1782015932205\",\"checksum\":-458825219,\"seqId\":325069876194,\"prevSeqId\":325069875975}]}"}
{"action": "update", "capture_sequence": 314, "channel": "books", "connection_sequence": 4, "event": null, "instId": "BTC-USDT-SWAP", "local_receive_ts": "2026-06-21T04:25:32Z", "monotonic_ns": 1643488207710454, "raw": "{\"arg\":{\"channel\":\"books\",\"instId\":\"BTC-USDT-SWAP\"},\"action\":\"update\",\"data\":[{\"asks\":[[\"64458.2\",\"20.21\",\"0\",\"2\"],[\"64458.3\",\"0.02\",\"0\",\"2\"],[\"64460.2\",\"0.78\",\"0\",\"2\"],[\"64483.7\",\"0.01\",\"0\",\"1\"],[\"64484.1\",\"0.33\",\"0\",\"2\"],[\"64490.9\",\"86.21\",\"0\",\"3\"],[\"64492.6\",\"0\",\"0\",\"0\"],[\"64508.2\",\"59.01\",\"0\",\"5\"]],\"bids\":[[\"64457.9\",\"431.78\",\"0\",\"21\"],[\"64456.5\",\"0\",\"0\",\"0\"],[\"64455.3\",\"0.02\",\"0\",\"2\"],[\"64453.9\",\"0.01\",\"0\",\"1\"],[\"64453.8\",\"0.77\",\"0\",\"1\"],[\"64453.7\",\"0.31\",\"0\",\"1\"],[\"64451.3\",\"11.7\",\"0\",\"5\"],[\"64450.9\",\"0\",\"0\",\"0\"],[\"64442.5\",\"86.2\",\"0\",\"1\"],[\"64442.4\",\"0.01\",\"0\",\"1\"]],\"ts\":\"1782015932305\",\"checksum\":1003573120,\"seqId\":325069876286,\"prevSeqId\":325069876194}]}"}
{"action": "update", "capture_sequence": 315, "channel": "books", "connection_sequence": 4, "event": null, "instId": "BTC-USDT-SWAP", "local_receive_ts": "2026-06-21T04:25:32Z", "monotonic_ns": 1643488309822534, "raw": "{\"arg\":{\"channel\":\"books\",\"instId\":\"BTC-USDT-SWAP\"},\"action\":\"update\",\"data\":[{\"asks\":[[\"64458.2\",\"9.21\",\"0\",\"2\"],[\"64460.8\",\"89.34\",\"0\",\"3\"],[\"64463.9\",\"31.05\",\"0\",\"1\"],[\"64464\",\"110.59\",\"0\",\"6\"],[\"64464.1\",\"0.03\",\"0\",\"3\"],[\"64465.8\",\"64.02\",\"0\",\"2\"],[\"64467.1\",\"1.22\",\"0\",\"2\"],[\"64486.3\",\"265.27\",\"0\",\"5\"],[\"64486.5\",\"15.65\",\"0\",\"1\"],[\"64487.8\",\"0.09\",\"0\",\"3\"],[\"64488.8\",\"50.02\",\"0\",\"2\"],[\"64508.2\",\"0\",\"0\",\"0\"]],\"bids\":[[\"64443.3\",\"31.08\",\"0\",\"2\"],[\"64443.2\",\"135.67\",\"0\",\"6\"],[\"64442.5\",\"0\",\"0\",\"0\"],[\"64442.1\",\"92.42\",\"0\",\"2\"],[\"64441.2\",\"0\",\"0\",\"0\"],[\"64440.7\",\"85.43\",\"0\",\"1\"],[\"64404.5\",\"0.16\",\"0\",\"2\"]],\"ts\":\"1782015932405\",\"checksum\":680884540,\"seqId\":325069876376,\"prevSeqId\":325069876286}]}"}
{"action": "update", "capture_sequence": 316, "channel": "books", "connection_sequence": 4, "event": null, "instId": "BTC-USDT-SWAP", "local_receive_ts": "2026-06-21T04:25:32Z", "monotonic_ns": 1643488407509612, "raw": "{\"arg\":{\"channel\":\"books\",\"instId\":\"BTC-USDT-SWAP\"},\"action\":\"update\",\"data\":[{\"asks\":[[\"64458.2\",\"39.06\",\"0\",\"3\"],[\"64458.5\",\"5\",\"0\",\"1\"],[\"64460.7\",\"103.95\",\"0\",\"2\"],[\"64460.8\",\"65.16\",\"0\",\"2\"],[\"64463.9\",\"0\",\"0\",\"0\"],[\"64464\",\"1.72\",\"0\",\"5\"],[\"64464.1\",\"31.08\",\"0\",\"4\"],[\"64466.4\",\"70.88\",\"0\",\"4\"],[\"64467.1\",\"1.2\",\"0\",\"1\"],[\"64476.3\",\"0\",\"0\",\"0\"],[\"64481.7\",\"33.81\",\"0\",\"1\"],[\"64482.6\",\"0.01\",\"0\",\"1\"],[\"64488.1\",\"0.69\",\"0\",\"3\"],[\"64488.8\",\"50\",\"0\",\"1\"],[\"64492.4\",\"77.93\",\"0\",\"7\"],[\"64492.7\",\"99.88\",\"0\",\"3\"],[\"64508.2\",\"59.01\",\"0\",\"5\"]],\"bids\":[[\"64454.4\",\"0.79\",\"0\",\"3\"],[\"64453.8\",\"0\",\"0\",\"0\"],[\"64442.8\",\"0.03\",\"0\",\"3\"],[\"64442.4\",\"33.84\",\"0\",\"2\"],[\"64442.3\",\"18.13\",\"0\",\"2\"],[\"64442.2\",\"0\",\"0\",\"0\"],[\"64442\",\"97.72\",\"0\",\"5\"],[\"64435.3\",\"0.01\",\"0\",\"1\"],[\"64404.4\",\"15.36\",\"0\",\"1\"],[\"64404.3\",\"0.05\",\"0\",\"4\"]],\"ts\":\"1782015932505\",\"checksum\":1619268300,\"seqId\":325069876476,\"prevSeqId\":325069876376}]}"}
{"action": "update", "capture_sequence": 317, "channel": "books", "connection_sequence": 4, "event": null, "instId": "BTC-USDT-SWAP", "local_receive_ts": "2026-06-21T04:25:32Z", "monotonic_ns": 1643488507983333, "raw": "{\"arg\":{\"channel\":\"books\",\"instId\":\"BTC-USDT-SWAP\"},\"action\":\"update\",\"data\":[{\"asks\":[[\"64458\",\"467.53\",\"0\",\"93\"],[\"64476.5\",\"0.15\",\"0\",\"1\"],[\"64483.1\",\"101.08\",\"0\",\"6\"],[\"64483.8\",\"0\",\"0\",\"0\"]],\"bids\":[[\"64444.5\",\"0\",\"0\",\"0\"],[\"64443.8\",\"0.77\",\"0\",\"1\"],[\"64442.2\",\"3.21\",\"0\",\"1\"],[\"64435.4\",\"263.06\",\"0\",\"4\"],[\"64417.4\",\"0.35\",\"0\",\"8\"],[\"64404.3\",\"0\",\"0\",\"0\"]],\"ts\":\"1782015932605\",\"checksum\":593526688,\"seqId\":325069876590,\"prevSeqId\":325069876476}]}"}
