{"action": "update", "capture_sequence": 112, "channel": "books", "connection_sequence": 2, "event": null, "instId": "BTC-USDT-SWAP", "local_receive_ts": "2026-06-21T04:25:13Z", "monotonic_ns": 1643469322890751, "raw": "{\"arg\":{\"channel\":\"books\",\"instId\":\"BTC-USDT-SWAP\"},\"action\":\"update\",\"data\":[{\"asks\":[[\"64458.3\",\"0.03\",\"0\",\"3\"],[\"64458.4\",\"6.35\",\"0\",\"3\"],[\"64458.7\",\"0.02\",\"0\",\"2\"],[\"64458.8\",\"15.53\",\"0\",\"1\"],[\"64459.1\",\"0\",\"0\",\"0\"],[\"64459.2\",\"0.01\",\"0\",\"1\"],[\"64459.3\",\"1.03\",\"0\",\"4\"],[\"64459.6\",\"0.6\",\"0\",\"1\"],[\"64460.4\",\"0\",\"0\",\"0\"],[\"64461.6\",\"0.01\",\"0\",\"1\"],[\"64481.7\",\"0\",\"0\",\"0\"],[\"64483.3\",\"33.85\",\"0\",\"3\"],[\"64483.7\",\"0.01\",\"0\",\"1\"],[\"64483.8\",\"0.77\",\"0\",\"1\"],[\"64486.2\",\"58.37\",\"0\",\"7\"],[\"64487.4\",\"0.49\",\"0\",\"5\"],[\"64492.5\",\"0.06\",\"0\",\"4\"],[\"64493.1\",\"117.89\",\"0\",\"6\"],[\"64508.7\",\"0\",\"0\",\"0\"]],\"bids\":[[\"64457.9\",\"460.6\",\"0\",\"20\"],[\"64444.6\",\"0\",\"0\",\"0\"],[\"64444.5\",\"34.59\",\"0\",\"2\"],[\"64443.5\",\"86.2\",\"0\",\"1\"],[\"64442.7\",\"0\",\"0\",\"0\"],[\"64442.5\",\"0\",\"0\",\"0\"],[\"64439.4\",\"0.01\",\"0\",\"1\"],[\"64438.2\",\"58.26\",\"0\",\"2\"],[\"64405.2\",\"239.07\",\"0\",\"5\"]],\"ts\":\"1782015913405\",\"checksum\":-708794899,\"seqId\":325069863853,\"prevSeqId\":325069863731}]}"}
{"action": "update", "capture_sequence": 113, "channel": "books", "connection_sequence": 2, "event": null, "instId": "BTC-USDT-SWAP", "local_receive_ts": "2026-06-21T04:25:13Z", "monotonic_ns": 1643469422865452, "raw": "{\"arg\":{\"channel\":\"books\",\"instId\":\"BTC-USDT-SWAP\"},\"action\":\"update\",\"data\":[{\"asks\":[],\"bids\":[[\"64457.9\",\"458\",\"0\",\"20\"],[\"64452.4\",\"1.87\",\"0\",\"2\"],[\"64452.3\",\"0.01\",\"0\",\"1\"]],\"ts\":\"1782015913505\",\"checksum\":-1066335452,\"seqId\":325069863924,\"prevSeqId\":325069863853}]}"}
{"action": "update", "capture_sequence": 114, "channel": "books", "connection_sequence": 2, "event": null, "instId": "BTC-USDT-SWAP", "local_receive_ts": "2026-06-21T04:25:13Z", "monotonic_ns": 1643469523097125, "raw": "{\"arg\":{\"channel\":\"books\",\"instId\":\"BTC-USDT-SWAP\"},\"action\":\"update\",\"data\":[{\"asks\":[[\"64467.4\",\"0\",\"0\",\"0\"],[\"64508.7\",\"42.88\",\"0\",\"9\"]],\"bids\":[[\"64457.5\",\"0\",\"0\",\"0\"],[\"64457.4\",\"0\",\"0\",\"0\"],[\"64454.9\",\"0.02\",\"0\",\"2\"],[\"64405.1\",\"0.07\",\"0\",\"3\"],[\"64405\",\"13.52\",\"0\",\"15\"]],\"ts\":\"1782015913605\",\"checksum\":-620399928,\"seqId\":325069864004,\"prevSeqId\":325069863924}]}"}
{"action": "update", "capture_sequence": 115, "channel": "books", "connection_sequence": 2, "event": null, "instId": "BTC-USDT-SWAP", "local_receive_ts": "2026-06-21T04:25:13Z", "monotonic_ns": 1643469622929065, "raw": "{\"arg\":{\"channel\":\"books\",\"instId\":\"BTC-USDT-SWAP\"},\"action\":\"update\",\"data\":[{\"asks\":[[\"64472\",\"2.07\",\"0\",\"5\"],[\"64472.6\",\"15.53\",\"0\",\"2\"],[\"64476.3\",\"0\",\"0\",\"0\"],[\"64508.8\",\"0.04\",\"0\",\"2\"]],\"bids\":[[\"64457.9\",\"457.46\",\"0\",\"19\"],[\"64456.6\",\"0.08\",\"0\",\"2\"],[\"64454.9\",\"109.46\",\"0\",\"3\"],[\"64453.7\",\"0\",\"0\",\"0\"],[\"64451.3\",\"14.45\",\"0\",\"8\"],[\"64450.5\",\"4.9\",\"0\",\"3\"],[\"64443.1\",\"0\",\"0\",\"0\"],[\"64436.3\",\"117.15\",\"0\",\"4\"],[\"64404.8\",\"0.04\",\"0\",\"1\"],[\"64404.7\",\"0.77\",\"0\",\"1\"]],\"ts\":\"1782015913705\",\"checksum\":-314671555,\"seqId\":325069864088,\"prevSeqId\":325069864004}]}"}
{"action": "update", "capture_sequence": 116, "channel": "books", "connection_sequence": 2, "event": null, "instId": "BTC-USDT-SWAP", "local_receive_ts": "2026-06-21T04:25:13Z", "monotonic_ns": 1643469723229368, "raw": "{\"arg\":{\"channel\":\"books\",\"instId\":\"BTC-USDT-SWAP\"},\"action\":\"update\",\"data\":[{\"asks\":[[\"64474.1\",\"0\",\"0\",\"0\"],[\"64474.9\",\"68.27\",\"0\",\"2\"],[\"64476.3\",\"0.15\",\"0\",\"1\"],[\"64484.2\",\"15.65\",\"0\",\"1\"],[\"64484.8\",\"496.84\",\"0\",\"2\"],[\"64486.2\",\"0.17\",\"0\",\"6\"],[\"64487.4\",\"58.69\",\"0\",\"6\"]],\"bids\":[[\"64456.7\",\"0\",\"0\",\"0\"],[\"64456.5\",\"0.61\",\"0\",\"2\"],[\"64456.4\",\"40.9\",\"0\",\"3\"],[\"64456\",\"0.02\",\"0\",\"2\"],[\"64455.9\",\"0.01\",\"0\",\"1\"],[\"64454.9\",\"0.01\",\"0\",\"1\"],[\"64454.8\",\"105.2\",\"0\",\"3\"],[\"64454.7\",\"37.26\",\"0\",\"3\"],[\"64452.8\",\"0.36\",\"0\",\"2\"],[\"64452.4\",\"1.56\",\"0\",\"1\"],[\"64452.2\",\"1.09\",\"0\",\"3\"],[\"64451.6\",\"0\",\"0\",\"0\"],[\"64443.1\",\"3.16\",\"0\",\"1\"],[\"64439.5\",\"37.27\",\"0\",\"4\"],[\"64439\",\"58.26\",\"0\",\"2\"],[\"64438.7\",\"4.99\",\"0\",\"2\"],[\"64438.2\",\"0.01\",\"0\",\"1\"],[\"64437.4\",\"31.06\",\"0\",\"1\"],[\"64436.3\",\"117.35\",\"0\",\"5\"],[\"64436.1\",\"25.65\",\"0\",\"2\"]],\"ts\":\"1782015913805\",\"checksum\":696425677,\"seqId\":325069864250,\"prevSeqId\":325069864088}]}"}
{"action": "update", "capture_sequence": 117, "channel": "books", "connection_sequence": 2, "event": null, "instId": "BTC-USDT-SWAP", "local_receive_ts": "2026-06-21T04:25:14Z", "monotonic_ns": 1643469822947848, "raw": "{\"arg\":{\"channel\":\"books\",\"instId\":\"BTC-USDT-SWAP\"},\"action\":\"update\",\"data\":[{\"asks\":[[\"64458\",\"529.13\",\"0\",\"72\"],[\"64458.7\",\"0\",\"0\",\"0\"],[\"64458.8\",\"0\",\"0\",\"0\"],[\"64459.2\",\"0.02\",\"0\",\"2\"],[\"64459.3\",\"16.56\",\"0\",\"5\"],[\"64462.3\",\"0.01\",\"0\",\"1\"],[\"64475.6\",\"0.39\",\"0\",\"2\"],[\"64476.7\",\"232.87\",\"0\",\"1\"],[\"64484.5\",\"0.37\",\"0\",\"4\"],[\"64484.8\",\"496.53\",\"0\",\"1\"]],\"bids\":[[\"64457.9\",\"467.46\",\"0\",\"20\"],[\"64456.4\",\"25.08\",\"0\",\"3\"],[\"64454.9\",\"0\",\"0\",\"0\"],[\"64454.8\",\"0.02\",\"0\",\"2\"],[\"64454.7\",\"37.27\",\"0\",\"4\"],[\"64453\",\"0.31\",\"0\",\"1\"],[\"64452.8\",\"0.05\",\"0\",\"1\"],[\"64452.2\",\"0.78\",\"0\",\"2\"],[\"64451.8\",\"0.32\",\"0\",\"2\"],[\"64437\",\"233.01\",\"0\",\"1\"],[\"64436.2\",\"0\",\"0\",\"0\"]],\"ts\":\"1782015913905\",\"checksum\":1552382421,\"seqId\":325069864340,\"prevSeqId\":325069864250}]}"}
{"action": "update", "capture_sequence": 118, "channel": "books", "connection_sequence": 2, "event": null, "instId": "BTC-USDT-SWAP", "local_receive_ts": "2026-06-21T04:25:14Z", "monotonic_ns": 1643469927536813, "raw": "{\"arg\":{\"channel\":\"books\",\"instId\":\"BTC-USDT-SWAP\"},\"action\":\"update\",\"data\":[{\"asks\":[[\"64458\",\"529.23\",\"0\",\"73\"],[\"64459.6\",\"2.16\",\"0\",\"2\"],[\"64474.4\",\"0.02\",\"0\",\"2\"],[\"64475\",\"263.09\",\"0\",\"11\"],[\"64477.2\",\"0\",\"0\",\"0\"],[\"64477.9\",\"1.55\",\"0\",\"1\"],[\"64483\",\"233.8\",\"0\",\"2\"],[\"64483.3\",\"0.05\",\"0\",\"2\"],[\"64487.4\",\"0.49\",\"0\",\"5\"],[\"64487.5\",\"101.67\",\"0\",\"7\"],[\"64487.6\",\"301.47\",\"0\",\"2\"],[\"64487.7\",\"130.34\",\"0\",\"4\"],[\"64487.9\",\"85.38\",\"0\",\"2\"],[\"64492.6\",\"185.06\",\"0\",\"2\"],[\"64493.1\",\"31.76\",\"0\",\"5\"],[\"64493.7\",\"359.29\",\"0\",\"5\"],[\"64494.1\",\"20.07\",\"0\",\"1\"],[\"64508.8\",\"0\",\"0\",\"0\"]],\"bids\":[[\"64457.9\",\"459.02\",\"0\",\"20\"],[\"64457.4\",\"1.56\",\"0\",\"1\"],[\"64453.2\",\"0.31\",\"0\",\"1\"],[\"64453\",\"0\",\"0\",\"0\"],[\"64451.8\",\"1.09\",\"0\",\"3\"],[\"64451.3\",\"13.68\",\"0\",\"7\"],[\"64451.2\",\"381.79\",\"0\",\"6\"],[\"64450.8\",\"77.57\",\"0\",\"1\"],[\"64450.7\",\"1.6\",\"0\",\"3\"],[\"64450.4\",\"0.31\",\"0\",\"1\"],[\"64450.3\",\"42.4\",\"0\",\"3\"],[\"64448.9\",\"0\",\"0\",\"0\"],[\"64444.6\",\"0.77\",\"0\",\"1\"],[\"64444.5\",\"0\",\"0\",\"0\"],[\"64443.8\",\"33.82\",\"0\",\"1\"],[\"64443.6\",\"20.1\",\"0\",\"2\"],[\"64443.3\",\"130.12\",\"0\",\"4\"],[\"64442.4\",\"85.43\",\"0\",\"2\"],[\"64442.2\",\"0\",\"0\",\"0\"],[\"64441.2\",\"0.02\",\"0\",\"1\"],[\"64441\",\"3.11\",\"0\",\"2\"],[\"64439.6\",\"58.25\",\"0\",\"1\"],[\"64439\",\"0.01\",\"0\",\"1\"],[\"64436.9\",\"354.26\",\"0\",\"3\"],[\"64436.8\",\"0\",\"0\",\"0\"],[\"64404.8\",\"0\",\"0\",\"0\"],[\"64404.7\",\"0\",\"0\",\"0\"]],\"ts\":\"1782015914005\",\"checksum\":1374033284,\"seqId\":325069864468,\"prevSeqId\":325069864340}]}"}
{"action": null, "capture_sequence": 119, "channel": "trades", "connection_sequence": 2, "event": null, "instId": "BTC-USDT-SWAP", "local_receive_ts": "2026-06-21T04:25:14Z", "monotonic_ns": 1643469955480662, "raw": "{\"arg\":{\"channel\":\"trades\",\"instId\":\"BTC-USDT-SWAP\"},\"data\":[{\"instId\":\"BTC-USDT-SWAP\",\"tradeId\":\"2718748855\",\"px\":\"64458\",\"sz\":\"0.54\",\"side\":\"buy\",\"ts\":\"1782015914038\",\"count\":\"1\",\"source\":\"0\",\"seqId\":325069864553}]}"}
{"action": "update", "capture_sequence": 120, "channel": "books", "connection_sequence": 2, "event": null, "instId": "BTC-USDT-SWAP", "local_receive_ts": "2026-06-21T04:25:14Z", "monotonic_ns": 1643470023215161, "raw": "{\"arg\":{\"channel\":\"books\",\"instId\":\"BTC-USDT-SWAP\"},\"action\":\"update\",\"data\":[{\"asks\":[[\"64458\",\"528.69\",\"0\",\"73\"],[\"64458.9\",\"1.56\",\"0\",\"1\"],[\"64459.6\",\"0.6\",\"0\",\"1\"],[\"64460.4\",\"1.56\",\"0\",\"1\"],[\"64461.2\",\"55.68\",\"0\",\"5\"],[\"64461.6\",\"1.56\",\"0\",\"1\"],[\"64461.7\",\"0\",\"0\",\"0\"],[\"64472.6\",\"0.01\",\"0\",\"1\"],[\"64472.7\",\"39.52\",\"0\",\"3\"],[\"64474.9\",\"37.23\",\"0\",\"1\"],[\"64475.5\",\"31.04\",\"0\",\"1\"],[\"64487.6\",\"301.45\",\"0\",\"1\"],[\"64487.7\",\"130.36\",\"0\",\"5\"],[\"64508.6\",\"0\",\"0\",\"0\"],[\"64508.7\",\"0\",\"0\",\"0\"]],\"bids\":[[\"64457.9\",\"457.46\",\"0\",\"19\"],[\"64457.8\",\"1.7\",\"0\",\"3\"],[\"64457.4\",\"0\",\"0\",\"0\"],[\"64457\",\"0.03\",\"0\",\"3\"],[\"64456.9\",\"1.56\",\"0\",\"1\"],[\"64456.4\",\"40.69\",\"0\",\"4\"],[\"64456\",\"0.03\",\"0\",\"3\"],[\"64455.9\",\"1.57\",\"0\",\"2\"],[\"64454.8\",\"0.01\",\"0\",\"1\"],[\"64454.7\",\"37.26\",\"0\",\"3\"],[\"64454.4\",\"170.66\",\"0\",\"3\"],[\"64451.9\",\"0.31\",\"0\",\"1\"],[\"64451.8\",\"0.78\",\"0\",\"2\"],[\"64451.3\",\"91.25\",\"0\",\"8\"],[\"64451.1\",\"0.01\",\"0\",\"1\"],[\"64450.8\",\"0\",\"0\",\"0\"],[\"64450.3\",\"42.39\",\"0\",\"2\"],[\"64444.6\",\"0\",\"0\",\"0\"],[\"64444.5\",\"0.77\",\"0\",\"1\"],[\"64441.4\",\"50.04\",\"0\",\"4\"],[\"64441.2\",\"0\",\"0\",\"0\"]],\"ts\":\"1782015914105\",\"checksum\":-183243186,\"seqId\":325069864651,\"prevSeqId\":325069864468}]}"}
{"action": "update", "capture_sequence": 121, "channel": "books", "connection_sequence": 2, "event": null, "instId": "BTC-USDT-SWAP", "local_receive_ts": "2026-06-21T04:25:14Z", "monotonic_ns": 1643470122958224, "raw": "{\"arg\":{\"channel\":\"books\",\"instId\":\"BTC-USDT-SWAP\"},\"action\":\"update\",\"data\":[{\"asks\":[[\"64458\",\"510.66\",\"0\",\"70\"],[\"64458.9\",\"0\",\"0\",\"0\"],[\"64460.3\",\"0.01\",\"0\",\"1\"],[\"64461.1\",\"1.58\",\"0\",\"3\"],[\"64461.2\",\"54.12\",\"0\",\"4\"],[\"64465.3\",\"1.56\",\"0\",\"1\"],[\"64466.7\",\"0.01\",\"0\",\"1\"],[\"64467.1\",\"0.02\",\"0\",\"1\"],[\"64477.9\",\"0\",\"0\",\"0\"],[\"64478.5\",\"1.55\",\"0\",\"1\"],[\"64483\",\"200\",\"0\",\"1\"],[\"64483.1\",\"134.1\",\"0\",\"5\"],[\"64487.9\",\"0.01\",\"0\",\"1\"],[\"64488.1\",\"86.04\",\"0\",\"3\"],[\"64492.6\",\"185.05\",\"0\",\"2\"],[\"64494.1\",\"0\",\"0\",\"0\"],[\"64494.2\",\"21.27\",\"0\",\"2\"],[\"64508.5\",\"0\",\"0\",\"0\"]],\"bids\":[[\"64457.9\",\"467.46\",\"0\",\"20\"],[\"64456.4\",\"44.6\",\"0\",\"3\"],[\"64451.4\",\"77.99\",\"0\",\"3\"],[\"64451.3\",\"13.68\",\"0\",\"7\"],[\"64443.9\",\"33.82\",\"0\",\"1\"],[\"64443.8\",\"20.09\",\"0\",\"1\"],[\"64443.6\",\"0.01\",\"0\",\"1\"],[\"64442.7\",\"85.42\",\"0\",\"1\"],[\"64442.4\",\"0.01\",\"0\",\"1\"],[\"64437.5\",\"31.06\",\"0\",\"1\"],[\"64437.4\",\"0\",\"0\",\"0\"],[\"64405.1\",\"0\",\"0\",\"0\"],[\"64405\",\"0\",\"0\",\"0\"]],\"ts\":\"1782015914205\",\"checksum\":2115506648,\"seqId\":325069864869,\"prevSeqId\":325069864651}]}"}
{"action": "update", "capture_sequence": 122, "channel": "books", "connection_sequence": 2, "event": null, "instId": "BTC-USDT-SWAP", "local_receive_ts": "2026-06-21T04:25:14Z", "monotonic_ns": 1643470222861689, "raw": "{\"arg\":{\"channel\":\"books\",\"instId\":\"BTC-USDT-SWAP\"},\"action\":\"update\",\"data\":[{\"asks\":[[\"64460.4\",\"0\",\"0\",\"0\"],[\"64465.3\",\"0\",\"0\",\"0\"],[\"64483.1\",\"100.3\",\"0\",\"4\"],[\"64483.8\",\"34.57\",\"0\",\"2\"],[\"64484.1\",\"0.33\",\"0\",\"2\"],[\"64484.5\",\"0.06\",\"0\",\"3\"],[\"64487.5\",\"43.47\",\"0\",\"6\"],[\"64487.6\",\"359.65\",\"0\",\"2\"],[\"64487.9\",\"85.38\",\"0\",\"2\"],[\"64488.1\",\"0.67\",\"0\",\"2\"],[\"64492.6\",\"98.92\",\"0\",\"1\"],[\"64493.5\",\"88.42\",\"0\",\"6\"],[\"64494.2\",\"1.2\",\"0\",\"1\"],[\"64494.7\",\"45.82\",\"0\",\"8\"],[\"64508.5\",\"42.46\",\"0\",\"3\"],[\"64508.6\",\"0.01\",\"0\",\"1\"]],\"bids\":[[\"64451.9\",\"0\",\"0\",\"0\"],[\"64451.5\",\"16.21\",\"0\",\"2\"],[\"64444.5\",\"34.59\",\"0\",\"2\"],[\"64444.1\",\"20.1\",\"0\",\"2\"],[\"64443.9\",\"0\",\"0\",\"0\"],[\"64443.8\",\"0\",\"0\",\"0\"],[\"64442.7\",\"0\",\"0\",\"0\"],[\"64442.4\",\"85.44\",\"0\",\"2\"],[\"64441.4\",\"50.02\",\"0\",\"3\"],[\"64441.3\",\"50.02\",\"0\",\"2\"],[\"64439.8\",\"58.25\",\"0\",\"1\"],[\"64439.6\",\"0\",\"0\",\"0\"],[\"64405.1\",\"0.07\",\"0\",\"3\"],[\"64405\",\"13.52\",\"0\",\"15\"],[\"64404.8\",\"0.04\",\"0\",\"1\"],[\"64404.7\",\"0.77\",\"0\",\"1\"]],\"ts\":\"1782015914305\",\"checksum\":-1894205875,\"seqId\":325069865036,\"prevSeqId\":325069864869}]}"}
{"action": "update", "capture_sequence": 123, "channel": "books", "connection_sequence": 2, "event": null, "instId": "BTC-USDT-SWAP", "local_receive_ts": "2026-06-21T04:25:14Z", "monotonic_ns": 1643470327813863, "raw": "{\"arg\":{\"channel\":\"books\",\"instId\":\"BTC-USDT-SWAP\"},\"action\":\"update\",\"data\":[{\"asks\":[[\"64458.4\",\"36.96\",\"0\",\"2\"],[\"64458.8\",\"15.53\",\"0\",\"1\"],[\"64459.2\",\"0.01\",\"0\",\"1\"],[\"64459.3\",\"1.03\",\"0\",\"4\"],[\"64460.1\",\"0.03\",\"0\",\"3\"],[\"64460.2\",\"119.8\",\"0\",\"3\"],[\"64460.3\",\"0\",\"0\",\"0\"],[\"64461.1\",\"119.04\",\"0\",\"3\"],[\"64461.2\",\"85.07\",\"0\",\"3\"],[\"64461.5\",\"0.01\",\"0\",\"1\"],[\"64463.8\",\"38.81\",\"0\",\"5\"],[\"64464\",\"7.83\",\"0\",\"3\"],[\"64464.1\",\"0.03\",\"0\",\"3\"],[\"64471.9\",\"15.54\",\"0\",\"3\"],[\"64472.7\",\"24\",\"0\",\"2\"],[\"64474.6\",\"31.05\",\"0\",\"1\"],[\"64475.4\",\"232.87\",\"0\",\"1\"],[\"64475.5\",\"0\",\"0\",\"0\"],[\"64476.7\",\"0\",\"0\",\"0\"],[\"64477.2\",\"1.55\",\"0\",\"1\"],[\"64478.5\",\"0\",\"0\",\"0\"],[\"64482.9\",\"144.7\",\"0\",\"3\"],[\"64483.8\",\"0.77\",\"0\",\"1\"],[\"64484.1\",\"0.02\",\"0\",\"1\"],[\"64484.5\",\"0.37\",\"0\",\"4\"],[\"64487.4\",\"144.06\",\"0\",\"7\"],[\"64487.6\",\"301.45\",\"0\",\"1\"],[\"64487.9\",\"0.01\",\"0\",\"1\"],[\"64492.5\",\"86.2\",\"0\",\"5\"],[\"64493\",\"33.79\",\"0\",\"5\"],[\"64493.5\",\"2.29\",\"0\",\"5\"],[\"64494.7\",\"25.75\",\"0\",\"7\"],[\"64508.6\",\"0\",\"0\",\"0\"]],\"bids\":[[\"64457.9\",\"238.68\",\"0\",\"18\"],[\"64457.8\",\"0.14\",\"0\",\"2\"],[\"64457\",\"0.01\",\"0\",\"1\"],[\"64456.9\",\"0\",\"0\",\"0\"],[\"64456.5\",\"0.62\",\"0\",\"3\"],[\"64456.4\",\"25.53\",\"0\",\"2\"],[\"64456\",\"0.02\",\"0\",\"2\"],[\"64455.9\",\"0.01\",\"0\",\"1\"],[\"64454.8\",\"0.79\",\"0\",\"3\"],[\"64454.7\",\"37.27\",\"0\",\"4\"],[\"64453.2\",\"0\",\"0\",\"0\"],[\"64452.5\",\"0.31\",\"0\",\"1\"],[\"64452.2\",\"3.94\",\"0\",\"2\"],[\"64451.9\",\"0.31\",\"0\",\"1\"],[\"64451.8\",\"0.01\",\"0\",\"1\"],[\"64451.7\",\"303.36\",\"0\",\"5\"],[\"64451.5\",\"15.9\",\"0\",\"1\"],[\"64451.4\",\"0.42\",\"0\",\"2\"],[\"64450.5\",\"5.67\",\"0\",\"4\"],[\"64450.4\",\"77.88\",\"0\",\"2\"],[\"64444.5\",\"0.77\",\"0\",\"1\"],[\"64444.1\",\"0.01\",\"0\",\"1\"],[\"64443.8\",\"33.82\",\"0\",\"1\"],[\"64443.5\",\"0\",\"0\",\"0\"],[\"64442.5\",\"106.29\",\"0\",\"2\"],[\"64442.4\",\"0.01\",\"0\",\"1\"],[\"64441.7\",\"85.45\",\"0\",\"2\"],[\"64439.8\",\"0\",\"0\",\"0\"],[\"64439\",\"58.26\",\"0\",\"2\"],[\"64437.5\",\"0\",\"0\",\"0\"],[\"64437\",\"31.06\",\"0\",\"1\"],[\"64436.2\",\"233.01\",\"0\",\"1\"],[\"64410.4\",\"0.31\",\"0\",\"1\"],[\"64408.5\",\"0.38\",\"0\",\"1\"],[\"64404.7\",\"0\",\"0\",\"0\"]],\"ts\":\"1782015914405\",\"checksum\":172326872,\"seqId\":325069865217,\"prevSeqId\":325069865036}]}"}
{"action": "update", "capture_sequence": 124, "channel": "books", "connection_sequence": 2, "event": null, "instId": "BTC-USDT-SWAP", "local_receive_ts": "2026-06-21T04:25:14Z", "monotonic_ns": 1643470428088887, "raw": "{\"arg\":{\"channel\":\"books\",\"instId\":\"BTC-USDT-SWAP\"},\"action\":\"update\",\"data\":[{\"asks\":[[\"64458.7\",\"0.01\",\"0\",\"1\"],[\"64460.1\",\"0.02\",\"0\",\"2\"],[\"64461.1\",\"0.02\",\"0\",\"2\"],[\"64461.2\",\"54.14\",\"0\",\"3\"],[\"64463.8\",\"0.01\",\"0\",\"1\"],[\"64464\",\"14.04\",\"0\",\"4\"],[\"64464.1\",\"32.62\",\"0\",\"6\"],[\"64464.2\",\"403.44\",\"0\",\"4\"],[\"64465.3\",\"0.02\",\"0\",\"1\"],[\"64467.1\",\"0\",\"0\",\"0\"],[\"64471.9\",\"0.02\",\"0\",\"2\"],[\"64472.6\",\"15.53\",\"0\",\"2\"],[\"64473.7\",\"276\",\"0\",\"3\"],[\"64473.8\",\"0.07\",\"0\",\"6\"],[\"64474.6\",\"0\",\"0\",\"0\"],[\"64474.8\",\"31.16\",\"0\",\"2\"],[\"64475\",\"263.06\",\"0\",\"9\"],[\"64475.4\",\"0\",\"0\",\"0\"],[\"64475.5\",\"0.01\",\"0\",\"1\"],[\"64475.6\",\"233.26\",\"0\",\"3\"],[\"64475.8\",\"46.54\",\"0\",\"1\"],[\"64476.9\",\"0.03\",\"0\",\"3\"],[\"64479.7\",\"0\",\"0\",\"0\"],[\"64479.9\",\"62.21\",\"0\",\"4\"],[\"64481.1\",\"62.3\",\"0\",\"2\"],[\"64483\",\"200.77\",\"0\",\"2\"],[\"64483.8\",\"0\",\"0\",\"0\"],[\"64484.1\",\"0.33\",\"0\",\"2\"],[\"64484.5\",\"0.06\",\"0\",\"3\"],[\"64486.7\",\"0.03\",\"0\",\"2\"],[\"64487.7\",\"130.34\",\"0\",\"4\"],[\"64493\",\"13.72\",\"0\",\"4\"],[\"64493.3\",\"600.4\",\"0\",\"7\"],[\"64508.6\",\"0.01\",\"0\",\"1\"],[\"64508.7\",\"42.88\",\"0\",\"9\"]],\"bids\":[[\"64457.9\",\"228.68\",\"0\",\"17\"],[\"64456.4\",\"82.33\",\"0\",\"2\"],[\"64454.9\",\"31.05\",\"0\",\"1\"],[\"64454.8\",\"106.11\",\"0\",\"4\"],[\"64454.6\",\"124.12\",\"0\",\"2\"],[\"64452.8\",\"0.36\",\"0\",\"2\"],[\"64452.5\",\"0\",\"0\",\"0\"],[\"64452.1\",\"0.03\",\"0\",\"3\"],[\"64451.9\",\"0\",\"0\",\"0\"],[\"64451.5\",\"16.21\",\"0\",\"2\"],[\"64451.3\",\"14.45\",\"0\",\"8\"],[\"64451.1\",\"0\",\"0\",\"0\"],[\"64450.6\",\"77.57\",\"0\",\"1\"],[\"64450.5\",\"4.9\",\"0\",\"3\"],[\"64450.4\",\"0.31\",\"0\",\"1\"],[\"64450\",\"0.03\",\"0\",\"3\"],[\"64444.5\",\"0\",\"0\",\"0\"],[\"64443.9\",\"0.77\",\"0\",\"1\"],[\"64443.4\",\"403.67\",\"0\",\"1\"],[\"64443.3\",\"130.09\",\"0\",\"2\"],[\"64443.1\",\"3.19\",\"0\",\"3\"],[\"64442.9\",\"20.09\",\"0\",\"1\"],[\"64442.5\",\"86.2\",\"0\",\"1\"],[\"64441.3\",\"50\",\"0\",\"1\"],[\"64440\",\"99.45\",\"0\",\"6\"],[\"64437.2\",\"31.07\",\"0\",\"2\"],[\"64437\",\"0\",\"0\",\"0\"],[\"64436.9\",\"354.24\",\"0\",\"2\"],[\"64436.8\",\"233.03\",\"0\",\"2\"],[\"64436.2\",\"0\",\"0\",\"0\"],[\"64404.7\",\"0.77\",\"0\",\"1\"]],\"ts\":\"1782015914505\",\"checksum\":1452902847,\"seqId\":325069865394,\"prevSeqId\":325069865217}]}"}
{"action": "update", "capture_sequence": 125, "channel": "books", "connection_sequence": 2, "event": null, "instId": "BTC-USDT-SWAP", "local_receive_ts": "2026-06-21T04:25:14Z", "monotonic_ns": 1643470522968879, "raw": "{\"arg\":{\"channel\":\"books\",\"instId\":\"BTC-USDT-SWAP\"},\"action\":\"update\",\"data\":[{\"asks\":[[\"64458.3\",\"6.9\",\"0\",\"4\"],[\"64458.4\",\"0.01\",\"0\",\"1\"],[\"64460.2\",\"0.78\",\"0\",\"2\"],[\"64460.8\",\"87.09\",\"0\",\"1\"],[\"64460.9\",\"104.23\",\"0\",\"1\"],[\"64461.2\",\"0.03\",\"0\",\"2\"],[\"64465.3\",\"0\",\"0\",\"0\"],[\"64465.8\",\"64.04\",\"0\",\"3\"],[\"64474.8\",\"0.11\",\"0\",\"1\"],[\"64475.5\",\"31.05\",\"0\",\"2\"],[\"64477.2\",\"0\",\"0\",\"0\"],[\"64477.7\",\"1.55\",\"0\",\"1\"],[\"64486.3\",\"238.1\",\"0\",\"5\"],[\"64487.4\",\"85.86\",\"0\",\"6\"],[\"64508.7\",\"0\",\"0\",\"0\"]],\"bids\":[[\"64457.9\",\"238.68\",\"0\",\"18\"],[\"64451.1\",\"0.01\",\"0\",\"1\"],[\"64450.8\",\"77.57\",\"0\",\"1\"],[\"64450.6\",\"0\",\"0\",\"0\"],[\"64450\",\"0.02\",\"0\",\"2\"],[\"64443.3\",\"130.12\",\"0\",\"4\"],[\"64443.1\",\"3.16\",\"0\",\"1\"],[\"64441.3\",\"50.02\",\"0\",\"2\"],[\"64440\",\"99.43\",\"0\",\"5\"],[\"64439\",\"0.01\",\"0\",\"1\"],[\"64438.2\",\"58.26\",\"0\",\"2\"],[\"64437.4\",\"31.06\",\"0\",\"1\"],[\"64437.2\",\"0.01\",\"0\",\"1\"],[\"64404.8\",\"0\",\"0\",\"0\"],[\"64404.7\",\"0\",\"0\",\"0\"]],\"ts\":\"1782015914605\",\"checksum\":-1709975248,\"seqId\":325069865503,\"prevSeqId\":325069865394}]}"}
{"action": null, "capture_sequence": 126, "channel": "trades", "connection_sequence": 2, "event": null, "instId": "BTC-USDT-SWAP", "local_receive_ts": "2026-06-21T04:25:14Z", "monotonic_ns": 1643470596159276, "raw": "{\"arg\":{\"channel\":\"trades\",\"instId\":\"BTC-USDT-SWAP\"},\"data\":[{\"instId\":\"BTC-USDT-SWAP\",\"tradeId\":\"2718748856\",\"px\":\"64457.9\",\"sz\":\"0.14\",\"side\":\"sell\",\"ts\":\"1782015914678\",\"count\":\"1\",\"source\":\"0\",\"seqId\":325069865625}]}"}
{"action": "update", "capture_sequence": 127, "channel": "books", "connection_sequence": 2, "event": null, "instId": "BTC-USDT-SWAP", "local_receive_ts": "2026-06-21T04:25:14Z", "monotonic_ns": 1643470622993406, "raw": "{\"arg\":{\"channel\":\"books\",\"instId\":\"BTC-USDT-SWAP\"},\"action\":\"update\",\"data\":[{\"asks\":[[\"64458\",\"511.15\",\"0\",\"71\"],[\"64458.2\",\"0.01\",\"0\",\"1\"],[\"64458.3\",\"6.89\",\"0\",\"3\"],[\"64458.7\",\"0.02\",\"0\",\"2\"],[\"64460.8\",\"55.97\",\"0\",\"1\"],[\"64460.9\",\"0\",\"0\",\"0\"],[\"64461.1\",\"0.01\",\"0\",\"1\"],[\"64464\",\"14.81\",\"0\",\"5\"],[\"64464.1\",\"31.85\",\"0\",\"5\"],[\"64476.3\",\"0\",\"0\",\"0\"],[\"64508.7\",\"42.88\",\"0\",\"9\"]],\"bids\":[[\"64457.9\",\"229.08\",\"0\",\"18\"],[\"64456.8\",\"0.02\",\"0\",\"2\"],[\"64456.7\",\"119.34\",\"0\",\"2\"],[\"64456.5\",\"0.6\",\"0\",\"1\"],[\"64456.4\",\"0.01\",\"0\",\"1\"],[\"64455.9\",\"0.02\",\"0\",\"2\"],[\"64455.8\",\"31.83\",\"0\",\"3\"],[\"64455.7\",\"119.02\",\"0\",\"1\"],[\"64454.9\",\"0\",\"0\",\"0\"],[\"64454.8\",\"0.01\",\"0\",\"1\"],[\"64454.7\",\"37.26\",\"0\",\"3\"],[\"64443.1\",\"0\",\"0\",\"0\"],[\"64436.3\",\"117.15\",\"0\",\"4\"],[\"64405.1\",\"0\",\"0\",\"0\"],[\"64405\",\"0\",\"0\",\"0\"]],\"ts\":\"1782015914705\",\"checksum\":954405451,\"seqId\":325069865659,\"prevSeqId\":325069865503}]}"}
{"action": "update", "capture_sequence": 128, "channel": "books", "connection_sequence": 2, "event": null, "instId": "BTC-USDT-SWAP", "local_receive_ts": "2026-06-21T04:25:14Z", "monotonic_ns": 1643470722753201, "raw": "{\"arg\":{\"channel\":\"books\",\"instId\":\"BTC-USDT-SWAP\"},\"action\":\"update\",\"data\":[{\"asks\":[[\"64460.8\",\"84.57\",\"0\",\"2\"],[\"64463.9\",\"120.58\",\"0\",\"2\"],[\"64470.1\",\"10.69\",\"0\",\"2\"],[\"64475.6\",\"0.39\",\"0\",\"2\"],[\"64476.4\",\"0.16\",\"0\",\"1\"],[\"64476.7\",\"232.87\",\"0\",\"1\"],[\"64483\",\"200\",\"0\",\"1\"],[\"64483.3\",\"0.82\",\"0\",\"3\"],[\"64493.3\",\"580.33\",\"0\",\"6\"],[\"64493.7\",\"379.36\",\"0\",\"6\"],[\"64508.6\",\"0\",\"0\",\"0\"],[\"64508.7\",\"0\",\"0\",\"0\"]],\"bids\":[[\"64456.7\",\"75.37\",\"0\",\"1\"],[\"64453.1\",\"0.01\",\"0\",\"1\"],[\"64453\",\"0.31\",\"0\",\"1\"],[\"64452.8\",\"0.05\",\"0\",\"1\"],[\"64450.9\",\"77.57\",\"0\",\"1\"],[\"64450.8\",\"0\",\"0\",\"0\"],[\"64444.4\",\"10.77\",\"0\",\"2\"],[\"64443.9\",\"0\",\"0\",\"0\"],[\"64443.3\",\"150.21\",\"0\",\"5\"],[\"64443\",\"3.24\",\"0\",\"3\"],[\"64442.9\",\"0\",\"0\",\"0\"],[\"64437\",\"233.01\",\"0\",\"1\"],[\"64436.8\",\"0.02\",\"0\",\"1\"],[\"64436.2\",\"0.19\",\"0\",\"1\"],[\"64405.2\",\"0\",\"0\",\"0\"]],\"ts\":\"1782015914805\",\"checksum\":261853210,\"seqId\":325069865784,\"prevSeqId\":325069865659}]}"}
{"action": null, "capture_sequence": 129, "channel": "trades", "connection_sequence": 2, "event": null, "instId": "BTC-USDT-SWAP", "local_receive_ts": "2026-06-21T04:25:14Z", "monotonic_ns": 1643470791416678, "raw": "{\"arg\":{\"channel\":\"trades\",\"instId\":\"BTC-USDT-SWAP\"},\"data\":[{\"instId\":\"BTC-USDT-SWAP\",\"tradeId\":\"2718748868\",\"px\":\"64458\",\"sz\":\"90.78\",\"side\":\"buy\",\"ts\":\"1782015914874\",\"count\":\"12\",\"source\":\"0\",\"seqId\":325069865853}]}"}
{"action": "update", "capture_sequence": 130, "channel": "books", "connection_sequence": 2, "event": null, "instId": "BTC-USDT-SWAP", "local_receive_ts": "2026-06-21T04:25:15Z", "monotonic_ns": 1643470827860016, "raw": "{\"arg\":{\"channel\":\"books\",\"instId\":\"BTC-USDT-SWAP\"},\"action\":\"update\",\"data\":[{\"asks\":[[\"64458\",\"405.81\",\"0\",\"56\"],[\"64461.2\",\"0.02\",\"0\",\"1\"],[\"64461.3\",\"0\",\"0\",\"0\"],[\"64461.5\",\"0\",\"0\",\"0\"],[\"64461.6\",\"0\",\"0\",\"0\"],[\"64462.3\",\"0\",\"0\",\"0\"],[\"64462.4\",\"0\",\"0\",\"0\"],[\"64462.9\",\"0.01\",\"0\",\"1\"],[\"64463.2\",\"7.76\",\"0\",\"4\"],[\"64463.3\",\"150.9\",\"0\",\"2\"],[\"64463.4\",\"0\",\"0\",\"0\"],[\"64463.8\",\"31.06\",\"0\",\"2\"],[\"64463.9\",\"0\",\"0\",\"0\"],[\"64464\",\"7.83\",\"0\",\"3\"],[\"64464.1\",\"0.03\",\"0\",\"3\"],[\"64464.2\",\"209.9\",\"0\",\"2\"],[\"64466.6\",\"0.01\",\"0\",\"1\"],[\"64472.6\",\"0.01\",\"0\",\"1\"],[\"64474.2\",\"15.81\",\"0\",\"2\"],[\"64475.5\",\"0.01\",\"0\",\"1\"],[\"64476.7\",\"31.04\",\"0\",\"1\"],[\"64477.4\",\"232.95\",\"0\",\"4\"],[\"64477.7\",\"0\",\"0\",\"0\"],[\"64479.1\",\"1.55\",\"0\",\"1\"],[\"64482.9\",\"110.9\",\"0\",\"2\"],[\"64483.8\",\"33.8\",\"0\",\"1\"],[\"64486.3\",\"179.9\",\"0\",\"4\"],[\"64487.4\",\"0.49\",\"0\",\"5\"],[\"64488.1\",\"58.87\",\"0\",\"3\"],[\"64488.6\",\"85.38\",\"0\",\"3\"],[\"64492.5\",\"0.06\",\"0\",\"4\"],[\"64493.1\",\"117.89\",\"0\",\"6\"],[\"64493.7\",\"359.29\",\"0\",\"5\"],[\"64494.7\",\"45.82\",\"0\",\"8\"],[\"64508.6\",\"0.01\",\"0\",\"1\"],[\"64508.7\",\"42.88\",\"0\",\"9\"],[\"64508.8\",\"0.04\",\"0\",\"2\"],[\"64508.9\",\"11.25\",\"0\",\"3\"],[\"64509\",\"155.92\",\"0\",\"2\"],[\"64509.1\",\"0.02\",\"0\",\"2\"]],\"bids\":[[\"64457.9\",\"657.06\",\"0\",\"26\"],[\"64456.8\",\"39.72\",\"0\",\"3\"],[\"64456.7\",\"0\",\"0\",\"0\"],[\"64456.6\",\"0.07\",\"0\",\"1\"],[\"64456.5\",\"0\",\"0\",\"0\"],[\"64455.9\",\"0.01\",\"0\",\"1\"],[\"64455.8\",\"0\",\"0\",\"0\"],[\"64455.7\",\"0\",\"0\",\"0\"],[\"64454.8\",\"0.02\",\"0\",\"2\"],[\"64454.7\",\"37.27\",\"0\",\"4\"],[\"64454.6\",\"46.54\",\"0\",\"1\"],[\"64454.5\",\"0.32\",\"0\",\"2\"],[\"64453\",\"0\",\"0\",\"0\"],[\"64452.7\",\"0.3\",\"0\",\"1\"],[\"64452.2\",\"17.9\",\"0\",\"5\"],[\"64452.1\",\"108.66\",\"0\",\"5\"],[\"64451.3\",\"13.68\",\"0\",\"7\"],[\"64450.9\",\"0\",\"0\",\"0\"],[\"64444.5\",\"33.82\",\"0\",\"1\"],[\"64443.8\",\"20.09\",\"0\",\"1\"],[\"64443.5\",\"86.2\",\"0\",\"1\"],[\"64443.3\",\"130.12\",\"0\",\"4\"],[\"64443.1\",\"85.42\",\"0\",\"1\"],[\"64442.5\",\"0\",\"0\",\"0\"],[\"64441.7\",\"0.02\",\"0\",\"1\"],[\"64440.2\",\"58.25\",\"0\",\"2\"],[\"64440.1\",\"150.57\",\"0\",\"6\"],[\"64439.5\",\"0.01\",\"0\",\"1\"],[\"64439\",\"31.07\",\"0\",\"2\"],[\"64438.7\",\"3.99\",\"0\",\"1\"],[\"64438.3\",\"233.01\",\"0\",\"2\"],[\"64438.2\",\"0.01\",\"0\",\"1\"],[\"64437.4\",\"0\",\"0\",\"0\"],[\"64437\",\"0\",\"0\",\"0\"],[\"64405.2\",\"239.07\",\"0\",\"5\"],[\"64405.1\",\"0.07\",\"0\",\"3\"],[\"64405\",\"13.52\",\"0\",\"15\"],[\"64404.8\",\"0.04\",\"0\",\"1\"],[\"64404.7\",\"0.77\",\"0\",\"1\"],[\"64404.5\",\"0.16\",\"0\",\"2\"]],\"ts\":\"1782015914905\",\"checksum\":-624734660,\"seqId\":325069865995,\"prevSeqId\":325069865784}]}"}
{"action": "update", "capture_sequence": 131, "channel": "books", "connection_sequence": 2, "event": null, "instId": "BTC-USDT-SWAP", "local_receive_ts": "2026-06-21T04:25:15Z", "monotonic_ns": 1643470932397624, "raw": "{\"arg\":{\"channel\":\"books\",\"instId\":\"BTC-USDT-SWAP\"},\"action\":\"update\",\"data\":[{\"asks\":[[\"64458\",\"485.8\",\"0\",\"51\"],[\"64458.7\",\"0\",\"0\",\"0\"],[\"64458.8\",\"0\",\"0\",\"0\"],[\"64459\",\"1.56\",\"0\",\"1\"],[\"64459.2\",\"0.02\",\"0\",\"2\"],[\"64459.3\",\"16.56\",\"0\",\"5\"],[\"64459.5\",\"1.57\",\"0\",\"2\"],[\"64460\",\"1.57\",\"0\",\"2\"],[\"64460.5\",\"1.56\",\"0\",\"1\"],[\"64460.7\",\"0.01\",\"0\",\"1\"],[\"64460.8\",\"55.97\",\"0\",\"1\"],[\"64460.9\",\"1.56\",\"0\",\"1\"],[\"64461.4\",\"1.59\",\"0\",\"4\"],[\"64461.7\",\"150\",\"0\",\"1\"],[\"64461.9\",\"1.71\",\"0\",\"2\"],[\"64462.4\",\"1.56\",\"0\",\"1\"],[\"64463.1\",\"6.23\",\"0\",\"3\"],[\"64463.2\",\"0.01\",\"0\",\"1\"],[\"64463.3\",\"0.9\",\"0\",\"1\"],[\"64463.5\",\"0.02\",\"0\",\"2\"],[\"64463.7\",\"0.01\",\"0\",\"1\"],[\"64463.8\",\"0.01\",\"0\",\"1\"],[\"64464.1\",\"32.62\",\"0\",\"6\"],[\"64464.4\",\"0.3\",\"0\",\"1\"],[\"64464.9\",\"65.64\",\"0\",\"1\"],[\"64465.8\",\"64.02\",\"0\",\"2\"],[\"64465.9\",\"1.22\",\"0\",\"2\"],[\"64468.3\",\"0.3\",\"0\",\"2\"],[\"64468.9\",\"0.14\",\"0\",\"2\"],[\"64470.9\",\"346.49\",\"0\",\"10\"],[\"64471\",\"0.31\",\"0\",\"2\"],[\"64471.6\",\"0.21\",\"0\",\"3\"],[\"64473.7\",\"275.99\",\"0\",\"2\"],[\"64473.8\",\"0.08\",\"0\",\"7\"],[\"64474.2\",\"0.29\",\"0\",\"1\"],[\"64474.6\",\"15.52\",\"0\",\"1\"],[\"64475.5\",\"0\",\"0\",\"0\"],[\"64475.8\",\"46.56\",\"0\",\"3\"],[\"64476.9\",\"0.02\",\"0\",\"2\"],[\"64478.4\",\"1.55\",\"0\",\"1\"],[\"64478.6\",\"3.12\",\"0\",\"3\"],[\"64479.1\",\"0\",\"0\",\"0\"],[\"64479.9\",\"62.2\",\"0\",\"3\"],[\"64480.3\",\"0.01\",\"0\",\"1\"],[\"64483.3\",\"0.05\",\"0\",\"2\"],[\"64483.8\",\"34.57\",\"0\",\"2\"],[\"64484.1\",\"0.02\",\"0\",\"1\"],[\"64484.5\",\"0.37\",\"0\",\"4\"],[\"64486.7\",\"0.01\",\"0\",\"1\"],[\"64487.4\",\"58.69\",\"0\",\"6\"],[\"64487.7\",\"130.36\",\"0\",\"5\"],[\"64487.9\",\"85.38\",\"0\",\"2\"],[\"64488.1\",\"0.67\",\"0\",\"2\"],[\"64488.6\",\"0.02\",\"0\",\"2\"],[\"64508.6\",\"0\",\"0\",\"0\"],[\"64508.7\",\"0\",\"0\",\"0\"],[\"64508.8\",\"0\",\"0\",\"0\"],[\"64508.9\",\"0\",\"0\",\"0\"],[\"64509\",\"0\",\"0\",\"0\"],[\"64509.1\",\"0\",\"0\",\"0\"]],\"bids\":[[\"64457.9\",\"580.41\",\"0\",\"25\"],[\"64457.7\",\"1.88\",\"0\",\"2\"],[\"64457.2\",\"1.56\",\"0\",\"1\"],[\"64456.9\",\"0.01\",\"0\",\"1\"],[\"64456.8\",\"1.56\",\"0\",\"1\"],[\"64454.9\",\"0.01\",\"0\",\"1\"],[\"64454.8\",\"28.39\",\"0\",\"3\"],[\"64454.6\",\"57.75\",\"0\",\"2\"],[\"64454.5\",\"0\",\"0\",\"0\"],[\"64454.4\",\"0.02\",\"0\",\"2\"],[\"64453.7\",\"0.31\",\"0\",\"1\"],[\"64452.5\",\"0.01\",\"0\",\"1\"],[\"64452.4\",\"3.1\",\"0\",\"3\"],[\"64452.3\",\"31.07\",\"0\",\"2\"],[\"64452.2\",\"181.83\",\"0\",\"4\"],[\"64452.1\",\"0.03\",\"0\",\"3\"],[\"64451.8\",\"77.89\",\"0\",\"3\"],[\"64451.5\",\"15.9\",\"0\",\"1\"],[\"64444.5\",\"34.59\",\"0\",\"2\"],[\"64444.4\",\"10\",\"0\",\"1\"],[\"64443.1\",\"0\",\"0\",\"0\"],[\"64442.4\",\"85.44\",\"0\",\"2\"],[\"64441.9\",\"36.96\",\"0\",\"3\"],[\"64441.7\",\"0\",\"0\",\"0\"],[\"64441.5\",\"61.31\",\"0\",\"3\"],[\"64441.3\",\"50\",\"0\",\"1\"],[\"64440.2\",\"0.01\",\"0\",\"1\"],[\"64439.4\",\"58.26\",\"0\",\"2\"],[\"64439.2\",\"0.02\",\"0\",\"1\"],[\"64439\",\"0.01\",\"0\",\"1\"],[\"64438.8\",\"31.06\",\"0\",\"1\"],[\"64438.3\",\"0.01\",\"0\",\"1\"],[\"64438.2\",\"233.01\",\"0\",\"2\"],[\"64436.8\",\"1\",\"0\",\"1\"],[\"64431.9\",\"17.94\",\"0\",\"3\"],[\"64431.6\",\"496.53\",\"0\",\"1\"],[\"64415.9\",\"0.01\",\"0\",\"1\"],[\"64415.2\",\"0.01\",\"0\",\"1\"],[\"64405.1\",\"0\",\"0\",\"0\"],[\"64405\",\"0\",\"0\",\"0\"],[\"64404.8\",\"0\",\"0\",\"0\"],[\"64404.7\",\"0\",\"0\",\"0\"],[\"64404.5\",\"0\",\"0\",\"0\"]],\"ts\":\"1782015915005\",\"checksum\":916520838,\"seqId\":325069866242,\"prevSeqId\":325069865995}]}"}
{"action": "update", "capture_sequence": 132, "channel": "books", "connection_sequence": 2, "event": null, "instId": "BTC-USDT-SWAP", "local_receive_ts": "2026-06-21T04:25:15Z", "monotonic_ns": 1643471028129085, "raw": "{\"arg\":{\"channel\":\"books\",\"instId\":\"BTC-USDT-SWAP\"},\"action\":\"update\",\"data\":[{\"asks\":[[\"64458.3\",\"6.89\",\"0\",\"4\"],[\"64458.7\",\"0.01\",\"0\",\"1\"],[\"64458.8\",\"15.53\",\"0\",\"1\"],[\"64459\",\"0\",\"0\",\"0\"],[\"64459.2\",\"0.01\",\"0\",\"1\"],[\"64459.3\",\"1.03\",\"0\",\"4\"],[\"64459.5\",\"0.01\",\"0\",\"1\"],[\"64460\",\"0.01\",\"0\",\"1\"],[\"64460.5\",\"0\",\"0\",\"0\"],[\"64460.6\",\"1.56\",\"0\",\"1\"],[\"64460.9\",\"0\",\"0\",\"0\"],[\"64462.8\",\"1.56\",\"0\",\"1\"],[\"64463.3\",\"2.46\",\"0\",\"2\"],[\"64463.8\",\"1.57\",\"0\",\"2\"],[\"64464.3\",\"73.77\",\"0\",\"2\"],[\"64464.8\",\"1.56\",\"0\",\"1\"],[\"64465.2\",\"80.31\",\"0\",\"4\"],[\"64465.9\",\"1.2\",\"0\",\"1\"],[\"64467.1\",\"0.02\",\"0\",\"1\"],[\"64473.6\",\"68.29\",\"0\",\"4\"],[\"64473.8\",\"0.05\",\"0\",\"5\"],[\"64474.6\",\"0\",\"0\",\"0\"],[\"64475.1\",\"0.03\",\"0\",\"2\"],[\"64475.8\",\"46.55\",\"0\",\"2\"],[\"64475.9\",\"0.91\",\"0\",\"2\"],[\"64476.3\",\"31.04\",\"0\",\"1\"],[\"64476.7\",\"232.86\",\"0\",\"1\"],[\"64477.4\",\"0.09\",\"0\",\"3\"],[\"64478.6\",\"3.11\",\"0\",\"2\"],[\"64479.7\",\"0.01\",\"0\",\"1\"],[\"64480.3\",\"0\",\"0\",\"0\"],[\"64481.1\",\"62.31\",\"0\",\"3\"],[\"64483.7\",\"33.81\",\"0\",\"2\"],[\"64483.8\",\"0.77\",\"0\",\"1\"],[\"64487.4\",\"144.06\",\"0\",\"7\"],[\"64487.9\",\"0.01\",\"0\",\"1\"],[\"64508.1\",\"0\",\"0\",\"0\"],[\"64508.2\",\"0\",\"0\",\"0\"],[\"64508.4\",\"0\",\"0\",\"0\"],[\"64508.5\",\"0\",\"0\",\"0\"]],\"bids\":[[\"64457.9\",\"580.37\",\"0\",\"26\"],[\"64457.8\",\"0.15\",\"0\",\"3\"],[\"64457.3\",\"0.01\",\"0\",\"1\"],[\"64456.9\",\"0.02\",\"0\",\"2\"],[\"64454.8\",\"28.38\",\"0\",\"2\"],[\"64454.7\",\"37.26\",\"0\",\"3\"],[\"64453.7\",\"0\",\"0\",\"0\"],[\"64453.6\",\"0.32\",\"0\",\"2\"],[\"64452.4\",\"120.23\",\"0\",\"5\"],[\"64452.2\",\"169.41\",\"0\",\"3\"],[\"64444.6\",\"33.82\",\"0\",\"1\"],[\"64444.5\",\"0.77\",\"0\",\"1\"],[\"64442.4\",\"0.01\",\"0\",\"1\"],[\"64442.2\",\"85.43\",\"0\",\"1\"],[\"64441.9\",\"36.94\",\"0\",\"2\"],[\"64441.8\",\"535.37\",\"0\",\"3\"],[\"64439.2\",\"0\",\"0\",\"0\"],[\"64438.8\",\"0\",\"0\",\"0\"],[\"64438.7\",\"4.01\",\"0\",\"2\"],[\"64438.2\",\"31.07\",\"0\",\"2\"],[\"64437.4\",\"233\",\"0\",\"1\"],[\"64405.2\",\"0\",\"0\",\"0\"]],\"ts\":\"1782015915105\",\"checksum\":561558365,\"seqId\":325069866364,\"prevSeqId\":325069866242}]}"}
{"action": "update", "capture_sequence": 133, "channel": "books", "connection_sequence": 2, "event": null, "instId": "BTC-USDT-SWAP", "local_receive_ts": "2026-06-21T04:25:15Z", "monotonic_ns": 1643471122756884, "raw": "{\"arg\":{\"channel\":\"books\",\"instId\":\"BTC-USDT-SWAP\"},\"action\":\"update\",\"data\":[{\"asks\":[[\"64459.1\",\"1.56\",\"0\",\"1\"],[\"64461.4\",\"0.03\",\"0\",\"3\"],[\"64482.6\",\"33.81\",\"0\",\"2\"],[\"64483.7\",\"0.01\",\"0\",\"1\"],[\"64493.6\",\"168.93\",\"0\",\"2\"],[\"64494.7\",\"25.75\",\"0\",\"7\"],[\"64508\",\"0\",\"0\",\"0\"]],\"bids\":[[\"64453.6\",\"0.01\",\"0\",\"1\"],[\"64453.2\",\"0.31\",\"0\",\"1\"],[\"64452.4\",\"15.52\",\"0\",\"4\"],[\"64444.6\",\"0\",\"0\",\"0\"],[\"64443.8\",\"0\",\"0\",\"0\"],[\"64443.6\",\"33.83\",\"0\",\"2\"],[\"64443.1\",\"20.09\",\"0\",\"1\"]],\"ts\":\"1782015915205\",\"checksum\":1927456088,\"seqId\":325069866435,\"prevSeqId\":325069866364}]}"}
{"action": "update", "capture_sequence": 134, "channel": "books", "connection_sequence": 2, "event": null, "instId": "BTC-USDT-SWAP", "local_receive_ts": "2026-06-21T04:25:15Z", "monotonic_ns": 1643471222819901, "raw": "{\"arg\":{\"channel\":\"books\",\"instId\":\"BTC-USDT-SWAP\"},\"action\":\"update\",\"data\":[{\"asks\":[[\"64458\",\"485.9\",\"0\",\"52\"],[\"64458.7\",\"0.02\",\"0\",\"2\"],[\"64459.1\",\"0\",\"0\",\"0\"],[\"64460.6\",\"0\",\"0\",\"0\"],[\"64461.1\",\"1.57\",\"0\",\"2\"],[\"64461.9\",\"0.15\",\"0\",\"1\"],[\"64462.1\",\"1.56\",\"0\",\"1\"],[\"64462.4\",\"0\",\"0\",\"0\"],[\"64462.6\",\"1.57\",\"0\",\"2\"],[\"64462.8\",\"0\",\"0\",\"0\"],[\"64463.1\",\"6.22\",\"0\",\"2\"],[\"64463.2\",\"1.57\",\"0\",\"2\"],[\"64463.3\",\"0.9\",\"0\",\"1\"],[\"64465.7\",\"76.68\",\"0\",\"3\"],[\"64476.4\",\"0\",\"0\",\"0\"],[\"64508\",\"13.54\",\"0\",\"7\"],[\"64508.1\",\"21.31\",\"0\",\"3\"],[\"64508.2\",\"59.01\",\"0\",\"5\"],[\"64508.4\",\"1367.19\",\"0\",\"6\"]],\"bids\":[[\"64457.9\",\"657.95\",\"0\",\"27\"],[\"64453.6\",\"0.32\",\"0\",\"2\"],[\"64453.2\",\"0\",\"0\",\"0\"],[\"64436.2\",\"0\",\"0\",\"0\"],[\"64405.2\",\"239.07\",\"0\",\"5\"],[\"64405.1\",\"0.07\",\"0\",\"3\"]],\"ts\":\"1782015915305\",\"checksum\":687605998,\"seqId\":325069866496,\"prevSeqId\":325069866435}]}"}
{"action": "update", "capture_sequence": 135, "channel": "books", "connection_sequence": 2, "event": null, "instId": "BTC-USDT-SWAP", "local_receive_ts": "2026-06-21T04:25:15Z", "monotonic_ns": 1643471322529335, "raw": "{\"arg\":{\"channel\":\"books\",\"instId\":\"BTC-USDT-SWAP\"},\"action\":\"update\",\"data\":[{\"asks\":[[\"64461.1\",\"0.01\",\"0\",\"1\"],[\"64470.9\",\"346.66\",\"0\",\"11\"],[\"64471\",\"0.54\",\"0\",\"3\"],[\"64471.6\",\"0.04\",\"0\",\"2\"],[\"64476.4\",\"0.16\",\"0\",\"1\"],[\"64508.4\",\"0\",\"0\",\"0\"]],\"bids\":[[\"64453.6\",\"0.01\",\"0\",\"1\"],[\"64453.2\",\"0.31\",\"0\",\"1\"],[\"64436.2\",\"0.19\",\"0\",\"1\"],[\"64405.2\",\"0\",\"0\",\"0\"],[\"64405.1\",\"0\",\"0\",\"0\"]],\"ts\":\"1782015915405\",\"checksum\":-935496936,\"seqId\":325069866508,\"prevSeqId\":325069866496}]}"}
{"action": "update", "capture_sequence": 136, "channel": "books", "connection_sequence": 2, "event": null, "instId": "BTC-USDT-SWAP", "local_receive_ts": "2026-06-21T04:25:15Z", "monotonic_ns": 1643471425257305, "raw": "{\"arg\":{\"channel\":\"books\",\"instId\":\"BTC-USDT-SWAP\"},\"action\":\"update\",\"data\":[{\"asks\":[[\"64462.1\",\"0\",\"0\",\"0\"],[\"64462.6\",\"0.01\",\"0\",\"1\"],[\"64464\",\"8.6\",\"0\",\"4\"],[\"64464.1\",\"31.85\",\"0\",\"5\"],[\"64508.4\",\"1367.19\",\"0\",\"6\"]],\"bids\":[[\"64457.9\",\"657.24\",\"0\",\"27\"],[\"64452.4\",\"14.75\",\"0\",\"3\"],[\"64452.1\",\"0.8\",\"0\",\"4\"]],\"ts\":\"1782015915505\",\"checksum\":1953837675,\"seqId\":325069866516,\"prevSeqId\":325069866508}]}"}
{"action": null, "capture_sequence": 137, "channel": "trades", "connection_sequence": 2, "event": null, "instId": "BTC-USDT-SWAP", "local_receive_ts": "2026-06-21T04:25:15Z", "monotonic_ns": 1643471464923583, "raw": "{\"arg\":{\"channel\":\"trades\",\"instId\":\"BTC-USDT-SWAP\"},\"data\":[{\"instId\":\"BTC-USDT-SWAP\",\"tradeId\":\"2718748869\",\"px\":\"64457.9\",\"sz\":\"0.37\",\"side\":\"sell\",\"ts\":\"1782015915547\",\"count\":\"1\",\"source\":\"0\",\"seqId\":325069866521}]}"}
{"action": "update", "capture_sequence": 138, "channel": "books", "connection_sequence": 2, "event": null, "instId": "BTC-USDT-SWAP", "local_receive_ts": "2026-06-21T04:25:15Z", "monotonic_ns": 1643471522731426, "raw": "{\"arg\":{\"channel\":\"books\",\"instId\":\"BTC-USDT-SWAP\"},\"action\":\"update\",\"data\":[{\"asks\":[[\"64483.1\",\"101.07\",\"0\",\"5\"],[\"64483.8\",\"0\",\"0\",\"0\"],[\"64493.6\",\"148.86\",\"0\",\"1\"],[\"64494.3\",\"35.8\",\"0\",\"6\"],[\"64508.5\",\"42.46\",\"0\",\"3\"]],\"bids\":[[\"64457.9\",\"656.87\",\"0\",\"27\"],[\"64444.5\",\"0\",\"0\",\"0\"],[\"64443.8\",\"20.86\",\"0\",\"2\"],[\"64443.1\",\"0\",\"0\",\"0\"],[\"64405.2\",\"239.07\",\"0\",\"5\"]],\"ts\":\"1782015915605\",\"checksum\":533187975,\"seqId\":325069866532,\"prevSeqId\":325069866516}]}"}
{"action": "update", "capture_sequence": 139, "channel": "books", "connection_sequence": 2, "event": null, "instId": "BTC-USDT-SWAP", "local_receive_ts": "2026-06-21T04:25:15Z", "monotonic_ns": 1643471622885047, "raw": "{\"arg\":{\"channel\":\"books\",\"instId\":\"BTC-USDT-SWAP\"},\"action\":\"update\",\"data\":[{\"asks\":[[\"64476.4\",\"0\",\"0\",\"0\"],[\"64483.1\",\"100.3\",\"0\",\"4\"],[\"64483.8\",\"0.77\",\"0\",\"1\"],[\"64493.4\",\"20.39\",\"0\",\"6\"],[\"64494.3\",\"15.73\",\"0\",\"5\"]],\"bids\":[[\"64457.9\",\"656.33\",\"0\",\"26\"],[\"64457.8\",\"0.14\",\"0\",\"2\"],[\"64457.7\",\"0.32\",\"0\",\"1\"],[\"64457.3\",\"0\",\"0\",\"0\"],[\"64457.2\",\"0\",\"0\",\"0\"],[\"64456.9\",\"0\",\"0\",\"0\"],[\"64456.8\",\"0\",\"0\",\"0\"],[\"64454.9\",\"0.02\",\"0\",\"2\"],[\"64454.8\",\"28.39\",\"0\",\"3\"],[\"64454.7\",\"37.27\",\"0\",\"4\"],[\"64452.4\",\"14.76\",\"0\",\"4\"],[\"64444.5\",\"0.77\",\"0\",\"1\"],[\"64443.8\",\"0\",\"0\",\"0\"],[\"64443\",\"0.02\",\"0\",\"2\"],[\"64442.9\",\"20.09\",\"0\",\"1\"],[\"64436.2\",\"0\",\"0\",\"0\"],[\"64405.1\",\"0.07\",\"0\",\"3\"],[\"64405\",\"13.52\",\"0\",\"15\"],[\"64404.8\",\"0.04\",\"0\",\"1\"],[\"64404.7\",\"0.77\",\"0\",\"1\"]],\"ts\":\"1782015915705\",\"checksum\":-1745432730,\"seqId\":325069866555,\"prevSeqId\":325069866532}]}"}
{"action": "update", "capture_sequence": 140, "channel": "books", "connection_sequence": 2, "event": null, "instId": "BTC-USDT-SWAP", "local_receive_ts": "2026-06-21T04:25:15Z", "monotonic_ns": 1643471722729932, "raw": "{\"arg\":{\"channel\":\"books\",\"instId\":\"BTC-USDT-SWAP\"},\"action\":\"update\",\"data\":[{\"asks\":[[\"64476.4\",\"0.16\",\"0\",\"1\"],[\"64486.3\",\"238.1\",\"0\",\"5\"],[\"64487.4\",\"85.86\",\"0\",\"6\"],[\"64508.5\",\"0\",\"0\",\"0\"]],\"bids\":[[\"64450.4\",\"0.69\",\"0\",\"2\"],[\"64447.2\",\"0\",\"0\",\"0\"],[\"64442.9\",\"23.31\",\"0\",\"2\"],[\"64439.4\",\"0.01\",\"0\",\"1\"],[\"64438.3\",\"58.26\",\"0\",\"2\"],[\"64436.1\",\"25.84\",\"0\",\"3\"],[\"64420\",\"5.83\",\"0\",\"21\"],[\"64411.5\",\"22.82\",\"0\",\"2\"],[\"64404.5\",\"0.16\",\"0\",\"2\"]],\"ts\":\"1782015915805\",\"checksum\":-1745432730,\"seqId\":325069866573,\"prevSeqId\":325069866555}]}"}
{"action": null, "capture_sequence": 141, "channel": "trades", "connection_sequence": 2, "event": null, "instId": "BTC-USDT-SWAP", "local_receive_ts": "2026-06-21T04:25:16Z", "monotonic_ns": 1643471805360224, "raw": "{\"arg\":{\"channel\":\"trades\",\"instId\":\"BTC-USDT-SWAP\"},\"data\":[{\"instId\":\"BTC-USDT-SWAP\",\"tradeId\":\"2718748870\",\"px\":\"64458\",\"sz\":\"1.25\",\"side\":\"buy\",\"ts\":\"1782015915888\",\"count\":\"1\",\"source\":\"0\",\"seqId\":325069866598}]}"}
{"action": null, "capture_sequence": 142, "channel": "trades", "connection_sequence": 2, "event": null, "instId": "BTC-USDT-SWAP", "local_receive_ts": "2026-06-21T04:25:16Z", "monotonic_ns": 1643471816960383, "raw": "{\"arg\":{\"channel\":\"trades\",\"instId\":\"BTC-USDT-SWAP\"},\"data\":[{\"instId\":\"BTC-USDT-SWAP\",\"tradeId\":\"2718748871\",\"px\":\"64457.9\",\"sz\":\"3.32\",\"side\":\"sell\",\"ts\":\"1782015915899\",\"count\":\"1\",\"source\":\"0\",\"seqId\":325069866601}]}"}
{"action": "update", "capture_sequence": 143, "channel": "books", "connection_sequence": 2, "event": null, "instId": "BTC-USDT-SWAP", "local_receive_ts": "2026-06-21T04:25:16Z", "monotonic_ns": 1643471823546793, "raw": "{\"arg\":{\"channel\":\"books\",\"instId\":\"BTC-USDT-SWAP\"},\"action\":\"update\",\"data\":[{\"asks\":[[\"64458\",\"484.8\",\"0\",\"52\"],[\"64468.5\",\"46.54\",\"0\",\"1\"],[\"64468.6\",\"1.74\",\"0\",\"1\"],[\"64486.3\",\"179.9\",\"0\",\"4\"],[\"64487.3\",\"58.24\",\"0\",\"3\"],[\"64493.4\",\"0.32\",\"0\",\"5\"],[\"64494.2\",\"21.27\",\"0\",\"2\"],[\"64508.4\",\"0\",\"0\",\"0\"]],\"bids\":[[\"64457.9\",\"653.01\",\"0\",\"26\"],[\"64443.8\",\"20.09\",\"0\",\"1\"],[\"64442.9\",\"3.22\",\"0\",\"1\"],[\"64439\",\"58.26\",\"0\",\"2\"],[\"64438.3\",\"0.01\",\"0\",\"1\"],[\"64430\",\"6.59\",\"0\",\"4\"],[\"64404.5\",\"0\",\"0\",\"0\"]],\"ts\":\"1782015915905\",\"checksum\":-1327970291,\"seqId\":325069866603,\"prevSeqId\":325069866573}]}"}
{"action": "update", "capture_sequence": 144, "channel": "books", "connection_sequence": 2, "event": null, "instId": "BTC-USDT-SWAP", "local_receive_ts": "2026-06-21T04:25:16Z", "monotonic_ns": 1643471923488841, "raw": "{\"arg\":{\"channel\":\"books\",\"instId\":\"BTC-USDT-SWAP\"},\"action\":\"update\",\"data\":[{\"asks\":[[\"64459.5\",\"1.57\",\"0\",\"2\"],[\"64460\",\"1.57\",\"0\",\"2\"],[\"64476.2\",\"232.89\",\"0\",\"3\"],[\"64476.7\",\"0\",\"0\",\"0\"],[\"64478.4\",\"0\",\"0\",\"0\"],[\"64478.5\",\"1.55\",\"0\",\"1\"],[\"64482.6\",\"0.01\",\"0\",\"1\"],[\"64483.2\",\"148.49\",\"0\",\"4\"],[\"64487.4\",\"0.49\",\"0\",\"5\"],[\"64487.6\",\"301.47\",\"0\",\"2\"],[\"64487.7\",\"130.34\",\"0\",\"4\"],[\"64488.1\",\"86.03\",\"0\",\"3\"],[\"64508.4\",\"1367.19\",\"0\",\"6\"]],\"bids\":[[\"64457.9\",\"654.57\",\"0\",\"27\"],[\"64457.4\",\"1.56\",\"0\",\"1\"],[\"64456.9\",\"1.56\",\"0\",\"1\"],[\"64454.6\",\"46.54\",\"0\",\"1\"],[\"64451.8\",\"0.32\",\"0\",\"2\"],[\"64451.6\",\"77.57\",\"0\",\"1\"],[\"64444.4\",\"43.82\",\"0\",\"2\"],[\"64443.6\",\"0.01\",\"0\",\"1\"],[\"64442.7\",\"85.42\",\"0\",\"1\"],[\"64442.2\",\"0\",\"0\",\"0\"],[\"64439.4\",\"58.26\",\"0\",\"2\"],[\"64439\",\"0.01\",\"0\",\"1\"],[\"64432.1\",\"0.09\",\"0\",\"2\"],[\"64431.9\",\"17.93\",\"0\",\"2\"],[\"64405\",\"0\",\"0\",\"0\"],[\"64404.8\",\"0\",\"0\",\"0\"],[\"64404.7\",\"0\",\"0\",\"0\"]],\"ts\":\"1782015916005\",\"checksum\":-1166760374,\"seqId\":325069866643,\"prevSeqId\":325069866603}]}"}
{"action": "update", "capture_sequence": 145, "channel": "books", "connection_sequence": 2, "event": null, "instId": "BTC-USDT-SWAP", "local_receive_ts": "2026-06-21T04:25:16Z", "monotonic_ns": 1643472027405928, "raw": "{\"arg\":{\"channel\":\"books\",\"instId\":\"BTC-USDT-SWAP\"},\"action\":\"update\",\"data\":[{\"asks\":[[\"64458\",\"486.36\",\"0\",\"53\"],[\"64458.6\",\"0.01\",\"0\",\"1\"],[\"64458.7\",\"1.57\",\"0\",\"2\"],[\"64459.5\",\"0.01\",\"0\",\"1\"],[\"64460.5\",\"1.56\",\"0\",\"1\"],[\"64473.5\",\"15.52\",\"0\",\"1\"],[\"64473.6\",\"52.77\",\"0\",\"3\"],[\"64475.5\",\"31.04\",\"0\",\"1\"],[\"64476.2\",\"0.02\",\"0\",\"2\"],[\"64476.3\",\"0\",\"0\",\"0\"],[\"64476.6\",\"232.87\",\"0\",\"1\"],[\"64484.5\",\"0.06\",\"0\",\"3\"],[\"64484.6\",\"1.52\",\"0\",\"3\"],[\"64487.3\",\"0.04\",\"0\",\"2\"],[\"64487.6\",\"359.65\",\"0\",\"2\"],[\"64487.7\",\"130.36\",\"0\",\"5\"],[\"64488.1\",\"0.67\",\"0\",\"2\"],[\"64488.2\",\"89.32\",\"0\",\"3\"],[\"64494.2\",\"1.2\",\"0\",\"1\"],[\"64494.5\",\"20.07\",\"0\",\"1\"],[\"64507.9\",\"0\",\"0\",\"0\"],[\"64508\",\"0\",\"0\",\"0\"],[\"64508.1\",\"0\",\"0\",\"0\"],[\"64508.2\",\"0\",\"0\",\"0\"],[\"64508.4\",\"0\",\"0\",\"0\"]],\"bids\":[[\"64457.9\",\"653.02\",\"0\",\"26\"],[\"64457.4\",\"0\",\"0\",\"0\"],[\"64457.1\",\"0.33\",\"0\",\"2\"],[\"64456.9\",\"0\",\"0\",\"0\"],[\"64456.4\",\"0.02\",\"0\",\"2\"],[\"64456.3\",\"1.56\",\"0\",\"1\"],[\"64455.9\",\"0.02\",\"0\",\"2\"],[\"64455.8\",\"1.56\",\"0\",\"1\"],[\"64455.3\",\"1.57\",\"0\",\"2\"],[\"64454.9\",\"1.57\",\"0\",\"2\"],[\"64454.8\",\"28.38\",\"0\",\"2\"],[\"64454.7\",\"37.26\",\"0\",\"3\"],[\"64445\",\"169.75\",\"0\",\"8\"],[\"64444.5\",\"0\",\"0\",\"0\"],[\"64443\",\"85.44\",\"0\",\"3\"],[\"64442.7\",\"0\",\"0\",\"0\"],[\"64441.9\",\"36.96\",\"0\",\"3\"],[\"64441.8\",\"535.35\",\"0\",\"2\"],[\"64439.2\",\"0.02\",\"0\",\"1\"],[\"64438.7\",\"3.99\",\"0\",\"1\"],[\"64438.2\",\"0.01\",\"0\",\"1\"],[\"64438\",\"31.07\",\"0\",\"2\"],[\"64405\",\"13.52\",\"0\",\"15\"]],\"ts\":\"1782015916105\",\"checksum\":-656191203,\"seqId\":325069866740,\"prevSeqId\":325069866643}]}"}
{"action": "update", "capture_sequence": 146, "channel": "books", "connection_sequence": 2, "event": null, "instId": "BTC-USDT-SWAP", "local_receive_ts": "2026-06-21T04:25:16Z", "monotonic_ns": 1643472122903900, "raw": "{\"arg\":{\"channel\":\"books\",\"instId\":\"BTC-USDT-SWAP\"},\"action\":\"update\",\"data\":[{\"asks\":[[\"64458\",\"484.8\",\"0\",\"52\"],[\"64458.6\",\"0\",\"0\",\"0\"],[\"64458.7\",\"0.02\",\"0\",\"2\"],[\"64461\",\"1.57\",\"0\",\"2\"],[\"64461.4\",\"1.59\",\"0\",\"4\"],[\"64461.9\",\"1.71\",\"0\",\"2\"],[\"64465.7\",\"75.12\",\"0\",\"2\"],[\"64483.2\",\"114.69\",\"0\",\"3\"],[\"64483.7\",\"33.81\",\"0\",\"2\"],[\"64487.6\",\"301.45\",\"0\",\"1\"],[\"64487.9\",\"58.21\",\"0\",\"2\"],[\"64507.9\",\"0.25\",\"0\",\"2\"]],\"bids\":[[\"64457.9\",\"654.58\",\"0\",\"27\"],[\"64457.4\",\"0.01\",\"0\",\"1\"],[\"64457.3\",\"1.56\",\"0\",\"1\"],[\"64457.1\",\"0.32\",\"0\",\"1\"],[\"64456.9\",\"0.01\",\"0\",\"1\"],[\"64456.8\",\"1.56\",\"0\",\"1\"],[\"64455.9\",\"0.01\",\"0\",\"1\"],[\"64450.3\",\"40.83\",\"0\",\"1\"],[\"64449.8\",\"0.01\",\"0\",\"1\"],[\"64444.5\",\"33.82\",\"0\",\"1\"],[\"64444.4\",\"10\",\"0\",\"1\"],[\"64439.8\",\"58.25\",\"0\",\"1\"],[\"64439.4\",\"0.01\",\"0\",\"1\"],[\"64405.6\",\"0\",\"0\",\"0\"],[\"64405.5\",\"0\",\"0\",\"0\"],[\"64405.3\",\"0\",\"0\",\"0\"],[\"64405.2\",\"0\",\"0\",\"0\"],[\"64405.1\",\"0\",\"0\",\"0\"],[\"64405\",\"0\",\"0\",\"0\"]],\"ts\":\"1782015916205\",\"checksum\":1069394044,\"seqId\":325069866811,\"prevSeqId\":325069866740}]}"}
{"action": "update", "capture_sequence": 147, "channel": "books", "connection_sequence": 2, "event": null, "instId": "BTC-USDT-SWAP", "local_receive_ts": "2026-06-21T04:25:16Z", "monotonic_ns": 1643472222953514, "raw": "{\"arg\":{\"channel\":\"books\",\"instId\":\"BTC-USDT-SWAP\"},\"action\":\"update\",\"data\":[{\"asks\":[[\"64458\",\"486.36\",\"0\",\"53\"],[\"64460\",\"0.01\",\"0\",\"1\"],[\"64462.4\",\"1.56\",\"0\",\"1\"],[\"64464.8\",\"0\",\"0\",\"0\"],[\"64465.2\",\"78.75\",\"0\",\"3\"],[\"64483.8\",\"0\",\"0\",\"0\"],[\"64484.1\",\"0.79\",\"0\",\"2\"],[\"64508\",\"13.54\",\"0\",\"7\"]],\"bids\":[[\"64457.9\",\"653.02\",\"0\",\"26\"],[\"64457.3\",\"0\",\"0\",\"0\"],[\"64456.8\",\"0\",\"0\",\"0\"],[\"64454.4\",\"1.58\",\"0\",\"3\"],[\"64453.9\",\"1.57\",\"0\",\"2\"],[\"64453.5\",\"0.32\",\"0\",\"2\"],[\"64453.4\",\"1.56\",\"0\",\"1\"],[\"64453.2\",\"0\",\"0\",\"0\"],[\"64453\",\"1.56\",\"0\",\"1\"],[\"64452.5\",\"1.57\",\"0\",\"2\"],[\"64452.4\",\"13.2\",\"0\",\"3\"],[\"64451.2\",\"380.23\",\"0\",\"5\"],[\"64450.7\",\"0.04\",\"0\",\"2\"],[\"64445.1\",\"185.38\",\"0\",\"5\"],[\"64445\",\"168.98\",\"0\",\"7\"],[\"64405.6\",\"0.04\",\"0\",\"4\"]],\"ts\":\"1782015916305\",\"checksum\":784455545,\"seqId\":325069866917,\"prevSeqId\":325069866811}]}"}
{"action": "update", "capture_sequence": 148, "channel": "books", "connection_sequence": 2, "event": null, "instId": "BTC-USDT-SWAP", "local_receive_ts": "2026-06-21T04:25:16Z", "monotonic_ns": 1643472323211731, "raw": "{\"arg\":{\"channel\":\"books\",\"instId\":\"BTC-USDT-SWAP\"},\"action\":\"update\",\"data\":[{\"asks\":[[\"64458\",\"484.8\",\"0\",\"52\"],[\"64458.8\",\"17.09\",\"0\",\"2\"],[\"64459.4\",\"1.56\",\"0\",\"1\"],[\"64475.5\",\"0\",\"0\",\"0\"],[\"64475.8\",\"77.59\",\"0\",\"3\"],[\"64483.1\",\"134.1\",\"0\",\"5\"],[\"64483.7\",\"0.01\",\"0\",\"1\"],[\"64487.9\",\"0.01\",\"0\",\"1\"],[\"64488.3\",\"97.04\",\"0\",\"3\"],[\"64492.6\",\"185.05\",\"0\",\"2\"],[\"64493.1\",\"31.76\",\"0\",\"5\"]],\"bids\":[[\"64457.4\",\"0\",\"0\",\"0\"],[\"64456.9\",\"0\",\"0\",\"0\"],[\"64456.4\",\"0.01\",\"0\",\"1\"],[\"64456.3\",\"0\",\"0\",\"0\"],[\"64455.8\",\"0\",\"0\",\"0\"],[\"64455.4\",\"0.01\",\"0\",\"1\"],[\"64455\",\"0.02\",\"0\",\"2\"],[\"64454.9\",\"1.58\",\"0\",\"3\"],[\"64444.5\",\"0\",\"0\",\"0\"],[\"64443.9\",\"33.82\",\"0\",\"1\"],[\"64443\",\"0.02\",\"0\",\"2\"],[\"64442.7\",\"85.42\",\"0\",\"1\"],[\"64440.2\",\"58.25\",\"0\",\"2\"],[\"64439.8\",\"0\",\"0\",\"0\"],[\"64438.2\",\"31.07\",\"0\",\"2\"],[\"64438\",\"0.01\",\"0\",\"1\"],[\"64405.6\",\"0.02\",\"0\",\"2\"],[\"64405.5\",\"0.01\",\"0\",\"1\"],[\"64405.3\",\"46.54\",\"0\",\"1\"],[\"64405.2\",\"239.07\",\"0\",\"5\"]],\"ts\":\"1782015916405\",\"checksum\":1479974060,\"seqId\":325069866968,\"prevSeqId\":325069866917}]}"}
{"action": null, "capture_sequence": 149, "channel": "trades", "connection_sequence": 2, "event": null, "instId": "BTC-USDT-SWAP", "local_receive_ts": "2026-06-21T04:25:16Z", "monotonic_ns": 1643472334509997, "raw": "{\"arg\":{\"channel\":\"trades\",\"instId\":\"BTC-USDT-SWAP\"},\"data\":[{\"instId\":\"BTC-USDT-SWAP\",\"tradeId\":\"2718748872\",\"px\":\"64458\",\"sz\":\"0.73\",\"side\":\"buy\",\"ts\":\"1782015916417\",\"count\":\"1\",\"source\":\"0\",\"seqId\":325069866980}]}"}
{"action": "update", "capture_sequence": 150, "channel": "books", "connection_sequence": 2, "event": null, "instId": "BTC-USDT-SWAP", "local_receive_ts": "2026-06-21T04:25:16Z", "monotonic_ns": 1643472423066242, "raw": "{\"arg\":{\"channel\":\"books\",\"instId\":\"BTC-USDT-SWAP\"},\"action\":\"update\",\"data\":[{\"asks\":[[\"64458\",\"484.07\",\"0\",\"52\"],[\"64458.8\",\"15.53\",\"0\",\"1\"],[\"64487.5\",\"101.67\",\"0\",\"7\"],[\"64487.9\",\"85.38\",\"0\",\"2\"],[\"64488.2\",\"3.96\",\"0\",\"2\"],[\"64488.3\",\"38.84\",\"0\",\"2\"],[\"64494.1\",\"20.07\",\"0\",\"1\"],[\"64494.5\",\"0\",\"0\",\"0\"]],\"bids\":[[\"64443.8\",\"0\",\"0\",\"0\"],[\"64443.6\",\"20.1\",\"0\",\"2\"],[\"64442.7\",\"0\",\"0\",\"0\"],[\"64442.4\",\"85.43\",\"0\",\"2\"],[\"64440.2\",\"0.01\",\"0\",\"1\"],[\"64439.4\",\"58.26\",\"0\",\"2\"],[\"64405.1\",\"0.07\",\"0\",\"3\"],[\"64405\",\"13.52\",\"0\",\"15\"]],\"ts\":\"1782015916505\",\"checksum\":1910076794,\"seqId\":325069866990,\"prevSeqId\":325069866968}]}"}
{"action": "update", "capture_sequence": 151, "channel": "books", "connection_sequence": 2, "event": null, "instId": "BTC-USDT-SWAP", "local_receive_ts": "2026-06-21T04:25:16Z", "monotonic_ns": 1643472522822486, "raw": "{\"arg\":{\"channel\":\"books\",\"instId\":\"BTC-USDT-SWAP\"},\"action\":\"update\",\"data\":[{\"asks\":[[\"64459.4\",\"0\",\"0\",\"0\"],[\"64475.6\",\"31.43\",\"0\",\"3\"],[\"64475.8\",\"46.55\",\"0\",\"2\"],[\"64487.4\",\"58.69\",\"0\",\"6\"],[\"64487.5\",\"43.47\",\"0\",\"6\"],[\"64508.1\",\"21.31\",\"0\",\"3\"]],\"bids\":[[\"64439.4\",\"0.01\",\"0\",\"1\"],[\"64439\",\"58.26\",\"0\",\"2\"],[\"64438.2\",\"0.01\",\"0\",\"1\"],[\"64438\",\"31.07\",\"0\",\"2\"]],\"ts\":\"1782015916605\",\"checksum\":1322883915,\"seqId\":325069867007,\"prevSeqId\":325069866990}]}"}
{"action": "update", "capture_sequence": 152, "channel": "books", "connection_sequence": 2, "event": null, "instId": "BTC-USDT-SWAP", "local_receive_ts": "2026-06-21T04:25:16Z", "monotonic_ns": 1643472622722088, "raw": "{\"arg\":{\"channel\":\"books\",\"instId\":\"BTC-USDT-SWAP\"},\"action\":\"update\",\"data\":[{\"asks\":[[\"64458\",\"484.17\",\"0\",\"53\"],[\"64487.9\",\"0.01\",\"0\",\"1\"],[\"64488.2\",\"89.32\",\"0\",\"3\"],[\"64492.6\",\"98.92\",\"0\",\"1\"],[\"64493.1\",\"117.89\",\"0\",\"6\"],[\"64494.1\",\"0\",\"0\",\"0\"],[\"64494.3\",\"35.8\",\"0\",\"6\"],[\"64508.2\",\"59.01\",\"0\",\"5\"]],\"bids\":[[\"64443.8\",\"20.09\",\"0\",\"1\"],[\"64443.6\",\"0.01\",\"0\",\"1\"],[\"64442.7\",\"85.42\",\"0\",\"1\"],[\"64442.4\",\"0.01\",\"0\",\"1\"],[\"64439.2\",\"0\",\"0\",\"0\"],[\"64438.7\",\"4.01\",\"0\",\"2\"],[\"64405\",\"0\",\"0\",\"0\"]],\"ts\":\"1782015916705\",\"checksum\":-1766784084,\"seqId\":325069867022,\"prevSeqId\":325069867007}]}"}
{"action": "update", "capture_sequence": 153, "channel": "books", "connection_sequence": 2, "event": null, "instId": "BTC-USDT-SWAP", "local_receive_ts": "2026-06-21T04:25:16Z", "monotonic_ns": 1643472722667450, "raw": "{\"arg\":{\"channel\":\"books\",\"instId\":\"BTC-USDT-SWAP\"},\"action\":\"update\",\"data\":[{\"asks\":[[\"64460.5\",\"0\",\"0\",\"0\"],[\"64461.3\",\"11.22\",\"0\",\"1\"],[\"64476.4\",\"0\",\"0\",\"0\"],[\"64483.1\",\"100.3\",\"0\",\"4\"],[\"64483.3\",\"33.85\",\"0\",\"3\"],[\"64508.4\",\"1367.19\",\"0\",\"6\"]],\"bids\":[[\"64444.5\",\"33.82\",\"0\",\"1\"],[\"64443.9\",\"0\",\"0\",\"0\"],[\"64442.9\",\"0\",\"0\",\"0\"],[\"64436.1\",\"25.65\",\"0\",\"2\"],[\"64405\",\"13.52\",\"0\",\"15\"]],\"ts\":\"1782015916805\",\"checksum\":-78005109,\"seqId\":325069867039,\"prevSeqId\":325069867022}]}"}
{"action": "update", "capture_sequence": 154, "channel": "books", "connection_sequence": 2, "event": null, "instId": "BTC-USDT-SWAP", "local_receive_ts": "2026-06-21T04:25:17Z", "monotonic_ns": 1643472822795103, "raw": "{\"arg\":{\"channel\":\"books\",\"instId\":\"BTC-USDT-SWAP\"},\"action\":\"update\",\"data\":[{\"asks\":[[\"64476.3\",\"0.16\",\"0\",\"1\"],[\"64483.3\",\"0.05\",\"0\",\"2\"],[\"64483.8\",\"33.8\",\"0\",\"1\"],[\"64508.2\",\"0\",\"0\",\"0\"],[\"64508.4\",\"0\",\"0\",\"0\"]],\"bids\":[[\"64455.4\",\"0\",\"0\",\"0\"],[\"64455.3\",\"0.01\",\"0\",\"1\"],[\"64455\",\"0.01\",\"0\",\"1\"],[\"64454.9\",\"0.02\",\"0\",\"2\"],[\"64454.8\",\"28.39\",\"0\",\"3\"],[\"64454.7\",\"37.27\",\"0\",\"4\"],[\"64443\",\"3.19\",\"0\",\"3\"],[\"64436.2\",\"0.2\",\"0\",\"1\"]],\"ts\":\"1782015916905\",\"checksum\":-2020069332,\"seqId\":325069867053,\"prevSeqId\":325069867039}]}"}
{"action": "update", "capture_sequence": 155, "channel": "books", "connection_sequence": 2, "event": null, "instId": "BTC-USDT-SWAP", "local_receive_ts": "2026-06-21T04:25:17Z", "monotonic_ns": 1643472923164901, "raw": "{\"arg\":{\"channel\":\"books\",\"instId\":\"BTC-USDT-SWAP\"},\"action\":\"update\",\"data\":[{\"asks\":[[\"64458.4\",\"1.57\",\"0\",\"2\"],[\"64472.8\",\"19.52\",\"0\",\"2\"],[\"64473.5\",\"0\",\"0\",\"0\"],[\"64475.5\",\"31.04\",\"0\",\"1\"],[\"64475.6\",\"0.39\",\"0\",\"2\"],[\"64476.6\",\"0\",\"0\",\"0\"],[\"64476.7\",\"232.87\",\"0\",\"1\"],[\"64477.9\",\"1.55\",\"0\",\"1\"],[\"64478.5\",\"0\",\"0\",\"0\"],[\"64484.5\",\"0.37\",\"0\",\"4\"],[\"64484.6\",\"1.21\",\"0\",\"2\"]],\"bids\":[[\"64457.9\",\"575.44\",\"0\",\"25\"],[\"64457.5\",\"1.56\",\"0\",\"1\"],[\"64457\",\"1.57\",\"0\",\"2\"],[\"64456.5\",\"1.56\",\"0\",\"1\"],[\"64453.5\",\"0.01\",\"0\",\"1\"],[\"64453.2\",\"0.31\",\"0\",\"1\"],[\"64451.6\",\"0\",\"0\",\"0\"],[\"64451.4\",\"77.99\",\"0\",\"3\"],[\"64438\",\"0.01\",\"0\",\"1\"],[\"64437.5\",\"31.06\",\"0\",\"1\"],[\"64437.4\",\"0\",\"0\",\"0\"],[\"64437\",\"233.01\",\"0\",\"1\"],[\"64432.1\",\"0.08\",\"0\",\"1\"],[\"64431.9\",\"17.94\",\"0\",\"3\"],[\"64415.9\",\"0\",\"0\",\"0\"],[\"64415.5\",\"20.01\",\"0\",\"2\"],[\"64405.1\",\"0\",\"0\",\"0\"],[\"64405\",\"0\",\"0\",\"0\"]],\"ts\":\"1782015917005\",\"checksum\":-826979931,\"seqId\":325069867096,\"prevSeqId\":325069867053}]}"}
{"action": "update", "capture_sequence": 156, "channel": "books", "connection_sequence": 2, "event": null, "instId": "BTC-USDT-SWAP", "local_receive_ts": "2026-06-21T04:25:17Z", "monotonic_ns": 1643473023403148, "raw": "{\"arg\":{\"channel\":\"books\",\"instId\":\"BTC-USDT-SWAP\"},\"action\":\"update\",\"data\":[{\"asks\":[[\"64458.4\",\"0.01\",\"0\",\"1\"],[\"64458.5\",\"5.01\",\"0\",\"2\"],[\"64458.7\",\"0.01\",\"0\",\"1\"],[\"64459.1\",\"1.56\",\"0\",\"1\"],[\"64472.8\",\"4\",\"0\",\"1\"],[\"64473.5\",\"15.52\",\"0\",\"1\"],[\"64475.8\",\"46.56\",\"0\",\"3\"],[\"64475.9\",\"0.9\",\"0\",\"1\"],[\"64483.7\",\"0.78\",\"0\",\"2\"],[\"64484.1\",\"0.33\",\"0\",\"2\"],[\"64484.5\",\"0.06\",\"0\",\"3\"],[\"64488.2\",\"3.96\",\"0\",\"2\"],[\"64489\",\"143.3\",\"0\",\"10\"],[\"64493.1\",\"31.76\",\"0\",\"5\"],[\"64493.6\",\"234.99\",\"0\",\"2\"],[\"64494.3\",\"15.73\",\"0\",\"5\"],[\"64495.2\",\"20.08\",\"0\",\"2\"],[\"64508\",\"0\",\"0\",\"0\"],[\"64508.1\",\"0\",\"0\",\"0\"]],\"bids\":[[\"64457.9\",\"575.43\",\"0\",\"25\"],[\"64457.6\",\"0.48\",\"0\",\"3\"],[\"64457.1\",\"0.33\",\"0\",\"2\"],[\"64456.6\",\"0.08\",\"0\",\"2\"],[\"64454.9\",\"0.01\",\"0\",\"1\"],[\"64454.8\",\"28.38\",\"0\",\"2\"],[\"64454.7\",\"37.26\",\"0\",\"3\"],[\"64451.8\",\"0.01\",\"0\",\"1\"],[\"64451.5\",\"16.21\",\"0\",\"2\"],[\"64445.2\",\"86.2\",\"0\",\"1\"],[\"64445.1\",\"184.61\",\"0\",\"4\"],[\"64444.6\",\"20.86\",\"0\",\"2\"],[\"64443.8\",\"0\",\"0\",\"0\"],[\"64443.5\",\"85.42\",\"0\",\"1\"],[\"64442.7\",\"0\",\"0\",\"0\"],[\"64441.9\",\"36.94\",\"0\",\"2\"],[\"64441.7\",\"0.02\",\"0\",\"1\"],[\"64438.7\",\"3.99\",\"0\",\"1\"],[\"64438.4\",\"0.03\",\"0\",\"2\"],[\"64405.2\",\"0\",\"0\",\"0\"]],\"ts\":\"1782015917105\",\"checksum\":2119149927,\"seqId\":325069867162,\"prevSeqId\":325069867096}]}"}
{"action": "update", "capture_sequence": 157, "channel": "books", "connection_sequence": 2, "event": null, "instId": "BTC-USDT-SWAP", "local_receive_ts": "2026-06-21T04:25:17Z", "monotonic_ns": 1643473127862530, "raw": "{\"arg\":{\"channel\":\"books\",\"instId\":\"BTC-USDT-SWAP\"},\"action\":\"update\",\"data\":[{\"asks\":[[\"64458.3\",\"8.45\",\"0\",\"5\"],[\"64458.5\",\"5\",\"0\",\"1\"],[\"64458.7\",\"0.02\",\"0\",\"2\"],[\"64459.1\",\"0\",\"0\",\"0\"],[\"64459.5\",\"1.57\",\"0\",\"2\"],[\"64461.3\",\"0\",\"0\",\"0\"],[\"64477.9\",\"0\",\"0\",\"0\"],[\"64478.5\",\"1.55\",\"0\",\"1\"],[\"64483.7\",\"0.01\",\"0\",\"1\"],[\"64484.1\",\"0.79\",\"0\",\"2\"],[\"64484.5\",\"0.37\",\"0\",\"4\"],[\"64488.2\",\"89.32\",\"0\",\"3\"],[\"64489\",\"57.94\",\"0\",\"9\"],[\"64493.1\",\"117.89\",\"0\",\"6\"],[\"64493.6\",\"148.86\",\"0\",\"1\"],[\"64494.5\",\"20.07\",\"0\",\"1\"],[\"64495.2\",\"0.01\",\"0\",\"1\"],[\"64508\",\"13.54\",\"0\",\"7\"]],\"bids\":[[\"64457.9\",\"575.44\",\"0\",\"25\"],[\"64457.6\",\"0.47\",\"0\",\"2\"],[\"64457.5\",\"0\",\"0\",\"0\"],[\"64457.2\",\"1.56\",\"0\",\"1\"],[\"64457.1\",\"0.32\",\"0\",\"1\"],[\"64457\",\"0.01\",\"0\",\"1\"],[\"64456.6\",\"0.09\",\"0\",\"3\"],[\"64456.1\",\"0.02\",\"0\",\"2\"],[\"64456\",\"1.58\",\"0\",\"3\"],[\"64455.7\",\"0.01\",\"0\",\"1\"],[\"64455.6\",\"1.56\",\"0\",\"1\"],[\"64455.3\",\"48.67\",\"0\",\"2\"],[\"64455.2\",\"77.62\",\"0\",\"5\"],[\"64455.1\",\"1.56\",\"0\",\"1\"],[\"64454.9\",\"0\",\"0\",\"0\"],[\"64454.8\",\"0.01\",\"0\",\"1\"],[\"64453.5\",\"0.32\",\"0\",\"2\"],[\"64453.2\",\"0\",\"0\",\"0\"],[\"64451.8\",\"0.32\",\"0\",\"2\"],[\"64451.5\",\"15.9\",\"0\",\"1\"],[\"64445.2\",\"0.77\",\"0\",\"1\"],[\"64444.6\",\"0\",\"0\",\"0\"],[\"64443.8\",\"20.09\",\"0\",\"1\"],[\"64443.6\",\"86.21\",\"0\",\"2\"],[\"64443.5\",\"0\",\"0\",\"0\"],[\"64442.7\",\"85.42\",\"0\",\"1\"],[\"64441.9\",\"36.96\",\"0\",\"3\"],[\"64441.7\",\"0\",\"0\",\"0\"],[\"64438.9\",\"37.25\",\"0\",\"2\"],[\"64438.4\",\"0.01\",\"0\",\"1\"],[\"64432.5\",\"0.02\",\"0\",\"2\"],[\"64431.9\",\"17.93\",\"0\",\"2\"],[\"64415.9\",\"0.01\",\"0\",\"1\"],[\"64415.5\",\"20\",\"0\",\"1\"],[\"64405.3\",\"0\",\"0\",\"0\"]],\"ts\":\"1782015917205\",\"checksum\":203550880,\"seqId\":325069867259,\"prevSeqId\":325069867162}]}"}
{"action": "update", "capture_sequence": 158, "channel": "books", "connection_sequence": 2, "event": null, "instId": "BTC-USDT-SWAP", "local_receive_ts": "2026-06-21T04:25:17Z", "monotonic_ns": 1643473222845801, "raw": "{\"arg\":{\"channel\":\"books\",\"instId\":\"BTC-USDT-SWAP\"},\"action\":\"update\",\"data\":[{\"asks\":[[\"64458.3\",\"6.89\",\"0\",\"4\"],[\"64459.5\",\"0.01\",\"0\",\"1\"],[\"64459.9\",\"1.56\",\"0\",\"1\"],[\"64460.5\",\"1.56\",\"0\",\"1\"],[\"64464.8\",\"1.56\",\"0\",\"1\"],[\"64507.8\",\"0\",\"0\",\"0\"],[\"64507.9\",\"0\",\"0\",\"0\"],[\"64508\",\"0\",\"0\",\"0\"]],\"bids\":[[\"64457.7\",\"0.33\",\"0\",\"2\"],[\"64457.6\",\"2.03\",\"0\",\"3\"],[\"64457.2\",\"0\",\"0\",\"0\"],[\"64455.7\",\"0\",\"0\",\"0\"],[\"64452.5\",\"0.01\",\"0\",\"1\"],[\"64405.3\",\"46.54\",\"0\",\"1\"],[\"64405.2\",\"239.07\",\"0\",\"5\"]],\"ts\":\"1782015917305\",\"checksum\":324859266,\"seqId\":325069867301,\"prevSeqId\":325069867259}]}"}
{"action": "update", "capture_sequence": 159, "channel": "books", "connection_sequence": 2, "event": null, "instId": "BTC-USDT-SWAP", "local_receive_ts": "2026-06-21T04:25:17Z", "monotonic_ns": 1643473323457935, "raw": "{\"arg\":{\"channel\":\"books\",\"instId\":\"BTC-USDT-SWAP\"},\"action\":\"update\",\"data\":[{\"asks\":[[\"64459.2\",\"1.57\",\"0\",\"2\"],[\"64459.9\",\"0\",\"0\",\"0\"],[\"64460.5\",\"0\",\"0\",\"0\"],[\"64460.9\",\"1.56\",\"0\",\"1\"],[\"64461\",\"0.01\",\"0\",\"1\"],[\"64465.6\",\"0.01\",\"0\",\"1\"],[\"64466.5\",\"0\",\"0\",\"0\"],[\"64467.7\",\"0\",\"0\",\"0\"],[\"64494.2\",\"0\",\"0\",\"0\"],[\"64495.3\",\"0.26\",\"0\",\"2\"],[\"64507.8\",\"2.83\",\"0\",\"3\"],[\"64507.9\",\"0.25\",\"0\",\"2\"],[\"64508\",\"13.54\",\"0\",\"7\"],[\"64508.1\",\"21.31\",\"0\",\"3\"]],\"bids\":[[\"64457.7\",\"0.32\",\"0\",\"1\"],[\"64457.6\",\"0.48\",\"0\",\"3\"],[\"64457.5\",\"1.56\",\"0\",\"1\"],[\"64449.1\",\"0.01\",\"0\",\"1\"],[\"64448.2\",\"247.83\",\"0\",\"3\"],[\"64447.4\",\"10.77\",\"0\",\"2\"],[\"64405.2\",\"0\",\"0\",\"0\"]],\"ts\":\"1782015917405\",\"checksum\":-190593070,\"seqId\":325069867380,\"prevSeqId\":325069867301}]}"}
{"action": "update", "capture_sequence": 160, "channel": "books", "connection_sequence": 2, "event": null, "instId": "BTC-USDT-SWAP", "local_receive_ts": "2026-06-21T04:25:17Z", "monotonic_ns": 1643473436419494, "raw": "{\"arg\":{\"channel\":\"books\",\"instId\":\"BTC-USDT-SWAP\"},\"action\":\"update\",\"data\":[{\"asks\":[[\"64458\",\"484.66\",\"0\",\"54\"],[\"64459.2\",\"0.01\",\"0\",\"1\"],[\"64459.9\",\"1.56\",\"0\",\"1\"],[\"64464.6\",\"0.01\",\"0\",\"1\"],[\"64464.8\",\"0\",\"0\",\"0\"],[\"64465.2\",\"77.75\",\"0\",\"2\"],[\"64465.4\",\"1\",\"0\",\"1\"],[\"64465.9\",\"0\",\"0\",\"0\"],[\"64466.2\",\"0\",\"0\",\"0\"],[\"64466.4\",\"72.06\",\"0\",\"4\"],[\"64467\",\"63.88\",\"0\",\"2\"],[\"64467.3\",\"0.01\",\"0\",\"1\"],[\"64467.8\",\"345.36\",\"0\",\"4\"],[\"64488.2\",\"3.96\",\"0\",\"2\"],[\"64488.6\",\"85.38\",\"0\",\"3\"],[\"64492\",\"1.03\",\"0\",\"4\"],[\"64492.2\",\"0.9\",\"0\",\"6\"],[\"64492.9\",\"9.21\",\"0\",\"3\"],[\"64493.5\",\"1.09\",\"0\",\"4\"],[\"64493.9\",\"0\",\"0\",\"0\"],[\"64494.5\",\"0\",\"0\",\"0\"],[\"64494.6\",\"25.11\",\"0\",\"5\"],[\"64494.7\",\"24.55\",\"0\",\"6\"],[\"64495\",\"1.5\",\"0\",\"9\"],[\"64495.5\",\"6.32\",\"0\",\"4\"],[\"64508.2\",\"59.01\",\"0\",\"5\"],[\"64508.4\",\"1367.19\",\"0\",\"6\"],[\"64508.5\",\"42.46\",\"0\",\"3\"]],\"bids\":[[\"64457.9\",\"577\",\"0\",\"26\"],[\"64457.6\",\"0.47\",\"0\",\"2\"],[\"64457.5\",\"0\",\"0\",\"0\"],[\"64456.8\",\"1.56\",\"0\",\"1\"],[\"64456.6\",\"0.08\",\"0\",\"2\"],[\"64456.5\",\"0\",\"0\",\"0\"],[\"64455.7\",\"0.01\",\"0\",\"1\"],[\"64452.5\",\"1.57\",\"0\",\"2\"],[\"64450.1\",\"40.77\",\"0\",\"1\"],[\"64449.5\",\"38.83\",\"0\",\"2\"],[\"64449.4\",\"16.17\",\"0\",\"2\"],[\"64448.8\",\"0\",\"0\",\"0\"],[\"64448.5\",\"2.16\",\"0\",\"1\"],[\"64448\",\"272.36\",\"0\",\"10\"],[\"64447.6\",\"0\",\"0\",\"0\"],[\"64446.9\",\"21.3\",\"0\",\"3\"],[\"64443.9\",\"20.09\",\"0\",\"1\"],[\"64443.8\",\"0\",\"0\",\"0\"],[\"64443.1\",\"85.42\",\"0\",\"1\"],[\"64442.7\",\"0\",\"0\",\"0\"],[\"64432.5\",\"0.01\",\"0\",\"1\"],[\"64432.1\",\"0.09\",\"0\",\"2\"],[\"64405.2\",\"239.07\",\"0\",\"5\"],[\"64405.1\",\"0.07\",\"0\",\"3\"]],\"ts\":\"1782015917505\",\"checksum\":-977959287,\"seqId\":325069867541,\"prevSeqId\":325069867380}]}"}
{"action": null, "capture_sequence": 161, "channel": "trades", "connection_sequence": 3, "event": "subscribe", "instId": "BTC-USDT-SWAP", "local_receive_ts": "2026-06-21T04:25:19Z", "monotonic_ns": 1643474858253943, "raw": "{\"event\":\"subscribe\",\"arg\":{\"channel\":\"trades\",\"instId\":\"BTC-USDT-SWAP\"},\"connId\":\"39517b23\"}"}
{"action": null, "capture_sequence": 162, "channel": "books", "connection_sequence": 3, "event": "subscribe", "instId": "BTC-USDT-SWAP", "local_receive_ts": "2026-06-21T04:25:19Z", "monotonic_ns": 1643474858438367, "raw": "{\"event\":\"subscribe\",\"arg\":{\"channel\":\"books\",\"instId\":\"BTC-USDT-SWAP\"},\"connId\":\"39517b23\"}"}
{"action": "snapshot", "capture_sequence": 163, "channel": "books", "connection_sequence": 3, "event": null, "instId": "BTC-USDT-SWAP", "local_receive_ts": "2026-06-21T04:25:19Z", "monotonic_ns": 1643475224387423, "raw": "{\"arg\":{\"channel\":\"books\",\"instId\":\"BTC-USDT-SWAP\"},\"action\":\"snapshot\",\"data\":[{\"asks\":[[\"64458\",\"484.3\",\"0\",\"55\"],[\"64458.1\",\"0.02\",\"0\",\"2\"],[\"64458.2\",\"0.01\",\"0\",\"1\"],[\"64458.3\",\"6.89\",\"0\",\"4\"],[\"64458.4\",\"0.01\",\"0\",\"1\"],[\"64458.5\",\"5\",\"0\",\"1\"],[\"64459.1\",\"0.02\",\"0\",\"2\"],[\"64459.2\",\"15.54\",\"0\",\"2\"],[\"64459.3\",\"1.03\",\"0\",\"4\"],[\"64459.5\",\"0.01\",\"0\",\"1\"],[\"64459.6\",\"0.6\",\"0\",\"1\"],[\"64460\",\"0.01\",\"0\",\"1\"],[\"64460.1\",\"0.02\",\"0\",\"2\"],[\"64460.2\",\"0.78\",\"0\",\"2\"],[\"64460.7\",\"0.01\",\"0\",\"1\"],[\"64460.8\",\"55.97\",\"0\",\"1\"],[\"64461\",\"0.01\",\"0\",\"1\"],[\"64461.1\",\"0.01\",\"0\",\"1\"],[\"64461.2\",\"0.02\",\"0\",\"1\"],[\"64461.4\",\"0.03\",\"0\",\"3\"],[\"64461.7\",\"150\",\"0\",\"1\"],[\"64461.8\",\"1.56\",\"0\",\"1\"],[\"64461.9\",\"0.15\",\"0\",\"1\"],[\"64462\",\"0.04\",\"0\",\"4\"],[\"64462.3\",\"1.56\",\"0\",\"1\"],[\"64462.6\",\"0.01\",\"0\",\"1\"],[\"64462.9\",\"1.57\",\"0\",\"2\"],[\"64463.1\",\"6.22\",\"0\",\"2\"],[\"64463.2\",\"0.01\",\"0\",\"1\"],[\"64463.3\",\"0.9\",\"0\",\"1\"],[\"64463.4\",\"1.56\",\"0\",\"1\"],[\"64463.5\",\"0.02\",\"0\",\"2\"],[\"64463.6\",\"14.45\",\"0\",\"1\"],[\"64463.7\",\"0.01\",\"0\",\"1\"],[\"64463.8\",\"1.57\",\"0\",\"2\"],[\"64464\",\"0.79\",\"0\",\"3\"],[\"64464.1\",\"31.85\",\"0\",\"5\"],[\"64464.2\",\"209.9\",\"0\",\"2\"],[\"64464.3\",\"73.77\",\"0\",\"2\"],[\"64464.4\",\"0.3\",\"0\",\"1\"],[\"64464.5\",\"1.32\",\"0\",\"4\"],[\"64464.6\",\"0.01\",\"0\",\"1\"],[\"64464.7\",\"0.01\",\"0\",\"1\"],[\"64464.9\",\"65.64\",\"0\",\"1\"],[\"64465\",\"67.79\",\"0\",\"2\"],[\"64465.1\",\"1\",\"0\",\"1\"],[\"64465.2\",\"79.31\",\"0\",\"3\"],[\"64465.4\",\"1\",\"0\",\"1\"],[\"64465.5\",\"0.01\",\"0\",\"1\"],[\"64465.6\",\"0.01\",\"0\",\"1\"],[\"64465.7\",\"77.88\",\"0\",\"4\"],[\"64465.8\",\"64.02\",\"0\",\"2\"],[\"64466\",\"0.01\",\"0\",\"1\"],[\"64466.1\",\"1.21\",\"0\",\"2\"],[\"64466.2\",\"1.56\",\"0\",\"1\"],[\"64466.4\",\"72.06\",\"0\",\"4\"],[\"64466.6\",\"0.01\",\"0\",\"1\"],[\"64466.7\",\"0.01\",\"0\",\"1\"],[\"64466.8\",\"1.2\",\"0\",\"1\"],[\"64466.9\",\"1.16\",\"0\",\"1\"],[\"64467\",\"63.88\",\"0\",\"2\"],[\"64467.1\",\"0.02\",\"0\",\"1\"],[\"64467.2\",\"1.2\",\"0\",\"1\"],[\"64467.3\",\"0.01\",\"0\",\"1\"],[\"64467.5\",\"1.2\",\"0\",\"1\"],[\"64467.6\",\"0.4\",\"0\",\"3\"],[\"64467.7\",\"147.75\",\"0\",\"3\"],[\"64467.8\",\"91.8\",\"0\",\"2\"],[\"64467.9\",\"0.02\",\"0\",\"2\"],[\"64468\",\"0.02\",\"0\",\"2\"],[\"64468.2\",\"15.88\",\"0\",\"1\"],[\"64468.3\",\"0.3\",\"0\",\"2\"],[\"64468.4\",\"69.47\",\"0\",\"1\"],[\"64468.5\",\"46.54\",\"0\",\"1\"],[\"64468.6\",\"1.74\",\"0\",\"1\"],[\"64468.7\",\"66.46\",\"0\",\"2\"],[\"64468.8\",\"76.01\",\"0\",\"7\"],[\"64468.9\",\"0.14\",\"0\",\"2\"],[\"64469\",\"22\",\"0\",\"1\"],[\"64469.1\",\"0.01\",\"0\",\"1\"],[\"64469.3\",\"4\",\"0\",\"1\"],[\"64469.4\",\"0.01\",\"0\",\"1\"],[\"64469.5\",\"4.77\",\"0\",\"1\"],[\"64469.6\",\"0.01\",\"0\",\"1\"],[\"64469.7\",\"37.75\",\"0\",\"3\"],[\"64469.8\",\"15.92\",\"0\",\"1\"],[\"64469.9\",\"0.01\",\"0\",\"1\"],[\"64470\",\"0.2\",\"0\",\"4\"],[\"64470.1\",\"10.69\",\"0\",\"2\"],[\"64470.2\",\"0.02\",\"0\",\"1\"],[\"64470.3\",\"0.01\",\"0\",\"1\"],[\"64470.4\",\"0.01\",\"0\",\"1\"],[\"64470.6\",\"372.95\",\"0\",\"2\"],[\"64470.7\",\"46.56\",\"0\",\"3\"],[\"64470.8\",\"0.77\",\"0\",\"1\"],[\"64470.9\",\"346.66\",\"0\",\"11\"],[\"64471\",\"0.54\",\"0\",\"3\"],[\"64471.3\",\"99.34\",\"0\",\"2\"],[\"64471.4\",\"15.97\",\"0\",\"1\"],[\"64471.6\",\"0.04\",\"0\",\"2\"],[\"64471.7\",\"2.56\",\"0\",\"1\"],[\"64471.8\",\"496.53\",\"0\",\"1\"],[\"64471.9\",\"0.02\",\"0\",\"2\"],[\"64472\",\"2.07\",\"0\",\"5\"],[\"64472.1\",\"11.42\",\"0\",\"1\"],[\"64472.2\",\"0.01\",\"0\",\"1\"],[\"64472.6\",\"0.01\",\"0\",\"1\"],[\"64472.7\",\"24\",\"0\",\"2\"],[\"64472.8\",\"4\",\"0\",\"1\"],[\"64472.9\",\"12.05\",\"0\",\"4\"],[\"64473.2\",\"0.01\",\"0\",\"1\"],[\"64473.3\",\"1.24\",\"0\",\"1\"],[\"64473.5\",\"15.52\",\"0\",\"1\"],[\"64473.6\",\"52.77\",\"0\",\"3\"],[\"64473.7\",\"275.99\",\"0\",\"2\"],[\"64473.8\",\"0.05\",\"0\",\"5\"],[\"64474\",\"0.03\",\"0\",\"3\"],[\"64474.2\",\"0.29\",\"0\",\"1\"],[\"64474.3\",\"18.95\",\"0\",\"1\"],[\"64474.4\",\"0.02\",\"0\",\"2\"],[\"64474.5\",\"0.03\",\"0\",\"1\"],[\"64474.7\",\"8.01\",\"0\",\"2\"],[\"64474.8\",\"0.11\",\"0\",\"1\"],[\"64474.9\",\"37.23\",\"0\",\"1\"],[\"64475\",\"263.06\",\"0\",\"9\"],[\"64475.3\",\"0.01\",\"0\",\"1\"],[\"64475.6\",\"31.43\",\"0\",\"3\"],[\"64475.7\",\"496.54\",\"0\",\"2\"],[\"64475.8\",\"46.58\",\"0\",\"4\"],[\"64475.9\",\"0.9\",\"0\",\"1\"],[\"64476\",\"0.03\",\"0\",\"3\"],[\"64476.2\",\"0.18\",\"0\",\"3\"],[\"64476.7\",\"232.87\",\"0\",\"1\"],[\"64476.8\",\"318.09\",\"0\",\"4\"],[\"64476.9\",\"0.02\",\"0\",\"2\"],[\"64477\",\"2.62\",\"0\",\"2\"],[\"64477.3\",\"1.01\",\"0\",\"2\"],[\"64477.4\",\"0.09\",\"0\",\"3\"],[\"64477.5\",\"14.77\",\"0\",\"2\"],[\"64477.6\",\"0.07\",\"0\",\"1\"],[\"64477.8\",\"46.54\",\"0\",\"1\"],[\"64477.9\",\"0.01\",\"0\",\"1\"],[\"64478\",\"0.02\",\"0\",\"2\"],[\"64478.3\",\"0.01\",\"0\",\"1\"],[\"64478.5\",\"1.55\",\"0\",\"1\"],[\"64478.6\",\"3.11\",\"0\",\"2\"],[\"64478.8\",\"0.01\",\"0\",\"1\"],[\"64479\",\"0.01\",\"0\",\"1\"],[\"64479.2\",\"15.81\",\"0\",\"4\"],[\"64479.5\",\"18.63\",\"0\",\"3\"],[\"64479.6\",\"102.93\",\"0\",\"2\"],[\"64479.8\",\"496.54\",\"0\",\"2\"],[\"64479.9\",\"62.2\",\"0\",\"3\"],[\"64480\",\"55.67\",\"0\",\"44\"],[\"64480.1\",\"0.02\",\"0\",\"2\"],[\"64480.2\",\"37.23\",\"0\",\"1\"],[\"64480.4\",\"0.01\",\"0\",\"1\"],[\"64480.8\",\"6.22\",\"0\",\"1\"],[\"64481\",\"171.94\",\"0\",\"5\"],[\"64481.1\",\"62.3\",\"0\",\"2\"],[\"64481.2\",\"0.68\",\"0\",\"1\"],[\"64481.6\",\"0.01\",\"0\",\"1\"],[\"64481.8\",\"0.04\",\"0\",\"3\"],[\"64481.9\",\"0.01\",\"0\",\"1\"],[\"64482\",\"0.04\",\"0\",\"2\"],[\"64482.1\",\"0.01\",\"0\",\"1\"],[\"64482.5\",\"0.02\",\"0\",\"1\"],[\"64482.6\",\"0.01\",\"0\",\"1\"],[\"64482.7\",\"3.91\",\"0\",\"2\"],[\"64482.8\",\"0.41\",\"0\",\"2\"],[\"64482.9\",\"110.9\",\"0\",\"2\"],[\"64483\",\"200\",\"0\",\"1\"],[\"64483.1\",\"100.3\",\"0\",\"4\"],[\"64483.2\",\"114.69\",\"0\",\"3\"],[\"64483.3\",\"0.06\",\"0\",\"3\"],[\"64483.4\",\"312.16\",\"0\",\"1\"],[\"64483.7\",\"0.01\",\"0\",\"1\"],[\"64483.8\",\"33.8\",\"0\",\"1\"],[\"64483.9\",\"11.07\",\"0\",\"2\"],[\"64484\",\"0.02\",\"0\",\"2\"],[\"64484.1\",\"0.02\",\"0\",\"1\"],[\"64484.2\",\"15.65\",\"0\",\"1\"],[\"64484.3\",\"9.88\",\"0\",\"1\"],[\"64484.4\",\"16.25\",\"0\",\"2\"],[\"64484.5\",\"1.14\",\"0\",\"5\"],[\"64484.6\",\"1.21\",\"0\",\"2\"],[\"64484.7\",\"28.42\",\"0\",\"2\"],[\"64484.8\",\"496.53\",\"0\",\"1\"],[\"64484.9\",\"15.65\",\"0\",\"1\"],[\"64485\",\"41.95\",\"0\",\"2\"],[\"64485.1\",\"38.83\",\"0\",\"2\"],[\"64485.2\",\"0.01\",\"0\",\"1\"],[\"64485.5\",\"0.01\",\"0\",\"1\"],[\"64485.6\",\"15.65\",\"0\",\"1\"],[\"64485.7\",\"0.35\",\"0\",\"5\"],[\"64485.8\",\"0.4\",\"0\",\"2\"],[\"64485.9\",\"5.42\",\"0\",\"1\"],[\"64486\",\"101.09\",\"0\",\"7\"],[\"64486.2\",\"0.17\",\"0\",\"6\"],[\"64486.3\",\"179.9\",\"0\",\"4\"],[\"64486.4\",\"1.27\",\"0\",\"2\"],[\"64486.5\",\"15.65\",\"0\",\"1\"],[\"64486.6\",\"47.53\",\"0\",\"2\"],[\"64486.7\",\"0.01\",\"0\",\"1\"],[\"64486.8\",\"37.42\",\"0\",\"4\"],[\"64486.9\",\"0.12\",\"0\",\"2\"],[\"64487\",\"51.82\",\"0\",\"5\"],[\"64487.1\",\"0.53\",\"0\",\"4\"],[\"64487.2\",\"0.03\",\"0\",\"2\"],[\"64487.3\",\"0.04\",\"0\",\"2\"],[\"64487.4\",\"58.69\",\"0\",\"6\"],[\"64487.5\",\"43.47\",\"0\",\"6\"],[\"64487.6\",\"301.45\",\"0\",\"1\"],[\"64487.7\",\"130.34\",\"0\",\"4\"],[\"64487.8\",\"0.09\",\"0\",\"3\"],[\"64487.9\",\"0.01\",\"0\",\"1\"],[\"64488\",\"57.87\",\"0\",\"27\"],[\"64488.1\",\"0.67\",\"0\",\"2\"],[\"64488.2\",\"3.96\",\"0\",\"2\"],[\"64488.3\",\"38.84\",\"0\",\"2\"],[\"64488.4\",\"21.02\",\"0\",\"6\"],[\"64488.6\",\"85.38\",\"0\",\"3\"],[\"64488.7\",\"496.58\",\"0\",\"3\"],[\"64488.8\",\"50.02\",\"0\",\"2\"],[\"64488.9\",\"0.32\",\"0\",\"5\"],[\"64489\",\"57.94\",\"0\",\"9\"],[\"64489.1\",\"26.75\",\"0\",\"5\"],[\"64489.2\",\"69.9\",\"0\",\"1\"],[\"64489.3\",\"23.26\",\"0\",\"6\"],[\"64489.4\",\"2.91\",\"0\",\"4\"],[\"64489.5\",\"0.01\",\"0\",\"1\"],[\"64489.6\",\"0.13\",\"0\",\"3\"],[\"64489.7\",\"47.34\",\"0\",\"2\"],[\"64489.8\",\"31.34\",\"0\",\"5\"],[\"64489.9\",\"143.6\",\"0\",\"1\"],[\"64490\",\"55.77\",\"0\",\"19\"],[\"64490.1\",\"0.01\",\"0\",\"1\"],[\"64490.3\",\"1\",\"0\",\"1\"],[\"64490.4\",\"0.02\",\"0\",\"2\"],[\"64490.5\",\"17.16\",\"0\",\"3\"],[\"64490.6\",\"1.08\",\"0\",\"3\"],[\"64490.7\",\"0.07\",\"0\",\"3\"],[\"64490.9\",\"0.07\",\"0\",\"2\"],[\"64491\",\"81.13\",\"0\",\"3\"],[\"64491.2\",\"1.01\",\"0\",\"2\"],[\"64491.3\",\"0.02\",\"0\",\"2\"],[\"64491.4\",\"0.02\",\"0\",\"2\"],[\"64491.5\",\"0.1\",\"0\",\"1\"],[\"64491.6\",\"0.09\",\"0\",\"3\"],[\"64491.7\",\"1.02\",\"0\",\"3\"],[\"64491.8\",\"0.05\",\"0\",\"1\"],[\"64491.9\",\"0.31\",\"0\",\"5\"],[\"64492\",\"1.03\",\"0\",\"4\"],[\"64492.2\",\"0.9\",\"0\",\"6\"],[\"64492.3\",\"1.23\",\"0\",\"2\"],[\"64492.4\",\"57.86\",\"0\",\"6\"],[\"64492.5\",\"0.06\",\"0\",\"4\"],[\"64492.6\",\"100.12\",\"0\",\"2\"],[\"64492.7\",\"99.88\",\"0\",\"3\"],[\"64492.8\",\"0.13\",\"0\",\"7\"],[\"64492.9\",\"9.21\",\"0\",\"3\"],[\"64493\",\"13.72\",\"0\",\"4\"],[\"64493.1\",\"117.89\",\"0\",\"6\"],[\"64493.2\",\"399.82\",\"0\",\"8\"],[\"64493.3\",\"580.33\",\"0\",\"6\"],[\"64493.4\",\"1.52\",\"0\",\"6\"],[\"64493.5\",\"1.09\",\"0\",\"4\"],[\"64493.6\",\"148.86\",\"0\",\"1\"],[\"64493.7\",\"360.49\",\"0\",\"6\"],[\"64493.8\",\"0.04\",\"0\",\"3\"],[\"64494\",\"205.23\",\"0\",\"4\"],[\"64494.1\",\"1.2\",\"0\",\"1\"],[\"64494.2\",\"1.5\",\"0\",\"1\"],[\"64494.3\",\"15.73\",\"0\",\"5\"],[\"64494.4\",\"0.23\",\"0\",\"6\"],[\"64494.5\",\"20.07\",\"0\",\"1\"],[\"64494.6\",\"5.04\",\"0\",\"4\"],[\"64494.7\",\"24.55\",\"0\",\"6\"],[\"64494.8\",\"1.2\",\"0\",\"2\"],[\"64494.9\",\"0.07\",\"0\",\"3\"],[\"64495\",\"1.5\",\"0\",\"9\"],[\"64495.1\",\"0.07\",\"0\",\"3\"],[\"64495.2\",\"0.01\",\"0\",\"1\"],[\"64495.3\",\"0.26\",\"0\",\"2\"],[\"64495.4\",\"0.06\",\"0\",\"3\"],[\"64495.5\",\"6.32\",\"0\",\"4\"],[\"64495.6\",\"0.02\",\"0\",\"2\"],[\"64495.7\",\"27\",\"0\",\"4\"],[\"64495.8\",\"0.03\",\"0\",\"2\"],[\"64495.9\",\"4.74\",\"0\",\"4\"],[\"64496\",\"104.13\",\"0\",\"6\"],[\"64496.1\",\"0.06\",\"0\",\"3\"],[\"64496.2\",\"0.01\",\"0\",\"1\"],[\"64496.3\",\"0.3\",\"0\",\"4\"],[\"64496.4\",\"21.88\",\"0\",\"3\"],[\"64496.6\",\"31.68\",\"0\",\"2\"],[\"64496.7\",\"22.72\",\"0\",\"2\"],[\"64496.8\",\"75.94\",\"0\",\"5\"],[\"64496.9\",\"449.69\",\"0\",\"2\"],[\"64497\",\"34.46\",\"0\",\"6\"],[\"64497.1\",\"0.01\",\"0\",\"1\"],[\"64497.2\",\"0.84\",\"0\",\"3\"],[\"64497.3\",\"41.14\",\"0\",\"4\"],[\"64497.4\",\"0.09\",\"0\",\"2\"],[\"64497.5\",\"0.33\",\"0\",\"3\"],[\"64497.6\",\"15.77\",\"0\",\"3\"],[\"64497.8\",\"0.01\",\"0\",\"1\"],[\"64497.9\",\"0.01\",\"0\",\"1\"],[\"64498\",\"497.3\",\"0\",\"4\"],[\"64498.1\",\"0.04\",\"0\",\"4\"],[\"64498.2\",\"0.03\",\"0\",\"2\"],[\"64498.3\",\"100.42\",\"0\",\"7\"],[\"64498.5\",\"4.51\",\"0\",\"5\"],[\"64498.6\",\"0.27\",\"0\",\"4\"],[\"64498.7\",\"2.36\",\"0\",\"3\"],[\"64498.8\",\"20.4\",\"0\",\"3\"],[\"64498.9\",\"40.65\",\"0\",\"3\"],[\"64499\",\"333.41\",\"0\",\"22\"],[\"64499.1\",\"0.15\",\"0\",\"3\"],[\"64499.2\",\"0.01\",\"0\",\"1\"],[\"64499.4\",\"1.72\",\"0\",\"2\"],[\"64499.6\",\"74.53\",\"0\",\"4\"],[\"64499.7\",\"35.37\",\"0\",\"5\"],[\"64499.8\",\"19.95\",\"0\",\"3\"],[\"64499.9\",\"1162.28\",\"0\",\"3\"],[\"64500\",\"3472.81\",\"0\",\"1035\"],[\"64500.1\",\"0.05\",\"0\",\"4\"],[\"64500.2\",\"0.01\",\"0\",\"1\"],[\"64500.3\",\"2.77\",\"0\",\"4\"],[\"64500.4\",\"0.04\",\"0\",\"4\"],[\"64500.5\",\"2.49\",\"0\",\"2\"],[\"64500.6\",\"0.38\",\"0\",\"2\"],[\"64500.7\",\"3.92\",\"0\",\"2\"],[\"64500.8\",\"0.36\",\"0\",\"1\"],[\"64500.9\",\"73.16\",\"0\",\"6\"],[\"64501\",\"0.27\",\"0\",\"3\"],[\"64501.1\",\"0.05\",\"0\",\"2\"],[\"64501.2\",\"0.02\",\"0\",\"2\"],[\"64501.3\",\"0.02\",\"0\",\"1\"],[\"64501.4\",\"0.01\",\"0\",\"1\"],[\"64501.5\",\"1.57\",\"0\",\"4\"],[\"64501.6\",\"4.99\",\"0\",\"4\"],[\"64501.7\",\"0.53\",\"0\",\"2\"],[\"64501.8\",\"59\",\"0\",\"5\"],[\"64501.9\",\"0.08\",\"0\",\"1\"],[\"64502\",\"3.11\",\"0\",\"6\"],[\"64502.1\",\"0.01\",\"0\",\"1\"],[\"64502.2\",\"15.76\",\"0\",\"4\"],[\"64502.3\",\"11.33\",\"0\",\"3\"],[\"64502.4\",\"0.18\",\"0\",\"5\"],[\"64502.5\",\"0.2\",\"0\",\"3\"],[\"64502.6\",\"0.01\",\"0\",\"1\"],[\"64502.7\",\"0.03\",\"0\",\"3\"],[\"64502.8\",\"10.53\",\"0\",\"2\"],[\"64502.9\",\"0.99\",\"0\",\"4\"],[\"64503\",\"15.94\",\"0\",\"2\"],[\"64503.1\",\"0.86\",\"0\",\"7\"],[\"64503.2\",\"15.95\",\"0\",\"3\"],[\"64503.3\",\"0.02\",\"0\",\"2\"],[\"64503.5\",\"63.72\",\"0\",\"6\"],[\"64503.6\",\"17.98\",\"0\",\"3\"],[\"64503.7\",\"0.29\",\"0\",\"2\"],[\"64503.9\",\"20.45\",\"0\",\"1\"],[\"64504\",\"17.31\",\"0\",\"6\"],[\"64504.1\",\"581.2\",\"0\",\"8\"],[\"64504.2\",\"16.06\",\"0\",\"3\"],[\"64504.3\",\"0.04\",\"0\",\"2\"],[\"64504.4\",\"1.13\",\"0\",\"4\"],[\"64504.5\",\"73.8\",\"0\",\"6\"],[\"64504.7\",\"0.01\",\"0\",\"1\"],[\"64504.8\",\"0.08\",\"0\",\"2\"],[\"64504.9\",\"0.1\",\"0\",\"3\"],[\"64505\",\"0.82\",\"0\",\"3\"],[\"64505.1\",\"0.02\",\"0\",\"2\"],[\"64505.3\",\"1.16\",\"0\",\"2\"],[\"64505.4\",\"59.22\",\"0\",\"3\"],[\"64505.5\",\"3.91\",\"0\",\"2\"],[\"64505.6\",\"11.43\",\"0\",\"3\"],[\"64505.7\",\"0.56\",\"0\",\"1\"],[\"64505.8\",\"21.95\",\"0\",\"3\"],[\"64505.9\",\"0.01\",\"0\",\"1\"],[\"64506\",\"10.05\",\"0\",\"3\"],[\"64506.1\",\"0.06\",\"0\",\"1\"],[\"64506.2\",\"0.03\",\"0\",\"2\"],[\"64506.4\",\"0.03\",\"0\",\"3\"],[\"64506.5\",\"0.07\",\"0\",\"1\"],[\"64506.6\",\"10.15\",\"0\",\"3\"],[\"64506.7\",\"0.19\",\"0\",\"15\"],[\"64506.8\",\"1.05\",\"0\",\"4\"],[\"64506.9\",\"0.01\",\"0\",\"1\"],[\"64507\",\"46.6\",\"0\",\"2\"],[\"64507.1\",\"0.06\",\"0\",\"4\"],[\"64507.2\",\"14.03\",\"0\",\"2\"],[\"64507.3\",\"0.03\",\"0\",\"2\"],[\"64507.4\",\"27.31\",\"0\",\"5\"],[\"64507.5\",\"15.77\",\"0\",\"6\"],[\"64507.6\",\"0.03\",\"0\",\"2\"],[\"64507.7\",\"0.07\",\"0\",\"4\"],[\"64507.8\",\"2.83\",\"0\",\"3\"],[\"64507.9\",\"0.25\",\"0\",\"2\"]],\"bids\":[[\"64457.9\",\"575.39\",\"0\",\"25\"],[\"64457.8\",\"0.15\",\"0\",\"3\"],[\"64457.7\",\"1.88\",\"0\",\"2\"],[\"64457.6\",\"0.47\",\"0\",\"2\"],[\"64457.1\",\"0.32\",\"0\",\"1\"],[\"64457\",\"0.01\",\"0\",\"1\"],[\"64456.9\",\"0.02\",\"0\",\"2\"],[\"64456.8\",\"1.56\",\"0\",\"1\"],[\"64456.6\",\"0.07\",\"0\",\"1\"],[\"64456.4\",\"0.01\",\"0\",\"1\"],[\"64456.1\",\"0.02\",\"0\",\"2\"],[\"64456\",\"1.58\",\"0\",\"3\"],[\"64455.9\",\"0.01\",\"0\",\"1\"],[\"64455.6\",\"1.56\",\"0\",\"1\"],[\"64455.3\",\"48.67\",\"0\",\"2\"],[\"64455.2\",\"77.62\",\"0\",\"5\"],[\"64455.1\",\"1.56\",\"0\",\"1\"],[\"64455\",\"0.01\",\"0\",\"1\"],[\"64454.8\",\"0.01\",\"0\",\"1\"],[\"64454.7\",\"37.26\",\"0\",\"3\"],[\"64454.6\",\"46.54\",\"0\",\"1\"],[\"64454.4\",\"1.58\",\"0\",\"3\"],[\"64454.3\",\"0.01\",\"0\",\"1\"],[\"64454.2\",\"0.01\",\"0\",\"1\"],[\"64454.1\",\"4.02\",\"0\",\"3\"],[\"64454\",\"8.01\",\"0\",\"2\"],[\"64453.9\",\"1.57\",\"0\",\"2\"],[\"64453.8\",\"0.77\",\"0\",\"1\"],[\"64453.7\",\"0.31\",\"0\",\"1\"],[\"64453.6\",\"0.01\",\"0\",\"1\"],[\"64453.5\",\"0.01\",\"0\",\"1\"],[\"64453.4\",\"1.56\",\"0\",\"1\"],[\"64453.1\",\"0.01\",\"0\",\"1\"],[\"64453\",\"1.56\",\"0\",\"1\"],[\"64452.9\",\"0.01\",\"0\",\"1\"],[\"64452.8\",\"0.05\",\"0\",\"1\"],[\"64452.7\",\"0.3\",\"0\",\"1\"],[\"64452.5\",\"1.57\",\"0\",\"2\"],[\"64452.4\",\"13.2\",\"0\",\"3\"],[\"64452.3\",\"31.07\",\"0\",\"2\"],[\"64452.2\",\"169.41\",\"0\",\"3\"],[\"64452.1\",\"0.8\",\"0\",\"4\"],[\"64452\",\"76.66\",\"0\",\"4\"],[\"64451.8\",\"77.89\",\"0\",\"3\"],[\"64451.7\",\"303.36\",\"0\",\"5\"],[\"64451.5\",\"15.9\",\"0\",\"1\"],[\"64451.4\",\"0.42\",\"0\",\"2\"],[\"64451.3\",\"13.68\",\"0\",\"7\"],[\"64451.2\",\"380.23\",\"0\",\"5\"],[\"64451.1\",\"0.01\",\"0\",\"1\"],[\"64451\",\"0.02\",\"0\",\"2\"],[\"64450.7\",\"0.04\",\"0\",\"2\"],[\"64450.5\",\"6.3\",\"0\",\"4\"],[\"64450.4\",\"0.69\",\"0\",\"2\"],[\"64450.3\",\"40.83\",\"0\",\"1\"],[\"64450.2\",\"32.01\",\"0\",\"2\"],[\"64450.1\",\"40.77\",\"0\",\"1\"],[\"64450\",\"0.02\",\"0\",\"2\"],[\"64449.9\",\"15.94\",\"0\",\"1\"],[\"64449.8\",\"1.91\",\"0\",\"2\"],[\"64449.7\",\"46.58\",\"0\",\"2\"],[\"64449.6\",\"517.16\",\"0\",\"8\"],[\"64449.5\",\"38.83\",\"0\",\"2\"],[\"64449.4\",\"16.17\",\"0\",\"2\"],[\"64449.3\",\"16.22\",\"0\",\"2\"],[\"64449.2\",\"1.57\",\"0\",\"2\"],[\"64449.1\",\"0.01\",\"0\",\"1\"],[\"64449\",\"0.03\",\"0\",\"3\"],[\"64448.9\",\"1.8\",\"0\",\"1\"],[\"64448.7\",\"4\",\"0\",\"1\"],[\"64448.6\",\"0.01\",\"0\",\"1\"],[\"64448.5\",\"2.16\",\"0\",\"1\"],[\"64448.4\",\"2.88\",\"0\",\"1\"],[\"64448.3\",\"16.01\",\"0\",\"3\"],[\"64448.2\",\"247.83\",\"0\",\"3\"],[\"64448.1\",\"10.01\",\"0\",\"2\"],[\"64448\",\"275.12\",\"0\",\"11\"],[\"64447.9\",\"4\",\"0\",\"1\"],[\"64447.8\",\"0.39\",\"0\",\"2\"],[\"64447.7\",\"3\",\"0\",\"1\"],[\"64447.4\",\"10.77\",\"0\",\"2\"],[\"64447.3\",\"44.88\",\"0\",\"4\"],[\"64447.1\",\"0.3\",\"0\",\"1\"],[\"64447\",\"83.8\",\"0\",\"1\"],[\"64446.9\",\"21.3\",\"0\",\"3\"],[\"64446.8\",\"0.01\",\"0\",\"1\"],[\"64446.4\",\"46.54\",\"0\",\"1\"],[\"64446.3\",\"48.85\",\"0\",\"3\"],[\"64446.2\",\"0.07\",\"0\",\"1\"],[\"64446\",\"0.04\",\"0\",\"2\"],[\"64445.9\",\"8.03\",\"0\",\"4\"],[\"64445.8\",\"1.51\",\"0\",\"2\"],[\"64445.7\",\"514.54\",\"0\",\"4\"],[\"64445.6\",\"3.9\",\"0\",\"2\"],[\"64445.4\",\"0.15\",\"0\",\"1\"],[\"64445.2\",\"0.77\",\"0\",\"1\"],[\"64445.1\",\"184.61\",\"0\",\"4\"],[\"64445\",\"168.98\",\"0\",\"7\"],[\"64444.9\",\"10.54\",\"0\",\"2\"],[\"64444.8\",\"0.02\",\"0\",\"2\"],[\"64444.5\",\"33.82\",\"0\",\"1\"],[\"64444.4\",\"10\",\"0\",\"1\"],[\"64444.3\",\"37.23\",\"0\",\"1\"],[\"64444.2\",\"0.01\",\"0\",\"1\"],[\"64444.1\",\"0.01\",\"0\",\"1\"],[\"64444\",\"0.02\",\"0\",\"2\"],[\"64443.8\",\"20.09\",\"0\",\"1\"],[\"64443.7\",\"37.63\",\"0\",\"4\"],[\"64443.6\",\"0.01\",\"0\",\"1\"],[\"64443.5\",\"86.2\",\"0\",\"1\"],[\"64443.4\",\"403.67\",\"0\",\"1\"],[\"64443.3\",\"130.12\",\"0\",\"4\"],[\"64443.2\",\"135.66\",\"0\",\"5\"],[\"64443\",\"3.15\",\"0\",\"3\"],[\"64442.8\",\"0.03\",\"0\",\"3\"],[\"64442.7\",\"85.42\",\"0\",\"1\"],[\"64442.6\",\"15.65\",\"0\",\"1\"],[\"64442.4\",\"0.01\",\"0\",\"1\"],[\"64442.3\",\"18.13\",\"0\",\"2\"],[\"64442.1\",\"6.22\",\"0\",\"1\"],[\"64442\",\"77.63\",\"0\",\"4\"],[\"64441.9\",\"36.96\",\"0\",\"3\"],[\"64441.8\",\"535.35\",\"0\",\"2\"],[\"64441.6\",\"278.86\",\"0\",\"5\"],[\"64441.5\",\"61.31\",\"0\",\"3\"],[\"64441.4\",\"50.02\",\"0\",\"3\"],[\"64441.3\",\"50\",\"0\",\"1\"],[\"64441.1\",\"13.9\",\"0\",\"2\"],[\"64441\",\"3.11\",\"0\",\"2\"],[\"64440.9\",\"0.01\",\"0\",\"1\"],[\"64440.6\",\"10.01\",\"0\",\"2\"],[\"64440.5\",\"7.73\",\"0\",\"1\"],[\"64440.4\",\"0.01\",\"0\",\"1\"],[\"64440.3\",\"0.04\",\"0\",\"2\"],[\"64440.2\",\"0.01\",\"0\",\"1\"],[\"64440.1\",\"150.57\",\"0\",\"6\"],[\"64440\",\"99.43\",\"0\",\"5\"],[\"64439.9\",\"62.15\",\"0\",\"1\"],[\"64439.7\",\"15.67\",\"0\",\"3\"],[\"64439.5\",\"0.01\",\"0\",\"1\"],[\"64439.4\",\"58.26\",\"0\",\"2\"],[\"64439.3\",\"99.78\",\"0\",\"1\"],[\"64439.2\",\"0.02\",\"0\",\"1\"],[\"64439\",\"0.01\",\"0\",\"1\"],[\"64438.9\",\"37.23\",\"0\",\"1\"],[\"64438.7\",\"3.99\",\"0\",\"1\"],[\"64438.6\",\"12.78\",\"0\",\"4\"],[\"64438.5\",\"16.46\",\"0\",\"3\"],[\"64438.4\",\"0.01\",\"0\",\"1\"],[\"64438.3\",\"0.01\",\"0\",\"1\"],[\"64438.2\",\"31.07\",\"0\",\"2\"],[\"64438.1\",\"15.69\",\"0\",\"2\"],[\"64438\",\"0.01\",\"0\",\"1\"],[\"64437.9\",\"15.65\",\"0\",\"1\"],[\"64437.8\",\"0.01\",\"0\",\"1\"],[\"64437.7\",\"0.01\",\"0\",\"1\"],[\"64437.6\",\"0.01\",\"0\",\"1\"],[\"64437.4\",\"233\",\"0\",\"1\"],[\"64437.3\",\"15.65\",\"0\",\"1\"],[\"64437.2\",\"0.01\",\"0\",\"1\"],[\"64437.1\",\"0.3\",\"0\",\"2\"],[\"64436.9\",\"354.24\",\"0\",\"2\"],[\"64436.8\",\"1\",\"0\",\"1\"],[\"64436.7\",\"15.66\",\"0\",\"2\"],[\"64436.6\",\"10.03\",\"0\",\"4\"],[\"64436.5\",\"11.31\",\"0\",\"3\"],[\"64436.4\",\"15.65\",\"0\",\"1\"],[\"64436.3\",\"117.15\",\"0\",\"4\"],[\"64436.2\",\"0.2\",\"0\",\"1\"],[\"64436.1\",\"25.65\",\"0\",\"2\"],[\"64436\",\"201.01\",\"0\",\"3\"],[\"64435.9\",\"0.01\",\"0\",\"1\"],[\"64435.8\",\"0.07\",\"0\",\"1\"],[\"64435.6\",\"28.42\",\"0\",\"2\"],[\"64435.5\",\"512.2\",\"0\",\"3\"],[\"64435.4\",\"262.87\",\"0\",\"3\"],[\"64435.3\",\"0.01\",\"0\",\"1\"],[\"64435.2\",\"0.02\",\"0\",\"2\"],[\"64435.1\",\"0.01\",\"0\",\"1\"],[\"64434.9\",\"15.7\",\"0\",\"2\"],[\"64434.8\",\"148.64\",\"0\",\"3\"],[\"64434.7\",\"10.01\",\"0\",\"2\"],[\"64434.6\",\"0.5\",\"0\",\"1\"],[\"64434.3\",\"3.11\",\"0\",\"2\"],[\"64434.2\",\"0.02\",\"0\",\"2\"],[\"64434.1\",\"0.35\",\"0\",\"2\"],[\"64434\",\"15.66\",\"0\",\"2\"],[\"64433.8\",\"6.23\",\"0\",\"2\"],[\"64433.7\",\"47.23\",\"0\",\"2\"],[\"64433.5\",\"0.02\",\"0\",\"2\"],[\"64433.4\",\"46.56\",\"0\",\"3\"],[\"64433.3\",\"17.97\",\"0\",\"4\"],[\"64433.2\",\"21.29\",\"0\",\"2\"],[\"64433.1\",\"15.65\",\"0\",\"1\"],[\"64433\",\"4.07\",\"0\",\"2\"],[\"64432.8\",\"0.01\",\"0\",\"1\"],[\"64432.6\",\"15.71\",\"0\",\"4\"],[\"64432.5\",\"0.02\",\"0\",\"2\"],[\"64432.3\",\"0.02\",\"0\",\"2\"],[\"64432.2\",\"46.57\",\"0\",\"2\"],[\"64432.1\",\"0.08\",\"0\",\"1\"],[\"64432\",\"64.4\",\"0\",\"5\"],[\"64431.9\",\"17.93\",\"0\",\"2\"],[\"64431.8\",\"15.87\",\"0\",\"2\"],[\"64431.7\",\"321.87\",\"0\",\"2\"],[\"64431.6\",\"496.53\",\"0\",\"1\"],[\"64431.5\",\"15.65\",\"0\",\"1\"],[\"64431.4\",\"198.51\",\"0\",\"3\"],[\"64431.3\",\"15.66\",\"0\",\"2\"],[\"64431.2\",\"46.54\",\"0\",\"1\"],[\"64431.1\",\"0.01\",\"0\",\"1\"],[\"64431\",\"4.06\",\"0\",\"17\"],[\"64430.7\",\"15.65\",\"0\",\"1\"],[\"64430.4\",\"0.04\",\"0\",\"4\"],[\"64430.3\",\"1.01\",\"0\",\"2\"],[\"64430.1\",\"15.67\",\"0\",\"3\"],[\"64430\",\"6.59\",\"0\",\"4\"],[\"64429.9\",\"12.37\",\"0\",\"4\"],[\"64429.8\",\"35.67\",\"0\",\"4\"],[\"64429.4\",\"155.94\",\"0\",\"3\"],[\"64429.2\",\"46.65\",\"0\",\"2\"],[\"64429.1\",\"0.02\",\"0\",\"1\"],[\"64428.9\",\"16.49\",\"0\",\"1\"],[\"64428.8\",\"0.02\",\"0\",\"2\"],[\"64428.6\",\"0.04\",\"0\",\"2\"],[\"64428.4\",\"37.23\",\"0\",\"1\"],[\"64428.2\",\"15.66\",\"0\",\"2\"],[\"64428.1\",\"0.65\",\"0\",\"2\"],[\"64428\",\"15.75\",\"0\",\"5\"],[\"64427.9\",\"3.88\",\"0\",\"1\"],[\"64427.8\",\"1.06\",\"0\",\"1\"],[\"64427.7\",\"387.46\",\"0\",\"4\"],[\"64427.6\",\"0.01\",\"0\",\"1\"],[\"64427.3\",\"255.84\",\"0\",\"5\"],[\"64427.2\",\"496.54\",\"0\",\"2\"],[\"64427\",\"266.25\",\"0\",\"5\"],[\"64426.8\",\"0.06\",\"0\",\"1\"],[\"64426.7\",\"46.66\",\"0\",\"13\"],[\"64426.6\",\"0.01\",\"0\",\"1\"],[\"64426.5\",\"15.69\",\"0\",\"2\"],[\"64426.4\",\"0.01\",\"0\",\"1\"],[\"64426.1\",\"0.77\",\"0\",\"1\"],[\"64426\",\"0.03\",\"0\",\"2\"],[\"64425.9\",\"15.65\",\"0\",\"1\"],[\"64425.8\",\"0.01\",\"0\",\"1\"],[\"64425.7\",\"4.01\",\"0\",\"2\"],[\"64425.6\",\"3.91\",\"0\",\"2\"],[\"64425.5\",\"11.06\",\"0\",\"1\"],[\"64425.4\",\"6.27\",\"0\",\"2\"],[\"64425.2\",\"0.79\",\"0\",\"3\"],[\"64425\",\"17.21\",\"0\",\"8\"],[\"64424.9\",\"15.66\",\"0\",\"2\"],[\"64424.6\",\"0.02\",\"0\",\"2\"],[\"64424.3\",\"46.54\",\"0\",\"1\"],[\"64424.2\",\"0.01\",\"0\",\"1\"],[\"64424.1\",\"42.31\",\"0\",\"1\"],[\"64424\",\"1.38\",\"0\",\"6\"],[\"64423.9\",\"0.05\",\"0\",\"1\"],[\"64423.8\",\"17.49\",\"0\",\"3\"],[\"64423.4\",\"198.67\",\"0\",\"2\"],[\"64423.3\",\"496.84\",\"0\",\"2\"],[\"64423.2\",\"52.88\",\"0\",\"2\"],[\"64423.1\",\"0.01\",\"0\",\"1\"],[\"64423\",\"1.59\",\"0\",\"6\"],[\"64422.8\",\"0.02\",\"0\",\"2\"],[\"64422.7\",\"0.02\",\"0\",\"1\"],[\"64422.6\",\"98.94\",\"0\",\"3\"],[\"64422.4\",\"326.23\",\"0\",\"4\"],[\"64422.2\",\"11.09\",\"0\",\"4\"],[\"64422\",\"0.03\",\"0\",\"3\"],[\"64421.9\",\"0.16\",\"0\",\"2\"],[\"64421.8\",\"0.03\",\"0\",\"2\"],[\"64421.7\",\"15.65\",\"0\",\"1\"],[\"64421.6\",\"15.66\",\"0\",\"2\"],[\"64421.5\",\"0.8\",\"0\",\"2\"],[\"64421.4\",\"46.54\",\"0\",\"1\"],[\"64421.3\",\"0.03\",\"0\",\"2\"],[\"64421.2\",\"0.01\",\"0\",\"1\"],[\"64421.1\",\"21.53\",\"0\",\"4\"],[\"64421\",\"0.01\",\"0\",\"1\"],[\"64420.9\",\"19.81\",\"0\",\"3\"],[\"64420.7\",\"0.03\",\"0\",\"1\"],[\"64420.6\",\"100.58\",\"0\",\"1\"],[\"64420.5\",\"0.02\",\"0\",\"2\"],[\"64420.4\",\"0.27\",\"0\",\"2\"],[\"64420.3\",\"212.64\",\"0\",\"2\"],[\"64420.2\",\"80.61\",\"0\",\"3\"],[\"64420\",\"5.83\",\"0\",\"21\"],[\"64419.9\",\"18.91\",\"0\",\"3\"],[\"64419.8\",\"0.02\",\"0\",\"2\"],[\"64419.7\",\"20.01\",\"0\",\"2\"],[\"64419.6\",\"0.03\",\"0\",\"3\"],[\"64419.5\",\"0.27\",\"0\",\"2\"],[\"64419.4\",\"33.02\",\"0\",\"2\"],[\"64419.3\",\"552.33\",\"0\",\"4\"],[\"64419.2\",\"46.56\",\"0\",\"3\"],[\"64419.1\",\"0.02\",\"0\",\"2\"],[\"64419\",\"0.03\",\"0\",\"3\"],[\"64418.9\",\"11.06\",\"0\",\"1\"],[\"64418.8\",\"0.02\",\"0\",\"1\"],[\"64418.7\",\"0.01\",\"0\",\"1\"],[\"64418.6\",\"0.3\",\"0\",\"2\"],[\"64418.5\",\"0.05\",\"0\",\"1\"],[\"64418.4\",\"0.97\",\"0\",\"1\"],[\"64418.3\",\"15.65\",\"0\",\"1\"],[\"64418.1\",\"15.31\",\"0\",\"1\"],[\"64418\",\"20.53\",\"0\",\"4\"],[\"64417.9\",\"2.28\",\"0\",\"1\"],[\"64417.8\",\"0.02\",\"0\",\"2\"],[\"64417.7\",\"0.04\",\"0\",\"1\"],[\"64417.6\",\"0.02\",\"0\",\"2\"],[\"64417.5\",\"0.02\",\"0\",\"2\"],[\"64417.4\",\"0.35\",\"0\",\"8\"],[\"64417.2\",\"0.02\",\"0\",\"2\"],[\"64417.1\",\"3.9\",\"0\",\"1\"],[\"64417\",\"0.12\",\"0\",\"1\"],[\"64416.9\",\"68.68\",\"0\",\"4\"],[\"64416.8\",\"0.01\",\"0\",\"1\"],[\"64416.7\",\"45.2\",\"0\",\"3\"],[\"64416.6\",\"15.66\",\"0\",\"2\"],[\"64416.5\",\"0.08\",\"0\",\"1\"],[\"64416.3\",\"47.19\",\"0\",\"6\"],[\"64416.2\",\"101.76\",\"0\",\"4\"],[\"64416\",\"298.12\",\"0\",\"6\"],[\"64415.9\",\"0.01\",\"0\",\"1\"],[\"64415.7\",\"1.18\",\"0\",\"1\"],[\"64415.6\",\"30.86\",\"0\",\"3\"],[\"64415.5\",\"20\",\"0\",\"1\"],[\"64415.4\",\"0.01\",\"0\",\"1\"],[\"64415.3\",\"581.08\",\"0\",\"5\"],[\"64415.2\",\"0.01\",\"0\",\"1\"],[\"64415.1\",\"6.91\",\"0\",\"2\"],[\"64415\",\"15.88\",\"0\",\"4\"],[\"64414.9\",\"2.32\",\"0\",\"2\"],[\"64414.8\",\"19.02\",\"0\",\"1\"],[\"64414.7\",\"26.09\",\"0\",\"3\"],[\"64414.6\",\"0.31\",\"0\",\"1\"],[\"64414.5\",\"1365.58\",\"0\",\"1\"],[\"64414.4\",\"99.09\",\"0\",\"1\"],[\"64414.2\",\"0.02\",\"0\",\"2\"],[\"64414.1\",\"0.11\",\"0\",\"2\"],[\"64414\",\"0.01\",\"0\",\"1\"],[\"64413.9\",\"23.27\",\"0\",\"1\"],[\"64413.8\",\"0.01\",\"0\",\"1\"],[\"64413.3\",\"15.69\",\"0\",\"4\"],[\"64413.1\",\"64.55\",\"0\",\"2\"],[\"64412.9\",\"0.01\",\"0\",\"1\"],[\"64412.8\",\"0.01\",\"0\",\"1\"],[\"64412.7\",\"0.09\",\"0\",\"3\"],[\"64412.4\",\"0.01\",\"0\",\"1\"],[\"64412.3\",\"11.43\",\"0\",\"2\"],[\"64412.2\",\"99.58\",\"0\",\"1\"],[\"64412.1\",\"50\",\"0\",\"1\"],[\"64412\",\"0.02\",\"0\",\"1\"],[\"64411.8\",\"0.01\",\"0\",\"1\"],[\"64411.7\",\"15.68\",\"0\",\"2\"],[\"64411.5\",\"22.82\",\"0\",\"2\"],[\"64411.4\",\"3.38\",\"0\",\"2\"],[\"64411.3\",\"0.01\",\"0\",\"1\"],[\"64411.2\",\"15.33\",\"0\",\"1\"],[\"64411.1\",\"0.06\",\"0\",\"2\"],[\"64410.9\",\"2.08\",\"0\",\"3\"],[\"64410.8\",\"0.03\",\"0\",\"2\"],[\"64410.6\",\"21.32\",\"0\",\"2\"],[\"64410.5\",\"46.54\",\"0\",\"1\"],[\"64410.4\",\"0.31\",\"0\",\"1\"],[\"64410.3\",\"0.06\",\"0\",\"2\"],[\"64410.2\",\"6.23\",\"0\",\"2\"],[\"64410.1\",\"0.81\",\"0\",\"4\"],[\"64410\",\"1.56\",\"0\",\"5\"],[\"64409.9\",\"0.1\",\"0\",\"4\"],[\"64409.8\",\"106.39\",\"0\",\"1\"],[\"64409.7\",\"0.03\",\"0\",\"3\"],[\"64409.6\",\"0.24\",\"0\",\"2\"],[\"64409.1\",\"0.85\",\"0\",\"4\"],[\"64409\",\"11.42\",\"0\",\"1\"],[\"64408.9\",\"69.14\",\"0\",\"5\"],[\"64408.8\",\"0.01\",\"0\",\"1\"],[\"64408.7\",\"5.45\",\"0\",\"4\"],[\"64408.5\",\"0.38\",\"0\",\"1\"],[\"64408.4\",\"7.93\",\"0\",\"5\"],[\"64408.3\",\"0.03\",\"0\",\"1\"],[\"64408.2\",\"83.77\",\"0\",\"2\"],[\"64408.1\",\"0.01\",\"0\",\"1\"],[\"64408\",\"4.48\",\"0\",\"6\"],[\"64407.9\",\"0.04\",\"0\",\"4\"],[\"64407.6\",\"0.02\",\"0\",\"2\"],[\"64407.5\",\"496.53\",\"0\",\"1\"],[\"64407.4\",\"0.51\",\"0\",\"1\"],[\"64407.3\",\"99.78\",\"0\",\"1\"],[\"64407.2\",\"0.05\",\"0\",\"1\"],[\"64407\",\"0.37\",\"0\",\"4\"],[\"64406.9\",\"0.01\",\"0\",\"1\"],[\"64406.7\",\"11.06\",\"0\",\"3\"],[\"64406.6\",\"3.92\",\"0\",\"2\"],[\"64406.4\",\"0.12\",\"0\",\"2\"],[\"64406.3\",\"0.32\",\"0\",\"1\"],[\"64406.1\",\"0.02\",\"0\",\"2\"],[\"64406\",\"0.01\",\"0\",\"1\"],[\"64405.9\",\"1.93\",\"0\",\"1\"]],\"ts\":\"1782015919205\",\"checksum\":-608858156,\"seqId\":325069868269,\"prevSeqId\":-1}]}"}
{"action": "update", "capture_sequence": 164, "channel": "books", "connection_sequence": 3, "event": null, "instId": "BTC-USDT-SWAP", "local_receive_ts": "2026-06-21T04:25:19Z", "monotonic_ns": 1643475225060822, "raw": "{\"arg\":{\"channel\":\"books\",\"instId\":\"BTC-USDT-SWAP\"},\"action\":\"update\",\"data\":[{\"asks\":[[\"64458\",\"484.31\",\"0\",\"55\"],[\"64458.1\",\"0.03\",\"0\",\"3\"],[\"64461.3\",\"1.56\",\"0\",\"1\"],[\"64476.2\",\"0.02\",\"0\",\"2\"],[\"64507.9\",\"0\",\"0\",\"0\"]],\"bids\":[[\"64443\",\"0.02\",\"0\",\"2\"],[\"64436.2\",\"0\",\"0\",\"0\"],[\"64405.7\",\"15.87\",\"0\",\"2\"]],\"ts\":\"1782015919305\",\"checksum\":-1652423067,\"seqId\":325069868305,\"prevSeqId\":325069868269}]}"}
{"action": "update", "capture_sequence": 165, "channel": "books", "connection_sequence": 3, "event": null, "instId": "BTC-USDT-SWAP", "local_receive_ts": "2026-06-21T04:25:19Z", "monotonic_ns": 1643475308218667, "raw": "{\"arg\":{\"channel\":\"books\",\"instId\":\"BTC-USDT-SWAP\"},\"action\":\"update\",\"data\":[{\"asks\":[[\"64458\",\"484.41\",\"0\",\"56\"],[\"64461.2\",\"1.58\",\"0\",\"2\"],[\"64461.3\",\"0\",\"0\",\"0\"],[\"64476.2\",\"0.17\",\"0\",\"3\"],[\"64507.9\",\"0.25\",\"0\",\"2\"]],\"bids\":[[\"64457.9\",\"576.56\",\"0\",\"26\"],[\"64445.5\",\"22\",\"0\",\"1\"],[\"64443\",\"3.25\",\"0\",\"3\"],[\"64436.2\",\"0.19\",\"0\",\"1\"],[\"64405.9\",\"0\",\"0\",\"0\"],[\"64405.7\",\"0\",\"0\",\"0\"]],\"ts\":\"1782015919405\",\"checksum\":1932551447,\"seqId\":325069868372,\"prevSeqId\":325069868305}]}"}
{"action": "update", "capture_sequence": 166, "channel": "books", "connection_sequence": 3, "event": null, "instId": "BTC-USDT-SWAP", "local_receive_ts": "2026-06-21T04:25:19Z", "monotonic_ns": 1643475408349299, "raw": "{\"arg\":{\"channel\":\"books\",\"instId\":\"BTC-USDT-SWAP\"},\"action\":\"update\",\"data\":[{\"asks\":[[\"64459.7\",\"1.56\",\"0\",\"1\"],[\"64461\",\"1.57\",\"0\",\"2\"],[\"64461.2\",\"0.02\",\"0\",\"1\"],[\"64461.8\",\"0\",\"0\",\"0\"],[\"64484.3\",\"10.65\",\"0\",\"2\"],[\"64484.5\",\"0.37\",\"0\",\"4\"]],\"bids\":[[\"64445.6\",\"4.67\",\"0\",\"3\"],[\"64445.2\",\"0\",\"0\",\"0\"],[\"64433.1\",\"15.66\",\"0\",\"2\"],[\"64432.5\",\"0.01\",\"0\",\"1\"],[\"64405.9\",\"1.93\",\"0\",\"1\"]],\"ts\":\"1782015919505\",\"checksum\":1265786530,\"seqId\":325069868404,\"prevSeqId\":325069868372}]}"}
{"action": "update", "capture_sequence": 167, "channel": "books", "connection_sequence": 3, "event": null, "instId": "BTC-USDT-SWAP", "local_receive_ts": "2026-06-21T04:25:19Z", "monotonic_ns": 1643475507978491, "raw": "{\"arg\":{\"channel\":\"books\",\"instId\":\"BTC-USDT-SWAP\"},\"action\":\"update\",\"data\":[{\"asks\":[[\"64459.7\",\"0\",\"0\",\"0\"],[\"64461\",\"0.01\",\"0\",\"1\"],[\"64462.3\",\"0\",\"0\",\"0\"],[\"64466.7\",\"1.57\",\"0\",\"2\"],[\"64508\",\"13.54\",\"0\",\"7\"],[\"64508.1\",\"21.31\",\"0\",\"3\"]],\"bids\":[],\"ts\":\"1782015919605\",\"checksum\":-1295686313,\"seqId\":325069868427,\"prevSeqId\":325069868404}]}"}
{"action": "update", "capture_sequence": 168, "channel": "books", "connection_sequence": 3, "event": null, "instId": "BTC-USDT-SWAP", "local_receive_ts": "2026-06-21T04:25:20Z", "monotonic_ns": 1643475908625701, "raw": "{\"arg\":{\"channel\":\"books\",\"instId\":\"BTC-USDT-SWAP\"},\"action\":\"update\",\"data\":[{\"asks\":[[\"64461\",\"1.57\",\"0\",\"2\"],[\"64483\",\"233.8\",\"0\",\"2\"],[\"64483.8\",\"0\",\"0\",\"0\"],[\"64487.4\",\"0.49\",\"0\",\"5\"],[\"64487.9\",\"143.58\",\"0\",\"3\"],[\"64488.6\",\"0.02\",\"0\",\"2\"],[\"64492.5\",\"86.2\",\"0\",\"5\"],[\"64493.1\",\"31.76\",\"0\",\"5\"],[\"64508.2\",\"59.01\",\"0\",\"5\"]],\"bids\":[[\"64445.6\",\"3.9\",\"0\",\"2\"],[\"64445.2\",\"0.77\",\"0\",\"1\"],[\"64444.5\",\"0\",\"0\",\"0\"],[\"64443.9\",\"33.82\",\"0\",\"1\"],[\"64442\",\"77.65\",\"0\",\"5\"],[\"64441.9\",\"36.94\",\"0\",\"2\"],[\"64440\",\"157.68\",\"0\",\"6\"],[\"64439.4\",\"0.01\",\"0\",\"1\"],[\"64405.9\",\"0\",\"0\",\"0\"]],\"ts\":\"1782015920005\",\"checksum\":1359890606,\"seqId\":325069868485,\"prevSeqId\":325069868427}]}"}
{"action": "update", "capture_sequence": 169, "channel": "books", "connection_sequence": 3, "event": null, "instId": "BTC-USDT-SWAP", "local_receive_ts": "2026-06-21T04:25:20Z", "monotonic_ns": 1643476008640306, "raw": "{\"arg\":{\"channel\":\"books\",\"instId\":\"BTC-USDT-SWAP\"},\"action\":\"update\",\"data\":[{\"asks\":[[\"64460.8\",\"57.53\",\"0\",\"2\"],[\"64461\",\"0.01\",\"0\",\"1\"],[\"64461.3\",\"1.56\",\"0\",\"1\"],[\"64461.8\",\"1.56\",\"0\",\"1\"],[\"64462.3\",\"1.56\",\"0\",\"1\"],[\"64464.8\",\"1.56\",\"0\",\"1\"],[\"64465.2\",\"77.75\",\"0\",\"2\"],[\"64465.7\",\"76.32\",\"0\",\"3\"],[\"64466.2\",\"0\",\"0\",\"0\"],[\"64466.7\",\"0.01\",\"0\",\"1\"],[\"64475.5\",\"31.04\",\"0\",\"1\"],[\"64475.6\",\"0.39\",\"0\",\"2\"],[\"64484.2\",\"16.42\",\"0\",\"2\"],[\"64484.3\",\"9.88\",\"0\",\"1\"],[\"64487.4\",\"58.69\",\"0\",\"6\"],[\"64487.9\",\"85.38\",\"0\",\"2\"],[\"64494.1\",\"21.27\",\"0\",\"2\"],[\"64494.5\",\"0\",\"0\",\"0\"],[\"64508\",\"0\",\"0\",\"0\"],[\"64508.1\",\"0\",\"0\",\"0\"],[\"64508.2\",\"0\",\"0\",\"0\"]],\"bids\":[[\"64457.8\",\"0.14\",\"0\",\"2\"],[\"64457.7\",\"0.32\",\"0\",\"1\"],[\"64457.5\",\"0.01\",\"0\",\"1\"],[\"64457.4\",\"1.56\",\"0\",\"1\"],[\"64451.9\",\"0.31\",\"0\",\"1\"],[\"64451.8\",\"0.01\",\"0\",\"1\"],[\"64451.6\",\"77.57\",\"0\",\"1\"],[\"64443.8\",\"0\",\"0\",\"0\"],[\"64443.6\",\"20.1\",\"0\",\"2\"],[\"64442.7\",\"0\",\"0\",\"0\"],[\"64442.4\",\"85.43\",\"0\",\"2\"],[\"64440\",\"99.43\",\"0\",\"5\"],[\"64439\",\"58.26\",\"0\",\"2\"],[\"64406.1\",\"0\",\"0\",\"0\"],[\"64406\",\"0\",\"0\",\"0\"]],\"ts\":\"1782015920105\",\"checksum\":-1346296572,\"seqId\":325069868588,\"prevSeqId\":325069868485}]}"}
{"action": null, "capture_sequence": 170, "channel": "trades", "connection_sequence": 3, "event": null, "instId": "BTC-USDT-SWAP", "local_receive_ts": "2026-06-21T04:25:20Z", "monotonic_ns": 1643476057669718, "raw": "{\"arg\":{\"channel\":\"trades\",\"instId\":\"BTC-USDT-SWAP\"},\"data\":[{\"instId\":\"BTC-USDT-SWAP\",\"tradeId\":\"2718748873\",\"px\":\"64457.9\",\"sz\":\"0.5\",\"side\":\"sell\",\"ts\":\"1782015920154\",\"count\":\"1\",\"source\":\"0\",\"seqId\":325069868629}]}"}
{"action": "update", "capture_sequence": 171, "channel": "books", "connection_sequence": 3, "event": null, "instId": "BTC-USDT-SWAP", "local_receive_ts": "2026-06-21T04:25:20Z", "monotonic_ns": 1643476108660985, "raw": "{\"arg\":{\"channel\":\"books\",\"instId\":\"BTC-USDT-SWAP\"},\"action\":\"update\",\"data\":[{\"asks\":[[\"64459.7\",\"1.56\",\"0\",\"1\"],[\"64460.2\",\"2.34\",\"0\",\"3\"],[\"64460.8\",\"55.97\",\"0\",\"1\"],[\"64461\",\"1.57\",\"0\",\"2\"],[\"64461.3\",\"0\",\"0\",\"0\"],[\"64464.8\",\"0\",\"0\",\"0\"],[\"64483\",\"200\",\"0\",\"1\"],[\"64483.1\",\"134.1\",\"0\",\"5\"],[\"64487.9\",\"0.01\",\"0\",\"1\"],[\"64488.1\",\"86.04\",\"0\",\"3\"],[\"64492.5\",\"0.06\",\"0\",\"4\"],[\"64492.6\",\"186.26\",\"0\",\"3\"],[\"64508\",\"13.54\",\"0\",\"7\"]],\"bids\":[[\"64457.9\",\"577.62\",\"0\",\"27\"],[\"64457.5\",\"0\",\"0\",\"0\"],[\"64457.4\",\"0\",\"0\",\"0\"],[\"64455.7\",\"0.01\",\"0\",\"1\"],[\"64444.4\",\"43.82\",\"0\",\"2\"],[\"64443.9\",\"0\",\"0\",\"0\"],[\"64442.7\",\"85.42\",\"0\",\"1\"],[\"64442.4\",\"0.01\",\"0\",\"1\"],[\"64438.2\",\"0.01\",\"0\",\"1\"],[\"64438\",\"31.07\",\"0\",\"2\"],[\"64406.2\",\"0.01\",\"0\",\"1\"]],\"ts\":\"1782015920205\",\"checksum\":-42904117,\"seqId\":325069868682,\"prevSeqId\":325069868588}]}"}
{"action": "update", "capture_sequence": 172, "channel": "books", "connection_sequence": 3, "event": null, "instId": "BTC-USDT-SWAP", "local_receive_ts": "2026-06-21T04:25:20Z", "monotonic_ns": 1643476208718473, "raw": "{\"arg\":{\"channel\":\"books\",\"instId\":\"BTC-USDT-SWAP\"},\"action\":\"update\",\"data\":[{\"asks\":[[\"64476.2\",\"0.02\",\"0\",\"2\"],[\"64483.1\",\"100.3\",\"0\",\"4\"],[\"64483.8\",\"33.8\",\"0\",\"1\"],[\"64492.6\",\"100.12\",\"0\",\"2\"],[\"64493.1\",\"117.89\",\"0\",\"6\"],[\"64494.1\",\"1.2\",\"0\",\"1\"],[\"64494.5\",\"20.07\",\"0\",\"1\"],[\"64507.9\",\"0\",\"0\",\"0\"],[\"64508\",\"0\",\"0\",\"0\"]],\"bids\":[[\"64457.9\",\"577.61\",\"0\",\"27\"],[\"64451.8\",\"77.58\",\"0\",\"2\"],[\"64451.6\",\"0\",\"0\",\"0\"],[\"64444.5\",\"33.82\",\"0\",\"1\"],[\"64444.4\",\"10\",\"0\",\"1\"],[\"64443.8\",\"20.09\",\"0\",\"1\"],[\"64443.6\",\"0.01\",\"0\",\"1\"],[\"64443\",\"0.02\",\"0\",\"2\"],[\"64436.2\",\"0\",\"0\",\"0\"],[\"64433.1\",\"15.65\",\"0\",\"1\"],[\"64433\",\"4.08\",\"0\",\"3\"]],\"ts\":\"1782015920305\",\"checksum\":751899558,\"seqId\":325069868723,\"prevSeqId\":325069868682}]}"}
{"action": "update", "capture_sequence": 173, "channel": "books", "connection_sequence": 3, "event": null, "instId": "BTC-USDT-SWAP", "local_receive_ts": "2026-06-21T04:25:20Z", "monotonic_ns": 1643476315332885, "raw": "{\"arg\":{\"channel\":\"books\",\"instId\":\"BTC-USDT-SWAP\"},\"action\":\"update\",\"data\":[{\"asks\":[[\"64476.2\",\"0.18\",\"0\",\"3\"],[\"64487.4\",\"0.49\",\"0\",\"5\"],[\"64487.5\",\"101.67\",\"0\",\"7\"],[\"64488.1\",\"0.67\",\"0\",\"2\"],[\"64488.6\",\"85.38\",\"0\",\"3\"],[\"64494.5\",\"0\",\"0\",\"0\"],[\"64494.7\",\"44.62\",\"0\",\"7\"],[\"64507.9\",\"0.25\",\"0\",\"2\"]],\"bids\":[[\"64457.9\",\"576.05\",\"0\",\"26\"],[\"64457.7\",\"0\",\"0\",\"0\"],[\"64457.6\",\"2.03\",\"0\",\"3\"],[\"64457.4\",\"0.32\",\"0\",\"2\"],[\"64457.1\",\"0\",\"0\",\"0\"],[\"64456.8\",\"1.87\",\"0\",\"2\"],[\"64455.7\",\"0\",\"0\",\"0\"],[\"64452.5\",\"0.01\",\"0\",\"1\"],[\"64444\",\"20.11\",\"0\",\"3\"],[\"64443.8\",\"0\",\"0\",\"0\"],[\"64443.1\",\"85.42\",\"0\",\"1\"],[\"64443\",\"3.13\",\"0\",\"3\"],[\"64442.7\",\"0\",\"0\",\"0\"],[\"64442\",\"77.63\",\"0\",\"4\"],[\"64441.9\",\"36.96\",\"0\",\"3\"],[\"64439.4\",\"58.26\",\"0\",\"2\"],[\"64439.2\",\"0\",\"0\",\"0\"],[\"64439\",\"0.01\",\"0\",\"1\"],[\"64438.9\",\"37.25\",\"0\",\"2\"],[\"64436.2\",\"0.19\",\"0\",\"1\"],[\"64406.1\",\"0.02\",\"0\",\"2\"],[\"64406\",\"0.02\",\"0\",\"2\"],[\"64405.9\",\"1.93\",\"0\",\"1\"]],\"ts\":\"1782015920405\",\"checksum\":1375538233,\"seqId\":325069868846,\"prevSeqId\":325069868723}]}"}
{"action": "update", "capture_sequence": 174, "channel": "books", "connection_sequence": 3, "event": null, "instId": "BTC-USDT-SWAP", "local_receive_ts": "2026-06-21T04:25:20Z", "monotonic_ns": 1643476407757023, "raw": "{\"arg\":{\"channel\":\"books\",\"instId\":\"BTC-USDT-SWAP\"},\"action\":\"update\",\"data\":[{\"asks\":[[\"64459.7\",\"0\",\"0\",\"0\"],[\"64460.2\",\"0.78\",\"0\",\"2\"],[\"64461\",\"0.01\",\"0\",\"1\"],[\"64464.8\",\"1.56\",\"0\",\"1\"]],\"bids\":[[\"64457.9\",\"577.61\",\"0\",\"27\"],[\"64457.6\",\"0.47\",\"0\",\"2\"],[\"64457.3\",\"1.56\",\"0\",\"1\"],[\"64405.9\",\"0\",\"0\",\"0\"]],\"ts\":\"1782015920505\",\"checksum\":1108434317,\"seqId\":325069868885,\"prevSeqId\":325069868846}]}"}
{"action": "update", "capture_sequence": 175, "channel": "books", "connection_sequence": 3, "event": null, "instId": "BTC-USDT-SWAP", "local_receive_ts": "2026-06-21T04:25:20Z", "monotonic_ns": 1643476507943188, "raw": "{\"arg\":{\"channel\":\"books\",\"instId\":\"BTC-USDT-SWAP\"},\"action\":\"update\",\"data\":[{\"asks\":[[\"64458\",\"484.39\",\"0\",\"56\"]],\"bids\":[[\"64457.9\",\"576.05\",\"0\",\"26\"]],\"ts\":\"1782015920605\",\"checksum\":264226024,\"seqId\":325069868896,\"prevSeqId\":325069868885}]}"}
{"action": "update", "capture_sequence": 176, "channel": "books", "connection_sequence": 3, "event": null, "instId": "BTC-USDT-SWAP", "local_receive_ts": "2026-06-21T04:25:20Z", "monotonic_ns": 1643476708170715, "raw": "{\"arg\":{\"channel\":\"books\",\"instId\":\"BTC-USDT-SWAP\"},\"action\":\"update\",\"data\":[{\"asks\":[[\"64458\",\"484.49\",\"0\",\"57\"],[\"64476.2\",\"0.02\",\"0\",\"2\"],[\"64484.3\",\"0\",\"0\",\"0\"],[\"64508\",\"13.54\",\"0\",\"7\"]],\"bids\":[[\"64457.4\",\"0.31\",\"0\",\"1\"],[\"64457.3\",\"0\",\"0\",\"0\"],[\"64455.7\",\"0.01\",\"0\",\"1\"],[\"64443\",\"0.02\",\"0\",\"2\"],[\"64436.2\",\"0\",\"0\",\"0\"],[\"64405.9\",\"1.93\",\"0\",\"1\"]],\"ts\":\"1782015920805\",\"checksum\":-1775618255,\"seqId\":325069868920,\"prevSeqId\":325069868896}]}"}
{"action": "update", "capture_sequence": 177, "channel": "books", "connection_sequence": 3, "event": null, "instId": "BTC-USDT-SWAP", "local_receive_ts": "2026-06-21T04:25:21Z", "monotonic_ns": 1643476808476040, "raw": "{\"arg\":{\"channel\":\"books\",\"instId\":\"BTC-USDT-SWAP\"},\"action\":\"update\",\"data\":[{\"asks\":[[\"64476.2\",\"0.18\",\"0\",\"3\"]],\"bids\":[[\"64443\",\"3.13\",\"0\",\"3\"],[\"64436.2\",\"0.19\",\"0\",\"1\"],[\"64405.9\",\"0\",\"0\",\"0\"]],\"ts\":\"1782015920905\",\"checksum\":-1775618255,\"seqId\":325069868930,\"prevSeqId\":325069868920}]}"}
{"action": "update", "capture_sequence": 178, "channel": "books", "connection_sequence": 3, "event": null, "instId": "BTC-USDT-SWAP", "local_receive_ts": "2026-06-21T04:25:21Z", "monotonic_ns": 1643476909053280, "raw": "{\"arg\":{\"channel\":\"books\",\"instId\":\"BTC-USDT-SWAP\"},\"action\":\"update\",\"data\":[{\"asks\":[[\"64459.9\",\"1.56\",\"0\",\"1\"],[\"64483.8\",\"0\",\"0\",\"0\"],[\"64484.5\",\"34.17\",\"0\",\"5\"],[\"64488.6\",\"0.02\",\"0\",\"2\"],[\"64489.3\",\"108.62\",\"0\",\"7\"],[\"64493.1\",\"31.76\",\"0\",\"5\"],[\"64493.9\",\"86.13\",\"0\",\"1\"],[\"64494.7\",\"24.55\",\"0\",\"6\"],[\"64495.6\",\"20.09\",\"0\",\"3\"],[\"64508\",\"0\",\"0\",\"0\"]],\"bids\":[[\"64457.9\",\"577.61\",\"0\",\"27\"],[\"64454.6\",\"57.76\",\"0\",\"2\"],[\"64445.7\",\"548.36\",\"0\",\"5\"],[\"64445.2\",\"86.97\",\"0\",\"2\"],[\"64445.1\",\"204.7\",\"0\",\"5\"],[\"64444.5\",\"0\",\"0\",\"0\"],[\"64444.1\",\"85.43\",\"0\",\"2\"],[\"64444\",\"0.02\",\"0\",\"2\"],[\"64443.5\",\"0\",\"0\",\"0\"],[\"64443.1\",\"0\",\"0\",\"0\"],[\"64405.9\",\"1.93\",\"0\",\"1\"],[\"64405.7\",\"4.65\",\"0\",\"1\"],[\"64405.6\",\"0.02\",\"0\",\"2\"]],\"ts\":\"1782015921005\",\"checksum\":513847525,\"seqId\":325069868973,\"prevSeqId\":325069868930}]}"}
{"action": null, "capture_sequence": 179, "channel": "trades", "connection_sequence": 3, "event": null, "instId": "BTC-USDT-SWAP", "local_receive_ts": "2026-06-21T04:25:21Z", "monotonic_ns": 1643476978129931, "raw": "{\"arg\":{\"channel\":\"trades\",\"instId\":\"BTC-USDT-SWAP\"},\"data\":[{\"instId\":\"BTC-USDT-SWAP\",\"tradeId\":\"2718748874\",\"px\":\"64457.9\",\"sz\":\"5\",\"side\":\"sell\",\"ts\":\"1782015921075\",\"count\":\"1\",\"source\":\"0\",\"seqId\":325069869046}]}"}
{"action": "update", "capture_sequence": 180, "channel": "books", "connection_sequence": 3, "event": null, "instId": "BTC-USDT-SWAP", "local_receive_ts": "2026-06-21T04:25:21Z", "monotonic_ns": 1643477016222198, "raw": "{\"arg\":{\"channel\":\"books\",\"instId\":\"BTC-USDT-SWAP\"},\"action\":\"update\",\"data\":[{\"asks\":[[\"64458.7\",\"0.01\",\"0\",\"1\"],[\"64459.1\",\"0.01\",\"0\",\"1\"],[\"64459.9\",\"0\",\"0\",\"0\"],[\"64460.3\",\"1.56\",\"0\",\"1\"],[\"64460.8\",\"57.53\",\"0\",\"2\"],[\"64461.3\",\"1.56\",\"0\",\"1\"],[\"64464.8\",\"0\",\"0\",\"0\"],[\"64475.5\",\"0\",\"0\",\"0\"],[\"64475.6\",\"31.43\",\"0\",\"3\"],[\"64477.6\",\"0.08\",\"0\",\"2\"],[\"64477.9\",\"0\",\"0\",\"0\"],[\"64483.8\",\"33.8\",\"0\",\"1\"],[\"64484.5\",\"0.37\",\"0\",\"4\"],[\"64487.5\",\"43.47\",\"0\",\"6\"],[\"64488.2\",\"62.16\",\"0\",\"3\"],[\"64488.6\",\"85.38\",\"0\",\"3\"],[\"64489.3\",\"23.26\",\"0\",\"6\"],[\"64493.1\",\"117.89\",\"0\",\"6\"],[\"64493.9\",\"0\",\"0\",\"0\"],[\"64494.6\",\"25.11\",\"0\",\"5\"],[\"64495.6\",\"0.02\",\"0\",\"2\"],[\"64508\",\"13.54\",\"0\",\"7\"]],\"bids\":[[\"64457.9\",\"572.61\",\"0\",\"27\"],[\"64456.9\",\"0\",\"0\",\"0\"],[\"64456.8\",\"0.33\",\"0\",\"3\"],[\"64456.7\",\"1.56\",\"0\",\"1\"],[\"64456.3\",\"0.01\",\"0\",\"1\"],[\"64456.2\",\"1.56\",\"0\",\"1\"],[\"64456.1\",\"0.01\",\"0\",\"1\"],[\"64456\",\"0.02\",\"0\",\"2\"],[\"64452.5\",\"1.57\",\"0\",\"2\"],[\"64445.7\",\"514.54\",\"0\",\"4\"],[\"64445.2\",\"0.77\",\"0\",\"1\"],[\"64445.1\",\"184.61\",\"0\",\"4\"],[\"64444.5\",\"33.82\",\"0\",\"1\"],[\"64444.1\",\"0.01\",\"0\",\"1\"],[\"64443.8\",\"20.09\",\"0\",\"1\"],[\"64443.5\",\"86.2\",\"0\",\"1\"],[\"64443.1\",\"85.42\",\"0\",\"1\"],[\"64442.2\",\"0.02\",\"0\",\"1\"],[\"64441.9\",\"36.94\",\"0\",\"2\"],[\"64440.2\",\"58.25\",\"0\",\"2\"],[\"64439.4\",\"0.01\",\"0\",\"1\"],[\"64439.2\",\"0.02\",\"0\",\"1\"],[\"64438.9\",\"37.23\",\"0\",\"1\"],[\"64438.2\",\"31.07\",\"0\",\"2\"],[\"64438\",\"0.01\",\"0\",\"1\"],[\"64433.1\",\"15.66\",\"0\",\"2\"],[\"64433\",\"4.07\",\"0\",\"2\"],[\"64406.4\",\"0\",\"0\",\"0\"],[\"64406.3\",\"0\",\"0\",\"0\"],[\"64406.2\",\"0\",\"0\",\"0\"],[\"64406.1\",\"0\",\"0\",\"0\"],[\"64406\",\"0\",\"0\",\"0\"],[\"64405.9\",\"0\",\"0\",\"0\"],[\"64405.7\",\"0\",\"0\",\"0\"],[\"64405.6\",\"0\",\"0\",\"0\"]],\"ts\":\"1782015921105\",\"checksum\":860080037,\"seqId\":325069869082,\"prevSeqId\":325069868973}]}"}
{"action": "update", "capture_sequence": 181, "channel": "books", "connection_sequence": 3, "event": null, "instId": "BTC-USDT-SWAP", "local_receive_ts": "2026-06-21T04:25:21Z", "monotonic_ns": 1643477108555199, "raw": "{\"arg\":{\"channel\":\"books\",\"instId\":\"BTC-USDT-SWAP\"},\"action\":\"update\",\"data\":[{\"asks\":[[\"64458.7\",\"0\",\"0\",\"0\"],[\"64459.1\",\"0.02\",\"0\",\"2\"],[\"64459.2\",\"17.1\",\"0\",\"3\"],[\"64459.8\",\"1.56\",\"0\",\"1\"],[\"64464.3\",\"72.21\",\"0\",\"1\"],[\"64477.6\",\"0.07\",\"0\",\"1\"],[\"64477.9\",\"0.01\",\"0\",\"1\"],[\"64481.1\",\"62.34\",\"0\",\"3\"],[\"64508\",\"0\",\"0\",\"0\"]],\"bids\":[[\"64457.4\",\"0.32\",\"0\",\"2\"],[\"64457.3\",\"1.56\",\"0\",\"1\"],[\"64455.7\",\"0\",\"0\",\"0\"],[\"64452.5\",\"0.01\",\"0\",\"1\"]],\"ts\":\"1782015921205\",\"checksum\":-353033713,\"seqId\":325069869142,\"prevSeqId\":325069869082}]}"}
{"action": "update", "capture_sequence": 182, "channel": "books", "connection_sequence": 3, "event": null, "instId": "BTC-USDT-SWAP", "local_receive_ts": "2026-06-21T04:25:21Z", "monotonic_ns": 1643477208614882, "raw": "{\"arg\":{\"channel\":\"books\",\"instId\":\"BTC-USDT-SWAP\"},\"action\":\"update\",\"data\":[{\"asks\":[[\"64459.2\",\"15.54\",\"0\",\"2\"],[\"64459.8\",\"0\",\"0\",\"0\"],[\"64460\",\"0.02\",\"0\",\"2\"],[\"64460.3\",\"0\",\"0\",\"0\"],[\"64460.8\",\"55.97\",\"0\",\"1\"],[\"64461.3\",\"0\",\"0\",\"0\"],[\"64461.4\",\"1.59\",\"0\",\"4\"],[\"64461.8\",\"0\",\"0\",\"0\"],[\"64461.9\",\"1.71\",\"0\",\"2\"],[\"64462.3\",\"0\",\"0\",\"0\"],[\"64462.4\",\"1.56\",\"0\",\"1\"],[\"64463.7\",\"0\",\"0\",\"0\"],[\"64464.3\",\"73.77\",\"0\",\"2\"],[\"64464.8\",\"1.56\",\"0\",\"1\"],[\"64465.3\",\"1.56\",\"0\",\"1\"],[\"64465.7\",\"77.88\",\"0\",\"4\"],[\"64508\",\"13.54\",\"0\",\"7\"],[\"64508.1\",\"21.31\",\"0\",\"3\"],[\"64508.2\",\"59.01\",\"0\",\"5\"]],\"bids\":[[\"64457.4\",\"0.31\",\"0\",\"1\"],[\"64457.3\",\"0\",\"0\",\"0\"],[\"64457.2\",\"0.01\",\"0\",\"1\"],[\"64457.1\",\"1.56\",\"0\",\"1\"],[\"64456.8\",\"0.32\",\"0\",\"2\"],[\"64456.7\",\"0\",\"0\",\"0\"],[\"64456.6\",\"0.08\",\"0\",\"2\"],[\"64456.5\",\"1.56\",\"0\",\"1\"],[\"64456.3\",\"0\",\"0\",\"0\"],[\"64456.2\",\"0\",\"0\",\"0\"],[\"64456\",\"0.03\",\"0\",\"3\"],[\"64455.9\",\"1.57\",\"0\",\"2\"],[\"64455.6\",\"0\",\"0\",\"0\"],[\"64455.4\",\"1.56\",\"0\",\"1\"],[\"64455.1\",\"0\",\"0\",\"0\"],[\"64454.9\",\"1.56\",\"0\",\"1\"],[\"64406.4\",\"0.12\",\"0\",\"2\"]],\"ts\":\"1782015921305\",\"checksum\":1423577877,\"seqId\":325069869245,\"prevSeqId\":325069869142}]}"}
{"action": "update", "capture_sequence": 183, "channel": "books", "connection_sequence": 3, "event": null, "instId": "BTC-USDT-SWAP", "local_receive_ts": "2026-06-21T04:25:21Z", "monotonic_ns": 1643477308291245, "raw": "{\"arg\":{\"channel\":\"books\",\"instId\":\"BTC-USDT-SWAP\"},\"action\":\"update\",\"data\":[{\"asks\":[[\"64458\",\"484.1\",\"0\",\"56\"],[\"64461.4\",\"0.03\",\"0\",\"3\"],[\"64461.9\",\"0.15\",\"0\",\"1\"],[\"64462.4\",\"0\",\"0\",\"0\"],[\"64462.9\",\"0.01\",\"0\",\"1\"],[\"64466.2\",\"1.56\",\"0\",\"1\"]],\"bids\":[[\"64443\",\"3.22\",\"0\",\"3\"],[\"64436.2\",\"0\",\"0\",\"0\"],[\"64436.1\",\"25.84\",\"0\",\"3\"],[\"64411.6\",\"22.95\",\"0\",\"1\"],[\"64411.5\",\"0.01\",\"0\",\"1\"]],\"ts\":\"1782015921405\",\"checksum\":-1645965656,\"seqId\":325069869261,\"prevSeqId\":325069869245}]}"}
{"action": "update", "capture_sequence": 184, "channel": "books", "connection_sequence": 3, "event": null, "instId": "BTC-USDT-SWAP", "local_receive_ts": "2026-06-21T04:25:21Z", "monotonic_ns": 1643477408324081, "raw": "{\"arg\":{\"channel\":\"books\",\"instId\":\"BTC-USDT-SWAP\"},\"action\":\"update\",\"data\":[{\"asks\":[[\"64458\",\"484.48\",\"0\",\"57\"]],\"bids\":[[\"64457.9\",\"571.05\",\"0\",\"26\"],[\"64457.2\",\"0\",\"0\",\"0\"],[\"64457.1\",\"0\",\"0\",\"0\"],[\"64456.8\",\"0.31\",\"0\",\"1\"],[\"64456.6\",\"0.09\",\"0\",\"3\"],[\"64455.5\",\"0.01\",\"0\",\"1\"],[\"64438.6\",\"43.84\",\"0\",\"5\"],[\"64438.2\",\"0.01\",\"0\",\"1\"],[\"64406.3\",\"0.34\",\"0\",\"3\"]],\"ts\":\"1782015921505\",\"checksum\":939875259,\"seqId\":325069869286,\"prevSeqId\":325069869261}]}"}
{"action": "update", "capture_sequence": 185, "channel": "books", "connection_sequence": 3, "event": null, "instId": "BTC-USDT-SWAP", "local_receive_ts": "2026-06-21T04:25:21Z", "monotonic_ns": 1643477515886781, "raw": "{\"arg\":{\"channel\":\"books\",\"instId\":\"BTC-USDT-SWAP\"},\"action\":\"update\",\"data\":[{\"asks\":[[\"64458\",\"404.47\",\"0\",\"55\"],[\"64458.3\",\"6.61\",\"0\",\"4\"],[\"64459.1\",\"0\",\"0\",\"0\"],[\"64459.2\",\"0.01\",\"0\",\"1\"],[\"64459.6\",\"0.61\",\"0\",\"2\"],[\"64459.7\",\"15.53\",\"0\",\"1\"],[\"64460\",\"0.01\",\"0\",\"1\"],[\"64461.6\",\"0.01\",\"0\",\"1\"],[\"64463.4\",\"0\",\"0\",\"0\"],[\"64465.7\",\"66.46\",\"0\",\"3\"],[\"64467.1\",\"0\",\"0\",\"0\"],[\"64467.8\",\"91.82\",\"0\",\"3\"],[\"64467.9\",\"11.24\",\"0\",\"3\"],[\"64468.8\",\"66.01\",\"0\",\"6\"],[\"64475.6\",\"0.39\",\"0\",\"2\"],[\"64476.1\",\"31.04\",\"0\",\"1\"],[\"64484.2\",\"15.65\",\"0\",\"1\"],[\"64484.5\",\"1.14\",\"0\",\"5\"],[\"64488.2\",\"3.96\",\"0\",\"2\"],[\"64489.3\",\"81.46\",\"0\",\"7\"],[\"64494.6\",\"5.04\",\"0\",\"4\"],[\"64494.7\",\"44.62\",\"0\",\"7\"]],\"bids\":[[\"64457.9\",\"643.54\",\"0\",\"27\"],[\"64454\",\"8.32\",\"0\",\"3\"],[\"64453.7\",\"0\",\"0\",\"0\"],[\"64451.9\",\"77.88\",\"0\",\"2\"],[\"64451.8\",\"0.01\",\"0\",\"1\"],[\"64451.6\",\"0.01\",\"0\",\"1\"],[\"64451.1\",\"0\",\"0\",\"0\"],[\"64445.7\",\"515.31\",\"0\",\"5\"],[\"64445.2\",\"0\",\"0\",\"0\"],[\"64443.4\",\"403.7\",\"0\",\"3\"],[\"64443.3\",\"130.09\",\"0\",\"2\"],[\"64443\",\"3.24\",\"0\",\"4\"],[\"64442.2\",\"0\",\"0\",\"0\"],[\"64441.5\",\"119.55\",\"0\",\"4\"],[\"64440.2\",\"0.01\",\"0\",\"1\"],[\"64439.8\",\"0.02\",\"0\",\"1\"],[\"64439.2\",\"0\",\"0\",\"0\"],[\"64438.8\",\"31.06\",\"0\",\"1\"],[\"64438.6\",\"12.78\",\"0\",\"4\"],[\"64433.3\",\"17.98\",\"0\",\"5\"],[\"64433.1\",\"15.65\",\"0\",\"1\"],[\"64406.2\",\"0.01\",\"0\",\"1\"],[\"64406.1\",\"0.02\",\"0\",\"2\"]],\"ts\":\"1782015921605\",\"checksum\":1272732457,\"seqId\":325069869407,\"prevSeqId\":325069869286}]}"}
{"action": null, "capture_sequence": 186, "channel": "trades", "connection_sequence": 3, "event": null, "instId": "BTC-USDT-SWAP", "local_receive_ts": "2026-06-21T04:25:21Z", "monotonic_ns": 1643477572061603, "raw": "{\"arg\":{\"channel\":\"trades\",\"instId\":\"BTC-USDT-SWAP\"},\"data\":[{\"instId\":\"BTC-USDT-SWAP\",\"tradeId\":\"2718748875\",\"px\":\"64457.9\",\"sz\":\"5\",\"side\":\"sell\",\"ts\":\"1782015921669\",\"count\":\"1\",\"source\":\"0\",\"seqId\":325069869460}]}"}
{"action": null, "capture_sequence": 187, "channel": "trades", "connection_sequence": 3, "event": null, "instId": "BTC-USDT-SWAP", "local_receive_ts": "2026-06-21T04:25:21Z", "monotonic_ns": 1643477606124601, "raw": "{\"arg\":{\"channel\":\"trades\",\"instId\":\"BTC-USDT-SWAP\"},\"data\":[{\"instId\":\"BTC-USDT-SWAP\",\"tradeId\":\"2718748876\",\"px\":\"64458\",\"sz\":\"1.9\",\"side\":\"buy\",\"ts\":\"1782015921702\",\"count\":\"1\",\"source\":\"0\",\"seqId\":325069869540}]}"}
{"action": "update", "capture_sequence": 188, "channel": "books", "connection_sequence": 3, "event": null, "instId": "BTC-USDT-SWAP", "local_receive_ts": "2026-06-21T04:25:21Z", "monotonic_ns": 1643477616516737, "raw": "{\"arg\":{\"channel\":\"books\",\"instId\":\"BTC-USDT-SWAP\"},\"action\":\"update\",\"data\":[{\"asks\":[[\"64458\",\"500.1\",\"0\",\"57\"],[\"64458.3\",\"46.19\",\"0\",\"3\"],[\"64459.1\",\"15.53\",\"0\",\"1\"],[\"64459.7\",\"0\",\"0\",\"0\"],[\"64459.9\",\"0.01\",\"0\",\"1\"],[\"64460\",\"150.01\",\"0\",\"2\"],[\"64461.7\",\"0\",\"0\",\"0\"],[\"64463.8\",\"0.01\",\"0\",\"1\"],[\"64463.9\",\"31.05\",\"0\",\"1\"],[\"64464\",\"119.81\",\"0\",\"4\"],[\"64464.1\",\"0.8\",\"0\",\"4\"],[\"64464.3\",\"72.21\",\"0\",\"1\"],[\"64464.6\",\"11.23\",\"0\",\"2\"],[\"64473.5\",\"0\",\"0\",\"0\"],[\"64473.6\",\"68.29\",\"0\",\"4\"],[\"64475.5\",\"31.04\",\"0\",\"1\"],[\"64476.1\",\"0\",\"0\",\"0\"],[\"64476.2\",\"0.02\",\"0\",\"2\"],[\"64476.7\",\"232.86\",\"0\",\"1\"],[\"64477.9\",\"0\",\"0\",\"0\"],[\"64479.7\",\"0.01\",\"0\",\"1\"],[\"64480.1\",\"0.01\",\"0\",\"1\"],[\"64481.1\",\"62.35\",\"0\",\"4\"],[\"64482.6\",\"33.81\",\"0\",\"2\"],[\"64483.3\",\"0.05\",\"0\",\"2\"],[\"64483.5\",\"0.01\",\"0\",\"1\"],[\"64483.8\",\"0\",\"0\",\"0\"],[\"64484.3\",\"0.77\",\"0\",\"1\"],[\"64484.4\",\"16.56\",\"0\",\"3\"],[\"64484.5\",\"0.06\",\"0\",\"3\"],[\"64487.4\",\"58.69\",\"0\",\"6\"],[\"64487.9\",\"85.38\",\"0\",\"2\"],[\"64488.6\",\"0.02\",\"0\",\"2\"],[\"64489.3\",\"23.26\",\"0\",\"6\"],[\"64493.6\",\"168.93\",\"0\",\"2\"],[\"64494.7\",\"24.55\",\"0\",\"6\"],[\"64508.2\",\"0\",\"0\",\"0\"]],\"bids\":[[\"64457.9\",\"566.47\",\"0\",\"26\"],[\"64456.6\",\"0.08\",\"0\",\"2\"],[\"64456.5\",\"0\",\"0\",\"0\"],[\"64456\",\"0.02\",\"0\",\"2\"],[\"64455.9\",\"0.01\",\"0\",\"1\"],[\"64455.5\",\"0\",\"0\",\"0\"],[\"64455.4\",\"0.01\",\"0\",\"1\"],[\"64455.3\",\"48.68\",\"0\",\"3\"],[\"64454.9\",\"0\",\"0\",\"0\"],[\"64454.8\",\"0.02\",\"0\",\"2\"],[\"64454.4\",\"0.02\",\"0\",\"2\"],[\"64454\",\"8.01\",\"0\",\"2\"],[\"64453.9\",\"0.01\",\"0\",\"1\"],[\"64453.6\",\"0.32\",\"0\",\"2\"],[\"64453.4\",\"0\",\"0\",\"0\"],[\"64451.9\",\"0\",\"0\",\"0\"],[\"64451.8\",\"0.32\",\"0\",\"2\"],[\"64451.6\",\"77.57\",\"0\",\"1\"],[\"64451.1\",\"0.01\",\"0\",\"1\"],[\"64445.7\",\"514.54\",\"0\",\"4\"],[\"64445.2\",\"0.77\",\"0\",\"1\"],[\"64444.5\",\"0\",\"0\",\"0\"],[\"64443.8\",\"0\",\"0\",\"0\"],[\"64443.6\",\"33.83\",\"0\",\"2\"],[\"64443.4\",\"403.67\",\"0\",\"1\"],[\"64443.3\",\"130.12\",\"0\",\"4\"],[\"64443.2\",\"155.75\",\"0\",\"6\"],[\"64443.1\",\"0\",\"0\",\"0\"],[\"64443\",\"0.02\",\"0\",\"2\"],[\"64442.4\",\"85.44\",\"0\",\"2\"],[\"64442\",\"77.65\",\"0\",\"5\"],[\"64441.5\",\"61.31\",\"0\",\"3\"],[\"64439.8\",\"0\",\"0\",\"0\"],[\"64439.2\",\"0.02\",\"0\",\"1\"],[\"64439\",\"58.26\",\"0\",\"2\"],[\"64438.8\",\"0\",\"0\",\"0\"],[\"64438.2\",\"31.07\",\"0\",\"2\"],[\"64436.1\",\"25.65\",\"0\",\"2\"],[\"64433.3\",\"17.97\",\"0\",\"4\"],[\"64433.1\",\"15.66\",\"0\",\"2\"],[\"64406\",\"0.02\",\"0\",\"2\"],[\"64405.9\",\"1.93\",\"0\",\"1\"],[\"64405.7\",\"15.87\",\"0\",\"2\"],[\"64405.6\",\"0.02\",\"0\",\"2\"],[\"64405.5\",\"0.01\",\"0\",\"1\"],[\"64405.3\",\"46.54\",\"0\",\"1\"],[\"64405.2\",\"6.39\",\"0\",\"4\"]],\"ts\":\"1782015921705\",\"checksum\":-199752191,\"seqId\":325069869540,\"prevSeqId\":325069869407}]}"}
{"action": "update", "capture_sequence": 189, "channel": "books", "connection_sequence": 3, "event": null, "instId": "BTC-USDT-SWAP", "local_receive_ts": "2026-06-21T04:25:21Z", "monotonic_ns": 1643477708480068, "raw": "{\"arg\":{\"channel\":\"books\",\"instId\":\"BTC-USDT-SWAP\"},\"action\":\"update\",\"data\":[{\"asks\":[[\"64459\",\"0.01\",\"0\",\"1\"],[\"64459.9\",\"0\",\"0\",\"0\"],[\"64460.8\",\"6.77\",\"0\",\"1\"],[\"64463.9\",\"0\",\"0\",\"0\"],[\"64464\",\"0.79\",\"0\",\"3\"],[\"64464.1\",\"31.85\",\"0\",\"5\"],[\"64467.1\",\"0.02\",\"0\",\"1\"],[\"64467.8\",\"91.8\",\"0\",\"2\"],[\"64476.2\",\"0.18\",\"0\",\"3\"],[\"64477.9\",\"0.01\",\"0\",\"1\"],[\"64479.7\",\"0\",\"0\",\"0\"],[\"64480.1\",\"0.02\",\"0\",\"2\"],[\"64481.1\",\"62.34\",\"0\",\"3\"],[\"64483.3\",\"0.06\",\"0\",\"3\"],[\"64483.5\",\"0\",\"0\",\"0\"],[\"64487.3\",\"85.41\",\"0\",\"3\"],[\"64487.9\",\"0.01\",\"0\",\"1\"],[\"64492.5\",\"86.2\",\"0\",\"5\"],[\"64493.1\",\"31.76\",\"0\",\"5\"],[\"64508.2\",\"59.01\",\"0\",\"5\"]],\"bids\":[[\"64456.6\",\"0.07\",\"0\",\"1\"],[\"64455.4\",\"0.02\",\"0\",\"2\"],[\"64454.6\",\"46.54\",\"0\",\"1\"],[\"64443.5\",\"0\",\"0\",\"0\"],[\"64442.9\",\"3.2\",\"0\",\"1\"],[\"64442.5\",\"86.2\",\"0\",\"1\"],[\"64442.4\",\"0.01\",\"0\",\"1\"],[\"64442\",\"77.63\",\"0\",\"4\"],[\"64441.9\",\"36.96\",\"0\",\"3\"],[\"64441.7\",\"85.43\",\"0\",\"1\"],[\"64436.1\",\"25.84\",\"0\",\"3\"],[\"64436\",\"1.01\",\"0\",\"2\"],[\"64433.1\",\"15.65\",\"0\",\"1\"],[\"64433\",\"4.08\",\"0\",\"3\"],[\"64405.3\",\"0\",\"0\",\"0\"],[\"64405.2\",\"0\",\"0\",\"0\"]],\"ts\":\"1782015921805\",\"checksum\":-1054186787,\"seqId\":325069869595,\"prevSeqId\":325069869540}]}"}
{"action": "update", "capture_sequence": 190, "channel": "books", "connection_sequence": 3, "event": null, "instId": "BTC-USDT-SWAP", "local_receive_ts": "2026-06-21T04:25:22Z", "monotonic_ns": 1643477809174999, "raw": "{\"arg\":{\"channel\":\"books\",\"instId\":\"BTC-USDT-SWAP\"},\"action\":\"update\",\"data\":[{\"asks\":[[\"64483.8\",\"0.77\",\"0\",\"1\"],[\"64484.3\",\"0\",\"0\",\"0\"],[\"64493\",\"33.79\",\"0\",\"5\"],[\"64493.6\",\"148.86\",\"0\",\"1\"]],\"bids\":[[\"64445.2\",\"0\",\"0\",\"0\"],[\"64444.5\",\"0.77\",\"0\",\"1\"],[\"64443.2\",\"135.66\",\"0\",\"5\"],[\"64442.6\",\"35.74\",\"0\",\"2\"],[\"64433\",\"4.07\",\"0\",\"2\"],[\"64431.6\",\"496.54\",\"0\",\"2\"],[\"64415.9\",\"0\",\"0\",\"0\"],[\"64415.2\",\"0.02\",\"0\",\"2\"],[\"64408.5\",\"0\",\"0\",\"0\"],[\"64405.3\",\"46.54\",\"0\",\"1\"],[\"64405.2\",\"6.39\",\"0\",\"4\"]],\"ts\":\"1782015921905\",\"checksum\":-1054186787,\"seqId\":325069869614,\"prevSeqId\":325069869595}]}"}
{"action": "update", "capture_sequence": 191, "channel": "books", "connection_sequence": 3, "event": null, "instId": "BTC-USDT-SWAP", "local_receive_ts": "2026-06-21T04:25:22Z", "monotonic_ns": 1643477916244336, "raw": "{\"arg\":{\"channel\":\"books\",\"instId\":\"BTC-USDT-SWAP\"},\"action\":\"update\",\"data\":[{\"asks\":[[\"64459.8\",\"1.56\",\"0\",\"1\"],[\"64460.3\",\"1.56\",\"0\",\"1\"],[\"64460.7\",\"1.57\",\"0\",\"2\"],[\"64461.2\",\"1.58\",\"0\",\"2\"],[\"64473.5\",\"15.52\",\"0\",\"1\"],[\"64473.6\",\"52.77\",\"0\",\"3\"],[\"64481.7\",\"33.8\",\"0\",\"1\"],[\"64482.6\",\"0.01\",\"0\",\"1\"],[\"64484.3\",\"0.31\",\"0\",\"1\"],[\"64484.4\",\"16.25\",\"0\",\"2\"],[\"64486.2\",\"58.37\",\"0\",\"7\"],[\"64486.5\",\"101.02\",\"0\",\"2\"],[\"64487.3\",\"0.04\",\"0\",\"2\"],[\"64487.4\",\"0.49\",\"0\",\"5\"],[\"64492.7\",\"119.95\",\"0\",\"4\"],[\"64493\",\"13.72\",\"0\",\"4\"],[\"64507.8\",\"0\",\"0\",\"0\"],[\"64507.9\",\"0\",\"0\",\"0\"],[\"64508\",\"0\",\"0\",\"0\"],[\"64508.1\",\"0\",\"0\",\"0\"],[\"64508.2\",\"0\",\"0\",\"0\"]],\"bids\":[[\"64457.9\",\"568.03\",\"0\",\"27\"],[\"64457.4\",\"1.87\",\"0\",\"2\"],[\"64456.9\",\"1.56\",\"0\",\"1\"],[\"64456.4\",\"1.57\",\"0\",\"2\"],[\"64455.9\",\"1.57\",\"0\",\"2\"],[\"64455.5\",\"1.56\",\"0\",\"1\"],[\"64455\",\"1.57\",\"0\",\"2\"],[\"64451.8\",\"77.58\",\"0\",\"2\"],[\"64451.6\",\"0.31\",\"0\",\"1\"],[\"64443.6\",\"0.01\",\"0\",\"1\"],[\"64442.7\",\"33.83\",\"0\",\"1\"],[\"64442.6\",\"15.65\",\"0\",\"1\"],[\"64442.5\",\"0\",\"0\",\"0\"],[\"64442.2\",\"20.09\",\"0\",\"1\"],[\"64442.1\",\"92.42\",\"0\",\"2\"],[\"64441.7\",\"0\",\"0\",\"0\"],[\"64441.2\",\"85.43\",\"0\",\"1\"],[\"64439\",\"0.01\",\"0\",\"1\"],[\"64438.3\",\"58.26\",\"0\",\"2\"],[\"64436\",\"201.01\",\"0\",\"3\"],[\"64419.2\",\"47.09\",\"0\",\"4\"],[\"64408.5\",\"0.38\",\"0\",\"1\"],[\"64405.6\",\"0\",\"0\",\"0\"],[\"64405.5\",\"0\",\"0\",\"0\"],[\"64405.3\",\"0\",\"0\",\"0\"],[\"64405.2\",\"0\",\"0\",\"0\"]],\"ts\":\"1782015922005\",\"checksum\":1543033802,\"seqId\":325069869680,\"prevSeqId\":325069869614}]}"}
{"action": null, "capture_sequence": 192, "channel": "trades", "connection_sequence": 3, "event": null, "instId": "BTC-USDT-SWAP", "local_receive_ts": "2026-06-21T04:25:22Z", "monotonic_ns": 1643477955800084, "raw": "{\"arg\":{\"channel\":\"trades\",\"instId\":\"BTC-USDT-SWAP\"},\"data\":[{\"instId\":\"BTC-USDT-SWAP\",\"tradeId\":\"2718748877\",\"px\":\"64457.9\",\"sz\":\"5\",\"side\":\"sell\",\"ts\":\"1782015922053\",\"count\":\"1\",\"source\":\"0\",\"seqId\":325069869764}]}"}
{"action": "update", "capture_sequence": 193, "channel": "books", "connection_sequence": 3, "event": null, "instId": "BTC-USDT-SWAP", "local_receive_ts": "2026-06-21T04:25:22Z", "monotonic_ns": 1643478016663272, "raw": "{\"arg\":{\"channel\":\"books\",\"instId\":\"BTC-USDT-SWAP\"},\"action\":\"update\",\"data\":[{\"asks\":[[\"64459\",\"0.02\",\"0\",\"2\"],[\"64459.6\",\"0.6\",\"0\",\"1\"],[\"64459.7\",\"0.01\",\"0\",\"1\"],[\"64459.8\",\"0\",\"0\",\"0\"],[\"64459.9\",\"1.56\",\"0\",\"1\"],[\"64460.3\",\"0\",\"0\",\"0\"],[\"64460.7\",\"0.01\",\"0\",\"1\"],[\"64461.6\",\"0\",\"0\",\"0\"],[\"64461.7\",\"1.56\",\"0\",\"1\"],[\"64462.2\",\"1.56\",\"0\",\"1\"],[\"64462.6\",\"1.57\",\"0\",\"2\"],[\"64463.1\",\"7.78\",\"0\",\"3\"],[\"64477.6\",\"0.08\",\"0\",\"2\"],[\"64477.9\",\"0\",\"0\",\"0\"],[\"64481.7\",\"0\",\"0\",\"0\"],[\"64482.6\",\"33.81\",\"0\",\"2\"],[\"64486.5\",\"15.65\",\"0\",\"1\"],[\"64487.4\",\"85.86\",\"0\",\"6\"],[\"64492.7\",\"99.88\",\"0\",\"3\"],[\"64493\",\"33.79\",\"0\",\"5\"],[\"64507.8\",\"2.83\",\"0\",\"3\"]],\"bids\":[[\"64457.9\",\"563.03\",\"0\",\"27\"],[\"64457.5\",\"0.01\",\"0\",\"1\"],[\"64457\",\"0.02\",\"0\",\"2\"],[\"64456.5\",\"0.01\",\"0\",\"1\"],[\"64455.4\",\"0.01\",\"0\",\"1\"],[\"64455.3\",\"48.67\",\"0\",\"2\"],[\"64454.8\",\"0.01\",\"0\",\"1\"],[\"64454.5\",\"1.56\",\"0\",\"1\"],[\"64453.7\",\"0.31\",\"0\",\"1\"],[\"64453.6\",\"0.01\",\"0\",\"1\"],[\"64451.7\",\"303.67\",\"0\",\"6\"],[\"64451.6\",\"0\",\"0\",\"0\"],[\"64443\",\"33.85\",\"0\",\"3\"],[\"64442.7\",\"0\",\"0\",\"0\"],[\"64442.4\",\"20.1\",\"0\",\"2\"],[\"64442.2\",\"0\",\"0\",\"0\"],[\"64441.9\",\"36.94\",\"0\",\"2\"],[\"64441.8\",\"535.37\",\"0\",\"3\"],[\"64441.7\",\"85.43\",\"0\",\"1\"],[\"64441.2\",\"0\",\"0\",\"0\"],[\"64439.2\",\"0\",\"0\",\"0\"],[\"64438.8\",\"0.02\",\"0\",\"1\"],[\"64438.3\",\"31.07\",\"0\",\"2\"],[\"64438.2\",\"58.26\",\"0\",\"2\"],[\"64432.9\",\"0.01\",\"0\",\"1\"],[\"64431.6\",\"496.53\",\"0\",\"1\"],[\"64415.9\",\"0.01\",\"0\",\"1\"],[\"64415.2\",\"0.01\",\"0\",\"1\"],[\"64406\",\"0\",\"0\",\"0\"],[\"64405.9\",\"0\",\"0\",\"0\"],[\"64405.7\",\"0\",\"0\",\"0\"]],\"ts\":\"1782015922105\",\"checksum\":933336781,\"seqId\":325069869789,\"prevSeqId\":325069869680}]}"}
{"action": "update", "capture_sequence": 194, "channel": "books", "connection_sequence": 3, "event": null, "instId": "BTC-USDT-SWAP", "local_receive_ts": "2026-06-21T04:25:22Z", "monotonic_ns": 1643478108571606, "raw": "{\"arg\":{\"channel\":\"books\",\"instId\":\"BTC-USDT-SWAP\"},\"action\":\"update\",\"data\":[{\"asks\":[[\"64459.3\",\"2.59\",\"0\",\"5\"],[\"64459.8\",\"1.56\",\"0\",\"1\"],[\"64459.9\",\"0\",\"0\",\"0\"],[\"64460.3\",\"1.56\",\"0\",\"1\"],[\"64463.6\",\"16.01\",\"0\",\"2\"],[\"64465.3\",\"0\",\"0\",\"0\"],[\"64465.7\",\"64.9\",\"0\",\"2\"],[\"64466.2\",\"0\",\"0\",\"0\"],[\"64486.2\",\"0.17\",\"0\",\"6\"],[\"64486.5\",\"73.85\",\"0\",\"2\"],[\"64493\",\"13.72\",\"0\",\"4\"],[\"64493.3\",\"600.4\",\"0\",\"7\"],[\"64507.9\",\"0.25\",\"0\",\"2\"]],\"bids\":[[\"64457.9\",\"563.04\",\"0\",\"27\"],[\"64457.5\",\"0\",\"0\",\"0\"],[\"64457.4\",\"0.31\",\"0\",\"1\"],[\"64457\",\"0.01\",\"0\",\"1\"],[\"64456.9\",\"0\",\"0\",\"0\"],[\"64456\",\"0.03\",\"0\",\"3\"],[\"64455.6\",\"0.01\",\"0\",\"1\"],[\"64454\",\"9.57\",\"0\",\"3\"],[\"64453.5\",\"1.57\",\"0\",\"2\"],[\"64443.3\",\"216.32\",\"0\",\"5\"],[\"64442.9\",\"23.29\",\"0\",\"2\"],[\"64442.4\",\"0.01\",\"0\",\"1\"],[\"64442.1\",\"6.22\",\"0\",\"1\"],[\"64438.7\",\"62.24\",\"0\",\"2\"],[\"64438.2\",\"0.01\",\"0\",\"1\"],[\"64432.9\",\"0\",\"0\",\"0\"],[\"64432.5\",\"0.02\",\"0\",\"2\"],[\"64406\",\"0.02\",\"0\",\"2\"],[\"64405.9\",\"1.93\",\"0\",\"1\"]],\"ts\":\"1782015922205\",\"checksum\":650108988,\"seqId\":325069869864,\"prevSeqId\":325069869789}]}"}
{"action": null, "capture_sequence": 195, "channel": "trades", "connection_sequence": 3, "event": null, "instId": "BTC-USDT-SWAP", "local_receive_ts": "2026-06-21T04:25:22Z", "monotonic_ns": 1643478184692948, "raw": "{\"arg\":{\"channel\":\"trades\",\"instId\":\"BTC-USDT-SWAP\"},\"data\":[{\"instId\":\"BTC-USDT-SWAP\",\"tradeId\":\"2718748878\",\"px\":\"64457.9\",\"sz\":\"1.96\",\"side\":\"sell\",\"ts\":\"1782015922281\",\"count\":\"1\",\"source\":\"0\",\"seqId\":325069869978}]}"}
{"action": "update", "capture_sequence": 196, "channel": "books", "connection_sequence": 3, "event": null, "instId": "BTC-USDT-SWAP", "local_receive_ts": "2026-06-21T04:25:22Z", "monotonic_ns": 1643478209193118, "raw": "{\"arg\":{\"channel\":\"books\",\"instId\":\"BTC-USDT-SWAP\"},\"action\":\"update\",\"data\":[{\"asks\":[[\"64458\",\"500.2\",\"0\",\"58\"],[\"64458.3\",\"46.2\",\"0\",\"4\"],[\"64458.4\",\"1.57\",\"0\",\"2\"],[\"64459\",\"0.01\",\"0\",\"1\"],[\"64459.3\",\"1.03\",\"0\",\"4\"],[\"64459.6\",\"2.16\",\"0\",\"2\"],[\"64459.7\",\"0\",\"0\",\"0\"],[\"64459.8\",\"0\",\"0\",\"0\"],[\"64459.9\",\"0.01\",\"0\",\"1\"],[\"64460.1\",\"1.58\",\"0\",\"3\"],[\"64460.3\",\"0\",\"0\",\"0\"],[\"64460.6\",\"1.56\",\"0\",\"1\"],[\"64464.8\",\"0\",\"0\",\"0\"],[\"64486.5\",\"15.65\",\"0\",\"1\"],[\"64487.3\",\"58.24\",\"0\",\"3\"],[\"64493.3\",\"580.33\",\"0\",\"6\"],[\"64493.5\",\"21.16\",\"0\",\"5\"],[\"64508\",\"13.54\",\"0\",\"7\"],[\"64508.1\",\"21.31\",\"0\",\"3\"]],\"bids\":[[\"64457.9\",\"559.52\",\"0\",\"26\"],[\"64456.5\",\"0\",\"0\",\"0\"],[\"64455.4\",\"0.02\",\"0\",\"2\"],[\"64454.6\",\"57.76\",\"0\",\"2\"],[\"64453.9\",\"0.32\",\"0\",\"2\"],[\"64453.7\",\"0\",\"0\",\"0\"],[\"64452.5\",\"1.57\",\"0\",\"2\"],[\"64451.7\",\"303.36\",\"0\",\"5\"],[\"64451.6\",\"0.31\",\"0\",\"1\"],[\"64443.5\",\"120.02\",\"0\",\"2\"],[\"64443.3\",\"130.12\",\"0\",\"4\"],[\"64443\",\"20.11\",\"0\",\"3\"],[\"64442.9\",\"3.2\",\"0\",\"1\"],[\"64442.1\",\"91.65\",\"0\",\"2\"],[\"64441.7\",\"0\",\"0\",\"0\"],[\"64439\",\"58.26\",\"0\",\"2\"],[\"64438.7\",\"3.99\",\"0\",\"1\"],[\"64405.7\",\"4.65\",\"0\",\"1\"]],\"ts\":\"1782015922305\",\"checksum\":-194012742,\"seqId\":325069869997,\"prevSeqId\":325069869864}]}"}
{"action": null, "capture_sequence": 197, "channel": "trades", "connection_sequence": 3, "event": null, "instId": "BTC-USDT-SWAP", "local_receive_ts": "2026-06-21T04:25:22Z", "monotonic_ns": 1643478297482248, "raw": "{\"arg\":{\"channel\":\"trades\",\"instId\":\"BTC-USDT-SWAP\"},\"data\":[{\"instId\":\"BTC-USDT-SWAP\",\"tradeId\":\"2718748879\",\"px\":\"64457.9\",\"sz\":\"5\",\"side\":\"sell\",\"ts\":\"1782015922394\",\"count\":\"1\",\"source\":\"0\",\"seqId\":325069870052}]}"}
{"action": "update", "capture_sequence": 198, "channel": "books", "connection_sequence": 3, "event": null, "instId": "BTC-USDT-SWAP", "local_receive_ts": "2026-06-21T04:25:22Z", "monotonic_ns": 1643478310321576, "raw": "{\"arg\":{\"channel\":\"books\",\"instId\":\"BTC-USDT-SWAP\"},\"action\":\"update\",\"data\":[{\"asks\":[[\"64458\",\"501.76\",\"0\",\"59\"],[\"64458.3\",\"46.19\",\"0\",\"3\"],[\"64458.4\",\"0.01\",\"0\",\"1\"],[\"64458.6\",\"0.01\",\"0\",\"1\"],[\"64458.7\",\"1.56\",\"0\",\"1\"],[\"64459.2\",\"1.57\",\"0\",\"2\"],[\"64459.6\",\"0.6\",\"0\",\"1\"],[\"64463.6\",\"14.45\",\"0\",\"1\"],[\"64508\",\"0\",\"0\",\"0\"],[\"64508.1\",\"0\",\"0\",\"0\"]],\"bids\":[[\"64457.9\",\"554.52\",\"0\",\"26\"],[\"64457.7\",\"0.01\",\"0\",\"1\"],[\"64457.1\",\"0.01\",\"0\",\"1\"],[\"64456.5\",\"0.01\",\"0\",\"1\"],[\"64456.4\",\"0.01\",\"0\",\"1\"],[\"64456\",\"0.02\",\"0\",\"2\"],[\"64455.6\",\"0\",\"0\",\"0\"],[\"64455.4\",\"0.01\",\"0\",\"1\"],[\"64442.9\",\"3.12\",\"0\",\"1\"],[\"64436.1\",\"25.85\",\"0\",\"3\"],[\"64405.9\",\"0\",\"0\",\"0\"],[\"64405.7\",\"0\",\"0\",\"0\"]],\"ts\":\"1782015922405\",\"checksum\":-1040479568,\"seqId\":325069870059,\"prevSeqId\":325069869997}]}"}
{"action": "update", "capture_sequence": 199, "channel": "books", "connection_sequence": 3, "event": null, "instId": "BTC-USDT-SWAP", "local_receive_ts": "2026-06-21T04:25:22Z", "monotonic_ns": 1643478408316833, "raw": "{\"arg\":{\"channel\":\"books\",\"instId\":\"BTC-USDT-SWAP\"},\"action\":\"update\",\"data\":[{\"asks\":[],\"bids\":[[\"64457.7\",\"0\",\"0\",\"0\"],[\"64457.1\",\"0\",\"0\",\"0\"],[\"64456.4\",\"1.57\",\"0\",\"2\"],[\"64456\",\"0.03\",\"0\",\"3\"],[\"64455.6\",\"0.01\",\"0\",\"1\"],[\"64405.9\",\"1.93\",\"0\",\"1\"]],\"ts\":\"1782015922505\",\"checksum\":1591107751,\"seqId\":325069870075,\"prevSeqId\":325069870059}]}"}
{"action": "update", "capture_sequence": 200, "channel": "books", "connection_sequence": 3, "event": null, "instId": "BTC-USDT-SWAP", "local_receive_ts": "2026-06-21T04:25:22Z", "monotonic_ns": 1643478509612742, "raw": "{\"arg\":{\"channel\":\"books\",\"instId\":\"BTC-USDT-SWAP\"},\"action\":\"update\",\"data\":[{\"asks\":[[\"64458\",\"500.2\",\"0\",\"58\"],[\"64458.6\",\"0\",\"0\",\"0\"],[\"64458.7\",\"0\",\"0\",\"0\"],[\"64459\",\"0.02\",\"0\",\"2\"],[\"64508\",\"13.54\",\"0\",\"7\"],[\"64508.1\",\"21.31\",\"0\",\"3\"]],\"bids\":[[\"64456.5\",\"0\",\"0\",\"0\"],[\"64456.4\",\"0.01\",\"0\",\"1\"],[\"64456\",\"0.02\",\"0\",\"2\"],[\"64455.9\",\"0.01\",\"0\",\"1\"],[\"64455.4\",\"0.02\",\"0\",\"2\"],[\"64455.3\",\"48.68\",\"0\",\"3\"],[\"64405.7\",\"15.87\",\"0\",\"2\"]],\"ts\":\"1782015922605\",\"checksum\":-1578183373,\"seqId\":325069870099,\"prevSeqId\":325069870075}]}"}
{"action": "update", "capture_sequence": 201, "channel": "books", "connection_sequence": 3, "event": null, "instId": "BTC-USDT-SWAP", "local_receive_ts": "2026-06-21T04:25:22Z", "monotonic_ns": 1643478608783795, "raw": "{\"arg\":{\"channel\":\"books\",\"instId\":\"BTC-USDT-SWAP\"},\"action\":\"update\",\"data\":[{\"asks\":[[\"64458.7\",\"0.02\",\"0\",\"2\"],[\"64458.8\",\"15.53\",\"0\",\"1\"],[\"64459\",\"0\",\"0\",\"0\"],[\"64459.1\",\"0\",\"0\",\"0\"],[\"64459.2\",\"0.01\",\"0\",\"1\"],[\"64473.5\",\"0\",\"0\",\"0\"],[\"64473.6\",\"68.29\",\"0\",\"4\"],[\"64475.5\",\"0\",\"0\",\"0\"],[\"64476.1\",\"31.04\",\"0\",\"1\"],[\"64476.7\",\"0\",\"0\",\"0\"],[\"64476.9\",\"232.88\",\"0\",\"3\"],[\"64477.6\",\"0.07\",\"0\",\"1\"],[\"64477.9\",\"0.01\",\"0\",\"1\"],[\"64486.4\",\"59.47\",\"0\",\"3\"],[\"64487.2\",\"85.4\",\"0\",\"3\"],[\"64487.3\",\"0.04\",\"0\",\"2\"],[\"64487.4\",\"0.49\",\"0\",\"5\"],[\"64493.2\",\"419.89\",\"0\",\"9\"],[\"64493.5\",\"1.09\",\"0\",\"4\"],[\"64508.2\",\"59.01\",\"0\",\"5\"]],\"bids\":[[\"64457.9\",\"555.06\",\"0\",\"27\"],[\"64454.6\",\"46.54\",\"0\",\"1\"],[\"64453.9\",\"0.01\",\"0\",\"1\"],[\"64453.7\",\"0.31\",\"0\",\"1\"],[\"64443.5\",\"0\",\"0\",\"0\"],[\"64443.4\",\"437.49\",\"0\",\"2\"],[\"64443\",\"0.02\",\"0\",\"2\"],[\"64442.7\",\"20.09\",\"0\",\"1\"],[\"64442.2\",\"86.2\",\"0\",\"1\"],[\"64442.1\",\"6.22\",\"0\",\"1\"],[\"64441.7\",\"85.43\",\"0\",\"1\"],[\"64439\",\"31.07\",\"0\",\"2\"],[\"64438.9\",\"37.25\",\"0\",\"2\"],[\"64438.8\",\"0\",\"0\",\"0\"],[\"64438.6\",\"71.03\",\"0\",\"5\"],[\"64438.3\",\"0.01\",\"0\",\"1\"],[\"64438\",\"233.01\",\"0\",\"2\"],[\"64437.4\",\"0\",\"0\",\"0\"],[\"64405.7\",\"0\",\"0\",\"0\"]],\"ts\":\"1782015922705\",\"checksum\":836050354,\"seqId\":325069870158,\"prevSeqId\":325069870099}]}"}
{"action": "update", "capture_sequence": 202, "channel": "books", "connection_sequence": 3, "event": null, "instId": "BTC-USDT-SWAP", "local_receive_ts": "2026-06-21T04:25:22Z", "monotonic_ns": 1643478708733869, "raw": "{\"arg\":{\"channel\":\"books\",\"instId\":\"BTC-USDT-SWAP\"},\"action\":\"update\",\"data\":[{\"asks\":[[\"64458.5\",\"20.53\",\"0\",\"2\"],[\"64458.8\",\"0\",\"0\",\"0\"],[\"64466.3\",\"46.54\",\"0\",\"1\"],[\"64473.5\",\"15.52\",\"0\",\"1\"],[\"64473.6\",\"52.77\",\"0\",\"3\"],[\"64475.6\",\"31.43\",\"0\",\"3\"],[\"64476.1\",\"0\",\"0\",\"0\"],[\"64476.6\",\"232.86\",\"0\",\"1\"],[\"64476.9\",\"0.02\",\"0\",\"2\"],[\"64486.4\",\"1.27\",\"0\",\"2\"],[\"64486.9\",\"58.32\",\"0\",\"3\"],[\"64508.2\",\"0\",\"0\",\"0\"]],\"bids\":[[\"64455.6\",\"0\",\"0\",\"0\"],[\"64455.5\",\"0\",\"0\",\"0\"],[\"64455.1\",\"0.01\",\"0\",\"1\"],[\"64439.1\",\"58.25\",\"0\",\"1\"],[\"64439\",\"0.01\",\"0\",\"1\"],[\"64438.6\",\"43.84\",\"0\",\"5\"],[\"64438\",\"0.01\",\"0\",\"1\"],[\"64437.4\",\"233\",\"0\",\"1\"],[\"64405.9\",\"0\",\"0\",\"0\"]],\"ts\":\"1782015922805\",\"checksum\":-1856338509,\"seqId\":325069870191,\"prevSeqId\":325069870158}]}"}
{"action": null, "capture_sequence": 203, "channel": "trades", "connection_sequence": 3, "event": null, "instId": "BTC-USDT-SWAP", "local_receive_ts": "2026-06-21T04:25:22Z", "monotonic_ns": 1643478750290525, "raw": "{\"arg\":{\"channel\":\"trades\",\"instId\":\"BTC-USDT-SWAP\"},\"data\":[{\"instId\":\"BTC-USDT-SWAP\",\"tradeId\":\"2718748880\",\"px\":\"64458\",\"sz\":\"4.03\",\"side\":\"buy\",\"ts\":\"1782015922846\",\"count\":\"1\",\"source\":\"0\",\"seqId\":325069870204}]}"}
{"action": null, "capture_sequence": 204, "channel": "trades", "connection_sequence": 3, "event": null, "instId": "BTC-USDT-SWAP", "local_receive_ts": "2026-06-21T04:25:22Z", "monotonic_ns": 1643478779301687, "raw": "{\"arg\":{\"channel\":\"trades\",\"instId\":\"BTC-USDT-SWAP\"},\"data\":[{\"instId\":\"BTC-USDT-SWAP\",\"tradeId\":\"2718748881\",\"px\":\"64457.9\",\"sz\":\"5\",\"side\":\"sell\",\"ts\":\"1782015922876\",\"count\":\"1\",\"source\":\"0\",\"seqId\":325069870208}]}"}
{"action": "update", "capture_sequence": 205, "channel": "books", "connection_sequence": 3, "event": null, "instId": "BTC-USDT-SWAP", "local_receive_ts": "2026-06-21T04:25:23Z", "monotonic_ns": 1643478808360530, "raw": "{\"arg\":{\"channel\":\"books\",\"instId\":\"BTC-USDT-SWAP\"},\"action\":\"update\",\"data\":[{\"asks\":[[\"64458\",\"496.17\",\"0\",\"58\"],[\"64458.7\",\"0\",\"0\",\"0\"],[\"64459.9\",\"0.02\",\"0\",\"2\"],[\"64460.1\",\"0.02\",\"0\",\"2\"],[\"64460.6\",\"0\",\"0\",\"0\"],[\"64461.1\",\"0.02\",\"0\",\"2\"],[\"64476.9\",\"0.03\",\"0\",\"3\"],[\"64477.9\",\"0\",\"0\",\"0\"],[\"64480\",\"55.68\",\"0\",\"45\"],[\"64480.1\",\"0.01\",\"0\",\"1\"],[\"64483.2\",\"114.7\",\"0\",\"4\"],[\"64483.3\",\"0.05\",\"0\",\"2\"],[\"64486.4\",\"59.47\",\"0\",\"3\"],[\"64486.9\",\"0.12\",\"0\",\"2\"],[\"64508.2\",\"59.01\",\"0\",\"5\"],[\"64508.4\",\"1367.19\",\"0\",\"6\"],[\"64508.5\",\"42.46\",\"0\",\"3\"]],\"bids\":[[\"64457.9\",\"550.06\",\"0\",\"27\"],[\"64455.1\",\"0\",\"0\",\"0\"],[\"64455\",\"0.01\",\"0\",\"1\"],[\"64454.8\",\"0.02\",\"0\",\"2\"],[\"64439.1\",\"0\",\"0\",\"0\"],[\"64439\",\"0.03\",\"0\",\"2\"],[\"64438.9\",\"37.23\",\"0\",\"1\"],[\"64438.2\",\"58.26\",\"0\",\"2\"],[\"64405.9\",\"1.93\",\"0\",\"1\"],[\"64405.7\",\"4.65\",\"0\",\"1\"]],\"ts\":\"1782015922905\",\"checksum\":-38293092,\"seqId\":325069870217,\"prevSeqId\":325069870191}]}"}
{"action": "update", "capture_sequence": 206, "channel": "books", "connection_sequence": 3, "event": null, "instId": "BTC-USDT-SWAP", "local_receive_ts": "2026-06-21T04:25:23Z", "monotonic_ns": 1643478908742971, "raw": "{\"arg\":{\"channel\":\"books\",\"instId\":\"BTC-USDT-SWAP\"},\"action\":\"update\",\"data\":[{\"asks\":[[\"64459.6\",\"2.16\",\"0\",\"2\"],[\"64460.1\",\"1.58\",\"0\",\"3\"],[\"64470.1\",\"0.01\",\"0\",\"1\"],[\"64484.1\",\"0.33\",\"0\",\"2\"],[\"64484.3\",\"0\",\"0\",\"0\"],[\"64508.6\",\"0.01\",\"0\",\"1\"]],\"bids\":[[\"64457.9\",\"551.62\",\"0\",\"28\"],[\"64456.7\",\"1.56\",\"0\",\"1\"],[\"64456.2\",\"1.56\",\"0\",\"1\"],[\"64455.7\",\"1.56\",\"0\",\"1\"],[\"64406\",\"0\",\"0\",\"0\"],[\"64405.9\",\"0\",\"0\",\"0\"],[\"64405.7\",\"0\",\"0\",\"0\"]],\"ts\":\"1782015923005\",\"checksum\":-814954392,\"seqId\":325069870242,\"prevSeqId\":325069870217}]}"}
{"action": "update", "capture_sequence": 207, "channel": "books", "connection_sequence": 3, "event": null, "instId": "BTC-USDT-SWAP", "local_receive_ts": "2026-06-21T04:25:23Z", "monotonic_ns": 1643479009449046, "raw": "{\"arg\":{\"channel\":\"books\",\"instId\":\"BTC-USDT-SWAP\"},\"action\":\"update\",\"data\":[{\"asks\":[[\"64458.3\",\"46.2\",\"0\",\"4\"],[\"64458.4\",\"1.57\",\"0\",\"2\"],[\"64458.9\",\"1.56\",\"0\",\"1\"],[\"64459.6\",\"0.6\",\"0\",\"1\"],[\"64459.9\",\"0.01\",\"0\",\"1\"],[\"64460.6\",\"1.56\",\"0\",\"1\"],[\"64463.6\",\"16.01\",\"0\",\"2\"],[\"64508.5\",\"0\",\"0\",\"0\"],[\"64508.6\",\"0\",\"0\",\"0\"]],\"bids\":[[\"64457.9\",\"550.06\",\"0\",\"27\"],[\"64457.5\",\"0.01\",\"0\",\"1\"],[\"64457.4\",\"1.87\",\"0\",\"2\"],[\"64456.7\",\"0\",\"0\",\"0\"],[\"64456.3\",\"0.01\",\"0\",\"1\"],[\"64455.8\",\"0.01\",\"0\",\"1\"],[\"64455.4\",\"0.01\",\"0\",\"1\"],[\"64455.3\",\"50.23\",\"0\",\"3\"],[\"64454.8\",\"0.01\",\"0\",\"1\"],[\"64406.3\",\"0.33\",\"0\",\"2\"],[\"64406.2\",\"0\",\"0\",\"0\"],[\"64406.1\",\"0\",\"0\",\"0\"]],\"ts\":\"1782015923105\",\"checksum\":310509588,\"seqId\":325069870283,\"prevSeqId\":325069870242}]}"}
{"action": "update", "capture_sequence": 208, "channel": "books", "connection_sequence": 3, "event": null, "instId": "BTC-USDT-SWAP", "local_receive_ts": "2026-06-21T04:25:23Z", "monotonic_ns": 1643479116138068, "raw": "{\"arg\":{\"channel\":\"books\",\"instId\":\"BTC-USDT-SWAP\"},\"action\":\"update\",\"data\":[{\"asks\":[[\"64458.1\",\"1.59\",\"0\",\"4\"],[\"64458.3\",\"46.19\",\"0\",\"3\"],[\"64458.4\",\"0.01\",\"0\",\"1\"],[\"64458.6\",\"0.01\",\"0\",\"1\"],[\"64458.7\",\"1.56\",\"0\",\"1\"],[\"64458.9\",\"0\",\"0\",\"0\"],[\"64459.5\",\"1.57\",\"0\",\"2\"],[\"64463.6\",\"14.45\",\"0\",\"1\"],[\"64464.5\",\"0.32\",\"0\",\"3\"],[\"64465.4\",\"0\",\"0\",\"0\"],[\"64465.7\",\"63.7\",\"0\",\"1\"],[\"64466.1\",\"0.01\",\"0\",\"1\"],[\"64466.4\",\"70.86\",\"0\",\"3\"],[\"64466.8\",\"0\",\"0\",\"0\"],[\"64467\",\"69.8\",\"0\",\"3\"],[\"64467.2\",\"0\",\"0\",\"0\"],[\"64467.5\",\"0\",\"0\",\"0\"],[\"64467.7\",\"146.25\",\"0\",\"2\"],[\"64484.1\",\"0.02\",\"0\",\"1\"],[\"64484.3\",\"0.31\",\"0\",\"1\"],[\"64486.9\",\"85.49\",\"0\",\"3\"],[\"64487.2\",\"0.03\",\"0\",\"2\"],[\"64491\",\"80.13\",\"0\",\"2\"],[\"64492\",\"0.03\",\"0\",\"3\"],[\"64492.3\",\"0.03\",\"0\",\"1\"],[\"64492.6\",\"98.92\",\"0\",\"1\"],[\"64492.9\",\"8.01\",\"0\",\"2\"],[\"64493.1\",\"51.83\",\"0\",\"6\"],[\"64493.2\",\"399.82\",\"0\",\"8\"],[\"64493.4\",\"0.32\",\"0\",\"5\"],[\"64493.7\",\"359.29\",\"0\",\"5\"],[\"64494.1\",\"0\",\"0\",\"0\"],[\"64494.2\",\"0\",\"0\",\"0\"],[\"64508.5\",\"42.46\",\"0\",\"3\"],[\"64508.6\",\"0.01\",\"0\",\"1\"],[\"64508.7\",\"42.88\",\"0\",\"9\"],[\"64508.8\",\"0.04\",\"0\",\"2\"]],\"bids\":[[\"64457.7\",\"0.01\",\"0\",\"1\"],[\"64457.5\",\"0\",\"0\",\"0\"],[\"64457.4\",\"0.31\",\"0\",\"1\"],[\"64457.3\",\"1.56\",\"0\",\"1\"],[\"64450.5\",\"4.9\",\"0\",\"3\"],[\"64450\",\"1.92\",\"0\",\"3\"],[\"64449.8\",\"0.01\",\"0\",\"1\"],[\"64449.5\",\"37.23\",\"0\",\"1\"],[\"64449.2\",\"0.01\",\"0\",\"1\"],[\"64448.9\",\"0\",\"0\",\"0\"],[\"64448.5\",\"0\",\"0\",\"0\"],[\"64448.4\",\"0\",\"0\",\"0\"],[\"64448\",\"272.36\",\"0\",\"10\"],[\"64447.7\",\"0\",\"0\",\"0\"],[\"64447.3\",\"42.48\",\"0\",\"3\"],[\"64443.4\",\"403.67\",\"0\",\"1\"],[\"64443.3\",\"163.94\",\"0\",\"5\"],[\"64442.2\",\"0\",\"0\",\"0\"],[\"64442.1\",\"92.42\",\"0\",\"2\"],[\"64441.8\",\"535.35\",\"0\",\"2\"],[\"64441.7\",\"85.45\",\"0\",\"2\"],[\"64439\",\"0.01\",\"0\",\"1\"],[\"64438.5\",\"16.48\",\"0\",\"4\"],[\"64432.5\",\"0.01\",\"0\",\"1\"],[\"64432.1\",\"0.09\",\"0\",\"2\"],[\"64406.1\",\"0.02\",\"0\",\"2\"],[\"64405.9\",\"1.93\",\"0\",\"1\"],[\"64405.7\",\"15.87\",\"0\",\"2\"],[\"64405.6\",\"0.01\",\"0\",\"1\"]],\"ts\":\"1782015923205\",\"checksum\":705187408,\"seqId\":325069870461,\"prevSeqId\":325069870283}]}"}
{"action": null, "capture_sequence": 209, "channel": "trades", "connection_sequence": 3, "event": null, "instId": "BTC-USDT-SWAP", "local_receive_ts": "2026-06-21T04:25:23Z", "monotonic_ns": 1643479182068716, "raw": "{\"arg\":{\"channel\":\"trades\",\"instId\":\"BTC-USDT-SWAP\"},\"data\":[{\"instId\":\"BTC-USDT-SWAP\",\"tradeId\":\"2718748882\",\"px\":\"64457.9\",\"sz\":\"5\",\"side\":\"sell\",\"ts\":\"1782015923278\",\"count\":\"1\",\"source\":\"0\",\"seqId\":325069870525}]}"}
{"action": "update", "capture_sequence": 210, "channel": "books", "connection_sequence": 3, "event": null, "instId": "BTC-USDT-SWAP", "local_receive_ts": "2026-06-21T04:25:23Z", "monotonic_ns": 1643479208895135, "raw": "{\"arg\":{\"channel\":\"books\",\"instId\":\"BTC-USDT-SWAP\"},\"action\":\"update\",\"data\":[{\"asks\":[[\"64458\",\"497.73\",\"0\",\"59\"],[\"64458.1\",\"0.03\",\"0\",\"3\"],[\"64458.6\",\"0\",\"0\",\"0\"],[\"64458.7\",\"0\",\"0\",\"0\"],[\"64458.9\",\"0.01\",\"0\",\"1\"],[\"64459\",\"1.56\",\"0\",\"1\"],[\"64459.5\",\"0.01\",\"0\",\"1\"],[\"64459.6\",\"2.16\",\"0\",\"2\"],[\"64465.5\",\"1.01\",\"0\",\"2\"],[\"64466.1\",\"1.21\",\"0\",\"2\"],[\"64466.4\",\"72.06\",\"0\",\"4\"],[\"64466.9\",\"2.36\",\"0\",\"2\"],[\"64467.2\",\"1.2\",\"0\",\"1\"],[\"64467.6\",\"1.6\",\"0\",\"4\"],[\"64492\",\"1.03\",\"0\",\"4\"],[\"64492.7\",\"101.08\",\"0\",\"4\"],[\"64493\",\"14.92\",\"0\",\"5\"],[\"64493.5\",\"2.29\",\"0\",\"5\"],[\"64493.8\",\"1.24\",\"0\",\"4\"],[\"64494.1\",\"1.2\",\"0\",\"1\"],[\"64508.7\",\"0\",\"0\",\"0\"],[\"64508.8\",\"0\",\"0\",\"0\"]],\"bids\":[[\"64457.9\",\"545.06\",\"0\",\"27\"],[\"64457.7\",\"0\",\"0\",\"0\"],[\"64457.3\",\"0\",\"0\",\"0\"],[\"64457.2\",\"1.56\",\"0\",\"1\"],[\"64456.8\",\"0.32\",\"0\",\"2\"],[\"64456.7\",\"1.56\",\"0\",\"1\"],[\"64449.7\",\"48.18\",\"0\",\"3\"],[\"64449\",\"1.83\",\"0\",\"4\"],[\"64448.7\",\"6.16\",\"0\",\"2\"],[\"64448.5\",\"2.88\",\"0\",\"1\"],[\"64448.2\",\"250.59\",\"0\",\"4\"],[\"64447.9\",\"7\",\"0\",\"2\"],[\"64405.6\",\"0\",\"0\",\"0\"]],\"ts\":\"1782015923305\",\"checksum\":1759680967,\"seqId\":325069870560,\"prevSeqId\":325069870461}]}"}
{"action": "update", "capture_sequence": 211, "channel": "books", "connection_sequence": 3, "event": null, "instId": "BTC-USDT-SWAP", "local_receive_ts": "2026-06-21T04:25:23Z", "monotonic_ns": 1643479308739615, "raw": "{\"arg\":{\"channel\":\"books\",\"instId\":\"BTC-USDT-SWAP\"},\"action\":\"update\",\"data\":[{\"asks\":[[\"64458.9\",\"0\",\"0\",\"0\"],[\"64459\",\"0\",\"0\",\"0\"],[\"64459.3\",\"1.04\",\"0\",\"5\"],[\"64459.4\",\"1.56\",\"0\",\"1\"],[\"64459.6\",\"0.6\",\"0\",\"1\"],[\"64461.2\",\"1.56\",\"0\",\"1\"],[\"64463.6\",\"16.01\",\"0\",\"2\"],[\"64464.5\",\"1.32\",\"0\",\"4\"],[\"64465.8\",\"65.22\",\"0\",\"3\"],[\"64467.7\",\"147.75\",\"0\",\"3\"],[\"64476.2\",\"0.17\",\"0\",\"3\"],[\"64491.1\",\"1\",\"0\",\"1\"],[\"64492.3\",\"1.23\",\"0\",\"2\"],[\"64494.3\",\"17.23\",\"0\",\"6\"]],\"bids\":[[\"64457.9\",\"539.37\",\"0\",\"26\"],[\"64457.2\",\"0\",\"0\",\"0\"],[\"64456.8\",\"0.31\",\"0\",\"1\"],[\"64456.7\",\"0\",\"0\",\"0\"],[\"64456.3\",\"0\",\"0\",\"0\"],[\"64456.2\",\"0\",\"0\",\"0\"],[\"64455.7\",\"0\",\"0\",\"0\"],[\"64455.4\",\"0.02\",\"0\",\"2\"],[\"64455.3\",\"50.24\",\"0\",\"4\"],[\"64452\",\"78.22\",\"0\",\"5\"],[\"64451.5\",\"17.46\",\"0\",\"2\"],[\"64450.6\",\"1.4\",\"0\",\"1\"],[\"64449.3\",\"17.78\",\"0\",\"3\"],[\"64447.4\",\"13.17\",\"0\",\"3\"],[\"64445.1\",\"185.38\",\"0\",\"5\"],[\"64444.5\",\"0\",\"0\",\"0\"],[\"64442.9\",\"3.21\",\"0\",\"1\"],[\"64436.1\",\"25.84\",\"0\",\"3\"],[\"64405.6\",\"0.01\",\"0\",\"1\"],[\"64405.5\",\"0.01\",\"0\",\"1\"],[\"64405.3\",\"46.54\",\"0\",\"1\"],[\"64405.2\",\"6.39\",\"0\",\"4\"],[\"64405.1\",\"0.07\",\"0\",\"3\"]],\"ts\":\"1782015923405\",\"checksum\":558752104,\"seqId\":325069870660,\"prevSeqId\":325069870560}]}"}
{"action": "update", "capture_sequence": 212, "channel": "books", "connection_sequence": 3, "event": null, "instId": "BTC-USDT-SWAP", "local_receive_ts": "2026-06-21T04:25:23Z", "monotonic_ns": 1643479408098017, "raw": "{\"arg\":{\"channel\":\"books\",\"instId\":\"BTC-USDT-SWAP\"},\"action\":\"update\",\"data\":[{\"asks\":[[\"64458\",\"496.17\",\"0\",\"58\"],[\"64483.8\",\"0\",\"0\",\"0\"],[\"64484.1\",\"0.79\",\"0\",\"2\"],[\"64508.7\",\"42.88\",\"0\",\"9\"]],\"bids\":[[\"64457.9\",\"549.69\",\"0\",\"28\"],[\"64456.8\",\"0.32\",\"0\",\"2\"],[\"64456.7\",\"1.56\",\"0\",\"1\"],[\"64456.1\",\"0.02\",\"0\",\"2\"],[\"64456\",\"1.58\",\"0\",\"3\"],[\"64455.8\",\"0\",\"0\",\"0\"],[\"64455.3\",\"50.23\",\"0\",\"3\"],[\"64453.9\",\"0.32\",\"0\",\"2\"],[\"64453.7\",\"0\",\"0\",\"0\"],[\"64451.5\",\"15.9\",\"0\",\"1\"],[\"64405\",\"13.52\",\"0\",\"15\"]],\"ts\":\"1782015923505\",\"checksum\":391522179,\"seqId\":325069870695,\"prevSeqId\":325069870660}]}"}
{"action": "update", "capture_sequence": 213, "channel": "books", "connection_sequence": 3, "event": null, "instId": "BTC-USDT-SWAP", "local_receive_ts": "2026-06-21T04:25:23Z", "monotonic_ns": 1643479508593211, "raw": "{\"arg\":{\"channel\":\"books\",\"instId\":\"BTC-USDT-SWAP\"},\"action\":\"update\",\"data\":[{\"asks\":[[\"64459.3\",\"1.03\",\"0\",\"4\"],[\"64459.4\",\"0\",\"0\",\"0\"],[\"64459.9\",\"0.02\",\"0\",\"2\"],[\"64460.1\",\"0.02\",\"0\",\"2\"],[\"64464.1\",\"33.41\",\"0\",\"6\"],[\"64508.8\",\"0.04\",\"0\",\"2\"]],\"bids\":[[\"64454.6\",\"57.76\",\"0\",\"2\"]],\"ts\":\"1782015923605\",\"checksum\":177014394,\"seqId\":325069870712,\"prevSeqId\":325069870695}]}"}
{"action": "update", "capture_sequence": 214, "channel": "books", "connection_sequence": 3, "event": null, "instId": "BTC-USDT-SWAP", "local_receive_ts": "2026-06-21T04:25:23Z", "monotonic_ns": 1643479609054947, "raw": "{\"arg\":{\"channel\":\"books\",\"instId\":\"BTC-USDT-SWAP\"},\"action\":\"update\",\"data\":[{\"asks\":[],\"bids\":[[\"64457.9\",\"549.15\",\"0\",\"27\"]],\"ts\":\"1782015923705\",\"checksum\":325238845,\"seqId\":325069870725,\"prevSeqId\":325069870712}]}"}
{"action": "update", "capture_sequence": 215, "channel": "books", "connection_sequence": 3, "event": null, "instId": "BTC-USDT-SWAP", "local_receive_ts": "2026-06-21T04:25:23Z", "monotonic_ns": 1643479708269464, "raw": "{\"arg\":{\"channel\":\"books\",\"instId\":\"BTC-USDT-SWAP\"},\"action\":\"update\",\"data\":[{\"asks\":[[\"64458\",\"496.32\",\"0\",\"60\"],[\"64460.6\",\"0\",\"0\",\"0\"],[\"64467\",\"63.88\",\"0\",\"2\"],[\"64476.2\",\"0.02\",\"0\",\"2\"],[\"64508.9\",\"11.26\",\"0\",\"3\"]],\"bids\":[[\"64457.9\",\"547.59\",\"0\",\"26\"],[\"64442.9\",\"0\",\"0\",\"0\"],[\"64436.1\",\"25.65\",\"0\",\"2\"],[\"64404.8\",\"0.04\",\"0\",\"1\"]],\"ts\":\"1782015923805\",\"checksum\":-2011311012,\"seqId\":325069870741,\"prevSeqId\":325069870725}]}"}
{"action": "update", "capture_sequence": 216, "channel": "books", "connection_sequence": 3, "event": null, "instId": "BTC-USDT-SWAP", "local_receive_ts": "2026-06-21T04:25:24Z", "monotonic_ns": 1643479808451473, "raw": "{\"arg\":{\"channel\":\"books\",\"instId\":\"BTC-USDT-SWAP\"},\"action\":\"update\",\"data\":[{\"asks\":[[\"64476.2\",\"0.17\",\"0\",\"3\"],[\"64481\",\"205.75\",\"0\",\"6\"],[\"64482.6\",\"0.01\",\"0\",\"1\"],[\"64484.1\",\"0.02\",\"0\",\"1\"],[\"64484.3\",\"0\",\"0\",\"0\"],[\"64484.5\",\"0.83\",\"0\",\"4\"],[\"64484.6\",\"1.52\",\"0\",\"3\"],[\"64485.8\",\"85.77\",\"0\",\"3\"],[\"64486.9\",\"0.12\",\"0\",\"2\"],[\"64490.9\",\"86.21\",\"0\",\"3\"],[\"64492.1\",\"20.07\",\"0\",\"1\"],[\"64492.5\",\"0.06\",\"0\",\"4\"],[\"64493.1\",\"31.76\",\"0\",\"5\"]],\"bids\":[[\"64456.8\",\"0.31\",\"0\",\"1\"],[\"64456.7\",\"0\",\"0\",\"0\"],[\"64455.3\",\"50.24\",\"0\",\"4\"],[\"64452.1\",\"1.11\",\"0\",\"5\"],[\"64451.6\",\"0\",\"0\",\"0\"],[\"64445.7\",\"515.31\",\"0\",\"5\"],[\"64445.1\",\"184.61\",\"0\",\"4\"],[\"64443.3\",\"130.12\",\"0\",\"4\"],[\"64442.9\",\"3.21\",\"0\",\"1\"],[\"64442.7\",\"0\",\"0\",\"0\"],[\"64442.2\",\"33.83\",\"0\",\"1\"],[\"64442.1\",\"6.22\",\"0\",\"1\"],[\"64441.9\",\"123.14\",\"0\",\"3\"],[\"64441.7\",\"20.11\",\"0\",\"2\"],[\"64440.6\",\"95.44\",\"0\",\"3\"],[\"64436.1\",\"25.84\",\"0\",\"3\"],[\"64404.7\",\"0.77\",\"0\",\"1\"]],\"ts\":\"1782015923905\",\"checksum\":-733593447,\"seqId\":325069870779,\"prevSeqId\":325069870741}]}"}
{"action": null, "capture_sequence": 217, "channel": "trades", "connection_sequence": 3, "event": null, "instId": "BTC-USDT-SWAP", "local_receive_ts": "2026-06-21T04:25:24Z", "monotonic_ns": 1643479842550873, "raw": "{\"arg\":{\"channel\":\"trades\",\"instId\":\"BTC-USDT-SWAP\"},\"data\":[{\"instId\":\"BTC-USDT-SWAP\",\"tradeId\":\"2718748883\",\"px\":\"64457.9\",\"sz\":\"5\",\"side\":\"sell\",\"ts\":\"1782015923939\",\"count\":\"1\",\"source\":\"0\",\"seqId\":325069870804}]}"}
{"action": "update", "capture_sequence": 218, "channel": "books", "connection_sequence": 3, "event": null, "instId": "BTC-USDT-SWAP", "local_receive_ts": "2026-06-21T04:25:24Z", "monotonic_ns": 1643479908758600, "raw": "{\"arg\":{\"channel\":\"books\",\"instId\":\"BTC-USDT-SWAP\"},\"action\":\"update\",\"data\":[{\"asks\":[[\"64458\",\"497.88\",\"0\",\"61\"],[\"64476.6\",\"0\",\"0\",\"0\"],[\"64476.7\",\"232.86\",\"0\",\"1\"],[\"64481\",\"171.94\",\"0\",\"5\"],[\"64481.9\",\"33.81\",\"0\",\"2\"],[\"64484.1\",\"0.79\",\"0\",\"2\"],[\"64484.3\",\"0.31\",\"0\",\"1\"],[\"64484.5\",\"0.06\",\"0\",\"3\"],[\"64484.6\",\"1.21\",\"0\",\"2\"],[\"64485.8\",\"0.4\",\"0\",\"2\"],[\"64486.2\",\"58.37\",\"0\",\"7\"],[\"64486.4\",\"1.27\",\"0\",\"2\"],[\"64486.7\",\"85.38\",\"0\",\"2\"],[\"64490.9\",\"0.07\",\"0\",\"2\"],[\"64492.1\",\"0\",\"0\",\"0\"],[\"64492.5\",\"86.2\",\"0\",\"5\"],[\"64492.9\",\"28.08\",\"0\",\"3\"]],\"bids\":[[\"64457.9\",\"542.59\",\"0\",\"26\"],[\"64456.1\",\"0.01\",\"0\",\"1\"],[\"64455.5\",\"1.56\",\"0\",\"1\"],[\"64455.3\",\"48.68\",\"0\",\"3\"],[\"64455\",\"1.57\",\"0\",\"2\"],[\"64454.8\",\"0.02\",\"0\",\"2\"],[\"64454.5\",\"0\",\"0\",\"0\"],[\"64452.1\",\"0.8\",\"0\",\"4\"],[\"64451.6\",\"0.31\",\"0\",\"1\"],[\"64445.7\",\"514.54\",\"0\",\"4\"],[\"64445.2\",\"0.77\",\"0\",\"1\"],[\"64443\",\"33.85\",\"0\",\"3\"],[\"64442.4\",\"20.1\",\"0\",\"2\"],[\"64442.2\",\"0\",\"0\",\"0\"],[\"64442.1\",\"92.42\",\"0\",\"2\"],[\"64441.9\",\"36.94\",\"0\",\"2\"],[\"64441.7\",\"0.02\",\"0\",\"1\"],[\"64441.4\",\"135.45\",\"0\",\"4\"],[\"64440.6\",\"10.01\",\"0\",\"2\"],[\"64404.7\",\"0\",\"0\",\"0\"]],\"ts\":\"1782015924005\",\"checksum\":-899857410,\"seqId\":325069870826,\"prevSeqId\":325069870779}]}"}
{"action": "update", "capture_sequence": 219, "channel": "books", "connection_sequence": 3, "event": null, "instId": "BTC-USDT-SWAP", "local_receive_ts": "2026-06-21T04:25:24Z", "monotonic_ns": 1643480009209811, "raw": "{\"arg\":{\"channel\":\"books\",\"instId\":\"BTC-USDT-SWAP\"},\"action\":\"update\",\"data\":[{\"asks\":[[\"64458\",\"496.32\",\"0\",\"60\"],[\"64458.3\",\"47.75\",\"0\",\"4\"],[\"64458.9\",\"0.01\",\"0\",\"1\"],[\"64459\",\"1.56\",\"0\",\"1\"],[\"64459.5\",\"1.57\",\"0\",\"2\"],[\"64459.9\",\"0.01\",\"0\",\"1\"],[\"64469.2\",\"9.69\",\"0\",\"1\"],[\"64508.7\",\"0\",\"0\",\"0\"],[\"64508.8\",\"0\",\"0\",\"0\"],[\"64508.9\",\"0\",\"0\",\"0\"]],\"bids\":[[\"64457.2\",\"0.01\",\"0\",\"1\"],[\"64457.1\",\"1.56\",\"0\",\"1\"],[\"64456\",\"0.02\",\"0\",\"2\"],[\"64455.5\",\"0\",\"0\",\"0\"],[\"64455\",\"0.01\",\"0\",\"1\"],[\"64454.9\",\"1.56\",\"0\",\"1\"],[\"64454.8\",\"0.01\",\"0\",\"1\"],[\"64451.5\",\"17.46\",\"0\",\"2\"],[\"64451\",\"1.58\",\"0\",\"3\"],[\"64441.8\",\"535.37\",\"0\",\"3\"],[\"64441.7\",\"0\",\"0\",\"0\"],[\"64441.5\",\"146.74\",\"0\",\"4\"],[\"64441.4\",\"50.02\",\"0\",\"3\"],[\"64438.8\",\"0.02\",\"0\",\"1\"],[\"64438.7\",\"35.05\",\"0\",\"2\"],[\"64438.6\",\"12.78\",\"0\",\"4\"],[\"64438.5\",\"16.46\",\"0\",\"3\"],[\"64432.5\",\"0.02\",\"0\",\"2\"],[\"64432.1\",\"0.08\",\"0\",\"1\"],[\"64405\",\"0\",\"0\",\"0\"],[\"64404.8\",\"0\",\"0\",\"0\"]],\"ts\":\"1782015924105\",\"checksum\":986182034,\"seqId\":325069870969,\"prevSeqId\":325069870826}]}"}
{"action": "update", "capture_sequence": 220, "channel": "books", "connection_sequence": 3, "event": null, "instId": "BTC-USDT-SWAP", "local_receive_ts": "2026-06-21T04:25:24Z", "monotonic_ns": 1643480108786898, "raw": "{\"arg\":{\"channel\":\"books\",\"instId\":\"BTC-USDT-SWAP\"},\"action\":\"update\",\"data\":[{\"asks\":[[\"64458.3\",\"46.19\",\"0\",\"3\"],[\"64459\",\"0\",\"0\",\"0\"],[\"64508.7\",\"42.88\",\"0\",\"9\"]],\"bids\":[[\"64457.9\",\"548.9\",\"0\",\"27\"],[\"64457.4\",\"0.32\",\"0\",\"2\"],[\"64457.3\",\"1.56\",\"0\",\"1\"],[\"64457.2\",\"0\",\"0\",\"0\"],[\"64457.1\",\"0\",\"0\",\"0\"],[\"64456.9\",\"0.01\",\"0\",\"1\"],[\"64456.8\",\"1.87\",\"0\",\"2\"],[\"64455.3\",\"48.67\",\"0\",\"2\"],[\"64451\",\"0.02\",\"0\",\"2\"],[\"64441.8\",\"535.35\",\"0\",\"2\"],[\"64441.7\",\"0.02\",\"0\",\"1\"],[\"64432.9\",\"0.01\",\"0\",\"1\"],[\"64432.5\",\"0.01\",\"0\",\"1\"],[\"64405.2\",\"0\",\"0\",\"0\"],[\"64405.1\",\"0\",\"0\",\"0\"]],\"ts\":\"1782015924205\",\"checksum\":-889825866,\"seqId\":325069870989,\"prevSeqId\":325069870969}]}"}
{"action": "update", "capture_sequence": 221, "channel": "books", "connection_sequence": 3, "event": null, "instId": "BTC-USDT-SWAP", "local_receive_ts": "2026-06-21T04:25:24Z", "monotonic_ns": 1643480208697187, "raw": "{\"arg\":{\"channel\":\"books\",\"instId\":\"BTC-USDT-SWAP\"},\"action\":\"update\",\"data\":[{\"asks\":[[\"64458\",\"496.33\",\"0\",\"60\"],[\"64458.9\",\"0\",\"0\",\"0\"],[\"64459.3\",\"1.04\",\"0\",\"5\"],[\"64459.4\",\"1.56\",\"0\",\"1\"],[\"64459.5\",\"0.01\",\"0\",\"1\"],[\"64460\",\"151.57\",\"0\",\"3\"],[\"64460.7\",\"1.57\",\"0\",\"2\"],[\"64481.7\",\"33.8\",\"0\",\"1\"],[\"64481.9\",\"0.01\",\"0\",\"1\"],[\"64483.8\",\"0.31\",\"0\",\"1\"],[\"64484.3\",\"0\",\"0\",\"0\"],[\"64486.5\",\"101.02\",\"0\",\"2\"],[\"64486.7\",\"0.01\",\"0\",\"1\"],[\"64492.9\",\"8.01\",\"0\",\"2\"],[\"64493.6\",\"168.93\",\"0\",\"2\"],[\"64508.7\",\"0\",\"0\",\"0\"]],\"bids\":[[\"64451.6\",\"0\",\"0\",\"0\"],[\"64451.3\",\"13.99\",\"0\",\"8\"],[\"64443.1\",\"20.09\",\"0\",\"1\"],[\"64443\",\"0.02\",\"0\",\"2\"],[\"64442.7\",\"33.83\",\"0\",\"1\"],[\"64442.4\",\"0.01\",\"0\",\"1\"],[\"64442.2\",\"86.2\",\"0\",\"1\"],[\"64442.1\",\"6.22\",\"0\",\"1\"],[\"64441.5\",\"61.31\",\"0\",\"3\"],[\"64441.2\",\"85.43\",\"0\",\"1\"],[\"64405.6\",\"0\",\"0\",\"0\"],[\"64405.5\",\"0\",\"0\",\"0\"],[\"64405.3\",\"0\",\"0\",\"0\"]],\"ts\":\"1782015924305\",\"checksum\":1171935843,\"seqId\":325069871079,\"prevSeqId\":325069870989}]}"}
{"action": "update", "capture_sequence": 222, "channel": "books", "connection_sequence": 3, "event": null, "instId": "BTC-USDT-SWAP", "local_receive_ts": "2026-06-21T04:25:24Z", "monotonic_ns": 1643480309917669, "raw": "{\"arg\":{\"channel\":\"books\",\"instId\":\"BTC-USDT-SWAP\"},\"action\":\"update\",\"data\":[{\"asks\":[[\"64459.1\",\"0.01\",\"0\",\"1\"],[\"64459.3\",\"1.03\",\"0\",\"4\"],[\"64459.4\",\"0\",\"0\",\"0\"],[\"64459.7\",\"1.56\",\"0\",\"1\"],[\"64460\",\"150.01\",\"0\",\"2\"],[\"64460.2\",\"2.34\",\"0\",\"3\"],[\"64463.6\",\"14.45\",\"0\",\"1\"],[\"64464.1\",\"31.85\",\"0\",\"5\"],[\"64476.2\",\"0.02\",\"0\",\"2\"],[\"64476.6\",\"0.15\",\"0\",\"1\"],[\"64483.8\",\"0\",\"0\",\"0\"],[\"64484.3\",\"0.31\",\"0\",\"1\"],[\"64492.7\",\"121.15\",\"0\",\"5\"],[\"64493.6\",\"148.86\",\"0\",\"1\"],[\"64508.5\",\"0\",\"0\",\"0\"],[\"64508.6\",\"0\",\"0\",\"0\"]],\"bids\":[[\"64457.4\",\"0.31\",\"0\",\"1\"],[\"64457.3\",\"0\",\"0\",\"0\"],[\"64456.5\",\"0.01\",\"0\",\"1\"],[\"64456.4\",\"1.57\",\"0\",\"2\"],[\"64456\",\"0.03\",\"0\",\"3\"],[\"64455.9\",\"1.57\",\"0\",\"2\"],[\"64455.4\",\"0.01\",\"0\",\"1\"],[\"64451.6\",\"0.31\",\"0\",\"1\"],[\"64451.5\",\"15.9\",\"0\",\"1\"],[\"64451.3\",\"13.68\",\"0\",\"7\"],[\"64443.1\",\"0\",\"0\",\"0\"],[\"64442.9\",\"0\",\"0\",\"0\"],[\"64442.4\",\"3.19\",\"0\",\"2\"],[\"64442.2\",\"106.29\",\"0\",\"2\"],[\"64436.1\",\"25.65\",\"0\",\"2\"],[\"64435.6\",\"28.61\",\"0\",\"3\"],[\"64432.9\",\"0\",\"0\",\"0\"],[\"64432.5\",\"0.02\",\"0\",\"2\"],[\"64405.6\",\"0.01\",\"0\",\"1\"],[\"64405.5\",\"0.01\",\"0\",\"1\"]],\"ts\":\"1782015924405\",\"checksum\":-1940632662,\"seqId\":325069871157,\"prevSeqId\":325069871079}]}"}
{"action": null, "capture_sequence": 223, "channel": "trades", "connection_sequence": 3, "event": null, "instId": "BTC-USDT-SWAP", "local_receive_ts": "2026-06-21T04:25:24Z", "monotonic_ns": 1643480382222771, "raw": "{\"arg\":{\"channel\":\"trades\",\"instId\":\"BTC-USDT-SWAP\"},\"data\":[{\"instId\":\"BTC-USDT-SWAP\",\"tradeId\":\"2718748884\",\"px\":\"64457.9\",\"sz\":\"5\",\"side\":\"sell\",\"ts\":\"1782015924478\",\"count\":\"1\",\"source\":\"0\",\"seqId\":325069871208}]}"}
{"action": "update", "capture_sequence": 224, "channel": "books", "connection_sequence": 3, "event": null, "instId": "BTC-USDT-SWAP", "local_receive_ts": "2026-06-21T04:25:24Z", "monotonic_ns": 1643480408631949, "raw": "{\"arg\":{\"channel\":\"books\",\"instId\":\"BTC-USDT-SWAP\"},\"action\":\"update\",\"data\":[{\"asks\":[[\"64458\",\"497.91\",\"0\",\"62\"],[\"64458.5\",\"20.54\",\"0\",\"3\"],[\"64458.6\",\"1.56\",\"0\",\"1\"],[\"64459.1\",\"0\",\"0\",\"0\"],[\"64459.3\",\"2.59\",\"0\",\"5\"],[\"64459.7\",\"0\",\"0\",\"0\"],[\"64459.8\",\"1.56\",\"0\",\"1\"],[\"64463.1\",\"6.22\",\"0\",\"2\"],[\"64468.9\",\"0.12\",\"0\",\"1\"]],\"bids\":[[\"64457.9\",\"542.34\",\"0\",\"26\"],[\"64456.9\",\"0\",\"0\",\"0\"],[\"64456.8\",\"0.31\",\"0\",\"1\"],[\"64456.5\",\"0\",\"0\",\"0\"],[\"64456\",\"0.02\",\"0\",\"2\"],[\"64455.9\",\"0.02\",\"0\",\"2\"],[\"64455.8\",\"1.56\",\"0\",\"1\"],[\"64455.4\",\"0.02\",\"0\",\"2\"],[\"64455.3\",\"50.24\",\"0\",\"4\"],[\"64454.9\",\"0\",\"0\",\"0\"],[\"64454.7\",\"38.82\",\"0\",\"4\"],[\"64451.5\",\"17.46\",\"0\",\"2\"],[\"64405.3\",\"46.54\",\"0\",\"1\"],[\"64405.2\",\"6.39\",\"0\",\"4\"]],\"ts\":\"1782015924505\",\"checksum\":845487883,\"seqId\":325069871220,\"prevSeqId\":325069871157}]}"}
{"action": null, "capture_sequence": 225, "channel": "trades", "connection_sequence": 3, "event": null, "instId": "BTC-USDT-SWAP", "local_receive_ts": "2026-06-21T04:25:24Z", "monotonic_ns": 1643480442262250, "raw": "{\"arg\":{\"channel\":\"trades\",\"instId\":\"BTC-USDT-SWAP\"},\"data\":[{\"instId\":\"BTC-USDT-SWAP\",\"tradeId\":\"2718748885\",\"px\":\"64458\",\"sz\":\"2.69\",\"side\":\"buy\",\"ts\":\"1782015924538\",\"count\":\"1\",\"source\":\"0\",\"seqId\":325069871245}]}"}
{"action": "update", "capture_sequence": 226, "channel": "books", "connection_sequence": 3, "event": null, "instId": "BTC-USDT-SWAP", "local_receive_ts": "2026-06-21T04:25:24Z", "monotonic_ns": 1643480508933225, "raw": "{\"arg\":{\"channel\":\"books\",\"instId\":\"BTC-USDT-SWAP\"},\"action\":\"update\",\"data\":[{\"asks\":[[\"64458\",\"493.66\",\"0\",\"61\"],[\"64458.5\",\"20.53\",\"0\",\"2\"],[\"64458.6\",\"0\",\"0\",\"0\"],[\"64459.3\",\"1.03\",\"0\",\"4\"],[\"64459.8\",\"0\",\"0\",\"0\"],[\"64459.9\",\"0.02\",\"0\",\"2\"],[\"64460.2\",\"0.78\",\"0\",\"2\"],[\"64463.1\",\"7.78\",\"0\",\"3\"],[\"64508.5\",\"42.46\",\"0\",\"3\"],[\"64508.6\",\"0.01\",\"0\",\"1\"]],\"bids\":[[\"64456.5\",\"0.01\",\"0\",\"1\"],[\"64455.3\",\"50.23\",\"0\",\"3\"],[\"64451.5\",\"15.9\",\"0\",\"1\"],[\"64411.6\",\"0\",\"0\",\"0\"]],\"ts\":\"1782015924605\",\"checksum\":-1675959852,\"seqId\":325069871261,\"prevSeqId\":325069871220}]}"}
{"action": "update", "capture_sequence": 227, "channel": "books", "connection_sequence": 3, "event": null, "instId": "BTC-USDT-SWAP", "local_receive_ts": "2026-06-21T04:25:24Z", "monotonic_ns": 1643480608184258, "raw": "{\"arg\":{\"channel\":\"books\",\"instId\":\"BTC-USDT-SWAP\"},\"action\":\"update\",\"data\":[{\"asks\":[[\"64460.7\",\"0.01\",\"0\",\"1\"],[\"64461.2\",\"0\",\"0\",\"0\"],[\"64476.6\",\"0\",\"0\",\"0\"],[\"64481.7\",\"0\",\"0\",\"0\"],[\"64481.9\",\"33.81\",\"0\",\"2\"],[\"64484.1\",\"0.02\",\"0\",\"1\"],[\"64484.3\",\"1.08\",\"0\",\"2\"],[\"64486.5\",\"15.65\",\"0\",\"1\"],[\"64486.7\",\"85.38\",\"0\",\"2\"],[\"64492.7\",\"101.08\",\"0\",\"4\"],[\"64492.9\",\"28.08\",\"0\",\"3\"],[\"64508.7\",\"42.88\",\"0\",\"9\"],[\"64508.8\",\"0.04\",\"0\",\"2\"],[\"64508.9\",\"0.04\",\"0\",\"2\"]],\"bids\":[[\"64457.9\",\"553.25\",\"0\",\"28\"],[\"64442.5\",\"20.09\",\"0\",\"1\"],[\"64442.4\",\"0.01\",\"0\",\"1\"],[\"64442.2\",\"0\",\"0\",\"0\"],[\"64442.1\",\"92.42\",\"0\",\"2\"],[\"64441.4\",\"135.45\",\"0\",\"4\"],[\"64441.2\",\"0\",\"0\",\"0\"],[\"64435.6\",\"28.42\",\"0\",\"2\"],[\"64417.4\",\"23.41\",\"0\",\"9\"],[\"64405.1\",\"0.07\",\"0\",\"3\"]],\"ts\":\"1782015924705\",\"checksum\":615193597,\"seqId\":325069871331,\"prevSeqId\":325069871261}]}"}
{"action": "update", "capture_sequence": 228, "channel": "books", "connection_sequence": 3, "event": null, "instId": "BTC-USDT-SWAP", "local_receive_ts": "2026-06-21T04:25:24Z", "monotonic_ns": 1643480708154116, "raw": "{\"arg\":{\"channel\":\"books\",\"instId\":\"BTC-USDT-SWAP\"},\"action\":\"update\",\"data\":[{\"asks\":[[\"64461.7\",\"0\",\"0\",\"0\"],[\"64476.6\",\"0.15\",\"0\",\"1\"],[\"64508.9\",\"11.26\",\"0\",\"3\"]],\"bids\":[[\"64457.9\",\"553.27\",\"0\",\"28\"],[\"64442.4\",\"3.19\",\"0\",\"2\"],[\"64435.6\",\"28.61\",\"0\",\"3\"]],\"ts\":\"1782015924805\",\"checksum\":261199299,\"seqId\":325069871342,\"prevSeqId\":325069871331}]}"}
{"action": "update", "capture_sequence": 229, "channel": "books", "connection_sequence": 3, "event": null, "instId": "BTC-USDT-SWAP", "local_receive_ts": "2026-06-21T04:25:25Z", "monotonic_ns": 1643480808671276, "raw": "{\"arg\":{\"channel\":\"books\",\"instId\":\"BTC-USDT-SWAP\"},\"action\":\"update\",\"data\":[{\"asks\":[[\"64462.2\",\"0\",\"0\",\"0\"],[\"64509\",\"155.92\",\"0\",\"2\"]],\"bids\":[],\"ts\":\"1782015924905\",\"checksum\":-1788947802,\"seqId\":325069871347,\"prevSeqId\":325069871342}]}"}
{"action": null, "capture_sequence": 230, "channel": "trades", "connection_sequence": 3, "event": null, "instId": "BTC-USDT-SWAP", "local_receive_ts": "2026-06-21T04:25:25Z", "monotonic_ns": 1643480841839908, "raw": "{\"arg\":{\"channel\":\"trades\",\"instId\":\"BTC-USDT-SWAP\"},\"data\":[{\"instId\":\"BTC-USDT-SWAP\",\"tradeId\":\"2718748886\",\"px\":\"64457.9\",\"sz\":\"5\",\"side\":\"sell\",\"ts\":\"1782015924939\",\"count\":\"1\",\"source\":\"0\",\"seqId\":325069871374}]}"}
{"action": "update", "capture_sequence": 231, "channel": "books", "connection_sequence": 3, "event": null, "instId": "BTC-USDT-SWAP", "local_receive_ts": "2026-06-21T04:25:25Z", "monotonic_ns": 1643480916736394, "raw": "{\"arg\":{\"channel\":\"books\",\"instId\":\"BTC-USDT-SWAP\"},\"action\":\"update\",\"data\":[{\"asks\":[[\"64458.3\",\"6.61\",\"0\",\"4\"],[\"64458.5\",\"5\",\"0\",\"1\"],[\"64459\",\"0.02\",\"0\",\"2\"],[\"64459.1\",\"15.53\",\"0\",\"1\"],[\"64459.9\",\"0\",\"0\",\"0\"],[\"64460\",\"1.57\",\"0\",\"2\"],[\"64460.4\",\"1.56\",\"0\",\"1\"],[\"64460.8\",\"50.68\",\"0\",\"2\"],[\"64460.9\",\"1.56\",\"0\",\"1\"],[\"64461.1\",\"0.01\",\"0\",\"1\"],[\"64461.4\",\"1.59\",\"0\",\"4\"],[\"64461.6\",\"0.01\",\"0\",\"1\"],[\"64461.7\",\"150\",\"0\",\"1\"],[\"64461.9\",\"1.71\",\"0\",\"2\"],[\"64462.3\",\"1.56\",\"0\",\"1\"],[\"64462.6\",\"0.01\",\"0\",\"1\"],[\"64462.8\",\"1.56\",\"0\",\"1\"],[\"64463.1\",\"6.22\",\"0\",\"2\"],[\"64463.3\",\"2.46\",\"0\",\"2\"],[\"64475.5\",\"31.04\",\"0\",\"1\"],[\"64475.6\",\"0.39\",\"0\",\"2\"],[\"64486.2\",\"0.17\",\"0\",\"6\"],[\"64487.4\",\"58.69\",\"0\",\"6\"],[\"64508.2\",\"0\",\"0\",\"0\"],[\"64508.4\",\"0\",\"0\",\"0\"],[\"64508.5\",\"0\",\"0\",\"0\"],[\"64508.6\",\"0\",\"0\",\"0\"],[\"64508.7\",\"0\",\"0\",\"0\"],[\"64508.8\",\"0\",\"0\",\"0\"],[\"64508.9\",\"0\",\"0\",\"0\"],[\"64509\",\"0\",\"0\",\"0\"]],\"bids\":[[\"64457.9\",\"549.83\",\"0\",\"29\"],[\"64456.5\",\"0\",\"0\",\"0\"],[\"64456.4\",\"0.01\",\"0\",\"1\"],[\"64455.3\",\"50.24\",\"0\",\"4\"],[\"64454\",\"9.88\",\"0\",\"4\"],[\"64453.9\",\"0.01\",\"0\",\"1\"],[\"64452.1\",\"78.37\",\"0\",\"5\"],[\"64451.8\",\"0.01\",\"0\",\"1\"],[\"64441.8\",\"535.37\",\"0\",\"3\"],[\"64441.7\",\"0\",\"0\",\"0\"],[\"64439\",\"58.26\",\"0\",\"2\"],[\"64438.9\",\"37.25\",\"0\",\"2\"],[\"64438.8\",\"0\",\"0\",\"0\"],[\"64438.7\",\"3.99\",\"0\",\"1\"],[\"64438.6\",\"43.84\",\"0\",\"5\"],[\"64438.2\",\"0.01\",\"0\",\"1\"],[\"64433\",\"4.08\",\"0\",\"3\"],[\"64432.5\",\"0.01\",\"0\",\"1\"],[\"64405\",\"13.52\",\"0\",\"15\"],[\"64404.8\",\"0.04\",\"0\",\"1\"],[\"64404.7\",\"0.77\",\"0\",\"1\"]],\"ts\":\"1782015925005\",\"checksum\":597895096,\"seqId\":325069871438,\"prevSeqId\":325069871347}]}"}
{"action": "update", "capture_sequence": 232, "channel": "books", "connection_sequence": 3, "event": null, "instId": "BTC-USDT-SWAP", "local_receive_ts": "2026-06-21T04:25:25Z", "monotonic_ns": 1643481008707222, "raw": "{\"arg\":{\"channel\":\"books\",\"instId\":\"BTC-USDT-SWAP\"},\"action\":\"update\",\"data\":[{\"asks\":[[\"64458.3\",\"7.54\",\"0\",\"4\"],[\"64458.6\",\"0.01\",\"0\",\"1\"],[\"64458.7\",\"15.53\",\"0\",\"1\"],[\"64459\",\"0.01\",\"0\",\"1\"],[\"64459.1\",\"0\",\"0\",\"0\"],[\"64475.5\",\"0\",\"0\",\"0\"],[\"64475.6\",\"31.43\",\"0\",\"3\"],[\"64486.2\",\"58.37\",\"0\",\"7\"],[\"64486.7\",\"0.01\",\"0\",\"1\"],[\"64487.4\",\"85.86\",\"0\",\"6\"]],\"bids\":[[\"64457.9\",\"548.27\",\"0\",\"28\"],[\"64457.8\",\"1.7\",\"0\",\"3\"],[\"64457.4\",\"0.32\",\"0\",\"2\"],[\"64457.3\",\"1.56\",\"0\",\"1\"],[\"64455.3\",\"50.23\",\"0\",\"3\"],[\"64453.2\",\"3.1\",\"0\",\"1\"],[\"64451.2\",\"377.55\",\"0\",\"4\"],[\"64441.7\",\"85.43\",\"0\",\"1\"],[\"64441.4\",\"50.02\",\"0\",\"3\"],[\"64439\",\"0.01\",\"0\",\"1\"],[\"64438.7\",\"35.05\",\"0\",\"2\"],[\"64438.6\",\"12.78\",\"0\",\"4\"],[\"64438.2\",\"58.26\",\"0\",\"2\"],[\"64405\",\"0\",\"0\",\"0\"],[\"64404.8\",\"0\",\"0\",\"0\"],[\"64404.7\",\"0\",\"0\",\"0\"]],\"ts\":\"1782015925105\",\"checksum\":633100122,\"seqId\":325069871514,\"prevSeqId\":325069871438}]}"}
{"action": "update", "capture_sequence": 233, "channel": "books", "connection_sequence": 3, "event": null, "instId": "BTC-USDT-SWAP", "local_receive_ts": "2026-06-21T04:25:25Z", "monotonic_ns": 1643481108510665, "raw": "{\"arg\":{\"channel\":\"books\",\"instId\":\"BTC-USDT-SWAP\"},\"action\":\"update\",\"data\":[{\"asks\":[[\"64458\",\"493.76\",\"0\",\"62\"],[\"64459.2\",\"1.57\",\"0\",\"2\"],[\"64459.8\",\"1.56\",\"0\",\"1\"],[\"64460\",\"0.01\",\"0\",\"1\"],[\"64463.8\",\"1.57\",\"0\",\"2\"],[\"64467\",\"63.9\",\"0\",\"3\"],[\"64467.1\",\"0\",\"0\",\"0\"],[\"64492.9\",\"8.01\",\"0\",\"2\"],[\"64493.4\",\"20.39\",\"0\",\"6\"]],\"bids\":[[\"64457.9\",\"549.82\",\"0\",\"29\"],[\"64457.8\",\"0.14\",\"0\",\"2\"],[\"64457.4\",\"0.31\",\"0\",\"1\"],[\"64457.3\",\"0.01\",\"0\",\"1\"],[\"64457.2\",\"1.56\",\"0\",\"1\"],[\"64454\",\"9.57\",\"0\",\"3\"],[\"64453.9\",\"0.32\",\"0\",\"2\"],[\"64452.1\",\"0.8\",\"0\",\"4\"],[\"64451.8\",\"77.58\",\"0\",\"2\"],[\"64443.3\",\"216.32\",\"0\",\"5\"],[\"64442.9\",\"20.09\",\"0\",\"1\"],[\"64442.5\",\"0\",\"0\",\"0\"],[\"64442.1\",\"6.22\",\"0\",\"1\"],[\"64433\",\"4.07\",\"0\",\"2\"],[\"64432.5\",\"0.02\",\"0\",\"2\"],[\"64405.1\",\"0\",\"0\",\"0\"]],\"ts\":\"1782015925205\",\"checksum\":-365433900,\"seqId\":325069871574,\"prevSeqId\":325069871514}]}"}
{"action": "update", "capture_sequence": 234, "channel": "books", "connection_sequence": 3, "event": null, "instId": "BTC-USDT-SWAP", "local_receive_ts": "2026-06-21T04:25:25Z", "monotonic_ns": 1643481208847311, "raw": "{\"arg\":{\"channel\":\"books\",\"instId\":\"BTC-USDT-SWAP\"},\"action\":\"update\",\"data\":[{\"asks\":[[\"64458.9\",\"1.56\",\"0\",\"1\"],[\"64459.2\",\"0.01\",\"0\",\"1\"],[\"64459.3\",\"2.59\",\"0\",\"5\"],[\"64463.8\",\"0.01\",\"0\",\"1\"],[\"64508.1\",\"0\",\"0\",\"0\"]],\"bids\":[],\"ts\":\"1782015925305\",\"checksum\":531046826,\"seqId\":325069871588,\"prevSeqId\":325069871574}]}"}
{"action": null, "capture_sequence": 235, "channel": "trades", "connection_sequence": 3, "event": null, "instId": "BTC-USDT-SWAP", "local_receive_ts": "2026-06-21T04:25:25Z", "monotonic_ns": 1643481296187681, "raw": "{\"arg\":{\"channel\":\"trades\",\"instId\":\"BTC-USDT-SWAP\"},\"data\":[{\"instId\":\"BTC-USDT-SWAP\",\"tradeId\":\"2718748887\",\"px\":\"64457.9\",\"sz\":\"5\",\"side\":\"sell\",\"ts\":\"1782015925393\",\"count\":\"1\",\"source\":\"0\",\"seqId\":325069871606}]}"}
{"action": "update", "capture_sequence": 236, "channel": "books", "connection_sequence": 3, "event": null, "instId": "BTC-USDT-SWAP", "local_receive_ts": "2026-06-21T04:25:25Z", "monotonic_ns": 1643481309082408, "raw": "{\"arg\":{\"channel\":\"books\",\"instId\":\"BTC-USDT-SWAP\"},\"action\":\"update\",\"data\":[{\"asks\":[[\"64458.6\",\"0.02\",\"0\",\"2\"],[\"64459\",\"0\",\"0\",\"0\"],[\"64459.3\",\"1.03\",\"0\",\"4\"],[\"64459.5\",\"1.57\",\"0\",\"2\"],[\"64459.8\",\"0\",\"0\",\"0\"],[\"64459.9\",\"1.56\",\"0\",\"1\"],[\"64463.3\",\"0.9\",\"0\",\"1\"],[\"64476.6\",\"0\",\"0\",\"0\"],[\"64508.1\",\"21.31\",\"0\",\"3\"],[\"64508.2\",\"59.01\",\"0\",\"5\"]],\"bids\":[[\"64457.9\",\"544.82\",\"0\",\"29\"],[\"64457.2\",\"0\",\"0\",\"0\"],[\"64456.6\",\"1.63\",\"0\",\"2\"],[\"64442.4\",\"0.01\",\"0\",\"1\"],[\"64435.6\",\"28.42\",\"0\",\"2\"],[\"64405.1\",\"0.07\",\"0\",\"3\"]],\"ts\":\"1782015925405\",\"checksum\":-758101127,\"seqId\":325069871615,\"prevSeqId\":325069871588}]}"}
{"action": "update", "capture_sequence": 237, "channel": "books", "connection_sequence": 3, "event": null, "instId": "BTC-USDT-SWAP", "local_receive_ts": "2026-06-21T04:25:25Z", "monotonic_ns": 1643481408700397, "raw": "{\"arg\":{\"channel\":\"books\",\"instId\":\"BTC-USDT-SWAP\"},\"action\":\"update\",\"data\":[{\"asks\":[[\"64458.9\",\"0\",\"0\",\"0\"],[\"64459.5\",\"0.01\",\"0\",\"1\"],[\"64459.9\",\"0\",\"0\",\"0\"],[\"64460.4\",\"0\",\"0\",\"0\"],[\"64460.9\",\"0\",\"0\",\"0\"],[\"64464.6\",\"0.01\",\"0\",\"1\"],[\"64467\",\"63.88\",\"0\",\"2\"],[\"64467.1\",\"0.02\",\"0\",\"1\"],[\"64475.5\",\"31.04\",\"0\",\"1\"],[\"64475.6\",\"0.39\",\"0\",\"2\"],[\"64476.6\",\"0.16\",\"0\",\"1\"],[\"64486.2\",\"0.17\",\"0\",\"6\"],[\"64486.9\",\"58.32\",\"0\",\"3\"],[\"64508.4\",\"1367.19\",\"0\",\"6\"]],\"bids\":[[\"64457.9\",\"543.26\",\"0\",\"28\"],[\"64457.3\",\"0\",\"0\",\"0\"],[\"64456.6\",\"0.07\",\"0\",\"1\"],[\"64455.9\",\"0.01\",\"0\",\"1\"],[\"64455.8\",\"0\",\"0\",\"0\"],[\"64455.3\",\"50.24\",\"0\",\"4\"],[\"64454.8\",\"0.02\",\"0\",\"2\"],[\"64452\",\"76.66\",\"0\",\"4\"],[\"64442.3\",\"21.25\",\"0\",\"3\"],[\"64439\",\"58.26\",\"0\",\"2\"],[\"64438.7\",\"3.99\",\"0\",\"1\"],[\"64438.2\",\"31.07\",\"0\",\"2\"],[\"64435.5\",\"512.4\",\"0\",\"4\"],[\"64405\",\"13.52\",\"0\",\"15\"],[\"64404.8\",\"0.04\",\"0\",\"1\"]],\"ts\":\"1782015925505\",\"checksum\":-819696673,\"seqId\":325069871684,\"prevSeqId\":325069871615}]}"}
{"action": null, "capture_sequence": 238, "channel": "trades", "connection_sequence": 3, "event": null, "instId": "BTC-USDT-SWAP", "local_receive_ts": "2026-06-21T04:25:25Z", "monotonic_ns": 1643481504451784, "raw": "{\"arg\":{\"channel\":\"trades\",\"instId\":\"BTC-USDT-SWAP\"},\"data\":[{\"instId\":\"BTC-USDT-SWAP\",\"tradeId\":\"2718748888\",\"px\":\"64457.9\",\"sz\":\"3.17\",\"side\":\"sell\",\"ts\":\"1782015925601\",\"count\":\"1\",\"source\":\"0\",\"seqId\":325069871729}]}"}
{"action": "update", "capture_sequence": 239, "channel": "books", "connection_sequence": 3, "event": null, "instId": "BTC-USDT-SWAP", "local_receive_ts": "2026-06-21T04:25:25Z", "monotonic_ns": 1643481508524596, "raw": "{\"arg\":{\"channel\":\"books\",\"instId\":\"BTC-USDT-SWAP\"},\"action\":\"update\",\"data\":[{\"asks\":[[\"64461.4\",\"0.03\",\"0\",\"3\"],[\"64481.9\",\"0.01\",\"0\",\"1\"],[\"64483.2\",\"148.5\",\"0\",\"5\"],[\"64483.8\",\"0.77\",\"0\",\"1\"],[\"64484.3\",\"0.31\",\"0\",\"1\"],[\"64486.9\",\"0.12\",\"0\",\"2\"],[\"64487.4\",\"0.49\",\"0\",\"5\"],[\"64487.9\",\"58.21\",\"0\",\"2\"],[\"64488.1\",\"86.03\",\"0\",\"3\"],[\"64492.5\",\"0.06\",\"0\",\"4\"],[\"64493.1\",\"117.89\",\"0\",\"6\"],[\"64493.4\",\"0.32\",\"0\",\"5\"],[\"64494.3\",\"37.3\",\"0\",\"7\"],[\"64508.4\",\"0\",\"0\",\"0\"]],\"bids\":[[\"64457.9\",\"540.09\",\"0\",\"28\"],[\"64454\",\"9.88\",\"0\",\"4\"],[\"64453.9\",\"0.01\",\"0\",\"1\"],[\"64452.1\",\"78.37\",\"0\",\"5\"],[\"64451.8\",\"0.01\",\"0\",\"1\"],[\"64445.2\",\"0\",\"0\",\"0\"],[\"64444.5\",\"34.59\",\"0\",\"2\"],[\"64443.8\",\"20.09\",\"0\",\"1\"],[\"64443.5\",\"86.2\",\"0\",\"1\"],[\"64443.3\",\"130.12\",\"0\",\"4\"],[\"64442.9\",\"0\",\"0\",\"0\"],[\"64442.8\",\"85.45\",\"0\",\"4\"],[\"64442.7\",\"0\",\"0\",\"0\"],[\"64441.7\",\"0\",\"0\",\"0\"],[\"64439.8\",\"58.25\",\"0\",\"1\"],[\"64439\",\"0.01\",\"0\",\"1\"],[\"64438.8\",\"31.06\",\"0\",\"1\"],[\"64438.2\",\"0.01\",\"0\",\"1\"],[\"64404.8\",\"0\",\"0\",\"0\"]],\"ts\":\"1782015925605\",\"checksum\":-1369250113,\"seqId\":325069871729,\"prevSeqId\":325069871684}]}"}
{"action": null, "capture_sequence": 240, "channel": "trades", "connection_sequence": 3, "event": null, "instId": "BTC-USDT-SWAP", "local_receive_ts": "2026-06-21T04:25:25Z", "monotonic_ns": 1643481556199341, "raw": "{\"arg\":{\"channel\":\"trades\",\"instId\":\"BTC-USDT-SWAP\"},\"data\":[{\"instId\":\"BTC-USDT-SWAP\",\"tradeId\":\"2718748889\",\"px\":\"64457.9\",\"sz\":\"1\",\"side\":\"sell\",\"ts\":\"1782015925652\",\"count\":\"1\",\"source\":\"0\",\"seqId\":325069871743}]}"}
{"action": null, "capture_sequence": 241, "channel": "trades", "connection_sequence": 4, "event": "subscribe", "instId": "BTC-USDT-SWAP", "local_receive_ts": "2026-06-21T04:25:26Z", "monotonic_ns": 1643482756494701, "raw": "{\"event\":\"subscribe\",\"arg\":{\"channel\":\"trades\",\"instId\":\"BTC-USDT-SWAP\"},\"connId\":\"08b7770a\"}"}
{"action": null, "capture_sequence": 242, "channel": "books", "connection_sequence": 4, "event": "subscribe", "instId": "BTC-USDT-SWAP", "local_receive_ts": "2026-06-21T04:25:26Z", "monotonic_ns": 1643482756678143, "raw": "{\"event\":\"subscribe\",\"arg\":{\"channel\":\"books\",\"instId\":\"BTC-USDT-SWAP\"},\"connId\":\"08b7770a\"}"}
{"action": null, "capture_sequence": 243, "channel": "trades", "connection_sequence": 4, "event": null, "instId": "BTC-USDT-SWAP", "local_receive_ts": "2026-06-21T04:25:27Z", "monotonic_ns": 1643482801736052, "raw": "{\"arg\":{\"channel\":\"trades\",\"instId\":\"BTC-USDT-SWAP\"},\"data\":[{\"instId\":\"BTC-USDT-SWAP\",\"tradeId\":\"2718748897\",\"px\":\"64457.9\",\"sz\":\"0.01\",\"side\":\"sell\",\"ts\":\"1782015926899\",\"count\":\"1\",\"source\":\"0\",\"seqId\":325069872331}]}"}
{"action": null, "capture_sequence": 244, "channel": "trades", "connection_sequence": 4, "event": null, "instId": "BTC-USDT-SWAP", "local_receive_ts": "2026-06-21T04:25:27Z", "monotonic_ns": 1643482897970604, "raw": "{\"arg\":{\"channel\":\"trades\",\"instId\":\"BTC-USDT-SWAP\"},\"data\":[{\"instId\":\"BTC-USDT-SWAP\",\"tradeId\":\"2718748898\",\"px\":\"64457.9\",\"sz\":\"0.01\",\"side\":\"sell\",\"ts\":\"1782015926996\",\"count\":\"1\",\"source\":\"0\",\"seqId\":325069872351}]}"}
