{"action": null, "capture_sequence": 1, "channel": "trades", "event": "subscribe", "instId": "BTC-USDT-SWAP", "local_receive_ts": "2026-06-20T17:44:01Z", "monotonic_ns": 1604997114700546, "raw": "{\"event\":\"subscribe\",\"arg\":{\"channel\":\"trades\",\"instId\":\"BTC-USDT-SWAP\"},\"connId\":\"b64f224d\"}"}
{"action": null, "capture_sequence": 2, "channel": "books", "event": "subscribe", "instId": "BTC-USDT-SWAP", "local_receive_ts": "2026-06-20T17:44:01Z", "monotonic_ns": 1604997114907405, "raw": "{\"event\":\"subscribe\",\"arg\":{\"channel\":\"books\",\"instId\":\"BTC-USDT-SWAP\"},\"connId\":\"b64f224d\"}"}
{"action": "snapshot", "capture_sequence": 3, "channel": "books", "event": null, "instId": "BTC-USDT-SWAP", "local_receive_ts": "2026-06-20T17:44:01Z", "monotonic_ns": 1604997363141341, "raw": "{\"arg\":{\"channel\":\"books\",\"instId\":\"BTC-USDT-SWAP\"},\"action\":\"snapshot\",\"data\":[{\"asks\":[[\"63836.9\",\"437.08\",\"0\",\"32\"],[\"63837\",\"7.84\",\"0\",\"2\"],[\"63837.1\",\"0.04\",\"0\",\"1\"],[\"63837.3\",\"0.02\",\"0\",\"2\"],[\"63837.4\",\"1.58\",\"0\",\"2\"],[\"63837.5\",\"0.2\",\"0\",\"1\"],[\"63837.6\",\"0.02\",\"0\",\"2\"],[\"63837.7\",\"206.86\",\"0\",\"6\"],[\"63837.8\",\"3.24\",\"0\",\"3\"],[\"63838.1\",\"0.01\",\"0\",\"1\"],[\"63838.2\",\"0.01\",\"0\",\"1\"],[\"63838.3\",\"1.6\",\"0\",\"4\"],[\"63838.4\",\"0.61\",\"0\",\"2\"],[\"63838.8\",\"0.03\",\"0\",\"3\"],[\"63838.9\",\"1.57\",\"0\",\"1\"],[\"63839.1\",\"0.04\",\"0\",\"3\"],[\"63839.2\",\"0.6\",\"0\",\"1\"],[\"63839.3\",\"0.01\",\"0\",\"1\"],[\"63839.4\",\"1.57\",\"0\",\"1\"],[\"63839.6\",\"0.01\",\"0\",\"1\"],[\"63839.7\",\"0.03\",\"0\",\"1\"],[\"63839.9\",\"1.58\",\"0\",\"2\"],[\"63840\",\"0.69\",\"0\",\"5\"],[\"63840.1\",\"0.01\",\"0\",\"1\"],[\"63840.3\",\"0.01\",\"0\",\"1\"],[\"63840.4\",\"1.58\",\"0\",\"2\"],[\"63840.6\",\"0.01\",\"0\",\"1\"],[\"63840.7\",\"72.02\",\"0\",\"3\"],[\"63840.8\",\"0.01\",\"0\",\"1\"],[\"63841\",\"0.01\",\"0\",\"1\"],[\"63841.1\",\"0.02\",\"0\",\"2\"],[\"63841.2\",\"1.58\",\"0\",\"2\"],[\"63841.4\",\"0.05\",\"0\",\"5\"],[\"63841.6\",\"0.01\",\"0\",\"1\"],[\"63841.7\",\"1.57\",\"0\",\"1\"],[\"63841.8\",\"0.01\",\"0\",\"1\"],[\"63842.2\",\"0.01\",\"0\",\"1\"],[\"63842.4\",\"0.78\",\"0\",\"1\"],[\"63842.5\",\"1.57\",\"0\",\"1\"],[\"63842.6\",\"0.01\",\"0\",\"1\"],[\"63842.8\",\"0.01\",\"0\",\"1\"],[\"63842.9\",\"11.12\",\"0\",\"2\"],[\"63843\",\"1.59\",\"0\",\"3\"],[\"63843.2\",\"213.94\",\"0\",\"3\"],[\"63843.3\",\"74.74\",\"0\",\"3\"],[\"63843.5\",\"0.27\",\"0\",\"1\"],[\"63843.6\",\"0.01\",\"0\",\"1\"],[\"63843.7\",\"0.01\",\"0\",\"1\"],[\"63843.9\",\"0.42\",\"0\",\"2\"],[\"63844\",\"12.02\",\"0\",\"4\"],[\"63844.2\",\"3\",\"0\",\"1\"],[\"63844.5\",\"0.02\",\"0\",\"2\"],[\"63844.6\",\"80.37\",\"0\",\"6\"],[\"63844.7\",\"4\",\"0\",\"1\"],[\"63845\",\"63.74\",\"0\",\"2\"],[\"63845.1\",\"5.3\",\"0\",\"2\"],[\"63845.3\",\"0.79\",\"0\",\"2\"],[\"63845.5\",\"0.03\",\"0\",\"2\"],[\"63845.6\",\"0.01\",\"0\",\"1\"],[\"63845.7\",\"2.76\",\"0\",\"1\"],[\"63845.9\",\"12.02\",\"0\",\"4\"],[\"63846\",\"0.02\",\"0\",\"2\"],[\"63846.1\",\"2.94\",\"0\",\"2\"],[\"63846.2\",\"62.77\",\"0\",\"2\"],[\"63846.3\",\"37.97\",\"0\",\"2\"],[\"63846.4\",\"262.89\",\"0\",\"2\"],[\"63846.5\",\"21.77\",\"0\",\"4\"],[\"63846.6\",\"20.57\",\"0\",\"4\"],[\"63846.7\",\"3.14\",\"0\",\"2\"],[\"63847\",\"2.65\",\"0\",\"2\"],[\"63847.2\",\"0.01\",\"0\",\"1\"],[\"63847.3\",\"2.52\",\"0\",\"1\"],[\"63847.4\",\"4.01\",\"0\",\"2\"],[\"63847.6\",\"0.03\",\"0\",\"3\"],[\"63847.7\",\"1.65\",\"0\",\"1\"],[\"63847.8\",\"8\",\"0\",\"1\"],[\"63847.9\",\"0.01\",\"0\",\"1\"],[\"63848\",\"0.01\",\"0\",\"1\"],[\"63848.1\",\"0.01\",\"0\",\"1\"],[\"63848.2\",\"16.1\",\"0\",\"3\"],[\"63848.3\",\"0.02\",\"0\",\"2\"],[\"63848.5\",\"47.35\",\"0\",\"2\"],[\"63848.6\",\"0.02\",\"0\",\"2\"],[\"63848.9\",\"57.27\",\"0\",\"3\"],[\"63849\",\"5.72\",\"0\",\"3\"],[\"63849.2\",\"12.11\",\"0\",\"4\"],[\"63849.3\",\"150.36\",\"0\",\"1\"],[\"63849.4\",\"62.77\",\"0\",\"2\"],[\"63849.5\",\"159.86\",\"0\",\"2\"],[\"63849.6\",\"627.42\",\"0\",\"6\"],[\"63849.7\",\"168.92\",\"0\",\"4\"],[\"63849.8\",\"16.26\",\"0\",\"3\"],[\"63849.9\",\"0.6\",\"0\",\"1\"],[\"63850\",\"54.02\",\"0\",\"23\"],[\"63850.4\",\"0.01\",\"0\",\"1\"],[\"63850.5\",\"1.1\",\"0\",\"1\"],[\"63850.7\",\"0.02\",\"0\",\"2\"],[\"63850.8\",\"0.15\",\"0\",\"3\"],[\"63851\",\"50.96\",\"0\",\"4\"],[\"63851.2\",\"0.01\",\"0\",\"1\"],[\"63851.3\",\"0.01\",\"0\",\"1\"],[\"63851.4\",\"67.11\",\"0\",\"4\"],[\"63851.5\",\"31.39\",\"0\",\"1\"],[\"63851.6\",\"0.41\",\"0\",\"1\"],[\"63851.8\",\"0.01\",\"0\",\"1\"],[\"63851.9\",\"0.02\",\"0\",\"1\"],[\"63852\",\"1.18\",\"0\",\"4\"],[\"63852.1\",\"15.66\",\"0\",\"1\"],[\"63852.2\",\"54.24\",\"0\",\"1\"],[\"63852.3\",\"10.5\",\"0\",\"1\"],[\"63852.4\",\"0.01\",\"0\",\"1\"],[\"63852.6\",\"38.16\",\"0\",\"2\"],[\"63852.7\",\"191.2\",\"0\",\"4\"],[\"63852.8\",\"3.92\",\"0\",\"3\"],[\"63852.9\",\"39.22\",\"0\",\"1\"],[\"63853\",\"368.57\",\"0\",\"3\"],[\"63853.2\",\"70.57\",\"0\",\"1\"],[\"63853.3\",\"0.01\",\"0\",\"1\"],[\"63853.4\",\"86.22\",\"0\",\"2\"],[\"63853.5\",\"79.1\",\"0\",\"2\"],[\"63853.6\",\"47.09\",\"0\",\"3\"],[\"63853.7\",\"0.15\",\"0\",\"1\"],[\"63853.8\",\"20.33\",\"0\",\"6\"],[\"63853.9\",\"101.95\",\"0\",\"2\"],[\"63854.2\",\"0.02\",\"0\",\"2\"],[\"63854.5\",\"0.01\",\"0\",\"1\"],[\"63854.6\",\"0.02\",\"0\",\"2\"],[\"63854.7\",\"0.01\",\"0\",\"1\"],[\"63854.8\",\"442.08\",\"0\",\"3\"],[\"63854.9\",\"39.27\",\"0\",\"3\"],[\"63855.1\",\"0.01\",\"0\",\"1\"],[\"63855.2\",\"2.36\",\"0\",\"1\"],[\"63855.4\",\"0.01\",\"0\",\"1\"],[\"63855.5\",\"235.12\",\"0\",\"1\"],[\"63855.6\",\"90.11\",\"0\",\"2\"],[\"63855.7\",\"68.15\",\"0\",\"2\"],[\"63855.8\",\"0.01\",\"0\",\"1\"],[\"63855.9\",\"62.77\",\"0\",\"2\"],[\"63856\",\"268.22\",\"0\",\"5\"],[\"63856.2\",\"0.01\",\"0\",\"1\"],[\"63856.3\",\"2.28\",\"0\",\"1\"],[\"63856.4\",\"0.01\",\"0\",\"1\"],[\"63856.6\",\"85.84\",\"0\",\"4\"],[\"63856.7\",\"80.19\",\"0\",\"1\"],[\"63856.8\",\"15.89\",\"0\",\"3\"],[\"63856.9\",\"0.02\",\"0\",\"2\"],[\"63857\",\"79.07\",\"0\",\"1\"],[\"63857.1\",\"0.15\",\"0\",\"1\"],[\"63857.2\",\"0.01\",\"0\",\"1\"],[\"63857.3\",\"53.87\",\"0\",\"1\"],[\"63857.4\",\"0.01\",\"0\",\"1\"],[\"63857.6\",\"55.1\",\"0\",\"2\"],[\"63857.9\",\"0.01\",\"0\",\"1\"],[\"63858\",\"0.01\",\"0\",\"1\"],[\"63858.1\",\"17.07\",\"0\",\"1\"],[\"63858.2\",\"37.7\",\"0\",\"2\"],[\"63858.3\",\"10.42\",\"0\",\"3\"],[\"63858.4\",\"15.88\",\"0\",\"2\"],[\"63858.6\",\"0.02\",\"0\",\"2\"],[\"63858.7\",\"407.95\",\"0\",\"3\"],[\"63858.8\",\"0.32\",\"0\",\"2\"],[\"63858.9\",\"15.81\",\"0\",\"3\"],[\"63859\",\"0.02\",\"0\",\"2\"],[\"63859.1\",\"62.77\",\"0\",\"2\"],[\"63859.2\",\"0.02\",\"0\",\"2\"],[\"63859.3\",\"0.12\",\"0\",\"2\"],[\"63859.4\",\"1.36\",\"0\",\"1\"],[\"63859.5\",\"0.05\",\"0\",\"2\"],[\"63859.6\",\"128.56\",\"0\",\"2\"],[\"63859.7\",\"15.88\",\"0\",\"2\"],[\"63859.8\",\"0.01\",\"0\",\"1\"],[\"63859.9\",\"15.89\",\"0\",\"3\"],[\"63860\",\"1.63\",\"0\",\"22\"],[\"63860.1\",\"5.64\",\"0\",\"1\"],[\"63860.2\",\"0.04\",\"0\",\"4\"],[\"63860.3\",\"0.13\",\"0\",\"4\"],[\"63860.5\",\"80.73\",\"0\",\"1\"],[\"63860.7\",\"15.87\",\"0\",\"1\"],[\"63860.8\",\"7.07\",\"0\",\"2\"],[\"63860.9\",\"79.85\",\"0\",\"2\"],[\"63861\",\"16.65\",\"0\",\"2\"],[\"63861.1\",\"0.09\",\"0\",\"5\"],[\"63861.2\",\"0.01\",\"0\",\"1\"],[\"63861.3\",\"54.47\",\"0\",\"1\"],[\"63861.4\",\"0.01\",\"0\",\"1\"],[\"63861.5\",\"20.89\",\"0\",\"4\"],[\"63861.7\",\"10.4\",\"0\",\"2\"],[\"63861.8\",\"0.09\",\"0\",\"1\"],[\"63861.9\",\"0.01\",\"0\",\"1\"],[\"63862\",\"39.24\",\"0\",\"3\"],[\"63862.1\",\"0.04\",\"0\",\"4\"],[\"63862.2\",\"70.01\",\"0\",\"2\"],[\"63862.3\",\"18.78\",\"0\",\"3\"],[\"63862.4\",\"65.93\",\"0\",\"6\"],[\"63862.5\",\"228.8\",\"0\",\"6\"],[\"63862.6\",\"167.76\",\"0\",\"10\"],[\"63862.7\",\"0.19\",\"0\",\"4\"],[\"63862.8\",\"0.02\",\"0\",\"2\"],[\"63862.9\",\"486.49\",\"0\",\"4\"],[\"63863\",\"37.9\",\"0\",\"1\"],[\"63863.1\",\"15.9\",\"0\",\"4\"],[\"63863.3\",\"12.89\",\"0\",\"2\"],[\"63863.4\",\"37.66\",\"0\",\"1\"],[\"63863.5\",\"0.01\",\"0\",\"1\"],[\"63863.6\",\"0.95\",\"0\",\"4\"],[\"63863.8\",\"0.01\",\"0\",\"1\"],[\"63863.9\",\"16.9\",\"0\",\"5\"],[\"63864\",\"0.05\",\"0\",\"3\"],[\"63864.1\",\"4.83\",\"0\",\"1\"],[\"63864.2\",\"15.87\",\"0\",\"1\"],[\"63864.3\",\"0.02\",\"0\",\"2\"],[\"63864.4\",\"83.34\",\"0\",\"4\"],[\"63864.5\",\"0.01\",\"0\",\"1\"],[\"63864.7\",\"0.03\",\"0\",\"2\"],[\"63864.8\",\"215.05\",\"0\",\"4\"],[\"63864.9\",\"10.95\",\"0\",\"3\"],[\"63865\",\"0.45\",\"0\",\"5\"],[\"63865.1\",\"0.12\",\"0\",\"4\"],[\"63865.2\",\"0.01\",\"0\",\"1\"],[\"63865.4\",\"0.04\",\"0\",\"3\"],[\"63865.6\",\"0.03\",\"0\",\"3\"],[\"63865.7\",\"47.02\",\"0\",\"4\"],[\"63865.8\",\"115.66\",\"0\",\"4\"],[\"63865.9\",\"0.01\",\"0\",\"1\"],[\"63866\",\"5.08\",\"0\",\"4\"],[\"63866.1\",\"16.05\",\"0\",\"4\"],[\"63866.2\",\"0.03\",\"0\",\"3\"],[\"63866.3\",\"22.63\",\"0\",\"4\"],[\"63866.4\",\"0.07\",\"0\",\"1\"],[\"63866.5\",\"0.01\",\"0\",\"1\"],[\"63866.7\",\"1.08\",\"0\",\"39\"],[\"63866.9\",\"0.02\",\"0\",\"2\"],[\"63867\",\"0.1\",\"0\",\"4\"],[\"63867.1\",\"0.07\",\"0\",\"1\"],[\"63867.2\",\"0.02\",\"0\",\"2\"],[\"63867.3\",\"7.06\",\"0\",\"1\"],[\"63867.4\",\"15.92\",\"0\",\"5\"],[\"63867.5\",\"0.01\",\"0\",\"1\"],[\"63867.6\",\"0.02\",\"0\",\"2\"],[\"63867.7\",\"0.01\",\"0\",\"1\"],[\"63868\",\"0.02\",\"0\",\"1\"],[\"63868.1\",\"0.1\",\"0\",\"2\"],[\"63868.2\",\"0.04\",\"0\",\"2\"],[\"63868.3\",\"0.02\",\"0\",\"2\"],[\"63868.4\",\"66.11\",\"0\",\"4\"],[\"63868.5\",\"146.43\",\"0\",\"4\"],[\"63868.6\",\"2.11\",\"0\",\"3\"],[\"63868.7\",\"0.01\",\"0\",\"1\"],[\"63868.8\",\"157.26\",\"0\",\"7\"],[\"63868.9\",\"0.01\",\"0\",\"1\"],[\"63869\",\"3.29\",\"0\",\"3\"],[\"63869.2\",\"0.01\",\"0\",\"1\"],[\"63869.3\",\"16.64\",\"0\",\"4\"],[\"63869.4\",\"257.88\",\"0\",\"5\"],[\"63869.5\",\"24.83\",\"0\",\"2\"],[\"63869.6\",\"0.82\",\"0\",\"7\"],[\"63869.7\",\"0.09\",\"0\",\"4\"],[\"63869.8\",\"0.05\",\"0\",\"2\"],[\"63869.9\",\"0.11\",\"0\",\"1\"],[\"63870\",\"4.76\",\"0\",\"8\"],[\"63870.1\",\"0.7\",\"0\",\"2\"],[\"63870.2\",\"0.3\",\"0\",\"2\"],[\"63870.3\",\"0.36\",\"0\",\"1\"],[\"63870.5\",\"86.98\",\"0\",\"2\"],[\"63870.6\",\"423.78\",\"0\",\"5\"],[\"63870.7\",\"0.2\",\"0\",\"3\"],[\"63870.8\",\"0.05\",\"0\",\"2\"],[\"63870.9\",\"0.06\",\"0\",\"2\"],[\"63871\",\"0.88\",\"0\",\"5\"],[\"63871.1\",\"80.06\",\"0\",\"4\"],[\"63871.2\",\"0.02\",\"0\",\"2\"],[\"63871.4\",\"0.01\",\"0\",\"1\"],[\"63871.5\",\"62.76\",\"0\",\"1\"],[\"63871.6\",\"3.9\",\"0\",\"1\"],[\"63871.7\",\"71.01\",\"0\",\"5\"],[\"63871.9\",\"0.1\",\"0\",\"3\"],[\"63872\",\"0.58\",\"0\",\"27\"],[\"63872.1\",\"0.01\",\"0\",\"1\"],[\"63872.2\",\"0.05\",\"0\",\"1\"],[\"63872.3\",\"0.15\",\"0\",\"1\"],[\"63872.4\",\"0.05\",\"0\",\"3\"],[\"63872.5\",\"0.01\",\"0\",\"1\"],[\"63872.6\",\"0.02\",\"0\",\"2\"],[\"63872.7\",\"0.04\",\"0\",\"3\"],[\"63872.8\",\"0.03\",\"0\",\"3\"],[\"63872.9\",\"1.36\",\"0\",\"2\"],[\"63873.1\",\"100\",\"0\",\"1\"],[\"63873.2\",\"0.2\",\"0\",\"3\"],[\"63873.3\",\"0.01\",\"0\",\"1\"],[\"63873.5\",\"78.86\",\"0\",\"3\"],[\"63873.6\",\"0.01\",\"0\",\"1\"],[\"63873.7\",\"0.07\",\"0\",\"2\"],[\"63873.8\",\"15.89\",\"0\",\"3\"],[\"63874\",\"0.01\",\"0\",\"1\"],[\"63874.1\",\"1\",\"0\",\"1\"],[\"63874.2\",\"7.07\",\"0\",\"2\"],[\"63874.3\",\"82.01\",\"0\",\"2\"],[\"63874.4\",\"56.58\",\"0\",\"4\"],[\"63874.5\",\"291.61\",\"0\",\"3\"],[\"63874.6\",\"3.45\",\"0\",\"4\"],[\"63874.7\",\"0.01\",\"0\",\"1\"],[\"63874.8\",\"15.88\",\"0\",\"2\"],[\"63874.9\",\"372.75\",\"0\",\"3\"],[\"63875\",\"161.32\",\"0\",\"40\"],[\"63875.1\",\"20.81\",\"0\",\"2\"],[\"63875.2\",\"0.01\",\"0\",\"1\"],[\"63875.3\",\"0.23\",\"0\",\"4\"],[\"63875.4\",\"0.06\",\"0\",\"1\"],[\"63875.5\",\"1.26\",\"0\",\"3\"],[\"63875.6\",\"4.24\",\"0\",\"5\"],[\"63875.7\",\"2\",\"0\",\"1\"],[\"63875.9\",\"3.99\",\"0\",\"4\"],[\"63876\",\"0.95\",\"0\",\"4\"],[\"63876.1\",\"0.81\",\"0\",\"3\"],[\"63876.2\",\"1.58\",\"0\",\"3\"],[\"63876.3\",\"0.01\",\"0\",\"1\"],[\"63876.4\",\"1.27\",\"0\",\"5\"],[\"63876.5\",\"0.03\",\"0\",\"3\"],[\"63876.6\",\"0.61\",\"0\",\"2\"],[\"63876.7\",\"0.01\",\"0\",\"1\"],[\"63876.9\",\"1.24\",\"0\",\"2\"],[\"63877\",\"36.89\",\"0\",\"3\"],[\"63877.1\",\"0.01\",\"0\",\"1\"],[\"63877.2\",\"1.2\",\"0\",\"1\"],[\"63877.3\",\"0.01\",\"0\",\"1\"],[\"63877.4\",\"0.18\",\"0\",\"2\"],[\"63877.5\",\"0.03\",\"0\",\"2\"],[\"63877.6\",\"1.61\",\"0\",\"5\"],[\"63877.7\",\"1.58\",\"0\",\"5\"],[\"63877.8\",\"5.73\",\"0\",\"7\"],[\"63878\",\"0.02\",\"0\",\"2\"],[\"63878.1\",\"10.89\",\"0\",\"2\"],[\"63878.2\",\"0.01\",\"0\",\"1\"],[\"63878.3\",\"470.63\",\"0\",\"3\"],[\"63878.4\",\"300.6\",\"0\",\"3\"],[\"63878.5\",\"0.28\",\"0\",\"8\"],[\"63878.6\",\"0.06\",\"0\",\"3\"],[\"63878.7\",\"81.3\",\"0\",\"2\"],[\"63878.8\",\"53.94\",\"0\",\"1\"],[\"63879\",\"0.11\",\"0\",\"2\"],[\"63879.1\",\"0.02\",\"0\",\"2\"],[\"63879.2\",\"80.07\",\"0\",\"2\"],[\"63879.3\",\"0.01\",\"0\",\"1\"],[\"63879.5\",\"0.08\",\"0\",\"1\"],[\"63879.6\",\"0.11\",\"0\",\"2\"],[\"63879.7\",\"0.56\",\"0\",\"2\"],[\"63880\",\"22.28\",\"0\",\"55\"],[\"63880.2\",\"31.74\",\"0\",\"2\"],[\"63880.3\",\"0.11\",\"0\",\"2\"],[\"63880.5\",\"0.01\",\"0\",\"1\"],[\"63880.6\",\"0.01\",\"0\",\"1\"],[\"63880.7\",\"3.42\",\"0\",\"2\"],[\"63880.8\",\"6.28\",\"0\",\"2\"],[\"63880.9\",\"0.04\",\"0\",\"2\"],[\"63881.2\",\"195.55\",\"0\",\"3\"],[\"63881.3\",\"10.74\",\"0\",\"2\"],[\"63881.4\",\"0.04\",\"0\",\"1\"],[\"63881.5\",\"0.02\",\"0\",\"1\"],[\"63881.6\",\"0.03\",\"0\",\"3\"],[\"63881.7\",\"3.29\",\"0\",\"3\"],[\"63881.8\",\"0.02\",\"0\",\"2\"],[\"63881.9\",\"81.23\",\"0\",\"3\"],[\"63882\",\"55.29\",\"0\",\"4\"],[\"63882.1\",\"0.11\",\"0\",\"1\"],[\"63882.2\",\"0.01\",\"0\",\"1\"],[\"63882.4\",\"10.17\",\"0\",\"6\"],[\"63882.6\",\"0.06\",\"0\",\"2\"],[\"63882.7\",\"0.01\",\"0\",\"1\"],[\"63882.8\",\"16.05\",\"0\",\"1\"],[\"63882.9\",\"82.03\",\"0\",\"2\"],[\"63883\",\"0.06\",\"0\",\"4\"],[\"63883.1\",\"30.3\",\"0\",\"2\"],[\"63883.2\",\"0.24\",\"0\",\"2\"],[\"63883.3\",\"0.26\",\"0\",\"5\"],[\"63883.4\",\"16.33\",\"0\",\"3\"],[\"63883.6\",\"0.01\",\"0\",\"1\"],[\"63883.7\",\"0.01\",\"0\",\"1\"],[\"63883.9\",\"0.02\",\"0\",\"1\"],[\"63884\",\"0.01\",\"0\",\"1\"],[\"63884.3\",\"1.81\",\"0\",\"1\"],[\"63884.4\",\"0.37\",\"0\",\"1\"],[\"63884.5\",\"10.75\",\"0\",\"2\"],[\"63884.7\",\"1.29\",\"0\",\"2\"],[\"63884.8\",\"0.03\",\"0\",\"3\"],[\"63884.9\",\"8.07\",\"0\",\"2\"],[\"63885.1\",\"0.04\",\"0\",\"2\"],[\"63885.2\",\"0.25\",\"0\",\"2\"],[\"63885.3\",\"2.76\",\"0\",\"7\"],[\"63885.4\",\"62.77\",\"0\",\"2\"],[\"63885.5\",\"14.03\",\"0\",\"2\"],[\"63885.6\",\"23.51\",\"0\",\"2\"],[\"63885.7\",\"423.76\",\"0\",\"4\"],[\"63886\",\"0.01\",\"0\",\"1\"],[\"63886.1\",\"81.99\",\"0\",\"1\"],[\"63886.2\",\"15.87\",\"0\",\"1\"],[\"63886.3\",\"0.01\",\"0\",\"1\"],[\"63886.5\",\"0.02\",\"0\",\"2\"],[\"63886.6\",\"0.61\",\"0\",\"1\"],[\"63886.7\",\"0.02\",\"0\",\"1\"],[\"63886.9\",\"59.11\",\"0\",\"3\"]],\"bids\":[[\"63836.8\",\"525.94\",\"0\",\"32\"],[\"63836.7\",\"30.64\",\"0\",\"2\"],[\"63836.5\",\"0.01\",\"0\",\"1\"],[\"63836.4\",\"1.78\",\"0\",\"2\"],[\"63836.1\",\"0.01\",\"0\",\"1\"],[\"63836\",\"1.94\",\"0\",\"1\"],[\"63835.7\",\"0.01\",\"0\",\"1\"],[\"63835.6\",\"1.57\",\"0\",\"1\"],[\"63835.5\",\"0.01\",\"0\",\"1\"],[\"63835.2\",\"0.03\",\"0\",\"3\"],[\"63835.1\",\"1.57\",\"0\",\"1\"],[\"63835\",\"0.02\",\"0\",\"2\"],[\"63834.9\",\"1.72\",\"0\",\"3\"],[\"63834.7\",\"0.01\",\"0\",\"1\"],[\"63834.6\",\"37.67\",\"0\",\"2\"],[\"63834.4\",\"0.01\",\"0\",\"1\"],[\"63834.3\",\"1.58\",\"0\",\"2\"],[\"63834.2\",\"62.77\",\"0\",\"2\"],[\"63834.1\",\"0.51\",\"0\",\"2\"],[\"63833.9\",\"0.4\",\"0\",\"1\"],[\"63833.7\",\"0.02\",\"0\",\"2\"],[\"63833.6\",\"3\",\"0\",\"3\"],[\"63833.5\",\"1.93\",\"0\",\"3\"],[\"63833.4\",\"116.14\",\"0\",\"2\"],[\"63833.3\",\"0.15\",\"0\",\"1\"],[\"63833.2\",\"0.02\",\"0\",\"2\"],[\"63833.1\",\"1.57\",\"0\",\"1\"],[\"63833\",\"0.01\",\"0\",\"1\"],[\"63832.9\",\"63.51\",\"0\",\"2\"],[\"63832.8\",\"0.01\",\"0\",\"1\"],[\"63832.6\",\"1.57\",\"0\",\"1\"],[\"63832.3\",\"0.01\",\"0\",\"1\"],[\"63832.1\",\"1.59\",\"0\",\"3\"],[\"63831.9\",\"0.02\",\"0\",\"2\"],[\"63831.7\",\"0.01\",\"0\",\"1\"],[\"63831.6\",\"73.44\",\"0\",\"4\"],[\"63831.1\",\"1.58\",\"0\",\"2\"],[\"63831\",\"0.01\",\"0\",\"1\"],[\"63830.8\",\"33.23\",\"0\",\"3\"],[\"63830.7\",\"62.76\",\"0\",\"1\"],[\"63830.6\",\"215.34\",\"0\",\"4\"],[\"63830.4\",\"0.04\",\"0\",\"4\"],[\"63830.1\",\"0.02\",\"0\",\"2\"],[\"63830\",\"22\",\"0\",\"2\"],[\"63829.9\",\"10.76\",\"0\",\"3\"],[\"63829.8\",\"7.43\",\"0\",\"3\"],[\"63829.7\",\"93.14\",\"0\",\"1\"],[\"63829.3\",\"0.02\",\"0\",\"2\"],[\"63829.2\",\"0.4\",\"0\",\"2\"],[\"63829.1\",\"33.71\",\"0\",\"2\"],[\"63829\",\"0.02\",\"0\",\"2\"],[\"63828.8\",\"0.01\",\"0\",\"1\"],[\"63828.7\",\"0.4\",\"0\",\"2\"],[\"63828.6\",\"62.76\",\"0\",\"1\"],[\"63828.4\",\"16.06\",\"0\",\"1\"],[\"63828.3\",\"65.94\",\"0\",\"1\"],[\"63828.1\",\"107.71\",\"0\",\"4\"],[\"63828\",\"0.38\",\"0\",\"6\"],[\"63827.7\",\"4.01\",\"0\",\"2\"],[\"63827.5\",\"0.01\",\"0\",\"1\"],[\"63827.4\",\"13\",\"0\",\"3\"],[\"63827.3\",\"20.43\",\"0\",\"2\"],[\"63827.2\",\"303.48\",\"0\",\"1\"],[\"63827.1\",\"0.17\",\"0\",\"2\"],[\"63827\",\"9.02\",\"0\",\"4\"],[\"63826.9\",\"81.01\",\"0\",\"1\"],[\"63826.8\",\"20.38\",\"0\",\"3\"],[\"63826.4\",\"9\",\"0\",\"2\"],[\"63826.3\",\"81.23\",\"0\",\"3\"],[\"63826.2\",\"0.02\",\"0\",\"1\"],[\"63826.1\",\"1.7\",\"0\",\"2\"],[\"63826\",\"0.4\",\"0\",\"1\"],[\"63825.9\",\"0.02\",\"0\",\"2\"],[\"63825.8\",\"1.2\",\"0\",\"1\"],[\"63825.7\",\"0.02\",\"0\",\"2\"],[\"63825.6\",\"62.77\",\"0\",\"2\"],[\"63825.5\",\"117.24\",\"0\",\"2\"],[\"63825.4\",\"16.01\",\"0\",\"2\"],[\"63825.3\",\"1.2\",\"0\",\"1\"],[\"63825.2\",\"100.74\",\"0\",\"2\"],[\"63825.1\",\"1.21\",\"0\",\"2\"],[\"63824.8\",\"409.07\",\"0\",\"3\"],[\"63824.7\",\"162.75\",\"0\",\"2\"],[\"63824.5\",\"1.5\",\"0\",\"1\"],[\"63824.4\",\"0.01\",\"0\",\"1\"],[\"63824.3\",\"0.01\",\"0\",\"1\"],[\"63824.2\",\"0.01\",\"0\",\"1\"],[\"63824\",\"0.31\",\"0\",\"2\"],[\"63823.9\",\"0.01\",\"0\",\"1\"],[\"63823.8\",\"10.73\",\"0\",\"1\"],[\"63823.5\",\"167.44\",\"0\",\"6\"],[\"63823.3\",\"0.01\",\"0\",\"1\"],[\"63823.2\",\"7.06\",\"0\",\"1\"],[\"63823\",\"265.22\",\"0\",\"3\"],[\"63822.9\",\"171.91\",\"0\",\"4\"],[\"63822.8\",\"65.16\",\"0\",\"4\"],[\"63822.6\",\"0.01\",\"0\",\"1\"],[\"63822.5\",\"0.02\",\"0\",\"2\"],[\"63822.4\",\"0.01\",\"0\",\"1\"],[\"63822.2\",\"19.14\",\"0\",\"3\"],[\"63822\",\"0.03\",\"0\",\"1\"],[\"63821.8\",\"0.01\",\"0\",\"1\"],[\"63821.7\",\"90.16\",\"0\",\"2\"],[\"63821.6\",\"81.14\",\"0\",\"2\"],[\"63821.5\",\"0.01\",\"0\",\"1\"],[\"63821.3\",\"0.01\",\"0\",\"1\"],[\"63820.8\",\"542.41\",\"0\",\"4\"],[\"63820.7\",\"138.6\",\"0\",\"3\"],[\"63820.6\",\"42.24\",\"0\",\"4\"],[\"63820.3\",\"1\",\"0\",\"1\"],[\"63820.2\",\"62.77\",\"0\",\"2\"],[\"63820.1\",\"0.02\",\"0\",\"2\"],[\"63820\",\"0.02\",\"0\",\"2\"],[\"63819.9\",\"70.58\",\"0\",\"2\"],[\"63819.8\",\"0.02\",\"0\",\"1\"],[\"63819.7\",\"15.7\",\"0\",\"5\"],[\"63819.6\",\"15.68\",\"0\",\"1\"],[\"63819.5\",\"31.39\",\"0\",\"1\"],[\"63819.2\",\"0.02\",\"0\",\"2\"],[\"63819.1\",\"0.03\",\"0\",\"1\"],[\"63818.9\",\"47.07\",\"0\",\"1\"],[\"63818.8\",\"0.01\",\"0\",\"1\"],[\"63818.7\",\"76.16\",\"0\",\"1\"],[\"63818.3\",\"0.01\",\"0\",\"1\"],[\"63818\",\"0.01\",\"0\",\"1\"],[\"63817.9\",\"3.14\",\"0\",\"2\"],[\"63817.6\",\"333.99\",\"0\",\"4\"],[\"63817.5\",\"77.47\",\"0\",\"2\"],[\"63817.4\",\"0.02\",\"0\",\"2\"],[\"63817.3\",\"100.43\",\"0\",\"3\"],[\"63817.2\",\"8.56\",\"0\",\"3\"],[\"63817\",\"10.71\",\"0\",\"1\"],[\"63816.9\",\"0.01\",\"0\",\"1\"],[\"63816.8\",\"237.55\",\"0\",\"3\"],[\"63816.7\",\"407.86\",\"0\",\"1\"],[\"63816.6\",\"214.55\",\"0\",\"7\"],[\"63816.5\",\"0.04\",\"0\",\"4\"],[\"63816.4\",\"50.04\",\"0\",\"3\"],[\"63816.3\",\"0.3\",\"0\",\"1\"],[\"63816.2\",\"0.01\",\"0\",\"1\"],[\"63816.1\",\"3.9\",\"0\",\"1\"],[\"63816\",\"31.42\",\"0\",\"4\"],[\"63815.8\",\"27.25\",\"0\",\"3\"],[\"63815.7\",\"0.01\",\"0\",\"1\"],[\"63815.4\",\"0.5\",\"0\",\"1\"],[\"63815.1\",\"0.02\",\"0\",\"2\"],[\"63815\",\"0.01\",\"0\",\"1\"],[\"63814.7\",\"12.04\",\"0\",\"6\"],[\"63814.5\",\"62.77\",\"0\",\"2\"],[\"63814.4\",\"234.94\",\"0\",\"3\"],[\"63814.2\",\"0.23\",\"0\",\"3\"],[\"63813.9\",\"0.01\",\"0\",\"1\"],[\"63813.7\",\"0.11\",\"0\",\"1\"],[\"63813.5\",\"0.02\",\"0\",\"2\"],[\"63813.4\",\"0.02\",\"0\",\"1\"],[\"63813.3\",\"0.14\",\"0\",\"14\"],[\"63813.2\",\"19.58\",\"0\",\"5\"],[\"63812.7\",\"0.51\",\"0\",\"2\"],[\"63812.5\",\"0.04\",\"0\",\"1\"],[\"63812.4\",\"0.01\",\"0\",\"1\"],[\"63812.3\",\"0.31\",\"0\",\"1\"],[\"63812.2\",\"408.99\",\"0\",\"2\"],[\"63812.1\",\"37.95\",\"0\",\"3\"],[\"63812\",\"0.03\",\"0\",\"3\"],[\"63811.9\",\"179.82\",\"0\",\"4\"],[\"63811.7\",\"2.57\",\"0\",\"1\"],[\"63811.6\",\"10.74\",\"0\",\"2\"],[\"63811.5\",\"0.02\",\"0\",\"2\"],[\"63811.4\",\"6.92\",\"0\",\"2\"],[\"63811.3\",\"7.06\",\"0\",\"1\"],[\"63811.2\",\"135.39\",\"0\",\"4\"],[\"63811.1\",\"239.12\",\"0\",\"2\"],[\"63811\",\"39.23\",\"0\",\"1\"],[\"63810.9\",\"0.04\",\"0\",\"3\"],[\"63810.5\",\"55.09\",\"0\",\"2\"],[\"63810.4\",\"0.03\",\"0\",\"3\"],[\"63810.3\",\"0.32\",\"0\",\"2\"],[\"63810.2\",\"15.88\",\"0\",\"2\"],[\"63810\",\"15.87\",\"0\",\"1\"],[\"63809.9\",\"0.29\",\"0\",\"1\"],[\"63809.8\",\"0.19\",\"0\",\"1\"],[\"63809.7\",\"15.88\",\"0\",\"2\"],[\"63809.5\",\"0.02\",\"0\",\"1\"],[\"63809.4\",\"0.01\",\"0\",\"1\"],[\"63809.3\",\"0.01\",\"0\",\"1\"],[\"63809.2\",\"0.02\",\"0\",\"2\"],[\"63809.1\",\"0.01\",\"0\",\"1\"],[\"63808.9\",\"15.87\",\"0\",\"1\"],[\"63808.8\",\"0.03\",\"0\",\"1\"],[\"63808.7\",\"34.5\",\"0\",\"4\"],[\"63808.6\",\"2.28\",\"0\",\"1\"],[\"63808.5\",\"0.01\",\"0\",\"1\"],[\"63808.4\",\"86.28\",\"0\",\"2\"],[\"63808.3\",\"418.49\",\"0\",\"2\"],[\"63808.2\",\"122.85\",\"0\",\"5\"],[\"63808.1\",\"15.87\",\"0\",\"1\"],[\"63808\",\"0.04\",\"0\",\"4\"],[\"63807.9\",\"0.52\",\"0\",\"2\"],[\"63807.7\",\"320.5\",\"0\",\"1\"],[\"63807.6\",\"376.73\",\"0\",\"2\"],[\"63807.4\",\"0.08\",\"0\",\"1\"],[\"63807.3\",\"15.9\",\"0\",\"4\"],[\"63807.2\",\"0.01\",\"0\",\"1\"],[\"63807\",\"15.9\",\"0\",\"3\"],[\"63806.8\",\"15.88\",\"0\",\"2\"],[\"63806.7\",\"54.14\",\"0\",\"4\"],[\"63806.6\",\"0.01\",\"0\",\"1\"],[\"63806.5\",\"96.3\",\"0\",\"2\"],[\"63806.3\",\"0.01\",\"0\",\"1\"],[\"63805.9\",\"0.01\",\"0\",\"1\"],[\"63805.8\",\"156\",\"0\",\"3\"],[\"63805.7\",\"15.87\",\"0\",\"1\"],[\"63805.4\",\"62.76\",\"0\",\"1\"],[\"63805.3\",\"81.49\",\"0\",\"2\"],[\"63805.1\",\"3.9\",\"0\",\"1\"],[\"63804.9\",\"26.52\",\"0\",\"4\"],[\"63804.8\",\"0.01\",\"0\",\"1\"],[\"63804.6\",\"249.19\",\"0\",\"4\"],[\"63804.5\",\"150.46\",\"0\",\"1\"],[\"63804.3\",\"0.01\",\"0\",\"1\"],[\"63804.2\",\"0.02\",\"0\",\"2\"],[\"63804.1\",\"15.87\",\"0\",\"1\"],[\"63804\",\"1.08\",\"0\",\"4\"],[\"63803.8\",\"15.87\",\"0\",\"1\"],[\"63803.7\",\"0.01\",\"0\",\"1\"],[\"63803.6\",\"15.87\",\"0\",\"1\"],[\"63803.5\",\"14.21\",\"0\",\"1\"],[\"63803.4\",\"470.95\",\"0\",\"4\"],[\"63803.3\",\"53.53\",\"0\",\"2\"],[\"63803.2\",\"0.01\",\"0\",\"1\"],[\"63803.1\",\"86.24\",\"0\",\"3\"],[\"63802.8\",\"39.23\",\"0\",\"1\"],[\"63802.7\",\"55.51\",\"0\",\"1\"],[\"63802.5\",\"33.31\",\"0\",\"4\"],[\"63802\",\"0.01\",\"0\",\"1\"],[\"63801.9\",\"0.01\",\"0\",\"1\"],[\"63801.8\",\"81.81\",\"0\",\"3\"],[\"63801.7\",\"26.5\",\"0\",\"2\"],[\"63801.6\",\"0.02\",\"0\",\"2\"],[\"63801.5\",\"15.88\",\"0\",\"2\"],[\"63801.4\",\"0.02\",\"0\",\"2\"],[\"63801.3\",\"0.01\",\"0\",\"1\"],[\"63801.1\",\"0.01\",\"0\",\"1\"],[\"63800.9\",\"80.79\",\"0\",\"3\"],[\"63800.7\",\"211.51\",\"0\",\"2\"],[\"63800.6\",\"22.95\",\"0\",\"3\"],[\"63800.4\",\"97.4\",\"0\",\"2\"],[\"63800.3\",\"0.04\",\"0\",\"1\"],[\"63800.2\",\"0.01\",\"0\",\"1\"],[\"63800.1\",\"276.8\",\"0\",\"3\"],[\"63800\",\"8.4\",\"0\",\"59\"],[\"63799.5\",\"0.01\",\"0\",\"1\"],[\"63799.3\",\"15.88\",\"0\",\"2\"],[\"63799.2\",\"2.06\",\"0\",\"2\"],[\"63799\",\"407.87\",\"0\",\"2\"],[\"63798.9\",\"55.52\",\"0\",\"2\"],[\"63798.8\",\"0.01\",\"0\",\"1\"],[\"63798.7\",\"0.07\",\"0\",\"1\"],[\"63798.6\",\"62.76\",\"0\",\"1\"],[\"63798.5\",\"75.13\",\"0\",\"7\"],[\"63798.4\",\"36.03\",\"0\",\"6\"],[\"63798.1\",\"41.75\",\"0\",\"2\"],[\"63798\",\"0.01\",\"0\",\"1\"],[\"63797.8\",\"0.02\",\"0\",\"1\"],[\"63797.7\",\"15.87\",\"0\",\"1\"],[\"63797.6\",\"0.02\",\"0\",\"1\"],[\"63797.5\",\"117.71\",\"0\",\"3\"],[\"63797.4\",\"99.85\",\"0\",\"3\"],[\"63797.2\",\"15.87\",\"0\",\"1\"],[\"63797.1\",\"0.01\",\"0\",\"1\"],[\"63796.9\",\"15.88\",\"0\",\"2\"],[\"63796.7\",\"6.26\",\"0\",\"1\"],[\"63796.4\",\"0.01\",\"0\",\"1\"],[\"63796.3\",\"0.01\",\"0\",\"1\"],[\"63796.2\",\"100.44\",\"0\",\"4\"],[\"63796\",\"91.5\",\"0\",\"3\"],[\"63795.9\",\"16.32\",\"0\",\"2\"],[\"63795.8\",\"0.02\",\"0\",\"2\"],[\"63795.5\",\"66.45\",\"0\",\"3\"],[\"63795.3\",\"10.61\",\"0\",\"5\"],[\"63795.2\",\"0.01\",\"0\",\"1\"],[\"63795\",\"0.31\",\"0\",\"2\"],[\"63794.9\",\"0.01\",\"0\",\"1\"],[\"63794.8\",\"8\",\"0\",\"1\"],[\"63794.7\",\"0.02\",\"0\",\"2\"],[\"63794.6\",\"0.01\",\"0\",\"1\"],[\"63794.5\",\"0.02\",\"0\",\"2\"],[\"63794.4\",\"0.01\",\"0\",\"1\"],[\"63794.2\",\"31.79\",\"0\",\"4\"],[\"63794.1\",\"7.07\",\"0\",\"2\"],[\"63794\",\"279.78\",\"0\",\"3\"],[\"63793.9\",\"407.88\",\"0\",\"3\"],[\"63793.8\",\"0.01\",\"0\",\"1\"],[\"63793.7\",\"0.01\",\"0\",\"1\"],[\"63793.6\",\"0.01\",\"0\",\"1\"],[\"63793.5\",\"159.82\",\"0\",\"3\"],[\"63793.4\",\"0.01\",\"0\",\"1\"],[\"63793.3\",\"0.43\",\"0\",\"2\"],[\"63793.1\",\"0.01\",\"0\",\"1\"],[\"63792.7\",\"0.07\",\"0\",\"2\"],[\"63792.6\",\"62.78\",\"0\",\"3\"],[\"63792.3\",\"0.27\",\"0\",\"3\"],[\"63792.2\",\"120.16\",\"0\",\"3\"],[\"63792.1\",\"65.58\",\"0\",\"4\"],[\"63792\",\"0.07\",\"0\",\"4\"],[\"63791.9\",\"0.11\",\"0\",\"1\"],[\"63791.8\",\"0.01\",\"0\",\"1\"],[\"63791.7\",\"0.04\",\"0\",\"4\"],[\"63791.6\",\"0.31\",\"0\",\"3\"],[\"63791.5\",\"15.92\",\"0\",\"3\"],[\"63791.4\",\"0.02\",\"0\",\"1\"],[\"63791.1\",\"0.22\",\"0\",\"4\"],[\"63791\",\"97.57\",\"0\",\"2\"],[\"63790.9\",\"0.11\",\"0\",\"1\"],[\"63790.8\",\"18.06\",\"0\",\"5\"],[\"63790.7\",\"37.66\",\"0\",\"1\"],[\"63790\",\"5.37\",\"0\",\"15\"],[\"63789.9\",\"0.04\",\"0\",\"2\"],[\"63789.7\",\"407.87\",\"0\",\"2\"],[\"63789.4\",\"20.01\",\"0\",\"2\"],[\"63789.2\",\"0.01\",\"0\",\"1\"],[\"63789.1\",\"0.13\",\"0\",\"5\"],[\"63789\",\"0.12\",\"0\",\"5\"],[\"63788.9\",\"154.14\",\"0\",\"3\"],[\"63788.8\",\"0.02\",\"0\",\"2\"],[\"63788.7\",\"247.87\",\"0\",\"6\"],[\"63788.6\",\"0.02\",\"0\",\"1\"],[\"63788.5\",\"0.01\",\"0\",\"1\"],[\"63788.2\",\"0.03\",\"0\",\"1\"],[\"63788.1\",\"0.02\",\"0\",\"2\"],[\"63787.8\",\"15.89\",\"0\",\"2\"],[\"63787.7\",\"0.18\",\"0\",\"2\"],[\"63787.6\",\"97.14\",\"0\",\"2\"],[\"63787.5\",\"0.03\",\"0\",\"2\"],[\"63787.4\",\"0.15\",\"0\",\"1\"],[\"63787.3\",\"0.51\",\"0\",\"1\"],[\"63787.2\",\"0.11\",\"0\",\"3\"],[\"63787\",\"0.01\",\"0\",\"1\"],[\"63786.9\",\"20.8\",\"0\",\"1\"],[\"63786.7\",\"4.02\",\"0\",\"13\"],[\"63786.6\",\"0.24\",\"0\",\"1\"],[\"63786.3\",\"4.75\",\"0\",\"2\"],[\"63786.2\",\"62.81\",\"0\",\"4\"],[\"63786\",\"0.19\",\"0\",\"19\"],[\"63785.9\",\"7.07\",\"0\",\"2\"],[\"63785.8\",\"0.04\",\"0\",\"2\"],[\"63785.7\",\"418.21\",\"0\",\"2\"],[\"63785.6\",\"4.78\",\"0\",\"4\"],[\"63785.5\",\"81.57\",\"0\",\"1\"],[\"63785.4\",\"55.6\",\"0\",\"2\"],[\"63785.3\",\"19.61\",\"0\",\"2\"],[\"63785.2\",\"0.01\",\"0\",\"1\"],[\"63785\",\"0.04\",\"0\",\"1\"],[\"63784.8\",\"0.02\",\"0\",\"1\"],[\"63784.6\",\"15.88\",\"0\",\"2\"],[\"63784.5\",\"19.03\",\"0\",\"2\"],[\"63784.4\",\"19.53\",\"0\",\"2\"],[\"63784.3\",\"0.07\",\"0\",\"1\"],[\"63784.1\",\"81.84\",\"0\",\"2\"],[\"63784\",\"0.15\",\"0\",\"3\"],[\"63783.9\",\"0.01\",\"0\",\"1\"],[\"63783.7\",\"0.01\",\"0\",\"1\"],[\"63783.6\",\"0.02\",\"0\",\"2\"],[\"63783.4\",\"4.72\",\"0\",\"1\"],[\"63783.3\",\"454.1\",\"0\",\"5\"],[\"63783.2\",\"37.66\",\"0\",\"1\"],[\"63783.1\",\"1378.82\",\"0\",\"2\"],[\"63782.8\",\"0.03\",\"0\",\"3\"],[\"63782.7\",\"0.01\",\"0\",\"1\"],[\"63782.6\",\"62.91\",\"0\",\"7\"],[\"63782.5\",\"10.65\",\"0\",\"3\"],[\"63782.4\",\"2.57\",\"0\",\"2\"],[\"63782.3\",\"0.2\",\"0\",\"2\"],[\"63782.1\",\"0.21\",\"0\",\"6\"],[\"63782\",\"0.06\",\"0\",\"1\"],[\"63781.8\",\"0.01\",\"0\",\"1\"],[\"63781.7\",\"0.01\",\"0\",\"1\"],[\"63781.4\",\"428.3\",\"0\",\"3\"],[\"63781.3\",\"137.17\",\"0\",\"3\"],[\"63781\",\"1.56\",\"0\",\"2\"],[\"63780.9\",\"0.02\",\"0\",\"2\"],[\"63780.7\",\"1.14\",\"0\",\"2\"],[\"63780.6\",\"62.76\",\"0\",\"1\"],[\"63780.4\",\"0.05\",\"0\",\"2\"],[\"63780.3\",\"0.02\",\"0\",\"2\"],[\"63780.1\",\"0.03\",\"0\",\"2\"],[\"63780\",\"0.78\",\"0\",\"8\"],[\"63779.9\",\"1.13\",\"0\",\"1\"],[\"63779.5\",\"407.89\",\"0\",\"3\"],[\"63779.4\",\"0.01\",\"0\",\"1\"],[\"63779.3\",\"10.71\",\"0\",\"2\"],[\"63779.2\",\"0.01\",\"0\",\"1\"],[\"63779.1\",\"0.27\",\"0\",\"2\"],[\"63778.8\",\"23.99\",\"0\",\"1\"],[\"63778.7\",\"0.01\",\"0\",\"1\"],[\"63778.4\",\"7.06\",\"0\",\"1\"],[\"63778.3\",\"112.76\",\"0\",\"2\"],[\"63778.2\",\"0.01\",\"0\",\"1\"],[\"63778.1\",\"81.87\",\"0\",\"1\"],[\"63778\",\"137.24\",\"0\",\"5\"]],\"ts\":\"1781977441206\",\"checksum\":-1544073543,\"seqId\":325022984688,\"prevSeqId\":-1}]}"}
{"action": "update", "capture_sequence": 4, "channel": "books", "event": null, "instId": "BTC-USDT-SWAP", "local_receive_ts": "2026-06-20T17:44:01Z", "monotonic_ns": 1604997373916500, "raw": "{\"arg\":{\"channel\":\"books\",\"instId\":\"BTC-USDT-SWAP\"},\"action\":\"update\",\"data\":[{\"asks\":[[\"63836.9\",\"445.57\",\"0\",\"38\"],[\"63837\",\"0.01\",\"0\",\"1\"],[\"63843.1\",\"0.31\",\"0\",\"1\"],[\"63843.9\",\"0.11\",\"0\",\"1\"],[\"63846.1\",\"34.29\",\"0\",\"3\"],[\"63848.5\",\"16\",\"0\",\"1\"],[\"63849.4\",\"63.55\",\"0\",\"3\"],[\"63849.6\",\"626.64\",\"0\",\"5\"],[\"63851.4\",\"82.77\",\"0\",\"5\"],[\"63851.6\",\"0\",\"0\",\"0\"],[\"63851.7\",\"0.41\",\"0\",\"1\"],[\"63852.1\",\"0\",\"0\",\"0\"],[\"63852.9\",\"125.43\",\"0\",\"2\"],[\"63853.4\",\"0.01\",\"0\",\"1\"],[\"63854.7\",\"269.26\",\"0\",\"3\"],[\"63854.8\",\"439.31\",\"0\",\"4\"],[\"63854.9\",\"39.25\",\"0\",\"2\"],[\"63855.1\",\"58.79\",\"0\",\"2\"],[\"63855.5\",\"0\",\"0\",\"0\"],[\"63855.6\",\"0\",\"0\",\"0\"],[\"63856.1\",\"0.02\",\"0\",\"1\"],[\"63856.6\",\"85.82\",\"0\",\"3\"],[\"63862.1\",\"0.06\",\"0\",\"5\"],[\"63862.5\",\"228.78\",\"0\",\"5\"],[\"63869.5\",\"24.85\",\"0\",\"3\"],[\"63870.7\",\"0.18\",\"0\",\"2\"],[\"63887\",\"0.01\",\"0\",\"1\"]],\"bids\":[[\"63836.8\",\"412.59\",\"0\",\"30\"],[\"63836.7\",\"0.01\",\"0\",\"1\"],[\"63835.7\",\"0\",\"0\",\"0\"],[\"63835.6\",\"0\",\"0\",\"0\"],[\"63835.1\",\"0\",\"0\",\"0\"],[\"63835\",\"0.03\",\"0\",\"3\"],[\"63834.8\",\"0.01\",\"0\",\"1\"],[\"63834.7\",\"12.44\",\"0\",\"2\"],[\"63834.3\",\"0\",\"0\",\"0\"],[\"63834.2\",\"0.01\",\"0\",\"1\"],[\"63833.8\",\"1.57\",\"0\",\"1\"],[\"63833.5\",\"0.36\",\"0\",\"2\"],[\"63833.1\",\"0\",\"0\",\"0\"],[\"63832.6\",\"0\",\"0\",\"0\"],[\"63832.3\",\"1.58\",\"0\",\"2\"],[\"63832.1\",\"0.02\",\"0\",\"2\"],[\"63831.7\",\"1.58\",\"0\",\"2\"],[\"63831.6\",\"71.87\",\"0\",\"3\"],[\"63831.2\",\"1.57\",\"0\",\"1\"],[\"63831.1\",\"0.01\",\"0\",\"1\"],[\"63830.8\",\"32.14\",\"0\",\"2\"],[\"63830.7\",\"64.33\",\"0\",\"2\"],[\"63830.6\",\"213.77\",\"0\",\"3\"],[\"63830.2\",\"1.57\",\"0\",\"1\"],[\"63829.9\",\"0.02\",\"0\",\"2\"],[\"63829.6\",\"1.57\",\"0\",\"1\"],[\"63829.2\",\"1.97\",\"0\",\"3\"],[\"63828.7\",\"3.06\",\"0\",\"4\"],[\"63828\",\"0.37\",\"0\",\"5\"],[\"63827.2\",\"306.65\",\"0\",\"3\"],[\"63827.1\",\"0.18\",\"0\",\"3\"],[\"63825.4\",\"0.01\",\"0\",\"1\"],[\"63824.2\",\"16.01\",\"0\",\"2\"],[\"63821.7\",\"3.13\",\"0\",\"1\"],[\"63820.9\",\"87.04\",\"0\",\"1\"],[\"63820.1\",\"0\",\"0\",\"0\"],[\"63819.7\",\"0.04\",\"0\",\"4\"],[\"63819.6\",\"0\",\"0\",\"0\"],[\"63819.1\",\"15.71\",\"0\",\"2\"],[\"63819\",\"15.66\",\"0\",\"1\"],[\"63817.5\",\"77.48\",\"0\",\"3\"],[\"63817.4\",\"0.03\",\"0\",\"3\"],[\"63817.2\",\"8.55\",\"0\",\"2\"],[\"63816.8\",\"2.29\",\"0\",\"2\"],[\"63816.5\",\"0.03\",\"0\",\"3\"],[\"63816.4\",\"15.88\",\"0\",\"2\"],[\"63816.2\",\"235.27\",\"0\",\"2\"],[\"63816.1\",\"3.91\",\"0\",\"2\"],[\"63816\",\"0.06\",\"0\",\"3\"],[\"63815.9\",\"34.16\",\"0\",\"1\"],[\"63815.5\",\"31.36\",\"0\",\"1\"],[\"63811.2\",\"134.61\",\"0\",\"3\"],[\"63811\",\"39.24\",\"0\",\"2\"],[\"63810.6\",\"0.78\",\"0\",\"1\"],[\"63810.3\",\"0.01\",\"0\",\"1\"],[\"63810.1\",\"0.31\",\"0\",\"1\"],[\"63808.4\",\"0.01\",\"0\",\"1\"],[\"63808.2\",\"64.03\",\"0\",\"4\"],[\"63807.8\",\"86.27\",\"0\",\"1\"],[\"63807.4\",\"58.9\",\"0\",\"2\"],[\"63807.2\",\"0\",\"0\",\"0\"],[\"63804.5\",\"150.47\",\"0\",\"2\"],[\"63785.6\",\"4.77\",\"0\",\"3\"],[\"63784\",\"0.16\",\"0\",\"4\"],[\"63778.2\",\"0\",\"0\",\"0\"],[\"63778.1\",\"0\",\"0\",\"0\"],[\"63778\",\"0\",\"0\",\"0\"]],\"ts\":\"1781977441306\",\"checksum\":1669702762,\"seqId\":325022984895,\"prevSeqId\":325022984688}]}"}
{"action": "update", "capture_sequence": 5, "channel": "books", "event": null, "instId": "BTC-USDT-SWAP", "local_receive_ts": "2026-06-20T17:44:01Z", "monotonic_ns": 1604997381445630, "raw": "{\"arg\":{\"channel\":\"books\",\"instId\":\"BTC-USDT-SWAP\"},\"action\":\"update\",\"data\":[{\"asks\":[[\"63837\",\"0.04\",\"0\",\"2\"],[\"63854.8\",\"439.29\",\"0\",\"3\"],[\"63854.9\",\"39.27\",\"0\",\"3\"],[\"63862.1\",\"0.04\",\"0\",\"4\"],[\"63862.5\",\"228.8\",\"0\",\"6\"],[\"63869.5\",\"24.83\",\"0\",\"2\"],[\"63870.6\",\"423.8\",\"0\",\"6\"]],\"bids\":[[\"63833.8\",\"0\",\"0\",\"0\"],[\"63832.3\",\"0.01\",\"0\",\"1\"],[\"63832.2\",\"1.57\",\"0\",\"1\"],[\"63830.7\",\"65.42\",\"0\",\"3\"],[\"63828.7\",\"1.97\",\"0\",\"3\"],[\"63828.2\",\"1.57\",\"0\",\"1\"],[\"63818.8\",\"0.03\",\"0\",\"3\"],[\"63817.5\",\"77.47\",\"0\",\"2\"],[\"63817.4\",\"0.02\",\"0\",\"2\"],[\"63816.6\",\"214.56\",\"0\",\"8\"],[\"63816.1\",\"3.9\",\"0\",\"1\"],[\"63815.7\",\"0.02\",\"0\",\"2\"],[\"63812.1\",\"37.94\",\"0\",\"2\"],[\"63812\",\"0.04\",\"0\",\"4\"],[\"63811\",\"39.23\",\"0\",\"1\"],[\"63805.7\",\"15.88\",\"0\",\"2\"],[\"63804.5\",\"150.46\",\"0\",\"1\"],[\"63785.6\",\"4.78\",\"0\",\"4\"],[\"63784\",\"0.15\",\"0\",\"3\"],[\"63778.3\",\"0\",\"0\",\"0\"]],\"ts\":\"1781977441406\",\"checksum\":420744781,\"seqId\":325022984960,\"prevSeqId\":325022984895}]}"}
{"action": null, "capture_sequence": 6, "channel": "trades", "event": null, "instId": "BTC-USDT-SWAP", "local_receive_ts": "2026-06-20T17:44:01Z", "monotonic_ns": 1604997381684168, "raw": "{\"arg\":{\"channel\":\"trades\",\"instId\":\"BTC-USDT-SWAP\"},\"data\":[{\"instId\":\"BTC-USDT-SWAP\",\"tradeId\":\"2718342515\",\"px\":\"63836.9\",\"sz\":\"9.6\",\"side\":\"buy\",\"ts\":\"1781977441418\",\"count\":\"1\",\"source\":\"0\",\"seqId\":325022984963}]}"}
{"action": null, "capture_sequence": 7, "channel": "trades", "event": null, "instId": "BTC-USDT-SWAP", "local_receive_ts": "2026-06-20T17:44:01Z", "monotonic_ns": 1604997384056365, "raw": "{\"arg\":{\"channel\":\"trades\",\"instId\":\"BTC-USDT-SWAP\"},\"data\":[{\"instId\":\"BTC-USDT-SWAP\",\"tradeId\":\"2718342520\",\"px\":\"63836.8\",\"sz\":\"11.3\",\"side\":\"sell\",\"ts\":\"1781977441470\",\"count\":\"5\",\"source\":\"0\",\"seqId\":325022985010}]}"}
{"action": "update", "capture_sequence": 8, "channel": "books", "event": null, "instId": "BTC-USDT-SWAP", "local_receive_ts": "2026-06-20T17:44:01Z", "monotonic_ns": 1604997417694252, "raw": "{\"arg\":{\"channel\":\"books\",\"instId\":\"BTC-USDT-SWAP\"},\"action\":\"update\",\"data\":[{\"asks\":[[\"63836.9\",\"438.69\",\"0\",\"34\"]],\"bids\":[[\"63836.8\",\"401.29\",\"0\",\"26\"],[\"63835.2\",\"0.04\",\"0\",\"4\"],[\"63835.1\",\"21.18\",\"0\",\"1\"],[\"63835\",\"26.02\",\"0\",\"3\"],[\"63834.7\",\"0.01\",\"0\",\"1\"],[\"63832.3\",\"1.58\",\"0\",\"2\"],[\"63832.2\",\"0\",\"0\",\"0\"],[\"63831.8\",\"1.57\",\"0\",\"1\"],[\"63831.7\",\"0.01\",\"0\",\"1\"],[\"63827.7\",\"5.58\",\"0\",\"3\"],[\"63778.4\",\"0\",\"0\",\"0\"]],\"ts\":\"1781977441506\",\"checksum\":1685990107,\"seqId\":325022985037,\"prevSeqId\":325022984960}]}"}
{"action": "update", "capture_sequence": 9, "channel": "books", "event": null, "instId": "BTC-USDT-SWAP", "local_receive_ts": "2026-06-20T17:44:01Z", "monotonic_ns": 1604997528895646, "raw": "{\"arg\":{\"channel\":\"books\",\"instId\":\"BTC-USDT-SWAP\"},\"action\":\"update\",\"data\":[{\"asks\":[[\"63874\",\"0.02\",\"0\",\"2\"],[\"63877.8\",\"5.72\",\"0\",\"6\"]],\"bids\":[[\"63836.8\",\"401.39\",\"0\",\"27\"],[\"63834\",\"0.01\",\"0\",\"1\"],[\"63832.7\",\"1.57\",\"0\",\"1\"],[\"63832.3\",\"0.01\",\"0\",\"1\"],[\"63832.2\",\"1.57\",\"0\",\"1\"],[\"63831.8\",\"0\",\"0\",\"0\"],[\"63831.7\",\"1.58\",\"0\",\"2\"],[\"63827.7\",\"4.01\",\"0\",\"2\"],[\"63793.8\",\"0\",\"0\",\"0\"],[\"63778.7\",\"0\",\"0\",\"0\"]],\"ts\":\"1781977441606\",\"checksum\":-180560234,\"seqId\":325022985055,\"prevSeqId\":325022985037}]}"}
{"action": "update", "capture_sequence": 10, "channel": "books", "event": null, "instId": "BTC-USDT-SWAP", "local_receive_ts": "2026-06-20T17:44:01Z", "monotonic_ns": 1604997618116579, "raw": "{\"arg\":{\"channel\":\"books\",\"instId\":\"BTC-USDT-SWAP\"},\"action\":\"update\",\"data\":[{\"asks\":[[\"63838\",\"73.62\",\"0\",\"1\"],[\"63846.1\",\"2.94\",\"0\",\"2\"],[\"63848.2\",\"47.45\",\"0\",\"4\"],[\"63851.4\",\"67.11\",\"0\",\"4\"],[\"63852.1\",\"15.66\",\"0\",\"1\"],[\"63886.9\",\"0\",\"0\",\"0\"],[\"63887\",\"0\",\"0\",\"0\"]],\"bids\":[[\"63834.8\",\"0\",\"0\",\"0\"],[\"63833.5\",\"1.93\",\"0\",\"3\"],[\"63828.2\",\"0\",\"0\",\"0\"],[\"63819.2\",\"15.68\",\"0\",\"3\"],[\"63819\",\"0\",\"0\",\"0\"],[\"63778.7\",\"0.01\",\"0\",\"1\"],[\"63778.4\",\"7.06\",\"0\",\"1\"],[\"63778.3\",\"112.76\",\"0\",\"2\"]],\"ts\":\"1781977441706\",\"checksum\":-1985486299,\"seqId\":325022985075,\"prevSeqId\":325022985055}]}"}
{"action": "update", "capture_sequence": 11, "channel": "books", "event": null, "instId": "BTC-USDT-SWAP", "local_receive_ts": "2026-06-20T17:44:01Z", "monotonic_ns": 1604997717918572, "raw": "{\"arg\":{\"channel\":\"books\",\"instId\":\"BTC-USDT-SWAP\"},\"action\":\"update\",\"data\":[{\"asks\":[],\"bids\":[[\"63833.5\",\"0.36\",\"0\",\"2\"],[\"63833.4\",\"117.71\",\"0\",\"3\"]],\"ts\":\"1781977441806\",\"checksum\":-2065938614,\"seqId\":325022985098,\"prevSeqId\":325022985075}]}"}
{"action": "update", "capture_sequence": 12, "channel": "books", "event": null, "instId": "BTC-USDT-SWAP", "local_receive_ts": "2026-06-20T17:44:02Z", "monotonic_ns": 1604997817867950, "raw": "{\"arg\":{\"channel\":\"books\",\"instId\":\"BTC-USDT-SWAP\"},\"action\":\"update\",\"data\":[{\"asks\":[],\"bids\":[[\"63833.4\",\"116.14\",\"0\",\"2\"],[\"63832.7\",\"0\",\"0\",\"0\"],[\"63832.2\",\"0\",\"0\",\"0\"],[\"63828.2\",\"1.57\",\"0\",\"1\"],[\"63827.7\",\"5.58\",\"0\",\"3\"],[\"63827.3\",\"22\",\"0\",\"3\"],[\"63824\",\"50.31\",\"0\",\"3\"],[\"63778.3\",\"62.76\",\"0\",\"1\"],[\"63778.2\",\"0.01\",\"0\",\"1\"]],\"ts\":\"1781977441906\",\"checksum\":349972893,\"seqId\":325022985119,\"prevSeqId\":325022985098}]}"}
{"action": "update", "capture_sequence": 13, "channel": "books", "event": null, "instId": "BTC-USDT-SWAP", "local_receive_ts": "2026-06-20T17:44:02Z", "monotonic_ns": 1604997917742937, "raw": "{\"arg\":{\"channel\":\"books\",\"instId\":\"BTC-USDT-SWAP\"},\"action\":\"update\",\"data\":[{\"asks\":[[\"63852.8\",\"90.13\",\"0\",\"4\"],[\"63852.9\",\"39.22\",\"0\",\"1\"],[\"63854.6\",\"34.15\",\"0\",\"3\"],[\"63854.7\",\"235.13\",\"0\",\"2\"],[\"63854.8\",\"498.07\",\"0\",\"4\"],[\"63855.1\",\"0.01\",\"0\",\"1\"],[\"63862.3\",\"18.8\",\"0\",\"4\"],[\"63862.5\",\"228.78\",\"0\",\"5\"],[\"63869.6\",\"0.84\",\"0\",\"8\"],[\"63870.6\",\"423.78\",\"0\",\"5\"]],\"bids\":[[\"63832.7\",\"1.57\",\"0\",\"1\"],[\"63827.3\",\"20.43\",\"0\",\"2\"],[\"63821.7\",\"90.17\",\"0\",\"2\"],[\"63820.9\",\"0\",\"0\",\"0\"],[\"63819.4\",\"0.02\",\"0\",\"2\"],[\"63819.3\",\"15.68\",\"0\",\"1\"],[\"63819.1\",\"0.03\",\"0\",\"1\"],[\"63818.8\",\"0.01\",\"0\",\"1\"],[\"63816.1\",\"3.91\",\"0\",\"2\"],[\"63815.7\",\"0.01\",\"0\",\"1\"],[\"63812.1\",\"37.95\",\"0\",\"3\"],[\"63812\",\"0.03\",\"0\",\"3\"],[\"63806.4\",\"0.01\",\"0\",\"1\"],[\"63805.7\",\"15.87\",\"0\",\"1\"],[\"63804.2\",\"0.03\",\"0\",\"3\"],[\"63778.4\",\"0\",\"0\",\"0\"],[\"63778.3\",\"0\",\"0\",\"0\"],[\"63778.2\",\"0\",\"0\",\"0\"]],\"ts\":\"1781977442006\",\"checksum\":349972893,\"seqId\":325022985152,\"prevSeqId\":325022985119}]}"}
{"action": "update", "capture_sequence": 14, "channel": "books", "event": null, "instId": "BTC-USDT-SWAP", "local_receive_ts": "2026-06-20T17:44:02Z", "monotonic_ns": 1604998017762485, "raw": "{\"arg\":{\"channel\":\"books\",\"instId\":\"BTC-USDT-SWAP\"},\"action\":\"update\",\"data\":[{\"asks\":[[\"63853.5\",\"99.37\",\"0\",\"3\"],[\"63853.8\",\"0.06\",\"0\",\"5\"],[\"63854.8\",\"466.73\",\"0\",\"3\"],[\"63855.1\",\"31.35\",\"0\",\"2\"]],\"bids\":[[\"63827.7\",\"4.01\",\"0\",\"2\"],[\"63821.7\",\"87.04\",\"0\",\"1\"],[\"63819.3\",\"0\",\"0\",\"0\"],[\"63819.2\",\"0.02\",\"0\",\"2\"],[\"63819\",\"31.34\",\"0\",\"2\"],[\"63818.8\",\"3.14\",\"0\",\"2\"],[\"63816\",\"31.42\",\"0\",\"4\"],[\"63815.5\",\"0\",\"0\",\"0\"],[\"63778.4\",\"7.06\",\"0\",\"1\"]],\"ts\":\"1781977442106\",\"checksum\":349972893,\"seqId\":325022985199,\"prevSeqId\":325022985152}]}"}
{"action": null, "capture_sequence": 15, "channel": "trades", "event": null, "instId": "BTC-USDT-SWAP", "local_receive_ts": "2026-06-20T17:44:02Z", "monotonic_ns": 1604998023889321, "raw": "{\"arg\":{\"channel\":\"trades\",\"instId\":\"BTC-USDT-SWAP\"},\"data\":[{\"instId\":\"BTC-USDT-SWAP\",\"tradeId\":\"2718342521\",\"px\":\"63836.8\",\"sz\":\"0.02\",\"side\":\"sell\",\"ts\":\"1781977442112\",\"count\":\"1\",\"source\":\"0\",\"seqId\":325022985205}]}"}
{"action": null, "capture_sequence": 16, "channel": "trades", "event": null, "instId": "BTC-USDT-SWAP", "local_receive_ts": "2026-06-20T17:44:02Z", "monotonic_ns": 1604998077988806, "raw": "{\"arg\":{\"channel\":\"trades\",\"instId\":\"BTC-USDT-SWAP\"},\"data\":[{\"instId\":\"BTC-USDT-SWAP\",\"tradeId\":\"2718342522\",\"px\":\"63836.8\",\"sz\":\"0.05\",\"side\":\"sell\",\"ts\":\"1781977442166\",\"count\":\"1\",\"source\":\"0\",\"seqId\":325022985276}]}"}
{"action": "update", "capture_sequence": 17, "channel": "books", "event": null, "instId": "BTC-USDT-SWAP", "local_receive_ts": "2026-06-20T17:44:02Z", "monotonic_ns": 1604998118555825, "raw": "{\"arg\":{\"channel\":\"books\",\"instId\":\"BTC-USDT-SWAP\"},\"action\":\"update\",\"data\":[{\"asks\":[[\"63836.9\",\"438.74\",\"0\",\"35\"],[\"63846.7\",\"0.01\",\"0\",\"1\"],[\"63849.5\",\"162.99\",\"0\",\"3\"],[\"63851.7\",\"0\",\"0\",\"0\"],[\"63851.8\",\"0.42\",\"0\",\"2\"],[\"63852.7\",\"277.41\",\"0\",\"5\"],[\"63852.8\",\"3.92\",\"0\",\"3\"],[\"63853.4\",\"20.28\",\"0\",\"2\"],[\"63853.5\",\"79.1\",\"0\",\"2\"],[\"63854.6\",\"34.16\",\"0\",\"3\"],[\"63855\",\"31.34\",\"0\",\"1\"],[\"63855.1\",\"0.01\",\"0\",\"1\"],[\"63872.1\",\"100.01\",\"0\",\"2\"],[\"63873.1\",\"0\",\"0\",\"0\"],[\"63886.9\",\"59.11\",\"0\",\"3\"]],\"bids\":[[\"63836.8\",\"402.32\",\"0\",\"28\"],[\"63835.2\",\"0.05\",\"0\",\"5\"],[\"63833.6\",\"2\",\"0\",\"2\"],[\"63832.7\",\"0\",\"0\",\"0\"],[\"63831.8\",\"1.57\",\"0\",\"1\"],[\"63831.7\",\"0.01\",\"0\",\"1\"],[\"63829.7\",\"94.71\",\"0\",\"2\"],[\"63829.6\",\"0\",\"0\",\"0\"],[\"63829.3\",\"1.59\",\"0\",\"3\"],[\"63829.2\",\"0.4\",\"0\",\"2\"],[\"63828.8\",\"1.58\",\"0\",\"2\"],[\"63828.7\",\"0.4\",\"0\",\"2\"],[\"63827.7\",\"5.58\",\"0\",\"3\"],[\"63827.3\",\"22\",\"0\",\"3\"],[\"63816\",\"0.06\",\"0\",\"3\"],[\"63815.9\",\"31.36\",\"0\",\"1\"],[\"63815.5\",\"34.16\",\"0\",\"1\"],[\"63804.2\",\"0.02\",\"0\",\"2\"]],\"ts\":\"1781977442206\",\"checksum\":1575048384,\"seqId\":325022985295,\"prevSeqId\":325022985199}]}"}
{"action": "update", "capture_sequence": 18, "channel": "books", "event": null, "instId": "BTC-USDT-SWAP", "local_receive_ts": "2026-06-20T17:44:02Z", "monotonic_ns": 1604998217813852, "raw": "{\"arg\":{\"channel\":\"books\",\"instId\":\"BTC-USDT-SWAP\"},\"action\":\"update\",\"data\":[{\"asks\":[[\"63856.3\",\"0\",\"0\",\"0\"],[\"63869\",\"1.01\",\"0\",\"2\"],[\"63881.7\",\"1.01\",\"0\",\"2\"],[\"63887\",\"0.01\",\"0\",\"1\"]],\"bids\":[[\"63816.5\",\"0.02\",\"0\",\"2\"]],\"ts\":\"1781977442306\",\"checksum\":1575048384,\"seqId\":325022985312,\"prevSeqId\":325022985295}]}"}
{"action": "update", "capture_sequence": 19, "channel": "books", "event": null, "instId": "BTC-USDT-SWAP", "local_receive_ts": "2026-06-20T17:44:02Z", "monotonic_ns": 1604998318787352, "raw": "{\"arg\":{\"channel\":\"books\",\"instId\":\"BTC-USDT-SWAP\"},\"action\":\"update\",\"data\":[{\"asks\":[[\"63837.1\",\"0.05\",\"0\",\"2\"],[\"63837.2\",\"1.57\",\"0\",\"1\"],[\"63837.3\",\"0.01\",\"0\",\"1\"],[\"63837.4\",\"0.01\",\"0\",\"1\"],[\"63837.7\",\"208.43\",\"0\",\"7\"],[\"63843\",\"0.02\",\"0\",\"2\"],[\"63854.7\",\"293.91\",\"0\",\"3\"],[\"63854.8\",\"407.95\",\"0\",\"2\"],[\"63887\",\"0\",\"0\",\"0\"]],\"bids\":[[\"63836.8\",\"402.33\",\"0\",\"28\"],[\"63834.2\",\"1.58\",\"0\",\"2\"],[\"63833.6\",\"2.01\",\"0\",\"3\"],[\"63832.8\",\"1.58\",\"0\",\"2\"],[\"63828.2\",\"0\",\"0\",\"0\"],[\"63827.7\",\"4.01\",\"0\",\"2\"],[\"63827.3\",\"20.43\",\"0\",\"2\"],[\"63816\",\"34.22\",\"0\",\"4\"],[\"63815.5\",\"0\",\"0\",\"0\"],[\"63807.4\",\"0.08\",\"0\",\"1\"],[\"63807.1\",\"58.82\",\"0\",\"1\"],[\"63778.3\",\"62.76\",\"0\",\"1\"]],\"ts\":\"1781977442406\",\"checksum\":450329730,\"seqId\":325022985377,\"prevSeqId\":325022985312}]}"}
{"action": "update", "capture_sequence": 20, "channel": "books", "event": null, "instId": "BTC-USDT-SWAP", "local_receive_ts": "2026-06-20T17:44:02Z", "monotonic_ns": 1604998424155019, "raw": "{\"arg\":{\"channel\":\"books\",\"instId\":\"BTC-USDT-SWAP\"},\"action\":\"update\",\"data\":[{\"asks\":[[\"63836.9\",\"435.57\",\"0\",\"34\"],[\"63843.1\",\"0\",\"0\",\"0\"],[\"63843.9\",\"0.42\",\"0\",\"2\"],[\"63849.4\",\"62.77\",\"0\",\"2\"],[\"63849.6\",\"627.42\",\"0\",\"6\"],[\"63852.7\",\"191.2\",\"0\",\"4\"],[\"63853.1\",\"86.21\",\"0\",\"1\"],[\"63853.4\",\"0.01\",\"0\",\"1\"],[\"63853.8\",\"20.33\",\"0\",\"6\"],[\"63854.6\",\"0.02\",\"0\",\"2\"],[\"63854.7\",\"269.26\",\"0\",\"3\"],[\"63854.8\",\"407.99\",\"0\",\"4\"],[\"63854.9\",\"39.23\",\"0\",\"1\"],[\"63855.6\",\"58.78\",\"0\",\"1\"],[\"63856.3\",\"2.28\",\"0\",\"1\"],[\"63862.2\",\"0.01\",\"0\",\"1\"],[\"63869\",\"3.29\",\"0\",\"3\"],[\"63872.1\",\"0.01\",\"0\",\"1\"],[\"63873.2\",\"100.2\",\"0\",\"4\"],[\"63880.2\",\"55.82\",\"0\",\"3\"],[\"63886.7\",\"0\",\"0\",\"0\"],[\"63886.9\",\"0\",\"0\",\"0\"]],\"bids\":[[\"63836.8\",\"437.2\",\"0\",\"29\"],[\"63835.5\",\"0.02\",\"0\",\"2\"],[\"63835.4\",\"1.57\",\"0\",\"1\"],[\"63835.2\",\"0.04\",\"0\",\"4\"],[\"63834.9\",\"3.29\",\"0\",\"4\"],[\"63834.4\",\"1.58\",\"0\",\"2\"],[\"63834.2\",\"0.01\",\"0\",\"1\"],[\"63833.8\",\"1.57\",\"0\",\"1\"],[\"63833.3\",\"1.72\",\"0\",\"2\"],[\"63832.3\",\"1.58\",\"0\",\"2\"],[\"63830.7\",\"63.85\",\"0\",\"2\"],[\"63830.4\",\"10.74\",\"0\",\"5\"],[\"63830.2\",\"0\",\"0\",\"0\"],[\"63829.7\",\"93.14\",\"0\",\"1\"],[\"63829.3\",\"0.02\",\"0\",\"2\"],[\"63828.8\",\"0.01\",\"0\",\"1\"],[\"63823.5\",\"35.34\",\"0\",\"4\"],[\"63821.8\",\"87.04\",\"0\",\"2\"],[\"63821.7\",\"0\",\"0\",\"0\"],[\"63819.8\",\"0.04\",\"0\",\"3\"],[\"63819.6\",\"15.68\",\"0\",\"1\"],[\"63819.4\",\"0\",\"0\",\"0\"],[\"63819\",\"15.66\",\"0\",\"1\"],[\"63816.3\",\"34.46\",\"0\",\"2\"],[\"63816\",\"0.06\",\"0\",\"3\"],[\"63811.2\",\"135.39\",\"0\",\"4\"],[\"63810.7\",\"132.1\",\"0\",\"2\"],[\"63810.6\",\"0\",\"0\",\"0\"],[\"63810.3\",\"0.32\",\"0\",\"2\"],[\"63810.1\",\"0\",\"0\",\"0\"],[\"63808.3\",\"504.76\",\"0\",\"3\"],[\"63807.8\",\"58.82\",\"0\",\"1\"],[\"63807.1\",\"0\",\"0\",\"0\"],[\"63806.6\",\"0.02\",\"0\",\"2\"],[\"63806.4\",\"0\",\"0\",\"0\"],[\"63778.2\",\"0.01\",\"0\",\"1\"],[\"63778.1\",\"81.87\",\"0\",\"1\"],[\"63778\",\"137.24\",\"0\",\"5\"]],\"ts\":\"1781977442506\",\"checksum\":-586911458,\"seqId\":325022985493,\"prevSeqId\":325022985377}]}"}
