{"action": null, "capture_sequence": 1, "channel": "trades", "connection_sequence": 1, "event": "subscribe", "instId": "BTC-USDT-SWAP", "local_receive_ts": "2026-06-21T04:26:59Z", "monotonic_ns": 1643574818113800, "raw": "{\"event\":\"subscribe\",\"arg\":{\"channel\":\"trades\",\"instId\":\"BTC-USDT-SWAP\"},\"connId\":\"aec4987f\"}"}
{"action": null, "capture_sequence": 2, "channel": "books", "connection_sequence": 1, "event": "subscribe", "instId": "BTC-USDT-SWAP", "local_receive_ts": "2026-06-21T04:26:59Z", "monotonic_ns": 1643574818462693, "raw": "{\"event\":\"subscribe\",\"arg\":{\"channel\":\"books\",\"instId\":\"BTC-USDT-SWAP\"},\"connId\":\"aec4987f\"}"}
{"action": null, "capture_sequence": 3, "channel": "trades", "connection_sequence": 1, "event": null, "instId": "BTC-USDT-SWAP", "local_receive_ts": "2026-06-21T04:26:59Z", "monotonic_ns": 1643574944939390, "raw": "{\"arg\":{\"channel\":\"trades\",\"instId\":\"BTC-USDT-SWAP\"},\"data\":[{\"instId\":\"BTC-USDT-SWAP\",\"tradeId\":\"2718750114\",\"px\":\"64479.9\",\"sz\":\"14.95\",\"side\":\"buy\",\"ts\":\"1782016019041\",\"count\":\"1\",\"source\":\"0\",\"seqId\":325070060322}]}"}
{"action": "snapshot", "capture_sequence": 4, "channel": "books", "connection_sequence": 1, "event": null, "instId": "BTC-USDT-SWAP", "local_receive_ts": "2026-06-21T04:26:59Z", "monotonic_ns": 1643575127847014, "raw": "{\"arg\":{\"channel\":\"books\",\"instId\":\"BTC-USDT-SWAP\"},\"action\":\"snapshot\",\"data\":[{\"asks\":[[\"64479.9\",\"479.24\",\"0\",\"36\"],[\"64480\",\"50.09\",\"0\",\"7\"],[\"64480.1\",\"0.01\",\"0\",\"1\"],[\"64480.6\",\"0.01\",\"0\",\"1\"],[\"64480.9\",\"0.02\",\"0\",\"2\"],[\"64481\",\"41.99\",\"0\",\"3\"],[\"64481.1\",\"0.01\",\"0\",\"1\"],[\"64481.2\",\"0.78\",\"0\",\"2\"],[\"64481.5\",\"0.02\",\"0\",\"1\"],[\"64481.8\",\"0.05\",\"0\",\"4\"],[\"64481.9\",\"0.51\",\"0\",\"2\"],[\"64482\",\"0.04\",\"0\",\"2\"],[\"64482.1\",\"0.03\",\"0\",\"3\"],[\"64482.2\",\"7.75\",\"0\",\"1\"],[\"64482.5\",\"0.02\",\"0\",\"1\"],[\"64482.6\",\"0.02\",\"0\",\"2\"],[\"64482.7\",\"1.01\",\"0\",\"2\"],[\"64482.8\",\"1.57\",\"0\",\"2\"],[\"64483\",\"0.04\",\"0\",\"3\"],[\"64483.1\",\"110.37\",\"0\",\"5\"],[\"64483.2\",\"24.5\",\"0\",\"3\"],[\"64483.3\",\"107.44\",\"0\",\"5\"],[\"64483.4\",\"1\",\"0\",\"1\"],[\"64483.7\",\"1.01\",\"0\",\"2\"],[\"64483.8\",\"136.13\",\"0\",\"1\"],[\"64483.9\",\"0.02\",\"0\",\"2\"],[\"64484\",\"1.72\",\"0\",\"4\"],[\"64484.1\",\"0.02\",\"0\",\"1\"],[\"64484.3\",\"1.2\",\"0\",\"1\"],[\"64484.5\",\"0.06\",\"0\",\"3\"],[\"64484.6\",\"1.21\",\"0\",\"2\"],[\"64484.7\",\"2.76\",\"0\",\"2\"],[\"64484.8\",\"0.01\",\"0\",\"1\"],[\"64484.9\",\"0.15\",\"0\",\"1\"],[\"64485\",\"41.95\",\"0\",\"2\"],[\"64485.1\",\"1.2\",\"0\",\"1\"],[\"64485.2\",\"1.58\",\"0\",\"3\"],[\"64485.5\",\"1.21\",\"0\",\"2\"],[\"64485.6\",\"1.56\",\"0\",\"1\"],[\"64485.7\",\"0.34\",\"0\",\"4\"],[\"64485.8\",\"1.61\",\"0\",\"4\"],[\"64485.9\",\"11.62\",\"0\",\"2\"],[\"64486\",\"52.59\",\"0\",\"7\"],[\"64486.1\",\"250.42\",\"0\",\"4\"],[\"64486.2\",\"0.17\",\"0\",\"6\"],[\"64486.4\",\"1.28\",\"0\",\"3\"],[\"64486.6\",\"82.88\",\"0\",\"3\"],[\"64486.7\",\"0.12\",\"0\",\"1\"],[\"64486.8\",\"22.19\",\"0\",\"4\"],[\"64486.9\",\"0.11\",\"0\",\"1\"],[\"64487\",\"5.11\",\"0\",\"4\"],[\"64487.1\",\"2.09\",\"0\",\"5\"],[\"64487.2\",\"0.03\",\"0\",\"2\"],[\"64487.3\",\"0.04\",\"0\",\"2\"],[\"64487.4\",\"5.57\",\"0\",\"8\"],[\"64487.5\",\"1.6\",\"0\",\"4\"],[\"64487.7\",\"30.74\",\"0\",\"2\"],[\"64487.8\",\"0.1\",\"0\",\"4\"],[\"64487.9\",\"0.51\",\"0\",\"2\"],[\"64488\",\"67.43\",\"0\",\"29\"],[\"64488.1\",\"0.66\",\"0\",\"1\"],[\"64488.2\",\"3.96\",\"0\",\"2\"],[\"64488.3\",\"0.02\",\"0\",\"2\"],[\"64488.4\",\"5.67\",\"0\",\"6\"],[\"64488.5\",\"0.5\",\"0\",\"1\"],[\"64488.6\",\"0.02\",\"0\",\"2\"],[\"64488.7\",\"0.04\",\"0\",\"1\"],[\"64488.8\",\"50\",\"0\",\"1\"],[\"64488.9\",\"0.33\",\"0\",\"6\"],[\"64489\",\"23.1\",\"0\",\"9\"],[\"64489.1\",\"11.1\",\"0\",\"4\"],[\"64489.3\",\"23.25\",\"0\",\"5\"],[\"64489.4\",\"2.94\",\"0\",\"6\"],[\"64489.5\",\"3.95\",\"0\",\"3\"],[\"64489.6\",\"21.56\",\"0\",\"3\"],[\"64489.7\",\"41.13\",\"0\",\"3\"],[\"64489.8\",\"268.73\",\"0\",\"5\"],[\"64490\",\"60.27\",\"0\",\"22\"],[\"64490.1\",\"16.18\",\"0\",\"3\"],[\"64490.3\",\"1\",\"0\",\"1\"],[\"64490.4\",\"0.03\",\"0\",\"3\"],[\"64490.5\",\"64.05\",\"0\",\"4\"],[\"64490.6\",\"84.87\",\"0\",\"4\"],[\"64490.7\",\"0.06\",\"0\",\"2\"],[\"64490.9\",\"0.45\",\"0\",\"3\"],[\"64491\",\"64.49\",\"0\",\"2\"],[\"64491.2\",\"1.01\",\"0\",\"2\"],[\"64491.3\",\"0.01\",\"0\",\"1\"],[\"64491.4\",\"0.02\",\"0\",\"2\"],[\"64491.5\",\"0.1\",\"0\",\"1\"],[\"64491.6\",\"1.25\",\"0\",\"5\"],[\"64491.7\",\"15.94\",\"0\",\"3\"],[\"64491.8\",\"8.05\",\"0\",\"2\"],[\"64491.9\",\"0.45\",\"0\",\"5\"],[\"64492\",\"0.04\",\"0\",\"4\"],[\"64492.2\",\"0.91\",\"0\",\"7\"],[\"64492.3\",\"0.03\",\"0\",\"1\"],[\"64492.4\",\"12.14\",\"0\",\"8\"],[\"64492.5\",\"590.02\",\"0\",\"5\"],[\"64492.6\",\"62.15\",\"0\",\"1\"],[\"64492.7\",\"99.88\",\"0\",\"3\"],[\"64492.8\",\"167.59\",\"0\",\"13\"],[\"64492.9\",\"0.01\",\"0\",\"1\"],[\"64493\",\"1.3\",\"0\",\"3\"],[\"64493.1\",\"2.25\",\"0\",\"3\"],[\"64493.2\",\"12.07\",\"0\",\"6\"],[\"64493.3\",\"15.99\",\"0\",\"4\"],[\"64493.4\",\"46.86\",\"0\",\"6\"],[\"64493.5\",\"134.25\",\"0\",\"5\"],[\"64493.7\",\"1.25\",\"0\",\"3\"],[\"64493.8\",\"0.03\",\"0\",\"2\"],[\"64494\",\"238.94\",\"0\",\"6\"],[\"64494.3\",\"0.08\",\"0\",\"4\"],[\"64494.4\",\"0.22\",\"0\",\"5\"],[\"64494.5\",\"15.52\",\"0\",\"1\"],[\"64494.6\",\"5.05\",\"0\",\"5\"],[\"64494.7\",\"24.05\",\"0\",\"5\"],[\"64494.8\",\"0.07\",\"0\",\"1\"],[\"64494.9\",\"0.07\",\"0\",\"3\"],[\"64495\",\"32.44\",\"0\",\"11\"],[\"64495.1\",\"0.07\",\"0\",\"3\"],[\"64495.2\",\"0.02\",\"0\",\"2\"],[\"64495.3\",\"0.26\",\"0\",\"2\"],[\"64495.4\",\"0.06\",\"0\",\"3\"],[\"64495.5\",\"0.14\",\"0\",\"5\"],[\"64495.6\",\"0.01\",\"0\",\"1\"],[\"64495.7\",\"11.35\",\"0\",\"3\"],[\"64495.8\",\"0.04\",\"0\",\"3\"],[\"64495.9\",\"0.84\",\"0\",\"3\"],[\"64496\",\"104.13\",\"0\",\"6\"],[\"64496.1\",\"1.3\",\"0\",\"4\"],[\"64496.3\",\"397.69\",\"0\",\"5\"],[\"64496.4\",\"543.09\",\"0\",\"4\"],[\"64496.5\",\"0.33\",\"0\",\"3\"],[\"64496.6\",\"31.68\",\"0\",\"2\"],[\"64496.7\",\"14.22\",\"0\",\"3\"],[\"64496.8\",\"29.39\",\"0\",\"3\"],[\"64496.9\",\"31.29\",\"0\",\"2\"],[\"64497\",\"18.82\",\"0\",\"6\"],[\"64497.1\",\"0.01\",\"0\",\"1\"],[\"64497.2\",\"31.87\",\"0\",\"4\"],[\"64497.3\",\"41.14\",\"0\",\"4\"],[\"64497.4\",\"37.31\",\"0\",\"2\"],[\"64497.5\",\"0.33\",\"0\",\"3\"],[\"64497.6\",\"1.33\",\"0\",\"4\"],[\"64497.8\",\"0.01\",\"0\",\"1\"],[\"64497.9\",\"0.21\",\"0\",\"2\"],[\"64498\",\"0.76\",\"0\",\"2\"],[\"64498.1\",\"232.82\",\"0\",\"4\"],[\"64498.2\",\"18.64\",\"0\",\"6\"],[\"64498.3\",\"84.77\",\"0\",\"6\"],[\"64498.5\",\"4.5\",\"0\",\"4\"],[\"64498.6\",\"1.39\",\"0\",\"7\"],[\"64498.7\",\"2.86\",\"0\",\"4\"],[\"64498.8\",\"6.24\",\"0\",\"3\"],[\"64498.9\",\"49.97\",\"0\",\"4\"],[\"64499\",\"333.09\",\"0\",\"21\"],[\"64499.1\",\"0.16\",\"0\",\"4\"],[\"64499.2\",\"0.01\",\"0\",\"1\"],[\"64499.4\",\"1.73\",\"0\",\"3\"],[\"64499.6\",\"59.37\",\"0\",\"3\"],[\"64499.7\",\"36.92\",\"0\",\"6\"],[\"64499.8\",\"1.08\",\"0\",\"2\"],[\"64499.9\",\"1114.67\",\"0\",\"2\"],[\"64500\",\"3485.25\",\"0\",\"1035\"],[\"64500.1\",\"0.06\",\"0\",\"5\"],[\"64500.2\",\"0.01\",\"0\",\"1\"],[\"64500.3\",\"2.77\",\"0\",\"4\"],[\"64500.4\",\"33.83\",\"0\",\"4\"],[\"64500.5\",\"2.49\",\"0\",\"2\"],[\"64500.6\",\"0.39\",\"0\",\"3\"],[\"64500.7\",\"3.91\",\"0\",\"1\"],[\"64500.8\",\"0.36\",\"0\",\"1\"],[\"64500.9\",\"41.86\",\"0\",\"4\"],[\"64501\",\"0.27\",\"0\",\"3\"],[\"64501.1\",\"0.05\",\"0\",\"2\"],[\"64501.2\",\"15.68\",\"0\",\"4\"],[\"64501.3\",\"0.02\",\"0\",\"1\"],[\"64501.4\",\"15.54\",\"0\",\"2\"],[\"64501.5\",\"1.57\",\"0\",\"4\"],[\"64501.6\",\"1.89\",\"0\",\"3\"],[\"64501.7\",\"0.55\",\"0\",\"4\"],[\"64501.8\",\"60.01\",\"0\",\"7\"],[\"64501.9\",\"0.08\",\"0\",\"1\"],[\"64502\",\"2.12\",\"0\",\"6\"],[\"64502.1\",\"0.01\",\"0\",\"1\"],[\"64502.2\",\"0.11\",\"0\",\"3\"],[\"64502.3\",\"11.22\",\"0\",\"3\"],[\"64502.4\",\"0.96\",\"0\",\"7\"],[\"64502.5\",\"80.1\",\"0\",\"5\"],[\"64502.6\",\"15.66\",\"0\",\"2\"],[\"64502.7\",\"0.03\",\"0\",\"3\"],[\"64502.8\",\"57.07\",\"0\",\"3\"],[\"64502.9\",\"280.5\",\"0\",\"6\"],[\"64503\",\"15.95\",\"0\",\"3\"],[\"64503.1\",\"39.69\",\"0\",\"8\"],[\"64503.2\",\"2.3\",\"0\",\"3\"],[\"64503.3\",\"0.02\",\"0\",\"2\"],[\"64503.5\",\"63.72\",\"0\",\"6\"],[\"64503.6\",\"0.02\",\"0\",\"2\"],[\"64503.7\",\"0.29\",\"0\",\"2\"],[\"64503.8\",\"58.19\",\"0\",\"1\"],[\"64503.9\",\"15.65\",\"0\",\"1\"],[\"64504\",\"254.55\",\"0\",\"9\"],[\"64504.1\",\"15.11\",\"0\",\"6\"],[\"64504.2\",\"496.95\",\"0\",\"4\"],[\"64504.3\",\"0.04\",\"0\",\"2\"],[\"64504.4\",\"1.13\",\"0\",\"4\"],[\"64504.5\",\"58.15\",\"0\",\"5\"],[\"64504.7\",\"0.01\",\"0\",\"1\"],[\"64504.8\",\"0.11\",\"0\",\"5\"],[\"64504.9\",\"0.1\",\"0\",\"3\"],[\"64505\",\"0.82\",\"0\",\"3\"],[\"64505.1\",\"85.36\",\"0\",\"3\"],[\"64505.2\",\"15.65\",\"0\",\"1\"],[\"64505.3\",\"2.66\",\"0\",\"4\"],[\"64505.4\",\"59.23\",\"0\",\"4\"],[\"64505.5\",\"3.91\",\"0\",\"2\"],[\"64505.6\",\"57.91\",\"0\",\"4\"],[\"64505.7\",\"0.56\",\"0\",\"1\"],[\"64505.8\",\"2.36\",\"0\",\"2\"],[\"64505.9\",\"1.01\",\"0\",\"2\"],[\"64506\",\"10.07\",\"0\",\"5\"],[\"64506.1\",\"6.28\",\"0\",\"2\"],[\"64506.2\",\"0.03\",\"0\",\"2\"],[\"64506.3\",\"52.86\",\"0\",\"3\"],[\"64506.4\",\"0.03\",\"0\",\"3\"],[\"64506.5\",\"16.72\",\"0\",\"3\"],[\"64506.6\",\"10.15\",\"0\",\"3\"],[\"64506.7\",\"0.19\",\"0\",\"15\"],[\"64506.8\",\"2.55\",\"0\",\"6\"],[\"64506.9\",\"38.85\",\"0\",\"3\"],[\"64507\",\"0.06\",\"0\",\"1\"],[\"64507.1\",\"0.06\",\"0\",\"4\"],[\"64507.2\",\"15.23\",\"0\",\"3\"],[\"64507.3\",\"189.35\",\"0\",\"3\"],[\"64507.4\",\"27.31\",\"0\",\"5\"],[\"64507.5\",\"1.33\",\"0\",\"7\"],[\"64507.6\",\"0.03\",\"0\",\"2\"],[\"64507.7\",\"0.07\",\"0\",\"4\"],[\"64507.8\",\"35.33\",\"0\",\"6\"],[\"64507.9\",\"0.27\",\"0\",\"4\"],[\"64508\",\"37.26\",\"0\",\"10\"],[\"64508.1\",\"0.82\",\"0\",\"3\"],[\"64508.2\",\"59.01\",\"0\",\"5\"],[\"64508.3\",\"1.2\",\"0\",\"1\"],[\"64508.4\",\"1.62\",\"0\",\"5\"],[\"64508.5\",\"42.46\",\"0\",\"3\"],[\"64508.6\",\"0.01\",\"0\",\"1\"],[\"64508.7\",\"24.98\",\"0\",\"8\"],[\"64508.8\",\"357.61\",\"0\",\"3\"],[\"64508.9\",\"12.42\",\"0\",\"4\"],[\"64509\",\"15.66\",\"0\",\"2\"],[\"64509.1\",\"1.52\",\"0\",\"3\"],[\"64509.3\",\"0.28\",\"0\",\"5\"],[\"64509.4\",\"128.83\",\"0\",\"2\"],[\"64509.6\",\"15.68\",\"0\",\"3\"],[\"64509.8\",\"0.01\",\"0\",\"1\"],[\"64509.9\",\"1.21\",\"0\",\"3\"],[\"64510\",\"71.5\",\"0\",\"30\"],[\"64510.1\",\"0.01\",\"0\",\"1\"],[\"64510.2\",\"15.65\",\"0\",\"1\"],[\"64510.3\",\"1\",\"0\",\"1\"],[\"64510.4\",\"0.53\",\"0\",\"4\"],[\"64510.5\",\"59.3\",\"0\",\"4\"],[\"64510.6\",\"0.19\",\"0\",\"2\"],[\"64510.7\",\"1.02\",\"0\",\"3\"],[\"64510.8\",\"0.02\",\"0\",\"1\"],[\"64510.9\",\"0.07\",\"0\",\"4\"],[\"64511\",\"24.52\",\"0\",\"7\"],[\"64511.1\",\"18.79\",\"0\",\"6\"],[\"64511.2\",\"0.02\",\"0\",\"2\"],[\"64511.3\",\"0.93\",\"0\",\"7\"],[\"64511.4\",\"15.78\",\"0\",\"4\"],[\"64511.5\",\"0.3\",\"0\",\"6\"],[\"64511.6\",\"86.12\",\"0\",\"2\"],[\"64511.7\",\"225.46\",\"0\",\"4\"],[\"64511.8\",\"6.2\",\"0\",\"1\"],[\"64511.9\",\"0.14\",\"0\",\"1\"],[\"64512\",\"2.88\",\"0\",\"13\"],[\"64512.1\",\"0.04\",\"0\",\"3\"],[\"64512.2\",\"11.23\",\"0\",\"3\"],[\"64512.3\",\"65.54\",\"0\",\"6\"],[\"64512.4\",\"0.08\",\"0\",\"1\"],[\"64512.5\",\"0.16\",\"0\",\"5\"],[\"64512.6\",\"58.24\",\"0\",\"6\"],[\"64512.7\",\"91.6\",\"0\",\"3\"],[\"64512.9\",\"17.79\",\"0\",\"4\"],[\"64513\",\"10.37\",\"0\",\"3\"],[\"64513.1\",\"1.56\",\"0\",\"2\"],[\"64513.2\",\"0.15\",\"0\",\"4\"],[\"64513.3\",\"1.97\",\"0\",\"9\"],[\"64513.4\",\"15.68\",\"0\",\"3\"],[\"64513.5\",\"0.6\",\"0\",\"3\"],[\"64513.7\",\"0.01\",\"0\",\"1\"],[\"64513.8\",\"0.01\",\"0\",\"1\"],[\"64513.9\",\"0.12\",\"0\",\"1\"],[\"64514\",\"15.66\",\"0\",\"2\"],[\"64514.1\",\"46.51\",\"0\",\"2\"],[\"64514.2\",\"1.07\",\"0\",\"4\"],[\"64514.3\",\"8.11\",\"0\",\"6\"],[\"64514.4\",\"15.7\",\"0\",\"4\"],[\"64514.5\",\"18.7\",\"0\",\"6\"],[\"64514.6\",\"15.68\",\"0\",\"2\"],[\"64514.7\",\"0.01\",\"0\",\"1\"],[\"64514.8\",\"60.79\",\"0\",\"6\"],[\"64514.9\",\"496.61\",\"0\",\"4\"],[\"64515\",\"0.04\",\"0\",\"2\"],[\"64515.1\",\"20.45\",\"0\",\"1\"],[\"64515.2\",\"15.66\",\"0\",\"2\"],[\"64515.3\",\"0.01\",\"0\",\"1\"],[\"64515.4\",\"0.46\",\"0\",\"5\"],[\"64515.5\",\"75.46\",\"0\",\"7\"],[\"64515.6\",\"0.09\",\"0\",\"4\"],[\"64515.7\",\"59.35\",\"0\",\"2\"],[\"64515.8\",\"16.99\",\"0\",\"3\"],[\"64515.9\",\"47.94\",\"0\",\"4\"],[\"64516\",\"500.05\",\"0\",\"6\"],[\"64516.1\",\"0.05\",\"0\",\"5\"],[\"64516.2\",\"15.65\",\"0\",\"1\"],[\"64516.3\",\"2.16\",\"0\",\"3\"],[\"64516.4\",\"16.74\",\"0\",\"9\"],[\"64516.5\",\"49.1\",\"0\",\"2\"],[\"64516.6\",\"0.7\",\"0\",\"2\"],[\"64516.7\",\"149.16\",\"0\",\"10\"],[\"64516.8\",\"6.26\",\"0\",\"3\"],[\"64516.9\",\"14.05\",\"0\",\"4\"],[\"64517\",\"17.37\",\"0\",\"20\"],[\"64517.1\",\"0.18\",\"0\",\"1\"],[\"64517.2\",\"0.76\",\"0\",\"5\"],[\"64517.4\",\"0.03\",\"0\",\"2\"],[\"64517.6\",\"25.58\",\"0\",\"2\"],[\"64517.7\",\"18.68\",\"0\",\"4\"],[\"64517.8\",\"0.1\",\"0\",\"3\"],[\"64517.9\",\"0.15\",\"0\",\"3\"],[\"64518\",\"103.05\",\"0\",\"13\"],[\"64518.1\",\"4.88\",\"0\",\"6\"],[\"64518.2\",\"15.68\",\"0\",\"2\"],[\"64518.3\",\"0.02\",\"0\",\"2\"],[\"64518.4\",\"76.16\",\"0\",\"4\"],[\"64518.5\",\"0.01\",\"0\",\"1\"],[\"64518.6\",\"0.11\",\"0\",\"8\"],[\"64518.8\",\"74.74\",\"0\",\"4\"],[\"64518.9\",\"0.01\",\"0\",\"1\"],[\"64519\",\"0.67\",\"0\",\"4\"],[\"64519.1\",\"43.07\",\"0\",\"2\"],[\"64519.2\",\"0.06\",\"0\",\"6\"],[\"64519.3\",\"0.05\",\"0\",\"2\"],[\"64519.4\",\"0.06\",\"0\",\"2\"],[\"64519.5\",\"54.3\",\"0\",\"6\"],[\"64519.6\",\"0.02\",\"0\",\"2\"],[\"64519.7\",\"10.81\",\"0\",\"7\"],[\"64519.8\",\"89.37\",\"0\",\"5\"],[\"64519.9\",\"496.56\",\"0\",\"2\"],[\"64520\",\"78.62\",\"0\",\"63\"],[\"64520.1\",\"0.02\",\"0\",\"2\"],[\"64520.2\",\"0.01\",\"0\",\"1\"],[\"64520.3\",\"0.05\",\"0\",\"3\"],[\"64520.4\",\"1.19\",\"0\",\"7\"],[\"64520.5\",\"0.04\",\"0\",\"3\"],[\"64520.6\",\"0.02\",\"0\",\"2\"],[\"64520.7\",\"30.4\",\"0\",\"1\"],[\"64520.8\",\"0.04\",\"0\",\"2\"],[\"64520.9\",\"0.02\",\"0\",\"2\"],[\"64521\",\"121.98\",\"0\",\"8\"],[\"64521.3\",\"69.03\",\"0\",\"2\"],[\"64521.4\",\"0.35\",\"0\",\"1\"],[\"64521.5\",\"7.71\",\"0\",\"5\"],[\"64521.6\",\"1.86\",\"0\",\"4\"],[\"64521.7\",\"0.06\",\"0\",\"3\"],[\"64521.8\",\"2.44\",\"0\",\"4\"],[\"64521.9\",\"16.99\",\"0\",\"2\"],[\"64522\",\"5.16\",\"0\",\"8\"],[\"64522.1\",\"14.42\",\"0\",\"2\"],[\"64522.2\",\"0.15\",\"0\",\"8\"],[\"64522.3\",\"0.01\",\"0\",\"1\"],[\"64522.4\",\"0.42\",\"0\",\"1\"],[\"64522.5\",\"0.01\",\"0\",\"1\"],[\"64522.6\",\"1.54\",\"0\",\"3\"],[\"64522.7\",\"46.54\",\"0\",\"1\"],[\"64522.8\",\"15.71\",\"0\",\"4\"],[\"64522.9\",\"58.86\",\"0\",\"2\"],[\"64523.1\",\"0.01\",\"0\",\"1\"],[\"64523.2\",\"0.02\",\"0\",\"2\"],[\"64523.3\",\"186.34\",\"0\",\"3\"],[\"64523.4\",\"0.02\",\"0\",\"2\"],[\"64523.6\",\"15.76\",\"0\",\"2\"],[\"64523.7\",\"43.32\",\"0\",\"2\"],[\"64523.8\",\"0.02\",\"0\",\"1\"],[\"64524\",\"0.05\",\"0\",\"4\"],[\"64524.1\",\"2.51\",\"0\",\"2\"],[\"64524.2\",\"0.03\",\"0\",\"1\"],[\"64524.3\",\"15.65\",\"0\",\"1\"],[\"64524.4\",\"0.01\",\"0\",\"1\"],[\"64524.5\",\"0.17\",\"0\",\"3\"],[\"64524.6\",\"0.01\",\"0\",\"1\"],[\"64524.7\",\"0.02\",\"0\",\"1\"],[\"64524.8\",\"3.05\",\"0\",\"5\"],[\"64524.9\",\"2.19\",\"0\",\"7\"],[\"64525\",\"2.51\",\"0\",\"18\"]],\"bids\":[[\"64479.8\",\"839.72\",\"0\",\"33\"],[\"64479.7\",\"0.62\",\"0\",\"4\"],[\"64479.6\",\"3.35\",\"0\",\"2\"],[\"64479.5\",\"5\",\"0\",\"1\"],[\"64479.1\",\"0.03\",\"0\",\"2\"],[\"64479\",\"5\",\"0\",\"1\"],[\"64478.5\",\"0.01\",\"0\",\"1\"],[\"64478.3\",\"0.01\",\"0\",\"1\"],[\"64478\",\"0.01\",\"0\",\"1\"],[\"64477.9\",\"1.57\",\"0\",\"2\"],[\"64477.8\",\"1\",\"0\",\"1\"],[\"64477.7\",\"0.02\",\"0\",\"2\"],[\"64477.6\",\"0.01\",\"0\",\"1\"],[\"64477.4\",\"1.56\",\"0\",\"1\"],[\"64477.1\",\"0.01\",\"0\",\"1\"],[\"64476.9\",\"0.02\",\"0\",\"2\"],[\"64476.7\",\"0.02\",\"0\",\"2\"],[\"64476.6\",\"1\",\"0\",\"1\"],[\"64476.3\",\"0.01\",\"0\",\"1\"],[\"64476.2\",\"12.01\",\"0\",\"3\"],[\"64476\",\"1.6\",\"0\",\"3\"],[\"64475.9\",\"0.01\",\"0\",\"1\"],[\"64475.8\",\"0.02\",\"0\",\"2\"],[\"64475.7\",\"2.01\",\"0\",\"2\"],[\"64475.6\",\"93.42\",\"0\",\"1\"],[\"64475.5\",\"1.56\",\"0\",\"1\"],[\"64475.4\",\"0.02\",\"0\",\"2\"],[\"64475\",\"1.88\",\"0\",\"3\"],[\"64474.9\",\"20.31\",\"0\",\"2\"],[\"64474.8\",\"0.01\",\"0\",\"1\"],[\"64474.7\",\"0.02\",\"0\",\"2\"],[\"64474.6\",\"3.56\",\"0\",\"2\"],[\"64474.4\",\"0.3\",\"0\",\"1\"],[\"64474.1\",\"1.58\",\"0\",\"3\"],[\"64474\",\"14.42\",\"0\",\"3\"],[\"64473.9\",\"46.56\",\"0\",\"3\"],[\"64473.8\",\"71.64\",\"0\",\"3\"],[\"64473.6\",\"154.61\",\"0\",\"2\"],[\"64473.5\",\"83.49\",\"0\",\"1\"],[\"64473.3\",\"0.01\",\"0\",\"1\"],[\"64473.2\",\"0.01\",\"0\",\"1\"],[\"64472.9\",\"94.7\",\"0\",\"1\"],[\"64472.8\",\"77.55\",\"0\",\"1\"],[\"64472.7\",\"1.58\",\"0\",\"3\"],[\"64472.3\",\"7.2\",\"0\",\"2\"],[\"64472.2\",\"1.56\",\"0\",\"1\"],[\"64472.1\",\"11.35\",\"0\",\"3\"],[\"64472\",\"70.34\",\"0\",\"5\"],[\"64471.7\",\"32.18\",\"0\",\"2\"],[\"64471.5\",\"0.01\",\"0\",\"1\"],[\"64471.4\",\"85.42\",\"0\",\"3\"],[\"64471.3\",\"1.15\",\"0\",\"1\"],[\"64470.9\",\"0.01\",\"0\",\"1\"],[\"64470.7\",\"0.02\",\"0\",\"2\"],[\"64470.5\",\"0.01\",\"0\",\"1\"],[\"64470.3\",\"0.01\",\"0\",\"1\"],[\"64470.1\",\"1.54\",\"0\",\"2\"],[\"64470\",\"37.27\",\"0\",\"3\"],[\"64469.9\",\"31.05\",\"0\",\"1\"],[\"64469.8\",\"83.79\",\"0\",\"1\"],[\"64469.7\",\"23.66\",\"0\",\"3\"],[\"64469.6\",\"12.01\",\"0\",\"3\"],[\"64469.5\",\"355.53\",\"0\",\"3\"],[\"64469.4\",\"46.54\",\"0\",\"1\"],[\"64469.3\",\"496.53\",\"0\",\"1\"],[\"64469.2\",\"154.75\",\"0\",\"2\"],[\"64469.1\",\"0.01\",\"0\",\"1\"],[\"64468.9\",\"0.3\",\"0\",\"1\"],[\"64468.8\",\"11.33\",\"0\",\"1\"],[\"64468.7\",\"140.55\",\"0\",\"8\"],[\"64468.6\",\"50\",\"0\",\"1\"],[\"64468.5\",\"50\",\"0\",\"1\"],[\"64468.4\",\"50\",\"0\",\"1\"],[\"64468.3\",\"4.77\",\"0\",\"1\"],[\"64468.2\",\"62.15\",\"0\",\"1\"],[\"64468.1\",\"15.94\",\"0\",\"1\"],[\"64468\",\"0.26\",\"0\",\"4\"],[\"64467.9\",\"0.01\",\"0\",\"1\"],[\"64467.8\",\"0.01\",\"0\",\"1\"],[\"64467.6\",\"1.29\",\"0\",\"3\"],[\"64467.5\",\"0.03\",\"0\",\"2\"],[\"64467.4\",\"0.3\",\"0\",\"1\"],[\"64467.3\",\"94.73\",\"0\",\"1\"],[\"64467\",\"0.07\",\"0\",\"1\"],[\"64466.9\",\"167.7\",\"0\",\"5\"],[\"64466.8\",\"0.01\",\"0\",\"1\"],[\"64466.6\",\"0.01\",\"0\",\"1\"],[\"64466.5\",\"15.98\",\"0\",\"1\"],[\"64466.4\",\"243.98\",\"0\",\"2\"],[\"64466.2\",\"0.01\",\"0\",\"1\"],[\"64466\",\"0.02\",\"0\",\"2\"],[\"64465.9\",\"148.92\",\"0\",\"1\"],[\"64465.7\",\"1.88\",\"0\",\"2\"],[\"64465.6\",\"28.21\",\"0\",\"4\"],[\"64465.5\",\"6.22\",\"0\",\"1\"],[\"64465.4\",\"507.87\",\"0\",\"3\"],[\"64465.3\",\"46.56\",\"0\",\"3\"],[\"64465.1\",\"25.9\",\"0\",\"3\"],[\"64465\",\"0.04\",\"0\",\"2\"],[\"64464.9\",\"31.06\",\"0\",\"1\"],[\"64464.8\",\"0.01\",\"0\",\"1\"],[\"64464.7\",\"1.6\",\"0\",\"1\"],[\"64464.5\",\"0.02\",\"0\",\"2\"],[\"64464.4\",\"1.69\",\"0\",\"2\"],[\"64464.2\",\"155.57\",\"0\",\"5\"],[\"64464.1\",\"1.92\",\"0\",\"1\"],[\"64464\",\"0.06\",\"0\",\"4\"],[\"64463.9\",\"0.31\",\"0\",\"1\"],[\"64463.8\",\"349.94\",\"0\",\"3\"],[\"64463.6\",\"14.77\",\"0\",\"4\"],[\"64463.5\",\"0.01\",\"0\",\"1\"],[\"64463.4\",\"0.77\",\"0\",\"1\"],[\"64463.3\",\"49.54\",\"0\",\"2\"],[\"64463.1\",\"37.23\",\"0\",\"1\"],[\"64463\",\"2.9\",\"0\",\"3\"],[\"64462.7\",\"22.95\",\"0\",\"2\"],[\"64462.6\",\"3.11\",\"0\",\"2\"],[\"64462.5\",\"5.3\",\"0\",\"2\"],[\"64462.4\",\"0.94\",\"0\",\"3\"],[\"64462.1\",\"11.33\",\"0\",\"1\"],[\"64462\",\"0.01\",\"0\",\"1\"],[\"64461.9\",\"0.01\",\"0\",\"1\"],[\"64461.7\",\"33.83\",\"0\",\"2\"],[\"64461.6\",\"1\",\"0\",\"1\"],[\"64461.5\",\"0.02\",\"0\",\"2\"],[\"64461.4\",\"0.03\",\"0\",\"3\"],[\"64461.3\",\"516.65\",\"0\",\"3\"],[\"64461.2\",\"0.06\",\"0\",\"3\"],[\"64461.1\",\"46.56\",\"0\",\"2\"],[\"64461\",\"86.18\",\"0\",\"1\"],[\"64460.9\",\"95.5\",\"0\",\"2\"],[\"64460.8\",\"352.77\",\"0\",\"6\"],[\"64460.7\",\"44.97\",\"0\",\"3\"],[\"64460.6\",\"0.16\",\"0\",\"2\"],[\"64460.5\",\"1.5\",\"0\",\"1\"],[\"64460.3\",\"0.55\",\"0\",\"1\"],[\"64460.1\",\"3.91\",\"0\",\"2\"],[\"64460\",\"0.31\",\"0\",\"3\"],[\"64459.7\",\"0.01\",\"0\",\"1\"],[\"64459.5\",\"15.65\",\"0\",\"1\"],[\"64459.4\",\"76.06\",\"0\",\"4\"],[\"64459.3\",\"0.18\",\"0\",\"2\"],[\"64459.2\",\"85.41\",\"0\",\"2\"],[\"64459.1\",\"46.54\",\"0\",\"1\"],[\"64459\",\"31.05\",\"0\",\"1\"],[\"64458.9\",\"232.94\",\"0\",\"2\"],[\"64458.8\",\"0.02\",\"0\",\"1\"],[\"64458.7\",\"21.33\",\"0\",\"3\"],[\"64458.6\",\"0.16\",\"0\",\"2\"],[\"64458.4\",\"2.61\",\"0\",\"2\"],[\"64458.3\",\"0.03\",\"0\",\"3\"],[\"64458\",\"151.93\",\"0\",\"3\"],[\"64457.9\",\"0.01\",\"0\",\"1\"],[\"64457.6\",\"0.01\",\"0\",\"1\"],[\"64457.5\",\"0.01\",\"0\",\"1\"],[\"64457.4\",\"11.18\",\"0\",\"1\"],[\"64457.1\",\"531.13\",\"0\",\"2\"],[\"64457\",\"743.15\",\"0\",\"5\"],[\"64456.6\",\"0.08\",\"0\",\"2\"],[\"64456.5\",\"26.96\",\"0\",\"2\"],[\"64456.3\",\"85.8\",\"0\",\"3\"],[\"64456.2\",\"21.87\",\"0\",\"2\"],[\"64456.1\",\"249.79\",\"0\",\"3\"],[\"64456\",\"10.02\",\"0\",\"3\"],[\"64455.8\",\"0.01\",\"0\",\"1\"],[\"64455.7\",\"58.53\",\"0\",\"3\"],[\"64455.6\",\"37.69\",\"0\",\"2\"],[\"64455.5\",\"31.3\",\"0\",\"2\"],[\"64455.3\",\"10.9\",\"0\",\"2\"],[\"64455.2\",\"71.24\",\"0\",\"5\"],[\"64455\",\"180.69\",\"0\",\"3\"],[\"64454.8\",\"13.1\",\"0\",\"2\"],[\"64454.7\",\"0.03\",\"0\",\"2\"],[\"64454.6\",\"0.01\",\"0\",\"1\"],[\"64454.4\",\"62.16\",\"0\",\"2\"],[\"64454.3\",\"10.02\",\"0\",\"2\"],[\"64454.2\",\"38.83\",\"0\",\"1\"],[\"64454\",\"0.06\",\"0\",\"3\"],[\"64453.6\",\"0.04\",\"0\",\"2\"],[\"64453.4\",\"15.67\",\"0\",\"3\"],[\"64453.3\",\"0.12\",\"0\",\"12\"],[\"64452.9\",\"15.65\",\"0\",\"1\"],[\"64452.8\",\"29.87\",\"0\",\"3\"],[\"64452.7\",\"323.57\",\"0\",\"4\"],[\"64452.6\",\"512.18\",\"0\",\"2\"],[\"64452.5\",\"31.32\",\"0\",\"4\"],[\"64452.4\",\"0.2\",\"0\",\"1\"],[\"64452.3\",\"0.15\",\"0\",\"1\"],[\"64452.2\",\"15.65\",\"0\",\"1\"],[\"64452.1\",\"10.02\",\"0\",\"3\"],[\"64452\",\"10.17\",\"0\",\"6\"],[\"64451.8\",\"46.54\",\"0\",\"1\"],[\"64451.7\",\"271.88\",\"0\",\"5\"],[\"64451.6\",\"25.67\",\"0\",\"4\"],[\"64451.5\",\"61.97\",\"0\",\"2\"],[\"64451.3\",\"15.65\",\"0\",\"1\"],[\"64451.2\",\"0.01\",\"0\",\"1\"],[\"64451\",\"0.02\",\"0\",\"2\"],[\"64450.8\",\"15.65\",\"0\",\"1\"],[\"64450.7\",\"0.04\",\"0\",\"2\"],[\"64450.5\",\"0.01\",\"0\",\"1\"],[\"64450.4\",\"15.43\",\"0\",\"1\"],[\"64450.3\",\"0.01\",\"0\",\"1\"],[\"64450.1\",\"0.18\",\"0\",\"2\"],[\"64450\",\"22.84\",\"0\",\"20\"],[\"64449.9\",\"273.58\",\"0\",\"3\"],[\"64449.8\",\"84.83\",\"0\",\"3\"],[\"64449.7\",\"0.04\",\"0\",\"1\"],[\"64449.6\",\"15.65\",\"0\",\"1\"],[\"64449.5\",\"15.54\",\"0\",\"2\"],[\"64449.4\",\"0.01\",\"0\",\"1\"],[\"64449.3\",\"6.22\",\"0\",\"1\"],[\"64449.2\",\"15.65\",\"0\",\"1\"],[\"64449\",\"0.03\",\"0\",\"3\"],[\"64448.9\",\"0.52\",\"0\",\"2\"],[\"64448.8\",\"0.07\",\"0\",\"1\"],[\"64448.5\",\"512.19\",\"0\",\"3\"],[\"64448.4\",\"5.06\",\"0\",\"3\"],[\"64448.3\",\"10.03\",\"0\",\"3\"],[\"64448.1\",\"46.54\",\"0\",\"1\"],[\"64448\",\"426.87\",\"0\",\"9\"],[\"64447.8\",\"46.55\",\"0\",\"2\"],[\"64447.7\",\"0.05\",\"0\",\"1\"],[\"64447.6\",\"0.01\",\"0\",\"1\"],[\"64447.5\",\"0.01\",\"0\",\"1\"],[\"64447.1\",\"0.01\",\"0\",\"1\"],[\"64447\",\"15.65\",\"0\",\"1\"],[\"64446.8\",\"38.84\",\"0\",\"1\"],[\"64446.7\",\"0.01\",\"0\",\"1\"],[\"64446.6\",\"11.18\",\"0\",\"1\"],[\"64446.5\",\"0.02\",\"0\",\"2\"],[\"64446.4\",\"31.07\",\"0\",\"1\"],[\"64446.3\",\"15.65\",\"0\",\"1\"],[\"64446.2\",\"0.07\",\"0\",\"1\"],[\"64446\",\"15.77\",\"0\",\"5\"],[\"64445.9\",\"0.01\",\"0\",\"1\"],[\"64445.8\",\"0.01\",\"0\",\"1\"],[\"64445.7\",\"0.02\",\"0\",\"2\"],[\"64445.6\",\"0.5\",\"0\",\"1\"],[\"64445.5\",\"357.5\",\"0\",\"1\"],[\"64445.4\",\"15.65\",\"0\",\"1\"],[\"64445.3\",\"10.03\",\"0\",\"4\"],[\"64445\",\"0.01\",\"0\",\"1\"],[\"64444.9\",\"0.5\",\"0\",\"1\"],[\"64444.8\",\"10.01\",\"0\",\"2\"],[\"64444.7\",\"342.07\",\"0\",\"3\"],[\"64444.6\",\"500.02\",\"0\",\"2\"],[\"64444.5\",\"156.71\",\"0\",\"3\"],[\"64444.4\",\"37.24\",\"0\",\"2\"],[\"64444.3\",\"0.01\",\"0\",\"1\"],[\"64444.2\",\"10\",\"0\",\"1\"],[\"64444.1\",\"142.6\",\"0\",\"3\"],[\"64444\",\"15.67\",\"0\",\"3\"],[\"64443.9\",\"0.01\",\"0\",\"1\"],[\"64443.8\",\"0.01\",\"0\",\"1\"],[\"64443.7\",\"10\",\"0\",\"1\"],[\"64443.3\",\"0.02\",\"0\",\"2\"],[\"64443.2\",\"10.01\",\"0\",\"2\"],[\"64443\",\"15.66\",\"0\",\"2\"],[\"64442.9\",\"0.01\",\"0\",\"1\"],[\"64442.8\",\"0.01\",\"0\",\"1\"],[\"64442.7\",\"0.01\",\"0\",\"1\"],[\"64442.6\",\"15.65\",\"0\",\"1\"],[\"64442.5\",\"10.01\",\"0\",\"2\"],[\"64442.1\",\"62.2\",\"0\",\"3\"],[\"64442\",\"15.02\",\"0\",\"3\"],[\"64441.9\",\"0.02\",\"0\",\"1\"],[\"64441.7\",\"0.01\",\"0\",\"1\"],[\"64441.6\",\"15.66\",\"0\",\"2\"],[\"64441.4\",\"15.66\",\"0\",\"2\"],[\"64441.3\",\"0.01\",\"0\",\"1\"],[\"64441.2\",\"208.93\",\"0\",\"1\"],[\"64441.1\",\"17.22\",\"0\",\"2\"],[\"64440.9\",\"0.01\",\"0\",\"1\"],[\"64440.7\",\"20\",\"0\",\"1\"],[\"64440.6\",\"15.65\",\"0\",\"1\"],[\"64440.4\",\"6.23\",\"0\",\"2\"],[\"64440.3\",\"11.02\",\"0\",\"3\"],[\"64440.2\",\"354.52\",\"0\",\"3\"],[\"64440.1\",\"512.18\",\"0\",\"2\"],[\"64440\",\"3.44\",\"0\",\"17\"],[\"64439.9\",\"46.55\",\"0\",\"2\"],[\"64439.8\",\"98.99\",\"0\",\"2\"],[\"64439.7\",\"15.65\",\"0\",\"1\"],[\"64439.6\",\"15.65\",\"0\",\"1\"],[\"64439.5\",\"0.03\",\"0\",\"2\"],[\"64439.4\",\"93.87\",\"0\",\"2\"],[\"64439.1\",\"97.71\",\"0\",\"2\"],[\"64439\",\"0.01\",\"0\",\"1\"],[\"64438.9\",\"0.01\",\"0\",\"1\"],[\"64438.7\",\"15.65\",\"0\",\"1\"],[\"64438.5\",\"13.07\",\"0\",\"2\"],[\"64438.4\",\"0.01\",\"0\",\"1\"],[\"64438.2\",\"304.51\",\"0\",\"2\"],[\"64438.1\",\"23.69\",\"0\",\"3\"],[\"64437.8\",\"62.2\",\"0\",\"3\"],[\"64437.6\",\"171.46\",\"0\",\"3\"],[\"64437.2\",\"0.01\",\"0\",\"1\"],[\"64437.1\",\"0.29\",\"0\",\"1\"],[\"64436.8\",\"0.79\",\"0\",\"1\"],[\"64436.7\",\"0.54\",\"0\",\"2\"],[\"64436.6\",\"0.01\",\"0\",\"1\"],[\"64436.5\",\"11.29\",\"0\",\"1\"],[\"64436.4\",\"17.99\",\"0\",\"2\"],[\"64436.3\",\"38.84\",\"0\",\"1\"],[\"64436.1\",\"10\",\"0\",\"1\"],[\"64435.9\",\"496.53\",\"0\",\"1\"],[\"64435.8\",\"247.26\",\"0\",\"4\"],[\"64435.6\",\"4.64\",\"0\",\"1\"],[\"64435.5\",\"0.02\",\"0\",\"1\"],[\"64435.2\",\"0.02\",\"0\",\"2\"],[\"64435.1\",\"0.01\",\"0\",\"1\"],[\"64435\",\"164.21\",\"0\",\"3\"],[\"64434.9\",\"0.05\",\"0\",\"1\"],[\"64434.8\",\"15.65\",\"0\",\"1\"],[\"64434.7\",\"118.85\",\"0\",\"4\"],[\"64434.6\",\"1.16\",\"0\",\"1\"],[\"64434.5\",\"38.83\",\"0\",\"1\"],[\"64434.4\",\"17.88\",\"0\",\"1\"],[\"64434.3\",\"0.02\",\"0\",\"2\"],[\"64434.2\",\"0.01\",\"0\",\"1\"],[\"64434.1\",\"0.35\",\"0\",\"2\"],[\"64433.9\",\"37.23\",\"0\",\"1\"],[\"64433.8\",\"6.22\",\"0\",\"1\"],[\"64433.4\",\"0.01\",\"0\",\"1\"],[\"64433.3\",\"0.04\",\"0\",\"2\"],[\"64433.2\",\"11.29\",\"0\",\"1\"],[\"64433.1\",\"15.65\",\"0\",\"1\"],[\"64433\",\"1.73\",\"0\",\"1\"],[\"64432.6\",\"0.06\",\"0\",\"3\"],[\"64432.5\",\"0.01\",\"0\",\"1\"],[\"64432.3\",\"0.02\",\"0\",\"2\"],[\"64432.2\",\"61.75\",\"0\",\"2\"],[\"64432.1\",\"298.07\",\"0\",\"2\"],[\"64432\",\"263.28\",\"0\",\"4\"],[\"64431.9\",\"496.53\",\"0\",\"1\"],[\"64431.5\",\"15.65\",\"0\",\"1\"],[\"64431.4\",\"60.49\",\"0\",\"2\"],[\"64431.3\",\"92.79\",\"0\",\"1\"],[\"64431.1\",\"24.84\",\"0\",\"2\"],[\"64431\",\"4.06\",\"0\",\"17\"],[\"64430.6\",\"0.77\",\"0\",\"1\"],[\"64430.5\",\"15.51\",\"0\",\"1\"],[\"64430.4\",\"113.91\",\"0\",\"3\"],[\"64430.3\",\"1.01\",\"0\",\"2\"],[\"64430.2\",\"0.31\",\"0\",\"1\"],[\"64430.1\",\"0.01\",\"0\",\"1\"],[\"64430\",\"51.55\",\"0\",\"3\"],[\"64429.9\",\"12.37\",\"0\",\"4\"],[\"64429.8\",\"15.66\",\"0\",\"2\"],[\"64429.6\",\"4.13\",\"0\",\"1\"],[\"64429.4\",\"0.02\",\"0\",\"1\"],[\"64429.2\",\"0.11\",\"0\",\"1\"],[\"64429.1\",\"20.02\",\"0\",\"2\"],[\"64428.8\",\"0.01\",\"0\",\"1\"],[\"64428.6\",\"1.19\",\"0\",\"4\"],[\"64428.4\",\"37.23\",\"0\",\"1\"],[\"64428.3\",\"0.38\",\"0\",\"1\"],[\"64428.2\",\"15.65\",\"0\",\"1\"],[\"64428.1\",\"0.65\",\"0\",\"2\"],[\"64428\",\"326.1\",\"0\",\"4\"],[\"64427.9\",\"18.87\",\"0\",\"1\"],[\"64427.8\",\"543.07\",\"0\",\"2\"],[\"64427.7\",\"0.01\",\"0\",\"1\"],[\"64427.3\",\"6.23\",\"0\",\"2\"],[\"64427.2\",\"0.01\",\"0\",\"1\"],[\"64427\",\"266.81\",\"0\",\"5\"],[\"64426.8\",\"0.06\",\"0\",\"1\"],[\"64426.7\",\"0.12\",\"0\",\"12\"],[\"64426.6\",\"0.01\",\"0\",\"1\"],[\"64426.5\",\"0.04\",\"0\",\"1\"],[\"64426.4\",\"3\",\"0\",\"1\"],[\"64426.1\",\"19.89\",\"0\",\"4\"],[\"64426\",\"0.02\",\"0\",\"1\"],[\"64425.7\",\"2.01\",\"0\",\"1\"],[\"64425.6\",\"3.91\",\"0\",\"2\"],[\"64425.5\",\"11.06\",\"0\",\"1\"],[\"64425.4\",\"0.07\",\"0\",\"1\"],[\"64425.3\",\"2\",\"0\",\"1\"],[\"64425\",\"1.87\",\"0\",\"7\"],[\"64424.9\",\"15.66\",\"0\",\"2\"],[\"64424.6\",\"0.01\",\"0\",\"1\"],[\"64424.4\",\"46.54\",\"0\",\"1\"],[\"64424.2\",\"0.01\",\"0\",\"1\"],[\"64424\",\"3.64\",\"0\",\"5\"],[\"64423.9\",\"229.18\",\"0\",\"2\"],[\"64423.8\",\"62.32\",\"0\",\"3\"],[\"64423.5\",\"15.48\",\"0\",\"1\"],[\"64423.3\",\"496.84\",\"0\",\"2\"],[\"64423.2\",\"37.23\",\"0\",\"1\"],[\"64423.1\",\"92.81\",\"0\",\"2\"],[\"64423\",\"1.59\",\"0\",\"6\"],[\"64422.8\",\"2.29\",\"0\",\"2\"],[\"64422.7\",\"0.02\",\"0\",\"1\"],[\"64422.6\",\"0.02\",\"0\",\"2\"],[\"64422.5\",\"14.15\",\"0\",\"1\"],[\"64422.4\",\"1365.48\",\"0\",\"3\"],[\"64422.3\",\"0.01\",\"0\",\"1\"],[\"64422.2\",\"11.42\",\"0\",\"3\"],[\"64422\",\"0.01\",\"0\",\"1\"]],\"ts\":\"1782016019105\",\"checksum\":-19878892,\"seqId\":325070060415,\"prevSeqId\":-1}]}"}
{"action": "update", "capture_sequence": 5, "channel": "books", "connection_sequence": 1, "event": null, "instId": "BTC-USDT-SWAP", "local_receive_ts": "2026-06-21T04:26:59Z", "monotonic_ns": 1643575128838258, "raw": "{\"arg\":{\"channel\":\"books\",\"instId\":\"BTC-USDT-SWAP\"},\"action\":\"update\",\"data\":[{\"asks\":[[\"64479.9\",\"469.24\",\"0\",\"35\"],[\"64482.6\",\"0.03\",\"0\",\"3\"],[\"64482.7\",\"2.57\",\"0\",\"3\"],[\"64482.8\",\"0.01\",\"0\",\"1\"],[\"64483\",\"0.03\",\"0\",\"2\"],[\"64488\",\"65.87\",\"0\",\"28\"],[\"64488.6\",\"0.03\",\"0\",\"3\"],[\"64489.4\",\"2.93\",\"0\",\"5\"]],\"bids\":[[\"64478.2\",\"1.56\",\"0\",\"1\"],[\"64477.9\",\"0.01\",\"0\",\"1\"],[\"64422\",\"0\",\"0\",\"0\"]],\"ts\":\"1782016019205\",\"checksum\":-888871989,\"seqId\":325070060500,\"prevSeqId\":325070060415}]}"}
{"action": null, "capture_sequence": 6, "channel": "trades", "connection_sequence": 1, "event": null, "instId": "BTC-USDT-SWAP", "local_receive_ts": "2026-06-21T04:26:59Z", "monotonic_ns": 1643575163513151, "raw": "{\"arg\":{\"channel\":\"trades\",\"instId\":\"BTC-USDT-SWAP\"},\"data\":[{\"instId\":\"BTC-USDT-SWAP\",\"tradeId\":\"2718750115\",\"px\":\"64479.9\",\"sz\":\"0.1\",\"side\":\"buy\",\"ts\":\"1782016019226\",\"count\":\"1\",\"source\":\"0\",\"seqId\":325070060528}]}"}
{"action": null, "capture_sequence": 7, "channel": "trades", "connection_sequence": 1, "event": null, "instId": "BTC-USDT-SWAP", "local_receive_ts": "2026-06-21T04:26:59Z", "monotonic_ns": 1643575188404785, "raw": "{\"arg\":{\"channel\":\"trades\",\"instId\":\"BTC-USDT-SWAP\"},\"data\":[{\"instId\":\"BTC-USDT-SWAP\",\"tradeId\":\"2718750116\",\"px\":\"64479.9\",\"sz\":\"4.96\",\"side\":\"buy\",\"ts\":\"1782016019285\",\"count\":\"1\",\"source\":\"0\",\"seqId\":325070060590}]}"}
{"action": null, "capture_sequence": 8, "channel": "trades", "connection_sequence": 1, "event": null, "instId": "BTC-USDT-SWAP", "local_receive_ts": "2026-06-21T04:26:59Z", "monotonic_ns": 1643575227254587, "raw": "{\"arg\":{\"channel\":\"trades\",\"instId\":\"BTC-USDT-SWAP\"},\"data\":[{\"instId\":\"BTC-USDT-SWAP\",\"tradeId\":\"2718750117\",\"px\":\"64479.8\",\"sz\":\"0.22\",\"side\":\"sell\",\"ts\":\"1782016019301\",\"count\":\"1\",\"source\":\"0\",\"seqId\":325070060613}]}"}
{"action": "update", "capture_sequence": 9, "channel": "books", "connection_sequence": 1, "event": null, "instId": "BTC-USDT-SWAP", "local_receive_ts": "2026-06-21T04:26:59Z", "monotonic_ns": 1643575227633699, "raw": "{\"arg\":{\"channel\":\"books\",\"instId\":\"BTC-USDT-SWAP\"},\"action\":\"update\",\"data\":[{\"asks\":[[\"64479.9\",\"468.54\",\"0\",\"37\"],[\"64481.5\",\"1.58\",\"0\",\"2\"],[\"64482.6\",\"0.02\",\"0\",\"2\"],[\"64482.7\",\"1.01\",\"0\",\"2\"],[\"64483\",\"0.04\",\"0\",\"3\"],[\"64483.3\",\"105.88\",\"0\",\"4\"],[\"64483.4\",\"2.56\",\"0\",\"2\"],[\"64484\",\"3.28\",\"0\",\"5\"],[\"64487.5\",\"0.04\",\"0\",\"3\"]],\"bids\":[[\"64479.8\",\"839.5\",\"0\",\"33\"],[\"64478.2\",\"0\",\"0\",\"0\"],[\"64477.4\",\"0\",\"0\",\"0\"],[\"64476\",\"0.04\",\"0\",\"2\"],[\"64475.5\",\"0\",\"0\",\"0\"],[\"64473.6\",\"156.17\",\"0\",\"3\"],[\"64473.1\",\"1.56\",\"0\",\"1\"],[\"64422.2\",\"0.02\",\"0\",\"2\"],[\"64422\",\"0.01\",\"0\",\"1\"],[\"64421.9\",\"0.01\",\"0\",\"1\"]],\"ts\":\"1782016019305\",\"checksum\":-553785634,\"seqId\":325070060627,\"prevSeqId\":325070060500}]}"}
{"action": null, "capture_sequence": 10, "channel": "trades", "connection_sequence": 1, "event": null, "instId": "BTC-USDT-SWAP", "local_receive_ts": "2026-06-21T04:26:59Z", "monotonic_ns": 1643575291684896, "raw": "{\"arg\":{\"channel\":\"trades\",\"instId\":\"BTC-USDT-SWAP\"},\"data\":[{\"instId\":\"BTC-USDT-SWAP\",\"tradeId\":\"2718750118\",\"px\":\"64479.9\",\"sz\":\"7\",\"side\":\"buy\",\"ts\":\"1782016019388\",\"count\":\"1\",\"source\":\"0\",\"seqId\":325070060713}]}"}
{"action": "update", "capture_sequence": 11, "channel": "books", "connection_sequence": 1, "event": null, "instId": "BTC-USDT-SWAP", "local_receive_ts": "2026-06-21T04:26:59Z", "monotonic_ns": 1643575308819757, "raw": "{\"arg\":{\"channel\":\"books\",\"instId\":\"BTC-USDT-SWAP\"},\"action\":\"update\",\"data\":[{\"asks\":[[\"64479.9\",\"474.36\",\"0\",\"38\"],[\"64481.5\",\"0.02\",\"0\",\"1\"],[\"64482.4\",\"0.01\",\"0\",\"1\"],[\"64483\",\"0.03\",\"0\",\"2\"],[\"64483.4\",\"1\",\"0\",\"1\"],[\"64484\",\"1.72\",\"0\",\"4\"],[\"64487.5\",\"1.6\",\"0\",\"4\"],[\"64488\",\"67.43\",\"0\",\"29\"],[\"64525\",\"0\",\"0\",\"0\"]],\"bids\":[[\"64479.8\",\"841.19\",\"0\",\"34\"],[\"64477.9\",\"1.57\",\"0\",\"2\"],[\"64477.5\",\"1.56\",\"0\",\"1\"],[\"64475.5\",\"1.56\",\"0\",\"1\"],[\"64475\",\"0.32\",\"0\",\"2\"],[\"64474.8\",\"1.57\",\"0\",\"2\"],[\"64474.6\",\"2\",\"0\",\"1\"],[\"64471.7\",\"30.62\",\"0\",\"1\"],[\"64422\",\"0\",\"0\",\"0\"],[\"64421.9\",\"0\",\"0\",\"0\"]],\"ts\":\"1782016019405\",\"checksum\":-801245831,\"seqId\":325070060752,\"prevSeqId\":325070060627}]}"}
{"action": null, "capture_sequence": 12, "channel": "trades", "connection_sequence": 1, "event": null, "instId": "BTC-USDT-SWAP", "local_receive_ts": "2026-06-21T04:26:59Z", "monotonic_ns": 1643575317286592, "raw": "{\"arg\":{\"channel\":\"trades\",\"instId\":\"BTC-USDT-SWAP\"},\"data\":[{\"instId\":\"BTC-USDT-SWAP\",\"tradeId\":\"2718750119\",\"px\":\"64479.9\",\"sz\":\"0.1\",\"side\":\"buy\",\"ts\":\"1782016019414\",\"count\":\"1\",\"source\":\"0\",\"seqId\":325070060766}]}"}
{"action": "update", "capture_sequence": 13, "channel": "books", "connection_sequence": 1, "event": null, "instId": "BTC-USDT-SWAP", "local_receive_ts": "2026-06-21T04:26:59Z", "monotonic_ns": 1643575413601793, "raw": "{\"arg\":{\"channel\":\"books\",\"instId\":\"BTC-USDT-SWAP\"},\"action\":\"update\",\"data\":[{\"asks\":[[\"64479.9\",\"660.58\",\"0\",\"40\"],[\"64480.3\",\"0.5\",\"0\",\"1\"],[\"64480.8\",\"0.01\",\"0\",\"1\"],[\"64480.9\",\"1.58\",\"0\",\"3\"],[\"64481\",\"52.61\",\"0\",\"2\"],[\"64481.7\",\"0.01\",\"0\",\"1\"],[\"64481.8\",\"1.6\",\"0\",\"4\"],[\"64481.9\",\"0.01\",\"0\",\"1\"],[\"64482.1\",\"0.02\",\"0\",\"2\"],[\"64482.2\",\"0\",\"0\",\"0\"],[\"64482.3\",\"137.69\",\"0\",\"2\"],[\"64482.4\",\"0\",\"0\",\"0\"],[\"64482.9\",\"1.56\",\"0\",\"1\"],[\"64483.1\",\"0.63\",\"0\",\"4\"],[\"64483.6\",\"1.56\",\"0\",\"1\"],[\"64483.8\",\"0\",\"0\",\"0\"],[\"64484.2\",\"1.56\",\"0\",\"1\"],[\"64486.1\",\"248.86\",\"0\",\"3\"],[\"64486.4\",\"1.78\",\"0\",\"4\"],[\"64486.6\",\"81.32\",\"0\",\"2\"],[\"64487.1\",\"0.53\",\"0\",\"4\"],[\"64487.5\",\"0.04\",\"0\",\"3\"],[\"64488\",\"65.87\",\"0\",\"28\"],[\"64488.1\",\"0.67\",\"0\",\"2\"],[\"64488.5\",\"0\",\"0\",\"0\"],[\"64488.6\",\"0.02\",\"0\",\"2\"],[\"64493.8\",\"15.55\",\"0\",\"3\"],[\"64494.5\",\"0\",\"0\",\"0\"],[\"64496.5\",\"264.15\",\"0\",\"5\"],[\"64497.2\",\"0.84\",\"0\",\"3\"],[\"64498.1\",\"0.03\",\"0\",\"3\"],[\"64498.8\",\"7.79\",\"0\",\"4\"],[\"64499.7\",\"35.37\",\"0\",\"5\"],[\"64499.8\",\"34.88\",\"0\",\"3\"],[\"64500.4\",\"0.03\",\"0\",\"3\"],[\"64502.7\",\"58.22\",\"0\",\"4\"],[\"64503.8\",\"0\",\"0\",\"0\"],[\"64504.3\",\"85.38\",\"0\",\"3\"],[\"64505.1\",\"0.02\",\"0\",\"2\"],[\"64509.3\",\"86.39\",\"0\",\"6\"],[\"64510.8\",\"20.09\",\"0\",\"2\"],[\"64511.6\",\"0.01\",\"0\",\"1\"],[\"64511.7\",\"205.39\",\"0\",\"3\"],[\"64524.9\",\"0\",\"0\",\"0\"]],\"bids\":[[\"64479.8\",\"465.41\",\"0\",\"28\"],[\"64478\",\"0.81\",\"0\",\"2\"],[\"64477.9\",\"0.01\",\"0\",\"1\"],[\"64477.5\",\"0\",\"0\",\"0\"],[\"64475.6\",\"56.42\",\"0\",\"1\"],[\"64475.5\",\"0\",\"0\",\"0\"],[\"64475\",\"0.01\",\"0\",\"1\"],[\"64474.8\",\"0.01\",\"0\",\"1\"],[\"64474.1\",\"0.02\",\"0\",\"2\"],[\"64474\",\"14.73\",\"0\",\"4\"],[\"64473.6\",\"1.56\",\"0\",\"1\"],[\"64472.8\",\"0\",\"0\",\"0\"],[\"64472.1\",\"88.9\",\"0\",\"4\"],[\"64471.7\",\"32.18\",\"0\",\"2\"],[\"64471.2\",\"1.56\",\"0\",\"1\"],[\"64470.7\",\"1.58\",\"0\",\"3\"],[\"64470.1\",\"0\",\"0\",\"0\"],[\"64469.9\",\"32.59\",\"0\",\"3\"],[\"64461.7\",\"0.01\",\"0\",\"1\"],[\"64461.3\",\"496.57\",\"0\",\"2\"],[\"64461\",\"33.82\",\"0\",\"1\"],[\"64460.2\",\"20.08\",\"0\",\"1\"],[\"64459.5\",\"101.83\",\"0\",\"2\"],[\"64459.2\",\"0.01\",\"0\",\"1\"],[\"64459\",\"0\",\"0\",\"0\"],[\"64458.9\",\"0.01\",\"0\",\"1\"],[\"64458.8\",\"85.42\",\"0\",\"2\"],[\"64458.1\",\"31.05\",\"0\",\"1\"],[\"64457.5\",\"232.94\",\"0\",\"2\"],[\"64455.7\",\"0.3\",\"0\",\"2\"],[\"64454.5\",\"58.23\",\"0\",\"1\"],[\"64439.5\",\"0.01\",\"0\",\"1\"],[\"64439.3\",\"0.02\",\"0\",\"1\"],[\"64422.2\",\"11.42\",\"0\",\"3\"]],\"ts\":\"1782016019505\",\"checksum\":1038652851,\"seqId\":325070061000,\"prevSeqId\":325070060752}]}"}
{"action": "update", "capture_sequence": 14, "channel": "books", "connection_sequence": 1, "event": null, "instId": "BTC-USDT-SWAP", "local_receive_ts": "2026-06-21T04:26:59Z", "monotonic_ns": 1643575513547869, "raw": "{\"arg\":{\"channel\":\"books\",\"instId\":\"BTC-USDT-SWAP\"},\"action\":\"update\",\"data\":[{\"asks\":[[\"64480.8\",\"0\",\"0\",\"0\"],[\"64480.9\",\"0.02\",\"0\",\"2\"],[\"64481.7\",\"0\",\"0\",\"0\"],[\"64481.8\",\"0.04\",\"0\",\"3\"],[\"64482.1\",\"0.01\",\"0\",\"1\"],[\"64482.2\",\"0.02\",\"0\",\"2\"],[\"64482.8\",\"0.02\",\"0\",\"2\"],[\"64487.8\",\"0.11\",\"0\",\"5\"],[\"64488.1\",\"0.66\",\"0\",\"1\"],[\"64493.8\",\"0.03\",\"0\",\"2\"],[\"64494.5\",\"15.52\",\"0\",\"1\"],[\"64496.2\",\"0.31\",\"0\",\"1\"],[\"64496.5\",\"31.05\",\"0\",\"3\"],[\"64497.2\",\"233.63\",\"0\",\"4\"],[\"64498.4\",\"0.01\",\"0\",\"1\"],[\"64498.8\",\"6.24\",\"0\",\"3\"],[\"64498.9\",\"49.96\",\"0\",\"3\"],[\"64499.5\",\"1.55\",\"0\",\"1\"],[\"64501.9\",\"0.85\",\"0\",\"2\"],[\"64502.4\",\"0.19\",\"0\",\"6\"],[\"64502.7\",\"0.03\",\"0\",\"3\"],[\"64503.4\",\"58.19\",\"0\",\"1\"],[\"64504.3\",\"0.04\",\"0\",\"2\"],[\"64505.1\",\"85.36\",\"0\",\"3\"],[\"64509.3\",\"0.28\",\"0\",\"5\"],[\"64511.6\",\"86.12\",\"0\",\"2\"],[\"64524.5\",\"0\",\"0\",\"0\"],[\"64524.6\",\"0\",\"0\",\"0\"],[\"64524.7\",\"0\",\"0\",\"0\"],[\"64524.8\",\"0\",\"0\",\"0\"]],\"bids\":[[\"64474.5\",\"0.31\",\"0\",\"1\"],[\"64474\",\"14.42\",\"0\",\"3\"],[\"64472.4\",\"77.55\",\"0\",\"1\"],[\"64472.1\",\"11.35\",\"0\",\"3\"],[\"64472\",\"70.32\",\"0\",\"4\"],[\"64469.4\",\"46.56\",\"0\",\"2\"],[\"64465\",\"0\",\"0\",\"0\"],[\"64463.9\",\"0\",\"0\",\"0\"],[\"64463.7\",\"0.31\",\"0\",\"1\"],[\"64463.4\",\"0\",\"0\",\"0\"],[\"64463.2\",\"0.04\",\"0\",\"2\"],[\"64463.1\",\"38\",\"0\",\"2\"],[\"64461.6\",\"0\",\"0\",\"0\"],[\"64461.2\",\"0.04\",\"0\",\"2\"],[\"64460.9\",\"181.68\",\"0\",\"3\"],[\"64460.8\",\"352.79\",\"0\",\"7\"],[\"64460.7\",\"44.95\",\"0\",\"2\"],[\"64459.5\",\"15.65\",\"0\",\"1\"],[\"64459.2\",\"85.41\",\"0\",\"2\"],[\"64458.8\",\"0\",\"0\",\"0\"],[\"64458.6\",\"0.18\",\"0\",\"3\"],[\"64458.2\",\"232.93\",\"0\",\"1\"],[\"64457.5\",\"0.01\",\"0\",\"1\"],[\"64457\",\"743.17\",\"0\",\"6\"],[\"64455.4\",\"58.23\",\"0\",\"1\"],[\"64454.5\",\"0\",\"0\",\"0\"],[\"64454.3\",\"10\",\"0\",\"1\"],[\"64452.5\",\"31.34\",\"0\",\"5\"],[\"64439.3\",\"0\",\"0\",\"0\"],[\"64437.7\",\"0.02\",\"0\",\"1\"]],\"ts\":\"1782016019605\",\"checksum\":460374410,\"seqId\":325070061111,\"prevSeqId\":325070061000}]}"}
{"action": "update", "capture_sequence": 15, "channel": "books", "connection_sequence": 1, "event": null, "instId": "BTC-USDT-SWAP", "local_receive_ts": "2026-06-21T04:26:59Z", "monotonic_ns": 1643575608438002, "raw": "{\"arg\":{\"channel\":\"books\",\"instId\":\"BTC-USDT-SWAP\"},\"action\":\"update\",\"data\":[{\"asks\":[[\"64479.9\",\"683.85\",\"0\",\"42\"],[\"64480\",\"50.1\",\"0\",\"8\"],[\"64496.5\",\"0.02\",\"0\",\"2\"],[\"64497.1\",\"31.04\",\"0\",\"2\"],[\"64497.2\",\"0.84\",\"0\",\"3\"],[\"64498.1\",\"232.82\",\"0\",\"4\"],[\"64510.8\",\"0.02\",\"0\",\"1\"],[\"64511.3\",\"21\",\"0\",\"8\"],[\"64520\",\"78.61\",\"0\",\"62\"]],\"bids\":[[\"64461.6\",\"1\",\"0\",\"1\"],[\"64460.9\",\"201.76\",\"0\",\"4\"],[\"64460.2\",\"0\",\"0\",\"0\"],[\"64458.8\",\"31.05\",\"0\",\"1\"],[\"64458.5\",\"232.93\",\"0\",\"1\"],[\"64458.2\",\"0\",\"0\",\"0\"],[\"64458.1\",\"0\",\"0\",\"0\"]],\"ts\":\"1782016019705\",\"checksum\":1264440012,\"seqId\":325070061131,\"prevSeqId\":325070061111}]}"}
{"action": "update", "capture_sequence": 16, "channel": "books", "connection_sequence": 1, "event": null, "instId": "BTC-USDT-SWAP", "local_receive_ts": "2026-06-21T04:26:59Z", "monotonic_ns": 1643575708284966, "raw": "{\"arg\":{\"channel\":\"books\",\"instId\":\"BTC-USDT-SWAP\"},\"action\":\"update\",\"data\":[{\"asks\":[[\"64482.3\",\"136.13\",\"0\",\"1\"]],\"bids\":[],\"ts\":\"1782016019805\",\"checksum\":-1139734145,\"seqId\":325070061136,\"prevSeqId\":325070061131}]}"}
{"action": "update", "capture_sequence": 17, "channel": "books", "connection_sequence": 1, "event": null, "instId": "BTC-USDT-SWAP", "local_receive_ts": "2026-06-21T04:27:00Z", "monotonic_ns": 1643575808447380, "raw": "{\"arg\":{\"channel\":\"books\",\"instId\":\"BTC-USDT-SWAP\"},\"action\":\"update\",\"data\":[{\"asks\":[[\"64479.9\",\"683.95\",\"0\",\"43\"],[\"64493.9\",\"15.52\",\"0\",\"1\"],[\"64494.5\",\"0\",\"0\",\"0\"]],\"bids\":[],\"ts\":\"1782016019905\",\"checksum\":2047642184,\"seqId\":325070061142,\"prevSeqId\":325070061136}]}"}
{"action": null, "capture_sequence": 18, "channel": "trades", "connection_sequence": 1, "event": null, "instId": "BTC-USDT-SWAP", "local_receive_ts": "2026-06-21T04:27:00Z", "monotonic_ns": 1643575809476476, "raw": "{\"arg\":{\"channel\":\"trades\",\"instId\":\"BTC-USDT-SWAP\"},\"data\":[{\"instId\":\"BTC-USDT-SWAP\",\"tradeId\":\"2718750120\",\"px\":\"64479.8\",\"sz\":\"0.06\",\"side\":\"sell\",\"ts\":\"1782016019906\",\"count\":\"1\",\"source\":\"0\",\"seqId\":325070061145}]}"}
{"action": null, "capture_sequence": 19, "channel": "trades", "connection_sequence": 1, "event": null, "instId": "BTC-USDT-SWAP", "local_receive_ts": "2026-06-21T04:27:00Z", "monotonic_ns": 1643575884607056, "raw": "{\"arg\":{\"channel\":\"trades\",\"instId\":\"BTC-USDT-SWAP\"},\"data\":[{\"instId\":\"BTC-USDT-SWAP\",\"tradeId\":\"2718750121\",\"px\":\"64479.9\",\"sz\":\"0.87\",\"side\":\"buy\",\"ts\":\"1782016019981\",\"count\":\"1\",\"source\":\"0\",\"seqId\":325070061256}]}"}
{"action": "update", "capture_sequence": 20, "channel": "books", "connection_sequence": 1, "event": null, "instId": "BTC-USDT-SWAP", "local_receive_ts": "2026-06-21T04:27:00Z", "monotonic_ns": 1643575913687693, "raw": "{\"arg\":{\"channel\":\"books\",\"instId\":\"BTC-USDT-SWAP\"},\"action\":\"update\",\"data\":[{\"asks\":[[\"64479.9\",\"481.22\",\"0\",\"39\"],[\"64481.4\",\"0.01\",\"0\",\"1\"],[\"64481.5\",\"15.54\",\"0\",\"2\"],[\"64482.9\",\"0\",\"0\",\"0\"],[\"64483.2\",\"0.01\",\"0\",\"1\"],[\"64483.6\",\"0\",\"0\",\"0\"],[\"64483.8\",\"1.56\",\"0\",\"1\"],[\"64484.2\",\"0\",\"0\",\"0\"],[\"64486.1\",\"250.42\",\"0\",\"4\"],[\"64486.6\",\"82.88\",\"0\",\"3\"],[\"64487.1\",\"2.09\",\"0\",\"5\"],[\"64487.5\",\"1.6\",\"0\",\"4\"],[\"64487.8\",\"0.1\",\"0\",\"4\"],[\"64488\",\"57.87\",\"0\",\"27\"],[\"64489.1\",\"19.1\",\"0\",\"5\"],[\"64489.4\",\"2.94\",\"0\",\"6\"],[\"64491.8\",\"0.05\",\"0\",\"1\"],[\"64491.9\",\"0.3\",\"0\",\"4\"],[\"64493.9\",\"0\",\"0\",\"0\"],[\"64494.7\",\"32.05\",\"0\",\"6\"],[\"64495.6\",\"15.53\",\"0\",\"2\"],[\"64496.2\",\"0\",\"0\",\"0\"],[\"64497.1\",\"0.32\",\"0\",\"2\"],[\"64498.1\",\"31.06\",\"0\",\"4\"],[\"64498.4\",\"0\",\"0\",\"0\"],[\"64498.6\",\"234.17\",\"0\",\"8\"],[\"64499.1\",\"0.17\",\"0\",\"5\"],[\"64499.5\",\"0\",\"0\",\"0\"],[\"64499.8\",\"1.08\",\"0\",\"2\"],[\"64500.5\",\"4.04\",\"0\",\"3\"],[\"64501.9\",\"0.08\",\"0\",\"1\"],[\"64502.1\",\"33.8\",\"0\",\"2\"],[\"64502.8\",\"57.84\",\"0\",\"4\"],[\"64503.4\",\"0\",\"0\",\"0\"],[\"64504.9\",\"58.29\",\"0\",\"4\"],[\"64505.1\",\"0.02\",\"0\",\"2\"],[\"64505.9\",\"86.35\",\"0\",\"3\"],[\"64511.3\",\"0.93\",\"0\",\"7\"],[\"64512.8\",\"20.07\",\"0\",\"1\"],[\"64524.5\",\"0.17\",\"0\",\"3\"],[\"64524.6\",\"0.01\",\"0\",\"1\"],[\"64524.7\",\"0.02\",\"0\",\"1\"],[\"64524.8\",\"3.05\",\"0\",\"5\"],[\"64524.9\",\"2.19\",\"0\",\"7\"]],\"bids\":[[\"64479.8\",\"444.19\",\"0\",\"28\"],[\"64478.7\",\"1.56\",\"0\",\"1\"],[\"64476.5\",\"11.4\",\"0\",\"1\"],[\"64476\",\"194.45\",\"0\",\"5\"],[\"64475.9\",\"166.77\",\"0\",\"3\"],[\"64475.8\",\"37.25\",\"0\",\"3\"],[\"64475.6\",\"0\",\"0\",\"0\"],[\"64475.5\",\"0.31\",\"0\",\"1\"],[\"64474.5\",\"0\",\"0\",\"0\"],[\"64473.7\",\"77.55\",\"0\",\"1\"],[\"64473.6\",\"94.38\",\"0\",\"2\"],[\"64472.4\",\"0\",\"0\",\"0\"],[\"64472.1\",\"17.57\",\"0\",\"4\"],[\"64471.3\",\"5.05\",\"0\",\"2\"],[\"64469.9\",\"0.77\",\"0\",\"1\"],[\"64464.5\",\"0.33\",\"0\",\"3\"],[\"64463.9\",\"0.77\",\"0\",\"1\"],[\"64463.7\",\"0.02\",\"0\",\"1\"],[\"64463.2\",\"33.83\",\"0\",\"2\"],[\"64463.1\",\"37.23\",\"0\",\"1\"],[\"64462.2\",\"20.08\",\"0\",\"1\"],[\"64461.4\",\"86.21\",\"0\",\"4\"],[\"64461\",\"0\",\"0\",\"0\"],[\"64460.9\",\"95.5\",\"0\",\"2\"],[\"64460.6\",\"85.56\",\"0\",\"3\"],[\"64460.1\",\"34.96\",\"0\",\"3\"],[\"64459.7\",\"232.93\",\"0\",\"2\"],[\"64459.2\",\"0.01\",\"0\",\"1\"],[\"64458.8\",\"0\",\"0\",\"0\"],[\"64458.7\",\"18.15\",\"0\",\"3\"],[\"64458.6\",\"0.16\",\"0\",\"2\"],[\"64458.5\",\"0\",\"0\",\"0\"],[\"64456.6\",\"58.31\",\"0\",\"3\"],[\"64455.4\",\"0\",\"0\",\"0\"],[\"64452.6\",\"512.2\",\"0\",\"3\"],[\"64452.5\",\"31.32\",\"0\",\"4\"],[\"64452.4\",\"0\",\"0\",\"0\"],[\"64438.1\",\"23.71\",\"0\",\"4\"],[\"64437.7\",\"0\",\"0\",\"0\"],[\"64423.5\",\"35.08\",\"0\",\"2\"],[\"64422.7\",\"19.04\",\"0\",\"2\"],[\"64422.6\",\"18.89\",\"0\",\"3\"],[\"64422.3\",\"0.02\",\"0\",\"2\"],[\"64422.2\",\"0.02\",\"0\",\"2\"],[\"64422\",\"0.01\",\"0\",\"1\"],[\"64421.9\",\"0.01\",\"0\",\"1\"],[\"64421.8\",\"0.03\",\"0\",\"2\"]],\"ts\":\"1782016020005\",\"checksum\":931884924,\"seqId\":325070061356,\"prevSeqId\":325070061142}]}"}
{"action": "update", "capture_sequence": 21, "channel": "books", "connection_sequence": 1, "event": null, "instId": "BTC-USDT-SWAP", "local_receive_ts": "2026-06-21T04:27:00Z", "monotonic_ns": 1643576018607254, "raw": "{\"arg\":{\"channel\":\"books\",\"instId\":\"BTC-USDT-SWAP\"},\"action\":\"update\",\"data\":[{\"asks\":[[\"64479.9\",\"189.63\",\"0\",\"33\"],[\"64480.3\",\"0\",\"0\",\"0\"],[\"64481\",\"5.59\",\"0\",\"2\"],[\"64481.4\",\"0\",\"0\",\"0\"],[\"64481.5\",\"0.02\",\"0\",\"1\"],[\"64482.1\",\"0.52\",\"0\",\"3\"],[\"64482.2\",\"15.52\",\"0\",\"1\"],[\"64482.3\",\"0\",\"0\",\"0\"],[\"64483.1\",\"0.62\",\"0\",\"3\"],[\"64483.2\",\"0.02\",\"0\",\"2\"],[\"64483.6\",\"0.01\",\"0\",\"1\"],[\"64483.8\",\"0\",\"0\",\"0\"],[\"64484.2\",\"136.13\",\"0\",\"1\"],[\"64484.7\",\"1.2\",\"0\",\"1\"],[\"64485.2\",\"0.02\",\"0\",\"2\"],[\"64485.3\",\"0.5\",\"0\",\"1\"],[\"64485.6\",\"0\",\"0\",\"0\"],[\"64486.1\",\"0\",\"0\",\"0\"],[\"64486.4\",\"1.28\",\"0\",\"3\"],[\"64486.6\",\"81.32\",\"0\",\"2\"],[\"64487.1\",\"0.53\",\"0\",\"4\"],[\"64488\",\"59.43\",\"0\",\"28\"],[\"64488.5\",\"1.56\",\"0\",\"1\"],[\"64489\",\"24.66\",\"0\",\"10\"],[\"64489.5\",\"5.51\",\"0\",\"4\"],[\"64489.6\",\"22.21\",\"0\",\"4\"],[\"64489.9\",\"1.56\",\"0\",\"1\"],[\"64490.4\",\"1.59\",\"0\",\"4\"],[\"64490.5\",\"17.51\",\"0\",\"3\"],[\"64490.9\",\"2.01\",\"0\",\"4\"],[\"64491.9\",\"0.45\",\"0\",\"5\"],[\"64492.4\",\"29.97\",\"0\",\"10\"],[\"64495.6\",\"0.01\",\"0\",\"1\"],[\"64496.3\",\"413.2\",\"0\",\"6\"],[\"64497.1\",\"0.01\",\"0\",\"1\"],[\"64498.1\",\"0.03\",\"0\",\"3\"],[\"64498.2\",\"0.04\",\"0\",\"3\"],[\"64498.4\",\"0.31\",\"0\",\"1\"],[\"64498.6\",\"1.39\",\"0\",\"7\"],[\"64499.3\",\"31.03\",\"0\",\"1\"],[\"64499.5\",\"232.78\",\"0\",\"1\"],[\"64500\",\"3484.17\",\"0\",\"1034\"],[\"64500.5\",\"2.49\",\"0\",\"2\"],[\"64501.8\",\"61.56\",\"0\",\"8\"],[\"64502.1\",\"0.01\",\"0\",\"1\"],[\"64502.8\",\"57.07\",\"0\",\"3\"],[\"64503.4\",\"33.79\",\"0\",\"1\"],[\"64503.8\",\"0.77\",\"0\",\"1\"],[\"64504\",\"54.55\",\"0\",\"8\"],[\"64504.9\",\"0.1\",\"0\",\"3\"],[\"64505.9\",\"1.01\",\"0\",\"2\"],[\"64506.7\",\"58.38\",\"0\",\"16\"],[\"64507.3\",\"274.69\",\"0\",\"4\"],[\"64511.6\",\"0.01\",\"0\",\"1\"],[\"64512.8\",\"0\",\"0\",\"0\"],[\"64514.8\",\"146.9\",\"0\",\"7\"],[\"64515\",\"20.11\",\"0\",\"3\"],[\"64516.1\",\"0.04\",\"0\",\"4\"],[\"64516.8\",\"6.27\",\"0\",\"4\"],[\"64521.3\",\"0.01\",\"0\",\"1\"],[\"64521.6\",\"1.7\",\"0\",\"3\"],[\"64524.7\",\"0\",\"0\",\"0\"],[\"64524.8\",\"0\",\"0\",\"0\"],[\"64524.9\",\"0\",\"0\",\"0\"]],\"bids\":[[\"64479.8\",\"638.06\",\"0\",\"36\"],[\"64479.7\",\"2.18\",\"0\",\"5\"],[\"64479.6\",\"39.97\",\"0\",\"3\"],[\"64479.3\",\"0.02\",\"0\",\"1\"],[\"64479.2\",\"1.56\",\"0\",\"1\"],[\"64479.1\",\"0.01\",\"0\",\"1\"],[\"64478.8\",\"0.01\",\"0\",\"1\"],[\"64478\",\"0.01\",\"0\",\"1\"],[\"64477.6\",\"120.23\",\"0\",\"2\"],[\"64477\",\"0.31\",\"0\",\"1\"],[\"64476\",\"162.64\",\"0\",\"3\"],[\"64475.9\",\"46.55\",\"0\",\"2\"],[\"64475.7\",\"2\",\"0\",\"1\"],[\"64475.5\",\"0\",\"0\",\"0\"],[\"64475\",\"77.55\",\"0\",\"2\"],[\"64474\",\"2.01\",\"0\",\"2\"],[\"64473.7\",\"0\",\"0\",\"0\"],[\"64473.6\",\"155.13\",\"0\",\"3\"],[\"64471.9\",\"0.02\",\"0\",\"1\"],[\"64471.3\",\"1.15\",\"0\",\"1\"],[\"64470.3\",\"12.42\",\"0\",\"2\"],[\"64470.1\",\"0.77\",\"0\",\"1\"],[\"64469.9\",\"31.82\",\"0\",\"2\"],[\"64469.4\",\"46.54\",\"0\",\"1\"],[\"64465.8\",\"0.31\",\"0\",\"1\"],[\"64465\",\"0.77\",\"0\",\"1\"],[\"64464.6\",\"20.08\",\"0\",\"1\"],[\"64464.5\",\"33.83\",\"0\",\"3\"],[\"64464.3\",\"86.17\",\"0\",\"1\"],[\"64464.1\",\"1.96\",\"0\",\"3\"],[\"64463.9\",\"0\",\"0\",\"0\"],[\"64463.7\",\"0\",\"0\",\"0\"],[\"64463.2\",\"0\",\"0\",\"0\"],[\"64462.2\",\"0\",\"0\",\"0\"],[\"64461.7\",\"85.41\",\"0\",\"2\"],[\"64461.4\",\"0.03\",\"0\",\"3\"],[\"64461.2\",\"0.06\",\"0\",\"3\"],[\"64461\",\"31.05\",\"0\",\"1\"],[\"64460.8\",\"352.77\",\"0\",\"6\"],[\"64460.7\",\"44.97\",\"0\",\"3\"],[\"64460.6\",\"0.16\",\"0\",\"2\"],[\"64460.3\",\"37.78\",\"0\",\"4\"],[\"64460.2\",\"232.92\",\"0\",\"1\"],[\"64460.1\",\"3.91\",\"0\",\"2\"],[\"64459.7\",\"0.01\",\"0\",\"1\"],[\"64459.4\",\"38.83\",\"0\",\"1\"],[\"64458.8\",\"58.23\",\"0\",\"1\"],[\"64458.7\",\"21.35\",\"0\",\"3\"],[\"64458.3\",\"0.05\",\"0\",\"4\"],[\"64457\",\"743.15\",\"0\",\"5\"],[\"64456.6\",\"0.08\",\"0\",\"2\"],[\"64454.1\",\"0.02\",\"0\",\"1\"],[\"64452.6\",\"512.18\",\"0\",\"2\"],[\"64452.4\",\"0.19\",\"0\",\"1\"],[\"64445.9\",\"0\",\"0\",\"0\"],[\"64439.3\",\"0.02\",\"0\",\"1\"],[\"64438.1\",\"23.69\",\"0\",\"3\"],[\"64428.9\",\"0.03\",\"0\",\"2\"],[\"64426.1\",\"19.87\",\"0\",\"2\"],[\"64423.5\",\"15.48\",\"0\",\"1\"],[\"64422.8\",\"0\",\"0\",\"0\"],[\"64422.7\",\"0\",\"0\",\"0\"],[\"64422.6\",\"0\",\"0\",\"0\"],[\"64422.5\",\"0\",\"0\",\"0\"],[\"64422.4\",\"0\",\"0\",\"0\"],[\"64422.3\",\"0\",\"0\",\"0\"],[\"64422.2\",\"0\",\"0\",\"0\"],[\"64422\",\"0\",\"0\",\"0\"],[\"64421.9\",\"0\",\"0\",\"0\"],[\"64421.8\",\"0\",\"0\",\"0\"]],\"ts\":\"1782016020105\",\"checksum\":-1952915445,\"seqId\":325070062293,\"prevSeqId\":325070061356}]}"}
{"action": "update", "capture_sequence": 22, "channel": "books", "connection_sequence": 1, "event": null, "instId": "BTC-USDT-SWAP", "local_receive_ts": "2026-06-21T04:27:00Z", "monotonic_ns": 1643576113470533, "raw": "{\"arg\":{\"channel\":\"books\",\"instId\":\"BTC-USDT-SWAP\"},\"action\":\"update\",\"data\":[{\"asks\":[[\"64479.9\",\"179.66\",\"0\",\"31\"],[\"64480\",\"50.09\",\"0\",\"7\"],[\"64482.2\",\"7.75\",\"0\",\"1\"],[\"64482.9\",\"0.01\",\"0\",\"1\"],[\"64483\",\"15.55\",\"0\",\"3\"],[\"64483.2\",\"0.01\",\"0\",\"1\"],[\"64483.3\",\"76.54\",\"0\",\"4\"],[\"64485.5\",\"2.77\",\"0\",\"3\"],[\"64486.7\",\"0\",\"0\",\"0\"],[\"64486.9\",\"1.67\",\"0\",\"2\"],[\"64488.7\",\"0.81\",\"0\",\"2\"],[\"64489.1\",\"33.04\",\"0\",\"6\"],[\"64489.4\",\"2.93\",\"0\",\"5\"],[\"64489.6\",\"21.44\",\"0\",\"3\"],[\"64490.3\",\"1.12\",\"0\",\"2\"],[\"64490.9\",\"0.45\",\"0\",\"3\"],[\"64491.8\",\"0.06\",\"0\",\"2\"],[\"64492.8\",\"167.42\",\"0\",\"12\"],[\"64494.3\",\"0.25\",\"0\",\"5\"],[\"64495.9\",\"16.35\",\"0\",\"4\"],[\"64496.3\",\"397.69\",\"0\",\"5\"],[\"64496.5\",\"0\",\"0\",\"0\"],[\"64498.4\",\"0\",\"0\",\"0\"],[\"64498.8\",\"37.27\",\"0\",\"4\"],[\"64499.1\",\"0.18\",\"0\",\"6\"],[\"64499.3\",\"0.31\",\"0\",\"1\"],[\"64500.2\",\"0.02\",\"0\",\"2\"],[\"64501.4\",\"17.09\",\"0\",\"3\"],[\"64501.8\",\"60.01\",\"0\",\"7\"],[\"64502.7\",\"33.82\",\"0\",\"4\"],[\"64503.4\",\"0\",\"0\",\"0\"],[\"64503.8\",\"0\",\"0\",\"0\"],[\"64504.9\",\"0.87\",\"0\",\"4\"],[\"64506.2\",\"58.22\",\"0\",\"3\"],[\"64506.7\",\"0.19\",\"0\",\"15\"],[\"64512.6\",\"144.35\",\"0\",\"7\"],[\"64514.1\",\"0.01\",\"0\",\"1\"],[\"64514.2\",\"21.14\",\"0\",\"5\"],[\"64514.8\",\"60.79\",\"0\",\"6\"],[\"64515\",\"0.04\",\"0\",\"2\"],[\"64516.8\",\"6.26\",\"0\",\"3\"],[\"64519.9\",\"496.57\",\"0\",\"3\"],[\"64520\",\"78.62\",\"0\",\"63\"],[\"64524.7\",\"0.02\",\"0\",\"1\"],[\"64524.8\",\"3.05\",\"0\",\"5\"],[\"64524.9\",\"2.19\",\"0\",\"7\"],[\"64525\",\"2.51\",\"0\",\"18\"]],\"bids\":[[\"64479.8\",\"657.61\",\"0\",\"38\"],[\"64477\",\"0\",\"0\",\"0\"],[\"64476.4\",\"0.31\",\"0\",\"1\"],[\"64475\",\"0.01\",\"0\",\"1\"],[\"64474.9\",\"0.77\",\"0\",\"1\"],[\"64474.1\",\"77.56\",\"0\",\"3\"],[\"64472.8\",\"0.02\",\"0\",\"1\"],[\"64471.9\",\"0\",\"0\",\"0\"],[\"64471.3\",\"1.39\",\"0\",\"3\"],[\"64468\",\"0.02\",\"0\",\"2\"],[\"64466.6\",\"0.32\",\"0\",\"2\"],[\"64466\",\"0.79\",\"0\",\"3\"],[\"64465.8\",\"0\",\"0\",\"0\"],[\"64465.3\",\"46.6\",\"0\",\"5\"],[\"64465\",\"0\",\"0\",\"0\"],[\"64464.6\",\"0\",\"0\",\"0\"],[\"64464.5\",\"0.02\",\"0\",\"2\"],[\"64464.3\",\"0\",\"0\",\"0\"],[\"64464.1\",\"1.92\",\"0\",\"1\"],[\"64463.9\",\"33.81\",\"0\",\"1\"],[\"64463.7\",\"20.1\",\"0\",\"2\"],[\"64461.8\",\"86.17\",\"0\",\"1\"],[\"64461.2\",\"0.04\",\"0\",\"2\"],[\"64461\",\"0.02\",\"0\",\"1\"],[\"64460.8\",\"390\",\"0\",\"9\"],[\"64460.7\",\"76\",\"0\",\"3\"],[\"64460.3\",\"0.55\",\"0\",\"1\"],[\"64460.1\",\"3.93\",\"0\",\"3\"],[\"64458.8\",\"0\",\"0\",\"0\"],[\"64458.3\",\"0.03\",\"0\",\"3\"],[\"64458.1\",\"58.23\",\"0\",\"1\"],[\"64454.9\",\"0.02\",\"0\",\"1\"],[\"64454.1\",\"0\",\"0\",\"0\"],[\"64439.7\",\"15.67\",\"0\",\"2\"],[\"64439.3\",\"0\",\"0\",\"0\"],[\"64422.8\",\"2.29\",\"0\",\"2\"],[\"64422.7\",\"3.4\",\"0\",\"3\"]],\"ts\":\"1782016020205\",\"checksum\":1910866603,\"seqId\":325070062581,\"prevSeqId\":325070062293}]}"}
{"action": null, "capture_sequence": 23, "channel": "trades", "connection_sequence": 1, "event": null, "instId": "BTC-USDT-SWAP", "local_receive_ts": "2026-06-21T04:27:00Z", "monotonic_ns": 1643576138513840, "raw": "{\"arg\":{\"channel\":\"trades\",\"instId\":\"BTC-USDT-SWAP\"},\"data\":[{\"instId\":\"BTC-USDT-SWAP\",\"tradeId\":\"2718750125\",\"px\":\"64479.9\",\"sz\":\"5\",\"side\":\"buy\",\"ts\":\"1782016020235\",\"count\":\"4\",\"source\":\"0\",\"seqId\":325070062663}]}"}
{"action": "update", "capture_sequence": 24, "channel": "books", "connection_sequence": 1, "event": null, "instId": "BTC-USDT-SWAP", "local_receive_ts": "2026-06-21T04:27:00Z", "monotonic_ns": 1643576214653497, "raw": "{\"arg\":{\"channel\":\"books\",\"instId\":\"BTC-USDT-SWAP\"},\"action\":\"update\",\"data\":[{\"asks\":[[\"64479.9\",\"184.41\",\"0\",\"29\"],[\"64481\",\"3.27\",\"0\",\"2\"],[\"64482\",\"0.05\",\"0\",\"3\"],[\"64482.8\",\"0.01\",\"0\",\"1\"],[\"64482.9\",\"0\",\"0\",\"0\"],[\"64483\",\"0.03\",\"0\",\"2\"],[\"64483.2\",\"114.74\",\"0\",\"3\"],[\"64483.4\",\"16.52\",\"0\",\"2\"],[\"64485.5\",\"1.21\",\"0\",\"2\"],[\"64487.4\",\"7.13\",\"0\",\"9\"],[\"64487.5\",\"0.04\",\"0\",\"3\"],[\"64487.9\",\"2.07\",\"0\",\"3\"],[\"64488\",\"57.87\",\"0\",\"27\"],[\"64488.4\",\"7.23\",\"0\",\"7\"],[\"64488.5\",\"0\",\"0\",\"0\"],[\"64488.7\",\"0.04\",\"0\",\"1\"],[\"64489.1\",\"25.04\",\"0\",\"5\"],[\"64489.5\",\"6.28\",\"0\",\"5\"],[\"64490.5\",\"25.51\",\"0\",\"4\"],[\"64490.9\",\"2.01\",\"0\",\"4\"],[\"64491.4\",\"1.58\",\"0\",\"3\"],[\"64495.6\",\"15.53\",\"0\",\"2\"],[\"64495.9\",\"0.84\",\"0\",\"3\"],[\"64498.4\",\"31.03\",\"0\",\"1\"],[\"64498.7\",\"235.64\",\"0\",\"5\"],[\"64498.8\",\"6.24\",\"0\",\"3\"],[\"64499.5\",\"0\",\"0\",\"0\"],[\"64501.5\",\"35.36\",\"0\",\"5\"],[\"64502.7\",\"0.03\",\"0\",\"3\"],[\"64504.9\",\"0.1\",\"0\",\"3\"],[\"64505.1\",\"0.79\",\"0\",\"3\"],[\"64505.9\",\"325.16\",\"0\",\"3\"],[\"64506\",\"210.07\",\"0\",\"6\"],[\"64506.2\",\"0.03\",\"0\",\"2\"],[\"64506.8\",\"87.89\",\"0\",\"7\"],[\"64507.1\",\"58.24\",\"0\",\"5\"],[\"64507.3\",\"0.03\",\"0\",\"2\"],[\"64513.8\",\"20.08\",\"0\",\"2\"],[\"64514.2\",\"1.07\",\"0\",\"4\"],[\"64525.1\",\"0.46\",\"0\",\"1\"],[\"64525.2\",\"55.22\",\"0\",\"2\"]],\"bids\":[[\"64479.8\",\"655.61\",\"0\",\"36\"],[\"64476.7\",\"0.01\",\"0\",\"1\"],[\"64476.6\",\"0\",\"0\",\"0\"],[\"64476.4\",\"0\",\"0\",\"0\"],[\"64476.1\",\"0.31\",\"0\",\"1\"],[\"64476\",\"120.81\",\"0\",\"3\"],[\"64469.9\",\"33.31\",\"0\",\"3\"],[\"64467.6\",\"0.02\",\"0\",\"2\"],[\"64463.9\",\"0\",\"0\",\"0\"],[\"64463.7\",\"0.02\",\"0\",\"1\"],[\"64463.2\",\"20.08\",\"0\",\"1\"],[\"64462.7\",\"56.76\",\"0\",\"3\"],[\"64461.7\",\"0.01\",\"0\",\"1\"],[\"64461.4\",\"85.43\",\"0\",\"4\"],[\"64460.7\",\"44.95\",\"0\",\"2\"],[\"64460.3\",\"31.6\",\"0\",\"2\"],[\"64460.2\",\"0\",\"0\",\"0\"],[\"64459.6\",\"232.92\",\"0\",\"1\"],[\"64458.8\",\"58.23\",\"0\",\"1\"],[\"64458.1\",\"0\",\"0\",\"0\"],[\"64422.6\",\"0.02\",\"0\",\"2\"]],\"ts\":\"1782016020305\",\"checksum\":-1965448741,\"seqId\":325070062813,\"prevSeqId\":325070062581}]}"}
{"action": "update", "capture_sequence": 25, "channel": "books", "connection_sequence": 1, "event": null, "instId": "BTC-USDT-SWAP", "local_receive_ts": "2026-06-21T04:27:00Z", "monotonic_ns": 1643576316739736, "raw": "{\"arg\":{\"channel\":\"books\",\"instId\":\"BTC-USDT-SWAP\"},\"action\":\"update\",\"data\":[{\"asks\":[[\"64479.9\",\"252.46\",\"0\",\"31\"],[\"64481\",\"37.09\",\"0\",\"3\"],[\"64482.1\",\"0.53\",\"0\",\"4\"],[\"64483.1\",\"0.63\",\"0\",\"4\"],[\"64483.2\",\"114.73\",\"0\",\"2\"],[\"64483.7\",\"2.57\",\"0\",\"3\"],[\"64484.8\",\"1.57\",\"0\",\"2\"],[\"64484.9\",\"0.31\",\"0\",\"2\"],[\"64485.6\",\"1.56\",\"0\",\"1\"],[\"64486.1\",\"1.56\",\"0\",\"1\"],[\"64489.9\",\"0\",\"0\",\"0\"],[\"64490.4\",\"0.03\",\"0\",\"3\"],[\"64490.7\",\"0.07\",\"0\",\"3\"],[\"64490.9\",\"0.45\",\"0\",\"3\"],[\"64491.4\",\"0.02\",\"0\",\"2\"],[\"64491.8\",\"0.05\",\"0\",\"1\"],[\"64494.3\",\"0.08\",\"0\",\"4\"],[\"64495.7\",\"11.52\",\"0\",\"4\"],[\"64497.9\",\"31.24\",\"0\",\"3\"],[\"64498.4\",\"0\",\"0\",\"0\"],[\"64498.7\",\"235.95\",\"0\",\"6\"],[\"64498.8\",\"6.26\",\"0\",\"5\"],[\"64499.1\",\"0.16\",\"0\",\"4\"],[\"64499.3\",\"0\",\"0\",\"0\"],[\"64500.6\",\"1.94\",\"0\",\"4\"],[\"64501.4\",\"15.54\",\"0\",\"2\"],[\"64504.3\",\"0.81\",\"0\",\"3\"],[\"64505.1\",\"0.02\",\"0\",\"2\"],[\"64506.2\",\"58.22\",\"0\",\"3\"],[\"64507.1\",\"0.06\",\"0\",\"4\"],[\"64511.9\",\"20.21\",\"0\",\"2\"],[\"64513.8\",\"0.01\",\"0\",\"1\"],[\"64518.1\",\"4.89\",\"0\",\"7\"],[\"64519.9\",\"496.56\",\"0\",\"2\"],[\"64525.3\",\"0.01\",\"0\",\"1\"]],\"bids\":[[\"64479.8\",\"655.78\",\"0\",\"37\"],[\"64479.7\",\"0.62\",\"0\",\"4\"],[\"64479.6\",\"3.35\",\"0\",\"2\"],[\"64479.3\",\"0\",\"0\",\"0\"],[\"64479.1\",\"0.03\",\"0\",\"2\"],[\"64478\",\"1.57\",\"0\",\"2\"],[\"64477.6\",\"0.01\",\"0\",\"1\"],[\"64476.6\",\"0.01\",\"0\",\"1\"],[\"64476.1\",\"109.13\",\"0\",\"1\"],[\"64475.8\",\"37.56\",\"0\",\"4\"],[\"64474.4\",\"12.71\",\"0\",\"2\"],[\"64474.1\",\"0.02\",\"0\",\"2\"],[\"64473.7\",\"77.55\",\"0\",\"1\"],[\"64472.8\",\"0\",\"0\",\"0\"],[\"64471.9\",\"0.02\",\"0\",\"1\"],[\"64470.3\",\"0.01\",\"0\",\"1\"],[\"64470.1\",\"1.54\",\"0\",\"2\"],[\"64469.9\",\"32.54\",\"0\",\"2\"],[\"64466.6\",\"0.01\",\"0\",\"1\"],[\"64466\",\"0.33\",\"0\",\"3\"],[\"64465.4\",\"508.64\",\"0\",\"4\"],[\"64465.3\",\"46.56\",\"0\",\"3\"],[\"64464.8\",\"0.05\",\"0\",\"3\"],[\"64463.7\",\"0\",\"0\",\"0\"],[\"64463.2\",\"0\",\"0\",\"0\"],[\"64461.7\",\"0.03\",\"0\",\"2\"],[\"64461.5\",\"20.1\",\"0\",\"3\"],[\"64461\",\"0\",\"0\",\"0\"],[\"64460.7\",\"44.97\",\"0\",\"3\"],[\"64460.3\",\"0.55\",\"0\",\"1\"],[\"64460.1\",\"3.91\",\"0\",\"2\"],[\"64459.7\",\"31.06\",\"0\",\"2\"],[\"64459\",\"0.02\",\"0\",\"1\"],[\"64458.8\",\"0\",\"0\",\"0\"],[\"64458.7\",\"18.13\",\"0\",\"2\"],[\"64458.1\",\"58.23\",\"0\",\"1\"],[\"64454.9\",\"0\",\"0\",\"0\"],[\"64454.2\",\"38.85\",\"0\",\"2\"],[\"64439.7\",\"15.65\",\"0\",\"1\"],[\"64439.3\",\"0.02\",\"0\",\"1\"],[\"64423.5\",\"35.08\",\"0\",\"2\"],[\"64422.7\",\"22.42\",\"0\",\"4\"],[\"64422.6\",\"18.89\",\"0\",\"3\"],[\"64422.5\",\"14.15\",\"0\",\"1\"]],\"ts\":\"1782016020405\",\"checksum\":-2042024881,\"seqId\":325070062996,\"prevSeqId\":325070062813}]}"}
{"action": "update", "capture_sequence": 26, "channel": "books", "connection_sequence": 1, "event": null, "instId": "BTC-USDT-SWAP", "local_receive_ts": "2026-06-21T04:27:00Z", "monotonic_ns": 1643576409183392, "raw": "{\"arg\":{\"channel\":\"books\",\"instId\":\"BTC-USDT-SWAP\"},\"action\":\"update\",\"data\":[{\"asks\":[[\"64479.9\",\"262.46\",\"0\",\"32\"],[\"64482.4\",\"0.01\",\"0\",\"1\"],[\"64483.1\",\"0.62\",\"0\",\"3\"],[\"64483.2\",\"116.29\",\"0\",\"3\"],[\"64483.7\",\"1.01\",\"0\",\"2\"],[\"64484.8\",\"0.01\",\"0\",\"1\"],[\"64491.9\",\"0.3\",\"0\",\"4\"],[\"64505.4\",\"144.57\",\"0\",\"5\"],[\"64506.8\",\"2.55\",\"0\",\"6\"],[\"64511.9\",\"0.14\",\"0\",\"1\"],[\"64512.5\",\"20.23\",\"0\",\"6\"],[\"64525.3\",\"0\",\"0\",\"0\"]],\"bids\":[[\"64479.8\",\"584.85\",\"0\",\"36\"],[\"64479.2\",\"0\",\"0\",\"0\"],[\"64478.8\",\"0\",\"0\",\"0\"],[\"64478.7\",\"0\",\"0\",\"0\"],[\"64478\",\"0.01\",\"0\",\"1\"],[\"64477.9\",\"1.57\",\"0\",\"2\"],[\"64477.4\",\"1.56\",\"0\",\"1\"],[\"64476.8\",\"1.56\",\"0\",\"1\"],[\"64476.3\",\"1.57\",\"0\",\"2\"],[\"64475.8\",\"37.25\",\"0\",\"3\"],[\"64475.5\",\"0.31\",\"0\",\"1\"],[\"64470.7\",\"0.02\",\"0\",\"2\"],[\"64461.9\",\"20.09\",\"0\",\"2\"],[\"64461.5\",\"0.02\",\"0\",\"2\"],[\"64461.4\",\"0.03\",\"0\",\"3\"],[\"64460.2\",\"85.4\",\"0\",\"1\"],[\"64458.8\",\"3.22\",\"0\",\"1\"],[\"64452.4\",\"0\",\"0\",\"0\"],[\"64449.9\",\"274.08\",\"0\",\"4\"],[\"64444.9\",\"0\",\"0\",\"0\"],[\"64423.5\",\"15.48\",\"0\",\"1\"],[\"64422.7\",\"3.4\",\"0\",\"3\"],[\"64422.6\",\"0.02\",\"0\",\"2\"],[\"64422.5\",\"0\",\"0\",\"0\"],[\"64422.4\",\"1365.48\",\"0\",\"3\"]],\"ts\":\"1782016020505\",\"checksum\":657397993,\"seqId\":325070063128,\"prevSeqId\":325070062996}]}"}
{"action": null, "capture_sequence": 27, "channel": "trades", "connection_sequence": 1, "event": null, "instId": "BTC-USDT-SWAP", "local_receive_ts": "2026-06-21T04:27:00Z", "monotonic_ns": 1643576425171064, "raw": "{\"arg\":{\"channel\":\"trades\",\"instId\":\"BTC-USDT-SWAP\"},\"data\":[{\"instId\":\"BTC-USDT-SWAP\",\"tradeId\":\"2718750126\",\"px\":\"64479.9\",\"sz\":\"0.07\",\"side\":\"buy\",\"ts\":\"1782016020522\",\"count\":\"1\",\"source\":\"0\",\"seqId\":325070063167}]}"}
{"action": "update", "capture_sequence": 28, "channel": "books", "connection_sequence": 1, "event": null, "instId": "BTC-USDT-SWAP", "local_receive_ts": "2026-06-21T04:27:00Z", "monotonic_ns": 1643576509658609, "raw": "{\"arg\":{\"channel\":\"books\",\"instId\":\"BTC-USDT-SWAP\"},\"action\":\"update\",\"data\":[{\"asks\":[[\"64479.9\",\"294.53\",\"0\",\"34\"],[\"64482.2\",\"7.76\",\"0\",\"2\"],[\"64482.3\",\"15.52\",\"0\",\"1\"],[\"64482.4\",\"0\",\"0\",\"0\"],[\"64483\",\"10.03\",\"0\",\"3\"],[\"64483.2\",\"114.73\",\"0\",\"2\"],[\"64483.4\",\"1\",\"0\",\"1\"],[\"64484.8\",\"1.57\",\"0\",\"2\"],[\"64489.5\",\"4.72\",\"0\",\"4\"],[\"64491.8\",\"0.2\",\"0\",\"2\"],[\"64494.3\",\"0.25\",\"0\",\"5\"],[\"64495.7\",\"11.35\",\"0\",\"3\"],[\"64504.1\",\"15.88\",\"0\",\"7\"],[\"64504.3\",\"0.04\",\"0\",\"2\"],[\"64505.4\",\"59.23\",\"0\",\"4\"],[\"64506.4\",\"85.37\",\"0\",\"4\"],[\"64512.5\",\"0.16\",\"0\",\"5\"],[\"64512.8\",\"20.07\",\"0\",\"1\"],[\"64525.2\",\"0\",\"0\",\"0\"]],\"bids\":[[\"64479.8\",\"586.41\",\"0\",\"37\"],[\"64478.4\",\"1.56\",\"0\",\"1\"],[\"64478\",\"0.02\",\"0\",\"2\"],[\"64477.9\",\"0.01\",\"0\",\"1\"],[\"64477.8\",\"2.56\",\"0\",\"2\"],[\"64475.9\",\"48.11\",\"0\",\"3\"],[\"64472.2\",\"0\",\"0\",\"0\"],[\"64471.7\",\"30.62\",\"0\",\"1\"],[\"64471.2\",\"0\",\"0\",\"0\"],[\"64465.4\",\"507.87\",\"0\",\"3\"],[\"64465.2\",\"0.77\",\"0\",\"1\"],[\"64462.2\",\"20.08\",\"0\",\"1\"],[\"64461.9\",\"0.01\",\"0\",\"1\"],[\"64461\",\"85.4\",\"0\",\"1\"],[\"64460.2\",\"0\",\"0\",\"0\"],[\"64452.4\",\"0.19\",\"0\",\"1\"],[\"64447.7\",\"16.53\",\"0\",\"2\"],[\"64422.6\",\"0\",\"0\",\"0\"],[\"64422.4\",\"0\",\"0\",\"0\"]],\"ts\":\"1782016020605\",\"checksum\":1412683127,\"seqId\":325070063289,\"prevSeqId\":325070063128}]}"}
{"action": "update", "capture_sequence": 29, "channel": "books", "connection_sequence": 1, "event": null, "instId": "BTC-USDT-SWAP", "local_receive_ts": "2026-06-21T04:27:00Z", "monotonic_ns": 1643576613966086, "raw": "{\"arg\":{\"channel\":\"books\",\"instId\":\"BTC-USDT-SWAP\"},\"action\":\"update\",\"data\":[{\"asks\":[[\"64479.9\",\"546.45\",\"0\",\"38\"],[\"64481\",\"51.52\",\"0\",\"2\"],[\"64482\",\"0.06\",\"0\",\"4\"],[\"64482.2\",\"7.75\",\"0\",\"1\"],[\"64482.6\",\"136.15\",\"0\",\"3\"],[\"64483.2\",\"0.01\",\"0\",\"1\"],[\"64483.3\",\"62.26\",\"0\",\"6\"],[\"64483.6\",\"0.51\",\"0\",\"2\"],[\"64484\",\"3.28\",\"0\",\"5\"],[\"64484.2\",\"0\",\"0\",\"0\"],[\"64484.9\",\"0.15\",\"0\",\"1\"],[\"64485.3\",\"0\",\"0\",\"0\"],[\"64486.1\",\"94.37\",\"0\",\"2\"],[\"64488.4\",\"5.67\",\"0\",\"6\"],[\"64489\",\"23.1\",\"0\",\"9\"],[\"64489.5\",\"3.95\",\"0\",\"3\"],[\"64492.3\",\"0.8\",\"0\",\"2\"],[\"64493.2\",\"12.24\",\"0\",\"7\"],[\"64494.3\",\"0.08\",\"0\",\"4\"],[\"64494.5\",\"15.52\",\"0\",\"1\"],[\"64495.6\",\"0.01\",\"0\",\"1\"],[\"64497.1\",\"31.04\",\"0\",\"2\"],[\"64497.8\",\"232.8\",\"0\",\"2\"],[\"64497.9\",\"0.21\",\"0\",\"2\"],[\"64498.7\",\"3.17\",\"0\",\"5\"],[\"64499.7\",\"36.92\",\"0\",\"6\"],[\"64500.4\",\"33.83\",\"0\",\"4\"],[\"64500.6\",\"0.39\",\"0\",\"3\"],[\"64501.5\",\"1.57\",\"0\",\"4\"],[\"64505\",\"200.82\",\"0\",\"4\"],[\"64505.1\",\"58.21\",\"0\",\"3\"],[\"64505.7\",\"85.9\",\"0\",\"2\"],[\"64505.9\",\"1.01\",\"0\",\"2\"],[\"64506\",\"10.07\",\"0\",\"5\"],[\"64506.2\",\"0.03\",\"0\",\"2\"],[\"64506.4\",\"0.03\",\"0\",\"3\"],[\"64511.4\",\"35.85\",\"0\",\"5\"],[\"64512.8\",\"0\",\"0\",\"0\"],[\"64525.2\",\"55.22\",\"0\",\"2\"],[\"64525.3\",\"0.01\",\"0\",\"1\"]],\"bids\":[[\"64479.8\",\"486.41\",\"0\",\"33\"],[\"64478.4\",\"0\",\"0\",\"0\"],[\"64477.8\",\"1\",\"0\",\"1\"],[\"64477.4\",\"0\",\"0\",\"0\"],[\"64476.8\",\"0\",\"0\",\"0\"],[\"64476.6\",\"0\",\"0\",\"0\"],[\"64476.5\",\"0\",\"0\",\"0\"],[\"64476.4\",\"0.01\",\"0\",\"1\"],[\"64476.3\",\"0.01\",\"0\",\"1\"],[\"64476.1\",\"0\",\"0\",\"0\"],[\"64475.5\",\"0\",\"0\",\"0\"],[\"64475.4\",\"1.58\",\"0\",\"3\"],[\"64474.9\",\"21.87\",\"0\",\"3\"],[\"64474.8\",\"0.32\",\"0\",\"2\"],[\"64474.4\",\"14.27\",\"0\",\"3\"],[\"64474\",\"33.83\",\"0\",\"4\"],[\"64473.7\",\"0\",\"0\",\"0\"],[\"64472.8\",\"77.55\",\"0\",\"1\"],[\"64470.1\",\"0.77\",\"0\",\"1\"],[\"64469.9\",\"1.49\",\"0\",\"1\"],[\"64462.7\",\"22.95\",\"0\",\"2\"],[\"64462.2\",\"0\",\"0\",\"0\"],[\"64461.4\",\"33.85\",\"0\",\"4\"],[\"64461\",\"20.08\",\"0\",\"1\"],[\"64460.2\",\"85.4\",\"0\",\"1\"],[\"64459.7\",\"0.01\",\"0\",\"1\"],[\"64459.6\",\"0\",\"0\",\"0\"],[\"64459\",\"31.07\",\"0\",\"2\"],[\"64458.9\",\"232.94\",\"0\",\"2\"],[\"64458.1\",\"0\",\"0\",\"0\"],[\"64457.2\",\"58.23\",\"0\",\"1\"],[\"64423.5\",\"35.08\",\"0\",\"2\"],[\"64422.7\",\"22.42\",\"0\",\"4\"],[\"64422.6\",\"18.89\",\"0\",\"3\"],[\"64422.5\",\"14.15\",\"0\",\"1\"],[\"64422.4\",\"1365.48\",\"0\",\"3\"],[\"64422.3\",\"0.01\",\"0\",\"1\"],[\"64422.2\",\"0.02\",\"0\",\"2\"],[\"64422\",\"0.01\",\"0\",\"1\"],[\"64421.9\",\"0.01\",\"0\",\"1\"]],\"ts\":\"1782016020705\",\"checksum\":2055183641,\"seqId\":325070063468,\"prevSeqId\":325070063289}]}"}
{"action": null, "capture_sequence": 30, "channel": "trades", "connection_sequence": 1, "event": null, "instId": "BTC-USDT-SWAP", "local_receive_ts": "2026-06-21T04:27:00Z", "monotonic_ns": 1643576615828628, "raw": "{\"arg\":{\"channel\":\"trades\",\"instId\":\"BTC-USDT-SWAP\"},\"data\":[{\"instId\":\"BTC-USDT-SWAP\",\"tradeId\":\"2718750127\",\"px\":\"64479.8\",\"sz\":\"11.4\",\"side\":\"sell\",\"ts\":\"1782016020710\",\"count\":\"1\",\"source\":\"0\",\"seqId\":325070063472}]}"}
{"action": "update", "capture_sequence": 31, "channel": "books", "connection_sequence": 1, "event": null, "instId": "BTC-USDT-SWAP", "local_receive_ts": "2026-06-21T04:27:00Z", "monotonic_ns": 1643576713559125, "raw": "{\"arg\":{\"channel\":\"books\",\"instId\":\"BTC-USDT-SWAP\"},\"action\":\"update\",\"data\":[{\"asks\":[[\"64479.9\",\"546.47\",\"0\",\"39\"],[\"64480.8\",\"0.5\",\"0\",\"1\"],[\"64481\",\"50.14\",\"0\",\"4\"],[\"64481.1\",\"136.14\",\"0\",\"2\"],[\"64482\",\"0.05\",\"0\",\"3\"],[\"64482.1\",\"0.03\",\"0\",\"3\"],[\"64482.6\",\"0.02\",\"0\",\"2\"],[\"64483.3\",\"107.87\",\"0\",\"5\"],[\"64483.9\",\"8.02\",\"0\",\"3\"],[\"64486.1\",\"249.15\",\"0\",\"4\"],[\"64487.3\",\"8.04\",\"0\",\"3\"],[\"64489.9\",\"0.01\",\"0\",\"1\"],[\"64490.5\",\"17.51\",\"0\",\"3\"],[\"64490.7\",\"0.06\",\"0\",\"2\"],[\"64491.8\",\"0.05\",\"0\",\"1\"],[\"64494.7\",\"24.05\",\"0\",\"5\"],[\"64496.7\",\"14.23\",\"0\",\"4\"],[\"64496.9\",\"31.3\",\"0\",\"3\"],[\"64498.2\",\"0.35\",\"0\",\"4\"],[\"64498.7\",\"2.86\",\"0\",\"4\"],[\"64498.8\",\"6.24\",\"0\",\"3\"],[\"64499.1\",\"0.17\",\"0\",\"5\"],[\"64499.6\",\"60.92\",\"0\",\"4\"],[\"64499.7\",\"35.37\",\"0\",\"5\"],[\"64500.2\",\"0.01\",\"0\",\"1\"],[\"64503.4\",\"0.77\",\"0\",\"1\"],[\"64504.1\",\"15.11\",\"0\",\"6\"],[\"64505.8\",\"0.08\",\"0\",\"1\"],[\"64517.7\",\"18.69\",\"0\",\"5\"],[\"64518.1\",\"4.88\",\"0\",\"6\"],[\"64525.1\",\"0\",\"0\",\"0\"],[\"64525.2\",\"0\",\"0\",\"0\"],[\"64525.3\",\"0\",\"0\",\"0\"]],\"bids\":[[\"64479.8\",\"474.78\",\"0\",\"33\"],[\"64475.9\",\"46.55\",\"0\",\"2\"],[\"64475.4\",\"0.02\",\"0\",\"2\"],[\"64474.9\",\"20.31\",\"0\",\"2\"],[\"64474.4\",\"12.71\",\"0\",\"2\"],[\"64473.6\",\"153.57\",\"0\",\"2\"],[\"64473.1\",\"0\",\"0\",\"0\"],[\"64472.8\",\"0\",\"0\",\"0\"],[\"64472.7\",\"0.02\",\"0\",\"2\"],[\"64472.4\",\"77.55\",\"0\",\"1\"],[\"64471.9\",\"0\",\"0\",\"0\"],[\"64469.9\",\"1.51\",\"0\",\"2\"],[\"64466\",\"0.02\",\"0\",\"2\"],[\"64465.5\",\"6.53\",\"0\",\"2\"],[\"64465.2\",\"0\",\"0\",\"0\"],[\"64464.8\",\"0.01\",\"0\",\"1\"],[\"64464.5\",\"0.79\",\"0\",\"3\"],[\"64464.1\",\"1.94\",\"0\",\"2\"],[\"64463.7\",\"0.02\",\"0\",\"1\"],[\"64463.6\",\"14.89\",\"0\",\"5\"],[\"64461.7\",\"0.01\",\"0\",\"1\"],[\"64461.2\",\"0.06\",\"0\",\"3\"],[\"64459\",\"31.05\",\"0\",\"1\"],[\"64458.8\",\"0\",\"0\",\"0\"],[\"64457.9\",\"0.03\",\"0\",\"2\"],[\"64454.2\",\"38.83\",\"0\",\"1\"],[\"64452.6\",\"512.2\",\"0\",\"3\"],[\"64452.4\",\"0\",\"0\",\"0\"],[\"64439.3\",\"0\",\"0\",\"0\"],[\"64438.1\",\"23.71\",\"0\",\"4\"],[\"64422.2\",\"11.42\",\"0\",\"3\"],[\"64421.8\",\"0.03\",\"0\",\"2\"],[\"64421.6\",\"15.65\",\"0\",\"1\"],[\"64421.5\",\"0.01\",\"0\",\"1\"],[\"64421.3\",\"0.03\",\"0\",\"2\"],[\"64421.2\",\"0.01\",\"0\",\"1\"]],\"ts\":\"1782016020805\",\"checksum\":1420361356,\"seqId\":325070063558,\"prevSeqId\":325070063468}]}"}
{"action": "update", "capture_sequence": 32, "channel": "books", "connection_sequence": 1, "event": null, "instId": "BTC-USDT-SWAP", "local_receive_ts": "2026-06-21T04:27:01Z", "monotonic_ns": 1643576808619297, "raw": "{\"arg\":{\"channel\":\"books\",\"instId\":\"BTC-USDT-SWAP\"},\"action\":\"update\",\"data\":[{\"asks\":[[\"64482\",\"0.04\",\"0\",\"2\"],[\"64487.3\",\"0.04\",\"0\",\"2\"],[\"64489.3\",\"31.25\",\"0\",\"6\"],[\"64489.6\",\"21.56\",\"0\",\"3\"],[\"64491.9\",\"0.45\",\"0\",\"5\"],[\"64492.8\",\"167.59\",\"0\",\"13\"],[\"64493.2\",\"12.07\",\"0\",\"6\"],[\"64494.5\",\"0\",\"0\",\"0\"],[\"64495.6\",\"15.53\",\"0\",\"2\"],[\"64497.1\",\"0.01\",\"0\",\"1\"],[\"64497.8\",\"0.01\",\"0\",\"1\"],[\"64498.2\",\"31.38\",\"0\",\"5\"],[\"64498.6\",\"234.17\",\"0\",\"8\"],[\"64525.1\",\"0.46\",\"0\",\"1\"]],\"bids\":[[\"64478\",\"0.01\",\"0\",\"1\"],[\"64474.1\",\"0.79\",\"0\",\"3\"],[\"64470.1\",\"0\",\"0\",\"0\"],[\"64466.9\",\"97.8\",\"0\",\"4\"],[\"64460.2\",\"116.45\",\"0\",\"2\"],[\"64459.6\",\"232.92\",\"0\",\"1\"],[\"64459\",\"0\",\"0\",\"0\"],[\"64458.9\",\"3.23\",\"0\",\"2\"],[\"64454\",\"69.96\",\"0\",\"4\"],[\"64452.5\",\"31.51\",\"0\",\"5\"],[\"64445.9\",\"0.01\",\"0\",\"1\"]],\"ts\":\"1782016020905\",\"checksum\":-2137063231,\"seqId\":325070063589,\"prevSeqId\":325070063558}]}"}
{"action": "update", "capture_sequence": 33, "channel": "books", "connection_sequence": 1, "event": null, "instId": "BTC-USDT-SWAP", "local_receive_ts": "2026-06-21T04:27:01Z", "monotonic_ns": 1643576908622888, "raw": "{\"arg\":{\"channel\":\"books\",\"instId\":\"BTC-USDT-SWAP\"},\"action\":\"update\",\"data\":[{\"asks\":[[\"64479.9\",\"548.03\",\"0\",\"40\"],[\"64496.2\",\"0.01\",\"0\",\"1\"],[\"64509.1\",\"1.53\",\"0\",\"4\"],[\"64522\",\"5.17\",\"0\",\"9\"],[\"64525.1\",\"0\",\"0\",\"0\"]],\"bids\":[[\"64474.2\",\"1.56\",\"0\",\"1\"],[\"64473.7\",\"1.56\",\"0\",\"1\"],[\"64473.2\",\"1.57\",\"0\",\"2\"],[\"64472.8\",\"1.56\",\"0\",\"1\"],[\"64472.3\",\"8.76\",\"0\",\"3\"],[\"64471.8\",\"1.56\",\"0\",\"1\"],[\"64471.3\",\"2.95\",\"0\",\"4\"],[\"64470.8\",\"1.56\",\"0\",\"1\"],[\"64466.9\",\"167.7\",\"0\",\"5\"],[\"64454\",\"0.06\",\"0\",\"3\"],[\"64421.8\",\"0\",\"0\",\"0\"],[\"64421.6\",\"0\",\"0\",\"0\"],[\"64421.5\",\"0\",\"0\",\"0\"],[\"64421.3\",\"0\",\"0\",\"0\"],[\"64421.2\",\"0\",\"0\",\"0\"]],\"ts\":\"1782016021005\",\"checksum\":1876933618,\"seqId\":325070063607,\"prevSeqId\":325070063589}]}"}
{"action": null, "capture_sequence": 34, "channel": "trades", "connection_sequence": 1, "event": null, "instId": "BTC-USDT-SWAP", "local_receive_ts": "2026-06-21T04:27:01Z", "monotonic_ns": 1643576980708431, "raw": "{\"arg\":{\"channel\":\"trades\",\"instId\":\"BTC-USDT-SWAP\"},\"data\":[{\"instId\":\"BTC-USDT-SWAP\",\"tradeId\":\"2718750128\",\"px\":\"64479.9\",\"sz\":\"0.02\",\"side\":\"buy\",\"ts\":\"1782016021077\",\"count\":\"1\",\"source\":\"0\",\"seqId\":325070063633}]}"}
{"action": "update", "capture_sequence": 35, "channel": "books", "connection_sequence": 1, "event": null, "instId": "BTC-USDT-SWAP", "local_receive_ts": "2026-06-21T04:27:01Z", "monotonic_ns": 1643577009215201, "raw": "{\"arg\":{\"channel\":\"books\",\"instId\":\"BTC-USDT-SWAP\"},\"action\":\"update\",\"data\":[{\"asks\":[[\"64479.9\",\"548.01\",\"0\",\"40\"],[\"64480.4\",\"1.56\",\"0\",\"1\"],[\"64481\",\"50.15\",\"0\",\"5\"],[\"64481.1\",\"151.66\",\"0\",\"3\"],[\"64482.3\",\"1.56\",\"0\",\"1\"],[\"64487.9\",\"0.51\",\"0\",\"2\"],[\"64491.9\",\"0.3\",\"0\",\"4\"],[\"64499.6\",\"59.37\",\"0\",\"3\"],[\"64500.2\",\"1.56\",\"0\",\"2\"],[\"64513.2\",\"46.65\",\"0\",\"5\"],[\"64525\",\"0\",\"0\",\"0\"]],\"bids\":[[\"64479.8\",\"486.78\",\"0\",\"34\"],[\"64476.4\",\"0\",\"0\",\"0\"],[\"64476.1\",\"0.01\",\"0\",\"1\"],[\"64476\",\"120.82\",\"0\",\"4\"],[\"64475.1\",\"0.31\",\"0\",\"1\"],[\"64474.8\",\"1.57\",\"0\",\"2\"],[\"64474.2\",\"0\",\"0\",\"0\"],[\"64473.3\",\"77.56\",\"0\",\"2\"],[\"64472.4\",\"0\",\"0\",\"0\"],[\"64470.4\",\"1.56\",\"0\",\"1\"],[\"64468.7\",\"128.55\",\"0\",\"7\"],[\"64458.9\",\"0.01\",\"0\",\"1\"],[\"64452.5\",\"31.32\",\"0\",\"4\"]],\"ts\":\"1782016021105\",\"checksum\":981537851,\"seqId\":325070063663,\"prevSeqId\":325070063607}]}"}
{"action": null, "capture_sequence": 36, "channel": "trades", "connection_sequence": 1, "event": null, "instId": "BTC-USDT-SWAP", "local_receive_ts": "2026-06-21T04:27:01Z", "monotonic_ns": 1643577063249502, "raw": "{\"arg\":{\"channel\":\"trades\",\"instId\":\"BTC-USDT-SWAP\"},\"data\":[{\"instId\":\"BTC-USDT-SWAP\",\"tradeId\":\"2718750129\",\"px\":\"64479.8\",\"sz\":\"0.06\",\"side\":\"sell\",\"ts\":\"1782016021160\",\"count\":\"1\",\"source\":\"0\",\"seqId\":325070063699}]}"}
{"action": "update", "capture_sequence": 37, "channel": "books", "connection_sequence": 1, "event": null, "instId": "BTC-USDT-SWAP", "local_receive_ts": "2026-06-21T04:27:01Z", "monotonic_ns": 1643577109096289, "raw": "{\"arg\":{\"channel\":\"books\",\"instId\":\"BTC-USDT-SWAP\"},\"action\":\"update\",\"data\":[{\"asks\":[[\"64479.9\",\"546.58\",\"0\",\"40\"],[\"64480.2\",\"0.01\",\"0\",\"1\"],[\"64480.3\",\"1.56\",\"0\",\"1\"],[\"64480.4\",\"0\",\"0\",\"0\"],[\"64481.1\",\"136.14\",\"0\",\"2\"],[\"64481.7\",\"15.52\",\"0\",\"1\"],[\"64482.1\",\"1.58\",\"0\",\"3\"],[\"64482.3\",\"0\",\"0\",\"0\"],[\"64482.8\",\"1.57\",\"0\",\"2\"],[\"64489.3\",\"23.25\",\"0\",\"5\"],[\"64490.5\",\"25.51\",\"0\",\"4\"],[\"64491.9\",\"0.45\",\"0\",\"5\"],[\"64504\",\"112.74\",\"0\",\"9\"],[\"64505.1\",\"0.02\",\"0\",\"2\"],[\"64524.9\",\"0\",\"0\",\"0\"]],\"bids\":[[\"64479.8\",\"486.72\",\"0\",\"34\"],[\"64475.5\",\"0.31\",\"0\",\"1\"],[\"64475.1\",\"0\",\"0\",\"0\"],[\"64474.8\",\"0.01\",\"0\",\"1\"],[\"64474.2\",\"1.56\",\"0\",\"1\"],[\"64458.9\",\"3.15\",\"0\",\"2\"],[\"64457.2\",\"0\",\"0\",\"0\"],[\"64456.2\",\"80.1\",\"0\",\"3\"],[\"64452.6\",\"512.4\",\"0\",\"4\"],[\"64436.9\",\"0.01\",\"0\",\"1\"],[\"64421.9\",\"0\",\"0\",\"0\"]],\"ts\":\"1782016021205\",\"checksum\":2087309012,\"seqId\":325070063722,\"prevSeqId\":325070063663}]}"}
{"action": null, "capture_sequence": 38, "channel": "trades", "connection_sequence": 1, "event": null, "instId": "BTC-USDT-SWAP", "local_receive_ts": "2026-06-21T04:27:01Z", "monotonic_ns": 1643577126680090, "raw": "{\"arg\":{\"channel\":\"trades\",\"instId\":\"BTC-USDT-SWAP\"},\"data\":[{\"instId\":\"BTC-USDT-SWAP\",\"tradeId\":\"2718750130\",\"px\":\"64479.8\",\"sz\":\"0.2\",\"side\":\"sell\",\"ts\":\"1782016021223\",\"count\":\"1\",\"source\":\"0\",\"seqId\":325070063731}]}"}
{"action": null, "capture_sequence": 39, "channel": "trades", "connection_sequence": 1, "event": null, "instId": "BTC-USDT-SWAP", "local_receive_ts": "2026-06-21T04:27:01Z", "monotonic_ns": 1643577126936060, "raw": "{\"arg\":{\"channel\":\"trades\",\"instId\":\"BTC-USDT-SWAP\"},\"data\":[{\"instId\":\"BTC-USDT-SWAP\",\"tradeId\":\"2718750131\",\"px\":\"64479.8\",\"sz\":\"0.51\",\"side\":\"sell\",\"ts\":\"1782016021223\",\"count\":\"1\",\"source\":\"0\",\"seqId\":325070063733}]}"}
{"action": null, "capture_sequence": 40, "channel": "trades", "connection_sequence": 1, "event": null, "instId": "BTC-USDT-SWAP", "local_receive_ts": "2026-06-21T04:27:01Z", "monotonic_ns": 1643577127970889, "raw": "{\"arg\":{\"channel\":\"trades\",\"instId\":\"BTC-USDT-SWAP\"},\"data\":[{\"instId\":\"BTC-USDT-SWAP\",\"tradeId\":\"2718750132\",\"px\":\"64479.8\",\"sz\":\"0.5\",\"side\":\"sell\",\"ts\":\"1782016021224\",\"count\":\"1\",\"source\":\"0\",\"seqId\":325070063736}]}"}
{"action": "update", "capture_sequence": 41, "channel": "books", "connection_sequence": 1, "event": null, "instId": "BTC-USDT-SWAP", "local_receive_ts": "2026-06-21T04:27:01Z", "monotonic_ns": 1643577209104237, "raw": "{\"arg\":{\"channel\":\"books\",\"instId\":\"BTC-USDT-SWAP\"},\"action\":\"update\",\"data\":[{\"asks\":[[\"64479.9\",\"546.73\",\"0\",\"42\"],[\"64497.9\",\"0.01\",\"0\",\"1\"],[\"64500.2\",\"0.01\",\"0\",\"1\"],[\"64500.3\",\"4.32\",\"0\",\"5\"],[\"64503.4\",\"0\",\"0\",\"0\"],[\"64504\",\"54.55\",\"0\",\"8\"],[\"64504.1\",\"15.88\",\"0\",\"7\"],[\"64504.9\",\"85.44\",\"0\",\"4\"],[\"64505.1\",\"58.21\",\"0\",\"3\"],[\"64505.7\",\"0.56\",\"0\",\"1\"],[\"64511.6\",\"86.12\",\"0\",\"2\"],[\"64512.6\",\"58.24\",\"0\",\"6\"],[\"64524.9\",\"2.19\",\"0\",\"7\"]],\"bids\":[[\"64479.8\",\"473.51\",\"0\",\"33\"],[\"64474.2\",\"0\",\"0\",\"0\"],[\"64473.7\",\"0\",\"0\",\"0\"],[\"64473.3\",\"0.01\",\"0\",\"1\"],[\"64473.2\",\"0.01\",\"0\",\"1\"],[\"64473\",\"77.55\",\"0\",\"1\"],[\"64472.8\",\"0\",\"0\",\"0\"],[\"64469.9\",\"3.07\",\"0\",\"3\"],[\"64465.2\",\"0.77\",\"0\",\"1\"],[\"64464.5\",\"0.02\",\"0\",\"2\"],[\"64461.8\",\"0\",\"0\",\"0\"],[\"64461\",\"106.26\",\"0\",\"2\"],[\"64460.2\",\"31.05\",\"0\",\"1\"],[\"64459.2\",\"85.41\",\"0\",\"2\"],[\"64457.2\",\"58.23\",\"0\",\"1\"],[\"64456.2\",\"21.87\",\"0\",\"2\"],[\"64421.9\",\"0.01\",\"0\",\"1\"]],\"ts\":\"1782016021305\",\"checksum\":1229343483,\"seqId\":325070063767,\"prevSeqId\":325070063722}]}"}
{"action": "update", "capture_sequence": 42, "channel": "books", "connection_sequence": 1, "event": null, "instId": "BTC-USDT-SWAP", "local_receive_ts": "2026-06-21T04:27:01Z", "monotonic_ns": 1643577308756701, "raw": "{\"arg\":{\"channel\":\"books\",\"instId\":\"BTC-USDT-SWAP\"},\"action\":\"update\",\"data\":[{\"asks\":[[\"64479.9\",\"474.38\",\"0\",\"43\"],[\"64480.2\",\"0\",\"0\",\"0\"],[\"64480.3\",\"0\",\"0\",\"0\"],[\"64481.1\",\"137.7\",\"0\",\"3\"],[\"64481.5\",\"1.58\",\"0\",\"2\"],[\"64481.6\",\"0.01\",\"0\",\"1\"],[\"64486.9\",\"0.11\",\"0\",\"1\"],[\"64487.4\",\"5.57\",\"0\",\"8\"],[\"64500.3\",\"2.77\",\"0\",\"4\"],[\"64500.6\",\"1.94\",\"0\",\"4\"],[\"64525\",\"2.51\",\"0\",\"18\"]],\"bids\":[[\"64479.8\",\"549.46\",\"0\",\"35\"],[\"64476.4\",\"31.04\",\"0\",\"1\"],[\"64476.3\",\"120.23\",\"0\",\"2\"],[\"64476.2\",\"200.86\",\"0\",\"5\"],[\"64476.1\",\"0\",\"0\",\"0\"],[\"64476\",\"0.05\",\"0\",\"3\"],[\"64475\",\"1.57\",\"0\",\"2\"],[\"64474.1\",\"1.58\",\"0\",\"3\"],[\"64474\",\"2.01\",\"0\",\"2\"],[\"64473.9\",\"124.11\",\"0\",\"4\"],[\"64473.3\",\"1.57\",\"0\",\"2\"],[\"64473\",\"0\",\"0\",\"0\"],[\"64472.9\",\"96.26\",\"0\",\"2\"],[\"64469.9\",\"2.28\",\"0\",\"3\"],[\"64468.7\",\"134.75\",\"0\",\"8\"],[\"64421.8\",\"0.03\",\"0\",\"2\"]],\"ts\":\"1782016021405\",\"checksum\":1281359881,\"seqId\":325070063853,\"prevSeqId\":325070063767}]}"}
{"action": "update", "capture_sequence": 43, "channel": "books", "connection_sequence": 1, "event": null, "instId": "BTC-USDT-SWAP", "local_receive_ts": "2026-06-21T04:27:01Z", "monotonic_ns": 1643577413201457, "raw": "{\"arg\":{\"channel\":\"books\",\"instId\":\"BTC-USDT-SWAP\"},\"action\":\"update\",\"data\":[{\"asks\":[[\"64479.9\",\"462.82\",\"0\",\"41\"],[\"64480.6\",\"0.02\",\"0\",\"2\"],[\"64480.7\",\"1.56\",\"0\",\"1\"],[\"64481.1\",\"136.14\",\"0\",\"2\"],[\"64481.3\",\"1.56\",\"0\",\"1\"],[\"64481.5\",\"0.02\",\"0\",\"1\"],[\"64481.6\",\"0\",\"0\",\"0\"],[\"64489.4\",\"2.94\",\"0\",\"6\"],[\"64489.9\",\"0\",\"0\",\"0\"],[\"64496.5\",\"0.01\",\"0\",\"1\"],[\"64496.9\",\"31.29\",\"0\",\"2\"],[\"64500.4\",\"0.03\",\"0\",\"3\"],[\"64501.7\",\"34.34\",\"0\",\"5\"],[\"64504.9\",\"0.1\",\"0\",\"3\"],[\"64505.9\",\"86.35\",\"0\",\"3\"],[\"64511.4\",\"15.78\",\"0\",\"4\"],[\"64512.4\",\"20.15\",\"0\",\"2\"],[\"64516.8\",\"6.27\",\"0\",\"4\"],[\"64517.7\",\"18.68\",\"0\",\"4\"],[\"64525\",\"0\",\"0\",\"0\"]],\"bids\":[[\"64476.7\",\"0.02\",\"0\",\"2\"],[\"64476.3\",\"0.17\",\"0\",\"2\"],[\"64476.2\",\"200.09\",\"0\",\"4\"],[\"64475.8\",\"38.81\",\"0\",\"4\"],[\"64475.3\",\"1.56\",\"0\",\"1\"],[\"64475\",\"0.01\",\"0\",\"1\"],[\"64474.8\",\"1.57\",\"0\",\"2\"],[\"64471.9\",\"0.02\",\"0\",\"1\"],[\"64470.4\",\"0\",\"0\",\"0\"],[\"64469.9\",\"3.03\",\"0\",\"3\"],[\"64464.1\",\"1.96\",\"0\",\"3\"],[\"64463.7\",\"0\",\"0\",\"0\"],[\"64462.8\",\"33.81\",\"0\",\"1\"],[\"64461.7\",\"20.09\",\"0\",\"2\"],[\"64461.4\",\"0.03\",\"0\",\"3\"],[\"64461\",\"86.18\",\"0\",\"1\"],[\"64460.6\",\"85.56\",\"0\",\"3\"],[\"64459.2\",\"0.01\",\"0\",\"1\"],[\"64454.1\",\"0.02\",\"0\",\"1\"],[\"64452.6\",\"512.38\",\"0\",\"3\"],[\"64439.3\",\"0.02\",\"0\",\"1\"],[\"64438.1\",\"23.69\",\"0\",\"3\"],[\"64422\",\"0\",\"0\",\"0\"],[\"64421.9\",\"0\",\"0\",\"0\"],[\"64421.8\",\"0\",\"0\",\"0\"]],\"ts\":\"1782016021505\",\"checksum\":-1841218113,\"seqId\":325070064005,\"prevSeqId\":325070063853}]}"}
{"action": "update", "capture_sequence": 44, "channel": "books", "connection_sequence": 1, "event": null, "instId": "BTC-USDT-SWAP", "local_receive_ts": "2026-06-21T04:27:01Z", "monotonic_ns": 1643577508915235, "raw": "{\"arg\":{\"channel\":\"books\",\"instId\":\"BTC-USDT-SWAP\"},\"action\":\"update\",\"data\":[{\"asks\":[[\"64479.9\",\"418.77\",\"0\",\"40\"],[\"64480.6\",\"0.01\",\"0\",\"1\"],[\"64480.7\",\"0\",\"0\",\"0\"],[\"64481\",\"50.13\",\"0\",\"3\"],[\"64481.1\",\"0.01\",\"0\",\"1\"],[\"64481.3\",\"0.01\",\"0\",\"1\"],[\"64481.4\",\"15.52\",\"0\",\"1\"],[\"64481.7\",\"0\",\"0\",\"0\"],[\"64481.9\",\"0.02\",\"0\",\"2\"],[\"64482\",\"1.6\",\"0\",\"3\"],[\"64482.1\",\"0.02\",\"0\",\"2\"],[\"64482.5\",\"1.58\",\"0\",\"2\"],[\"64482.7\",\"137.14\",\"0\",\"3\"],[\"64482.8\",\"0.01\",\"0\",\"1\"],[\"64483.9\",\"0.02\",\"0\",\"2\"],[\"64486.6\",\"82.88\",\"0\",\"3\"],[\"64487.1\",\"2.09\",\"0\",\"5\"],[\"64487.5\",\"1.6\",\"0\",\"4\"],[\"64490.7\",\"8.06\",\"0\",\"3\"],[\"64505.8\",\"2.36\",\"0\",\"2\"],[\"64506.4\",\"200.97\",\"0\",\"4\"],[\"64511.6\",\"0.01\",\"0\",\"1\"],[\"64512.6\",\"144.35\",\"0\",\"7\"],[\"64525\",\"2.51\",\"0\",\"18\"]],\"bids\":[[\"64476.5\",\"12.96\",\"0\",\"2\"],[\"64476.4\",\"31.81\",\"0\",\"2\"],[\"64476.3\",\"120.39\",\"0\",\"3\"],[\"64475.9\",\"46.86\",\"0\",\"3\"],[\"64475.5\",\"0\",\"0\",\"0\"],[\"64471.8\",\"0\",\"0\",\"0\"],[\"64471.3\",\"1.39\",\"0\",\"3\"],[\"64470.8\",\"0\",\"0\",\"0\"],[\"64470.1\",\"0.77\",\"0\",\"1\"],[\"64469.9\",\"1.49\",\"0\",\"1\"],[\"64461.4\",\"86.2\",\"0\",\"4\"],[\"64461\",\"0\",\"0\",\"0\"],[\"64422.3\",\"0.02\",\"0\",\"2\"],[\"64422\",\"0.01\",\"0\",\"1\"],[\"64421.9\",\"0.01\",\"0\",\"1\"]],\"ts\":\"1782016021605\",\"checksum\":2102197855,\"seqId\":325070064146,\"prevSeqId\":325070064005}]}"}
{"action": null, "capture_sequence": 45, "channel": "trades", "connection_sequence": 1, "event": null, "instId": "BTC-USDT-SWAP", "local_receive_ts": "2026-06-21T04:27:01Z", "monotonic_ns": 1643577552152035, "raw": "{\"arg\":{\"channel\":\"trades\",\"instId\":\"BTC-USDT-SWAP\"},\"data\":[{\"instId\":\"BTC-USDT-SWAP\",\"tradeId\":\"2718750133\",\"px\":\"64479.9\",\"sz\":\"0.04\",\"side\":\"buy\",\"ts\":\"1782016021648\",\"count\":\"1\",\"source\":\"0\",\"seqId\":325070064208}]}"}
{"action": "update", "capture_sequence": 46, "channel": "books", "connection_sequence": 1, "event": null, "instId": "BTC-USDT-SWAP", "local_receive_ts": "2026-06-21T04:27:01Z", "monotonic_ns": 1643577613365672, "raw": "{\"arg\":{\"channel\":\"books\",\"instId\":\"BTC-USDT-SWAP\"},\"action\":\"update\",\"data\":[{\"asks\":[[\"64479.9\",\"418.77\",\"0\",\"41\"],[\"64481.3\",\"0.02\",\"0\",\"2\"],[\"64481.9\",\"0.01\",\"0\",\"1\"],[\"64482\",\"0.04\",\"0\",\"2\"],[\"64482.1\",\"0.03\",\"0\",\"3\"],[\"64482.5\",\"0.02\",\"0\",\"1\"],[\"64483.3\",\"106.31\",\"0\",\"4\"],[\"64484\",\"1.72\",\"0\",\"4\"],[\"64484.8\",\"0.01\",\"0\",\"1\"],[\"64497.9\",\"0.32\",\"0\",\"2\"],[\"64498\",\"24.4\",\"0\",\"3\"],[\"64498.2\",\"31.07\",\"0\",\"4\"],[\"64501.7\",\"0.55\",\"0\",\"4\"],[\"64503.4\",\"33.79\",\"0\",\"1\"],[\"64505.1\",\"0.02\",\"0\",\"2\"],[\"64505.9\",\"1.01\",\"0\",\"2\"],[\"64506.2\",\"58.22\",\"0\",\"3\"],[\"64507.7\",\"85.41\",\"0\",\"5\"],[\"64508.7\",\"1.34\",\"0\",\"7\"],[\"64512.4\",\"0.08\",\"0\",\"1\"],[\"64512.5\",\"86.27\",\"0\",\"6\"],[\"64512.6\",\"58.24\",\"0\",\"6\"],[\"64513.2\",\"66.72\",\"0\",\"6\"],[\"64525\",\"0\",\"0\",\"0\"]],\"bids\":[[\"64479.8\",\"549.5\",\"0\",\"36\"],[\"64477\",\"3.09\",\"0\",\"1\"],[\"64476.5\",\"11.4\",\"0\",\"1\"],[\"64476.4\",\"0\",\"0\",\"0\"],[\"64476.3\",\"3.26\",\"0\",\"3\"],[\"64475.8\",\"37.25\",\"0\",\"3\"],[\"64474.6\",\"0\",\"0\",\"0\"],[\"64474\",\"0.01\",\"0\",\"1\"],[\"64469.9\",\"33.31\",\"0\",\"3\"],[\"64465.5\",\"6.22\",\"0\",\"1\"],[\"64465\",\"0.31\",\"0\",\"1\"],[\"64464.3\",\"33.81\",\"0\",\"1\"],[\"64462.8\",\"20.08\",\"0\",\"1\"],[\"64462.3\",\"86.17\",\"0\",\"1\"],[\"64462.2\",\"85.4\",\"0\",\"1\"],[\"64461.7\",\"0.01\",\"0\",\"1\"],[\"64461.4\",\"0.03\",\"0\",\"3\"],[\"64460.6\",\"0.16\",\"0\",\"2\"],[\"64458.1\",\"58.23\",\"0\",\"1\"],[\"64457.2\",\"0\",\"0\",\"0\"],[\"64422.3\",\"0.01\",\"0\",\"1\"],[\"64422.2\",\"0\",\"0\",\"0\"],[\"64422\",\"0\",\"0\",\"0\"],[\"64421.9\",\"0\",\"0\",\"0\"]],\"ts\":\"1782016021705\",\"checksum\":-2048840485,\"seqId\":325070064277,\"prevSeqId\":325070064146}]}"}
{"action": "update", "capture_sequence": 47, "channel": "books", "connection_sequence": 1, "event": null, "instId": "BTC-USDT-SWAP", "local_receive_ts": "2026-06-21T04:27:01Z", "monotonic_ns": 1643577708924845, "raw": "{\"arg\":{\"channel\":\"books\",\"instId\":\"BTC-USDT-SWAP\"},\"action\":\"update\",\"data\":[{\"asks\":[],\"bids\":[[\"64477\",\"0\",\"0\",\"0\"],[\"64476.3\",\"0.17\",\"0\",\"2\"],[\"64474.6\",\"3.09\",\"0\",\"1\"],[\"64473.9\",\"127.2\",\"0\",\"5\"],[\"64468.8\",\"11.63\",\"0\",\"2\"],[\"64467.4\",\"0\",\"0\",\"0\"],[\"64422.2\",\"11.42\",\"0\",\"3\"]],\"ts\":\"1782016021805\",\"checksum\":-1950438946,\"seqId\":325070064357,\"prevSeqId\":325070064277}]}"}
{"action": "update", "capture_sequence": 48, "channel": "books", "connection_sequence": 1, "event": null, "instId": "BTC-USDT-SWAP", "local_receive_ts": "2026-06-21T04:27:02Z", "monotonic_ns": 1643577808781562, "raw": "{\"arg\":{\"channel\":\"books\",\"instId\":\"BTC-USDT-SWAP\"},\"action\":\"update\",\"data\":[{\"asks\":[[\"64489.6\",\"0.12\",\"0\",\"2\"],[\"64492.2\",\"16.48\",\"0\",\"8\"]],\"bids\":[[\"64479.8\",\"649.9\",\"0\",\"37\"],[\"64476.7\",\"0.01\",\"0\",\"1\"],[\"64474.1\",\"1.57\",\"0\",\"2\"]],\"ts\":\"1782016021905\",\"checksum\":-782072895,\"seqId\":325070064434,\"prevSeqId\":325070064357}]}"}
{"action": "update", "capture_sequence": 49, "channel": "books", "connection_sequence": 1, "event": null, "instId": "BTC-USDT-SWAP", "local_receive_ts": "2026-06-21T04:27:02Z", "monotonic_ns": 1643577913154330, "raw": "{\"arg\":{\"channel\":\"books\",\"instId\":\"BTC-USDT-SWAP\"},\"action\":\"update\",\"data\":[{\"asks\":[[\"64479.9\",\"541.1\",\"0\",\"44\"],[\"64480.7\",\"1.56\",\"0\",\"1\"],[\"64481.1\",\"1.57\",\"0\",\"2\"],[\"64481.6\",\"1.56\",\"0\",\"1\"],[\"64483.6\",\"0.67\",\"0\",\"3\"],[\"64483.9\",\"8.02\",\"0\",\"3\"],[\"64489.6\",\"15.69\",\"0\",\"3\"],[\"64490.5\",\"17.51\",\"0\",\"3\"],[\"64490.7\",\"0.06\",\"0\",\"2\"],[\"64491.7\",\"23.94\",\"0\",\"4\"],[\"64492.2\",\"0.91\",\"0\",\"7\"],[\"64494.9\",\"15.59\",\"0\",\"4\"],[\"64495.6\",\"0.01\",\"0\",\"1\"],[\"64497.5\",\"0.64\",\"0\",\"4\"],[\"64497.9\",\"0.01\",\"0\",\"1\"],[\"64500.3\",\"4.32\",\"0\",\"5\"],[\"64500.6\",\"0.39\",\"0\",\"3\"],[\"64502.2\",\"33.9\",\"0\",\"4\"],[\"64503.4\",\"0\",\"0\",\"0\"],[\"64505.8\",\"0.08\",\"0\",\"1\"],[\"64506.2\",\"0.03\",\"0\",\"2\"],[\"64506.7\",\"58.38\",\"0\",\"16\"],[\"64506.8\",\"87.89\",\"0\",\"7\"],[\"64507.7\",\"0.07\",\"0\",\"4\"],[\"64511.6\",\"86.12\",\"0\",\"2\"],[\"64512.5\",\"0.16\",\"0\",\"5\"],[\"64513.1\",\"21.63\",\"0\",\"3\"],[\"64513.2\",\"46.65\",\"0\",\"5\"],[\"64524.9\",\"0\",\"0\",\"0\"]],\"bids\":[[\"64479.8\",\"586.11\",\"0\",\"36\"],[\"64476.6\",\"0.01\",\"0\",\"1\"],[\"64476.2\",\"131.51\",\"0\",\"4\"],[\"64475.9\",\"46.56\",\"0\",\"3\"],[\"64475.7\",\"3.56\",\"0\",\"2\"],[\"64475.5\",\"0.31\",\"0\",\"1\"],[\"64475.3\",\"0\",\"0\",\"0\"],[\"64474\",\"32.6\",\"0\",\"4\"],[\"64473.9\",\"49.65\",\"0\",\"4\"],[\"64473.6\",\"231.12\",\"0\",\"3\"],[\"64471.8\",\"1.56\",\"0\",\"1\"],[\"64471.3\",\"2.95\",\"0\",\"4\"],[\"64470.1\",\"0\",\"0\",\"0\"],[\"64469.9\",\"1.49\",\"0\",\"1\"],[\"64464.3\",\"0\",\"0\",\"0\"],[\"64463.4\",\"33.81\",\"0\",\"1\"],[\"64462.8\",\"0\",\"0\",\"0\"],[\"64462.7\",\"43.03\",\"0\",\"3\"],[\"64462.3\",\"0\",\"0\",\"0\"],[\"64462.2\",\"0\",\"0\",\"0\"],[\"64461.5\",\"85.42\",\"0\",\"3\"],[\"64461.4\",\"86.21\",\"0\",\"4\"],[\"64458.8\",\"58.23\",\"0\",\"1\"],[\"64458.1\",\"0\",\"0\",\"0\"],[\"64422\",\"0.01\",\"0\",\"1\"],[\"64421.9\",\"0.01\",\"0\",\"1\"]],\"ts\":\"1782016022005\",\"checksum\":1322552294,\"seqId\":325070064598,\"prevSeqId\":325070064434}]}"}
{"action": null, "capture_sequence": 50, "channel": "trades", "connection_sequence": 1, "event": null, "instId": "BTC-USDT-SWAP", "local_receive_ts": "2026-06-21T04:27:02Z", "monotonic_ns": 1643577976656149, "raw": "{\"arg\":{\"channel\":\"trades\",\"instId\":\"BTC-USDT-SWAP\"},\"data\":[{\"instId\":\"BTC-USDT-SWAP\",\"tradeId\":\"2718750134\",\"px\":\"64479.9\",\"sz\":\"0.12\",\"side\":\"buy\",\"ts\":\"1782016022073\",\"count\":\"1\",\"source\":\"0\",\"seqId\":325070064821}]}"}
{"action": null, "capture_sequence": 51, "channel": "trades", "connection_sequence": 1, "event": null, "instId": "BTC-USDT-SWAP", "local_receive_ts": "2026-06-21T04:27:02Z", "monotonic_ns": 1643577997546185, "raw": "{\"arg\":{\"channel\":\"trades\",\"instId\":\"BTC-USDT-SWAP\"},\"data\":[{\"instId\":\"BTC-USDT-SWAP\",\"tradeId\":\"2718750135\",\"px\":\"64479.8\",\"sz\":\"0.02\",\"side\":\"sell\",\"ts\":\"1782016022094\",\"count\":\"1\",\"source\":\"0\",\"seqId\":325070064870}]}"}
{"action": "update", "capture_sequence": 52, "channel": "books", "connection_sequence": 1, "event": null, "instId": "BTC-USDT-SWAP", "local_receive_ts": "2026-06-21T04:27:02Z", "monotonic_ns": 1643578018384371, "raw": "{\"arg\":{\"channel\":\"books\",\"instId\":\"BTC-USDT-SWAP\"},\"action\":\"update\",\"data\":[{\"asks\":[[\"64479.9\",\"532.54\",\"0\",\"44\"],[\"64480.7\",\"0\",\"0\",\"0\"],[\"64481.1\",\"0.01\",\"0\",\"1\"],[\"64481.6\",\"0\",\"0\",\"0\"],[\"64481.8\",\"1.6\",\"0\",\"4\"],[\"64482\",\"0.05\",\"0\",\"3\"],[\"64482.5\",\"0.03\",\"0\",\"2\"],[\"64482.6\",\"1.58\",\"0\",\"3\"],[\"64482.7\",\"136.14\",\"0\",\"2\"],[\"64483\",\"11.59\",\"0\",\"4\"],[\"64483.3\",\"106.3\",\"0\",\"3\"],[\"64483.4\",\"0\",\"0\",\"0\"],[\"64483.5\",\"1.56\",\"0\",\"1\"],[\"64483.6\",\"0.66\",\"0\",\"2\"],[\"64483.7\",\"0.01\",\"0\",\"1\"],[\"64484\",\"2.08\",\"0\",\"4\"],[\"64484.3\",\"0\",\"0\",\"0\"],[\"64484.7\",\"0\",\"0\",\"0\"],[\"64485.1\",\"0\",\"0\",\"0\"],[\"64485.5\",\"0.01\",\"0\",\"1\"],[\"64485.8\",\"0.41\",\"0\",\"3\"],[\"64486\",\"51.09\",\"0\",\"6\"],[\"64487.5\",\"0.04\",\"0\",\"3\"],[\"64488.9\",\"0.34\",\"0\",\"7\"],[\"64489.4\",\"2.93\",\"0\",\"5\"],[\"64491.9\",\"0.3\",\"0\",\"4\"],[\"64494.9\",\"0.07\",\"0\",\"3\"],[\"64495.6\",\"15.53\",\"0\",\"2\"],[\"64496.5\",\"0.02\",\"0\",\"2\"],[\"64496.7\",\"14.22\",\"0\",\"3\"],[\"64497.9\",\"31.04\",\"0\",\"2\"],[\"64498.2\",\"232.83\",\"0\",\"4\"],[\"64498.6\",\"1.39\",\"0\",\"7\"],[\"64500\",\"3487.27\",\"0\",\"1035\"],[\"64500.3\",\"2.77\",\"0\",\"4\"],[\"64500.4\",\"1.58\",\"0\",\"4\"],[\"64502.2\",\"0.11\",\"0\",\"3\"],[\"64502.3\",\"45.01\",\"0\",\"4\"],[\"64503.8\",\"0.77\",\"0\",\"1\"],[\"64504.1\",\"15.11\",\"0\",\"6\"],[\"64505.8\",\"2.36\",\"0\",\"2\"],[\"64505.9\",\"0.01\",\"0\",\"1\"],[\"64506.5\",\"15.72\",\"0\",\"2\"],[\"64506.7\",\"0.19\",\"0\",\"15\"],[\"64506.8\",\"59.73\",\"0\",\"6\"],[\"64507.1\",\"85.4\",\"0\",\"5\"],[\"64507.2\",\"14.03\",\"0\",\"2\"],[\"64507.5\",\"0.13\",\"0\",\"6\"],[\"64507.8\",\"34.13\",\"0\",\"5\"],[\"64508.3\",\"0\",\"0\",\"0\"],[\"64508.7\",\"0.14\",\"0\",\"6\"],[\"64508.9\",\"11.22\",\"0\",\"3\"],[\"64509.1\",\"0.03\",\"0\",\"3\"],[\"64511.6\",\"0.01\",\"0\",\"1\"],[\"64512.6\",\"144.35\",\"0\",\"7\"],[\"64513.1\",\"1.56\",\"0\",\"2\"],[\"64513.4\",\"35.75\",\"0\",\"4\"],[\"64516.1\",\"0.05\",\"0\",\"5\"],[\"64516.8\",\"6.26\",\"0\",\"3\"],[\"64524.9\",\"2.19\",\"0\",\"7\"],[\"64525\",\"2.51\",\"0\",\"18\"],[\"64525.1\",\"0.46\",\"0\",\"1\"],[\"64525.2\",\"55.22\",\"0\",\"2\"],[\"64525.3\",\"0.01\",\"0\",\"1\"]],\"bids\":[[\"64479.8\",\"586.09\",\"0\",\"36\"],[\"64475.7\",\"2\",\"0\",\"1\"],[\"64474.8\",\"0.01\",\"0\",\"1\"],[\"64474.1\",\"0.01\",\"0\",\"1\"],[\"64471.9\",\"0\",\"0\",\"0\"],[\"64471.6\",\"0.02\",\"0\",\"1\"],[\"64470.8\",\"1.56\",\"0\",\"1\"],[\"64470.4\",\"1.56\",\"0\",\"1\"],[\"64469.9\",\"3.05\",\"0\",\"2\"],[\"64465.7\",\"0.38\",\"0\",\"1\"],[\"64465.2\",\"0\",\"0\",\"0\"],[\"64465.1\",\"24\",\"0\",\"2\"],[\"64465\",\"1.08\",\"0\",\"2\"],[\"64464.7\",\"0\",\"0\",\"0\"],[\"64464.4\",\"0.01\",\"0\",\"1\"],[\"64464.1\",\"0.04\",\"0\",\"2\"],[\"64463.8\",\"347.78\",\"0\",\"2\"],[\"64463.6\",\"12.13\",\"0\",\"4\"],[\"64463.3\",\"46.54\",\"0\",\"1\"],[\"64463\",\"0.02\",\"0\",\"2\"],[\"64462.8\",\"20.08\",\"0\",\"1\"],[\"64462.7\",\"22.95\",\"0\",\"2\"],[\"64462.5\",\"2.6\",\"0\",\"1\"],[\"64461.6\",\"86.4\",\"0\",\"2\"],[\"64461.5\",\"86.19\",\"0\",\"3\"],[\"64461.4\",\"0.03\",\"0\",\"3\"],[\"64460.2\",\"0\",\"0\",\"0\"],[\"64459.6\",\"31.05\",\"0\",\"1\"],[\"64459.5\",\"248.58\",\"0\",\"2\"],[\"64458.9\",\"0.01\",\"0\",\"1\"],[\"64454.1\",\"0\",\"0\",\"0\"],[\"64452.7\",\"323.59\",\"0\",\"5\"],[\"64452.6\",\"512.18\",\"0\",\"2\"],[\"64439.3\",\"0\",\"0\",\"0\"],[\"64439\",\"0.03\",\"0\",\"2\"],[\"64421.8\",\"0.03\",\"0\",\"2\"],[\"64421.6\",\"15.65\",\"0\",\"1\"]],\"ts\":\"1782016022105\",\"checksum\":1041157727,\"seqId\":325070064894,\"prevSeqId\":325070064598}]}"}
{"action": null, "capture_sequence": 53, "channel": "trades", "connection_sequence": 1, "event": null, "instId": "BTC-USDT-SWAP", "local_receive_ts": "2026-06-21T04:27:02Z", "monotonic_ns": 1643578068500600, "raw": "{\"arg\":{\"channel\":\"trades\",\"instId\":\"BTC-USDT-SWAP\"},\"data\":[{\"instId\":\"BTC-USDT-SWAP\",\"tradeId\":\"2718750136\",\"px\":\"64479.8\",\"sz\":\"0.16\",\"side\":\"sell\",\"ts\":\"1782016022165\",\"count\":\"1\",\"source\":\"0\",\"seqId\":325070064983}]}"}
{"action": "update", "capture_sequence": 54, "channel": "books", "connection_sequence": 1, "event": null, "instId": "BTC-USDT-SWAP", "local_receive_ts": "2026-06-21T04:27:02Z", "monotonic_ns": 1643578109143360, "raw": "{\"arg\":{\"channel\":\"books\",\"instId\":\"BTC-USDT-SWAP\"},\"action\":\"update\",\"data\":[{\"asks\":[[\"64479.9\",\"541.46\",\"0\",\"46\"],[\"64480\",\"50.1\",\"0\",\"8\"],[\"64480.1\",\"1.57\",\"0\",\"2\"],[\"64480.5\",\"0.01\",\"0\",\"1\"],[\"64480.6\",\"1.57\",\"0\",\"2\"],[\"64481.3\",\"0\",\"0\",\"0\"],[\"64481.4\",\"0\",\"0\",\"0\"],[\"64481.5\",\"15.54\",\"0\",\"2\"],[\"64481.7\",\"0.01\",\"0\",\"1\"],[\"64482.1\",\"0.02\",\"0\",\"2\"],[\"64483.4\",\"1\",\"0\",\"1\"],[\"64483.6\",\"0.5\",\"0\",\"1\"],[\"64484.3\",\"1.2\",\"0\",\"1\"],[\"64485.1\",\"1.2\",\"0\",\"1\"],[\"64485.8\",\"1.61\",\"0\",\"4\"],[\"64487.1\",\"0.53\",\"0\",\"4\"],[\"64488.9\",\"0.33\",\"0\",\"6\"],[\"64489.1\",\"25.05\",\"0\",\"6\"],[\"64491.8\",\"0.2\",\"0\",\"2\"],[\"64498.2\",\"0.04\",\"0\",\"3\"],[\"64498.4\",\"232.79\",\"0\",\"1\"],[\"64503.8\",\"0\",\"0\",\"0\"],[\"64503.9\",\"16.42\",\"0\",\"2\"],[\"64506.5\",\"16.72\",\"0\",\"3\"],[\"64506.8\",\"1.55\",\"0\",\"5\"],[\"64507\",\"58.24\",\"0\",\"2\"],[\"64507.5\",\"1.33\",\"0\",\"7\"],[\"64508.2\",\"60.21\",\"0\",\"6\"],[\"64508.9\",\"12.42\",\"0\",\"4\"],[\"64515.1\",\"0\",\"0\",\"0\"],[\"64525.2\",\"0\",\"0\",\"0\"],[\"64525.3\",\"0\",\"0\",\"0\"]],\"bids\":[[\"64479.8\",\"585.92\",\"0\",\"35\"],[\"64475.4\",\"1.58\",\"0\",\"3\"],[\"64474.9\",\"21.87\",\"0\",\"3\"],[\"64464.6\",\"1.92\",\"0\",\"1\"],[\"64464.1\",\"2.8\",\"0\",\"3\"],[\"64463.5\",\"2.89\",\"0\",\"2\"],[\"64459.1\",\"104.77\",\"0\",\"2\"],[\"64459\",\"3.23\",\"0\",\"1\"],[\"64458.8\",\"0\",\"0\",\"0\"],[\"64452.7\",\"323.57\",\"0\",\"4\"],[\"64452.6\",\"512.39\",\"0\",\"4\"],[\"64421.6\",\"0\",\"0\",\"0\"]],\"ts\":\"1782016022205\",\"checksum\":-1724666258,\"seqId\":325070065053,\"prevSeqId\":325070064894}]}"}
{"action": null, "capture_sequence": 55, "channel": "trades", "connection_sequence": 1, "event": null, "instId": "BTC-USDT-SWAP", "local_receive_ts": "2026-06-21T04:27:02Z", "monotonic_ns": 1643578133439134, "raw": "{\"arg\":{\"channel\":\"trades\",\"instId\":\"BTC-USDT-SWAP\"},\"data\":[{\"instId\":\"BTC-USDT-SWAP\",\"tradeId\":\"2718750137\",\"px\":\"64479.8\",\"sz\":\"0.06\",\"side\":\"sell\",\"ts\":\"1782016022230\",\"count\":\"1\",\"source\":\"0\",\"seqId\":325070065082}]}"}
{"action": "update", "capture_sequence": 56, "channel": "books", "connection_sequence": 1, "event": null, "instId": "BTC-USDT-SWAP", "local_receive_ts": "2026-06-21T04:27:02Z", "monotonic_ns": 1643578208840008, "raw": "{\"arg\":{\"channel\":\"books\",\"instId\":\"BTC-USDT-SWAP\"},\"action\":\"update\",\"data\":[{\"asks\":[[\"64480\",\"51.65\",\"0\",\"8\"],[\"64480.1\",\"0.01\",\"0\",\"1\"],[\"64481.5\",\"0.02\",\"0\",\"1\"],[\"64481.7\",\"0.02\",\"0\",\"2\"],[\"64481.8\",\"17.12\",\"0\",\"5\"],[\"64482.7\",\"137.14\",\"0\",\"3\"],[\"64483.7\",\"1.01\",\"0\",\"2\"],[\"64484.6\",\"2.41\",\"0\",\"3\"],[\"64485.5\",\"1.21\",\"0\",\"2\"],[\"64485.9\",\"13.12\",\"0\",\"3\"],[\"64503.9\",\"15.65\",\"0\",\"1\"],[\"64504.1\",\"15.88\",\"0\",\"7\"],[\"64505.9\",\"1.01\",\"0\",\"2\"],[\"64506.8\",\"2.55\",\"0\",\"6\"],[\"64507.8\",\"35.33\",\"0\",\"6\"],[\"64508.6\",\"1.21\",\"0\",\"2\"],[\"64509.1\",\"1.53\",\"0\",\"4\"],[\"64513.4\",\"15.68\",\"0\",\"3\"],[\"64513.8\",\"20.08\",\"0\",\"2\"]],\"bids\":[[\"64479.8\",\"585.86\",\"0\",\"35\"],[\"64475.4\",\"0.02\",\"0\",\"2\"],[\"64475\",\"1.57\",\"0\",\"2\"],[\"64474.9\",\"20.31\",\"0\",\"2\"],[\"64474.4\",\"14.27\",\"0\",\"3\"],[\"64473.9\",\"51.21\",\"0\",\"5\"],[\"64469.9\",\"1.49\",\"0\",\"1\"],[\"64466.2\",\"1.51\",\"0\",\"2\"],[\"64465.3\",\"48.16\",\"0\",\"4\"],[\"64465.2\",\"0.77\",\"0\",\"1\"],[\"64465\",\"0.31\",\"0\",\"1\"],[\"64464.3\",\"2.16\",\"0\",\"1\"],[\"64463.8\",\"350.78\",\"0\",\"3\"],[\"64463\",\"2.72\",\"0\",\"3\"],[\"64459.1\",\"46.54\",\"0\",\"1\"],[\"64458.8\",\"58.23\",\"0\",\"1\"],[\"64422\",\"0\",\"0\",\"0\"],[\"64421.9\",\"0\",\"0\",\"0\"],[\"64421.8\",\"0\",\"0\",\"0\"]],\"ts\":\"1782016022305\",\"checksum\":-279329809,\"seqId\":325070065182,\"prevSeqId\":325070065053}]}"}
{"action": null, "capture_sequence": 57, "channel": "trades", "connection_sequence": 1, "event": null, "instId": "BTC-USDT-SWAP", "local_receive_ts": "2026-06-21T04:27:02Z", "monotonic_ns": 1643578237244517, "raw": "{\"arg\":{\"channel\":\"trades\",\"instId\":\"BTC-USDT-SWAP\"},\"data\":[{\"instId\":\"BTC-USDT-SWAP\",\"tradeId\":\"2718750138\",\"px\":\"64479.9\",\"sz\":\"3.96\",\"side\":\"buy\",\"ts\":\"1782016022334\",\"count\":\"1\",\"source\":\"0\",\"seqId\":325070065217}]}"}
{"action": null, "capture_sequence": 58, "channel": "trades", "connection_sequence": 1, "event": null, "instId": "BTC-USDT-SWAP", "local_receive_ts": "2026-06-21T04:27:02Z", "monotonic_ns": 1643578293286642, "raw": "{\"arg\":{\"channel\":\"trades\",\"instId\":\"BTC-USDT-SWAP\"},\"data\":[{\"instId\":\"BTC-USDT-SWAP\",\"tradeId\":\"2718750139\",\"px\":\"64479.9\",\"sz\":\"0.01\",\"side\":\"buy\",\"ts\":\"1782016022390\",\"count\":\"1\",\"source\":\"0\",\"seqId\":325070065292}]}"}
{"action": "update", "capture_sequence": 59, "channel": "books", "connection_sequence": 1, "event": null, "instId": "BTC-USDT-SWAP", "local_receive_ts": "2026-06-21T04:27:02Z", "monotonic_ns": 1643578311653381, "raw": "{\"arg\":{\"channel\":\"books\",\"instId\":\"BTC-USDT-SWAP\"},\"action\":\"update\",\"data\":[{\"asks\":[[\"64479.9\",\"537.49\",\"0\",\"46\"],[\"64480\",\"50.09\",\"0\",\"7\"],[\"64480.5\",\"0\",\"0\",\"0\"],[\"64480.6\",\"0.01\",\"0\",\"1\"],[\"64481.8\",\"15.56\",\"0\",\"4\"],[\"64481.9\",\"1.57\",\"0\",\"2\"],[\"64482\",\"0.04\",\"0\",\"2\"],[\"64482.1\",\"0.03\",\"0\",\"3\"],[\"64482.9\",\"0.01\",\"0\",\"1\"],[\"64484\",\"3.28\",\"0\",\"5\"],[\"64484.5\",\"1.62\",\"0\",\"4\"],[\"64497.5\",\"0.33\",\"0\",\"3\"],[\"64497.8\",\"0.32\",\"0\",\"2\"],[\"64504.1\",\"15.11\",\"0\",\"6\"],[\"64504.3\",\"0.81\",\"0\",\"3\"],[\"64507.2\",\"15.23\",\"0\",\"3\"]],\"bids\":[[\"64477.5\",\"1.56\",\"0\",\"1\"],[\"64475\",\"0.01\",\"0\",\"1\"],[\"64474.9\",\"21.87\",\"0\",\"3\"],[\"64474.4\",\"12.71\",\"0\",\"2\"],[\"64474.3\",\"1.56\",\"0\",\"1\"],[\"64473.9\",\"49.65\",\"0\",\"4\"],[\"64473.8\",\"73.2\",\"0\",\"4\"],[\"64470.8\",\"0\",\"0\",\"0\"],[\"64470.4\",\"0\",\"0\",\"0\"],[\"64465.6\",\"30.11\",\"0\",\"5\"],[\"64465.4\",\"508.64\",\"0\",\"4\"],[\"64465.2\",\"0\",\"0\",\"0\"],[\"64464.9\",\"32.74\",\"0\",\"2\"],[\"64422\",\"0.01\",\"0\",\"1\"]],\"ts\":\"1782016022405\",\"checksum\":382130773,\"seqId\":325070065304,\"prevSeqId\":325070065182}]}"}
{"action": null, "capture_sequence": 60, "channel": "trades", "connection_sequence": 1, "event": null, "instId": "BTC-USDT-SWAP", "local_receive_ts": "2026-06-21T04:27:02Z", "monotonic_ns": 1643578367610556, "raw": "{\"arg\":{\"channel\":\"trades\",\"instId\":\"BTC-USDT-SWAP\"},\"data\":[{\"instId\":\"BTC-USDT-SWAP\",\"tradeId\":\"2718750140\",\"px\":\"64479.9\",\"sz\":\"0.1\",\"side\":\"buy\",\"ts\":\"1782016022464\",\"count\":\"1\",\"source\":\"0\",\"seqId\":325070065386}]}"}
{"action": "update", "capture_sequence": 61, "channel": "books", "connection_sequence": 1, "event": null, "instId": "BTC-USDT-SWAP", "local_receive_ts": "2026-06-21T04:27:02Z", "monotonic_ns": 1643578413406133, "raw": "{\"arg\":{\"channel\":\"books\",\"instId\":\"BTC-USDT-SWAP\"},\"action\":\"update\",\"data\":[{\"asks\":[[\"64479.9\",\"527.39\",\"0\",\"45\"],[\"64481\",\"80.85\",\"0\",\"2\"],[\"64481.9\",\"0.01\",\"0\",\"1\"],[\"64482.5\",\"0.02\",\"0\",\"1\"],[\"64482.6\",\"120.24\",\"0\",\"3\"],[\"64483\",\"10.03\",\"0\",\"3\"],[\"64483.3\",\"106.31\",\"0\",\"4\"],[\"64483.5\",\"0\",\"0\",\"0\"],[\"64484\",\"1.72\",\"0\",\"4\"],[\"64485\",\"43.51\",\"0\",\"3\"],[\"64487.1\",\"2.09\",\"0\",\"5\"],[\"64487.5\",\"1.6\",\"0\",\"4\"],[\"64488\",\"59.43\",\"0\",\"28\"],[\"64492.4\",\"11.37\",\"0\",\"7\"],[\"64494.9\",\"15.59\",\"0\",\"4\"],[\"64495.6\",\"0.01\",\"0\",\"1\"],[\"64497.1\",\"0.32\",\"0\",\"2\"],[\"64497.8\",\"0.01\",\"0\",\"1\"],[\"64498.2\",\"232.83\",\"0\",\"4\"],[\"64498.4\",\"0\",\"0\",\"0\"],[\"64499.8\",\"19.68\",\"0\",\"5\"],[\"64501.7\",\"34.34\",\"0\",\"5\"],[\"64502.3\",\"11.22\",\"0\",\"3\"],[\"64503.9\",\"16.42\",\"0\",\"2\"],[\"64504.3\",\"0.04\",\"0\",\"2\"],[\"64505.9\",\"59.2\",\"0\",\"3\"],[\"64506.5\",\"102.06\",\"0\",\"4\"],[\"64507\",\"0.06\",\"0\",\"1\"],[\"64507.1\",\"0.06\",\"0\",\"4\"],[\"64511.6\",\"86.12\",\"0\",\"2\"],[\"64512.6\",\"58.24\",\"0\",\"6\"],[\"64512.8\",\"20.07\",\"0\",\"1\"],[\"64513.8\",\"0.01\",\"0\",\"1\"],[\"64525.2\",\"55.22\",\"0\",\"2\"]],\"bids\":[[\"64477.5\",\"0\",\"0\",\"0\"],[\"64474.8\",\"3.1\",\"0\",\"2\"],[\"64474.7\",\"0.01\",\"0\",\"1\"],[\"64474.6\",\"0\",\"0\",\"0\"],[\"64474.2\",\"3.09\",\"0\",\"1\"],[\"64473.9\",\"46.56\",\"0\",\"3\"],[\"64471.3\",\"1.39\",\"0\",\"3\"],[\"64465.4\",\"507.87\",\"0\",\"3\"],[\"64465\",\"0.77\",\"0\",\"1\"],[\"64464.4\",\"0.32\",\"0\",\"2\"],[\"64463.4\",\"0\",\"0\",\"0\"],[\"64462.9\",\"33.81\",\"0\",\"1\"],[\"64462.8\",\"0\",\"0\",\"0\"],[\"64462.2\",\"20.08\",\"0\",\"1\"],[\"64461.7\",\"86.18\",\"0\",\"2\"],[\"64461.6\",\"1\",\"0\",\"1\"],[\"64461.5\",\"0.02\",\"0\",\"2\"],[\"64461.2\",\"85.46\",\"0\",\"4\"],[\"64459.5\",\"15.65\",\"0\",\"1\"],[\"64459.2\",\"232.94\",\"0\",\"2\"],[\"64458.8\",\"0\",\"0\",\"0\"],[\"64457.5\",\"58.24\",\"0\",\"2\"],[\"64421.9\",\"0.01\",\"0\",\"1\"],[\"64421.8\",\"0.03\",\"0\",\"2\"]],\"ts\":\"1782016022505\",\"checksum\":2119759031,\"seqId\":325070065473,\"prevSeqId\":325070065304}]}"}
{"action": "update", "capture_sequence": 62, "channel": "books", "connection_sequence": 1, "event": null, "instId": "BTC-USDT-SWAP", "local_receive_ts": "2026-06-21T04:27:02Z", "monotonic_ns": 1643578513687229, "raw": "{\"arg\":{\"channel\":\"books\",\"instId\":\"BTC-USDT-SWAP\"},\"action\":\"update\",\"data\":[{\"asks\":[[\"64479.9\",\"699.35\",\"0\",\"47\"],[\"64480.3\",\"15.52\",\"0\",\"1\"],[\"64481\",\"51.39\",\"0\",\"3\"],[\"64481.1\",\"136.14\",\"0\",\"2\"],[\"64481.7\",\"0.01\",\"0\",\"1\"],[\"64481.8\",\"0.04\",\"0\",\"3\"],[\"64482.6\",\"0.02\",\"0\",\"2\"],[\"64482.7\",\"1.01\",\"0\",\"2\"],[\"64484\",\"15.96\",\"0\",\"5\"],[\"64488.9\",\"0.34\",\"0\",\"7\"],[\"64489.1\",\"11.1\",\"0\",\"4\"],[\"64492.3\",\"0.03\",\"0\",\"1\"],[\"64492.4\",\"12.14\",\"0\",\"8\"],[\"64493.8\",\"15.55\",\"0\",\"3\"],[\"64493.9\",\"1.6\",\"0\",\"1\"],[\"64494.9\",\"0.07\",\"0\",\"3\"],[\"64496.1\",\"0.06\",\"0\",\"3\"],[\"64496.3\",\"428.72\",\"0\",\"6\"],[\"64496.6\",\"31.99\",\"0\",\"3\"],[\"64496.7\",\"247.01\",\"0\",\"4\"],[\"64497.1\",\"0.01\",\"0\",\"1\"],[\"64497.9\",\"0.01\",\"0\",\"1\"],[\"64498.2\",\"0.04\",\"0\",\"3\"],[\"64499.5\",\"1.55\",\"0\",\"1\"],[\"64500.4\",\"0.03\",\"0\",\"3\"],[\"64500.9\",\"75.65\",\"0\",\"5\"],[\"64501.7\",\"0.55\",\"0\",\"4\"],[\"64503.8\",\"0.77\",\"0\",\"1\"],[\"64503.9\",\"15.65\",\"0\",\"1\"],[\"64504.9\",\"58.29\",\"0\",\"4\"],[\"64505.3\",\"88\",\"0\",\"5\"],[\"64505.9\",\"1.01\",\"0\",\"2\"],[\"64506.5\",\"16.72\",\"0\",\"3\"],[\"64511.6\",\"106.19\",\"0\",\"3\"],[\"64512.8\",\"0\",\"0\",\"0\"],[\"64525\",\"0\",\"0\",\"0\"],[\"64525.1\",\"0\",\"0\",\"0\"],[\"64525.2\",\"0\",\"0\",\"0\"]],\"bids\":[[\"64479.8\",\"489.72\",\"0\",\"29\"],[\"64478.3\",\"0.81\",\"0\",\"2\"],[\"64476.6\",\"0\",\"0\",\"0\"],[\"64476.5\",\"0\",\"0\",\"0\"],[\"64476.2\",\"94.24\",\"0\",\"4\"],[\"64475.5\",\"0\",\"0\",\"0\"],[\"64474.9\",\"20.32\",\"0\",\"3\"],[\"64474.3\",\"0.31\",\"0\",\"1\"],[\"64474\",\"0.01\",\"0\",\"1\"],[\"64473.8\",\"71.64\",\"0\",\"3\"],[\"64473.6\",\"0\",\"0\",\"0\"],[\"64473.3\",\"0.01\",\"0\",\"1\"],[\"64472.9\",\"94.7\",\"0\",\"1\"],[\"64472.4\",\"77.55\",\"0\",\"1\"],[\"64469.9\",\"32.59\",\"0\",\"3\"],[\"64467.7\",\"1.6\",\"0\",\"1\"],[\"64466.9\",\"35.67\",\"0\",\"3\"],[\"64465\",\"0\",\"0\",\"0\"],[\"64464.7\",\"0.77\",\"0\",\"1\"],[\"64464.4\",\"0.01\",\"0\",\"1\"],[\"64463.9\",\"0.31\",\"0\",\"1\"],[\"64462.9\",\"0\",\"0\",\"0\"],[\"64462.2\",\"0\",\"0\",\"0\"],[\"64461.7\",\"33.83\",\"0\",\"2\"],[\"64461.4\",\"86.2\",\"0\",\"4\"],[\"64461.2\",\"20.14\",\"0\",\"4\"],[\"64459.6\",\"85.4\",\"0\",\"1\"],[\"64459.2\",\"0.01\",\"0\",\"1\"],[\"64458.1\",\"31.05\",\"0\",\"1\"],[\"64457.5\",\"232.94\",\"0\",\"2\"],[\"64456.6\",\"58.31\",\"0\",\"3\"],[\"64454\",\"132.09\",\"0\",\"5\"],[\"64452.7\",\"323.59\",\"0\",\"5\"],[\"64452.6\",\"512.37\",\"0\",\"3\"],[\"64421.6\",\"15.65\",\"0\",\"1\"],[\"64421.5\",\"0.01\",\"0\",\"1\"]],\"ts\":\"1782016022605\",\"checksum\":-581057757,\"seqId\":325070065710,\"prevSeqId\":325070065473}]}"}
{"action": "update", "capture_sequence": 63, "channel": "books", "connection_sequence": 1, "event": null, "instId": "BTC-USDT-SWAP", "local_receive_ts": "2026-06-21T04:27:02Z", "monotonic_ns": 1643578609826805, "raw": "{\"arg\":{\"channel\":\"books\",\"instId\":\"BTC-USDT-SWAP\"},\"action\":\"update\",\"data\":[{\"asks\":[[\"64479.9\",\"699.45\",\"0\",\"48\"],[\"64480\",\"65.61\",\"0\",\"8\"],[\"64480.3\",\"0\",\"0\",\"0\"],[\"64480.7\",\"0.01\",\"0\",\"1\"],[\"64481.7\",\"0\",\"0\",\"0\"],[\"64483.2\",\"11.41\",\"0\",\"2\"],[\"64486.7\",\"0.01\",\"0\",\"1\"],[\"64488.9\",\"0.33\",\"0\",\"6\"],[\"64498.4\",\"0.01\",\"0\",\"1\"],[\"64499\",\"334.64\",\"0\",\"22\"],[\"64499.1\",\"0.16\",\"0\",\"4\"],[\"64499.5\",\"0\",\"0\",\"0\"],[\"64502.9\",\"281.27\",\"0\",\"7\"],[\"64503.8\",\"0\",\"0\",\"0\"],[\"64525\",\"2.51\",\"0\",\"18\"]],\"bids\":[[\"64479.8\",\"401.99\",\"0\",\"27\"],[\"64479.7\",\"0.6\",\"0\",\"3\"],[\"64479.6\",\"0.02\",\"0\",\"1\"],[\"64478.4\",\"0.01\",\"0\",\"1\"],[\"64476.3\",\"0.19\",\"0\",\"3\"],[\"64474.3\",\"0\",\"0\",\"0\"],[\"64474.2\",\"3.4\",\"0\",\"2\"],[\"64472.9\",\"0\",\"0\",\"0\"],[\"64472.4\",\"0\",\"0\",\"0\"],[\"64472.3\",\"7.2\",\"0\",\"2\"],[\"64472.2\",\"77.55\",\"0\",\"1\"],[\"64471.8\",\"0\",\"0\",\"0\"],[\"64471.6\",\"0\",\"0\",\"0\"],[\"64470.1\",\"31.05\",\"0\",\"1\"],[\"64469.9\",\"1.54\",\"0\",\"2\"],[\"64469.4\",\"46.56\",\"0\",\"2\"],[\"64464.7\",\"0\",\"0\",\"0\"],[\"64464.1\",\"2.76\",\"0\",\"1\"],[\"64463.9\",\"1.08\",\"0\",\"2\"],[\"64461.6\",\"1.04\",\"0\",\"3\"],[\"64461.2\",\"20.12\",\"0\",\"3\"],[\"64460.8\",\"312.1\",\"0\",\"8\"],[\"64457.9\",\"0.01\",\"0\",\"1\"],[\"64457.4\",\"11.2\",\"0\",\"2\"],[\"64456.9\",\"0.02\",\"0\",\"1\"],[\"64452.7\",\"323.57\",\"0\",\"4\"],[\"64452.5\",\"31.34\",\"0\",\"5\"],[\"64439\",\"0.01\",\"0\",\"1\"],[\"64437.5\",\"0.02\",\"0\",\"1\"],[\"64421.3\",\"0.03\",\"0\",\"2\"]],\"ts\":\"1782016022705\",\"checksum\":849980331,\"seqId\":325070065822,\"prevSeqId\":325070065710}]}"}
{"action": "update", "capture_sequence": 64, "channel": "books", "connection_sequence": 1, "event": null, "instId": "BTC-USDT-SWAP", "local_receive_ts": "2026-06-21T04:27:02Z", "monotonic_ns": 1643578708465512, "raw": "{\"arg\":{\"channel\":\"books\",\"instId\":\"BTC-USDT-SWAP\"},\"action\":\"update\",\"data\":[{\"asks\":[[\"64480\",\"65.62\",\"0\",\"9\"],[\"64503.9\",\"73.84\",\"0\",\"2\"],[\"64504\",\"254.55\",\"0\",\"9\"],[\"64504.9\",\"0.1\",\"0\",\"3\"],[\"64505\",\"0.82\",\"0\",\"3\"],[\"64520\",\"78.61\",\"0\",\"62\"],[\"64523.4\",\"21.46\",\"0\",\"3\"]],\"bids\":[[\"64479.8\",\"345.03\",\"0\",\"26\"],[\"64474.2\",\"3.09\",\"0\",\"1\"],[\"64474\",\"0.32\",\"0\",\"2\"],[\"64456.6\",\"0.08\",\"0\",\"2\"],[\"64456.1\",\"308.02\",\"0\",\"4\"]],\"ts\":\"1782016022805\",\"checksum\":1246672913,\"seqId\":325070065836,\"prevSeqId\":325070065822}]}"}
{"action": "update", "capture_sequence": 65, "channel": "books", "connection_sequence": 1, "event": null, "instId": "BTC-USDT-SWAP", "local_receive_ts": "2026-06-21T04:27:03Z", "monotonic_ns": 1643578808440765, "raw": "{\"arg\":{\"channel\":\"books\",\"instId\":\"BTC-USDT-SWAP\"},\"action\":\"update\",\"data\":[{\"asks\":[[\"64491.8\",\"0.05\",\"0\",\"1\"],[\"64511.6\",\"86.12\",\"0\",\"2\"],[\"64512\",\"22.95\",\"0\",\"14\"]],\"bids\":[[\"64479.7\",\"0.62\",\"0\",\"4\"],[\"64479.6\",\"3.58\",\"0\",\"2\"],[\"64476.3\",\"0.17\",\"0\",\"2\"],[\"64474.3\",\"0.31\",\"0\",\"1\"],[\"64474\",\"0.01\",\"0\",\"1\"],[\"64461.5\",\"20.1\",\"0\",\"3\"],[\"64461.2\",\"0.04\",\"0\",\"2\"],[\"64459\",\"0\",\"0\",\"0\"],[\"64452.6\",\"512.18\",\"0\",\"2\"]],\"ts\":\"1782016022905\",\"checksum\":-338437707,\"seqId\":325070065848,\"prevSeqId\":325070065836}]}"}
{"action": null, "capture_sequence": 66, "channel": "trades", "connection_sequence": 1, "event": null, "instId": "BTC-USDT-SWAP", "local_receive_ts": "2026-06-21T04:27:03Z", "monotonic_ns": 1643578861252383, "raw": "{\"arg\":{\"channel\":\"trades\",\"instId\":\"BTC-USDT-SWAP\"},\"data\":[{\"instId\":\"BTC-USDT-SWAP\",\"tradeId\":\"2718750143\",\"px\":\"64479.8\",\"sz\":\"1\",\"side\":\"sell\",\"ts\":\"1782016022958\",\"count\":\"3\",\"source\":\"0\",\"seqId\":325070065865}]}"}
{"action": "update", "capture_sequence": 67, "channel": "books", "connection_sequence": 1, "event": null, "instId": "BTC-USDT-SWAP", "local_receive_ts": "2026-06-21T04:27:03Z", "monotonic_ns": 1643578908936504, "raw": "{\"arg\":{\"channel\":\"books\",\"instId\":\"BTC-USDT-SWAP\"},\"action\":\"update\",\"data\":[{\"asks\":[[\"64479.9\",\"701.01\",\"0\",\"49\"],[\"64491.8\",\"0.2\",\"0\",\"2\"],[\"64496.7\",\"14.22\",\"0\",\"3\"],[\"64497.2\",\"233.63\",\"0\",\"4\"]],\"bids\":[[\"64479.8\",\"344.04\",\"0\",\"25\"],[\"64460.8\",\"377.94\",\"0\",\"9\"],[\"64459\",\"3.23\",\"0\",\"1\"],[\"64458.2\",\"232.93\",\"0\",\"1\"],[\"64457.5\",\"0.01\",\"0\",\"1\"],[\"64452.7\",\"323.76\",\"0\",\"5\"],[\"64421.5\",\"0\",\"0\",\"0\"],[\"64421.3\",\"0\",\"0\",\"0\"]],\"ts\":\"1782016023005\",\"checksum\":-649433992,\"seqId\":325070065882,\"prevSeqId\":325070065848}]}"}
{"action": "update", "capture_sequence": 68, "channel": "books", "connection_sequence": 1, "event": null, "instId": "BTC-USDT-SWAP", "local_receive_ts": "2026-06-21T04:27:03Z", "monotonic_ns": 1643579008725438, "raw": "{\"arg\":{\"channel\":\"books\",\"instId\":\"BTC-USDT-SWAP\"},\"action\":\"update\",\"data\":[{\"asks\":[[\"64479.9\",\"703.21\",\"0\",\"49\"],[\"64481.5\",\"0.52\",\"0\",\"2\"],[\"64483.6\",\"0\",\"0\",\"0\"],[\"64505.3\",\"2.66\",\"0\",\"4\"],[\"64505.8\",\"85.42\",\"0\",\"2\"],[\"64525.1\",\"0.46\",\"0\",\"1\"]],\"bids\":[[\"64460.2\",\"85.4\",\"0\",\"1\"],[\"64459.6\",\"0\",\"0\",\"0\"]],\"ts\":\"1782016023105\",\"checksum\":2030055597,\"seqId\":325070065916,\"prevSeqId\":325070065882}]}"}
{"action": "update", "capture_sequence": 69, "channel": "books", "connection_sequence": 1, "event": null, "instId": "BTC-USDT-SWAP", "local_receive_ts": "2026-06-21T04:27:03Z", "monotonic_ns": 1643579108713729, "raw": "{\"arg\":{\"channel\":\"books\",\"instId\":\"BTC-USDT-SWAP\"},\"action\":\"update\",\"data\":[{\"asks\":[[\"64491.8\",\"0.05\",\"0\",\"1\"],[\"64491.9\",\"0.45\",\"0\",\"5\"],[\"64492.3\",\"0.53\",\"0\",\"2\"],[\"64510.4\",\"0.03\",\"0\",\"3\"],[\"64512\",\"2.88\",\"0\",\"13\"],[\"64512.5\",\"20.23\",\"0\",\"6\"]],\"bids\":[[\"64461.8\",\"20.08\",\"0\",\"1\"],[\"64461.5\",\"0.02\",\"0\",\"2\"],[\"64459\",\"0\",\"0\",\"0\"],[\"64458.9\",\"3.2\",\"0\",\"2\"],[\"64452.7\",\"323.57\",\"0\",\"4\"],[\"64452.5\",\"31.53\",\"0\",\"6\"]],\"ts\":\"1782016023205\",\"checksum\":2030055597,\"seqId\":325070065945,\"prevSeqId\":325070065916}]}"}
{"action": "update", "capture_sequence": 70, "channel": "books", "connection_sequence": 1, "event": null, "instId": "BTC-USDT-SWAP", "local_receive_ts": "2026-06-21T04:27:03Z", "monotonic_ns": 1643579208635870, "raw": "{\"arg\":{\"channel\":\"books\",\"instId\":\"BTC-USDT-SWAP\"},\"action\":\"update\",\"data\":[{\"asks\":[[\"64496.3\",\"429.03\",\"0\",\"7\"],[\"64496.6\",\"31.68\",\"0\",\"2\"]],\"bids\":[[\"64479.8\",\"343.69\",\"0\",\"25\"],[\"64474.5\",\"0.31\",\"0\",\"1\"],[\"64474.3\",\"0\",\"0\",\"0\"]],\"ts\":\"1782016023305\",\"checksum\":-868051132,\"seqId\":325070065955,\"prevSeqId\":325070065945}]}"}
{"action": null, "capture_sequence": 71, "channel": "trades", "connection_sequence": 1, "event": null, "instId": "BTC-USDT-SWAP", "local_receive_ts": "2026-06-21T04:27:03Z", "monotonic_ns": 1643579228385926, "raw": "{\"arg\":{\"channel\":\"trades\",\"instId\":\"BTC-USDT-SWAP\"},\"data\":[{\"instId\":\"BTC-USDT-SWAP\",\"tradeId\":\"2718750144\",\"px\":\"64479.8\",\"sz\":\"0.06\",\"side\":\"sell\",\"ts\":\"1782016023324\",\"count\":\"1\",\"source\":\"0\",\"seqId\":325070065963}]}"}
{"action": "update", "capture_sequence": 72, "channel": "books", "connection_sequence": 1, "event": null, "instId": "BTC-USDT-SWAP", "local_receive_ts": "2026-06-21T04:27:03Z", "monotonic_ns": 1643579308837029, "raw": "{\"arg\":{\"channel\":\"books\",\"instId\":\"BTC-USDT-SWAP\"},\"action\":\"update\",\"data\":[{\"asks\":[[\"64479.9\",\"707.71\",\"0\",\"50\"],[\"64481.5\",\"0.02\",\"0\",\"1\"],[\"64493.8\",\"0.03\",\"0\",\"2\"],[\"64493.9\",\"17.12\",\"0\",\"2\"],[\"64496.3\",\"397.69\",\"0\",\"5\"],[\"64496.7\",\"45.56\",\"0\",\"5\"],[\"64503.4\",\"58.19\",\"0\",\"1\"],[\"64503.9\",\"15.65\",\"0\",\"1\"],[\"64505.1\",\"85.36\",\"0\",\"3\"],[\"64505.8\",\"0.08\",\"0\",\"1\"],[\"64513.3\",\"1.12\",\"0\",\"8\"],[\"64525.1\",\"0\",\"0\",\"0\"]],\"bids\":[[\"64479.8\",\"343.63\",\"0\",\"25\"],[\"64476.8\",\"3.09\",\"0\",\"1\"],[\"64476.5\",\"3.09\",\"0\",\"1\"],[\"64474.8\",\"0.01\",\"0\",\"1\"],[\"64474.5\",\"0\",\"0\",\"0\"],[\"64474.2\",\"0.31\",\"0\",\"1\"],[\"64468.7\",\"84.75\",\"0\",\"7\"],[\"64468.6\",\"0\",\"0\",\"0\"],[\"64468.5\",\"0\",\"0\",\"0\"],[\"64464.3\",\"2.47\",\"0\",\"2\"],[\"64463.9\",\"0.77\",\"0\",\"1\"],[\"64460.2\",\"0\",\"0\",\"0\"],[\"64459.6\",\"85.4\",\"0\",\"1\"],[\"64458.8\",\"31.05\",\"0\",\"1\"],[\"64458.1\",\"0\",\"0\",\"0\"],[\"64456.1\",\"249.79\",\"0\",\"3\"],[\"64455.4\",\"58.23\",\"0\",\"1\"]],\"ts\":\"1782016023405\",\"checksum\":-477955623,\"seqId\":325070066001,\"prevSeqId\":325070065955}]}"}
{"action": null, "capture_sequence": 73, "channel": "trades", "connection_sequence": 1, "event": null, "instId": "BTC-USDT-SWAP", "local_receive_ts": "2026-06-21T04:27:03Z", "monotonic_ns": 1643579352170352, "raw": "{\"arg\":{\"channel\":\"trades\",\"instId\":\"BTC-USDT-SWAP\"},\"data\":[{\"instId\":\"BTC-USDT-SWAP\",\"tradeId\":\"2718750147\",\"px\":\"64479.8\",\"sz\":\"99.7\",\"side\":\"sell\",\"ts\":\"1782016023449\",\"count\":\"3\",\"source\":\"0\",\"seqId\":325070066020}]}"}
{"action": "update", "capture_sequence": 74, "channel": "books", "connection_sequence": 1, "event": null, "instId": "BTC-USDT-SWAP", "local_receive_ts": "2026-06-21T04:27:03Z", "monotonic_ns": 1643579413671300, "raw": "{\"arg\":{\"channel\":\"books\",\"instId\":\"BTC-USDT-SWAP\"},\"action\":\"update\",\"data\":[{\"asks\":[[\"64479.9\",\"707.72\",\"0\",\"51\"],[\"64493.8\",\"15.55\",\"0\",\"3\"],[\"64493.9\",\"1.6\",\"0\",\"1\"],[\"64496.2\",\"31.04\",\"0\",\"2\"],[\"64496.5\",\"0.33\",\"0\",\"3\"],[\"64496.7\",\"247.01\",\"0\",\"4\"],[\"64497.2\",\"0.84\",\"0\",\"3\"],[\"64498.7\",\"4.41\",\"0\",\"5\"],[\"64499\",\"333.09\",\"0\",\"21\"],[\"64500.9\",\"41.86\",\"0\",\"4\"],[\"64501\",\"34.06\",\"0\",\"4\"],[\"64502.7\",\"58.22\",\"0\",\"4\"],[\"64503.4\",\"0\",\"0\",\"0\"],[\"64505.1\",\"0.02\",\"0\",\"2\"],[\"64506\",\"95.41\",\"0\",\"6\"],[\"64525.1\",\"0.46\",\"0\",\"1\"]],\"bids\":[[\"64479.8\",\"243.88\",\"0\",\"23\"],[\"64479.7\",\"0.6\",\"0\",\"3\"],[\"64479.6\",\"4.21\",\"0\",\"2\"],[\"64477.8\",\"0\",\"0\",\"0\"],[\"64476.9\",\"0.04\",\"0\",\"3\"],[\"64475.7\",\"0\",\"0\",\"0\"],[\"64475.3\",\"2\",\"0\",\"1\"],[\"64474.9\",\"20.31\",\"0\",\"2\"],[\"64474.2\",\"0\",\"0\",\"0\"],[\"64473.9\",\"46.87\",\"0\",\"4\"],[\"64472.2\",\"0\",\"0\",\"0\"],[\"64472.1\",\"6.24\",\"0\",\"3\"],[\"64471.8\",\"77.55\",\"0\",\"1\"],[\"64470.1\",\"68.28\",\"0\",\"4\"],[\"64469.4\",\"46.54\",\"0\",\"1\"],[\"64469.3\",\"496.55\",\"0\",\"2\"],[\"64468.4\",\"0\",\"0\",\"0\"],[\"64464.3\",\"2.16\",\"0\",\"1\"],[\"64463.9\",\"1.08\",\"0\",\"2\"],[\"64462.2\",\"33.82\",\"0\",\"1\"],[\"64461.7\",\"0.01\",\"0\",\"1\"],[\"64461.6\",\"0.02\",\"0\",\"1\"],[\"64461.2\",\"0.06\",\"0\",\"3\"],[\"64460.8\",\"274.87\",\"0\",\"5\"],[\"64460.6\",\"85.56\",\"0\",\"3\"],[\"64459.6\",\"0\",\"0\",\"0\"],[\"64458.8\",\"0\",\"0\",\"0\"],[\"64458.3\",\"31.08\",\"0\",\"4\"],[\"64458.2\",\"0\",\"0\",\"0\"],[\"64457.5\",\"232.94\",\"0\",\"2\"],[\"64455.4\",\"0\",\"0\",\"0\"],[\"64454.5\",\"58.23\",\"0\",\"1\"],[\"64437.5\",\"0\",\"0\",\"0\"],[\"64435.8\",\"247.28\",\"0\",\"5\"],[\"64421.5\",\"0.01\",\"0\",\"1\"],[\"64421.3\",\"0.03\",\"0\",\"2\"],[\"64421.2\",\"0.01\",\"0\",\"1\"],[\"64421.1\",\"1.53\",\"0\",\"3\"],[\"64420.9\",\"0.01\",\"0\",\"1\"],[\"64420.7\",\"0.03\",\"0\",\"1\"]],\"ts\":\"1782016023505\",\"checksum\":627911961,\"seqId\":325070066083,\"prevSeqId\":325070066001}]}"}
{"action": "update", "capture_sequence": 75, "channel": "books", "connection_sequence": 1, "event": null, "instId": "BTC-USDT-SWAP", "local_receive_ts": "2026-06-21T04:27:03Z", "monotonic_ns": 1643579508969470, "raw": "{\"arg\":{\"channel\":\"books\",\"instId\":\"BTC-USDT-SWAP\"},\"action\":\"update\",\"data\":[{\"asks\":[[\"64479.9\",\"708.22\",\"0\",\"52\"],[\"64480\",\"50.1\",\"0\",\"8\"],[\"64480.6\",\"15.53\",\"0\",\"2\"],[\"64480.7\",\"0\",\"0\",\"0\"],[\"64480.8\",\"0\",\"0\",\"0\"],[\"64481\",\"51.4\",\"0\",\"4\"],[\"64498.1\",\"0.04\",\"0\",\"4\"],[\"64498.4\",\"0\",\"0\",\"0\"],[\"64505.4\",\"144.57\",\"0\",\"5\"],[\"64506\",\"10.07\",\"0\",\"5\"],[\"64513\",\"12.65\",\"0\",\"4\"],[\"64513.3\",\"1.97\",\"0\",\"9\"],[\"64525.2\",\"55.22\",\"0\",\"2\"],[\"64525.3\",\"0.01\",\"0\",\"1\"],[\"64525.4\",\"11.4\",\"0\",\"1\"]],\"bids\":[[\"64479.7\",\"0.62\",\"0\",\"4\"],[\"64477.9\",\"0\",\"0\",\"0\"],[\"64476.9\",\"0.03\",\"0\",\"3\"],[\"64476.6\",\"0.01\",\"0\",\"1\"],[\"64475.8\",\"37.24\",\"0\",\"2\"],[\"64475.4\",\"0.03\",\"0\",\"3\"],[\"64461.6\",\"0\",\"0\",\"0\"],[\"64461.2\",\"0.08\",\"0\",\"4\"],[\"64460.7\",\"44.95\",\"0\",\"2\"],[\"64460.6\",\"0.16\",\"0\",\"2\"],[\"64459.6\",\"85.4\",\"0\",\"1\"],[\"64459.5\",\"15.67\",\"0\",\"2\"],[\"64457.4\",\"11.18\",\"0\",\"1\"],[\"64457\",\"743.17\",\"0\",\"6\"]],\"ts\":\"1782016023605\",\"checksum\":1996015382,\"seqId\":325070066125,\"prevSeqId\":325070066083}]}"}
{"action": "update", "capture_sequence": 76, "channel": "books", "connection_sequence": 1, "event": null, "instId": "BTC-USDT-SWAP", "local_receive_ts": "2026-06-21T04:27:03Z", "monotonic_ns": 1643579608580949, "raw": "{\"arg\":{\"channel\":\"books\",\"instId\":\"BTC-USDT-SWAP\"},\"action\":\"update\",\"data\":[{\"asks\":[[\"64480.1\",\"0.02\",\"0\",\"2\"],[\"64480.2\",\"15.52\",\"0\",\"1\"],[\"64480.6\",\"0.01\",\"0\",\"1\"],[\"64482.1\",\"0.02\",\"0\",\"2\"],[\"64513\",\"10.37\",\"0\",\"3\"],[\"64525.4\",\"0\",\"0\",\"0\"]],\"bids\":[[\"64431.9\",\"517.46\",\"0\",\"2\"],[\"64428.3\",\"0\",\"0\",\"0\"],[\"64428.2\",\"16.03\",\"0\",\"2\"],[\"64420.6\",\"116.12\",\"0\",\"2\"]],\"ts\":\"1782016023705\",\"checksum\":988706381,\"seqId\":325070066140,\"prevSeqId\":325070066125}]}"}
{"action": null, "capture_sequence": 77, "channel": "trades", "connection_sequence": 1, "event": null, "instId": "BTC-USDT-SWAP", "local_receive_ts": "2026-06-21T04:27:03Z", "monotonic_ns": 1643579663495931, "raw": "{\"arg\":{\"channel\":\"trades\",\"instId\":\"BTC-USDT-SWAP\"},\"data\":[{\"instId\":\"BTC-USDT-SWAP\",\"tradeId\":\"2718750148\",\"px\":\"64479.9\",\"sz\":\"0.01\",\"side\":\"buy\",\"ts\":\"1782016023760\",\"count\":\"1\",\"source\":\"0\",\"seqId\":325070066164}]}"}
{"action": "update", "capture_sequence": 78, "channel": "books", "connection_sequence": 1, "event": null, "instId": "BTC-USDT-SWAP", "local_receive_ts": "2026-06-21T04:27:03Z", "monotonic_ns": 1643579708733787, "raw": "{\"arg\":{\"channel\":\"books\",\"instId\":\"BTC-USDT-SWAP\"},\"action\":\"update\",\"data\":[{\"asks\":[[\"64479.9\",\"708.21\",\"0\",\"52\"],[\"64491.9\",\"0.3\",\"0\",\"4\"],[\"64511.6\",\"106.19\",\"0\",\"3\"],[\"64512.5\",\"0.16\",\"0\",\"5\"]],\"bids\":[[\"64478\",\"0\",\"0\",\"0\"],[\"64461.8\",\"0\",\"0\",\"0\"],[\"64461.2\",\"20.16\",\"0\",\"5\"],[\"64458.9\",\"0.01\",\"0\",\"1\"],[\"64452.5\",\"31.34\",\"0\",\"5\"],[\"64438\",\"0.01\",\"0\",\"1\"],[\"64420.5\",\"0.02\",\"0\",\"2\"]],\"ts\":\"1782016023805\",\"checksum\":391678152,\"seqId\":325070066168,\"prevSeqId\":325070066140}]}"}
{"action": null, "capture_sequence": 79, "channel": "trades", "connection_sequence": 1, "event": null, "instId": "BTC-USDT-SWAP", "local_receive_ts": "2026-06-21T04:27:04Z", "monotonic_ns": 1643579800527594, "raw": "{\"arg\":{\"channel\":\"trades\",\"instId\":\"BTC-USDT-SWAP\"},\"data\":[{\"instId\":\"BTC-USDT-SWAP\",\"tradeId\":\"2718750149\",\"px\":\"64479.8\",\"sz\":\"2\",\"side\":\"sell\",\"ts\":\"1782016023897\",\"count\":\"1\",\"source\":\"0\",\"seqId\":325070066198}]}"}
{"action": "update", "capture_sequence": 80, "channel": "books", "connection_sequence": 1, "event": null, "instId": "BTC-USDT-SWAP", "local_receive_ts": "2026-06-21T04:27:04Z", "monotonic_ns": 1643579808710970, "raw": "{\"arg\":{\"channel\":\"books\",\"instId\":\"BTC-USDT-SWAP\"},\"action\":\"update\",\"data\":[{\"asks\":[[\"64492\",\"0.19\",\"0\",\"5\"],[\"64502.4\",\"0.96\",\"0\",\"7\"],[\"64502.9\",\"280.5\",\"0\",\"6\"],[\"64505.8\",\"2.36\",\"0\",\"2\"]],\"bids\":[[\"64479.8\",\"241.88\",\"0\",\"23\"],[\"64470.9\",\"1.57\",\"0\",\"2\"],[\"64470.4\",\"1.56\",\"0\",\"1\"],[\"64463.9\",\"0.31\",\"0\",\"1\"],[\"64463.4\",\"0.77\",\"0\",\"1\"],[\"64458.9\",\"3.2\",\"0\",\"2\"],[\"64452.6\",\"512.37\",\"0\",\"3\"],[\"64420.6\",\"0\",\"0\",\"0\"],[\"64420.5\",\"0\",\"0\",\"0\"]],\"ts\":\"1782016023905\",\"checksum\":-1986464898,\"seqId\":325070066200,\"prevSeqId\":325070066168}]}"}
{"action": "update", "capture_sequence": 81, "channel": "books", "connection_sequence": 1, "event": null, "instId": "BTC-USDT-SWAP", "local_receive_ts": "2026-06-21T04:27:04Z", "monotonic_ns": 1643579909081620, "raw": "{\"arg\":{\"channel\":\"books\",\"instId\":\"BTC-USDT-SWAP\"},\"action\":\"update\",\"data\":[{\"asks\":[[\"64479.9\",\"708.31\",\"0\",\"53\"],[\"64492.3\",\"4.53\",\"0\",\"2\"],[\"64498.7\",\"2.86\",\"0\",\"4\"],[\"64498.8\",\"7.79\",\"0\",\"4\"],[\"64499.6\",\"63.37\",\"0\",\"3\"],[\"64500.4\",\"33.83\",\"0\",\"4\"],[\"64501\",\"0.27\",\"0\",\"3\"],[\"64502.7\",\"0.03\",\"0\",\"3\"],[\"64503.1\",\"97.88\",\"0\",\"9\"],[\"64505.1\",\"85.36\",\"0\",\"3\"],[\"64505.4\",\"59.23\",\"0\",\"4\"],[\"64511.4\",\"35.85\",\"0\",\"5\"],[\"64511.6\",\"86.12\",\"0\",\"2\"]],\"bids\":[[\"64472.1\",\"83.79\",\"0\",\"4\"],[\"64471.8\",\"0\",\"0\",\"0\"],[\"64470.9\",\"0.01\",\"0\",\"1\"],[\"64470.4\",\"0\",\"0\",\"0\"],[\"64470.2\",\"31.05\",\"0\",\"1\"],[\"64470.1\",\"37.23\",\"0\",\"3\"],[\"64462.2\",\"0\",\"0\",\"0\"],[\"64461.6\",\"33.82\",\"0\",\"1\"],[\"64461.2\",\"0.08\",\"0\",\"4\"],[\"64461\",\"20.08\",\"0\",\"1\"],[\"64458.3\",\"0.03\",\"0\",\"3\"],[\"64458.1\",\"31.05\",\"0\",\"1\"],[\"64455.3\",\"69.13\",\"0\",\"3\"],[\"64454.5\",\"0\",\"0\",\"0\"],[\"64434.4\",\"18.88\",\"0\",\"2\"]],\"ts\":\"1782016024005\",\"checksum\":-1971544794,\"seqId\":325070066259,\"prevSeqId\":325070066200}]}"}
{"action": "update", "capture_sequence": 82, "channel": "books", "connection_sequence": 1, "event": null, "instId": "BTC-USDT-SWAP", "local_receive_ts": "2026-06-21T04:27:04Z", "monotonic_ns": 1643580008728000, "raw": "{\"arg\":{\"channel\":\"books\",\"instId\":\"BTC-USDT-SWAP\"},\"action\":\"update\",\"data\":[{\"asks\":[[\"64502.2\",\"0.88\",\"0\",\"4\"],[\"64502.4\",\"0.19\",\"0\",\"6\"]],\"bids\":[[\"64474\",\"0.32\",\"0\",\"2\"],[\"64473.9\",\"46.56\",\"0\",\"3\"],[\"64470.3\",\"1.55\",\"0\",\"3\"],[\"64469.9\",\"0\",\"0\",\"0\"],[\"64461.4\",\"0.03\",\"0\",\"3\"],[\"64461\",\"106.26\",\"0\",\"2\"],[\"64455.3\",\"10.9\",\"0\",\"2\"],[\"64455.1\",\"58.23\",\"0\",\"1\"],[\"64452.5\",\"31.32\",\"0\",\"4\"],[\"64451.7\",\"271.9\",\"0\",\"6\"]],\"ts\":\"1782016024105\",\"checksum\":-1971544794,\"seqId\":325070066281,\"prevSeqId\":325070066259}]}"}
{"action": null, "capture_sequence": 83, "channel": "trades", "connection_sequence": 1, "event": null, "instId": "BTC-USDT-SWAP", "local_receive_ts": "2026-06-21T04:27:04Z", "monotonic_ns": 1643580074380162, "raw": "{\"arg\":{\"channel\":\"trades\",\"instId\":\"BTC-USDT-SWAP\"},\"data\":[{\"instId\":\"BTC-USDT-SWAP\",\"tradeId\":\"2718750150\",\"px\":\"64479.9\",\"sz\":\"0.02\",\"side\":\"buy\",\"ts\":\"1782016024171\",\"count\":\"1\",\"source\":\"0\",\"seqId\":325070066292}]}"}
{"action": "update", "capture_sequence": 84, "channel": "books", "connection_sequence": 1, "event": null, "instId": "BTC-USDT-SWAP", "local_receive_ts": "2026-06-21T04:27:04Z", "monotonic_ns": 1643580108444861, "raw": "{\"arg\":{\"channel\":\"books\",\"instId\":\"BTC-USDT-SWAP\"},\"action\":\"update\",\"data\":[{\"asks\":[[\"64479.9\",\"708.29\",\"0\",\"53\"]],\"bids\":[[\"64461.6\",\"0\",\"0\",\"0\"],[\"64461.4\",\"120.03\",\"0\",\"5\"],[\"64461\",\"20.08\",\"0\",\"1\"],[\"64420.6\",\"116.12\",\"0\",\"2\"]],\"ts\":\"1782016024205\",\"checksum\":1885953453,\"seqId\":325070066298,\"prevSeqId\":325070066281}]}"}
{"action": "update", "capture_sequence": 85, "channel": "books", "connection_sequence": 1, "event": null, "instId": "BTC-USDT-SWAP", "local_receive_ts": "2026-06-21T04:27:04Z", "monotonic_ns": 1643580208659904, "raw": "{\"arg\":{\"channel\":\"books\",\"instId\":\"BTC-USDT-SWAP\"},\"action\":\"update\",\"data\":[{\"asks\":[[\"64486.8\",\"0.19\",\"0\",\"3\"],[\"64498.1\",\"0.03\",\"0\",\"3\"],[\"64498.4\",\"0.01\",\"0\",\"1\"],[\"64509.4\",\"69.18\",\"0\",\"1\"],[\"64511.4\",\"15.78\",\"0\",\"4\"],[\"64511.6\",\"0.01\",\"0\",\"1\"],[\"64511.7\",\"20.09\",\"0\",\"3\"],[\"64512.6\",\"144.35\",\"0\",\"7\"],[\"64525.3\",\"0\",\"0\",\"0\"]],\"bids\":[[\"64474.1\",\"0.32\",\"0\",\"2\"],[\"64474\",\"0.01\",\"0\",\"1\"],[\"64473.2\",\"1.57\",\"0\",\"2\"],[\"64472.7\",\"1.58\",\"0\",\"3\"],[\"64472.2\",\"1.56\",\"0\",\"1\"],[\"64471.7\",\"32.18\",\"0\",\"2\"],[\"64471.2\",\"1.56\",\"0\",\"1\"],[\"64470.8\",\"1.56\",\"0\",\"1\"],[\"64470.3\",\"3.11\",\"0\",\"4\"],[\"64461.5\",\"33.84\",\"0\",\"3\"],[\"64461.4\",\"86.21\",\"0\",\"4\"],[\"64459\",\"3.21\",\"0\",\"1\"],[\"64458.9\",\"0.01\",\"0\",\"1\"],[\"64421.1\",\"0\",\"0\",\"0\"],[\"64420.9\",\"0\",\"0\",\"0\"],[\"64420.7\",\"0\",\"0\",\"0\"],[\"64420.6\",\"0\",\"0\",\"0\"]],\"ts\":\"1782016024305\",\"checksum\":1885953453,\"seqId\":325070066364,\"prevSeqId\":325070066298}]}"}
{"action": "update", "capture_sequence": 86, "channel": "books", "connection_sequence": 1, "event": null, "instId": "BTC-USDT-SWAP", "local_receive_ts": "2026-06-21T04:27:04Z", "monotonic_ns": 1643580314835459, "raw": "{\"arg\":{\"channel\":\"books\",\"instId\":\"BTC-USDT-SWAP\"},\"action\":\"update\",\"data\":[{\"asks\":[[\"64502.4\",\"58.38\",\"0\",\"7\"],[\"64503.1\",\"39.69\",\"0\",\"8\"],[\"64516.6\",\"208.86\",\"0\",\"3\"]],\"bids\":[[\"64479.8\",\"241.89\",\"0\",\"23\"],[\"64475.2\",\"1.56\",\"0\",\"1\"],[\"64474.1\",\"1.88\",\"0\",\"3\"],[\"64473.6\",\"1.56\",\"0\",\"1\"],[\"64473.2\",\"0.01\",\"0\",\"1\"],[\"64472.9\",\"1.56\",\"0\",\"1\"],[\"64472.7\",\"0.02\",\"0\",\"2\"],[\"64455.1\",\"0\",\"0\",\"0\"],[\"64454.5\",\"58.23\",\"0\",\"1\"],[\"64421.5\",\"0\",\"0\",\"0\"],[\"64421.3\",\"0\",\"0\",\"0\"],[\"64421.2\",\"0\",\"0\",\"0\"]],\"ts\":\"1782016024405\",\"checksum\":-919487793,\"seqId\":325070066401,\"prevSeqId\":325070066364}]}"}
{"action": null, "capture_sequence": 87, "channel": "trades", "connection_sequence": 1, "event": null, "instId": "BTC-USDT-SWAP", "local_receive_ts": "2026-06-21T04:27:04Z", "monotonic_ns": 1643580366376517, "raw": "{\"arg\":{\"channel\":\"trades\",\"instId\":\"BTC-USDT-SWAP\"},\"data\":[{\"instId\":\"BTC-USDT-SWAP\",\"tradeId\":\"2718750151\",\"px\":\"64479.8\",\"sz\":\"0.06\",\"side\":\"sell\",\"ts\":\"1782016024463\",\"count\":\"1\",\"source\":\"0\",\"seqId\":325070066790}]}"}
{"action": null, "capture_sequence": 88, "channel": "trades", "connection_sequence": 1, "event": null, "instId": "BTC-USDT-SWAP", "local_receive_ts": "2026-06-21T04:27:04Z", "monotonic_ns": 1643580367191756, "raw": "{\"arg\":{\"channel\":\"trades\",\"instId\":\"BTC-USDT-SWAP\"},\"data\":[{\"instId\":\"BTC-USDT-SWAP\",\"tradeId\":\"2718750152\",\"px\":\"64479.8\",\"sz\":\"1.07\",\"side\":\"sell\",\"ts\":\"1782016024464\",\"count\":\"1\",\"source\":\"0\",\"seqId\":325070066796}]}"}
{"action": "update", "capture_sequence": 89, "channel": "books", "connection_sequence": 1, "event": null, "instId": "BTC-USDT-SWAP", "local_receive_ts": "2026-06-21T04:27:04Z", "monotonic_ns": 1643580423656210, "raw": "{\"arg\":{\"channel\":\"books\",\"instId\":\"BTC-USDT-SWAP\"},\"action\":\"update\",\"data\":[{\"asks\":[[\"64479.9\",\"210.66\",\"0\",\"28\"],[\"64480.1\",\"0.01\",\"0\",\"1\"],[\"64480.2\",\"0\",\"0\",\"0\"],[\"64480.9\",\"0\",\"0\",\"0\"],[\"64481\",\"0.01\",\"0\",\"1\"],[\"64481.1\",\"0\",\"0\",\"0\"],[\"64481.2\",\"0.01\",\"0\",\"1\"],[\"64482\",\"0.06\",\"0\",\"4\"],[\"64482.1\",\"120.25\",\"0\",\"4\"],[\"64482.2\",\"8.25\",\"0\",\"2\"],[\"64482.8\",\"0.02\",\"0\",\"2\"],[\"64482.9\",\"1.57\",\"0\",\"2\"],[\"64483\",\"10.01\",\"0\",\"2\"],[\"64483.1\",\"0.63\",\"0\",\"4\"],[\"64483.2\",\"0\",\"0\",\"0\"],[\"64483.3\",\"0.06\",\"0\",\"3\"],[\"64483.6\",\"0.01\",\"0\",\"1\"],[\"64483.7\",\"2.57\",\"0\",\"3\"],[\"64483.9\",\"21.62\",\"0\",\"4\"],[\"64484\",\"116.76\",\"0\",\"5\"],[\"64484.2\",\"2.34\",\"0\",\"3\"],[\"64484.5\",\"0.06\",\"0\",\"3\"],[\"64484.6\",\"138.54\",\"0\",\"4\"],[\"64485\",\"41.95\",\"0\",\"2\"],[\"64485.6\",\"0\",\"0\",\"0\"],[\"64485.9\",\"22.44\",\"0\",\"3\"],[\"64486.1\",\"0\",\"0\",\"0\"],[\"64486.2\",\"1.73\",\"0\",\"7\"],[\"64486.6\",\"81.32\",\"0\",\"2\"],[\"64486.7\",\"0\",\"0\",\"0\"],[\"64488.5\",\"1.56\",\"0\",\"1\"],[\"64489\",\"20.66\",\"0\",\"9\"],[\"64489.6\",\"0.12\",\"0\",\"2\"],[\"64490.4\",\"8.03\",\"0\",\"4\"],[\"64491\",\"68.49\",\"0\",\"3\"],[\"64491.1\",\"0.01\",\"0\",\"1\"],[\"64492.4\",\"29.97\",\"0\",\"10\"],[\"64492.5\",\"93.49\",\"0\",\"4\"],[\"64493.2\",\"0.07\",\"0\",\"4\"],[\"64493.8\",\"0.03\",\"0\",\"2\"],[\"64493.9\",\"0\",\"0\",\"0\"],[\"64496\",\"105.83\",\"0\",\"7\"],[\"64496.2\",\"15.52\",\"0\",\"2\"],[\"64496.5\",\"0\",\"0\",\"0\"],[\"64496.7\",\"14.22\",\"0\",\"3\"],[\"64497.8\",\"4.01\",\"0\",\"2\"],[\"64498.1\",\"8.03\",\"0\",\"4\"],[\"64498.4\",\"0\",\"0\",\"0\"],[\"64498.6\",\"32.42\",\"0\",\"8\"],[\"64498.8\",\"6.24\",\"0\",\"3\"],[\"64499.4\",\"234.51\",\"0\",\"4\"],[\"64499.7\",\"35.69\",\"0\",\"7\"],[\"64499.8\",\"1.08\",\"0\",\"2\"],[\"64500.2\",\"0.02\",\"0\",\"2\"],[\"64500.3\",\"2.78\",\"0\",\"5\"],[\"64500.4\",\"0.03\",\"0\",\"3\"],[\"64502.2\",\"0.11\",\"0\",\"3\"],[\"64502.4\",\"1.74\",\"0\",\"7\"],[\"64502.5\",\"70.1\",\"0\",\"4\"],[\"64504\",\"54.55\",\"0\",\"8\"],[\"64505.1\",\"0.02\",\"0\",\"2\"],[\"64505.4\",\"60\",\"0\",\"5\"],[\"64505.7\",\"34.35\",\"0\",\"2\"],[\"64509.3\",\"143.8\",\"0\",\"7\"],[\"64510.7\",\"11.02\",\"0\",\"4\"],[\"64511.7\",\"0.02\",\"0\",\"2\"],[\"64512.6\",\"58.24\",\"0\",\"6\"],[\"64513.2\",\"0.15\",\"0\",\"4\"],[\"64515.4\",\"86.57\",\"0\",\"6\"],[\"64516.1\",\"0.04\",\"0\",\"4\"],[\"64516.6\",\"228.93\",\"0\",\"4\"],[\"64521.1\",\"0.01\",\"0\",\"1\"],[\"64522.1\",\"11.33\",\"0\",\"1\"],[\"64525.3\",\"0.01\",\"0\",\"1\"],[\"64525.4\",\"11.4\",\"0\",\"1\"],[\"64525.5\",\"0.02\",\"0\",\"1\"],[\"64525.6\",\"37.24\",\"0\",\"2\"],[\"64525.7\",\"0.03\",\"0\",\"1\"]],\"bids\":[[\"64479.8\",\"755.89\",\"0\",\"31\"],[\"64479.6\",\"6.08\",\"0\",\"3\"],[\"64479.2\",\"1.56\",\"0\",\"1\"],[\"64478.8\",\"0.01\",\"0\",\"1\"],[\"64478.6\",\"1.56\",\"0\",\"1\"],[\"64478.4\",\"0.77\",\"0\",\"1\"],[\"64478.3\",\"0.01\",\"0\",\"1\"],[\"64478.1\",\"1.56\",\"0\",\"1\"],[\"64478\",\"0.01\",\"0\",\"1\"],[\"64477.7\",\"0.33\",\"0\",\"3\"],[\"64477.6\",\"1.57\",\"0\",\"2\"],[\"64477\",\"1.56\",\"0\",\"1\"],[\"64476.5\",\"14.49\",\"0\",\"2\"],[\"64476.3\",\"1.73\",\"0\",\"3\"],[\"64476.2\",\"143.02\",\"0\",\"4\"],[\"64475.7\",\"1.56\",\"0\",\"1\"],[\"64475.4\",\"77.57\",\"0\",\"4\"],[\"64475.2\",\"0\",\"0\",\"0\"],[\"64474.9\",\"19.54\",\"0\",\"1\"],[\"64474.6\",\"1.56\",\"0\",\"1\"],[\"64474.4\",\"0.3\",\"0\",\"1\"],[\"64474.1\",\"1.57\",\"0\",\"2\"],[\"64473.9\",\"46.58\",\"0\",\"4\"],[\"64473.6\",\"248.53\",\"0\",\"4\"],[\"64473.2\",\"11.41\",\"0\",\"2\"],[\"64472.9\",\"0\",\"0\",\"0\"],[\"64472.7\",\"3.92\",\"0\",\"3\"],[\"64472.2\",\"0\",\"0\",\"0\"],[\"64472.1\",\"6.24\",\"0\",\"3\"],[\"64471.8\",\"1.7\",\"0\",\"1\"],[\"64471.7\",\"30.62\",\"0\",\"1\"],[\"64471.2\",\"0\",\"0\",\"0\"],[\"64470.8\",\"0\",\"0\",\"0\"],[\"64470.3\",\"0.01\",\"0\",\"1\"],[\"64470.2\",\"0\",\"0\",\"0\"],[\"64470.1\",\"0\",\"0\",\"0\"],[\"64469.9\",\"32.59\",\"0\",\"3\"],[\"64469.6\",\"24.42\",\"0\",\"4\"],[\"64469.3\",\"496.53\",\"0\",\"1\"],[\"64467.7\",\"0\",\"0\",\"0\"],[\"64467\",\"0.38\",\"0\",\"2\"],[\"64466.9\",\"167.7\",\"0\",\"5\"],[\"64466.6\",\"0.78\",\"0\",\"2\"],[\"64466.5\",\"135.96\",\"0\",\"3\"],[\"64466.1\",\"20.08\",\"0\",\"1\"],[\"64465.3\",\"48.2\",\"0\",\"6\"],[\"64463.9\",\"0\",\"0\",\"0\"],[\"64463.7\",\"85.42\",\"0\",\"2\"],[\"64463.4\",\"0\",\"0\",\"0\"],[\"64461.5\",\"0.02\",\"0\",\"2\"],[\"64461.4\",\"0.03\",\"0\",\"3\"],[\"64461.2\",\"0.06\",\"0\",\"3\"],[\"64461\",\"0\",\"0\",\"0\"],[\"64460.9\",\"132.73\",\"0\",\"5\"],[\"64460.8\",\"305.92\",\"0\",\"6\"],[\"64460.2\",\"232.92\",\"0\",\"1\"],[\"64459.6\",\"58.23\",\"0\",\"1\"],[\"64459.5\",\"15.65\",\"0\",\"1\"],[\"64459.3\",\"0.2\",\"0\",\"3\"],[\"64458.1\",\"0\",\"0\",\"0\"],[\"64457.5\",\"0.01\",\"0\",\"1\"],[\"64457\",\"743.15\",\"0\",\"5\"],[\"64456.9\",\"0\",\"0\",\"0\"],[\"64455.5\",\"31.32\",\"0\",\"3\"],[\"64454.8\",\"10\",\"0\",\"1\"],[\"64454.5\",\"0\",\"0\",\"0\"],[\"64454\",\"0.06\",\"0\",\"3\"],[\"64451.7\",\"271.88\",\"0\",\"5\"],[\"64445.9\",\"0\",\"0\",\"0\"],[\"64440\",\"3.46\",\"0\",\"18\"],[\"64438\",\"0\",\"0\",\"0\"],[\"64435.8\",\"247.26\",\"0\",\"4\"],[\"64434.4\",\"17.88\",\"0\",\"1\"],[\"64421.5\",\"0.01\",\"0\",\"1\"],[\"64421.3\",\"0.03\",\"0\",\"2\"],[\"64421.2\",\"0.01\",\"0\",\"1\"]],\"ts\":\"1782016024505\",\"checksum\":984442765,\"seqId\":325070067087,\"prevSeqId\":325070066401}]}"}
{"action": "update", "capture_sequence": 90, "channel": "books", "connection_sequence": 1, "event": null, "instId": "BTC-USDT-SWAP", "local_receive_ts": "2026-06-21T04:27:04Z", "monotonic_ns": 1643580513536827, "raw": "{\"arg\":{\"channel\":\"books\",\"instId\":\"BTC-USDT-SWAP\"},\"action\":\"update\",\"data\":[{\"asks\":[[\"64479.9\",\"267.66\",\"0\",\"30\"],[\"64480\",\"50.08\",\"0\",\"6\"],[\"64481.9\",\"0.02\",\"0\",\"2\"],[\"64482\",\"6.95\",\"0\",\"4\"],[\"64482.1\",\"0.03\",\"0\",\"3\"],[\"64482.5\",\"0.03\",\"0\",\"2\"],[\"64482.8\",\"0.01\",\"0\",\"1\"],[\"64482.9\",\"0.01\",\"0\",\"1\"],[\"64483.7\",\"127.43\",\"0\",\"4\"],[\"64483.8\",\"79.45\",\"0\",\"1\"],[\"64483.9\",\"0.02\",\"0\",\"2\"],[\"64484\",\"1.72\",\"0\",\"4\"],[\"64484.2\",\"1.57\",\"0\",\"2\"],[\"64484.6\",\"140.1\",\"0\",\"5\"],[\"64485.1\",\"2.76\",\"0\",\"2\"],[\"64489\",\"19.1\",\"0\",\"8\"],[\"64489.5\",\"16.75\",\"0\",\"4\"],[\"64489.6\",\"16.24\",\"0\",\"4\"],[\"64492\",\"0.04\",\"0\",\"4\"],[\"64492.5\",\"590.02\",\"0\",\"5\"],[\"64492.8\",\"167.42\",\"0\",\"12\"],[\"64496.6\",\"31.85\",\"0\",\"3\"],[\"64498.4\",\"31.03\",\"0\",\"1\"],[\"64498.6\",\"234.17\",\"0\",\"8\"],[\"64499.1\",\"0.17\",\"0\",\"5\"],[\"64499.4\",\"1.73\",\"0\",\"3\"],[\"64499.5\",\"0.32\",\"0\",\"2\"],[\"64499.7\",\"35.37\",\"0\",\"5\"],[\"64500.3\",\"2.77\",\"0\",\"4\"],[\"64501.6\",\"3.44\",\"0\",\"4\"],[\"64502.4\",\"0.19\",\"0\",\"6\"],[\"64504.1\",\"48.9\",\"0\",\"7\"],[\"64505.4\",\"59.23\",\"0\",\"4\"],[\"64505.7\",\"1.33\",\"0\",\"2\"],[\"64508.8\",\"442.95\",\"0\",\"4\"],[\"64509.2\",\"116.14\",\"0\",\"1\"],[\"64509.3\",\"58.46\",\"0\",\"6\"],[\"64509.4\",\"0\",\"0\",\"0\"],[\"64514.9\",\"516.68\",\"0\",\"5\"],[\"64515.4\",\"0.46\",\"0\",\"5\"],[\"64515.9\",\"134.04\",\"0\",\"5\"],[\"64516.6\",\"208.86\",\"0\",\"3\"],[\"64520\",\"78.62\",\"0\",\"63\"],[\"64521.1\",\"0\",\"0\",\"0\"],[\"64522\",\"5.18\",\"0\",\"10\"],[\"64525.6\",\"0\",\"0\",\"0\"],[\"64525.7\",\"0\",\"0\",\"0\"]],\"bids\":[[\"64479.8\",\"777.13\",\"0\",\"35\"],[\"64479.2\",\"0\",\"0\",\"0\"],[\"64478.9\",\"1.56\",\"0\",\"1\"],[\"64478.6\",\"0\",\"0\",\"0\"],[\"64478.4\",\"0\",\"0\",\"0\"],[\"64478.2\",\"1.57\",\"0\",\"2\"],[\"64478.1\",\"0\",\"0\",\"0\"],[\"64477.7\",\"0.02\",\"0\",\"2\"],[\"64476.8\",\"3.4\",\"0\",\"2\"],[\"64475.7\",\"3.56\",\"0\",\"2\"],[\"64475.4\",\"0.02\",\"0\",\"2\"],[\"64475.3\",\"0\",\"0\",\"0\"],[\"64475.2\",\"1.56\",\"0\",\"1\"],[\"64474.9\",\"0\",\"0\",\"0\"],[\"64474.7\",\"77.55\",\"0\",\"2\"],[\"64473.9\",\"46.56\",\"0\",\"3\"],[\"64473.6\",\"246.97\",\"0\",\"3\"],[\"64473.4\",\"0.02\",\"0\",\"1\"],[\"64470.1\",\"0.77\",\"0\",\"1\"],[\"64469.9\",\"31.82\",\"0\",\"2\"],[\"64467\",\"0.07\",\"0\",\"1\"],[\"64466.6\",\"1.09\",\"0\",\"3\"],[\"64466.5\",\"15.98\",\"0\",\"1\"],[\"64466.1\",\"0\",\"0\",\"0\"],[\"64466\",\"86.19\",\"0\",\"3\"],[\"64465.3\",\"48.16\",\"0\",\"4\"],[\"64465\",\"0.02\",\"0\",\"1\"],[\"64464.7\",\"33.81\",\"0\",\"1\"],[\"64464.4\",\"20.09\",\"0\",\"2\"],[\"64464.1\",\"2.78\",\"0\",\"2\"],[\"64463.7\",\"0\",\"0\",\"0\"],[\"64462.8\",\"85.4\",\"0\",\"1\"],[\"64461.6\",\"1\",\"0\",\"1\"],[\"64460.8\",\"332.6\",\"0\",\"6\"],[\"64460.7\",\"44.97\",\"0\",\"3\"],[\"64460.4\",\"31.05\",\"0\",\"1\"],[\"64460.2\",\"0\",\"0\",\"0\"],[\"64459.7\",\"232.93\",\"0\",\"2\"],[\"64459.3\",\"0.18\",\"0\",\"2\"],[\"64459\",\"0\",\"0\",\"0\"],[\"64457\",\"743.17\",\"0\",\"6\"],[\"64455.5\",\"31.3\",\"0\",\"2\"],[\"64452.6\",\"512.2\",\"0\",\"3\"],[\"64444.8\",\"13.11\",\"0\",\"3\"],[\"64440\",\"3.44\",\"0\",\"17\"],[\"64438.4\",\"0.03\",\"0\",\"2\"]],\"ts\":\"1782016024605\",\"checksum\":1675328798,\"seqId\":325070067467,\"prevSeqId\":325070067087}]}"}
{"action": "update", "capture_sequence": 91, "channel": "books", "connection_sequence": 1, "event": null, "instId": "BTC-USDT-SWAP", "local_receive_ts": "2026-06-21T04:27:04Z", "monotonic_ns": 1643580613092453, "raw": "{\"arg\":{\"channel\":\"books\",\"instId\":\"BTC-USDT-SWAP\"},\"action\":\"update\",\"data\":[{\"asks\":[[\"64479.9\",\"331.62\",\"0\",\"32\"],[\"64482.5\",\"0.02\",\"0\",\"1\"],[\"64482.9\",\"0.02\",\"0\",\"2\"],[\"64485.4\",\"15.52\",\"0\",\"1\"],[\"64485.9\",\"6.92\",\"0\",\"2\"],[\"64486.8\",\"0.96\",\"0\",\"4\"],[\"64492\",\"0.19\",\"0\",\"5\"],[\"64494.7\",\"24.22\",\"0\",\"6\"],[\"64496.6\",\"31.68\",\"0\",\"2\"],[\"64498.4\",\"0\",\"0\",\"0\"],[\"64498.6\",\"1.39\",\"0\",\"7\"],[\"64498.9\",\"80.99\",\"0\",\"4\"],[\"64499.5\",\"233.1\",\"0\",\"3\"],[\"64501.3\",\"1.57\",\"0\",\"2\"],[\"64501.6\",\"1.89\",\"0\",\"3\"],[\"64508.8\",\"357.61\",\"0\",\"3\"],[\"64509.5\",\"85.34\",\"0\",\"1\"],[\"64512\",\"202.88\",\"0\",\"14\"],[\"64514.9\",\"496.61\",\"0\",\"4\"],[\"64515.5\",\"95.53\",\"0\",\"8\"],[\"64525.5\",\"0\",\"0\",\"0\"]],\"bids\":[[\"64479.8\",\"775.57\",\"0\",\"34\"],[\"64479.6\",\"4.21\",\"0\",\"2\"],[\"64478.9\",\"0\",\"0\",\"0\"],[\"64478.3\",\"0.02\",\"0\",\"2\"],[\"64478.2\",\"0.01\",\"0\",\"1\"],[\"64477.6\",\"0.01\",\"0\",\"1\"],[\"64476.8\",\"3.09\",\"0\",\"1\"],[\"64476.3\",\"2.04\",\"0\",\"4\"],[\"64475\",\"0\",\"0\",\"0\"],[\"64474.7\",\"0.01\",\"0\",\"1\"],[\"64474.2\",\"77.54\",\"0\",\"1\"],[\"64465\",\"20.1\",\"0\",\"2\"],[\"64464.4\",\"0.01\",\"0\",\"1\"],[\"64463.4\",\"85.4\",\"0\",\"1\"],[\"64462.8\",\"0\",\"0\",\"0\"],[\"64461\",\"31.05\",\"0\",\"1\"],[\"64460.5\",\"234.42\",\"0\",\"2\"],[\"64460.4\",\"0\",\"0\",\"0\"],[\"64459.7\",\"0.01\",\"0\",\"1\"],[\"64459\",\"3.21\",\"0\",\"1\"],[\"64452.6\",\"512.39\",\"0\",\"4\"],[\"64438.8\",\"4.13\",\"0\",\"1\"],[\"64434.4\",\"0\",\"0\",\"0\"],[\"64429.6\",\"0\",\"0\",\"0\"],[\"64421.1\",\"1.53\",\"0\",\"3\"]],\"ts\":\"1782016024705\",\"checksum\":-1823929102,\"seqId\":325070067608,\"prevSeqId\":325070067467}]}"}
{"action": "update", "capture_sequence": 92, "channel": "books", "connection_sequence": 1, "event": null, "instId": "BTC-USDT-SWAP", "local_receive_ts": "2026-06-21T04:27:04Z", "monotonic_ns": 1643580708816600, "raw": "{\"arg\":{\"channel\":\"books\",\"instId\":\"BTC-USDT-SWAP\"},\"action\":\"update\",\"data\":[{\"asks\":[[\"64479.9\",\"331.64\",\"0\",\"33\"],[\"64483.6\",\"6.21\",\"0\",\"2\"],[\"64483.7\",\"1.01\",\"0\",\"2\"],[\"64499.3\",\"0.31\",\"0\",\"1\"],[\"64499.5\",\"232.79\",\"0\",\"2\"],[\"64504.1\",\"15.11\",\"0\",\"6\"],[\"64504.7\",\"33.8\",\"0\",\"2\"],[\"64504.9\",\"0.87\",\"0\",\"4\"],[\"64505.7\",\"0.56\",\"0\",\"1\"],[\"64505.8\",\"0.08\",\"0\",\"1\"],[\"64509.2\",\"201.48\",\"0\",\"2\"],[\"64509.3\",\"0.28\",\"0\",\"5\"],[\"64509.5\",\"0\",\"0\",\"0\"],[\"64509.9\",\"59.39\",\"0\",\"4\"],[\"64515.9\",\"47.94\",\"0\",\"4\"],[\"64516.5\",\"135.2\",\"0\",\"3\"]],\"bids\":[[\"64466.7\",\"0.31\",\"0\",\"1\"],[\"64466.6\",\"0.01\",\"0\",\"1\"],[\"64466.5\",\"102.15\",\"0\",\"2\"],[\"64466\",\"0.02\",\"0\",\"2\"],[\"64465.7\",\"1.15\",\"0\",\"2\"],[\"64465.2\",\"33.81\",\"0\",\"1\"],[\"64464.7\",\"0\",\"0\",\"0\"],[\"64460.8\",\"390.83\",\"0\",\"7\"],[\"64459.6\",\"0\",\"0\",\"0\"]],\"ts\":\"1782016024805\",\"checksum\":-2063289656,\"seqId\":325070067736,\"prevSeqId\":325070067608}]}"}
{"action": "update", "capture_sequence": 93, "channel": "books", "connection_sequence": 1, "event": null, "instId": "BTC-USDT-SWAP", "local_receive_ts": "2026-06-21T04:27:05Z", "monotonic_ns": 1643580808454067, "raw": "{\"arg\":{\"channel\":\"books\",\"instId\":\"BTC-USDT-SWAP\"},\"action\":\"update\",\"data\":[{\"asks\":[[\"64479.9\",\"321.64\",\"0\",\"32\"],[\"64480\",\"50.09\",\"0\",\"7\"],[\"64485.4\",\"0\",\"0\",\"0\"],[\"64493.9\",\"0.17\",\"0\",\"1\"],[\"64494.7\",\"24.05\",\"0\",\"5\"],[\"64504.9\",\"0.1\",\"0\",\"3\"],[\"64505.8\",\"0.85\",\"0\",\"2\"],[\"64509.8\",\"58.19\",\"0\",\"2\"],[\"64509.9\",\"1.21\",\"0\",\"3\"]],\"bids\":[[\"64479.8\",\"776.34\",\"0\",\"35\"],[\"64478.3\",\"0.78\",\"0\",\"3\"],[\"64476.9\",\"0.63\",\"0\",\"4\"],[\"64466.6\",\"0.78\",\"0\",\"2\"],[\"64465.7\",\"0.38\",\"0\",\"1\"],[\"64460.8\",\"332.6\",\"0\",\"6\"],[\"64460.2\",\"58.23\",\"0\",\"1\"],[\"64460\",\"200.31\",\"0\",\"4\"],[\"64457\",\"543.17\",\"0\",\"5\"],[\"64431.9\",\"496.53\",\"0\",\"1\"],[\"64421.1\",\"0\",\"0\",\"0\"]],\"ts\":\"1782016024905\",\"checksum\":-715874482,\"seqId\":325070067827,\"prevSeqId\":325070067736}]}"}
{"action": "update", "capture_sequence": 94, "channel": "books", "connection_sequence": 1, "event": null, "instId": "BTC-USDT-SWAP", "local_receive_ts": "2026-06-21T04:27:05Z", "monotonic_ns": 1643580908912171, "raw": "{\"arg\":{\"channel\":\"books\",\"instId\":\"BTC-USDT-SWAP\"},\"action\":\"update\",\"data\":[{\"asks\":[[\"64481.8\",\"1.6\",\"0\",\"4\"]],\"bids\":[[\"64477.9\",\"1.56\",\"0\",\"1\"],[\"64476.9\",\"0.93\",\"0\",\"4\"],[\"64474\",\"496.54\",\"0\",\"2\"],[\"64473.6\",\"248.53\",\"0\",\"4\"],[\"64464.9\",\"32.76\",\"0\",\"3\"],[\"64464.1\",\"2.76\",\"0\",\"1\"],[\"64461.5\",\"0.04\",\"0\",\"3\"],[\"64461.2\",\"0.04\",\"0\",\"2\"],[\"64459.9\",\"0.02\",\"0\",\"1\"],[\"64457\",\"543.15\",\"0\",\"4\"],[\"64451.7\",\"271.87\",\"0\",\"4\"],[\"64444.6\",\"500.03\",\"0\",\"3\"],[\"64421.3\",\"0\",\"0\",\"0\"],[\"64421.2\",\"0\",\"0\",\"0\"]],\"ts\":\"1782016025005\",\"checksum\":326391655,\"seqId\":325070067910,\"prevSeqId\":325070067827}]}"}
{"action": "update", "capture_sequence": 95, "channel": "books", "connection_sequence": 1, "event": null, "instId": "BTC-USDT-SWAP", "local_receive_ts": "2026-06-21T04:27:05Z", "monotonic_ns": 1643581009551922, "raw": "{\"arg\":{\"channel\":\"books\",\"instId\":\"BTC-USDT-SWAP\"},\"action\":\"update\",\"data\":[{\"asks\":[[\"64481.8\",\"0.06\",\"0\",\"5\"],[\"64481.9\",\"1.59\",\"0\",\"4\"],[\"64482\",\"6.94\",\"0\",\"3\"],[\"64482.4\",\"1.56\",\"0\",\"1\"],[\"64482.9\",\"0.01\",\"0\",\"1\"],[\"64483.1\",\"0.62\",\"0\",\"3\"],[\"64488\",\"57.87\",\"0\",\"27\"],[\"64488.5\",\"0\",\"0\",\"0\"],[\"64505.8\",\"3.13\",\"0\",\"3\"],[\"64517.8\",\"46.59\",\"0\",\"4\"]],\"bids\":[[\"64479.6\",\"5.93\",\"0\",\"3\"],[\"64478.8\",\"0\",\"0\",\"0\"],[\"64478.6\",\"0.01\",\"0\",\"1\"],[\"64478.4\",\"0.01\",\"0\",\"1\"],[\"64478.3\",\"0.77\",\"0\",\"2\"],[\"64478.2\",\"0\",\"0\",\"0\"],[\"64478\",\"1.58\",\"0\",\"3\"],[\"64477.9\",\"0\",\"0\",\"0\"],[\"64477.7\",\"2.02\",\"0\",\"3\"],[\"64477.5\",\"1.56\",\"0\",\"1\"],[\"64476.9\",\"0.03\",\"0\",\"3\"],[\"64476.3\",\"33.85\",\"0\",\"6\"],[\"64476.2\",\"303.69\",\"0\",\"5\"],[\"64475.7\",\"1.56\",\"0\",\"1\"],[\"64474.4\",\"12.71\",\"0\",\"2\"],[\"64474.3\",\"0.77\",\"0\",\"1\"],[\"64473.1\",\"1.56\",\"0\",\"1\"],[\"64470.1\",\"0\",\"0\",\"0\"],[\"64469.9\",\"0\",\"0\",\"0\"],[\"64469.6\",\"12.01\",\"0\",\"3\"],[\"64465.5\",\"6.24\",\"0\",\"2\"],[\"64464.9\",\"32.74\",\"0\",\"2\"],[\"64464.1\",\"2.78\",\"0\",\"2\"],[\"64461.5\",\"0.02\",\"0\",\"2\"],[\"64461.2\",\"0.06\",\"0\",\"3\"],[\"64459.9\",\"0\",\"0\",\"0\"],[\"64421.3\",\"0.03\",\"0\",\"2\"]],\"ts\":\"1782016025105\",\"checksum\":1365140527,\"seqId\":325070068048,\"prevSeqId\":325070067910}]}"}
{"action": null, "capture_sequence": 96, "channel": "trades", "connection_sequence": 1, "event": null, "instId": "BTC-USDT-SWAP", "local_receive_ts": "2026-06-21T04:27:05Z", "monotonic_ns": 1643581070790478, "raw": "{\"arg\":{\"channel\":\"trades\",\"instId\":\"BTC-USDT-SWAP\"},\"data\":[{\"instId\":\"BTC-USDT-SWAP\",\"tradeId\":\"2718750154\",\"px\":\"64479.9\",\"sz\":\"0.25\",\"side\":\"buy\",\"ts\":\"1782016025167\",\"count\":\"2\",\"source\":\"0\",\"seqId\":325070068103}]}"}
{"action": "update", "capture_sequence": 97, "channel": "books", "connection_sequence": 1, "event": null, "instId": "BTC-USDT-SWAP", "local_receive_ts": "2026-06-21T04:27:05Z", "monotonic_ns": 1643581108922880, "raw": "{\"arg\":{\"channel\":\"books\",\"instId\":\"BTC-USDT-SWAP\"},\"action\":\"update\",\"data\":[{\"asks\":[[\"64479.9\",\"321.37\",\"0\",\"30\"],[\"64481.8\",\"0.05\",\"0\",\"4\"],[\"64481.9\",\"0.03\",\"0\",\"3\"],[\"64482.4\",\"0\",\"0\",\"0\"],[\"64482.9\",\"0.02\",\"0\",\"2\"],[\"64484.1\",\"1.58\",\"0\",\"2\"],[\"64484.2\",\"0.01\",\"0\",\"1\"],[\"64484.4\",\"77.54\",\"0\",\"1\"],[\"64484.7\",\"0.16\",\"0\",\"1\"],[\"64485.6\",\"1.56\",\"0\",\"1\"],[\"64488\",\"59.43\",\"0\",\"28\"],[\"64488.5\",\"1.56\",\"0\",\"1\"],[\"64489.5\",\"38.75\",\"0\",\"5\"],[\"64525.2\",\"0\",\"0\",\"0\"],[\"64525.3\",\"0\",\"0\",\"0\"],[\"64525.4\",\"0\",\"0\",\"0\"]],\"bids\":[[\"64479.5\",\"6.56\",\"0\",\"2\"],[\"64479\",\"6.56\",\"0\",\"2\"],[\"64478.4\",\"0.8\",\"0\",\"2\"],[\"64478.3\",\"0.01\",\"0\",\"1\"],[\"64473.6\",\"246.97\",\"0\",\"3\"],[\"64473.1\",\"0\",\"0\",\"0\"],[\"64451.1\",\"17.95\",\"0\",\"1\"]],\"ts\":\"1782016025205\",\"checksum\":1432242430,\"seqId\":325070068164,\"prevSeqId\":325070068048}]}"}
{"action": "update", "capture_sequence": 98, "channel": "books", "connection_sequence": 1, "event": null, "instId": "BTC-USDT-SWAP", "local_receive_ts": "2026-06-21T04:27:05Z", "monotonic_ns": 1643581208698328, "raw": "{\"arg\":{\"channel\":\"books\",\"instId\":\"BTC-USDT-SWAP\"},\"action\":\"update\",\"data\":[{\"asks\":[[\"64479.9\",\"321.49\",\"0\",\"32\"],[\"64483.4\",\"2.56\",\"0\",\"2\"],[\"64492\",\"0.2\",\"0\",\"5\"],[\"64493.1\",\"4.65\",\"0\",\"3\"],[\"64493.9\",\"0\",\"0\",\"0\"],[\"64494\",\"239.11\",\"0\",\"7\"],[\"64495.6\",\"15.53\",\"0\",\"2\"],[\"64496.2\",\"0.01\",\"0\",\"1\"],[\"64497.6\",\"4.03\",\"0\",\"4\"],[\"64497.9\",\"31.04\",\"0\",\"2\"],[\"64498.4\",\"232.78\",\"0\",\"1\"],[\"64498.6\",\"3.59\",\"0\",\"7\"],[\"64498.9\",\"49.96\",\"0\",\"3\"],[\"64499.5\",\"0.01\",\"0\",\"1\"],[\"64503.2\",\"3.7\",\"0\",\"3\"],[\"64505.8\",\"0.85\",\"0\",\"2\"]],\"bids\":[[\"64470\",\"237.27\",\"0\",\"4\"],[\"64461\",\"37.23\",\"0\",\"3\"],[\"64460.9\",\"95.5\",\"0\",\"2\"],[\"64460.5\",\"1.5\",\"0\",\"1\"],[\"64460.1\",\"34.96\",\"0\",\"3\"],[\"64459.6\",\"232.92\",\"0\",\"1\"],[\"64459\",\"3.2\",\"0\",\"1\"],[\"64452.7\",\"323.76\",\"0\",\"5\"],[\"64452.6\",\"512.2\",\"0\",\"3\"],[\"64421.3\",\"0\",\"0\",\"0\"]],\"ts\":\"1782016025305\",\"checksum\":413803382,\"seqId\":325070068287,\"prevSeqId\":325070068164}]}"}
{"action": null, "capture_sequence": 99, "channel": "trades", "connection_sequence": 1, "event": null, "instId": "BTC-USDT-SWAP", "local_receive_ts": "2026-06-21T04:27:05Z", "monotonic_ns": 1643581242330376, "raw": "{\"arg\":{\"channel\":\"trades\",\"instId\":\"BTC-USDT-SWAP\"},\"data\":[{\"instId\":\"BTC-USDT-SWAP\",\"tradeId\":\"2718750170\",\"px\":\"64479.9\",\"sz\":\"2.19\",\"side\":\"buy\",\"ts\":\"1782016025339\",\"count\":\"16\",\"source\":\"0\",\"seqId\":325070068350}]}"}
{"action": "update", "capture_sequence": 100, "channel": "books", "connection_sequence": 1, "event": null, "instId": "BTC-USDT-SWAP", "local_receive_ts": "2026-06-21T04:27:05Z", "monotonic_ns": 1643581308818099, "raw": "{\"arg\":{\"channel\":\"books\",\"instId\":\"BTC-USDT-SWAP\"},\"action\":\"update\",\"data\":[{\"asks\":[[\"64479.9\",\"319.31\",\"0\",\"17\"],[\"64481.8\",\"0.04\",\"0\",\"3\"],[\"64483.4\",\"1\",\"0\",\"1\"],[\"64483.5\",\"0.01\",\"0\",\"1\"],[\"64483.8\",\"81.01\",\"0\",\"2\"],[\"64484.1\",\"0.02\",\"0\",\"1\"],[\"64484.6\",\"138.54\",\"0\",\"4\"],[\"64485.1\",\"1.2\",\"0\",\"1\"],[\"64485.3\",\"1.56\",\"0\",\"1\"],[\"64485.6\",\"0\",\"0\",\"0\"],[\"64485.7\",\"1.9\",\"0\",\"5\"],[\"64489\",\"20.66\",\"0\",\"9\"],[\"64489.4\",\"4.49\",\"0\",\"6\"],[\"64525.1\",\"0\",\"0\",\"0\"]],\"bids\":[[\"64478.6\",\"0\",\"0\",\"0\"],[\"64478.5\",\"0.02\",\"0\",\"2\"],[\"64478.4\",\"0.79\",\"0\",\"1\"],[\"64478.1\",\"0.01\",\"0\",\"1\"],[\"64478\",\"1.57\",\"0\",\"2\"],[\"64477.8\",\"0.01\",\"0\",\"1\"],[\"64476.9\",\"0.93\",\"0\",\"4\"],[\"64421.5\",\"0\",\"0\",\"0\"]],\"ts\":\"1782016025405\",\"checksum\":1484492022,\"seqId\":325070068427,\"prevSeqId\":325070068287}]}"}
{"action": "update", "capture_sequence": 101, "channel": "books", "connection_sequence": 1, "event": null, "instId": "BTC-USDT-SWAP", "local_receive_ts": "2026-06-21T04:27:05Z", "monotonic_ns": 1643581408652830, "raw": "{\"arg\":{\"channel\":\"books\",\"instId\":\"BTC-USDT-SWAP\"},\"action\":\"update\",\"data\":[{\"asks\":[[\"64483.8\",\"79.45\",\"0\",\"1\"],[\"64485.3\",\"0\",\"0\",\"0\"],[\"64493.9\",\"0.17\",\"0\",\"1\"],[\"64494\",\"238.94\",\"0\",\"6\"],[\"64495.6\",\"0.01\",\"0\",\"1\"],[\"64495.9\",\"16.35\",\"0\",\"4\"]],\"bids\":[[\"64479.8\",\"776.37\",\"0\",\"35\"],[\"64476.9\",\"0.03\",\"0\",\"3\"]],\"ts\":\"1782016025505\",\"checksum\":-1578781646,\"seqId\":325070068523,\"prevSeqId\":325070068427}]}"}
{"action": "update", "capture_sequence": 102, "channel": "books", "connection_sequence": 1, "event": null, "instId": "BTC-USDT-SWAP", "local_receive_ts": "2026-06-21T04:27:05Z", "monotonic_ns": 1643581508789668, "raw": "{\"arg\":{\"channel\":\"books\",\"instId\":\"BTC-USDT-SWAP\"},\"action\":\"update\",\"data\":[{\"asks\":[[\"64484.1\",\"1.58\",\"0\",\"2\"],[\"64484.6\",\"140.1\",\"0\",\"5\"],[\"64485.3\",\"1.56\",\"0\",\"1\"],[\"64489\",\"19.1\",\"0\",\"8\"],[\"64489.4\",\"2.93\",\"0\",\"5\"],[\"64505.8\",\"3.13\",\"0\",\"3\"],[\"64525\",\"0\",\"0\",\"0\"]],\"bids\":[[\"64478.4\",\"0\",\"0\",\"0\"],[\"64478.3\",\"0.79\",\"0\",\"2\"],[\"64421.5\",\"0.01\",\"0\",\"1\"]],\"ts\":\"1782016025605\",\"checksum\":-1209445059,\"seqId\":325070068629,\"prevSeqId\":325070068523}]}"}
{"action": null, "capture_sequence": 103, "channel": "trades", "connection_sequence": 1, "event": null, "instId": "BTC-USDT-SWAP", "local_receive_ts": "2026-06-21T04:27:05Z", "monotonic_ns": 1643581550382869, "raw": "{\"arg\":{\"channel\":\"trades\",\"instId\":\"BTC-USDT-SWAP\"},\"data\":[{\"instId\":\"BTC-USDT-SWAP\",\"tradeId\":\"2718750171\",\"px\":\"64479.8\",\"sz\":\"0.06\",\"side\":\"sell\",\"ts\":\"1782016025647\",\"count\":\"1\",\"source\":\"0\",\"seqId\":325070068731}]}"}
{"action": "update", "capture_sequence": 104, "channel": "books", "connection_sequence": 1, "event": null, "instId": "BTC-USDT-SWAP", "local_receive_ts": "2026-06-21T04:27:05Z", "monotonic_ns": 1643581610087207, "raw": "{\"arg\":{\"channel\":\"books\",\"instId\":\"BTC-USDT-SWAP\"},\"action\":\"update\",\"data\":[{\"asks\":[[\"64484.1\",\"0.02\",\"0\",\"1\"],[\"64484.6\",\"138.54\",\"0\",\"4\"],[\"64485.3\",\"0\",\"0\",\"0\"],[\"64489\",\"20.66\",\"0\",\"9\"],[\"64495.6\",\"15.53\",\"0\",\"2\"],[\"64495.9\",\"0.84\",\"0\",\"3\"],[\"64497.9\",\"0.01\",\"0\",\"1\"],[\"64499\",\"364.12\",\"0\",\"22\"],[\"64499.3\",\"0\",\"0\",\"0\"],[\"64499.5\",\"0.32\",\"0\",\"2\"],[\"64505.8\",\"2.36\",\"0\",\"2\"],[\"64506.7\",\"0.96\",\"0\",\"16\"],[\"64508.8\",\"442.95\",\"0\",\"4\"],[\"64509.2\",\"160.99\",\"0\",\"2\"],[\"64514.3\",\"0.11\",\"0\",\"5\"],[\"64514.9\",\"516.68\",\"0\",\"5\"],[\"64515.5\",\"75.46\",\"0\",\"7\"],[\"64516.5\",\"49.1\",\"0\",\"2\"],[\"64517.9\",\"86.25\",\"0\",\"4\"],[\"64518\",\"111.05\",\"0\",\"14\"],[\"64525\",\"2.51\",\"0\",\"18\"],[\"64525.1\",\"0.46\",\"0\",\"1\"]],\"bids\":[[\"64479.8\",\"776.31\",\"0\",\"35\"],[\"64479.5\",\"5\",\"0\",\"1\"],[\"64479\",\"5\",\"0\",\"1\"],[\"64478.5\",\"0.01\",\"0\",\"1\"],[\"64476.3\",\"33.54\",\"0\",\"5\"],[\"64476.1\",\"0.31\",\"0\",\"1\"],[\"64467.4\",\"0.77\",\"0\",\"1\"],[\"64467\",\"86.24\",\"0\",\"2\"],[\"64466.6\",\"0.01\",\"0\",\"1\"],[\"64466.5\",\"15.98\",\"0\",\"1\"],[\"64465\",\"0.02\",\"0\",\"1\"],[\"64464.4\",\"20.09\",\"0\",\"2\"],[\"64463.4\",\"0\",\"0\",\"0\"],[\"64463.1\",\"122.63\",\"0\",\"2\"],[\"64461.2\",\"37.29\",\"0\",\"6\"],[\"64461.1\",\"77.61\",\"0\",\"3\"],[\"64461\",\"0\",\"0\",\"0\"],[\"64460.1\",\"3.91\",\"0\",\"2\"]],\"ts\":\"1782016025705\",\"checksum\":1016048103,\"seqId\":325070068814,\"prevSeqId\":325070068629}]}"}
{"action": "update", "capture_sequence": 105, "channel": "books", "connection_sequence": 1, "event": null, "instId": "BTC-USDT-SWAP", "local_receive_ts": "2026-06-21T04:27:05Z", "monotonic_ns": 1643581713429594, "raw": "{\"arg\":{\"channel\":\"books\",\"instId\":\"BTC-USDT-SWAP\"},\"action\":\"update\",\"data\":[{\"asks\":[[\"64479.9\",\"157.14\",\"0\",\"14\"],[\"64480\",\"50.08\",\"0\",\"6\"],[\"64486.4\",\"16.8\",\"0\",\"4\"],[\"64487.4\",\"0.8\",\"0\",\"7\"],[\"64489.1\",\"0.04\",\"0\",\"3\"],[\"64489.2\",\"0.77\",\"0\",\"1\"],[\"64489.4\",\"18.41\",\"0\",\"6\"],[\"64489.6\",\"0.12\",\"0\",\"2\"],[\"64491.7\",\"15.94\",\"0\",\"3\"],[\"64492.5\",\"93.49\",\"0\",\"4\"],[\"64493.3\",\"23.99\",\"0\",\"5\"],[\"64493.4\",\"0.32\",\"0\",\"5\"],[\"64493.8\",\"0.2\",\"0\",\"3\"],[\"64493.9\",\"0\",\"0\",\"0\"],[\"64495.6\",\"0.01\",\"0\",\"1\"],[\"64495.9\",\"16.35\",\"0\",\"4\"],[\"64496\",\"104.13\",\"0\",\"6\"],[\"64498.2\",\"1.81\",\"0\",\"4\"],[\"64498.4\",\"0\",\"0\",\"0\"],[\"64499.5\",\"232.79\",\"0\",\"2\"],[\"64500.2\",\"0.33\",\"0\",\"3\"],[\"64506.7\",\"0.19\",\"0\",\"15\"],[\"64507.7\",\"0.84\",\"0\",\"5\"],[\"64508.8\",\"357.61\",\"0\",\"3\"],[\"64509\",\"215.66\",\"0\",\"3\"],[\"64509.2\",\"116.14\",\"0\",\"1\"],[\"64509.8\",\"0.01\",\"0\",\"1\"],[\"64509.9\",\"86.55\",\"0\",\"4\"],[\"64511.7\",\"58.2\",\"0\",\"3\"],[\"64512\",\"2.88\",\"0\",\"13\"],[\"64515.9\",\"134.04\",\"0\",\"5\"],[\"64517.9\",\"0.15\",\"0\",\"3\"],[\"64525.2\",\"55.22\",\"0\",\"2\"]],\"bids\":[[\"64479.8\",\"778.31\",\"0\",\"36\"],[\"64479.6\",\"41.33\",\"0\",\"2\"],[\"64478.4\",\"0.01\",\"0\",\"1\"],[\"64477.7\",\"0.02\",\"0\",\"2\"],[\"64476.7\",\"31.82\",\"0\",\"3\"],[\"64476.6\",\"0.32\",\"0\",\"2\"],[\"64476.3\",\"1.57\",\"0\",\"2\"],[\"64476.1\",\"0\",\"0\",\"0\"],[\"64474.1\",\"7.79\",\"0\",\"3\"],[\"64472.1\",\"0.02\",\"0\",\"2\"],[\"64468.4\",\"0.77\",\"0\",\"1\"],[\"64468.3\",\"0\",\"0\",\"0\"],[\"64467.5\",\"0.34\",\"0\",\"3\"],[\"64467.4\",\"0\",\"0\",\"0\"],[\"64467.1\",\"31.07\",\"0\",\"1\"],[\"64467\",\"0.07\",\"0\",\"1\"],[\"64466.7\",\"0\",\"0\",\"0\"],[\"64466\",\"86.19\",\"0\",\"3\"],[\"64465.7\",\"6.6\",\"0\",\"2\"],[\"64465.5\",\"0.02\",\"0\",\"1\"],[\"64464.3\",\"87.56\",\"0\",\"2\"],[\"64463.1\",\"37.23\",\"0\",\"1\"],[\"64462.2\",\"58.22\",\"0\",\"1\"],[\"64461.4\",\"37.26\",\"0\",\"6\"],[\"64461.2\",\"0.06\",\"0\",\"3\"],[\"64460.2\",\"232.92\",\"0\",\"1\"],[\"64459.6\",\"0\",\"0\",\"0\"],[\"64446.4\",\"0\",\"0\",\"0\"],[\"64421.3\",\"0.03\",\"0\",\"2\"],[\"64421.2\",\"0.01\",\"0\",\"1\"]],\"ts\":\"1782016025805\",\"checksum\":-423253440,\"seqId\":325070068978,\"prevSeqId\":325070068814}]}"}
{"action": "update", "capture_sequence": 106, "channel": "books", "connection_sequence": 1, "event": null, "instId": "BTC-USDT-SWAP", "local_receive_ts": "2026-06-21T04:27:06Z", "monotonic_ns": 1643581813306906, "raw": "{\"arg\":{\"channel\":\"books\",\"instId\":\"BTC-USDT-SWAP\"},\"action\":\"update\",\"data\":[{\"asks\":[[\"64482\",\"6.93\",\"0\",\"2\"],[\"64482.2\",\"7.75\",\"0\",\"1\"],[\"64483.6\",\"6.71\",\"0\",\"3\"],[\"64485.7\",\"0.34\",\"0\",\"4\"],[\"64486.1\",\"15.52\",\"0\",\"1\"],[\"64486.4\",\"1.28\",\"0\",\"3\"],[\"64489.2\",\"0\",\"0\",\"0\"],[\"64489.4\",\"19.01\",\"0\",\"7\"],[\"64495.9\",\"0.84\",\"0\",\"3\"],[\"64496.2\",\"15.52\",\"0\",\"2\"],[\"64496.6\",\"31.85\",\"0\",\"3\"],[\"64496.9\",\"31.07\",\"0\",\"1\"],[\"64499.5\",\"232.78\",\"0\",\"1\"],[\"64499.8\",\"1.09\",\"0\",\"3\"],[\"64500.1\",\"0.05\",\"0\",\"4\"],[\"64501\",\"0.28\",\"0\",\"4\"],[\"64504.7\",\"0.01\",\"0\",\"1\"],[\"64506\",\"43.86\",\"0\",\"6\"],[\"64509.9\",\"1.21\",\"0\",\"3\"],[\"64510\",\"71.08\",\"0\",\"29\"],[\"64511.2\",\"85.35\",\"0\",\"3\"],[\"64514.9\",\"496.61\",\"0\",\"4\"],[\"64515.9\",\"47.94\",\"0\",\"4\"],[\"64516.9\",\"34.12\",\"0\",\"5\"],[\"64517.8\",\"0.1\",\"0\",\"3\"],[\"64517.9\",\"86.25\",\"0\",\"4\"],[\"64519.2\",\"0.48\",\"0\",\"7\"],[\"64520\",\"78.63\",\"0\",\"64\"],[\"64520.9\",\"46.51\",\"0\",\"3\"]],\"bids\":[[\"64479.7\",\"28.96\",\"0\",\"5\"],[\"64479.6\",\"0.02\",\"0\",\"1\"],[\"64479.3\",\"0.02\",\"0\",\"1\"],[\"64479.2\",\"78.37\",\"0\",\"1\"],[\"64478.3\",\"0.01\",\"0\",\"1\"],[\"64477.8\",\"0\",\"0\",\"0\"],[\"64477.6\",\"0.02\",\"0\",\"2\"],[\"64477.1\",\"0.02\",\"0\",\"2\"],[\"64476.7\",\"0.32\",\"0\",\"2\"],[\"64476.6\",\"0.01\",\"0\",\"1\"],[\"64476.4\",\"0.77\",\"0\",\"1\"],[\"64476.3\",\"32.61\",\"0\",\"3\"],[\"64474.1\",\"7.81\",\"0\",\"4\"],[\"64473.9\",\"46.55\",\"0\",\"2\"],[\"64473.8\",\"0.02\",\"0\",\"2\"],[\"64473.4\",\"0\",\"0\",\"0\"],[\"64467\",\"469.96\",\"0\",\"3\"],[\"64466.6\",\"33.82\",\"0\",\"2\"],[\"64466.4\",\"0\",\"0\",\"0\"],[\"64466.3\",\"20.1\",\"0\",\"2\"],[\"64466\",\"0.02\",\"0\",\"2\"],[\"64465.5\",\"85.41\",\"0\",\"2\"],[\"64465.2\",\"0\",\"0\",\"0\"],[\"64465\",\"0\",\"0\",\"0\"],[\"64464.4\",\"0.01\",\"0\",\"1\"],[\"64464.3\",\"2.16\",\"0\",\"1\"],[\"64456.9\",\"0.02\",\"0\",\"1\"],[\"64452.6\",\"512.18\",\"0\",\"2\"],[\"64445.9\",\"3.1\",\"0\",\"1\"],[\"64444.8\",\"10.01\",\"0\",\"2\"],[\"64440.1\",\"512.2\",\"0\",\"3\"],[\"64438.4\",\"0.01\",\"0\",\"1\"],[\"64421.2\",\"0\",\"0\",\"0\"]],\"ts\":\"1782016025905\",\"checksum\":-1489939773,\"seqId\":325070069193,\"prevSeqId\":325070068978}]}"}
{"action": "update", "capture_sequence": 107, "channel": "books", "connection_sequence": 1, "event": null, "instId": "BTC-USDT-SWAP", "local_receive_ts": "2026-06-21T04:27:06Z", "monotonic_ns": 1643581913832043, "raw": "{\"arg\":{\"channel\":\"books\",\"instId\":\"BTC-USDT-SWAP\"},\"action\":\"update\",\"data\":[{\"asks\":[[\"64479.9\",\"277.65\",\"0\",\"16\"],[\"64482.9\",\"1.58\",\"0\",\"3\"],[\"64483.4\",\"2.56\",\"0\",\"2\"],[\"64483.5\",\"6.21\",\"0\",\"2\"],[\"64483.6\",\"102.99\",\"0\",\"3\"],[\"64483.8\",\"0\",\"0\",\"0\"],[\"64485.8\",\"17.13\",\"0\",\"5\"],[\"64486.1\",\"0\",\"0\",\"0\"],[\"64489.4\",\"19\",\"0\",\"7\"],[\"64493.8\",\"0.03\",\"0\",\"2\"],[\"64495.9\",\"16.35\",\"0\",\"4\"],[\"64496.2\",\"0.01\",\"0\",\"1\"],[\"64496.9\",\"31.29\",\"0\",\"2\"],[\"64499.7\",\"35.68\",\"0\",\"6\"],[\"64500.2\",\"0.02\",\"0\",\"2\"],[\"64501.1\",\"1.6\",\"0\",\"3\"],[\"64501.3\",\"0.02\",\"0\",\"1\"],[\"64506\",\"10.07\",\"0\",\"5\"],[\"64506.7\",\"33.98\",\"0\",\"16\"],[\"64507.1\",\"0.83\",\"0\",\"5\"],[\"64507.7\",\"0.07\",\"0\",\"4\"],[\"64511.2\",\"0.02\",\"0\",\"2\"],[\"64511.7\",\"85.35\",\"0\",\"3\"],[\"64512.5\",\"58.34\",\"0\",\"6\"],[\"64516.9\",\"14.05\",\"0\",\"4\"],[\"64517.1\",\"20.24\",\"0\",\"2\"],[\"64517.9\",\"0.15\",\"0\",\"3\"],[\"64518.3\",\"86.12\",\"0\",\"3\"],[\"64525.3\",\"0.01\",\"0\",\"1\"],[\"64525.4\",\"11.4\",\"0\",\"1\"]],\"bids\":[[\"64479.1\",\"1.59\",\"0\",\"3\"],[\"64478.6\",\"1.56\",\"0\",\"1\"],[\"64476.7\",\"0.01\",\"0\",\"1\"],[\"64476.3\",\"32.92\",\"0\",\"4\"],[\"64468.4\",\"0\",\"0\",\"0\"],[\"64467.6\",\"33.83\",\"0\",\"3\"],[\"64467.5\",\"0.03\",\"0\",\"2\"],[\"64467.4\",\"133.48\",\"0\",\"3\"],[\"64467.2\",\"0.31\",\"0\",\"1\"],[\"64467\",\"383.79\",\"0\",\"2\"],[\"64466.7\",\"20.08\",\"0\",\"1\"],[\"64466.6\",\"0.01\",\"0\",\"1\"],[\"64466.3\",\"0.02\",\"0\",\"1\"],[\"64465.8\",\"85.39\",\"0\",\"1\"],[\"64465.5\",\"0.02\",\"0\",\"1\"],[\"64463.2\",\"58.22\",\"0\",\"1\"],[\"64462.2\",\"0\",\"0\",\"0\"],[\"64461\",\"200\",\"0\",\"1\"],[\"64460\",\"0.31\",\"0\",\"3\"],[\"64421.9\",\"0\",\"0\",\"0\"],[\"64421.8\",\"0\",\"0\",\"0\"],[\"64421.6\",\"0\",\"0\",\"0\"],[\"64421.5\",\"0\",\"0\",\"0\"],[\"64421.3\",\"0\",\"0\",\"0\"]],\"ts\":\"1782016026005\",\"checksum\":2072202923,\"seqId\":325070069369,\"prevSeqId\":325070069193}]}"}
{"action": "update", "capture_sequence": 108, "channel": "books", "connection_sequence": 1, "event": null, "instId": "BTC-USDT-SWAP", "local_receive_ts": "2026-06-21T04:27:06Z", "monotonic_ns": 1643582013981452, "raw": "{\"arg\":{\"channel\":\"books\",\"instId\":\"BTC-USDT-SWAP\"},\"action\":\"update\",\"data\":[{\"asks\":[[\"64482.9\",\"0.02\",\"0\",\"2\"],[\"64483.1\",\"2.18\",\"0\",\"4\"],[\"64483.4\",\"1\",\"0\",\"1\"],[\"64484\",\"3.28\",\"0\",\"5\"],[\"64484.4\",\"79.1\",\"0\",\"2\"],[\"64485.1\",\"2.76\",\"0\",\"2\"],[\"64485.6\",\"1.56\",\"0\",\"1\"],[\"64488.5\",\"0\",\"0\",\"0\"],[\"64489\",\"19.1\",\"0\",\"8\"],[\"64490.5\",\"17.52\",\"0\",\"4\"],[\"64491.1\",\"0\",\"0\",\"0\"],[\"64494.5\",\"0.17\",\"0\",\"1\"],[\"64496.6\",\"31.68\",\"0\",\"2\"],[\"64498.6\",\"34.62\",\"0\",\"8\"],[\"64499\",\"333.09\",\"0\",\"21\"],[\"64499.1\",\"0.16\",\"0\",\"4\"],[\"64499.6\",\"63.7\",\"0\",\"6\"],[\"64499.7\",\"35.37\",\"0\",\"5\"],[\"64499.8\",\"1.08\",\"0\",\"2\"],[\"64500.1\",\"0.06\",\"0\",\"5\"],[\"64501\",\"0.27\",\"0\",\"3\"],[\"64501.1\",\"0.05\",\"0\",\"2\"],[\"64501.2\",\"17.23\",\"0\",\"5\"],[\"64505.8\",\"0.08\",\"0\",\"1\"],[\"64506.7\",\"0.19\",\"0\",\"15\"],[\"64507.3\",\"33.82\",\"0\",\"3\"],[\"64511.7\",\"0.02\",\"0\",\"2\"],[\"64511.9\",\"85.47\",\"0\",\"2\"],[\"64512.5\",\"0.16\",\"0\",\"5\"],[\"64512.8\",\"58.18\",\"0\",\"1\"],[\"64517.1\",\"0.18\",\"0\",\"1\"],[\"64517.7\",\"38.74\",\"0\",\"5\"],[\"64518.3\",\"0.02\",\"0\",\"2\"],[\"64519.7\",\"96.91\",\"0\",\"8\"],[\"64525.4\",\"0\",\"0\",\"0\"]],\"bids\":[[\"64479.7\",\"30.52\",\"0\",\"6\"],[\"64479.2\",\"79.93\",\"0\",\"2\"],[\"64479.1\",\"0.03\",\"0\",\"2\"],[\"64478.6\",\"0.01\",\"0\",\"1\"],[\"64478.5\",\"1.57\",\"0\",\"2\"],[\"64478.4\",\"0\",\"0\",\"0\"],[\"64476.4\",\"1.08\",\"0\",\"2\"],[\"64476.3\",\"32.61\",\"0\",\"3\"],[\"64474.5\",\"77.55\",\"0\",\"1\"],[\"64474.3\",\"0\",\"0\",\"0\"],[\"64474.2\",\"0\",\"0\",\"0\"],[\"64474.1\",\"7\",\"0\",\"3\"],[\"64473.9\",\"46.57\",\"0\",\"3\"],[\"64468.8\",\"97.8\",\"0\",\"3\"],[\"64467.8\",\"33.82\",\"0\",\"2\"],[\"64467.7\",\"0.77\",\"0\",\"1\"],[\"64467.6\",\"0.02\",\"0\",\"2\"],[\"64467.4\",\"46.54\",\"0\",\"1\"],[\"64467.2\",\"20.39\",\"0\",\"2\"],[\"64466.9\",\"167.74\",\"0\",\"7\"],[\"64466.7\",\"0\",\"0\",\"0\"],[\"64466.3\",\"0\",\"0\",\"0\"],[\"64466\",\"85.41\",\"0\",\"3\"],[\"64465.8\",\"0\",\"0\",\"0\"],[\"64465.5\",\"0\",\"0\",\"0\"],[\"64465.3\",\"48.18\",\"0\",\"5\"],[\"64464.1\",\"2.76\",\"0\",\"1\"],[\"64463.7\",\"0.02\",\"0\",\"1\"],[\"64463.6\",\"70.35\",\"0\",\"5\"],[\"64463.2\",\"0\",\"0\",\"0\"],[\"64461.1\",\"46.56\",\"0\",\"2\"],[\"64460.7\",\"76\",\"0\",\"3\"],[\"64426.4\",\"0\",\"0\",\"0\"],[\"64421.9\",\"0.01\",\"0\",\"1\"],[\"64421.8\",\"0.03\",\"0\",\"2\"],[\"64421.6\",\"15.65\",\"0\",\"1\"],[\"64421.5\",\"0.01\",\"0\",\"1\"],[\"64421.3\",\"0.03\",\"0\",\"2\"],[\"64421.2\",\"0.01\",\"0\",\"1\"]],\"ts\":\"1782016026105\",\"checksum\":742688564,\"seqId\":325070069635,\"prevSeqId\":325070069369}]}"}
{"action": null, "capture_sequence": 109, "channel": "trades", "connection_sequence": 1, "event": null, "instId": "BTC-USDT-SWAP", "local_receive_ts": "2026-06-21T04:27:06Z", "monotonic_ns": 1643582067303957, "raw": "{\"arg\":{\"channel\":\"trades\",\"instId\":\"BTC-USDT-SWAP\"},\"data\":[{\"instId\":\"BTC-USDT-SWAP\",\"tradeId\":\"2718750178\",\"px\":\"64479.9\",\"sz\":\"10\",\"side\":\"buy\",\"ts\":\"1782016026164\",\"count\":\"7\",\"source\":\"0\",\"seqId\":325070069725}]}"}
{"action": "update", "capture_sequence": 110, "channel": "books", "connection_sequence": 1, "event": null, "instId": "BTC-USDT-SWAP", "local_receive_ts": "2026-06-21T04:27:06Z", "monotonic_ns": 1643582113518976, "raw": "{\"arg\":{\"channel\":\"books\",\"instId\":\"BTC-USDT-SWAP\"},\"action\":\"update\",\"data\":[{\"asks\":[[\"64479.9\",\"267.66\",\"0\",\"11\"],[\"64482.8\",\"0.02\",\"0\",\"2\"],[\"64482.9\",\"0.01\",\"0\",\"1\"],[\"64483.1\",\"0.62\",\"0\",\"3\"],[\"64484\",\"1.72\",\"0\",\"4\"],[\"64484.4\",\"77.54\",\"0\",\"1\"],[\"64485.1\",\"1.2\",\"0\",\"1\"],[\"64485.6\",\"0\",\"0\",\"0\"],[\"64485.9\",\"8.48\",\"0\",\"3\"],[\"64486.2\",\"0.17\",\"0\",\"6\"],[\"64486.5\",\"1.56\",\"0\",\"1\"],[\"64488.5\",\"1.56\",\"0\",\"1\"],[\"64489\",\"20.66\",\"0\",\"9\"],[\"64489.4\",\"20.56\",\"0\",\"8\"],[\"64489.7\",\"38.03\",\"0\",\"2\"],[\"64489.9\",\"1.56\",\"0\",\"1\"],[\"64490.4\",\"9.59\",\"0\",\"5\"],[\"64498.6\",\"3.59\",\"0\",\"7\"],[\"64498.7\",\"33.89\",\"0\",\"5\"],[\"64499.1\",\"3.26\",\"0\",\"5\"],[\"64499.3\",\"0.31\",\"0\",\"1\"],[\"64499.6\",\"63.39\",\"0\",\"5\"],[\"64505.9\",\"3.29\",\"0\",\"3\"],[\"64506.4\",\"201.74\",\"0\",\"5\"],[\"64507.1\",\"0.06\",\"0\",\"4\"],[\"64507.3\",\"0.03\",\"0\",\"2\"],[\"64508.3\",\"33.79\",\"0\",\"1\"],[\"64509.2\",\"0\",\"0\",\"0\"],[\"64511.9\",\"0.14\",\"0\",\"1\"],[\"64512.5\",\"58.34\",\"0\",\"6\"],[\"64512.8\",\"85.33\",\"0\",\"1\"],[\"64517.7\",\"18.68\",\"0\",\"4\"],[\"64518.9\",\"20.07\",\"0\",\"2\"],[\"64519.7\",\"10.81\",\"0\",\"7\"],[\"64520.9\",\"132.61\",\"0\",\"4\"],[\"64525.1\",\"0\",\"0\",\"0\"],[\"64525.2\",\"0\",\"0\",\"0\"],[\"64525.3\",\"0\",\"0\",\"0\"]],\"bids\":[[\"64479.8\",\"779.87\",\"0\",\"37\"],[\"64479.7\",\"28.96\",\"0\",\"5\"],[\"64479.2\",\"78.37\",\"0\",\"1\"],[\"64479\",\"6.56\",\"0\",\"2\"],[\"64470.1\",\"86.16\",\"0\",\"1\"],[\"64469\",\"33.81\",\"0\",\"1\"],[\"64468.8\",\"11.63\",\"0\",\"2\"],[\"64468.3\",\"20.08\",\"0\",\"1\"],[\"64467.8\",\"0.01\",\"0\",\"1\"],[\"64467.7\",\"0\",\"0\",\"0\"],[\"64467.5\",\"0.8\",\"0\",\"3\"],[\"64467.2\",\"85.39\",\"0\",\"1\"],[\"64466.6\",\"0.32\",\"0\",\"2\"],[\"64466.1\",\"0.38\",\"0\",\"1\"],[\"64466\",\"0.02\",\"0\",\"2\"],[\"64463.6\",\"12.13\",\"0\",\"4\"],[\"64463.4\",\"58.22\",\"0\",\"1\"],[\"64462.4\",\"0.56\",\"0\",\"2\"],[\"64460.9\",\"126.55\",\"0\",\"3\"],[\"64460.7\",\"44.95\",\"0\",\"2\"],[\"64452.6\",\"515.18\",\"0\",\"3\"],[\"64421.6\",\"0\",\"0\",\"0\"],[\"64421.5\",\"0\",\"0\",\"0\"],[\"64421.3\",\"0\",\"0\",\"0\"],[\"64421.2\",\"0\",\"0\",\"0\"]],\"ts\":\"1782016026205\",\"checksum\":413450844,\"seqId\":325070069814,\"prevSeqId\":325070069635}]}"}
{"action": "update", "capture_sequence": 111, "channel": "books", "connection_sequence": 1, "event": null, "instId": "BTC-USDT-SWAP", "local_receive_ts": "2026-06-21T04:27:06Z", "monotonic_ns": 1643582213429502, "raw": "{\"arg\":{\"channel\":\"books\",\"instId\":\"BTC-USDT-SWAP\"},\"action\":\"update\",\"data\":[{\"asks\":[[\"64479.9\",\"277.66\",\"0\",\"12\"],[\"64480.5\",\"0.01\",\"0\",\"1\"],[\"64480.6\",\"4.11\",\"0\",\"2\"],[\"64482.8\",\"0.01\",\"0\",\"1\"],[\"64484.9\",\"1.71\",\"0\",\"2\"],[\"64485.1\",\"16.72\",\"0\",\"2\"],[\"64485.6\",\"1.56\",\"0\",\"1\"],[\"64485.8\",\"1.61\",\"0\",\"4\"],[\"64485.9\",\"6.92\",\"0\",\"2\"],[\"64486\",\"52.65\",\"0\",\"7\"],[\"64486.5\",\"0\",\"0\",\"0\"],[\"64486.6\",\"82.88\",\"0\",\"3\"],[\"64489.4\",\"19\",\"0\",\"7\"],[\"64489.9\",\"0\",\"0\",\"0\"],[\"64490.4\",\"8.03\",\"0\",\"4\"],[\"64492\",\"0.04\",\"0\",\"4\"],[\"64492.3\",\"0.03\",\"0\",\"1\"],[\"64494.5\",\"0\",\"0\",\"0\"],[\"64494.7\",\"24.22\",\"0\",\"6\"],[\"64495.9\",\"0.84\",\"0\",\"3\"],[\"64496.2\",\"15.52\",\"0\",\"2\"],[\"64499.3\",\"0\",\"0\",\"0\"],[\"64499.8\",\"1.39\",\"0\",\"3\"],[\"64506.4\",\"200.97\",\"0\",\"4\"],[\"64507.1\",\"0.83\",\"0\",\"5\"],[\"64507.3\",\"33.82\",\"0\",\"3\"],[\"64508.3\",\"0\",\"0\",\"0\"],[\"64511.9\",\"85.47\",\"0\",\"2\"],[\"64512.5\",\"0.16\",\"0\",\"5\"],[\"64512.8\",\"0\",\"0\",\"0\"],[\"64513.2\",\"58.33\",\"0\",\"5\"],[\"64517.8\",\"20.16\",\"0\",\"4\"],[\"64518.9\",\"0.01\",\"0\",\"1\"],[\"64519.7\",\"96.91\",\"0\",\"8\"],[\"64520.9\",\"46.51\",\"0\",\"3\"],[\"64525.1\",\"0.46\",\"0\",\"1\"],[\"64525.2\",\"55.22\",\"0\",\"2\"],[\"64525.3\",\"0.01\",\"0\",\"1\"],[\"64525.4\",\"11.4\",\"0\",\"1\"]],\"bids\":[[\"64478.1\",\"0.81\",\"0\",\"2\"],[\"64470.1\",\"0\",\"0\",\"0\"],[\"64469\",\"0\",\"0\",\"0\"],[\"64468.8\",\"97.8\",\"0\",\"3\"],[\"64468.3\",\"0\",\"0\",\"0\"],[\"64467.6\",\"33.83\",\"0\",\"3\"],[\"64467.4\",\"66.62\",\"0\",\"2\"],[\"64467.3\",\"95.53\",\"0\",\"2\"],[\"64467.2\",\"0.31\",\"0\",\"1\"],[\"64466.6\",\"0.01\",\"0\",\"1\"],[\"64466\",\"85.41\",\"0\",\"3\"],[\"64464.2\",\"213.79\",\"0\",\"6\"],[\"64463.4\",\"0\",\"0\",\"0\"],[\"64459\",\"0\",\"0\",\"0\"],[\"64456.5\",\"27.76\",\"0\",\"3\"],[\"64452.7\",\"323.57\",\"0\",\"4\"],[\"64427.2\",\"0.02\",\"0\",\"2\"],[\"64421.6\",\"15.65\",\"0\",\"1\"],[\"64421.5\",\"0.01\",\"0\",\"1\"],[\"64421.3\",\"0.03\",\"0\",\"2\"],[\"64421.2\",\"0.01\",\"0\",\"1\"],[\"64421.1\",\"1.53\",\"0\",\"3\"]],\"ts\":\"1782016026305\",\"checksum\":1765352349,\"seqId\":325070069960,\"prevSeqId\":325070069814}]}"}
{"action": null, "capture_sequence": 112, "channel": "trades", "connection_sequence": 1, "event": null, "instId": "BTC-USDT-SWAP", "local_receive_ts": "2026-06-21T04:27:06Z", "monotonic_ns": 1643582287201636, "raw": "{\"arg\":{\"channel\":\"trades\",\"instId\":\"BTC-USDT-SWAP\"},\"data\":[{\"instId\":\"BTC-USDT-SWAP\",\"tradeId\":\"2718750179\",\"px\":\"64479.9\",\"sz\":\"1.07\",\"side\":\"buy\",\"ts\":\"1782016026384\",\"count\":\"1\",\"source\":\"0\",\"seqId\":325070070129}]}"}
{"action": "update", "capture_sequence": 113, "channel": "books", "connection_sequence": 1, "event": null, "instId": "BTC-USDT-SWAP", "local_receive_ts": "2026-06-21T04:27:06Z", "monotonic_ns": 1643582318119783, "raw": "{\"arg\":{\"channel\":\"books\",\"instId\":\"BTC-USDT-SWAP\"},\"action\":\"update\",\"data\":[{\"asks\":[[\"64479.9\",\"192.67\",\"0\",\"9\"],[\"64484.9\",\"0.15\",\"0\",\"1\"],[\"64485.1\",\"1.2\",\"0\",\"1\"],[\"64485.4\",\"1.56\",\"0\",\"1\"],[\"64485.5\",\"16.73\",\"0\",\"3\"],[\"64485.6\",\"0\",\"0\",\"0\"],[\"64486\",\"51.09\",\"0\",\"6\"],[\"64486.1\",\"1.56\",\"0\",\"1\"],[\"64489.4\",\"20.56\",\"0\",\"8\"],[\"64489.9\",\"1.56\",\"0\",\"1\"],[\"64490.5\",\"17.51\",\"0\",\"3\"],[\"64490.7\",\"0.07\",\"0\",\"3\"],[\"64492\",\"0.2\",\"0\",\"5\"],[\"64496.2\",\"0.01\",\"0\",\"1\"],[\"64496.5\",\"15.51\",\"0\",\"1\"],[\"64496.9\",\"0.22\",\"0\",\"1\"],[\"64498.7\",\"2.86\",\"0\",\"4\"],[\"64499.3\",\"31.03\",\"0\",\"1\"],[\"64499.6\",\"63.37\",\"0\",\"3\"],[\"64499.7\",\"35.39\",\"0\",\"7\"],[\"64499.8\",\"1.08\",\"0\",\"2\"],[\"64500.2\",\"0.33\",\"0\",\"3\"],[\"64501.2\",\"15.68\",\"0\",\"4\"],[\"64501.6\",\"3.44\",\"0\",\"4\"],[\"64501.8\",\"91.08\",\"0\",\"8\"],[\"64507.1\",\"0.06\",\"0\",\"4\"],[\"64507.3\",\"0.03\",\"0\",\"2\"],[\"64507.7\",\"0.84\",\"0\",\"5\"],[\"64508.3\",\"33.79\",\"0\",\"1\"],[\"64510.4\",\"4.13\",\"0\",\"4\"],[\"64511.9\",\"0.14\",\"0\",\"1\"],[\"64512.5\",\"85.49\",\"0\",\"6\"],[\"64513.2\",\"0.15\",\"0\",\"4\"],[\"64514.1\",\"58.19\",\"0\",\"2\"],[\"64517.8\",\"0.1\",\"0\",\"3\"],[\"64518.5\",\"20.07\",\"0\",\"2\"],[\"64519.7\",\"10.81\",\"0\",\"7\"],[\"64520.9\",\"132.61\",\"0\",\"4\"],[\"64525\",\"0\",\"0\",\"0\"],[\"64525.1\",\"0\",\"0\",\"0\"],[\"64525.2\",\"0\",\"0\",\"0\"],[\"64525.3\",\"0\",\"0\",\"0\"],[\"64525.4\",\"0\",\"0\",\"0\"]],\"bids\":[[\"64479.8\",\"780.45\",\"0\",\"37\"],[\"64478.6\",\"0.79\",\"0\",\"2\"],[\"64476.8\",\"3.4\",\"0\",\"2\"],[\"64476.4\",\"0.77\",\"0\",\"1\"],[\"64474.7\",\"77.55\",\"0\",\"2\"],[\"64474.5\",\"0\",\"0\",\"0\"],[\"64474.2\",\"1.8\",\"0\",\"1\"],[\"64471.8\",\"0\",\"0\",\"0\"],[\"64470.1\",\"86.16\",\"0\",\"1\"],[\"64469\",\"33.81\",\"0\",\"1\"],[\"64468.8\",\"11.63\",\"0\",\"2\"],[\"64468.3\",\"0.77\",\"0\",\"1\"],[\"64467.8\",\"20.09\",\"0\",\"2\"],[\"64467.7\",\"0.31\",\"0\",\"1\"],[\"64467.6\",\"0.02\",\"0\",\"2\"],[\"64467.5\",\"0.03\",\"0\",\"2\"],[\"64467.4\",\"46.54\",\"0\",\"1\"],[\"64467.2\",\"0\",\"0\",\"0\"],[\"64466.6\",\"85.4\",\"0\",\"2\"],[\"64466\",\"0.02\",\"0\",\"2\"],[\"64465\",\"58.22\",\"0\",\"1\"],[\"64464.2\",\"155.57\",\"0\",\"5\"],[\"64461.2\",\"31.11\",\"0\",\"4\"],[\"64460.9\",\"95.5\",\"0\",\"2\"],[\"64460.8\",\"274.87\",\"0\",\"5\"],[\"64459\",\"3.11\",\"0\",\"1\"],[\"64452.6\",\"515.37\",\"0\",\"4\"],[\"64421.5\",\"0\",\"0\",\"0\"],[\"64421.3\",\"0\",\"0\",\"0\"],[\"64421.2\",\"0\",\"0\",\"0\"],[\"64421.1\",\"0\",\"0\",\"0\"]],\"ts\":\"1782016026405\",\"checksum\":-1709968704,\"seqId\":325070070150,\"prevSeqId\":325070069960}]}"}
{"action": "update", "capture_sequence": 114, "channel": "books", "connection_sequence": 1, "event": null, "instId": "BTC-USDT-SWAP", "local_receive_ts": "2026-06-21T04:27:06Z", "monotonic_ns": 1643582408874637, "raw": "{\"arg\":{\"channel\":\"books\",\"instId\":\"BTC-USDT-SWAP\"},\"action\":\"update\",\"data\":[{\"asks\":[[\"64480.5\",\"0\",\"0\",\"0\"],[\"64480.6\",\"0.01\",\"0\",\"1\"],[\"64482.9\",\"0.02\",\"0\",\"2\"],[\"64485.4\",\"0\",\"0\",\"0\"],[\"64486.1\",\"0\",\"0\",\"0\"],[\"64486.6\",\"81.32\",\"0\",\"2\"],[\"64486.8\",\"1.46\",\"0\",\"5\"],[\"64490.4\",\"9.59\",\"0\",\"5\"],[\"64494.7\",\"24.05\",\"0\",\"5\"],[\"64495.8\",\"0.21\",\"0\",\"4\"],[\"64525\",\"2.51\",\"0\",\"18\"],[\"64525.1\",\"0.46\",\"0\",\"1\"],[\"64525.2\",\"55.22\",\"0\",\"2\"]],\"bids\":[[\"64479.8\",\"775.27\",\"0\",\"37\"],[\"64478.1\",\"0.01\",\"0\",\"1\"],[\"64476.8\",\"3.09\",\"0\",\"1\"],[\"64476.7\",\"0.32\",\"0\",\"2\"]],\"ts\":\"1782016026505\",\"checksum\":633985065,\"seqId\":325070070254,\"prevSeqId\":325070070150}]}"}
{"action": "update", "capture_sequence": 115, "channel": "books", "connection_sequence": 1, "event": null, "instId": "BTC-USDT-SWAP", "local_receive_ts": "2026-06-21T04:27:06Z", "monotonic_ns": 1643582508907583, "raw": "{\"arg\":{\"channel\":\"books\",\"instId\":\"BTC-USDT-SWAP\"},\"action\":\"update\",\"data\":[{\"asks\":[[\"64485\",\"57.47\",\"0\",\"3\"],[\"64485.5\",\"1.21\",\"0\",\"2\"],[\"64487.1\",\"0.53\",\"0\",\"4\"],[\"64490.9\",\"2.01\",\"0\",\"4\"],[\"64498.9\",\"80.99\",\"0\",\"4\"],[\"64499.3\",\"0\",\"0\",\"0\"],[\"64500.1\",\"0.05\",\"0\",\"4\"],[\"64500.8\",\"0.37\",\"0\",\"2\"],[\"64512.9\",\"75.97\",\"0\",\"5\"],[\"64514.1\",\"0.01\",\"0\",\"1\"],[\"64519.7\",\"96.91\",\"0\",\"8\"],[\"64520.9\",\"46.51\",\"0\",\"3\"],[\"64525.3\",\"0.01\",\"0\",\"1\"]],\"bids\":[[\"64479.8\",\"788.7\",\"0\",\"38\"],[\"64470.1\",\"0\",\"0\",\"0\"],[\"64469.4\",\"132.71\",\"0\",\"2\"],[\"64465\",\"0\",\"0\",\"0\"],[\"64463.7\",\"58.24\",\"0\",\"2\"],[\"64461.2\",\"0.06\",\"0\",\"3\"],[\"64461\",\"231.05\",\"0\",\"2\"],[\"64421.5\",\"0.01\",\"0\",\"1\"],[\"64421.3\",\"0.03\",\"0\",\"2\"]],\"ts\":\"1782016026605\",\"checksum\":1381021425,\"seqId\":325070070359,\"prevSeqId\":325070070254}]}"}
{"action": "update", "capture_sequence": 116, "channel": "books", "connection_sequence": 1, "event": null, "instId": "BTC-USDT-SWAP", "local_receive_ts": "2026-06-21T04:27:06Z", "monotonic_ns": 1643582608912953, "raw": "{\"arg\":{\"channel\":\"books\",\"instId\":\"BTC-USDT-SWAP\"},\"action\":\"update\",\"data\":[{\"asks\":[[\"64479.9\",\"202.79\",\"0\",\"12\"],[\"64485\",\"41.95\",\"0\",\"2\"],[\"64485.4\",\"15.52\",\"0\",\"1\"],[\"64489.4\",\"5.26\",\"0\",\"7\"],[\"64489.5\",\"16.75\",\"0\",\"4\"],[\"64489.6\",\"15.42\",\"0\",\"3\"],[\"64495.8\",\"0.04\",\"0\",\"3\"],[\"64495.9\",\"1.01\",\"0\",\"4\"],[\"64500.2\",\"0.02\",\"0\",\"2\"],[\"64500.4\",\"0.34\",\"0\",\"4\"],[\"64507.7\",\"34.63\",\"0\",\"6\"],[\"64508.3\",\"0\",\"0\",\"0\"]],\"bids\":[[\"64476.7\",\"0.01\",\"0\",\"1\"],[\"64476.6\",\"0.32\",\"0\",\"2\"],[\"64469\",\"0\",\"0\",\"0\"],[\"64468.4\",\"33.81\",\"0\",\"1\"],[\"64467.9\",\"0.32\",\"0\",\"2\"],[\"64467.8\",\"0.01\",\"0\",\"1\"],[\"64467.7\",\"0\",\"0\",\"0\"],[\"64467.6\",\"20.1\",\"0\",\"3\"],[\"64421.2\",\"0.01\",\"0\",\"1\"]],\"ts\":\"1782016026705\",\"checksum\":1819687540,\"seqId\":325070070471,\"prevSeqId\":325070070359}]}"}
{"action": "update", "capture_sequence": 117, "channel": "books", "connection_sequence": 1, "event": null, "instId": "BTC-USDT-SWAP", "local_receive_ts": "2026-06-21T04:27:06Z", "monotonic_ns": 1643582708829597, "raw": "{\"arg\":{\"channel\":\"books\",\"instId\":\"BTC-USDT-SWAP\"},\"action\":\"update\",\"data\":[{\"asks\":[[\"64479.9\",\"202.77\",\"0\",\"11\"],[\"64485\",\"57.47\",\"0\",\"3\"],[\"64485.4\",\"0\",\"0\",\"0\"],[\"64490.7\",\"0.06\",\"0\",\"2\"],[\"64491\",\"68.5\",\"0\",\"4\"],[\"64492\",\"0.04\",\"0\",\"4\"],[\"64506.7\",\"0.96\",\"0\",\"16\"],[\"64507.7\",\"33.86\",\"0\",\"5\"],[\"64512.5\",\"0.16\",\"0\",\"5\"],[\"64513.2\",\"85.48\",\"0\",\"5\"],[\"64518.5\",\"0.01\",\"0\",\"1\"],[\"64519.2\",\"20.54\",\"0\",\"8\"],[\"64519.7\",\"10.81\",\"0\",\"7\"],[\"64520.9\",\"132.61\",\"0\",\"4\"],[\"64525.4\",\"11.18\",\"0\",\"1\"]],\"bids\":[[\"64470.1\",\"86.16\",\"0\",\"1\"],[\"64469.4\",\"46.54\",\"0\",\"1\"],[\"64468.8\",\"31.71\",\"0\",\"3\"],[\"64468.3\",\"0\",\"0\",\"0\"],[\"64467.9\",\"0.01\",\"0\",\"1\"],[\"64467.7\",\"0.77\",\"0\",\"1\"],[\"64467.6\",\"0.33\",\"0\",\"3\"],[\"64467.5\",\"85.42\",\"0\",\"3\"],[\"64466.6\",\"0.01\",\"0\",\"1\"],[\"64459\",\"0\",\"0\",\"0\"],[\"64452.6\",\"515.18\",\"0\",\"3\"]],\"ts\":\"1782016026805\",\"checksum\":-989624921,\"seqId\":325070070568,\"prevSeqId\":325070070471}]}"}
{"action": null, "capture_sequence": 118, "channel": "trades", "connection_sequence": 1, "event": null, "instId": "BTC-USDT-SWAP", "local_receive_ts": "2026-06-21T04:27:06Z", "monotonic_ns": 1643582792579680, "raw": "{\"arg\":{\"channel\":\"trades\",\"instId\":\"BTC-USDT-SWAP\"},\"data\":[{\"instId\":\"BTC-USDT-SWAP\",\"tradeId\":\"2718750182\",\"px\":\"64479.8\",\"sz\":\"33.72\",\"side\":\"sell\",\"ts\":\"1782016026889\",\"count\":\"3\",\"source\":\"0\",\"seqId\":325070070668}]}"}
{"action": "update", "capture_sequence": 119, "channel": "books", "connection_sequence": 1, "event": null, "instId": "BTC-USDT-SWAP", "local_receive_ts": "2026-06-21T04:27:07Z", "monotonic_ns": 1643582809411080, "raw": "{\"arg\":{\"channel\":\"books\",\"instId\":\"BTC-USDT-SWAP\"},\"action\":\"update\",\"data\":[{\"asks\":[[\"64480\",\"50.85\",\"0\",\"7\"],[\"64482\",\"45.6\",\"0\",\"3\"],[\"64482.7\",\"137.14\",\"0\",\"3\"],[\"64483.5\",\"0.01\",\"0\",\"1\"],[\"64483.6\",\"61.89\",\"0\",\"3\"],[\"64484.6\",\"2.41\",\"0\",\"3\"],[\"64484.7\",\"15.68\",\"0\",\"2\"],[\"64485\",\"41.95\",\"0\",\"2\"],[\"64487.5\",\"0.04\",\"0\",\"3\"],[\"64488\",\"57.87\",\"0\",\"27\"],[\"64488.5\",\"0\",\"0\",\"0\"],[\"64488.7\",\"6.24\",\"0\",\"2\"],[\"64492.1\",\"0.16\",\"0\",\"1\"],[\"64492.5\",\"115.49\",\"0\",\"5\"],[\"64495.7\",\"11.52\",\"0\",\"4\"],[\"64495.9\",\"0.84\",\"0\",\"3\"],[\"64505.9\",\"1.01\",\"0\",\"2\"],[\"64506.7\",\"0.19\",\"0\",\"15\"],[\"64507.1\",\"0.83\",\"0\",\"5\"],[\"64512.1\",\"85.37\",\"0\",\"4\"],[\"64513.2\",\"0.15\",\"0\",\"4\"],[\"64518\",\"131.11\",\"0\",\"15\"],[\"64519.2\",\"0.48\",\"0\",\"7\"],[\"64519.7\",\"96.91\",\"0\",\"8\"],[\"64520.9\",\"46.51\",\"0\",\"3\"]],\"bids\":[[\"64479.8\",\"753.42\",\"0\",\"35\"],[\"64479\",\"5\",\"0\",\"1\"],[\"64478.5\",\"0.01\",\"0\",\"1\"],[\"64478\",\"0.01\",\"0\",\"1\"],[\"64477.5\",\"0\",\"0\",\"0\"],[\"64474.2\",\"0\",\"0\",\"0\"],[\"64472.1\",\"1.85\",\"0\",\"3\"],[\"64470.1\",\"0\",\"0\",\"0\"],[\"64469.4\",\"132.71\",\"0\",\"2\"],[\"64468.8\",\"11.63\",\"0\",\"2\"],[\"64467.6\",\"20.41\",\"0\",\"4\"],[\"64467.5\",\"0.03\",\"0\",\"2\"],[\"64466.3\",\"85.39\",\"0\",\"1\"],[\"64459.1\",\"49.65\",\"0\",\"2\"],[\"64452.7\",\"323.76\",\"0\",\"5\"],[\"64421.1\",\"1.53\",\"0\",\"3\"],[\"64420.9\",\"0.01\",\"0\",\"1\"]],\"ts\":\"1782016026905\",\"checksum\":-319182907,\"seqId\":325070070694,\"prevSeqId\":325070070568}]}"}
{"action": null, "capture_sequence": 120, "channel": "trades", "connection_sequence": 1, "event": null, "instId": "BTC-USDT-SWAP", "local_receive_ts": "2026-06-21T04:27:07Z", "monotonic_ns": 1643582834693074, "raw": "{\"arg\":{\"channel\":\"trades\",\"instId\":\"BTC-USDT-SWAP\"},\"data\":[{\"instId\":\"BTC-USDT-SWAP\",\"tradeId\":\"2718750183\",\"px\":\"64479.8\",\"sz\":\"0.06\",\"side\":\"sell\",\"ts\":\"1782016026931\",\"count\":\"1\",\"source\":\"0\",\"seqId\":325070070712}]}"}
{"action": "update", "capture_sequence": 121, "channel": "books", "connection_sequence": 1, "event": null, "instId": "BTC-USDT-SWAP", "local_receive_ts": "2026-06-21T04:27:07Z", "monotonic_ns": 1643582908855456, "raw": "{\"arg\":{\"channel\":\"books\",\"instId\":\"BTC-USDT-SWAP\"},\"action\":\"update\",\"data\":[{\"asks\":[[\"64479.9\",\"192.77\",\"0\",\"10\"],[\"64482.8\",\"1.57\",\"0\",\"2\"],[\"64483.5\",\"1.57\",\"0\",\"2\"],[\"64484\",\"3.28\",\"0\",\"5\"],[\"64484.2\",\"15.53\",\"0\",\"2\"],[\"64484.5\",\"1.62\",\"0\",\"4\"],[\"64484.7\",\"0.16\",\"0\",\"1\"],[\"64491\",\"68.49\",\"0\",\"3\"],[\"64491.1\",\"0.01\",\"0\",\"1\"],[\"64496.2\",\"15.52\",\"0\",\"2\"],[\"64496.5\",\"0\",\"0\",\"0\"],[\"64500.1\",\"0.06\",\"0\",\"5\"],[\"64500.8\",\"0.36\",\"0\",\"1\"],[\"64501.3\",\"1.57\",\"0\",\"2\"],[\"64501.6\",\"1.89\",\"0\",\"3\"]],\"bids\":[[\"64479.8\",\"753.36\",\"0\",\"35\"],[\"64479.7\",\"30.52\",\"0\",\"6\"],[\"64479.2\",\"79.93\",\"0\",\"2\"],[\"64478.7\",\"1.56\",\"0\",\"1\"],[\"64478.6\",\"0.78\",\"0\",\"1\"],[\"64478.1\",\"0\",\"0\",\"0\"],[\"64477.6\",\"0.01\",\"0\",\"1\"],[\"64474.7\",\"0.01\",\"0\",\"1\"],[\"64474.5\",\"77.54\",\"0\",\"1\"],[\"64420.9\",\"0\",\"0\",\"0\"]],\"ts\":\"1782016027005\",\"checksum\":-2102355096,\"seqId\":325070070786,\"prevSeqId\":325070070694}]}"}
{"action": "update", "capture_sequence": 122, "channel": "books", "connection_sequence": 1, "event": null, "instId": "BTC-USDT-SWAP", "local_receive_ts": "2026-06-21T04:27:07Z", "monotonic_ns": 1643583009247498, "raw": "{\"arg\":{\"channel\":\"books\",\"instId\":\"BTC-USDT-SWAP\"},\"action\":\"update\",\"data\":[{\"asks\":[[\"64479.9\",\"202.77\",\"0\",\"11\"],[\"64482.3\",\"0.01\",\"0\",\"1\"],[\"64482.8\",\"0.01\",\"0\",\"1\"],[\"64482.9\",\"0.01\",\"0\",\"1\"],[\"64484.2\",\"0.01\",\"0\",\"1\"],[\"64484.5\",\"17.14\",\"0\",\"5\"],[\"64485\",\"43.51\",\"0\",\"3\"],[\"64485.4\",\"1.56\",\"0\",\"1\"],[\"64485.9\",\"8.48\",\"0\",\"3\"],[\"64489.9\",\"0\",\"0\",\"0\"],[\"64490.4\",\"8.03\",\"0\",\"4\"],[\"64490.9\",\"0.45\",\"0\",\"3\"],[\"64495.6\",\"0.18\",\"0\",\"2\"],[\"64495.7\",\"11.35\",\"0\",\"3\"],[\"64498.2\",\"0.04\",\"0\",\"3\"],[\"64500.7\",\"5.75\",\"0\",\"2\"],[\"64512.9\",\"17.79\",\"0\",\"4\"],[\"64513.9\",\"58.3\",\"0\",\"2\"],[\"64525.4\",\"0\",\"0\",\"0\"]],\"bids\":[[\"64479.8\",\"763.36\",\"0\",\"36\"],[\"64479.7\",\"28.96\",\"0\",\"5\"],[\"64479.3\",\"1.58\",\"0\",\"2\"],[\"64479.2\",\"78.37\",\"0\",\"1\"],[\"64478.8\",\"1.57\",\"0\",\"2\"],[\"64478.7\",\"0.77\",\"0\",\"2\"],[\"64478.6\",\"0\",\"0\",\"0\"],[\"64478.3\",\"1.57\",\"0\",\"2\"],[\"64477.8\",\"1.56\",\"0\",\"1\"],[\"64476.5\",\"14.5\",\"0\",\"3\"],[\"64474.2\",\"1.56\",\"0\",\"1\"],[\"64469.6\",\"98.18\",\"0\",\"4\"],[\"64469.4\",\"46.54\",\"0\",\"1\"],[\"64467.8\",\"0.32\",\"0\",\"2\"],[\"64467.6\",\"20.1\",\"0\",\"3\"],[\"64464.7\",\"58.22\",\"0\",\"1\"],[\"64463.7\",\"0.02\",\"0\",\"1\"],[\"64421.3\",\"0\",\"0\",\"0\"],[\"64421.2\",\"0\",\"0\",\"0\"],[\"64421.1\",\"0\",\"0\",\"0\"]],\"ts\":\"1782016027105\",\"checksum\":-1051964743,\"seqId\":325070070965,\"prevSeqId\":325070070786}]}"}
{"action": null, "capture_sequence": 123, "channel": "trades", "connection_sequence": 1, "event": null, "instId": "BTC-USDT-SWAP", "local_receive_ts": "2026-06-21T04:27:07Z", "monotonic_ns": 1643583014416386, "raw": "{\"arg\":{\"channel\":\"trades\",\"instId\":\"BTC-USDT-SWAP\"},\"data\":[{\"instId\":\"BTC-USDT-SWAP\",\"tradeId\":\"2718750184\",\"px\":\"64479.8\",\"sz\":\"1.95\",\"side\":\"sell\",\"ts\":\"1782016027111\",\"count\":\"1\",\"source\":\"0\",\"seqId\":325070070971}]}"}
{"action": null, "capture_sequence": 124, "channel": "trades", "connection_sequence": 1, "event": null, "instId": "BTC-USDT-SWAP", "local_receive_ts": "2026-06-21T04:27:07Z", "monotonic_ns": 1643583103639651, "raw": "{\"arg\":{\"channel\":\"trades\",\"instId\":\"BTC-USDT-SWAP\"},\"data\":[{\"instId\":\"BTC-USDT-SWAP\",\"tradeId\":\"2718750185\",\"px\":\"64479.9\",\"sz\":\"0.39\",\"side\":\"buy\",\"ts\":\"1782016027200\",\"count\":\"1\",\"source\":\"0\",\"seqId\":325070071249}]}"}
{"action": "update", "capture_sequence": 125, "channel": "books", "connection_sequence": 1, "event": null, "instId": "BTC-USDT-SWAP", "local_receive_ts": "2026-06-21T04:27:07Z", "monotonic_ns": 1643583113560974, "raw": "{\"arg\":{\"channel\":\"books\",\"instId\":\"BTC-USDT-SWAP\"},\"action\":\"update\",\"data\":[{\"asks\":[[\"64479.9\",\"212.32\",\"0\",\"10\"],[\"64482\",\"45.61\",\"0\",\"4\"],[\"64482.3\",\"0\",\"0\",\"0\"],[\"64483.1\",\"0.61\",\"0\",\"2\"],[\"64483.5\",\"0.01\",\"0\",\"1\"],[\"64484\",\"1.72\",\"0\",\"4\"],[\"64484.2\",\"1.57\",\"0\",\"2\"],[\"64484.5\",\"0.06\",\"0\",\"3\"],[\"64486.2\",\"0.16\",\"0\",\"5\"],[\"64486.4\",\"2.84\",\"0\",\"4\"],[\"64486.9\",\"1.67\",\"0\",\"2\"],[\"64487.4\",\"2.36\",\"0\",\"8\"],[\"64487.8\",\"1.66\",\"0\",\"5\"],[\"64488.3\",\"1.58\",\"0\",\"3\"],[\"64489\",\"19.1\",\"0\",\"8\"],[\"64489.4\",\"3.7\",\"0\",\"6\"],[\"64492.6\",\"0\",\"0\",\"0\"],[\"64492.8\",\"35.39\",\"0\",\"10\"],[\"64496.2\",\"0.01\",\"0\",\"1\"],[\"64496.3\",\"459.84\",\"0\",\"6\"],[\"64496.6\",\"47.19\",\"0\",\"3\"],[\"64498.9\",\"49.96\",\"0\",\"3\"],[\"64499.5\",\"0\",\"0\",\"0\"],[\"64499.7\",\"66.41\",\"0\",\"7\"],[\"64500\",\"3487.28\",\"0\",\"1036\"],[\"64500.1\",\"0.05\",\"0\",\"4\"],[\"64500.2\",\"232.8\",\"0\",\"3\"],[\"64500.4\",\"0.03\",\"0\",\"3\"],[\"64500.6\",\"0.7\",\"0\",\"4\"],[\"64501.3\",\"0.02\",\"0\",\"1\"],[\"64501.5\",\"1.58\",\"0\",\"5\"],[\"64502.1\",\"1.56\",\"0\",\"2\"],[\"64507.1\",\"0.06\",\"0\",\"4\"],[\"64507.3\",\"0.8\",\"0\",\"3\"],[\"64507.4\",\"61.1\",\"0\",\"6\"],[\"64507.7\",\"0.07\",\"0\",\"4\"],[\"64525.4\",\"11.18\",\"0\",\"1\"],[\"64525.5\",\"0.02\",\"0\",\"1\"],[\"64525.6\",\"37.24\",\"0\",\"2\"]],\"bids\":[[\"64479.8\",\"773.43\",\"0\",\"39\"],[\"64479.7\",\"30.52\",\"0\",\"6\"],[\"64479.3\",\"0.02\",\"0\",\"1\"],[\"64476.9\",\"0.34\",\"0\",\"4\"],[\"64476.6\",\"0.01\",\"0\",\"1\"],[\"64476.5\",\"26.91\",\"0\",\"4\"],[\"64476.2\",\"291.69\",\"0\",\"3\"],[\"64475.3\",\"77.54\",\"0\",\"1\"],[\"64474.5\",\"0\",\"0\",\"0\"],[\"64474.4\",\"0.3\",\"0\",\"1\"],[\"64469.6\",\"12.01\",\"0\",\"3\"],[\"64469.4\",\"132.71\",\"0\",\"2\"],[\"64468.4\",\"0\",\"0\",\"0\"],[\"64468.3\",\"34.58\",\"0\",\"2\"],[\"64467.7\",\"0\",\"0\",\"0\"],[\"64461.7\",\"31.06\",\"0\",\"2\"],[\"64461.2\",\"232.98\",\"0\",\"4\"],[\"64461\",\"200\",\"0\",\"1\"],[\"64460.2\",\"0\",\"0\",\"0\"],[\"64421.3\",\"0.03\",\"0\",\"2\"],[\"64421.2\",\"0.01\",\"0\",\"1\"]],\"ts\":\"1782016027205\",\"checksum\":-2134474552,\"seqId\":325070071286,\"prevSeqId\":325070070965}]}"}
{"action": null, "capture_sequence": 126, "channel": "trades", "connection_sequence": 1, "event": null, "instId": "BTC-USDT-SWAP", "local_receive_ts": "2026-06-21T04:27:07Z", "monotonic_ns": 1643583119808956, "raw": "{\"arg\":{\"channel\":\"trades\",\"instId\":\"BTC-USDT-SWAP\"},\"data\":[{\"instId\":\"BTC-USDT-SWAP\",\"tradeId\":\"2718750186\",\"px\":\"64479.9\",\"sz\":\"0.02\",\"side\":\"buy\",\"ts\":\"1782016027216\",\"count\":\"1\",\"source\":\"0\",\"seqId\":325070071341}]}"}
{"action": null, "capture_sequence": 127, "channel": "trades", "connection_sequence": 1, "event": null, "instId": "BTC-USDT-SWAP", "local_receive_ts": "2026-06-21T04:27:07Z", "monotonic_ns": 1643583129090446, "raw": "{\"arg\":{\"channel\":\"trades\",\"instId\":\"BTC-USDT-SWAP\"},\"data\":[{\"instId\":\"BTC-USDT-SWAP\",\"tradeId\":\"2718750187\",\"px\":\"64479.8\",\"sz\":\"3\",\"side\":\"sell\",\"ts\":\"1782016027226\",\"count\":\"1\",\"source\":\"0\",\"seqId\":325070071367}]}"}
{"action": null, "capture_sequence": 128, "channel": "trades", "connection_sequence": 1, "event": null, "instId": "BTC-USDT-SWAP", "local_receive_ts": "2026-06-21T04:27:07Z", "monotonic_ns": 1643583170675952, "raw": "{\"arg\":{\"channel\":\"trades\",\"instId\":\"BTC-USDT-SWAP\"},\"data\":[{\"instId\":\"BTC-USDT-SWAP\",\"tradeId\":\"2718750192\",\"px\":\"64479.9\",\"sz\":\"3.2\",\"side\":\"buy\",\"ts\":\"1782016027267\",\"count\":\"5\",\"source\":\"0\",\"seqId\":325070071483}]}"}
