{"action": "update", "capture_sequence": 405, "channel": "books", "connection_sequence": 3, "event": null, "instId": "BTC-USDT-SWAP", "local_receive_ts": "2026-06-21T04:27:29Z", "monotonic_ns": 1643605310659809, "raw": "{\"arg\":{\"channel\":\"books\",\"instId\":\"BTC-USDT-SWAP\"},\"action\":\"update\",\"data\":[{\"asks\":[[\"64497.3\",\"41.3\",\"0\",\"5\"]],\"bids\":[[\"64482.9\",\"482.6\",\"0\",\"30\"],[\"64480\",\"78.72\",\"0\",\"6\"],[\"64479.6\",\"0.02\",\"0\",\"2\"],[\"64478.8\",\"1.56\",\"0\",\"1\"],[\"64478.1\",\"15.51\",\"0\",\"2\"],[\"64477.8\",\"0\",\"0\",\"0\"],[\"64477.5\",\"3.56\",\"0\",\"5\"],[\"64477.4\",\"151.27\",\"0\",\"3\"],[\"64477.3\",\"77.54\",\"0\",\"1\"],[\"64476.8\",\"0\",\"0\",\"0\"],[\"64473.3\",\"0.01\",\"0\",\"1\"],[\"64466.9\",\"0.02\",\"0\",\"1\"],[\"64465.5\",\"0\",\"0\",\"0\"],[\"64464.5\",\"3.22\",\"0\",\"3\"],[\"64464.4\",\"0.03\",\"0\",\"2\"],[\"64464.1\",\"0\",\"0\",\"0\"],[\"64463.2\",\"0.02\",\"0\",\"1\"],[\"64462.1\",\"14.43\",\"0\",\"2\"]],\"ts\":\"1782016049405\",\"checksum\":1554148039,\"seqId\":325070095717,\"prevSeqId\":325070095635}]}"}
{"action": null, "capture_sequence": 406, "channel": "trades", "connection_sequence": 3, "event": null, "instId": "BTC-USDT-SWAP", "local_receive_ts": "2026-06-21T04:27:29Z", "monotonic_ns": 1643605371587530, "raw": "{\"arg\":{\"channel\":\"trades\",\"instId\":\"BTC-USDT-SWAP\"},\"data\":[{\"instId\":\"BTC-USDT-SWAP\",\"tradeId\":\"2718750356\",\"px\":\"64482.9\",\"sz\":\"100\",\"side\":\"sell\",\"ts\":\"1782016049466\",\"count\":\"5\",\"source\":\"0\",\"seqId\":325070095734}]}"}
{"action": "update", "capture_sequence": 407, "channel": "books", "connection_sequence": 3, "event": null, "instId": "BTC-USDT-SWAP", "local_receive_ts": "2026-06-21T04:27:29Z", "monotonic_ns": 1643605413457876, "raw": "{\"arg\":{\"channel\":\"books\",\"instId\":\"BTC-USDT-SWAP\"},\"action\":\"update\",\"data\":[{\"asks\":[[\"64483\",\"658.35\",\"0\",\"51\"],[\"64483.2\",\"0.4\",\"0\",\"1\"],[\"64484.1\",\"35.61\",\"0\",\"1\"],[\"64484.7\",\"0\",\"0\",\"0\"],[\"64484.8\",\"0\",\"0\",\"0\"],[\"64498.8\",\"512.06\",\"0\",\"4\"],[\"64499.3\",\"0\",\"0\",\"0\"],[\"64501.5\",\"32.6\",\"0\",\"5\"],[\"64502.1\",\"0.01\",\"0\",\"1\"],[\"64509.8\",\"143.53\",\"0\",\"3\"],[\"64510.4\",\"0.03\",\"0\",\"3\"],[\"64510.6\",\"0.19\",\"0\",\"2\"],[\"64527.1\",\"0.46\",\"0\",\"1\"],[\"64527.2\",\"0.18\",\"0\",\"4\"]],\"bids\":[[\"64482.9\",\"332.6\",\"0\",\"25\"],[\"64482.6\",\"3.29\",\"0\",\"2\"],[\"64482\",\"7.77\",\"0\",\"3\"],[\"64481.2\",\"0.7\",\"0\",\"1\"],[\"64478.8\",\"0\",\"0\",\"0\"],[\"64478.1\",\"13.95\",\"0\",\"1\"],[\"64478\",\"0.01\",\"0\",\"1\"],[\"64477.5\",\"14.41\",\"0\",\"5\"],[\"64477.1\",\"1.57\",\"0\",\"2\"],[\"64477\",\"0.01\",\"0\",\"1\"],[\"64476.9\",\"4.02\",\"0\",\"3\"],[\"64476.7\",\"4.78\",\"0\",\"2\"],[\"64476.1\",\"264.05\",\"0\",\"3\"],[\"64475.7\",\"0\",\"0\",\"0\"],[\"64475.2\",\"0\",\"0\",\"0\"],[\"64474.7\",\"0.01\",\"0\",\"1\"],[\"64468.8\",\"11.33\",\"0\",\"1\"],[\"64467.4\",\"132.71\",\"0\",\"2\"],[\"64464.9\",\"0\",\"0\",\"0\"],[\"64464.8\",\"0.01\",\"0\",\"1\"],[\"64464.7\",\"0\",\"0\",\"0\"],[\"64464.3\",\"116.45\",\"0\",\"2\"],[\"64462.2\",\"0\",\"0\",\"0\"],[\"64461.5\",\"58.25\",\"0\",\"3\"],[\"64423.2\",\"38.43\",\"0\",\"2\"],[\"64423.1\",\"92.81\",\"0\",\"2\"],[\"64423\",\"1.59\",\"0\",\"6\"],[\"64422.8\",\"1.51\",\"0\",\"2\"]],\"ts\":\"1782016049505\",\"checksum\":-2033477467,\"seqId\":325070095783,\"prevSeqId\":325070095717}]}"}
{"action": null, "capture_sequence": 408, "channel": "trades", "connection_sequence": 3, "event": null, "instId": "BTC-USDT-SWAP", "local_receive_ts": "2026-06-21T04:27:29Z", "monotonic_ns": 1643605487905493, "raw": "{\"arg\":{\"channel\":\"trades\",\"instId\":\"BTC-USDT-SWAP\"},\"data\":[{\"instId\":\"BTC-USDT-SWAP\",\"tradeId\":\"2718750362\",\"px\":\"64482.9\",\"sz\":\"21.07\",\"side\":\"sell\",\"ts\":\"1782016049582\",\"count\":\"6\",\"source\":\"0\",\"seqId\":325070095850}]}"}
{"action": "update", "capture_sequence": 409, "channel": "books", "connection_sequence": 3, "event": null, "instId": "BTC-USDT-SWAP", "local_receive_ts": "2026-06-21T04:27:29Z", "monotonic_ns": 1643605515979932, "raw": "{\"arg\":{\"channel\":\"books\",\"instId\":\"BTC-USDT-SWAP\"},\"action\":\"update\",\"data\":[{\"asks\":[[\"64483\",\"658.45\",\"0\",\"52\"],[\"64490.1\",\"0.3\",\"0\",\"2\"],[\"64490.9\",\"0.08\",\"0\",\"3\"],[\"64498.5\",\"38.96\",\"0\",\"6\"],[\"64498.8\",\"496.55\",\"0\",\"3\"],[\"64500.4\",\"31.06\",\"0\",\"4\"],[\"64501.4\",\"232.78\",\"0\",\"2\"],[\"64501.5\",\"1.57\",\"0\",\"4\"],[\"64502.5\",\"0.2\",\"0\",\"3\"],[\"64504.9\",\"0.41\",\"0\",\"4\"],[\"64505.1\",\"0.02\",\"0\",\"2\"],[\"64509.5\",\"85.34\",\"0\",\"1\"],[\"64509.8\",\"58.19\",\"0\",\"2\"],[\"64515.5\",\"95.53\",\"0\",\"8\"],[\"64516.5\",\"197.9\",\"0\",\"3\"],[\"64517.7\",\"104.78\",\"0\",\"5\"],[\"64517.8\",\"0.1\",\"0\",\"3\"],[\"64527.2\",\"0\",\"0\",\"0\"]],\"bids\":[[\"64482.9\",\"311.53\",\"0\",\"20\"],[\"64482.8\",\"21.54\",\"0\",\"14\"],[\"64480\",\"109.35\",\"0\",\"5\"],[\"64478.7\",\"31.04\",\"0\",\"1\"],[\"64478.6\",\"47.31\",\"0\",\"2\"],[\"64477.5\",\"12.87\",\"0\",\"3\"],[\"64477.4\",\"0.01\",\"0\",\"1\"],[\"64477.1\",\"0.01\",\"0\",\"1\"],[\"64476.6\",\"0.01\",\"0\",\"1\"],[\"64476.4\",\"0.77\",\"0\",\"1\"],[\"64476.1\",\"262.49\",\"0\",\"2\"],[\"64474.2\",\"46.54\",\"0\",\"1\"],[\"64473.7\",\"0\",\"0\",\"0\"],[\"64466.9\",\"0\",\"0\",\"0\"],[\"64465.7\",\"0\",\"0\",\"0\"],[\"64465.3\",\"46.6\",\"0\",\"5\"],[\"64464.6\",\"20.08\",\"0\",\"1\"],[\"64464.4\",\"0.01\",\"0\",\"1\"],[\"64464.3\",\"0\",\"0\",\"0\"],[\"64464.1\",\"0.02\",\"0\",\"1\"],[\"64463.6\",\"85.53\",\"0\",\"3\"],[\"64463.5\",\"0.01\",\"0\",\"1\"],[\"64463.2\",\"31.05\",\"0\",\"1\"],[\"64462.2\",\"232.91\",\"0\",\"1\"],[\"64462.1\",\"14.45\",\"0\",\"3\"],[\"64461.2\",\"0.04\",\"0\",\"2\"],[\"64461\",\"0.02\",\"0\",\"1\"],[\"64456\",\"10.02\",\"0\",\"3\"],[\"64455.4\",\"0.02\",\"0\",\"1\"],[\"64440\",\"23.47\",\"0\",\"18\"],[\"64439.9\",\"46.56\",\"0\",\"2\"],[\"64423.2\",\"0\",\"0\",\"0\"],[\"64423.1\",\"0\",\"0\",\"0\"],[\"64423\",\"0\",\"0\",\"0\"],[\"64422.8\",\"0\",\"0\",\"0\"]],\"ts\":\"1782016049605\",\"checksum\":-1297295793,\"seqId\":325070095870,\"prevSeqId\":325070095783}]}"}
{"action": null, "capture_sequence": 410, "channel": "trades", "connection_sequence": 3, "event": null, "instId": "BTC-USDT-SWAP", "local_receive_ts": "2026-06-21T04:27:29Z", "monotonic_ns": 1643605570861323, "raw": "{\"arg\":{\"channel\":\"trades\",\"instId\":\"BTC-USDT-SWAP\"},\"data\":[{\"instId\":\"BTC-USDT-SWAP\",\"tradeId\":\"2718750363\",\"px\":\"64482.9\",\"sz\":\"1\",\"side\":\"sell\",\"ts\":\"1782016049666\",\"count\":\"1\",\"source\":\"0\",\"seqId\":325070095906}]}"}
{"action": "update", "capture_sequence": 411, "channel": "books", "connection_sequence": 3, "event": null, "instId": "BTC-USDT-SWAP", "local_receive_ts": "2026-06-21T04:27:29Z", "monotonic_ns": 1643605610661568, "raw": "{\"arg\":{\"channel\":\"books\",\"instId\":\"BTC-USDT-SWAP\"},\"action\":\"update\",\"data\":[{\"asks\":[[\"64498.5\",\"23.45\",\"0\",\"5\"],[\"64498.8\",\"512.06\",\"0\",\"4\"],[\"64500.4\",\"0.03\",\"0\",\"3\"],[\"64501.4\",\"31.04\",\"0\",\"2\"],[\"64502.1\",\"232.78\",\"0\",\"2\"],[\"64504.3\",\"1.9\",\"0\",\"4\"],[\"64504.9\",\"0.1\",\"0\",\"3\"],[\"64515.5\",\"75.46\",\"0\",\"7\"],[\"64515.7\",\"81.92\",\"0\",\"5\"]],\"bids\":[[\"64482.9\",\"310.53\",\"0\",\"20\"],[\"64482.8\",\"11.21\",\"0\",\"13\"],[\"64480\",\"89.49\",\"0\",\"6\"],[\"64478.7\",\"0\",\"0\",\"0\"],[\"64478.6\",\"46.54\",\"0\",\"1\"],[\"64477.6\",\"32.59\",\"0\",\"4\"],[\"64477.4\",\"119.91\",\"0\",\"2\"],[\"64476.4\",\"0\",\"0\",\"0\"],[\"64472.3\",\"0.01\",\"0\",\"1\"],[\"64471.7\",\"0.61\",\"0\",\"2\"],[\"64464.1\",\"0\",\"0\",\"0\"],[\"64463.9\",\"31.05\",\"0\",\"1\"],[\"64463.7\",\"0.02\",\"0\",\"1\"],[\"64463.2\",\"0\",\"0\",\"0\"],[\"64462.9\",\"232.91\",\"0\",\"1\"],[\"64462.2\",\"0\",\"0\",\"0\"],[\"64462.1\",\"14.43\",\"0\",\"2\"],[\"64461.4\",\"51.49\",\"0\",\"8\"],[\"64461\",\"0\",\"0\",\"0\"],[\"64460.7\",\"44.97\",\"0\",\"3\"],[\"64423.2\",\"38.43\",\"0\",\"2\"],[\"64423.1\",\"92.81\",\"0\",\"2\"],[\"64423\",\"1.59\",\"0\",\"6\"]],\"ts\":\"1782016049705\",\"checksum\":-1637948332,\"seqId\":325070095922,\"prevSeqId\":325070095870}]}"}
{"action": "update", "capture_sequence": 412, "channel": "books", "connection_sequence": 3, "event": null, "instId": "BTC-USDT-SWAP", "local_receive_ts": "2026-06-21T04:27:29Z", "monotonic_ns": 1643605710869690, "raw": "{\"arg\":{\"channel\":\"books\",\"instId\":\"BTC-USDT-SWAP\"},\"action\":\"update\",\"data\":[{\"asks\":[[\"64483\",\"649.84\",\"0\",\"51\"],[\"64498.8\",\"496.55\",\"0\",\"3\"],[\"64499.3\",\"15.51\",\"0\",\"1\"],[\"64504.3\",\"1.59\",\"0\",\"3\"],[\"64504.9\",\"0.41\",\"0\",\"4\"],[\"64527.1\",\"0\",\"0\",\"0\"]],\"bids\":[[\"64482.9\",\"314.34\",\"0\",\"21\"],[\"64472\",\"0.33\",\"0\",\"3\"],[\"64471.7\",\"0.3\",\"0\",\"1\"]],\"ts\":\"1782016049805\",\"checksum\":1128093947,\"seqId\":325070095931,\"prevSeqId\":325070095922}]}"}
{"action": "update", "capture_sequence": 413, "channel": "books", "connection_sequence": 3, "event": null, "instId": "BTC-USDT-SWAP", "local_receive_ts": "2026-06-21T04:27:30Z", "monotonic_ns": 1643605810477345, "raw": "{\"arg\":{\"channel\":\"books\",\"instId\":\"BTC-USDT-SWAP\"},\"action\":\"update\",\"data\":[{\"asks\":[[\"64483\",\"655.84\",\"0\",\"52\"]],\"bids\":[[\"64482\",\"7.76\",\"0\",\"2\"],[\"64463.7\",\"1.02\",\"0\",\"2\"]],\"ts\":\"1782016049905\",\"checksum\":-986879828,\"seqId\":325070095936,\"prevSeqId\":325070095931}]}"}
{"action": null, "capture_sequence": 414, "channel": "trades", "connection_sequence": 3, "event": null, "instId": "BTC-USDT-SWAP", "local_receive_ts": "2026-06-21T04:27:30Z", "monotonic_ns": 1643605863287723, "raw": "{\"arg\":{\"channel\":\"trades\",\"instId\":\"BTC-USDT-SWAP\"},\"data\":[{\"instId\":\"BTC-USDT-SWAP\",\"tradeId\":\"2718750374\",\"px\":\"64483\",\"sz\":\"23.26\",\"side\":\"buy\",\"ts\":\"1782016049958\",\"count\":\"11\",\"source\":\"0\",\"seqId\":325070095961}]}"}
{"action": "update", "capture_sequence": 415, "channel": "books", "connection_sequence": 3, "event": null, "instId": "BTC-USDT-SWAP", "local_receive_ts": "2026-06-21T04:27:30Z", "monotonic_ns": 1643605916426532, "raw": "{\"arg\":{\"channel\":\"books\",\"instId\":\"BTC-USDT-SWAP\"},\"action\":\"update\",\"data\":[{\"asks\":[[\"64483\",\"496.46\",\"0\",\"42\"],[\"64483.4\",\"0\",\"0\",\"0\"],[\"64484.1\",\"71.57\",\"0\",\"2\"],[\"64484.9\",\"0.02\",\"0\",\"2\"],[\"64485.4\",\"136.13\",\"0\",\"1\"],[\"64499.3\",\"0\",\"0\",\"0\"],[\"64499.8\",\"16.59\",\"0\",\"3\"],[\"64501.4\",\"0.01\",\"0\",\"1\"],[\"64502.1\",\"31.04\",\"0\",\"2\"],[\"64502.9\",\"513.49\",\"0\",\"8\"],[\"64504.3\",\"0.04\",\"0\",\"2\"],[\"64504.4\",\"2.68\",\"0\",\"5\"],[\"64504.8\",\"33.9\",\"0\",\"6\"],[\"64505.6\",\"57.91\",\"0\",\"4\"],[\"64513.3\",\"23.83\",\"0\",\"9\"],[\"64515.5\",\"95.53\",\"0\",\"8\"],[\"64515.7\",\"61.85\",\"0\",\"4\"],[\"64517.7\",\"18.68\",\"0\",\"4\"],[\"64517.8\",\"86.2\",\"0\",\"4\"],[\"64527.1\",\"0.46\",\"0\",\"1\"]],\"bids\":[[\"64482.8\",\"26.28\",\"0\",\"13\"],[\"64481\",\"1.56\",\"0\",\"1\"],[\"64480.8\",\"46.56\",\"0\",\"3\"],[\"64480.5\",\"1.56\",\"0\",\"1\"],[\"64480\",\"62.86\",\"0\",\"6\"],[\"64479.6\",\"1.58\",\"0\",\"3\"],[\"64479.1\",\"1.56\",\"0\",\"1\"],[\"64478.6\",\"48.1\",\"0\",\"2\"],[\"64478.2\",\"77.55\",\"0\",\"2\"],[\"64478.1\",\"15.51\",\"0\",\"2\"],[\"64477.7\",\"1.58\",\"0\",\"3\"],[\"64477.6\",\"0.01\",\"0\",\"1\"],[\"64477.4\",\"0.01\",\"0\",\"1\"],[\"64477.3\",\"0\",\"0\",\"0\"],[\"64476.4\",\"32.58\",\"0\",\"3\"],[\"64472.3\",\"0.32\",\"0\",\"2\"],[\"64472\",\"0.02\",\"0\",\"2\"],[\"64466.2\",\"0.01\",\"0\",\"1\"],[\"64465.7\",\"33.81\",\"0\",\"1\"],[\"64464.8\",\"20.09\",\"0\",\"2\"],[\"64464.7\",\"31.05\",\"0\",\"1\"],[\"64464.6\",\"0\",\"0\",\"0\"],[\"64464.1\",\"85.4\",\"0\",\"1\"],[\"64464\",\"232.97\",\"0\",\"5\"],[\"64463.9\",\"0\",\"0\",\"0\"],[\"64463.6\",\"0.13\",\"0\",\"2\"],[\"64462.9\",\"0\",\"0\",\"0\"],[\"64461.9\",\"2.31\",\"0\",\"3\"],[\"64461.4\",\"51.47\",\"0\",\"7\"],[\"64460.8\",\"154.65\",\"0\",\"5\"],[\"64460.7\",\"44.95\",\"0\",\"2\"],[\"64442\",\"15.02\",\"0\",\"3\"],[\"64435.7\",\"2\",\"0\",\"1\"],[\"64423.3\",\"0\",\"0\",\"0\"],[\"64423.2\",\"0\",\"0\",\"0\"],[\"64423.1\",\"0\",\"0\",\"0\"],[\"64423\",\"0\",\"0\",\"0\"]],\"ts\":\"1782016050005\",\"checksum\":-1306719447,\"seqId\":325070096085,\"prevSeqId\":325070095936}]}"}
{"action": "update", "capture_sequence": 416, "channel": "books", "connection_sequence": 3, "event": null, "instId": "BTC-USDT-SWAP", "local_receive_ts": "2026-06-21T04:27:30Z", "monotonic_ns": 1643606015734207, "raw": "{\"arg\":{\"channel\":\"books\",\"instId\":\"BTC-USDT-SWAP\"},\"action\":\"update\",\"data\":[{\"asks\":[[\"64483\",\"497.96\",\"0\",\"43\"],[\"64483.4\",\"0.01\",\"0\",\"1\"],[\"64484\",\"8.65\",\"0\",\"7\"],[\"64484.9\",\"0.01\",\"0\",\"1\"],[\"64488.8\",\"50\",\"0\",\"1\"],[\"64490.1\",\"0.31\",\"0\",\"3\"],[\"64490.9\",\"0.07\",\"0\",\"2\"],[\"64494.9\",\"15.37\",\"0\",\"6\"],[\"64498.1\",\"4.23\",\"0\",\"4\"],[\"64502.6\",\"15.66\",\"0\",\"2\"],[\"64502.9\",\"513.5\",\"0\",\"9\"],[\"64503.5\",\"63.72\",\"0\",\"6\"],[\"64504.4\",\"1.13\",\"0\",\"4\"],[\"64504.7\",\"1.56\",\"0\",\"2\"],[\"64504.8\",\"0.11\",\"0\",\"5\"],[\"64506.4\",\"33.82\",\"0\",\"4\"],[\"64506.8\",\"93.04\",\"0\",\"6\"],[\"64509.5\",\"0\",\"0\",\"0\"],[\"64509.8\",\"0.01\",\"0\",\"1\"],[\"64510.4\",\"58.21\",\"0\",\"4\"],[\"64510.5\",\"62\",\"0\",\"5\"],[\"64511\",\"110.35\",\"0\",\"9\"],[\"64515.5\",\"75.46\",\"0\",\"7\"],[\"64516.3\",\"22.23\",\"0\",\"4\"]],\"bids\":[[\"64482.9\",\"385.64\",\"0\",\"23\"],[\"64482.3\",\"1.59\",\"0\",\"3\"],[\"64481.6\",\"1.57\",\"0\",\"2\"],[\"64478.7\",\"114.49\",\"0\",\"1\"],[\"64468.8\",\"97.5\",\"0\",\"2\"],[\"64467.6\",\"33.84\",\"0\",\"4\"],[\"64467.4\",\"46.54\",\"0\",\"1\"],[\"64466.7\",\"0.02\",\"0\",\"1\"],[\"64465.7\",\"105.47\",\"0\",\"2\"],[\"64465.3\",\"46.58\",\"0\",\"4\"],[\"64464.8\",\"0.01\",\"0\",\"1\"],[\"64464.1\",\"0\",\"0\",\"0\"],[\"64464\",\"0.06\",\"0\",\"4\"],[\"64463.9\",\"232.93\",\"0\",\"2\"],[\"64463.7\",\"1\",\"0\",\"1\"],[\"64462.2\",\"58.22\",\"0\",\"1\"],[\"64461.5\",\"0.02\",\"0\",\"2\"],[\"64456\",\"10.04\",\"0\",\"4\"],[\"64455.4\",\"0\",\"0\",\"0\"],[\"64440\",\"23.49\",\"0\",\"19\"],[\"64439.9\",\"46.54\",\"0\",\"1\"],[\"64423.8\",\"0\",\"0\",\"0\"],[\"64423.6\",\"0\",\"0\",\"0\"]],\"ts\":\"1782016050105\",\"checksum\":2001486829,\"seqId\":325070096280,\"prevSeqId\":325070096085}]}"}
{"action": null, "capture_sequence": 417, "channel": "trades", "connection_sequence": 3, "event": null, "instId": "BTC-USDT-SWAP", "local_receive_ts": "2026-06-21T04:27:30Z", "monotonic_ns": 1643606098819627, "raw": "{\"arg\":{\"channel\":\"trades\",\"instId\":\"BTC-USDT-SWAP\"},\"data\":[{\"instId\":\"BTC-USDT-SWAP\",\"tradeId\":\"2718750375\",\"px\":\"64482.9\",\"sz\":\"0.53\",\"side\":\"sell\",\"ts\":\"1782016050193\",\"count\":\"1\",\"source\":\"0\",\"seqId\":325070096567}]}"}
{"action": "update", "capture_sequence": 418, "channel": "books", "connection_sequence": 3, "event": null, "instId": "BTC-USDT-SWAP", "local_receive_ts": "2026-06-21T04:27:30Z", "monotonic_ns": 1643606116358456, "raw": "{\"arg\":{\"channel\":\"books\",\"instId\":\"BTC-USDT-SWAP\"},\"action\":\"update\",\"data\":[{\"asks\":[[\"64483\",\"539.34\",\"0\",\"41\"],[\"64483.2\",\"0.41\",\"0\",\"2\"],[\"64483.3\",\"1.6\",\"0\",\"2\"],[\"64483.4\",\"0\",\"0\",\"0\"],[\"64483.5\",\"0\",\"0\",\"0\"],[\"64484.7\",\"1.56\",\"0\",\"1\"],[\"64485.2\",\"1.58\",\"0\",\"3\"],[\"64490\",\"55.78\",\"0\",\"20\"],[\"64490.1\",\"0.3\",\"0\",\"2\"],[\"64499.8\",\"1.08\",\"0\",\"2\"],[\"64500.2\",\"15.53\",\"0\",\"3\"],[\"64502.1\",\"0.01\",\"0\",\"1\"],[\"64502.3\",\"42.29\",\"0\",\"5\"],[\"64502.9\",\"280.72\",\"0\",\"7\"],[\"64503\",\"15.96\",\"0\",\"4\"],[\"64503.4\",\"232.77\",\"0\",\"1\"],[\"64504.7\",\"0.01\",\"0\",\"1\"],[\"64504.9\",\"1.65\",\"0\",\"4\"],[\"64505.9\",\"0.32\",\"0\",\"2\"],[\"64506.2\",\"33.82\",\"0\",\"3\"],[\"64506.4\",\"0.03\",\"0\",\"3\"],[\"64506.8\",\"92.27\",\"0\",\"5\"],[\"64507.1\",\"0.83\",\"0\",\"5\"],[\"64510.4\",\"0.03\",\"0\",\"3\"],[\"64510.6\",\"58.37\",\"0\",\"3\"],[\"64511\",\"25.02\",\"0\",\"8\"],[\"64511.7\",\"85.35\",\"0\",\"3\"],[\"64513.3\",\"24.68\",\"0\",\"10\"],[\"64516.3\",\"2.16\",\"0\",\"3\"],[\"64517.3\",\"20.06\",\"0\",\"1\"],[\"64517.8\",\"0.1\",\"0\",\"3\"],[\"64518.3\",\"86.12\",\"0\",\"3\"],[\"64521.9\",\"17\",\"0\",\"3\"],[\"64522.8\",\"15.71\",\"0\",\"4\"],[\"64527.1\",\"0\",\"0\",\"0\"]],\"bids\":[[\"64482.9\",\"615.03\",\"0\",\"26\"],[\"64482.8\",\"35.94\",\"0\",\"13\"],[\"64482.6\",\"3.31\",\"0\",\"3\"],[\"64482.3\",\"0.03\",\"0\",\"2\"],[\"64482.1\",\"0.03\",\"0\",\"2\"],[\"64481.6\",\"0.01\",\"0\",\"1\"],[\"64481\",\"37.23\",\"0\",\"1\"],[\"64480.1\",\"5\",\"0\",\"3\"],[\"64480\",\"61.3\",\"0\",\"5\"],[\"64478.7\",\"0\",\"0\",\"0\"],[\"64478.5\",\"77.56\",\"0\",\"3\"],[\"64478.2\",\"0.01\",\"0\",\"1\"],[\"64477.2\",\"7.78\",\"0\",\"2\"],[\"64476.7\",\"6.34\",\"0\",\"3\"],[\"64473\",\"0.31\",\"0\",\"1\"],[\"64472.3\",\"0.01\",\"0\",\"1\"],[\"64469.4\",\"132.71\",\"0\",\"2\"],[\"64468.8\",\"11.33\",\"0\",\"1\"],[\"64467.6\",\"0.03\",\"0\",\"3\"],[\"64467.3\",\"129.34\",\"0\",\"3\"],[\"64466.7\",\"0\",\"0\",\"0\"],[\"64466.2\",\"105.48\",\"0\",\"3\"],[\"64465.7\",\"0.02\",\"0\",\"1\"],[\"64465.6\",\"28.23\",\"0\",\"5\"],[\"64465.4\",\"538.92\",\"0\",\"4\"],[\"64465.3\",\"46.56\",\"0\",\"3\"],[\"64464.7\",\"1\",\"0\",\"1\"],[\"64464.3\",\"232.91\",\"0\",\"1\"],[\"64464.1\",\"0.02\",\"0\",\"1\"],[\"64463.9\",\"0\",\"0\",\"0\"],[\"64463.7\",\"0\",\"0\",\"0\"],[\"64462.3\",\"58.22\",\"0\",\"1\"],[\"64462.2\",\"0.02\",\"0\",\"1\"],[\"64461.9\",\"2.29\",\"0\",\"2\"],[\"64461\",\"0.02\",\"0\",\"1\"],[\"64460.8\",\"154.63\",\"0\",\"4\"],[\"64423.9\",\"0\",\"0\",\"0\"]],\"ts\":\"1782016050205\",\"checksum\":-418129654,\"seqId\":325070096591,\"prevSeqId\":325070096280}]}"}
{"action": "update", "capture_sequence": 419, "channel": "books", "connection_sequence": 3, "event": null, "instId": "BTC-USDT-SWAP", "local_receive_ts": "2026-06-21T04:27:30Z", "monotonic_ns": 1643606211423213, "raw": "{\"arg\":{\"channel\":\"books\",\"instId\":\"BTC-USDT-SWAP\"},\"action\":\"update\",\"data\":[{\"asks\":[[\"64483\",\"549.34\",\"0\",\"42\"],[\"64497.3\",\"41.14\",\"0\",\"4\"],[\"64503\",\"248.73\",\"0\",\"5\"],[\"64503.4\",\"0\",\"0\",\"0\"],[\"64504.7\",\"1.56\",\"0\",\"2\"],[\"64504.9\",\"0.1\",\"0\",\"3\"],[\"64527.1\",\"0.46\",\"0\",\"1\"]],\"bids\":[[\"64482.6\",\"3.29\",\"0\",\"2\"],[\"64482.1\",\"0.05\",\"0\",\"3\"],[\"64482\",\"9.32\",\"0\",\"3\"],[\"64480.6\",\"1.56\",\"0\",\"1\"],[\"64480.5\",\"0\",\"0\",\"0\"],[\"64478.5\",\"0.02\",\"0\",\"2\"],[\"64478.2\",\"77.55\",\"0\",\"2\"],[\"64468.3\",\"0.77\",\"0\",\"1\"],[\"64467.5\",\"0.03\",\"0\",\"2\"],[\"64465.4\",\"507.87\",\"0\",\"3\"],[\"64464.8\",\"31.06\",\"0\",\"2\"],[\"64464.5\",\"0.02\",\"0\",\"2\"],[\"64464.3\",\"0\",\"0\",\"0\"],[\"64463.9\",\"232.91\",\"0\",\"1\"],[\"64424\",\"0\",\"0\",\"0\"]],\"ts\":\"1782016050305\",\"checksum\":632360226,\"seqId\":325070096722,\"prevSeqId\":325070096591}]}"}
{"action": "update", "capture_sequence": 420, "channel": "books", "connection_sequence": 3, "event": null, "instId": "BTC-USDT-SWAP", "local_receive_ts": "2026-06-21T04:27:30Z", "monotonic_ns": 1643606310769910, "raw": "{\"arg\":{\"channel\":\"books\",\"instId\":\"BTC-USDT-SWAP\"},\"action\":\"update\",\"data\":[{\"asks\":[[\"64497.3\",\"41.3\",\"0\",\"5\"],[\"64499.5\",\"62.05\",\"0\",\"2\"],[\"64500.2\",\"0.02\",\"0\",\"2\"],[\"64510.9\",\"85.4\",\"0\",\"5\"],[\"64511.7\",\"0.02\",\"0\",\"2\"]],\"bids\":[[\"64482\",\"7.76\",\"0\",\"2\"],[\"64480.6\",\"0\",\"0\",\"0\"],[\"64480.1\",\"3.44\",\"0\",\"2\"],[\"64479.6\",\"0.02\",\"0\",\"2\"],[\"64479.1\",\"0\",\"0\",\"0\"],[\"64468.3\",\"0\",\"0\",\"0\"],[\"64467.5\",\"0.8\",\"0\",\"3\"],[\"64466.2\",\"20.09\",\"0\",\"2\"],[\"64465.5\",\"85.39\",\"0\",\"1\"],[\"64464.5\",\"3.24\",\"0\",\"3\"],[\"64424\",\"1.36\",\"0\",\"4\"],[\"64423.9\",\"0.05\",\"0\",\"1\"]],\"ts\":\"1782016050405\",\"checksum\":-1059155369,\"seqId\":325070096813,\"prevSeqId\":325070096722}]}"}
{"action": "update", "capture_sequence": 421, "channel": "books", "connection_sequence": 3, "event": null, "instId": "BTC-USDT-SWAP", "local_receive_ts": "2026-06-21T04:27:30Z", "monotonic_ns": 1643606410532320, "raw": "{\"arg\":{\"channel\":\"books\",\"instId\":\"BTC-USDT-SWAP\"},\"action\":\"update\",\"data\":[{\"asks\":[[\"64504.4\",\"2.68\",\"0\",\"5\"],[\"64504.7\",\"0.01\",\"0\",\"1\"],[\"64510.6\",\"0.19\",\"0\",\"2\"],[\"64511\",\"83.2\",\"0\",\"9\"]],\"bids\":[[\"64478.2\",\"0.01\",\"0\",\"1\"],[\"64477.8\",\"77.54\",\"0\",\"1\"],[\"64462.9\",\"58.22\",\"0\",\"1\"],[\"64462.3\",\"0\",\"0\",\"0\"],[\"64423.9\",\"0\",\"0\",\"0\"]],\"ts\":\"1782016050505\",\"checksum\":-1059155369,\"seqId\":325070096900,\"prevSeqId\":325070096813}]}"}
{"action": "update", "capture_sequence": 422, "channel": "books", "connection_sequence": 3, "event": null, "instId": "BTC-USDT-SWAP", "local_receive_ts": "2026-06-21T04:27:30Z", "monotonic_ns": 1643606510692516, "raw": "{\"arg\":{\"channel\":\"books\",\"instId\":\"BTC-USDT-SWAP\"},\"action\":\"update\",\"data\":[{\"asks\":[[\"64483\",\"549.84\",\"0\",\"44\"],[\"64501.7\",\"31.58\",\"0\",\"5\"],[\"64502.3\",\"11.26\",\"0\",\"4\"]],\"bids\":[[\"64464.5\",\"0.02\",\"0\",\"2\"]],\"ts\":\"1782016050605\",\"checksum\":956978917,\"seqId\":325070096971,\"prevSeqId\":325070096900}]}"}
{"action": "update", "capture_sequence": 423, "channel": "books", "connection_sequence": 3, "event": null, "instId": "BTC-USDT-SWAP", "local_receive_ts": "2026-06-21T04:27:30Z", "monotonic_ns": 1643606610526315, "raw": "{\"arg\":{\"channel\":\"books\",\"instId\":\"BTC-USDT-SWAP\"},\"action\":\"update\",\"data\":[{\"asks\":[[\"64483\",\"539.84\",\"0\",\"43\"],[\"64483.2\",\"0.4\",\"0\",\"1\"],[\"64483.3\",\"0.04\",\"0\",\"1\"],[\"64484.6\",\"1.22\",\"0\",\"3\"],[\"64514\",\"19.86\",\"0\",\"3\"],[\"64523.4\",\"21.46\",\"0\",\"3\"]],\"bids\":[[\"64481\",\"39.68\",\"0\",\"2\"],[\"64480.7\",\"0.01\",\"0\",\"1\"],[\"64480.4\",\"2.45\",\"0\",\"1\"],[\"64480.1\",\"0.01\",\"0\",\"1\"],[\"64464.5\",\"3.24\",\"0\",\"3\"],[\"64458.7\",\"0.01\",\"0\",\"1\"],[\"64424\",\"0\",\"0\",\"0\"]],\"ts\":\"1782016050705\",\"checksum\":1174056894,\"seqId\":325070097062,\"prevSeqId\":325070096971}]}"}
{"action": null, "capture_sequence": 424, "channel": "trades", "connection_sequence": 3, "event": null, "instId": "BTC-USDT-SWAP", "local_receive_ts": "2026-06-21T04:27:30Z", "monotonic_ns": 1643606618169411, "raw": "{\"arg\":{\"channel\":\"trades\",\"instId\":\"BTC-USDT-SWAP\"},\"data\":[{\"instId\":\"BTC-USDT-SWAP\",\"tradeId\":\"2718750376\",\"px\":\"64483\",\"sz\":\"13.83\",\"side\":\"buy\",\"ts\":\"1782016050713\",\"count\":\"1\",\"source\":\"0\",\"seqId\":325070097070}]}"}
{"action": null, "capture_sequence": 425, "channel": "trades", "connection_sequence": 3, "event": null, "instId": "BTC-USDT-SWAP", "local_receive_ts": "2026-06-21T04:27:30Z", "monotonic_ns": 1643606667973074, "raw": "{\"arg\":{\"channel\":\"trades\",\"instId\":\"BTC-USDT-SWAP\"},\"data\":[{\"instId\":\"BTC-USDT-SWAP\",\"tradeId\":\"2718750377\",\"px\":\"64482.9\",\"sz\":\"0.06\",\"side\":\"sell\",\"ts\":\"1782016050762\",\"count\":\"1\",\"source\":\"0\",\"seqId\":325070097120}]}"}
{"action": null, "capture_sequence": 426, "channel": "trades", "connection_sequence": 3, "event": null, "instId": "BTC-USDT-SWAP", "local_receive_ts": "2026-06-21T04:27:30Z", "monotonic_ns": 1643606675641061, "raw": "{\"arg\":{\"channel\":\"trades\",\"instId\":\"BTC-USDT-SWAP\"},\"data\":[{\"instId\":\"BTC-USDT-SWAP\",\"tradeId\":\"2718750378\",\"px\":\"64482.9\",\"sz\":\"0.44\",\"side\":\"sell\",\"ts\":\"1782016050771\",\"count\":\"1\",\"source\":\"0\",\"seqId\":325070097133}]}"}
{"action": "update", "capture_sequence": 427, "channel": "books", "connection_sequence": 3, "event": null, "instId": "BTC-USDT-SWAP", "local_receive_ts": "2026-06-21T04:27:30Z", "monotonic_ns": 1643606710674478, "raw": "{\"arg\":{\"channel\":\"books\",\"instId\":\"BTC-USDT-SWAP\"},\"action\":\"update\",\"data\":[{\"asks\":[[\"64483\",\"459.95\",\"0\",\"43\"],[\"64484\",\"7.09\",\"0\",\"6\"],[\"64492.3\",\"0.03\",\"0\",\"1\"],[\"64501.7\",\"0.55\",\"0\",\"4\"],[\"64502.1\",\"31.04\",\"0\",\"2\"],[\"64511\",\"25.02\",\"0\",\"8\"],[\"64511.7\",\"58.2\",\"0\",\"3\"]],\"bids\":[[\"64482.9\",\"682.19\",\"0\",\"29\"],[\"64481.3\",\"0.01\",\"0\",\"1\"],[\"64481.1\",\"0.01\",\"0\",\"1\"],[\"64480.8\",\"46.55\",\"0\",\"2\"],[\"64480.5\",\"2.45\",\"0\",\"1\"],[\"64480.4\",\"0\",\"0\",\"0\"],[\"64480.2\",\"0\",\"0\",\"0\"],[\"64467.5\",\"18.92\",\"0\",\"4\"],[\"64463.4\",\"58.22\",\"0\",\"1\"],[\"64462.9\",\"0\",\"0\",\"0\"],[\"64424.1\",\"0\",\"0\",\"0\"]],\"ts\":\"1782016050805\",\"checksum\":1662032636,\"seqId\":325070097160,\"prevSeqId\":325070097062}]}"}
{"action": "update", "capture_sequence": 428, "channel": "books", "connection_sequence": 3, "event": null, "instId": "BTC-USDT-SWAP", "local_receive_ts": "2026-06-21T04:27:31Z", "monotonic_ns": 1643606810957803, "raw": "{\"arg\":{\"channel\":\"books\",\"instId\":\"BTC-USDT-SWAP\"},\"action\":\"update\",\"data\":[{\"asks\":[[\"64483\",\"531.12\",\"0\",\"43\"],[\"64490\",\"55.77\",\"0\",\"19\"],[\"64490.1\",\"0.31\",\"0\",\"3\"],[\"64506.2\",\"0.03\",\"0\",\"2\"],[\"64506.4\",\"33.82\",\"0\",\"4\"],[\"64510.6\",\"85.53\",\"0\",\"3\"],[\"64510.9\",\"0.07\",\"0\",\"4\"],[\"64516.8\",\"26.33\",\"0\",\"4\"],[\"64517.3\",\"0\",\"0\",\"0\"],[\"64517.8\",\"86.2\",\"0\",\"4\"],[\"64518.3\",\"0.02\",\"0\",\"2\"],[\"64521.9\",\"16.99\",\"0\",\"2\"],[\"64522.2\",\"0.16\",\"0\",\"9\"],[\"64527.2\",\"0.18\",\"0\",\"4\"]],\"bids\":[[\"64482.9\",\"614.6\",\"0\",\"28\"],[\"64482\",\"7.77\",\"0\",\"3\"],[\"64478.6\",\"46.54\",\"0\",\"1\"],[\"64478.1\",\"13.95\",\"0\",\"1\"],[\"64474.7\",\"0.03\",\"0\",\"2\"],[\"64474\",\"0.01\",\"0\",\"1\"],[\"64469.4\",\"46.54\",\"0\",\"1\"],[\"64468.8\",\"97.5\",\"0\",\"2\"],[\"64467.6\",\"0.8\",\"0\",\"4\"],[\"64467.5\",\"18.15\",\"0\",\"3\"],[\"64466.9\",\"0.02\",\"0\",\"1\"],[\"64465.6\",\"28.21\",\"0\",\"4\"],[\"64465.5\",\"0\",\"0\",\"0\"],[\"64465.4\",\"593.26\",\"0\",\"4\"],[\"64442\",\"15.01\",\"0\",\"2\"]],\"ts\":\"1782016050905\",\"checksum\":229244827,\"seqId\":325070097301,\"prevSeqId\":325070097160}]}"}
{"action": "update", "capture_sequence": 429, "channel": "books", "connection_sequence": 3, "event": null, "instId": "BTC-USDT-SWAP", "local_receive_ts": "2026-06-21T04:27:31Z", "monotonic_ns": 1643606910590676, "raw": "{\"arg\":{\"channel\":\"books\",\"instId\":\"BTC-USDT-SWAP\"},\"action\":\"update\",\"data\":[{\"asks\":[[\"64483\",\"501.27\",\"0\",\"45\"],[\"64485\",\"2\",\"0\",\"1\"],[\"64493.8\",\"0.03\",\"0\",\"2\"],[\"64497.3\",\"41.14\",\"0\",\"4\"],[\"64502.7\",\"232.8\",\"0\",\"4\"],[\"64503\",\"15.96\",\"0\",\"4\"],[\"64504.4\",\"1.13\",\"0\",\"4\"],[\"64504.7\",\"1.56\",\"0\",\"2\"],[\"64510.6\",\"143.71\",\"0\",\"4\"],[\"64511.7\",\"0.02\",\"0\",\"2\"],[\"64513.5\",\"1.6\",\"0\",\"4\"],[\"64516.5\",\"217.97\",\"0\",\"4\"],[\"64516.8\",\"6.26\",\"0\",\"3\"],[\"64517.6\",\"72.07\",\"0\",\"3\"]],\"bids\":[[\"64482.9\",\"685.35\",\"0\",\"29\"],[\"64480.2\",\"1.56\",\"0\",\"1\"],[\"64479.3\",\"1.56\",\"0\",\"1\"],[\"64478.8\",\"1.56\",\"0\",\"1\"],[\"64478.3\",\"1.57\",\"0\",\"2\"],[\"64478.2\",\"77.55\",\"0\",\"2\"],[\"64477.8\",\"0\",\"0\",\"0\"],[\"64476.2\",\"1.57\",\"0\",\"2\"],[\"64466.2\",\"0.01\",\"0\",\"1\"],[\"64465.7\",\"20.1\",\"0\",\"2\"],[\"64463.9\",\"0\",\"0\",\"0\"],[\"64463.4\",\"232.91\",\"0\",\"1\"],[\"64462.2\",\"58.24\",\"0\",\"2\"],[\"64424.2\",\"0\",\"0\",\"0\"]],\"ts\":\"1782016051005\",\"checksum\":-2090547895,\"seqId\":325070097410,\"prevSeqId\":325070097301}]}"}
{"action": null, "capture_sequence": 430, "channel": "trades", "connection_sequence": 3, "event": null, "instId": "BTC-USDT-SWAP", "local_receive_ts": "2026-06-21T04:27:31Z", "monotonic_ns": 1643606929978891, "raw": "{\"arg\":{\"channel\":\"trades\",\"instId\":\"BTC-USDT-SWAP\"},\"data\":[{\"instId\":\"BTC-USDT-SWAP\",\"tradeId\":\"2718750379\",\"px\":\"64483\",\"sz\":\"1.75\",\"side\":\"buy\",\"ts\":\"1782016051025\",\"count\":\"1\",\"source\":\"0\",\"seqId\":325070097452}]}"}
{"action": "update", "capture_sequence": 431, "channel": "books", "connection_sequence": 3, "event": null, "instId": "BTC-USDT-SWAP", "local_receive_ts": "2026-06-21T04:27:31Z", "monotonic_ns": 1643607011257616, "raw": "{\"arg\":{\"channel\":\"books\",\"instId\":\"BTC-USDT-SWAP\"},\"action\":\"update\",\"data\":[{\"asks\":[[\"64483\",\"499.52\",\"0\",\"45\"],[\"64484.1\",\"71.58\",\"0\",\"3\"],[\"64484.2\",\"1.56\",\"0\",\"1\"],[\"64484.6\",\"1.21\",\"0\",\"2\"],[\"64490.1\",\"0.3\",\"0\",\"2\"],[\"64491.9\",\"0.43\",\"0\",\"6\"],[\"64497.3\",\"41.3\",\"0\",\"5\"],[\"64499.5\",\"46.54\",\"0\",\"1\"],[\"64499.6\",\"74.78\",\"0\",\"4\"],[\"64502.9\",\"280.73\",\"0\",\"8\"],[\"64503\",\"15.95\",\"0\",\"3\"],[\"64505.5\",\"74.12\",\"0\",\"4\"],[\"64505.9\",\"0.01\",\"0\",\"1\"],[\"64522.2\",\"0.15\",\"0\",\"8\"],[\"64522.8\",\"15.72\",\"0\",\"5\"],[\"64527.2\",\"0\",\"0\",\"0\"]],\"bids\":[[\"64482.1\",\"1.61\",\"0\",\"4\"],[\"64481.5\",\"1.56\",\"0\",\"1\"],[\"64481\",\"41.24\",\"0\",\"3\"],[\"64480.5\",\"4.01\",\"0\",\"2\"],[\"64480.2\",\"0\",\"0\",\"0\"],[\"64479.9\",\"1.69\",\"0\",\"3\"],[\"64479.3\",\"0\",\"0\",\"0\"],[\"64479.1\",\"1.56\",\"0\",\"1\"],[\"64478.8\",\"0\",\"0\",\"0\"],[\"64478.6\",\"48.1\",\"0\",\"2\"],[\"64478.3\",\"0.01\",\"0\",\"1\"],[\"64478.2\",\"79.11\",\"0\",\"3\"],[\"64476.7\",\"4.78\",\"0\",\"2\"],[\"64476.2\",\"0.01\",\"0\",\"1\"],[\"64475\",\"0.02\",\"0\",\"1\"],[\"64474.7\",\"0.01\",\"0\",\"1\"],[\"64456.2\",\"21.9\",\"0\",\"4\"],[\"64456\",\"10.02\",\"0\",\"3\"]],\"ts\":\"1782016051105\",\"checksum\":2107881632,\"seqId\":325070097598,\"prevSeqId\":325070097410}]}"}
{"action": "update", "capture_sequence": 432, "channel": "books", "connection_sequence": 3, "event": null, "instId": "BTC-USDT-SWAP", "local_receive_ts": "2026-06-21T04:27:31Z", "monotonic_ns": 1643607110401140, "raw": "{\"arg\":{\"channel\":\"books\",\"instId\":\"BTC-USDT-SWAP\"},\"action\":\"update\",\"data\":[{\"asks\":[[\"64483\",\"487.96\",\"0\",\"43\"],[\"64483.3\",\"0.05\",\"0\",\"2\"],[\"64483.4\",\"1.56\",\"0\",\"1\"],[\"64484.1\",\"71.57\",\"0\",\"2\"],[\"64492.5\",\"22.05\",\"0\",\"4\"],[\"64527.1\",\"0\",\"0\",\"0\"]],\"bids\":[[\"64482.1\",\"0.05\",\"0\",\"3\"],[\"64481.7\",\"1.56\",\"0\",\"1\"],[\"64481.5\",\"0\",\"0\",\"0\"]],\"ts\":\"1782016051205\",\"checksum\":-1675482371,\"seqId\":325070097717,\"prevSeqId\":325070097598}]}"}
{"action": "update", "capture_sequence": 433, "channel": "books", "connection_sequence": 3, "event": null, "instId": "BTC-USDT-SWAP", "local_receive_ts": "2026-06-21T04:27:31Z", "monotonic_ns": 1643607210616800, "raw": "{\"arg\":{\"channel\":\"books\",\"instId\":\"BTC-USDT-SWAP\"},\"action\":\"update\",\"data\":[{\"asks\":[[\"64483\",\"567.17\",\"0\",\"45\"],[\"64497.3\",\"41.14\",\"0\",\"4\"],[\"64504.1\",\"22.88\",\"0\",\"8\"],[\"64504.7\",\"0.01\",\"0\",\"1\"],[\"64505.9\",\"33.8\",\"0\",\"2\"],[\"64506.4\",\"0.03\",\"0\",\"3\"]],\"bids\":[[\"64482.9\",\"614.6\",\"0\",\"28\"],[\"64481.7\",\"0\",\"0\",\"0\"],[\"64481\",\"39.68\",\"0\",\"2\"],[\"64480.5\",\"2.45\",\"0\",\"1\"],[\"64479.9\",\"0.13\",\"0\",\"2\"],[\"64478.2\",\"1.57\",\"0\",\"2\"],[\"64477.8\",\"77.54\",\"0\",\"1\"],[\"64476.7\",\"6.34\",\"0\",\"3\"],[\"64468.8\",\"11.33\",\"0\",\"1\"],[\"64467.4\",\"132.71\",\"0\",\"2\"],[\"64467.3\",\"95.53\",\"0\",\"2\"],[\"64466.2\",\"33.82\",\"0\",\"2\"]],\"ts\":\"1782016051305\",\"checksum\":-2104103241,\"seqId\":325070097808,\"prevSeqId\":325070097717}]}"}
{"action": "update", "capture_sequence": 434, "channel": "books", "connection_sequence": 3, "event": null, "instId": "BTC-USDT-SWAP", "local_receive_ts": "2026-06-21T04:27:31Z", "monotonic_ns": 1643607315749990, "raw": "{\"arg\":{\"channel\":\"books\",\"instId\":\"BTC-USDT-SWAP\"},\"action\":\"update\",\"data\":[{\"asks\":[[\"64483\",\"488.25\",\"0\",\"44\"],[\"64483.3\",\"0.04\",\"0\",\"1\"],[\"64483.4\",\"0\",\"0\",\"0\"],[\"64484.1\",\"71.58\",\"0\",\"3\"],[\"64488.9\",\"0.33\",\"0\",\"6\"],[\"64490.1\",\"0.31\",\"0\",\"3\"],[\"64490.8\",\"30.53\",\"0\",\"2\"],[\"64491.3\",\"0.01\",\"0\",\"1\"],[\"64491.9\",\"0.42\",\"0\",\"5\"],[\"64492.1\",\"0\",\"0\",\"0\"],[\"64497.2\",\"1\",\"0\",\"4\"],[\"64499.6\",\"59.27\",\"0\",\"3\"],[\"64499.8\",\"16.59\",\"0\",\"3\"],[\"64501.9\",\"31.11\",\"0\",\"2\"],[\"64502.1\",\"0.01\",\"0\",\"1\"],[\"64502.8\",\"57.08\",\"0\",\"4\"],[\"64502.9\",\"280.72\",\"0\",\"7\"],[\"64504.1\",\"21.33\",\"0\",\"7\"],[\"64504.7\",\"1.56\",\"0\",\"2\"],[\"64505.5\",\"73.81\",\"0\",\"3\"],[\"64505.6\",\"58.22\",\"0\",\"5\"],[\"64509.8\",\"85.35\",\"0\",\"2\"],[\"64510.4\",\"58.21\",\"0\",\"4\"],[\"64510.6\",\"0.19\",\"0\",\"2\"],[\"64512.5\",\"0.16\",\"0\",\"5\"],[\"64514.4\",\"15.7\",\"0\",\"4\"],[\"64514.9\",\"496.61\",\"0\",\"4\"],[\"64515.7\",\"60.35\",\"0\",\"3\"],[\"64522\",\"5.19\",\"0\",\"11\"],[\"64522.8\",\"15.71\",\"0\",\"4\"],[\"64527.1\",\"0.46\",\"0\",\"1\"],[\"64527.2\",\"0.18\",\"0\",\"4\"]],\"bids\":[[\"64482.9\",\"685.6\",\"0\",\"28\"],[\"64478.3\",\"77.55\",\"0\",\"2\"],[\"64477.8\",\"0\",\"0\",\"0\"],[\"64475\",\"0\",\"0\",\"0\"],[\"64474.7\",\"0.03\",\"0\",\"2\"],[\"64473.2\",\"11.41\",\"0\",\"2\"],[\"64471.3\",\"15.98\",\"0\",\"1\"],[\"64471.1\",\"148.91\",\"0\",\"1\"],[\"64470\",\"37.69\",\"0\",\"4\"],[\"64465.4\",\"507.87\",\"0\",\"3\"],[\"64464.6\",\"85.4\",\"0\",\"1\"],[\"64464.5\",\"0.02\",\"0\",\"2\"],[\"64456.2\",\"21.88\",\"0\",\"3\"],[\"64456\",\"10.04\",\"0\",\"4\"],[\"64426\",\"3.27\",\"0\",\"2\"],[\"64424.2\",\"0.01\",\"0\",\"1\"]],\"ts\":\"1782016051405\",\"checksum\":1946399860,\"seqId\":325070097966,\"prevSeqId\":325070097808}]}"}
{"action": "update", "capture_sequence": 435, "channel": "books", "connection_sequence": 3, "event": null, "instId": "BTC-USDT-SWAP", "local_receive_ts": "2026-06-21T04:27:31Z", "monotonic_ns": 1643607416587548, "raw": "{\"arg\":{\"channel\":\"books\",\"instId\":\"BTC-USDT-SWAP\"},\"action\":\"update\",\"data\":[{\"asks\":[[\"64483\",\"564.54\",\"0\",\"45\"],[\"64489.5\",\"0.02\",\"0\",\"2\"],[\"64489.9\",\"0\",\"0\",\"0\"],[\"64490.1\",\"0.3\",\"0\",\"2\"],[\"64490.2\",\"0\",\"0\",\"0\"],[\"64490.5\",\"1.81\",\"0\",\"3\"],[\"64491.3\",\"1.21\",\"0\",\"2\"],[\"64491.7\",\"0.02\",\"0\",\"2\"],[\"64491.8\",\"0.06\",\"0\",\"2\"],[\"64502.8\",\"57.07\",\"0\",\"3\"],[\"64502.9\",\"280.73\",\"0\",\"8\"],[\"64513.2\",\"0.15\",\"0\",\"4\"],[\"64513.5\",\"0.6\",\"0\",\"3\"],[\"64513.8\",\"0.01\",\"0\",\"1\"],[\"64514.1\",\"0.03\",\"0\",\"3\"],[\"64514.9\",\"497.81\",\"0\",\"5\"],[\"64515.3\",\"0.01\",\"0\",\"1\"],[\"64522\",\"5.18\",\"0\",\"10\"],[\"64522.8\",\"15.72\",\"0\",\"5\"],[\"64527.3\",\"0.05\",\"0\",\"5\"],[\"64527.4\",\"0.27\",\"0\",\"2\"]],\"bids\":[[\"64475\",\"0.02\",\"0\",\"1\"],[\"64474.7\",\"0.01\",\"0\",\"1\"],[\"64472.6\",\"0.12\",\"0\",\"1\"],[\"64472.2\",\"0\",\"0\",\"0\"],[\"64471.9\",\"0\",\"0\",\"0\"],[\"64471.6\",\"0.03\",\"0\",\"1\"],[\"64471.4\",\"49.31\",\"0\",\"3\"],[\"64470.8\",\"49.48\",\"0\",\"2\"],[\"64470.4\",\"4\",\"0\",\"1\"],[\"64464.6\",\"88.55\",\"0\",\"2\"],[\"64456.2\",\"21.9\",\"0\",\"4\"],[\"64456\",\"10.02\",\"0\",\"3\"],[\"64425.3\",\"2\",\"0\",\"1\"],[\"64425\",\"1.87\",\"0\",\"7\"],[\"64424.7\",\"0\",\"0\",\"0\"],[\"64424.4\",\"46.54\",\"0\",\"1\"],[\"64424.2\",\"1.21\",\"0\",\"2\"],[\"64424\",\"1.36\",\"0\",\"4\"],[\"64423.9\",\"0.05\",\"0\",\"1\"]],\"ts\":\"1782016051505\",\"checksum\":1774323179,\"seqId\":325070098100,\"prevSeqId\":325070097966}]}"}
{"action": null, "capture_sequence": 436, "channel": "trades", "connection_sequence": 3, "event": null, "instId": "BTC-USDT-SWAP", "local_receive_ts": "2026-06-21T04:27:31Z", "monotonic_ns": 1643607489215381, "raw": "{\"arg\":{\"channel\":\"trades\",\"instId\":\"BTC-USDT-SWAP\"},\"data\":[{\"instId\":\"BTC-USDT-SWAP\",\"tradeId\":\"2718750380\",\"px\":\"64482.9\",\"sz\":\"18.55\",\"side\":\"sell\",\"ts\":\"1782016051584\",\"count\":\"1\",\"source\":\"0\",\"seqId\":325070098196}]}"}
{"action": "update", "capture_sequence": 437, "channel": "books", "connection_sequence": 3, "event": null, "instId": "BTC-USDT-SWAP", "local_receive_ts": "2026-06-21T04:27:31Z", "monotonic_ns": 1643607510721976, "raw": "{\"arg\":{\"channel\":\"books\",\"instId\":\"BTC-USDT-SWAP\"},\"action\":\"update\",\"data\":[{\"asks\":[[\"64483.6\",\"67.74\",\"0\",\"2\"],[\"64483.7\",\"136.14\",\"0\",\"2\"],[\"64484.1\",\"0\",\"0\",\"0\"],[\"64485.4\",\"0\",\"0\",\"0\"],[\"64488.9\",\"1.33\",\"0\",\"7\"],[\"64489.9\",\"1\",\"0\",\"1\"],[\"64490.8\",\"31.73\",\"0\",\"3\"],[\"64491.7\",\"1.22\",\"0\",\"3\"],[\"64492.1\",\"1.5\",\"0\",\"1\"],[\"64499.3\",\"15.51\",\"0\",\"1\"],[\"64499.8\",\"1.08\",\"0\",\"2\"],[\"64504.2\",\"512.65\",\"0\",\"7\"],[\"64504.7\",\"0.01\",\"0\",\"1\"],[\"64512.5\",\"1.16\",\"0\",\"6\"],[\"64513.5\",\"1.6\",\"0\",\"4\"],[\"64514.4\",\"16.9\",\"0\",\"5\"],[\"64515.3\",\"1.21\",\"0\",\"2\"],[\"64515.7\",\"61.85\",\"0\",\"4\"],[\"64527.3\",\"0\",\"0\",\"0\"],[\"64527.4\",\"0\",\"0\",\"0\"]],\"bids\":[[\"64482.9\",\"595.82\",\"0\",\"27\"],[\"64479.1\",\"0\",\"0\",\"0\"],[\"64478.6\",\"46.54\",\"0\",\"1\"],[\"64478.3\",\"0.01\",\"0\",\"1\"],[\"64478.2\",\"0.01\",\"0\",\"1\"],[\"64477.8\",\"77.54\",\"0\",\"1\"],[\"64477.7\",\"0.02\",\"0\",\"2\"],[\"64477.2\",\"6.22\",\"0\",\"1\"],[\"64476.7\",\"4.78\",\"0\",\"2\"],[\"64473.5\",\"99.58\",\"0\",\"2\"],[\"64472.6\",\"1.72\",\"0\",\"2\"],[\"64471.6\",\"2.19\",\"0\",\"2\"],[\"64471.1\",\"151.91\",\"0\",\"2\"],[\"64470.3\",\"14.71\",\"0\",\"4\"],[\"64426.3\",\"1\",\"0\",\"1\"],[\"64425.3\",\"3\",\"0\",\"2\"],[\"64424.4\",\"47.74\",\"0\",\"2\"],[\"64423.9\",\"0\",\"0\",\"0\"]],\"ts\":\"1782016051605\",\"checksum\":676511118,\"seqId\":325070098223,\"prevSeqId\":325070098100}]}"}
{"action": null, "capture_sequence": 438, "channel": "trades", "connection_sequence": 3, "event": null, "instId": "BTC-USDT-SWAP", "local_receive_ts": "2026-06-21T04:27:31Z", "monotonic_ns": 1643607530477590, "raw": "{\"arg\":{\"channel\":\"trades\",\"instId\":\"BTC-USDT-SWAP\"},\"data\":[{\"instId\":\"BTC-USDT-SWAP\",\"tradeId\":\"2718750383\",\"px\":\"64482.9\",\"sz\":\"39.15\",\"side\":\"sell\",\"ts\":\"1782016051625\",\"count\":\"3\",\"source\":\"0\",\"seqId\":325070098263}]}"}
{"action": "update", "capture_sequence": 439, "channel": "books", "connection_sequence": 3, "event": null, "instId": "BTC-USDT-SWAP", "local_receive_ts": "2026-06-21T04:27:31Z", "monotonic_ns": 1643607615962358, "raw": "{\"arg\":{\"channel\":\"books\",\"instId\":\"BTC-USDT-SWAP\"},\"action\":\"update\",\"data\":[{\"asks\":[[\"64483\",\"574.54\",\"0\",\"46\"],[\"64483.5\",\"0.01\",\"0\",\"1\"],[\"64484\",\"7.08\",\"0\",\"5\"],[\"64489.5\",\"1.02\",\"0\",\"3\"],[\"64490.1\",\"0.31\",\"0\",\"3\"],[\"64490.2\",\"1.2\",\"0\",\"1\"],[\"64490.5\",\"3.01\",\"0\",\"4\"],[\"64491.8\",\"0.05\",\"0\",\"1\"],[\"64496.6\",\"34.78\",\"0\",\"3\"],[\"64498.4\",\"15.51\",\"0\",\"1\"],[\"64498.6\",\"0.29\",\"0\",\"6\"],[\"64499.3\",\"0\",\"0\",\"0\"],[\"64500.6\",\"93.57\",\"0\",\"5\"],[\"64501.7\",\"233.32\",\"0\",\"5\"],[\"64501.9\",\"0.08\",\"0\",\"1\"],[\"64502.7\",\"0.03\",\"0\",\"3\"],[\"64502.8\",\"57.08\",\"0\",\"4\"],[\"64502.9\",\"280.72\",\"0\",\"7\"],[\"64503.8\",\"1.55\",\"0\",\"1\"],[\"64504.2\",\"511.1\",\"0\",\"6\"],[\"64504.9\",\"0.41\",\"0\",\"4\"],[\"64505.6\",\"57.91\",\"0\",\"4\"],[\"64506.2\",\"0.8\",\"0\",\"3\"],[\"64507.1\",\"0.06\",\"0\",\"4\"],[\"64509.5\",\"85.34\",\"0\",\"1\"],[\"64509.8\",\"0.01\",\"0\",\"1\"],[\"64513.2\",\"1.15\",\"0\",\"5\"],[\"64513.8\",\"1.21\",\"0\",\"2\"],[\"64514.1\",\"1.23\",\"0\",\"4\"],[\"64515.6\",\"21.36\",\"0\",\"6\"],[\"64516.5\",\"197.9\",\"0\",\"3\"],[\"64522\",\"5.19\",\"0\",\"11\"],[\"64522.8\",\"15.71\",\"0\",\"4\"],[\"64526.9\",\"0\",\"0\",\"0\"],[\"64527\",\"0\",\"0\",\"0\"],[\"64527.1\",\"0\",\"0\",\"0\"],[\"64527.2\",\"0\",\"0\",\"0\"]],\"bids\":[[\"64482.9\",\"556.67\",\"0\",\"25\"],[\"64477.8\",\"0\",\"0\",\"0\"],[\"64477.3\",\"77.54\",\"0\",\"1\"],[\"64475\",\"0\",\"0\",\"0\"],[\"64474.1\",\"496.56\",\"0\",\"3\"],[\"64473\",\"0\",\"0\",\"0\"],[\"64472.9\",\"17.84\",\"0\",\"2\"],[\"64472.2\",\"1.99\",\"0\",\"2\"],[\"64471.9\",\"1.92\",\"0\",\"1\"],[\"64467.6\",\"0.03\",\"0\",\"3\"],[\"64467.3\",\"96.3\",\"0\",\"3\"],[\"64465.7\",\"0.02\",\"0\",\"1\"],[\"64464.9\",\"20.08\",\"0\",\"1\"],[\"64464.8\",\"0.01\",\"0\",\"1\"],[\"64464.6\",\"3.15\",\"0\",\"1\"],[\"64463.9\",\"85.4\",\"0\",\"1\"],[\"64463.7\",\"31.05\",\"0\",\"1\"],[\"64463.4\",\"0\",\"0\",\"0\"],[\"64462.3\",\"232.91\",\"0\",\"1\"],[\"64456.2\",\"21.88\",\"0\",\"3\"],[\"64456\",\"10.04\",\"0\",\"4\"],[\"64425.7\",\"3.01\",\"0\",\"2\"],[\"64425\",\"3.07\",\"0\",\"8\"],[\"64424.7\",\"1.2\",\"0\",\"1\"],[\"64424.6\",\"0\",\"0\",\"0\"],[\"64424.4\",\"0\",\"0\",\"0\"],[\"64424.2\",\"0\",\"0\",\"0\"],[\"64424\",\"0\",\"0\",\"0\"]],\"ts\":\"1782016051705\",\"checksum\":176362928,\"seqId\":325070098321,\"prevSeqId\":325070098223}]}"}
{"action": null, "capture_sequence": 440, "channel": "trades", "connection_sequence": 3, "event": null, "instId": "BTC-USDT-SWAP", "local_receive_ts": "2026-06-21T04:27:31Z", "monotonic_ns": 1643607635579741, "raw": "{\"arg\":{\"channel\":\"trades\",\"instId\":\"BTC-USDT-SWAP\"},\"data\":[{\"instId\":\"BTC-USDT-SWAP\",\"tradeId\":\"2718750384\",\"px\":\"64483\",\"sz\":\"0.19\",\"side\":\"buy\",\"ts\":\"1782016051730\",\"count\":\"1\",\"source\":\"0\",\"seqId\":325070098325}]}"}
{"action": "update", "capture_sequence": 441, "channel": "books", "connection_sequence": 3, "event": null, "instId": "BTC-USDT-SWAP", "local_receive_ts": "2026-06-21T04:27:31Z", "monotonic_ns": 1643607711665019, "raw": "{\"arg\":{\"channel\":\"books\",\"instId\":\"BTC-USDT-SWAP\"},\"action\":\"update\",\"data\":[{\"asks\":[[\"64483\",\"574.35\",\"0\",\"46\"],[\"64492.5\",\"0.05\",\"0\",\"3\"],[\"64498.4\",\"0\",\"0\",\"0\"],[\"64499.3\",\"15.51\",\"0\",\"1\"],[\"64500.6\",\"62.54\",\"0\",\"4\"],[\"64501.5\",\"32.6\",\"0\",\"5\"],[\"64501.7\",\"0.55\",\"0\",\"4\"],[\"64502.5\",\"232.97\",\"0\",\"4\"],[\"64503.4\",\"1.55\",\"0\",\"1\"],[\"64503.8\",\"0\",\"0\",\"0\"]],\"bids\":[[\"64477.3\",\"0\",\"0\",\"0\"],[\"64477\",\"77.55\",\"0\",\"2\"],[\"64464.3\",\"31.05\",\"0\",\"1\"],[\"64463.7\",\"0\",\"0\",\"0\"],[\"64463.4\",\"232.91\",\"0\",\"1\"],[\"64462.3\",\"0\",\"0\",\"0\"],[\"64424.6\",\"0.01\",\"0\",\"1\"]],\"ts\":\"1782016051805\",\"checksum\":1347822818,\"seqId\":325070098343,\"prevSeqId\":325070098321}]}"}
{"action": null, "capture_sequence": 442, "channel": "trades", "connection_sequence": 3, "event": null, "instId": "BTC-USDT-SWAP", "local_receive_ts": "2026-06-21T04:27:31Z", "monotonic_ns": 1643607731588951, "raw": "{\"arg\":{\"channel\":\"trades\",\"instId\":\"BTC-USDT-SWAP\"},\"data\":[{\"instId\":\"BTC-USDT-SWAP\",\"tradeId\":\"2718750385\",\"px\":\"64483\",\"sz\":\"1\",\"side\":\"buy\",\"ts\":\"1782016051826\",\"count\":\"1\",\"source\":\"0\",\"seqId\":325070098347}]}"}
{"action": null, "capture_sequence": 443, "channel": "trades", "connection_sequence": 3, "event": null, "instId": "BTC-USDT-SWAP", "local_receive_ts": "2026-06-21T04:27:32Z", "monotonic_ns": 1643607798189965, "raw": "{\"arg\":{\"channel\":\"trades\",\"instId\":\"BTC-USDT-SWAP\"},\"data\":[{\"instId\":\"BTC-USDT-SWAP\",\"tradeId\":\"2718750394\",\"px\":\"64483\",\"sz\":\"150\",\"side\":\"buy\",\"ts\":\"1782016051893\",\"count\":\"9\",\"source\":\"0\",\"seqId\":325070098366}]}"}
{"action": "update", "capture_sequence": 444, "channel": "books", "connection_sequence": 3, "event": null, "instId": "BTC-USDT-SWAP", "local_receive_ts": "2026-06-21T04:27:32Z", "monotonic_ns": 1643607810677672, "raw": "{\"arg\":{\"channel\":\"books\",\"instId\":\"BTC-USDT-SWAP\"},\"action\":\"update\",\"data\":[{\"asks\":[[\"64483\",\"483.15\",\"0\",\"41\"],[\"64483.7\",\"0.01\",\"0\",\"1\"],[\"64484.2\",\"0\",\"0\",\"0\"],[\"64486.7\",\"136.13\",\"0\",\"1\"],[\"64514.3\",\"0.11\",\"0\",\"5\"],[\"64514.6\",\"25.68\",\"0\",\"3\"]],\"bids\":[],\"ts\":\"1782016051905\",\"checksum\":-1829107266,\"seqId\":325070098380,\"prevSeqId\":325070098343}]}"}
{"action": null, "capture_sequence": 445, "channel": "trades", "connection_sequence": 3, "event": null, "instId": "BTC-USDT-SWAP", "local_receive_ts": "2026-06-21T04:27:32Z", "monotonic_ns": 1643607880114370, "raw": "{\"arg\":{\"channel\":\"trades\",\"instId\":\"BTC-USDT-SWAP\"},\"data\":[{\"instId\":\"BTC-USDT-SWAP\",\"tradeId\":\"2718750395\",\"px\":\"64483\",\"sz\":\"0.47\",\"side\":\"buy\",\"ts\":\"1782016051975\",\"count\":\"1\",\"source\":\"0\",\"seqId\":325070098470}]}"}
{"action": "update", "capture_sequence": 446, "channel": "books", "connection_sequence": 3, "event": null, "instId": "BTC-USDT-SWAP", "local_receive_ts": "2026-06-21T04:27:32Z", "monotonic_ns": 1643607916923130, "raw": "{\"arg\":{\"channel\":\"books\",\"instId\":\"BTC-USDT-SWAP\"},\"action\":\"update\",\"data\":[{\"asks\":[[\"64483\",\"537.4\",\"0\",\"42\"],[\"64483.1\",\"0.64\",\"0\",\"5\"],[\"64483.6\",\"63.85\",\"0\",\"2\"],[\"64484.6\",\"1.22\",\"0\",\"3\"],[\"64485.2\",\"137.71\",\"0\",\"4\"],[\"64486.7\",\"0\",\"0\",\"0\"],[\"64490.1\",\"0.3\",\"0\",\"2\"],[\"64493.6\",\"0.03\",\"0\",\"2\"],[\"64499\",\"348.6\",\"0\",\"22\"],[\"64499.3\",\"0\",\"0\",\"0\"],[\"64502.2\",\"316.68\",\"0\",\"7\"],[\"64502.5\",\"0.2\",\"0\",\"3\"],[\"64502.8\",\"57.07\",\"0\",\"3\"],[\"64503\",\"15.96\",\"0\",\"4\"],[\"64503.4\",\"0\",\"0\",\"0\"],[\"64503.6\",\"1.57\",\"0\",\"3\"],[\"64505.5\",\"107.6\",\"0\",\"4\"],[\"64505.9\",\"0.01\",\"0\",\"1\"],[\"64506\",\"10.84\",\"0\",\"6\"],[\"64506.2\",\"0.03\",\"0\",\"2\"],[\"64509.4\",\"58.18\",\"0\",\"1\"],[\"64509.5\",\"0\",\"0\",\"0\"],[\"64509.8\",\"85.35\",\"0\",\"2\"],[\"64510.4\",\"0.03\",\"0\",\"3\"],[\"64515.5\",\"95.53\",\"0\",\"8\"],[\"64515.6\",\"1.29\",\"0\",\"5\"],[\"64522\",\"5.18\",\"0\",\"10\"],[\"64522.8\",\"15.72\",\"0\",\"5\"],[\"64526.9\",\"40.21\",\"0\",\"5\"],[\"64527\",\"0.17\",\"0\",\"3\"],[\"64527.1\",\"0.46\",\"0\",\"1\"]],\"bids\":[[\"64481.3\",\"1.57\",\"0\",\"2\"],[\"64480.7\",\"1.57\",\"0\",\"2\"],[\"64480.2\",\"1.56\",\"0\",\"1\"],[\"64479.7\",\"1.56\",\"0\",\"1\"],[\"64479.2\",\"1.56\",\"0\",\"1\"],[\"64478.7\",\"1.56\",\"0\",\"1\"],[\"64478.3\",\"1.57\",\"0\",\"2\"],[\"64477.8\",\"1.56\",\"0\",\"1\"],[\"64477.3\",\"79.1\",\"0\",\"2\"],[\"64477.1\",\"32.59\",\"0\",\"4\"],[\"64477\",\"0.01\",\"0\",\"1\"],[\"64476.7\",\"157.79\",\"0\",\"4\"],[\"64476.4\",\"0\",\"0\",\"0\"],[\"64475\",\"0.02\",\"0\",\"1\"],[\"64474.1\",\"496.54\",\"0\",\"2\"],[\"64472.3\",\"0.32\",\"0\",\"2\"],[\"64472.2\",\"1.68\",\"0\",\"1\"],[\"64467.3\",\"95.53\",\"0\",\"2\"],[\"64467.2\",\"70.67\",\"0\",\"2\"],[\"64466.9\",\"0.04\",\"0\",\"2\"],[\"64465.7\",\"0\",\"0\",\"0\"],[\"64465.2\",\"0.02\",\"0\",\"1\"],[\"64464.9\",\"0\",\"0\",\"0\"],[\"64464.8\",\"20.09\",\"0\",\"2\"],[\"64464.4\",\"85.41\",\"0\",\"2\"],[\"64464.1\",\"0\",\"0\",\"0\"],[\"64463.9\",\"0\",\"0\",\"0\"],[\"64463.3\",\"46.56\",\"0\",\"2\"],[\"64462.2\",\"0\",\"0\",\"0\"],[\"64461.2\",\"58.29\",\"0\",\"4\"],[\"64461\",\"0\",\"0\",\"0\"],[\"64456.4\",\"15.67\",\"0\",\"2\"],[\"64456\",\"10.02\",\"0\",\"3\"],[\"64424.6\",\"0\",\"0\",\"0\"]],\"ts\":\"1782016052005\",\"checksum\":-216397826,\"seqId\":325070098552,\"prevSeqId\":325070098380}]}"}
{"action": null, "capture_sequence": 447, "channel": "trades", "connection_sequence": 3, "event": null, "instId": "BTC-USDT-SWAP", "local_receive_ts": "2026-06-21T04:27:32Z", "monotonic_ns": 1643607986050789, "raw": "{\"arg\":{\"channel\":\"trades\",\"instId\":\"BTC-USDT-SWAP\"},\"data\":[{\"instId\":\"BTC-USDT-SWAP\",\"tradeId\":\"2718750396\",\"px\":\"64482.9\",\"sz\":\"2.68\",\"side\":\"sell\",\"ts\":\"1782016052080\",\"count\":\"1\",\"source\":\"0\",\"seqId\":325070098716}]}"}
{"action": "update", "capture_sequence": 448, "channel": "books", "connection_sequence": 3, "event": null, "instId": "BTC-USDT-SWAP", "local_receive_ts": "2026-06-21T04:27:32Z", "monotonic_ns": 1643608015933910, "raw": "{\"arg\":{\"channel\":\"books\",\"instId\":\"BTC-USDT-SWAP\"},\"action\":\"update\",\"data\":[{\"asks\":[[\"64483\",\"527.42\",\"0\",\"42\"],[\"64486.3\",\"2.53\",\"0\",\"3\"],[\"64490.9\",\"0.08\",\"0\",\"3\"],[\"64493.6\",\"0.02\",\"0\",\"1\"],[\"64499\",\"333.09\",\"0\",\"21\"],[\"64499.3\",\"15.51\",\"0\",\"1\"],[\"64501.4\",\"31.04\",\"0\",\"2\"],[\"64501.5\",\"1.57\",\"0\",\"4\"],[\"64502.2\",\"83.91\",\"0\",\"6\"],[\"64502.5\",\"232.97\",\"0\",\"4\"],[\"64502.9\",\"280.73\",\"0\",\"8\"],[\"64503\",\"15.95\",\"0\",\"3\"],[\"64503.6\",\"0.02\",\"0\",\"2\"],[\"64503.8\",\"1.55\",\"0\",\"1\"],[\"64505.5\",\"73.81\",\"0\",\"3\"],[\"64505.9\",\"33.8\",\"0\",\"2\"],[\"64506\",\"10.07\",\"0\",\"5\"],[\"64506.4\",\"0.8\",\"0\",\"4\"],[\"64509.4\",\"0\",\"0\",\"0\"],[\"64509.8\",\"58.19\",\"0\",\"2\"],[\"64510\",\"356.42\",\"0\",\"31\"],[\"64515.5\",\"75.46\",\"0\",\"7\"],[\"64516.2\",\"35.72\",\"0\",\"2\"],[\"64527.1\",\"0\",\"0\",\"0\"]],\"bids\":[[\"64482.9\",\"556.44\",\"0\",\"26\"],[\"64481.3\",\"0.01\",\"0\",\"1\"],[\"64480.7\",\"0.01\",\"0\",\"1\"],[\"64480.5\",\"0\",\"0\",\"0\"],[\"64480.2\",\"0\",\"0\",\"0\"],[\"64479.7\",\"0\",\"0\",\"0\"],[\"64479.2\",\"0\",\"0\",\"0\"],[\"64478.7\",\"0\",\"0\",\"0\"],[\"64478.3\",\"0.01\",\"0\",\"1\"],[\"64477.8\",\"0\",\"0\",\"0\"],[\"64477.6\",\"77.55\",\"0\",\"2\"],[\"64477.3\",\"1.56\",\"0\",\"1\"],[\"64477.1\",\"0.01\",\"0\",\"1\"],[\"64476.8\",\"34.14\",\"0\",\"4\"],[\"64476.4\",\"1.56\",\"0\",\"1\"],[\"64475.9\",\"1.57\",\"0\",\"2\"],[\"64475.4\",\"1.58\",\"0\",\"3\"],[\"64474.9\",\"1.56\",\"0\",\"1\"],[\"64474.4\",\"1.56\",\"0\",\"1\"],[\"64474\",\"1.57\",\"0\",\"2\"],[\"64467.5\",\"18.92\",\"0\",\"4\"],[\"64467.2\",\"69.9\",\"0\",\"1\"],[\"64465.7\",\"20.08\",\"0\",\"1\"],[\"64464.8\",\"85.41\",\"0\",\"2\"],[\"64464.4\",\"0.01\",\"0\",\"1\"],[\"64461.5\",\"58.25\",\"0\",\"3\"],[\"64461.2\",\"0.06\",\"0\",\"3\"],[\"64456.9\",\"0.02\",\"0\",\"1\"],[\"64456.4\",\"15.65\",\"0\",\"1\"]],\"ts\":\"1782016052105\",\"checksum\":-243046578,\"seqId\":325070098814,\"prevSeqId\":325070098552}]}"}
{"action": null, "capture_sequence": 449, "channel": "trades", "connection_sequence": 3, "event": null, "instId": "BTC-USDT-SWAP", "local_receive_ts": "2026-06-21T04:27:32Z", "monotonic_ns": 1643608094733816, "raw": "{\"arg\":{\"channel\":\"trades\",\"instId\":\"BTC-USDT-SWAP\"},\"data\":[{\"instId\":\"BTC-USDT-SWAP\",\"tradeId\":\"2718750397\",\"px\":\"64483\",\"sz\":\"3.65\",\"side\":\"buy\",\"ts\":\"1782016052190\",\"count\":\"1\",\"source\":\"0\",\"seqId\":325070098946}]}"}
{"action": "update", "capture_sequence": 450, "channel": "books", "connection_sequence": 3, "event": null, "instId": "BTC-USDT-SWAP", "local_receive_ts": "2026-06-21T04:27:32Z", "monotonic_ns": 1643608110481732, "raw": "{\"arg\":{\"channel\":\"books\",\"instId\":\"BTC-USDT-SWAP\"},\"action\":\"update\",\"data\":[{\"asks\":[[\"64483\",\"523.77\",\"0\",\"42\"],[\"64492.5\",\"22.05\",\"0\",\"4\"],[\"64506.2\",\"0.8\",\"0\",\"3\"],[\"64506.4\",\"0.03\",\"0\",\"3\"],[\"64509.8\",\"0.01\",\"0\",\"1\"],[\"64509.9\",\"86.55\",\"0\",\"4\"],[\"64510\",\"271.08\",\"0\",\"30\"],[\"64510.1\",\"58.19\",\"0\",\"2\"],[\"64516\",\"520.12\",\"0\",\"7\"],[\"64516.2\",\"15.65\",\"0\",\"1\"]],\"bids\":[[\"64480.5\",\"1.56\",\"0\",\"1\"],[\"64477.6\",\"0.01\",\"0\",\"1\"],[\"64477.5\",\"14.43\",\"0\",\"4\"],[\"64477.4\",\"77.55\",\"0\",\"2\"],[\"64477.3\",\"0\",\"0\",\"0\"],[\"64476.9\",\"5.58\",\"0\",\"4\"],[\"64476.8\",\"32.58\",\"0\",\"3\"],[\"64476.5\",\"1.56\",\"0\",\"1\"],[\"64476.4\",\"0\",\"0\",\"0\"],[\"64467.5\",\"18.15\",\"0\",\"3\"],[\"64467.3\",\"96.3\",\"0\",\"3\"],[\"64465.7\",\"0\",\"0\",\"0\"],[\"64465.5\",\"20.08\",\"0\",\"1\"],[\"64464.8\",\"0.01\",\"0\",\"1\"],[\"64464.4\",\"85.41\",\"0\",\"2\"],[\"64462.2\",\"58.23\",\"0\",\"1\"],[\"64461.5\",\"0.02\",\"0\",\"2\"],[\"64424.7\",\"0\",\"0\",\"0\"]],\"ts\":\"1782016052205\",\"checksum\":1980478199,\"seqId\":325070098964,\"prevSeqId\":325070098814}]}"}
{"action": null, "capture_sequence": 451, "channel": "trades", "connection_sequence": 4, "event": "subscribe", "instId": "BTC-USDT-SWAP", "local_receive_ts": "2026-06-21T04:27:33Z", "monotonic_ns": 1643609567402115, "raw": "{\"event\":\"subscribe\",\"arg\":{\"channel\":\"trades\",\"instId\":\"BTC-USDT-SWAP\"},\"connId\":\"1f23270e\"}"}
{"action": null, "capture_sequence": 452, "channel": "books", "connection_sequence": 4, "event": "subscribe", "instId": "BTC-USDT-SWAP", "local_receive_ts": "2026-06-21T04:27:33Z", "monotonic_ns": 1643609567601671, "raw": "{\"event\":\"subscribe\",\"arg\":{\"channel\":\"books\",\"instId\":\"BTC-USDT-SWAP\"},\"connId\":\"1f23270e\"}"}
{"action": null, "capture_sequence": 453, "channel": "trades", "connection_sequence": 4, "event": null, "instId": "BTC-USDT-SWAP", "local_receive_ts": "2026-06-21T04:27:33Z", "monotonic_ns": 1643609571889861, "raw": "{\"arg\":{\"channel\":\"trades\",\"instId\":\"BTC-USDT-SWAP\"},\"data\":[{\"instId\":\"BTC-USDT-SWAP\",\"tradeId\":\"2718750412\",\"px\":\"64483\",\"sz\":\"7.57\",\"side\":\"buy\",\"ts\":\"1782016053668\",\"count\":\"2\",\"source\":\"0\",\"seqId\":325070100295}]}"}
{"action": "snapshot", "capture_sequence": 454, "channel": "books", "connection_sequence": 4, "event": null, "instId": "BTC-USDT-SWAP", "local_receive_ts": "2026-06-21T04:27:34Z", "monotonic_ns": 1643609938443110, "raw": "{\"arg\":{\"channel\":\"books\",\"instId\":\"BTC-USDT-SWAP\"},\"action\":\"snapshot\",\"data\":[{\"asks\":[[\"64483\",\"494.08\",\"0\",\"42\"],[\"64483.1\",\"0.65\",\"0\",\"6\"],[\"64483.2\",\"0.4\",\"0\",\"1\"],[\"64483.3\",\"0.04\",\"0\",\"1\"],[\"64483.5\",\"0.01\",\"0\",\"1\"],[\"64483.6\",\"70.89\",\"0\",\"1\"],[\"64483.7\",\"0.01\",\"0\",\"1\"],[\"64483.9\",\"0.02\",\"0\",\"2\"],[\"64484\",\"7.08\",\"0\",\"5\"],[\"64484.5\",\"0.47\",\"0\",\"5\"],[\"64484.6\",\"1.22\",\"0\",\"3\"],[\"64484.7\",\"1.56\",\"0\",\"1\"],[\"64484.9\",\"0.01\",\"0\",\"1\"],[\"64485\",\"2\",\"0\",\"1\"],[\"64485.2\",\"137.71\",\"0\",\"4\"],[\"64485.5\",\"0.01\",\"0\",\"1\"],[\"64485.6\",\"0.01\",\"0\",\"1\"],[\"64485.7\",\"1.7\",\"0\",\"4\"],[\"64485.8\",\"0.42\",\"0\",\"4\"],[\"64485.9\",\"5.43\",\"0\",\"2\"],[\"64486\",\"51.09\",\"0\",\"6\"],[\"64486.1\",\"0.01\",\"0\",\"1\"],[\"64486.2\",\"13.53\",\"0\",\"7\"],[\"64486.3\",\"13.95\",\"0\",\"4\"],[\"64486.4\",\"1.27\",\"0\",\"2\"],[\"64486.5\",\"154.5\",\"0\",\"3\"],[\"64486.6\",\"0.99\",\"0\",\"1\"],[\"64486.8\",\"1.75\",\"0\",\"4\"],[\"64486.9\",\"0.12\",\"0\",\"2\"],[\"64487\",\"5.11\",\"0\",\"4\"],[\"64487.1\",\"0.53\",\"0\",\"4\"],[\"64487.2\",\"0.03\",\"0\",\"2\"],[\"64487.3\",\"0.04\",\"0\",\"2\"],[\"64487.4\",\"0.5\",\"0\",\"6\"],[\"64487.5\",\"1.6\",\"0\",\"4\"],[\"64487.7\",\"0.01\",\"0\",\"1\"],[\"64487.8\",\"0.1\",\"0\",\"4\"],[\"64487.9\",\"2.07\",\"0\",\"3\"],[\"64488\",\"57.87\",\"0\",\"27\"],[\"64488.1\",\"0.66\",\"0\",\"1\"],[\"64488.2\",\"4.73\",\"0\",\"3\"],[\"64488.3\",\"0.02\",\"0\",\"2\"],[\"64488.4\",\"5.67\",\"0\",\"6\"],[\"64488.6\",\"1.58\",\"0\",\"3\"],[\"64488.7\",\"0.04\",\"0\",\"1\"],[\"64488.8\",\"50\",\"0\",\"1\"],[\"64488.9\",\"1.33\",\"0\",\"7\"],[\"64489\",\"19.1\",\"0\",\"8\"],[\"64489.1\",\"0.04\",\"0\",\"3\"],[\"64489.2\",\"247.47\",\"0\",\"3\"],[\"64489.3\",\"3.25\",\"0\",\"4\"],[\"64489.4\",\"2.93\",\"0\",\"5\"],[\"64489.5\",\"1.02\",\"0\",\"3\"],[\"64489.6\",\"63.4\",\"0\",\"3\"],[\"64489.7\",\"38.03\",\"0\",\"2\"],[\"64489.8\",\"0.04\",\"0\",\"3\"],[\"64489.9\",\"1\",\"0\",\"1\"],[\"64490\",\"55.77\",\"0\",\"19\"],[\"64490.1\",\"0.3\",\"0\",\"2\"],[\"64490.2\",\"1.2\",\"0\",\"1\"],[\"64490.3\",\"1\",\"0\",\"1\"],[\"64490.4\",\"0.03\",\"0\",\"3\"],[\"64490.5\",\"3.01\",\"0\",\"4\"],[\"64490.6\",\"1.08\",\"0\",\"3\"],[\"64490.7\",\"0.06\",\"0\",\"2\"],[\"64490.8\",\"31.73\",\"0\",\"3\"],[\"64490.9\",\"0.08\",\"0\",\"3\"],[\"64491\",\"0.01\",\"0\",\"1\"],[\"64491.2\",\"1.01\",\"0\",\"2\"],[\"64491.3\",\"1.21\",\"0\",\"2\"],[\"64491.4\",\"0.02\",\"0\",\"2\"],[\"64491.5\",\"0.1\",\"0\",\"1\"],[\"64491.6\",\"1.25\",\"0\",\"5\"],[\"64491.7\",\"1.22\",\"0\",\"3\"],[\"64491.8\",\"0.05\",\"0\",\"1\"],[\"64491.9\",\"0.42\",\"0\",\"5\"],[\"64492\",\"1.24\",\"0\",\"5\"],[\"64492.1\",\"1.5\",\"0\",\"1\"],[\"64492.2\",\"0.91\",\"0\",\"7\"],[\"64492.3\",\"0.03\",\"0\",\"1\"],[\"64492.4\",\"0.08\",\"0\",\"6\"],[\"64492.5\",\"22.05\",\"0\",\"4\"],[\"64492.6\",\"0.12\",\"0\",\"1\"],[\"64492.7\",\"0.3\",\"0\",\"2\"],[\"64492.8\",\"0.43\",\"0\",\"8\"],[\"64492.9\",\"0.01\",\"0\",\"1\"],[\"64493\",\"17.18\",\"0\",\"4\"],[\"64493.1\",\"0.45\",\"0\",\"2\"],[\"64493.2\",\"8.07\",\"0\",\"5\"],[\"64493.3\",\"18.63\",\"0\",\"6\"],[\"64493.4\",\"21.5\",\"0\",\"9\"],[\"64493.5\",\"186.04\",\"0\",\"6\"],[\"64493.6\",\"0.02\",\"0\",\"1\"],[\"64493.7\",\"1.25\",\"0\",\"3\"],[\"64493.8\",\"0.03\",\"0\",\"2\"],[\"64493.9\",\"46.54\",\"0\",\"1\"],[\"64494\",\"238.94\",\"0\",\"6\"],[\"64494.3\",\"0.48\",\"0\",\"5\"],[\"64494.4\",\"0.6\",\"0\",\"6\"],[\"64494.6\",\"24.97\",\"0\",\"7\"],[\"64494.7\",\"24.05\",\"0\",\"5\"],[\"64494.8\",\"0.45\",\"0\",\"2\"],[\"64494.9\",\"15.37\",\"0\",\"6\"],[\"64495\",\"1.49\",\"0\",\"8\"],[\"64495.1\",\"0.07\",\"0\",\"3\"],[\"64495.2\",\"0.02\",\"0\",\"2\"],[\"64495.3\",\"5.03\",\"0\",\"3\"],[\"64495.4\",\"0.06\",\"0\",\"3\"],[\"64495.5\",\"37.37\",\"0\",\"6\"],[\"64495.6\",\"92.77\",\"0\",\"2\"],[\"64495.7\",\"11.35\",\"0\",\"3\"],[\"64495.8\",\"167.02\",\"0\",\"6\"],[\"64495.9\",\"1.01\",\"0\",\"4\"],[\"64496\",\"5.1\",\"0\",\"5\"],[\"64496.1\",\"46.6\",\"0\",\"4\"],[\"64496.2\",\"15.96\",\"0\",\"1\"],[\"64496.3\",\"349.92\",\"0\",\"7\"],[\"64496.4\",\"0.02\",\"0\",\"2\"],[\"64496.6\",\"34.78\",\"0\",\"3\"],[\"64496.7\",\"0.01\",\"0\",\"1\"],[\"64496.8\",\"29.39\",\"0\",\"3\"],[\"64497\",\"18.82\",\"0\",\"6\"],[\"64497.1\",\"0.01\",\"0\",\"1\"],[\"64497.2\",\"0.84\",\"0\",\"3\"],[\"64497.3\",\"41.14\",\"0\",\"4\"],[\"64497.4\",\"0.08\",\"0\",\"1\"],[\"64497.5\",\"0.33\",\"0\",\"3\"],[\"64497.6\",\"0.13\",\"0\",\"3\"],[\"64497.8\",\"0.01\",\"0\",\"1\"],[\"64497.9\",\"0.01\",\"0\",\"1\"],[\"64498\",\"24.62\",\"0\",\"4\"],[\"64498.1\",\"4.23\",\"0\",\"4\"],[\"64498.2\",\"0.04\",\"0\",\"3\"],[\"64498.3\",\"84.77\",\"0\",\"6\"],[\"64498.5\",\"23.45\",\"0\",\"5\"],[\"64498.6\",\"0.29\",\"0\",\"6\"],[\"64498.7\",\"2.02\",\"0\",\"4\"],[\"64498.8\",\"512.06\",\"0\",\"4\"],[\"64498.9\",\"3.42\",\"0\",\"2\"],[\"64499\",\"333.09\",\"0\",\"21\"],[\"64499.1\",\"3.41\",\"0\",\"6\"],[\"64499.2\",\"0.01\",\"0\",\"1\"],[\"64499.4\",\"1.73\",\"0\",\"3\"],[\"64499.5\",\"46.54\",\"0\",\"1\"],[\"64499.6\",\"59.27\",\"0\",\"3\"],[\"64499.7\",\"19.72\",\"0\",\"4\"],[\"64499.8\",\"1.08\",\"0\",\"2\"],[\"64499.9\",\"1118.67\",\"0\",\"3\"],[\"64500\",\"3463.89\",\"0\",\"1038\"],[\"64500.1\",\"0.05\",\"0\",\"4\"],[\"64500.2\",\"0.02\",\"0\",\"2\"],[\"64500.3\",\"2.78\",\"0\",\"5\"],[\"64500.4\",\"0.03\",\"0\",\"3\"],[\"64500.5\",\"2.49\",\"0\",\"2\"],[\"64500.6\",\"93.57\",\"0\",\"5\"],[\"64500.7\",\"3.91\",\"0\",\"1\"],[\"64500.8\",\"0.36\",\"0\",\"1\"],[\"64500.9\",\"41.86\",\"0\",\"4\"],[\"64501\",\"0.27\",\"0\",\"3\"],[\"64501.1\",\"0.05\",\"0\",\"2\"],[\"64501.2\",\"0.03\",\"0\",\"3\"],[\"64501.3\",\"0.02\",\"0\",\"1\"],[\"64501.4\",\"0.01\",\"0\",\"1\"],[\"64501.5\",\"1.57\",\"0\",\"4\"],[\"64501.6\",\"1.89\",\"0\",\"3\"],[\"64501.7\",\"233.32\",\"0\",\"5\"],[\"64501.8\",\"59.01\",\"0\",\"6\"],[\"64501.9\",\"0.08\",\"0\",\"1\"],[\"64502\",\"2.12\",\"0\",\"6\"],[\"64502.1\",\"0.01\",\"0\",\"1\"],[\"64502.2\",\"83.91\",\"0\",\"6\"],[\"64502.3\",\"11.26\",\"0\",\"4\"],[\"64502.4\",\"0.19\",\"0\",\"6\"],[\"64502.5\",\"0.2\",\"0\",\"3\"],[\"64502.6\",\"15.66\",\"0\",\"2\"],[\"64502.7\",\"0.04\",\"0\",\"4\"],[\"64502.8\",\"57.07\",\"0\",\"3\"],[\"64502.9\",\"280.72\",\"0\",\"7\"],[\"64503\",\"15.95\",\"0\",\"3\"],[\"64503.1\",\"41.24\",\"0\",\"9\"],[\"64503.2\",\"12.3\",\"0\",\"4\"],[\"64503.3\",\"0.02\",\"0\",\"2\"],[\"64503.5\",\"63.72\",\"0\",\"6\"],[\"64503.6\",\"0.02\",\"0\",\"2\"],[\"64503.7\",\"0.29\",\"0\",\"2\"],[\"64503.9\",\"15.65\",\"0\",\"1\"],[\"64504\",\"54.55\",\"0\",\"8\"],[\"64504.1\",\"21.33\",\"0\",\"7\"],[\"64504.2\",\"511.1\",\"0\",\"6\"],[\"64504.3\",\"0.04\",\"0\",\"2\"],[\"64504.4\",\"1.13\",\"0\",\"4\"],[\"64504.5\",\"59.15\",\"0\",\"6\"],[\"64504.7\",\"0.01\",\"0\",\"1\"],[\"64504.8\",\"0.11\",\"0\",\"5\"],[\"64504.9\",\"0.41\",\"0\",\"4\"],[\"64505\",\"0.82\",\"0\",\"3\"],[\"64505.1\",\"0.02\",\"0\",\"2\"],[\"64505.2\",\"15.65\",\"0\",\"1\"],[\"64505.3\",\"1.16\",\"0\",\"2\"],[\"64505.4\",\"59.23\",\"0\",\"4\"],[\"64505.5\",\"73.81\",\"0\",\"3\"],[\"64505.6\",\"57.91\",\"0\",\"4\"],[\"64505.7\",\"0.56\",\"0\",\"1\"],[\"64505.8\",\"0.85\",\"0\",\"2\"],[\"64505.9\",\"33.8\",\"0\",\"2\"],[\"64506\",\"10.07\",\"0\",\"5\"],[\"64506.1\",\"31.13\",\"0\",\"2\"],[\"64506.2\",\"0.03\",\"0\",\"2\"],[\"64506.3\",\"15.66\",\"0\",\"2\"],[\"64506.4\",\"0.03\",\"0\",\"3\"],[\"64506.5\",\"15.72\",\"0\",\"2\"],[\"64506.6\",\"10.15\",\"0\",\"3\"],[\"64506.7\",\"0.19\",\"0\",\"15\"],[\"64506.8\",\"92.27\",\"0\",\"5\"],[\"64506.9\",\"38.85\",\"0\",\"3\"],[\"64507\",\"0.06\",\"0\",\"1\"],[\"64507.1\",\"0.06\",\"0\",\"4\"],[\"64507.2\",\"14.03\",\"0\",\"2\"],[\"64507.3\",\"0.03\",\"0\",\"2\"],[\"64507.4\",\"27.27\",\"0\",\"1\"],[\"64507.5\",\"0.13\",\"0\",\"6\"],[\"64507.6\",\"0.03\",\"0\",\"2\"],[\"64507.7\",\"0.07\",\"0\",\"4\"],[\"64507.8\",\"34.13\",\"0\",\"5\"],[\"64507.9\",\"0.27\",\"0\",\"4\"],[\"64508\",\"14.55\",\"0\",\"9\"],[\"64508.1\",\"0.82\",\"0\",\"3\"],[\"64508.2\",\"59.01\",\"0\",\"5\"],[\"64508.4\",\"1.62\",\"0\",\"5\"],[\"64508.5\",\"42.46\",\"0\",\"3\"],[\"64508.6\",\"0.01\",\"0\",\"1\"],[\"64508.7\",\"15.67\",\"0\",\"7\"],[\"64508.8\",\"0.04\",\"0\",\"2\"],[\"64508.9\",\"160.96\",\"0\",\"5\"],[\"64509\",\"15.66\",\"0\",\"2\"],[\"64509.1\",\"0.03\",\"0\",\"3\"],[\"64509.3\",\"0.28\",\"0\",\"5\"],[\"64509.5\",\"85.34\",\"0\",\"1\"],[\"64509.6\",\"15.68\",\"0\",\"3\"],[\"64509.8\",\"58.19\",\"0\",\"2\"],[\"64509.9\",\"1.21\",\"0\",\"3\"],[\"64510\",\"271.08\",\"0\",\"30\"],[\"64510.1\",\"0.01\",\"0\",\"1\"],[\"64510.2\",\"15.65\",\"0\",\"1\"],[\"64510.3\",\"1\",\"0\",\"1\"],[\"64510.4\",\"0.03\",\"0\",\"3\"],[\"64510.5\",\"62\",\"0\",\"5\"],[\"64510.6\",\"0.19\",\"0\",\"2\"],[\"64510.7\",\"1.02\",\"0\",\"3\"],[\"64510.8\",\"0.02\",\"0\",\"1\"],[\"64510.9\",\"0.07\",\"0\",\"4\"],[\"64511\",\"25.02\",\"0\",\"8\"],[\"64511.1\",\"18.79\",\"0\",\"6\"],[\"64511.2\",\"0.02\",\"0\",\"2\"],[\"64511.3\",\"0.93\",\"0\",\"7\"],[\"64511.4\",\"15.78\",\"0\",\"4\"],[\"64511.5\",\"0.3\",\"0\",\"6\"],[\"64511.7\",\"0.02\",\"0\",\"2\"],[\"64511.8\",\"6.2\",\"0\",\"1\"],[\"64511.9\",\"0.14\",\"0\",\"1\"],[\"64512\",\"2.88\",\"0\",\"13\"],[\"64512.1\",\"37.24\",\"0\",\"4\"],[\"64512.2\",\"11.23\",\"0\",\"3\"],[\"64512.3\",\"63.54\",\"0\",\"5\"],[\"64512.4\",\"0.08\",\"0\",\"1\"],[\"64512.5\",\"1.16\",\"0\",\"6\"],[\"64512.6\",\"58.74\",\"0\",\"7\"],[\"64512.7\",\"91.6\",\"0\",\"3\"],[\"64512.9\",\"17.79\",\"0\",\"4\"],[\"64513\",\"10.37\",\"0\",\"3\"],[\"64513.1\",\"1.56\",\"0\",\"2\"],[\"64513.2\",\"1.15\",\"0\",\"5\"],[\"64513.3\",\"24.68\",\"0\",\"10\"],[\"64513.4\",\"15.68\",\"0\",\"3\"],[\"64513.5\",\"1.6\",\"0\",\"4\"],[\"64513.7\",\"0.01\",\"0\",\"1\"],[\"64513.8\",\"1.21\",\"0\",\"2\"],[\"64513.9\",\"0.12\",\"0\",\"1\"],[\"64514\",\"19.86\",\"0\",\"3\"],[\"64514.1\",\"1.23\",\"0\",\"4\"],[\"64514.2\",\"1.07\",\"0\",\"4\"],[\"64514.3\",\"0.11\",\"0\",\"5\"],[\"64514.4\",\"16.9\",\"0\",\"5\"],[\"64514.5\",\"0.74\",\"0\",\"5\"],[\"64514.6\",\"25.68\",\"0\",\"3\"],[\"64514.7\",\"1.01\",\"0\",\"2\"],[\"64514.8\",\"60.79\",\"0\",\"6\"],[\"64514.9\",\"497.81\",\"0\",\"5\"],[\"64515\",\"0.04\",\"0\",\"2\"],[\"64515.2\",\"15.66\",\"0\",\"2\"],[\"64515.3\",\"1.21\",\"0\",\"2\"],[\"64515.4\",\"20.53\",\"0\",\"6\"],[\"64515.5\",\"75.46\",\"0\",\"7\"],[\"64515.6\",\"1.29\",\"0\",\"5\"],[\"64515.7\",\"61.85\",\"0\",\"4\"],[\"64515.8\",\"16.99\",\"0\",\"3\"],[\"64515.9\",\"47.94\",\"0\",\"4\"],[\"64516\",\"500.05\",\"0\",\"6\"],[\"64516.1\",\"0.04\",\"0\",\"4\"],[\"64516.2\",\"15.65\",\"0\",\"1\"],[\"64516.3\",\"2.16\",\"0\",\"3\"],[\"64516.4\",\"102.84\",\"0\",\"10\"],[\"64516.5\",\"197.9\",\"0\",\"3\"],[\"64516.6\",\"0.7\",\"0\",\"2\"],[\"64516.7\",\"0.36\",\"0\",\"9\"],[\"64516.8\",\"211.24\",\"0\",\"4\"],[\"64516.9\",\"14.05\",\"0\",\"4\"],[\"64517\",\"17.37\",\"0\",\"20\"],[\"64517.1\",\"0.18\",\"0\",\"1\"],[\"64517.2\",\"0.76\",\"0\",\"5\"],[\"64517.4\",\"0.03\",\"0\",\"2\"],[\"64517.6\",\"72.07\",\"0\",\"3\"],[\"64517.7\",\"18.68\",\"0\",\"4\"],[\"64517.8\",\"0.1\",\"0\",\"3\"],[\"64517.9\",\"0.15\",\"0\",\"3\"],[\"64518\",\"103.04\",\"0\",\"12\"],[\"64518.1\",\"0.15\",\"0\",\"5\"],[\"64518.2\",\"15.68\",\"0\",\"2\"],[\"64518.3\",\"0.02\",\"0\",\"2\"],[\"64518.4\",\"76.16\",\"0\",\"4\"],[\"64518.5\",\"0.01\",\"0\",\"1\"],[\"64518.6\",\"0.11\",\"0\",\"8\"],[\"64518.8\",\"70.2\",\"0\",\"3\"],[\"64518.9\",\"4.54\",\"0\",\"2\"],[\"64519\",\"8.67\",\"0\",\"5\"],[\"64519.1\",\"43.07\",\"0\",\"2\"],[\"64519.2\",\"0.48\",\"0\",\"7\"],[\"64519.3\",\"15.7\",\"0\",\"3\"],[\"64519.4\",\"0.06\",\"0\",\"2\"],[\"64519.5\",\"54.3\",\"0\",\"6\"],[\"64519.6\",\"4.76\",\"0\",\"3\"],[\"64519.7\",\"10.81\",\"0\",\"7\"],[\"64519.8\",\"89.37\",\"0\",\"5\"],[\"64519.9\",\"496.56\",\"0\",\"2\"],[\"64520\",\"78.62\",\"0\",\"63\"],[\"64520.1\",\"0.02\",\"0\",\"2\"],[\"64520.2\",\"0.01\",\"0\",\"1\"],[\"64520.3\",\"0.05\",\"0\",\"3\"],[\"64520.4\",\"1.19\",\"0\",\"7\"],[\"64520.5\",\"0.04\",\"0\",\"3\"],[\"64520.6\",\"0.02\",\"0\",\"2\"],[\"64520.8\",\"0.04\",\"0\",\"2\"],[\"64520.9\",\"0.02\",\"0\",\"2\"],[\"64521\",\"121.98\",\"0\",\"8\"],[\"64521.1\",\"0.01\",\"0\",\"1\"],[\"64521.3\",\"0.01\",\"0\",\"1\"],[\"64521.4\",\"0.35\",\"0\",\"1\"],[\"64521.5\",\"3.16\",\"0\",\"7\"],[\"64521.6\",\"0.02\",\"0\",\"2\"],[\"64521.7\",\"0.06\",\"0\",\"3\"],[\"64521.8\",\"2.44\",\"0\",\"4\"],[\"64521.9\",\"16.99\",\"0\",\"2\"],[\"64522\",\"5.18\",\"0\",\"10\"],[\"64522.1\",\"15.99\",\"0\",\"2\"],[\"64522.2\",\"0.15\",\"0\",\"8\"],[\"64522.3\",\"0.01\",\"0\",\"1\"],[\"64522.4\",\"0.42\",\"0\",\"1\"],[\"64522.5\",\"0.01\",\"0\",\"1\"],[\"64522.6\",\"1.54\",\"0\",\"3\"],[\"64522.7\",\"403.98\",\"0\",\"2\"],[\"64522.8\",\"15.72\",\"0\",\"5\"],[\"64522.9\",\"58.86\",\"0\",\"2\"],[\"64523.1\",\"0.01\",\"0\",\"1\"],[\"64523.2\",\"0.02\",\"0\",\"2\"],[\"64523.3\",\"186.34\",\"0\",\"3\"],[\"64523.4\",\"21.46\",\"0\",\"3\"],[\"64523.6\",\"0.03\",\"0\",\"1\"],[\"64523.7\",\"43.32\",\"0\",\"2\"],[\"64523.8\",\"0.02\",\"0\",\"1\"],[\"64524\",\"0.05\",\"0\",\"4\"],[\"64524.1\",\"2.51\",\"0\",\"2\"],[\"64524.2\",\"17.99\",\"0\",\"2\"],[\"64524.3\",\"15.65\",\"0\",\"1\"],[\"64524.5\",\"0.17\",\"0\",\"3\"],[\"64524.6\",\"0.01\",\"0\",\"1\"],[\"64524.7\",\"0.02\",\"0\",\"1\"],[\"64524.8\",\"3.05\",\"0\",\"5\"],[\"64524.9\",\"2.19\",\"0\",\"7\"],[\"64525\",\"2.51\",\"0\",\"18\"],[\"64525.1\",\"0.46\",\"0\",\"1\"],[\"64525.2\",\"55.22\",\"0\",\"2\"],[\"64525.3\",\"0.01\",\"0\",\"1\"],[\"64525.4\",\"11.18\",\"0\",\"1\"],[\"64525.5\",\"0.02\",\"0\",\"1\"],[\"64525.6\",\"37.24\",\"0\",\"2\"],[\"64525.7\",\"0.03\",\"0\",\"1\"],[\"64525.8\",\"0.02\",\"0\",\"2\"],[\"64525.9\",\"2.54\",\"0\",\"3\"],[\"64526\",\"1.3\",\"0\",\"4\"],[\"64526.1\",\"15.65\",\"0\",\"1\"],[\"64526.2\",\"6.57\",\"0\",\"2\"],[\"64526.3\",\"2.95\",\"0\",\"1\"],[\"64526.4\",\"46.54\",\"0\",\"1\"],[\"64526.5\",\"60\",\"0\",\"3\"],[\"64526.6\",\"14.23\",\"0\",\"4\"],[\"64526.7\",\"0.01\",\"0\",\"1\"],[\"64526.8\",\"0.37\",\"0\",\"2\"],[\"64526.9\",\"40.21\",\"0\",\"5\"],[\"64527\",\"0.17\",\"0\",\"3\"],[\"64527.1\",\"0.46\",\"0\",\"1\"]],\"bids\":[[\"64482.9\",\"474.52\",\"0\",\"23\"],[\"64482.8\",\"63.5\",\"0\",\"14\"],[\"64482.7\",\"0.02\",\"0\",\"1\"],[\"64482.6\",\"3.29\",\"0\",\"2\"],[\"64482.3\",\"0.03\",\"0\",\"2\"],[\"64482.2\",\"1.6\",\"0\",\"1\"],[\"64482.1\",\"0.05\",\"0\",\"3\"],[\"64482\",\"107.76\",\"0\",\"3\"],[\"64481.9\",\"0.77\",\"0\",\"1\"],[\"64481.6\",\"0.01\",\"0\",\"1\"],[\"64481.4\",\"0.01\",\"0\",\"1\"],[\"64481.3\",\"0.01\",\"0\",\"1\"],[\"64481.2\",\"0.7\",\"0\",\"1\"],[\"64481.1\",\"0.01\",\"0\",\"1\"],[\"64481\",\"39.68\",\"0\",\"2\"],[\"64480.8\",\"46.55\",\"0\",\"2\"],[\"64480.7\",\"0.01\",\"0\",\"1\"],[\"64480.5\",\"2.45\",\"0\",\"1\"],[\"64480.1\",\"0.01\",\"0\",\"1\"],[\"64480\",\"61.3\",\"0\",\"5\"],[\"64479.9\",\"0.13\",\"0\",\"2\"],[\"64479.8\",\"0.01\",\"0\",\"1\"],[\"64479.6\",\"0.02\",\"0\",\"2\"],[\"64479\",\"0.02\",\"0\",\"2\"],[\"64478.9\",\"4\",\"0\",\"1\"],[\"64478.6\",\"46.54\",\"0\",\"1\"],[\"64478.5\",\"0.02\",\"0\",\"2\"],[\"64478.4\",\"8\",\"0\",\"1\"],[\"64478.3\",\"0.01\",\"0\",\"1\"],[\"64478.2\",\"0.01\",\"0\",\"1\"],[\"64478.1\",\"13.95\",\"0\",\"1\"],[\"64478\",\"0.01\",\"0\",\"1\"],[\"64477.7\",\"0.02\",\"0\",\"2\"],[\"64477.6\",\"0.01\",\"0\",\"1\"],[\"64477.5\",\"12.87\",\"0\",\"3\"],[\"64477.4\",\"0.01\",\"0\",\"1\"],[\"64477.2\",\"6.22\",\"0\",\"1\"],[\"64477.1\",\"1.55\",\"0\",\"3\"],[\"64477\",\"0.01\",\"0\",\"1\"],[\"64476.9\",\"35.06\",\"0\",\"4\"],[\"64476.8\",\"77.54\",\"0\",\"1\"],[\"64476.7\",\"157.79\",\"0\",\"4\"],[\"64476.6\",\"0.01\",\"0\",\"1\"],[\"64476.3\",\"62.54\",\"0\",\"3\"],[\"64476.2\",\"0.01\",\"0\",\"1\"],[\"64476.1\",\"262.49\",\"0\",\"2\"],[\"64476\",\"0.04\",\"0\",\"2\"],[\"64475.9\",\"0.01\",\"0\",\"1\"],[\"64475.8\",\"37.24\",\"0\",\"2\"],[\"64475.7\",\"1.56\",\"0\",\"1\"],[\"64475.4\",\"0.02\",\"0\",\"2\"],[\"64475.2\",\"1.56\",\"0\",\"1\"],[\"64475.1\",\"138.61\",\"0\",\"5\"],[\"64475\",\"0.02\",\"0\",\"1\"],[\"64474.8\",\"31.07\",\"0\",\"2\"],[\"64474.7\",\"1.57\",\"0\",\"2\"],[\"64474.6\",\"0.38\",\"0\",\"1\"],[\"64474.5\",\"15.9\",\"0\",\"1\"],[\"64474.3\",\"3.1\",\"0\",\"1\"],[\"64474.2\",\"46.54\",\"0\",\"1\"],[\"64474.1\",\"496.54\",\"0\",\"2\"],[\"64474\",\"0.01\",\"0\",\"1\"],[\"64473.9\",\"0.03\",\"0\",\"2\"],[\"64473.8\",\"0.02\",\"0\",\"2\"],[\"64473.6\",\"1.56\",\"0\",\"1\"],[\"64473.5\",\"99.58\",\"0\",\"2\"],[\"64473.4\",\"0.42\",\"0\",\"2\"],[\"64473.3\",\"0.01\",\"0\",\"1\"],[\"64473.2\",\"12.97\",\"0\",\"3\"],[\"64472.9\",\"17.84\",\"0\",\"2\"],[\"64472.8\",\"0.38\",\"0\",\"1\"],[\"64472.7\",\"1.17\",\"0\",\"3\"],[\"64472.6\",\"1.72\",\"0\",\"2\"],[\"64472.5\",\"3.1\",\"0\",\"1\"],[\"64472.3\",\"0.32\",\"0\",\"2\"],[\"64472.2\",\"1.68\",\"0\",\"1\"],[\"64472.1\",\"0.82\",\"0\",\"3\"],[\"64472\",\"0.02\",\"0\",\"2\"],[\"64471.9\",\"1.92\",\"0\",\"1\"],[\"64471.7\",\"0.3\",\"0\",\"1\"],[\"64471.6\",\"2.19\",\"0\",\"2\"],[\"64471.5\",\"0.01\",\"0\",\"1\"],[\"64471.4\",\"49.31\",\"0\",\"3\"],[\"64471.3\",\"15.98\",\"0\",\"1\"],[\"64471.1\",\"151.91\",\"0\",\"2\"],[\"64470.9\",\"16.01\",\"0\",\"2\"],[\"64470.8\",\"49.48\",\"0\",\"2\"],[\"64470.7\",\"6.24\",\"0\",\"3\"],[\"64470.5\",\"0.01\",\"0\",\"1\"],[\"64470.4\",\"4\",\"0\",\"1\"],[\"64470.3\",\"14.71\",\"0\",\"4\"],[\"64470.2\",\"7.75\",\"0\",\"1\"],[\"64470.1\",\"395.28\",\"0\",\"1\"],[\"64470\",\"37.69\",\"0\",\"4\"],[\"64469.9\",\"169.58\",\"0\",\"4\"],[\"64469.8\",\"84.34\",\"0\",\"2\"],[\"64469.7\",\"0.01\",\"0\",\"1\"],[\"64469.6\",\"0.01\",\"0\",\"1\"],[\"64469.5\",\"0.01\",\"0\",\"1\"],[\"64469.4\",\"46.54\",\"0\",\"1\"],[\"64469.3\",\"496.53\",\"0\",\"1\"],[\"64469.2\",\"154.75\",\"0\",\"2\"],[\"64469.1\",\"0.01\",\"0\",\"1\"],[\"64468.9\",\"0.3\",\"0\",\"1\"],[\"64468.8\",\"11.33\",\"0\",\"1\"],[\"64468.7\",\"76.39\",\"0\",\"4\"],[\"64468.2\",\"62.15\",\"0\",\"1\"],[\"64468\",\"0.02\",\"0\",\"2\"],[\"64467.9\",\"0.01\",\"0\",\"1\"],[\"64467.8\",\"0.56\",\"0\",\"2\"],[\"64467.6\",\"0.03\",\"0\",\"3\"],[\"64467.5\",\"18.15\",\"0\",\"3\"],[\"64467.4\",\"132.71\",\"0\",\"2\"],[\"64467.3\",\"95.53\",\"0\",\"2\"],[\"64467.2\",\"69.9\",\"0\",\"1\"],[\"64467.1\",\"31.22\",\"0\",\"2\"],[\"64467\",\"282.31\",\"0\",\"3\"],[\"64466.9\",\"0.04\",\"0\",\"2\"],[\"64466.8\",\"18.96\",\"0\",\"2\"],[\"64466.6\",\"0.01\",\"0\",\"1\"],[\"64466.3\",\"0.77\",\"0\",\"1\"],[\"64466.2\",\"33.82\",\"0\",\"2\"],[\"64466.1\",\"2.28\",\"0\",\"1\"],[\"64466\",\"0.02\",\"0\",\"2\"],[\"64465.6\",\"28.21\",\"0\",\"4\"],[\"64465.4\",\"507.87\",\"0\",\"3\"],[\"64465.3\",\"46.58\",\"0\",\"4\"],[\"64464.8\",\"20.09\",\"0\",\"2\"],[\"64464.7\",\"1\",\"0\",\"1\"],[\"64464.5\",\"0.02\",\"0\",\"2\"],[\"64464.4\",\"0.01\",\"0\",\"1\"],[\"64464.2\",\"161.79\",\"0\",\"6\"],[\"64464\",\"0.06\",\"0\",\"4\"],[\"64463.9\",\"85.4\",\"0\",\"1\"],[\"64463.8\",\"347.78\",\"0\",\"2\"],[\"64463.7\",\"31.05\",\"0\",\"1\"],[\"64463.6\",\"0.13\",\"0\",\"2\"],[\"64463.5\",\"0.01\",\"0\",\"1\"],[\"64463.3\",\"46.56\",\"0\",\"2\"],[\"64463.1\",\"40.45\",\"0\",\"2\"],[\"64463\",\"0.02\",\"0\",\"2\"],[\"64462.8\",\"15.65\",\"0\",\"1\"],[\"64462.6\",\"0.01\",\"0\",\"1\"],[\"64462.4\",\"0.01\",\"0\",\"1\"],[\"64462.2\",\"232.91\",\"0\",\"1\"],[\"64462.1\",\"14.43\",\"0\",\"2\"],[\"64462\",\"200.01\",\"0\",\"2\"],[\"64461.9\",\"2.29\",\"0\",\"2\"],[\"64461.7\",\"0.01\",\"0\",\"1\"],[\"64461.6\",\"58.23\",\"0\",\"1\"],[\"64461.5\",\"37.25\",\"0\",\"5\"],[\"64461.4\",\"14.24\",\"0\",\"4\"],[\"64461.3\",\"496.57\",\"0\",\"2\"],[\"64461.2\",\"0.06\",\"0\",\"3\"],[\"64461.1\",\"46.56\",\"0\",\"2\"],[\"64460.9\",\"95.5\",\"0\",\"2\"],[\"64460.8\",\"154.63\",\"0\",\"4\"],[\"64460.7\",\"44.95\",\"0\",\"2\"],[\"64460.6\",\"0.01\",\"0\",\"1\"],[\"64460.3\",\"2.28\",\"0\",\"1\"],[\"64460.1\",\"3.91\",\"0\",\"2\"],[\"64460\",\"0.31\",\"0\",\"3\"],[\"64459.7\",\"0.01\",\"0\",\"1\"],[\"64459.6\",\"169.56\",\"0\",\"2\"],[\"64459.5\",\"15.65\",\"0\",\"1\"],[\"64459.4\",\"38.83\",\"0\",\"1\"],[\"64459.3\",\"39.02\",\"0\",\"3\"],[\"64459.2\",\"0.01\",\"0\",\"1\"],[\"64459.1\",\"46.54\",\"0\",\"1\"],[\"64458.9\",\"0.01\",\"0\",\"1\"],[\"64458.7\",\"0.01\",\"0\",\"1\"],[\"64458.6\",\"0.16\",\"0\",\"2\"],[\"64458.4\",\"2.61\",\"0\",\"2\"],[\"64458.3\",\"0.03\",\"0\",\"3\"],[\"64458\",\"76.93\",\"0\",\"2\"],[\"64457.9\",\"0.01\",\"0\",\"1\"],[\"64457.6\",\"357.43\",\"0\",\"2\"],[\"64457.5\",\"0.01\",\"0\",\"1\"],[\"64457.4\",\"11.19\",\"0\",\"2\"],[\"64457.1\",\"396.35\",\"0\",\"2\"],[\"64457\",\"527.72\",\"0\",\"4\"],[\"64456.9\",\"0.02\",\"0\",\"1\"],[\"64456.6\",\"0.08\",\"0\",\"2\"],[\"64456.5\",\"0.81\",\"0\",\"2\"],[\"64456.4\",\"15.65\",\"0\",\"1\"],[\"64456.3\",\"37.24\",\"0\",\"2\"],[\"64456.2\",\"21.88\",\"0\",\"3\"],[\"64456.1\",\"249.79\",\"0\",\"3\"],[\"64456\",\"10.02\",\"0\",\"3\"],[\"64455.8\",\"15.66\",\"0\",\"2\"],[\"64455.7\",\"0.3\",\"0\",\"2\"],[\"64455.6\",\"37.69\",\"0\",\"2\"],[\"64455.5\",\"31.3\",\"0\",\"2\"],[\"64455.3\",\"56.54\",\"0\",\"2\"],[\"64455.2\",\"16.19\",\"0\",\"6\"],[\"64455\",\"285.9\",\"0\",\"2\"],[\"64454.9\",\"12.86\",\"0\",\"1\"],[\"64454.8\",\"10\",\"0\",\"1\"],[\"64454.7\",\"0.03\",\"0\",\"2\"],[\"64454.6\",\"31.31\",\"0\",\"3\"],[\"64454.5\",\"0.01\",\"0\",\"1\"],[\"64454.4\",\"62.16\",\"0\",\"2\"],[\"64454.3\",\"10\",\"0\",\"1\"],[\"64454.2\",\"38.83\",\"0\",\"1\"],[\"64454\",\"15.71\",\"0\",\"4\"],[\"64453.9\",\"38.83\",\"0\",\"1\"],[\"64453.8\",\"0.2\",\"0\",\"1\"],[\"64453.6\",\"0.04\",\"0\",\"2\"],[\"64453.4\",\"15.67\",\"0\",\"3\"],[\"64453.3\",\"0.12\",\"0\",\"12\"],[\"64453.1\",\"0.5\",\"0\",\"1\"],[\"64452.9\",\"16.71\",\"0\",\"2\"],[\"64452.8\",\"29.87\",\"0\",\"3\"],[\"64452.7\",\"307.08\",\"0\",\"2\"],[\"64452.6\",\"512.18\",\"0\",\"2\"],[\"64452.5\",\"31.32\",\"0\",\"4\"],[\"64452.3\",\"0.15\",\"0\",\"1\"],[\"64452.2\",\"15.65\",\"0\",\"1\"],[\"64452.1\",\"10.02\",\"0\",\"3\"],[\"64452\",\"10.16\",\"0\",\"5\"],[\"64451.8\",\"46.54\",\"0\",\"1\"],[\"64451.7\",\"201.97\",\"0\",\"3\"],[\"64451.6\",\"25.68\",\"0\",\"5\"],[\"64451.5\",\"61.97\",\"0\",\"2\"],[\"64451.3\",\"15.65\",\"0\",\"1\"],[\"64451.2\",\"0.01\",\"0\",\"1\"],[\"64451.1\",\"21.6\",\"0\",\"2\"],[\"64451\",\"0.02\",\"0\",\"2\"],[\"64450.8\",\"15.65\",\"0\",\"1\"],[\"64450.7\",\"0.04\",\"0\",\"2\"],[\"64450.6\",\"155.91\",\"0\",\"1\"],[\"64450.5\",\"0.01\",\"0\",\"1\"],[\"64450.4\",\"15.43\",\"0\",\"1\"],[\"64450.3\",\"0.03\",\"0\",\"2\"],[\"64450.1\",\"0.18\",\"0\",\"2\"],[\"64450\",\"22.84\",\"0\",\"20\"],[\"64449.9\",\"273.58\",\"0\",\"3\"],[\"64449.8\",\"83.77\",\"0\",\"2\"],[\"64449.7\",\"0.04\",\"0\",\"1\"],[\"64449.6\",\"15.65\",\"0\",\"1\"],[\"64449.5\",\"0.01\",\"0\",\"1\"],[\"64449.4\",\"0.01\",\"0\",\"1\"],[\"64449.3\",\"6.22\",\"0\",\"1\"],[\"64449.2\",\"15.65\",\"0\",\"1\"],[\"64449\",\"0.02\",\"0\",\"2\"],[\"64448.9\",\"0.52\",\"0\",\"2\"],[\"64448.8\",\"0.07\",\"0\",\"1\"],[\"64448.5\",\"512.19\",\"0\",\"3\"],[\"64448.4\",\"5.06\",\"0\",\"3\"],[\"64448.3\",\"10.03\",\"0\",\"3\"],[\"64448\",\"264.99\",\"0\",\"7\"],[\"64447.8\",\"46.55\",\"0\",\"2\"],[\"64447.7\",\"16.53\",\"0\",\"2\"],[\"64447.6\",\"0.01\",\"0\",\"1\"],[\"64447.5\",\"0.01\",\"0\",\"1\"],[\"64447.1\",\"0.01\",\"0\",\"1\"],[\"64447\",\"15.65\",\"0\",\"1\"],[\"64446.9\",\"55.78\",\"0\",\"1\"],[\"64446.8\",\"38.84\",\"0\",\"1\"],[\"64446.7\",\"208.61\",\"0\",\"4\"],[\"64446.6\",\"11.95\",\"0\",\"2\"],[\"64446.5\",\"0.02\",\"0\",\"2\"],[\"64446.3\",\"15.65\",\"0\",\"1\"],[\"64446.2\",\"42.38\",\"0\",\"2\"],[\"64446\",\"35.77\",\"0\",\"6\"],[\"64445.8\",\"0.01\",\"0\",\"1\"],[\"64445.7\",\"0.02\",\"0\",\"2\"],[\"64445.4\",\"15.65\",\"0\",\"1\"],[\"64445.3\",\"10.03\",\"0\",\"4\"],[\"64445\",\"0.01\",\"0\",\"1\"],[\"64444.8\",\"10.32\",\"0\",\"3\"],[\"64444.7\",\"342.07\",\"0\",\"3\"],[\"64444.6\",\"496.53\",\"0\",\"1\"],[\"64444.5\",\"156.71\",\"0\",\"3\"],[\"64444.4\",\"37.24\",\"0\",\"2\"],[\"64444.3\",\"0.01\",\"0\",\"1\"],[\"64444.2\",\"10.01\",\"0\",\"2\"],[\"64444.1\",\"159.26\",\"0\",\"5\"],[\"64444\",\"15.67\",\"0\",\"3\"],[\"64443.9\",\"1.83\",\"0\",\"2\"],[\"64443.8\",\"0.01\",\"0\",\"1\"],[\"64443.7\",\"10\",\"0\",\"1\"],[\"64443.3\",\"0.02\",\"0\",\"2\"],[\"64443.2\",\"10.01\",\"0\",\"2\"],[\"64443\",\"15.66\",\"0\",\"2\"],[\"64442.8\",\"0.01\",\"0\",\"1\"],[\"64442.7\",\"0.01\",\"0\",\"1\"],[\"64442.6\",\"15.65\",\"0\",\"1\"],[\"64442.5\",\"10\",\"0\",\"1\"],[\"64442.1\",\"62.19\",\"0\",\"2\"],[\"64442\",\"15.02\",\"0\",\"3\"],[\"64441.9\",\"0.02\",\"0\",\"1\"],[\"64441.6\",\"35.81\",\"0\",\"4\"],[\"64441.4\",\"15.66\",\"0\",\"2\"],[\"64441.1\",\"1.57\",\"0\",\"1\"],[\"64440.4\",\"6.23\",\"0\",\"2\"],[\"64440.3\",\"11.02\",\"0\",\"3\"],[\"64440.2\",\"354.51\",\"0\",\"2\"],[\"64440.1\",\"496.53\",\"0\",\"1\"],[\"64440\",\"23.49\",\"0\",\"19\"],[\"64439.9\",\"46.54\",\"0\",\"1\"],[\"64439.8\",\"92.79\",\"0\",\"1\"],[\"64439.7\",\"15.65\",\"0\",\"1\"],[\"64439.4\",\"93.87\",\"0\",\"2\"],[\"64439.1\",\"97.71\",\"0\",\"2\"],[\"64438.9\",\"19.61\",\"0\",\"2\"],[\"64438.8\",\"4.13\",\"0\",\"1\"],[\"64438.5\",\"0.01\",\"0\",\"1\"],[\"64438.4\",\"0.01\",\"0\",\"1\"],[\"64438.2\",\"304.51\",\"0\",\"2\"],[\"64438.1\",\"42.72\",\"0\",\"5\"],[\"64438\",\"18.87\",\"0\",\"1\"],[\"64437.9\",\"14.15\",\"0\",\"1\"],[\"64437.8\",\"1411.73\",\"0\",\"3\"],[\"64437.6\",\"0.01\",\"0\",\"1\"],[\"64437.2\",\"15.46\",\"0\",\"2\"],[\"64437.1\",\"0.29\",\"0\",\"1\"],[\"64436.9\",\"0.01\",\"0\",\"1\"],[\"64436.8\",\"0.79\",\"0\",\"1\"],[\"64436.7\",\"0.54\",\"0\",\"2\"],[\"64436.6\",\"0.01\",\"0\",\"1\"],[\"64436.5\",\"11.29\",\"0\",\"1\"],[\"64436.4\",\"17.99\",\"0\",\"2\"],[\"64436.1\",\"10\",\"0\",\"1\"],[\"64435.9\",\"496.53\",\"0\",\"1\"],[\"64435.8\",\"247.26\",\"0\",\"4\"],[\"64435.7\",\"2\",\"0\",\"1\"],[\"64435.6\",\"4.64\",\"0\",\"1\"],[\"64435.5\",\"0.02\",\"0\",\"1\"],[\"64435.2\",\"0.02\",\"0\",\"2\"],[\"64435.1\",\"3.01\",\"0\",\"2\"],[\"64435\",\"164.23\",\"0\",\"4\"],[\"64434.9\",\"0.05\",\"0\",\"1\"],[\"64434.8\",\"15.65\",\"0\",\"1\"],[\"64434.7\",\"56.54\",\"0\",\"2\"],[\"64434.6\",\"1.16\",\"0\",\"1\"],[\"64434.4\",\"20\",\"0\",\"1\"],[\"64434.3\",\"0.02\",\"0\",\"2\"],[\"64434.2\",\"0.01\",\"0\",\"1\"],[\"64434.1\",\"0.35\",\"0\",\"2\"],[\"64433.9\",\"37.23\",\"0\",\"1\"],[\"64433.8\",\"6.22\",\"0\",\"1\"],[\"64433.6\",\"0.77\",\"0\",\"1\"],[\"64433.4\",\"0.01\",\"0\",\"1\"],[\"64433.3\",\"0.04\",\"0\",\"2\"],[\"64433.2\",\"11.29\",\"0\",\"1\"],[\"64433.1\",\"15.65\",\"0\",\"1\"],[\"64433\",\"1.73\",\"0\",\"1\"],[\"64432.8\",\"0.01\",\"0\",\"1\"],[\"64432.6\",\"0.06\",\"0\",\"3\"],[\"64432.5\",\"0.01\",\"0\",\"1\"],[\"64432.3\",\"0.02\",\"0\",\"2\"],[\"64432.2\",\"61.75\",\"0\",\"2\"],[\"64432.1\",\"298.07\",\"0\",\"2\"],[\"64432\",\"263.28\",\"0\",\"4\"],[\"64431.9\",\"517.26\",\"0\",\"2\"],[\"64431.6\",\"0.38\",\"0\",\"1\"],[\"64431.5\",\"15.65\",\"0\",\"1\"],[\"64431.4\",\"60.49\",\"0\",\"2\"],[\"64431.3\",\"92.79\",\"0\",\"1\"],[\"64431.1\",\"0.77\",\"0\",\"1\"],[\"64431\",\"4.06\",\"0\",\"17\"],[\"64430.8\",\"23.04\",\"0\",\"1\"],[\"64430.4\",\"93.91\",\"0\",\"2\"],[\"64430.3\",\"1.01\",\"0\",\"2\"],[\"64430.2\",\"15.73\",\"0\",\"2\"],[\"64430\",\"51.55\",\"0\",\"3\"],[\"64429.9\",\"12.37\",\"0\",\"4\"],[\"64429.8\",\"0.01\",\"0\",\"1\"],[\"64429.4\",\"0.02\",\"0\",\"1\"],[\"64429.2\",\"0.11\",\"0\",\"1\"],[\"64429.1\",\"0.02\",\"0\",\"1\"],[\"64428.9\",\"0.03\",\"0\",\"2\"],[\"64428.8\",\"0.01\",\"0\",\"1\"],[\"64428.6\",\"1.04\",\"0\",\"3\"],[\"64428.4\",\"37.23\",\"0\",\"1\"],[\"64428.2\",\"15.65\",\"0\",\"1\"],[\"64428.1\",\"0.65\",\"0\",\"2\"],[\"64428\",\"326.06\",\"0\",\"3\"],[\"64427.9\",\"18.87\",\"0\",\"1\"],[\"64427.8\",\"543.07\",\"0\",\"2\"],[\"64427.7\",\"0.01\",\"0\",\"1\"],[\"64427.3\",\"6.23\",\"0\",\"2\"],[\"64427.2\",\"0.01\",\"0\",\"1\"],[\"64427\",\"266.81\",\"0\",\"5\"],[\"64426.8\",\"0.06\",\"0\",\"1\"],[\"64426.7\",\"0.12\",\"0\",\"12\"],[\"64426.6\",\"0.01\",\"0\",\"1\"],[\"64426.5\",\"0.04\",\"0\",\"1\"],[\"64426.3\",\"1\",\"0\",\"1\"],[\"64426.1\",\"19.87\",\"0\",\"2\"],[\"64426\",\"3.27\",\"0\",\"2\"],[\"64425.7\",\"3.01\",\"0\",\"2\"],[\"64425.6\",\"3.91\",\"0\",\"2\"],[\"64425.5\",\"11.06\",\"0\",\"1\"],[\"64425.4\",\"0.07\",\"0\",\"1\"],[\"64425.3\",\"3\",\"0\",\"2\"],[\"64425\",\"3.07\",\"0\",\"8\"],[\"64424.9\",\"15.66\",\"0\",\"2\"],[\"64424.7\",\"1.2\",\"0\",\"1\"]],\"ts\":\"1782016053905\",\"checksum\":-1053747485,\"seqId\":325070100327,\"prevSeqId\":-1}]}"}
{"action": null, "capture_sequence": 455, "channel": "trades", "connection_sequence": 4, "event": null, "instId": "BTC-USDT-SWAP", "local_receive_ts": "2026-06-21T04:27:34Z", "monotonic_ns": 1643609940676395, "raw": "{\"arg\":{\"channel\":\"trades\",\"instId\":\"BTC-USDT-SWAP\"},\"data\":[{\"instId\":\"BTC-USDT-SWAP\",\"tradeId\":\"2718750413\",\"px\":\"64482.9\",\"sz\":\"0.46\",\"side\":\"sell\",\"ts\":\"1782016053980\",\"count\":\"1\",\"source\":\"0\",\"seqId\":325070100333}]}"}
{"action": "update", "capture_sequence": 456, "channel": "books", "connection_sequence": 4, "event": null, "instId": "BTC-USDT-SWAP", "local_receive_ts": "2026-06-21T04:27:34Z", "monotonic_ns": 1643609941188538, "raw": "{\"arg\":{\"channel\":\"books\",\"instId\":\"BTC-USDT-SWAP\"},\"action\":\"update\",\"data\":[{\"asks\":[[\"64483\",\"495.64\",\"0\",\"43\"],[\"64505.2\",\"49.44\",\"0\",\"2\"],[\"64505.8\",\"0.08\",\"0\",\"1\"],[\"64505.9\",\"0.01\",\"0\",\"1\"],[\"64506\",\"10.84\",\"0\",\"6\"],[\"64509.4\",\"58.18\",\"0\",\"1\"],[\"64509.8\",\"0.01\",\"0\",\"1\"],[\"64516.4\",\"16.74\",\"0\",\"9\"],[\"64516.7\",\"86.46\",\"0\",\"10\"],[\"64527.1\",\"0\",\"0\",\"0\"]],\"bids\":[[\"64482.9\",\"474.06\",\"0\",\"23\"],[\"64482.3\",\"0.01\",\"0\",\"1\"],[\"64482.2\",\"0.7\",\"0\",\"1\"],[\"64481.1\",\"0.03\",\"0\",\"2\"],[\"64478.2\",\"1.57\",\"0\",\"2\"],[\"64477.7\",\"1.58\",\"0\",\"3\"],[\"64477.3\",\"1.56\",\"0\",\"1\"],[\"64477\",\"77.55\",\"0\",\"2\"],[\"64476.8\",\"0\",\"0\",\"0\"],[\"64467.2\",\"70.67\",\"0\",\"2\"],[\"64466.3\",\"0\",\"0\",\"0\"],[\"64461.6\",\"0\",\"0\",\"0\"],[\"64461.5\",\"95.48\",\"0\",\"6\"],[\"64446.9\",\"109.06\",\"0\",\"2\"],[\"64424.6\",\"0.01\",\"0\",\"1\"],[\"64424.4\",\"47.74\",\"0\",\"2\"]],\"ts\":\"1782016054005\",\"checksum\":2029673189,\"seqId\":325070100369,\"prevSeqId\":325070100327}]}"}
{"action": "update", "capture_sequence": 457, "channel": "books", "connection_sequence": 4, "event": null, "instId": "BTC-USDT-SWAP", "local_receive_ts": "2026-06-21T04:27:34Z", "monotonic_ns": 1643610010803158, "raw": "{\"arg\":{\"channel\":\"books\",\"instId\":\"BTC-USDT-SWAP\"},\"action\":\"update\",\"data\":[{\"asks\":[[\"64498.4\",\"15.51\",\"0\",\"1\"],[\"64498.8\",\"496.55\",\"0\",\"3\"],[\"64505.2\",\"15.65\",\"0\",\"1\"],[\"64505.4\",\"93.02\",\"0\",\"5\"],[\"64509.4\",\"0\",\"0\",\"0\"],[\"64509.5\",\"0\",\"0\",\"0\"],[\"64509.7\",\"85.34\",\"0\",\"1\"],[\"64509.8\",\"58.19\",\"0\",\"2\"],[\"64515.4\",\"0.46\",\"0\",\"5\"],[\"64515.6\",\"21.36\",\"0\",\"6\"]],\"bids\":[[\"64478.3\",\"1.57\",\"0\",\"2\"],[\"64478.2\",\"0.01\",\"0\",\"1\"],[\"64477.1\",\"32.59\",\"0\",\"4\"],[\"64476.9\",\"4.02\",\"0\",\"3\"],[\"64476.8\",\"1.56\",\"0\",\"1\"],[\"64464.3\",\"85.4\",\"0\",\"1\"],[\"64463.9\",\"0\",\"0\",\"0\"],[\"64463.3\",\"46.54\",\"0\",\"1\"],[\"64463.2\",\"0.02\",\"0\",\"1\"],[\"64461.6\",\"58.23\",\"0\",\"1\"],[\"64461.5\",\"37.25\",\"0\",\"5\"],[\"64424.7\",\"0\",\"0\",\"0\"],[\"64424.6\",\"0\",\"0\",\"0\"],[\"64424.4\",\"0\",\"0\",\"0\"]],\"ts\":\"1782016054105\",\"checksum\":2029673189,\"seqId\":325070100470,\"prevSeqId\":325070100369}]}"}
{"action": null, "capture_sequence": 458, "channel": "trades", "connection_sequence": 4, "event": null, "instId": "BTC-USDT-SWAP", "local_receive_ts": "2026-06-21T04:27:34Z", "monotonic_ns": 1643610077259711, "raw": "{\"arg\":{\"channel\":\"trades\",\"instId\":\"BTC-USDT-SWAP\"},\"data\":[{\"instId\":\"BTC-USDT-SWAP\",\"tradeId\":\"2718750416\",\"px\":\"64483\",\"sz\":\"30.84\",\"side\":\"buy\",\"ts\":\"1782016054173\",\"count\":\"3\",\"source\":\"0\",\"seqId\":325070100503}]}"}
{"action": null, "capture_sequence": 459, "channel": "trades", "connection_sequence": 4, "event": null, "instId": "BTC-USDT-SWAP", "local_receive_ts": "2026-06-21T04:27:34Z", "monotonic_ns": 1643610087770096, "raw": "{\"arg\":{\"channel\":\"trades\",\"instId\":\"BTC-USDT-SWAP\"},\"data\":[{\"instId\":\"BTC-USDT-SWAP\",\"tradeId\":\"2718750417\",\"px\":\"64482.9\",\"sz\":\"0.1\",\"side\":\"sell\",\"ts\":\"1782016054183\",\"count\":\"1\",\"source\":\"0\",\"seqId\":325070100528}]}"}
{"action": "update", "capture_sequence": 460, "channel": "books", "connection_sequence": 4, "event": null, "instId": "BTC-USDT-SWAP", "local_receive_ts": "2026-06-21T04:27:34Z", "monotonic_ns": 1643610109661024, "raw": "{\"arg\":{\"channel\":\"books\",\"instId\":\"BTC-USDT-SWAP\"},\"action\":\"update\",\"data\":[{\"asks\":[[\"64483\",\"483.06\",\"0\",\"44\"],[\"64489.1\",\"1.6\",\"0\",\"4\"],[\"64498.7\",\"1.86\",\"0\",\"3\"],[\"64503.1\",\"39.69\",\"0\",\"8\"],[\"64503.2\",\"13.85\",\"0\",\"5\"]],\"bids\":[[\"64482.9\",\"473.96\",\"0\",\"23\"],[\"64480.6\",\"1.56\",\"0\",\"1\"],[\"64478.7\",\"1.56\",\"0\",\"1\"],[\"64478.3\",\"0.01\",\"0\",\"1\"],[\"64477.7\",\"0.02\",\"0\",\"2\"],[\"64477.3\",\"0\",\"0\",\"0\"],[\"64477.1\",\"34.15\",\"0\",\"5\"],[\"64476.8\",\"0\",\"0\",\"0\"],[\"64476.3\",\"64.1\",\"0\",\"4\"],[\"64474.2\",\"48.1\",\"0\",\"2\"],[\"64463.1\",\"37.23\",\"0\",\"1\"]],\"ts\":\"1782016054205\",\"checksum\":-1999817605,\"seqId\":325070100555,\"prevSeqId\":325070100470}]}"}
{"action": null, "capture_sequence": 461, "channel": "trades", "connection_sequence": 4, "event": null, "instId": "BTC-USDT-SWAP", "local_receive_ts": "2026-06-21T04:27:34Z", "monotonic_ns": 1643610159749561, "raw": "{\"arg\":{\"channel\":\"trades\",\"instId\":\"BTC-USDT-SWAP\"},\"data\":[{\"instId\":\"BTC-USDT-SWAP\",\"tradeId\":\"2718750418\",\"px\":\"64482.9\",\"sz\":\"0.06\",\"side\":\"sell\",\"ts\":\"1782016054256\",\"count\":\"1\",\"source\":\"0\",\"seqId\":325070100605}]}"}
{"action": "update", "capture_sequence": 462, "channel": "books", "connection_sequence": 4, "event": null, "instId": "BTC-USDT-SWAP", "local_receive_ts": "2026-06-21T04:27:34Z", "monotonic_ns": 1643610210300081, "raw": "{\"arg\":{\"channel\":\"books\",\"instId\":\"BTC-USDT-SWAP\"},\"action\":\"update\",\"data\":[{\"asks\":[[\"64483\",\"443.17\",\"0\",\"41\"],[\"64498.4\",\"0\",\"0\",\"0\"],[\"64498.7\",\"17.53\",\"0\",\"5\"],[\"64500.6\",\"62.54\",\"0\",\"4\"],[\"64501.4\",\"31.04\",\"0\",\"2\"],[\"64501.7\",\"0.55\",\"0\",\"4\"],[\"64502.1\",\"232.78\",\"0\",\"2\"],[\"64502.7\",\"0.03\",\"0\",\"3\"],[\"64502.9\",\"280.73\",\"0\",\"8\"],[\"64503.2\",\"12.3\",\"0\",\"4\"],[\"64503.6\",\"1.57\",\"0\",\"3\"],[\"64504.9\",\"0.1\",\"0\",\"3\"],[\"64505.1\",\"0.33\",\"0\",\"3\"],[\"64506\",\"10.07\",\"0\",\"5\"],[\"64506.2\",\"0.8\",\"0\",\"3\"],[\"64515.6\",\"1.29\",\"0\",\"5\"],[\"64515.7\",\"81.92\",\"0\",\"5\"],[\"64516.7\",\"0.36\",\"0\",\"9\"],[\"64517.8\",\"86.2\",\"0\",\"4\"],[\"64527.1\",\"0.46\",\"0\",\"1\"]],\"bids\":[[\"64482.9\",\"462.45\",\"0\",\"22\"],[\"64480.6\",\"0\",\"0\",\"0\"],[\"64478.7\",\"0\",\"0\",\"0\"],[\"64478.2\",\"1.57\",\"0\",\"2\"],[\"64477.7\",\"1.58\",\"0\",\"3\"],[\"64477.5\",\"90.41\",\"0\",\"4\"],[\"64477.4\",\"1.55\",\"0\",\"3\"],[\"64477.1\",\"1.57\",\"0\",\"2\"],[\"64477\",\"0.01\",\"0\",\"1\"],[\"64476.8\",\"31.04\",\"0\",\"1\"],[\"64473.6\",\"0\",\"0\",\"0\"],[\"64473.2\",\"11.41\",\"0\",\"2\"],[\"64467.3\",\"96.3\",\"0\",\"3\"],[\"64467.2\",\"69.9\",\"0\",\"1\"],[\"64463.9\",\"31.05\",\"0\",\"1\"],[\"64463.7\",\"0\",\"0\",\"0\"],[\"64463.1\",\"40.45\",\"0\",\"2\"],[\"64462.9\",\"232.91\",\"0\",\"1\"],[\"64462.2\",\"0\",\"0\",\"0\"],[\"64424.7\",\"1.2\",\"0\",\"1\"],[\"64424.6\",\"0.01\",\"0\",\"1\"]],\"ts\":\"1782016054305\",\"checksum\":-186306450,\"seqId\":325070100675,\"prevSeqId\":325070100555}]}"}
{"action": "update", "capture_sequence": 463, "channel": "books", "connection_sequence": 4, "event": null, "instId": "BTC-USDT-SWAP", "local_receive_ts": "2026-06-21T04:27:34Z", "monotonic_ns": 1643610310231329, "raw": "{\"arg\":{\"channel\":\"books\",\"instId\":\"BTC-USDT-SWAP\"},\"action\":\"update\",\"data\":[{\"asks\":[[\"64490.9\",\"0.07\",\"0\",\"2\"],[\"64493.1\",\"0.46\",\"0\",\"3\"],[\"64498.7\",\"2.02\",\"0\",\"4\"],[\"64498.9\",\"18.93\",\"0\",\"3\"],[\"64517.8\",\"0.1\",\"0\",\"3\"],[\"64517.9\",\"86.25\",\"0\",\"4\"]],\"bids\":[[\"64482.9\",\"473.91\",\"0\",\"23\"],[\"64480.3\",\"1.56\",\"0\",\"1\"],[\"64479.8\",\"1.57\",\"0\",\"2\"],[\"64478.8\",\"1.56\",\"0\",\"1\"],[\"64477.5\",\"12.87\",\"0\",\"3\"],[\"64477.4\",\"0.01\",\"0\",\"1\"],[\"64477.3\",\"77.54\",\"0\",\"1\"],[\"64476.9\",\"5.56\",\"0\",\"5\"],[\"64474.7\",\"0.01\",\"0\",\"1\"],[\"64474.2\",\"46.54\",\"0\",\"1\"],[\"64464.4\",\"31.06\",\"0\",\"2\"],[\"64463.9\",\"0\",\"0\",\"0\"],[\"64424.7\",\"0\",\"0\",\"0\"],[\"64424.6\",\"0\",\"0\",\"0\"]],\"ts\":\"1782016054405\",\"checksum\":-1640852923,\"seqId\":325070100830,\"prevSeqId\":325070100675}]}"}
{"action": null, "capture_sequence": 464, "channel": "trades", "connection_sequence": 4, "event": null, "instId": "BTC-USDT-SWAP", "local_receive_ts": "2026-06-21T04:27:34Z", "monotonic_ns": 1643610373626629, "raw": "{\"arg\":{\"channel\":\"trades\",\"instId\":\"BTC-USDT-SWAP\"},\"data\":[{\"instId\":\"BTC-USDT-SWAP\",\"tradeId\":\"2718750419\",\"px\":\"64483\",\"sz\":\"0.02\",\"side\":\"buy\",\"ts\":\"1782016054469\",\"count\":\"1\",\"source\":\"0\",\"seqId\":325070100885}]}"}
{"action": "update", "capture_sequence": 465, "channel": "books", "connection_sequence": 4, "event": null, "instId": "BTC-USDT-SWAP", "local_receive_ts": "2026-06-21T04:27:34Z", "monotonic_ns": 1643610410281696, "raw": "{\"arg\":{\"channel\":\"books\",\"instId\":\"BTC-USDT-SWAP\"},\"action\":\"update\",\"data\":[{\"asks\":[[\"64483\",\"451.59\",\"0\",\"41\"],[\"64503.6\",\"0.02\",\"0\",\"2\"],[\"64503.8\",\"1.55\",\"0\",\"1\"],[\"64509.4\",\"58.18\",\"0\",\"1\"],[\"64509.5\",\"85.34\",\"0\",\"1\"],[\"64509.7\",\"0\",\"0\",\"0\"],[\"64509.8\",\"0.01\",\"0\",\"1\"],[\"64527\",\"0\",\"0\",\"0\"],[\"64527.1\",\"0\",\"0\",\"0\"]],\"bids\":[[\"64480.3\",\"0\",\"0\",\"0\"],[\"64477.4\",\"77.55\",\"0\",\"2\"],[\"64477.3\",\"0\",\"0\",\"0\"],[\"64464.3\",\"0\",\"0\",\"0\"],[\"64463.9\",\"85.4\",\"0\",\"1\"],[\"64463.4\",\"232.91\",\"0\",\"1\"],[\"64462.9\",\"0\",\"0\",\"0\"],[\"64461.6\",\"0\",\"0\",\"0\"],[\"64461.2\",\"58.29\",\"0\",\"4\"],[\"64424.7\",\"1.2\",\"0\",\"1\"],[\"64424.6\",\"0.01\",\"0\",\"1\"],[\"64424.4\",\"280.36\",\"0\",\"3\"]],\"ts\":\"1782016054505\",\"checksum\":790370173,\"seqId\":325070100927,\"prevSeqId\":325070100830}]}"}
{"action": "update", "capture_sequence": 466, "channel": "books", "connection_sequence": 4, "event": null, "instId": "BTC-USDT-SWAP", "local_receive_ts": "2026-06-21T04:27:34Z", "monotonic_ns": 1643610509621182, "raw": "{\"arg\":{\"channel\":\"books\",\"instId\":\"BTC-USDT-SWAP\"},\"action\":\"update\",\"data\":[{\"asks\":[[\"64483\",\"426.45\",\"0\",\"38\"],[\"64493.1\",\"0.45\",\"0\",\"2\"],[\"64493.4\",\"21.51\",\"0\",\"10\"],[\"64498.7\",\"1.86\",\"0\",\"3\"],[\"64502.9\",\"280.72\",\"0\",\"7\"],[\"64503\",\"15.96\",\"0\",\"4\"],[\"64516.4\",\"102.84\",\"0\",\"10\"],[\"64517.9\",\"0.15\",\"0\",\"3\"]],\"bids\":[],\"ts\":\"1782016054605\",\"checksum\":-1151979989,\"seqId\":325070101017,\"prevSeqId\":325070100927}]}"}
{"action": "update", "capture_sequence": 467, "channel": "books", "connection_sequence": 4, "event": null, "instId": "BTC-USDT-SWAP", "local_receive_ts": "2026-06-21T04:27:34Z", "monotonic_ns": 1643610610382206, "raw": "{\"arg\":{\"channel\":\"books\",\"instId\":\"BTC-USDT-SWAP\"},\"action\":\"update\",\"data\":[{\"asks\":[[\"64483\",\"588.34\",\"0\",\"54\"],[\"64493.2\",\"504.6\",\"0\",\"6\"],[\"64498.7\",\"2.01\",\"0\",\"4\"]],\"bids\":[[\"64482.9\",\"319.26\",\"0\",\"19\"],[\"64482.8\",\"6.65\",\"0\",\"12\"],[\"64481\",\"2.45\",\"0\",\"1\"],[\"64480.8\",\"0.01\",\"0\",\"1\"],[\"64478.6\",\"0\",\"0\",\"0\"],[\"64476.7\",\"4.78\",\"0\",\"2\"],[\"64476.3\",\"17.56\",\"0\",\"3\"],[\"64475.8\",\"0.01\",\"0\",\"1\"],[\"64475.1\",\"138.3\",\"0\",\"4\"],[\"64474.2\",\"0\",\"0\",\"0\"],[\"64474.1\",\"0.01\",\"0\",\"1\"],[\"64471.4\",\"2.77\",\"0\",\"2\"],[\"64470\",\"0.46\",\"0\",\"3\"],[\"64469.4\",\"0\",\"0\",\"0\"],[\"64469.3\",\"0\",\"0\",\"0\"],[\"64467.4\",\"86.17\",\"0\",\"1\"],[\"64465.4\",\"11.34\",\"0\",\"2\"],[\"64465.3\",\"0.04\",\"0\",\"3\"],[\"64463.3\",\"0\",\"0\",\"0\"],[\"64463.1\",\"3.17\",\"0\",\"1\"],[\"64461.3\",\"0.04\",\"0\",\"1\"],[\"64461.1\",\"0.02\",\"0\",\"1\"],[\"64459.1\",\"0\",\"0\",\"0\"],[\"64424.2\",\"1.21\",\"0\",\"2\"],[\"64424\",\"1.36\",\"0\",\"4\"],[\"64423.9\",\"1.25\",\"0\",\"2\"],[\"64423.8\",\"60.49\",\"0\",\"2\"],[\"64423.5\",\"381.6\",\"0\",\"2\"],[\"64423.3\",\"512.29\",\"0\",\"3\"]],\"ts\":\"1782016054705\",\"checksum\":881804472,\"seqId\":325070101150,\"prevSeqId\":325070101017}]}"}
{"action": null, "capture_sequence": 468, "channel": "trades", "connection_sequence": 4, "event": null, "instId": "BTC-USDT-SWAP", "local_receive_ts": "2026-06-21T04:27:34Z", "monotonic_ns": 1643610651849656, "raw": "{\"arg\":{\"channel\":\"trades\",\"instId\":\"BTC-USDT-SWAP\"},\"data\":[{\"instId\":\"BTC-USDT-SWAP\",\"tradeId\":\"2718750420\",\"px\":\"64482.9\",\"sz\":\"2.27\",\"side\":\"sell\",\"ts\":\"1782016054748\",\"count\":\"1\",\"source\":\"0\",\"seqId\":325070101613}]}"}
{"action": "update", "capture_sequence": 469, "channel": "books", "connection_sequence": 4, "event": null, "instId": "BTC-USDT-SWAP", "local_receive_ts": "2026-06-21T04:27:34Z", "monotonic_ns": 1643610733947345, "raw": "{\"arg\":{\"channel\":\"books\",\"instId\":\"BTC-USDT-SWAP\"},\"action\":\"update\",\"data\":[{\"asks\":[[\"64483\",\"671.71\",\"0\",\"52\"],[\"64483.2\",\"0\",\"0\",\"0\"],[\"64483.6\",\"30.14\",\"0\",\"1\"],[\"64484.5\",\"0.07\",\"0\",\"4\"],[\"64485.2\",\"1.58\",\"0\",\"3\"],[\"64486.3\",\"2.53\",\"0\",\"3\"],[\"64488.2\",\"3.96\",\"0\",\"2\"],[\"64489\",\"34.98\",\"0\",\"9\"],[\"64489.3\",\"3.26\",\"0\",\"5\"],[\"64490.6\",\"17\",\"0\",\"4\"],[\"64492.2\",\"16.87\",\"0\",\"8\"],[\"64492.8\",\"12.43\",\"0\",\"10\"],[\"64492.9\",\"20.15\",\"0\",\"3\"],[\"64493\",\"26.1\",\"0\",\"7\"],[\"64493.1\",\"364.57\",\"0\",\"3\"],[\"64493.3\",\"0.03\",\"0\",\"3\"],[\"64493.4\",\"4.25\",\"0\",\"6\"],[\"64493.5\",\"1.09\",\"0\",\"4\"],[\"64493.8\",\"3.13\",\"0\",\"3\"],[\"64494.6\",\"9.05\",\"0\",\"6\"],[\"64495.3\",\"0.26\",\"0\",\"2\"],[\"64496\",\"11.32\",\"0\",\"6\"],[\"64496.2\",\"0\",\"0\",\"0\"],[\"64496.6\",\"31.68\",\"0\",\"2\"],[\"64497.9\",\"15.52\",\"0\",\"2\"],[\"64498.9\",\"3.44\",\"0\",\"4\"],[\"64499.3\",\"31.03\",\"0\",\"1\"],[\"64500\",\"3463.88\",\"0\",\"1037\"],[\"64500.1\",\"0.06\",\"0\",\"5\"],[\"64500.2\",\"232.8\",\"0\",\"3\"],[\"64500.3\",\"2.77\",\"0\",\"4\"],[\"64501.4\",\"0.01\",\"0\",\"1\"],[\"64501.8\",\"60.56\",\"0\",\"7\"],[\"64502.1\",\"0.01\",\"0\",\"1\"],[\"64503\",\"15.95\",\"0\",\"3\"],[\"64503.2\",\"0.3\",\"0\",\"2\"],[\"64503.8\",\"0\",\"0\",\"0\"],[\"64504.4\",\"1.44\",\"0\",\"5\"],[\"64504.7\",\"33.8\",\"0\",\"2\"],[\"64505.1\",\"0.79\",\"0\",\"3\"],[\"64505.4\",\"59.23\",\"0\",\"4\"],[\"64506\",\"149.35\",\"0\",\"6\"],[\"64506.2\",\"0.03\",\"0\",\"2\"],[\"64506.8\",\"1.05\",\"0\",\"4\"],[\"64508.6\",\"58.19\",\"0\",\"2\"],[\"64508.9\",\"246.3\",\"0\",\"6\"],[\"64509.4\",\"0\",\"0\",\"0\"],[\"64509.5\",\"0\",\"0\",\"0\"],[\"64514.8\",\"166.97\",\"0\",\"8\"],[\"64515.2\",\"23.66\",\"0\",\"3\"],[\"64515.7\",\"61.85\",\"0\",\"4\"],[\"64516.4\",\"16.74\",\"0\",\"9\"],[\"64516.5\",\"49.1\",\"0\",\"2\"],[\"64519\",\"0.67\",\"0\",\"4\"],[\"64519.9\",\"496.57\",\"0\",\"3\"],[\"64522.8\",\"15.71\",\"0\",\"4\"],[\"64523.2\",\"3.11\",\"0\",\"3\"],[\"64527\",\"0.17\",\"0\",\"3\"],[\"64527.1\",\"0.46\",\"0\",\"1\"],[\"64527.2\",\"0.18\",\"0\",\"4\"],[\"64527.3\",\"0.05\",\"0\",\"5\"]],\"bids\":[[\"64482.9\",\"448.55\",\"0\",\"20\"],[\"64482.8\",\"3.95\",\"0\",\"11\"],[\"64482.3\",\"0\",\"0\",\"0\"],[\"64482.2\",\"0\",\"0\",\"0\"],[\"64482\",\"107.75\",\"0\",\"2\"],[\"64481.9\",\"0\",\"0\",\"0\"],[\"64481.3\",\"0\",\"0\",\"0\"],[\"64481.2\",\"0\",\"0\",\"0\"],[\"64481.1\",\"0\",\"0\",\"0\"],[\"64481\",\"0\",\"0\",\"0\"],[\"64480.5\",\"0\",\"0\",\"0\"],[\"64480.1\",\"0\",\"0\",\"0\"],[\"64480\",\"0.02\",\"0\",\"2\"],[\"64479.8\",\"0.01\",\"0\",\"1\"],[\"64479.7\",\"0.01\",\"0\",\"1\"],[\"64479.6\",\"0.72\",\"0\",\"3\"],[\"64479.4\",\"0.01\",\"0\",\"1\"],[\"64479.3\",\"0.7\",\"0\",\"1\"],[\"64479.2\",\"0.03\",\"0\",\"2\"],[\"64479.1\",\"2.2\",\"0\",\"1\"],[\"64479\",\"0.01\",\"0\",\"1\"],[\"64478.9\",\"0\",\"0\",\"0\"],[\"64478.8\",\"0\",\"0\",\"0\"],[\"64478.4\",\"2.2\",\"0\",\"1\"],[\"64478.2\",\"0\",\"0\",\"0\"],[\"64478.1\",\"0\",\"0\",\"0\"],[\"64478\",\"0\",\"0\",\"0\"],[\"64477.7\",\"0.03\",\"0\",\"3\"],[\"64477.6\",\"5.02\",\"0\",\"3\"],[\"64477.5\",\"12.71\",\"0\",\"2\"],[\"64477.4\",\"0.01\",\"0\",\"1\"],[\"64477.2\",\"0\",\"0\",\"0\"],[\"64477.1\",\"0.01\",\"0\",\"1\"],[\"64476.9\",\"4.02\",\"0\",\"3\"],[\"64476.8\",\"0\",\"0\",\"0\"],[\"64476.7\",\"108.15\",\"0\",\"2\"],[\"64476.6\",\"98.89\",\"0\",\"2\"],[\"64476.4\",\"0.01\",\"0\",\"1\"],[\"64476.3\",\"8\",\"0\",\"1\"],[\"64476.2\",\"0.02\",\"0\",\"2\"],[\"64476.1\",\"65.88\",\"0\",\"1\"],[\"64475.7\",\"0\",\"0\",\"0\"],[\"64475.4\",\"37.25\",\"0\",\"3\"],[\"64475.2\",\"0\",\"0\",\"0\"],[\"64475.1\",\"0\",\"0\",\"0\"],[\"64475\",\"0\",\"0\",\"0\"],[\"64474.8\",\"0.01\",\"0\",\"1\"],[\"64474.5\",\"0\",\"0\",\"0\"],[\"64474.4\",\"77.54\",\"0\",\"1\"],[\"64473.6\",\"46.54\",\"0\",\"1\"],[\"64473.5\",\"97.98\",\"0\",\"1\"],[\"64473.4\",\"0.3\",\"0\",\"1\"],[\"64473.3\",\"8.01\",\"0\",\"2\"],[\"64473\",\"12\",\"0\",\"2\"],[\"64472.9\",\"0\",\"0\",\"0\"],[\"64472.6\",\"0\",\"0\",\"0\"],[\"64472.3\",\"16.03\",\"0\",\"3\"],[\"64472.2\",\"0\",\"0\",\"0\"],[\"64471.9\",\"13.95\",\"0\",\"1\"],[\"64471.6\",\"0.34\",\"0\",\"2\"],[\"64471.5\",\"51.21\",\"0\",\"6\"],[\"64471.4\",\"0.01\",\"0\",\"1\"],[\"64471.2\",\"46.54\",\"0\",\"1\"],[\"64471.1\",\"0\",\"0\",\"0\"],[\"64470.9\",\"0.01\",\"0\",\"1\"],[\"64470.8\",\"46.6\",\"0\",\"1\"],[\"64470.7\",\"15.96\",\"0\",\"3\"],[\"64470.4\",\"36.59\",\"0\",\"4\"],[\"64470.3\",\"354.38\",\"0\",\"4\"],[\"64470.2\",\"533.76\",\"0\",\"2\"],[\"64470.1\",\"0.02\",\"0\",\"1\"],[\"64470\",\"16.46\",\"0\",\"4\"],[\"64469.2\",\"0\",\"0\",\"0\"],[\"64468.7\",\"175.93\",\"0\",\"8\"],[\"64468.3\",\"46.54\",\"0\",\"1\"],[\"64467.4\",\"0\",\"0\",\"0\"],[\"64467.3\",\"95.53\",\"0\",\"2\"],[\"64467.1\",\"31.07\",\"0\",\"1\"],[\"64467\",\"139.88\",\"0\",\"4\"],[\"64466.9\",\"0\",\"0\",\"0\"],[\"64466.8\",\"2.71\",\"0\",\"2\"],[\"64466.6\",\"31.07\",\"0\",\"2\"],[\"64466.2\",\"0.01\",\"0\",\"1\"],[\"64466.1\",\"0\",\"0\",\"0\"],[\"64465.7\",\"0.77\",\"0\",\"1\"],[\"64465.6\",\"108.56\",\"0\",\"6\"],[\"64465.5\",\"107.59\",\"0\",\"3\"],[\"64465.3\",\"0.02\",\"0\",\"2\"],[\"64464.8\",\"0.01\",\"0\",\"1\"],[\"64464.4\",\"20.09\",\"0\",\"2\"],[\"64464.3\",\"92.39\",\"0\",\"2\"],[\"64464.2\",\"155.57\",\"0\",\"5\"],[\"64463.9\",\"0\",\"0\",\"0\"],[\"64463.8\",\"342\",\"0\",\"2\"],[\"64463.4\",\"0\",\"0\",\"0\"],[\"64463.2\",\"85.4\",\"0\",\"1\"],[\"64463\",\"18.97\",\"0\",\"3\"],[\"64462.2\",\"31.05\",\"0\",\"1\"],[\"64462.1\",\"11.33\",\"0\",\"1\"],[\"64462\",\"0.01\",\"0\",\"1\"],[\"64461.9\",\"0.01\",\"0\",\"1\"],[\"64461.7\",\"46.55\",\"0\",\"2\"],[\"64461.6\",\"533.76\",\"0\",\"2\"],[\"64461.5\",\"0.02\",\"0\",\"2\"],[\"64461.4\",\"0.03\",\"0\",\"3\"],[\"64461.2\",\"0.04\",\"0\",\"2\"],[\"64461\",\"232.92\",\"0\",\"1\"],[\"64460.4\",\"58.27\",\"0\",\"3\"],[\"64460.3\",\"2.43\",\"0\",\"2\"],[\"64458.5\",\"46.54\",\"0\",\"1\"],[\"64457.5\",\"0.03\",\"0\",\"2\"],[\"64457.1\",\"364.02\",\"0\",\"2\"],[\"64456.8\",\"2.28\",\"0\",\"1\"],[\"64455.9\",\"3.1\",\"0\",\"1\"],[\"64455.2\",\"16.21\",\"0\",\"7\"],[\"64455\",\"239.36\",\"0\",\"1\"],[\"64452.3\",\"0\",\"0\",\"0\"],[\"64449.8\",\"83.79\",\"0\",\"3\"],[\"64449\",\"0.03\",\"0\",\"3\"],[\"64446.7\",\"208.6\",\"0\",\"3\"],[\"64440\",\"23.48\",\"0\",\"19\"],[\"64438\",\"18.88\",\"0\",\"2\"],[\"64435.8\",\"247.28\",\"0\",\"5\"],[\"64434.5\",\"0.13\",\"0\",\"1\"],[\"64430.3\",\"3.29\",\"0\",\"3\"],[\"64423.2\",\"37.23\",\"0\",\"1\"],[\"64423.1\",\"94.31\",\"0\",\"3\"],[\"64423\",\"1.59\",\"0\",\"6\"],[\"64422.8\",\"0.01\",\"0\",\"1\"],[\"64422.7\",\"3.4\",\"0\",\"3\"],[\"64422.6\",\"0.02\",\"0\",\"2\"],[\"64422.4\",\"0.02\",\"0\",\"2\"],[\"64422.3\",\"0.01\",\"0\",\"1\"],[\"64422.2\",\"11.44\",\"0\",\"3\"],[\"64422\",\"0.01\",\"0\",\"1\"]],\"ts\":\"1782016054805\",\"checksum\":385549301,\"seqId\":325070101814,\"prevSeqId\":325070101150}]}"}
{"action": null, "capture_sequence": 470, "channel": "trades", "connection_sequence": 4, "event": null, "instId": "BTC-USDT-SWAP", "local_receive_ts": "2026-06-21T04:27:34Z", "monotonic_ns": 1643610735388408, "raw": "{\"arg\":{\"channel\":\"trades\",\"instId\":\"BTC-USDT-SWAP\"},\"data\":[{\"instId\":\"BTC-USDT-SWAP\",\"tradeId\":\"2718750421\",\"px\":\"64482.9\",\"sz\":\"0.26\",\"side\":\"sell\",\"ts\":\"1782016054830\",\"count\":\"1\",\"source\":\"0\",\"seqId\":325070101854}]}"}
{"action": "update", "capture_sequence": 471, "channel": "books", "connection_sequence": 4, "event": null, "instId": "BTC-USDT-SWAP", "local_receive_ts": "2026-06-21T04:27:35Z", "monotonic_ns": 1643610816738710, "raw": "{\"arg\":{\"channel\":\"books\",\"instId\":\"BTC-USDT-SWAP\"},\"action\":\"update\",\"data\":[{\"asks\":[[\"64483.6\",\"58.76\",\"0\",\"2\"],[\"64485.9\",\"125.65\",\"0\",\"3\"],[\"64489.3\",\"3.25\",\"0\",\"4\"],[\"64490.7\",\"0.07\",\"0\",\"3\"],[\"64492.8\",\"12.44\",\"0\",\"11\"],[\"64498.9\",\"3.43\",\"0\",\"3\"],[\"64499.1\",\"3.42\",\"0\",\"7\"],[\"64504.4\",\"1.13\",\"0\",\"4\"],[\"64504.9\",\"0.41\",\"0\",\"4\"],[\"64514.8\",\"80.86\",\"0\",\"7\"],[\"64515.2\",\"15.66\",\"0\",\"2\"],[\"64515.9\",\"134.04\",\"0\",\"5\"],[\"64518.6\",\"8.11\",\"0\",\"9\"],[\"64519.9\",\"496.56\",\"0\",\"2\"],[\"64520\",\"78.63\",\"0\",\"64\"]],\"bids\":[[\"64482.9\",\"448.31\",\"0\",\"21\"],[\"64476.8\",\"83.92\",\"0\",\"1\"],[\"64476.7\",\"0.01\",\"0\",\"1\"],[\"64476.6\",\"0.01\",\"0\",\"1\"],[\"64475.6\",\"46.54\",\"0\",\"1\"],[\"64475.5\",\"77.54\",\"0\",\"1\"],[\"64474.4\",\"0\",\"0\",\"0\"],[\"64473.3\",\"0.01\",\"0\",\"1\"],[\"64472.4\",\"8\",\"0\",\"1\"],[\"64472.3\",\"16.15\",\"0\",\"4\"],[\"64472\",\"0.33\",\"0\",\"3\"],[\"64471.6\",\"0.03\",\"0\",\"1\"],[\"64470.2\",\"533.78\",\"0\",\"3\"],[\"64470.1\",\"0\",\"0\",\"0\"],[\"64469.4\",\"1.9\",\"0\",\"1\"],[\"64468.7\",\"216.28\",\"0\",\"10\"],[\"64468.4\",\"1.92\",\"0\",\"1\"],[\"64467.9\",\"2.77\",\"0\",\"2\"],[\"64467.3\",\"98.41\",\"0\",\"3\"],[\"64465.7\",\"86.94\",\"0\",\"2\"],[\"64465.5\",\"38.67\",\"0\",\"1\"],[\"64464.3\",\"6.22\",\"0\",\"1\"],[\"64461.5\",\"0.06\",\"0\",\"4\"],[\"64460.4\",\"58.23\",\"0\",\"1\"],[\"64459.4\",\"38.85\",\"0\",\"2\"],[\"64457.5\",\"0.01\",\"0\",\"1\"],[\"64457\",\"527.74\",\"0\",\"5\"],[\"64456.9\",\"0\",\"0\",\"0\"],[\"64456.1\",\"249.81\",\"0\",\"4\"],[\"64455.2\",\"16.19\",\"0\",\"6\"],[\"64450.5\",\"0.03\",\"0\",\"2\"],[\"64449.8\",\"83.77\",\"0\",\"2\"],[\"64437.7\",\"0.02\",\"0\",\"1\"],[\"64435.8\",\"247.26\",\"0\",\"4\"],[\"64431.6\",\"0\",\"0\",\"0\"],[\"64422.3\",\"0\",\"0\",\"0\"],[\"64422.2\",\"0\",\"0\",\"0\"],[\"64422\",\"0\",\"0\",\"0\"]],\"ts\":\"1782016054905\",\"checksum\":1604175832,\"seqId\":325070101882,\"prevSeqId\":325070101814}]}"}
{"action": "update", "capture_sequence": 472, "channel": "books", "connection_sequence": 4, "event": null, "instId": "BTC-USDT-SWAP", "local_receive_ts": "2026-06-21T04:27:35Z", "monotonic_ns": 1643610916498115, "raw": "{\"arg\":{\"channel\":\"books\",\"instId\":\"BTC-USDT-SWAP\"},\"action\":\"update\",\"data\":[{\"asks\":[[\"64483\",\"674.04\",\"0\",\"54\"],[\"64483.6\",\"30.14\",\"0\",\"1\"],[\"64485.9\",\"5.43\",\"0\",\"2\"],[\"64491\",\"4.78\",\"0\",\"2\"],[\"64504.3\",\"0.35\",\"0\",\"3\"],[\"64504.7\",\"0.01\",\"0\",\"1\"],[\"64504.9\",\"0.1\",\"0\",\"3\"],[\"64505.7\",\"34.35\",\"0\",\"2\"],[\"64506\",\"10.07\",\"0\",\"5\"],[\"64508.6\",\"0.01\",\"0\",\"1\"],[\"64508.9\",\"160.96\",\"0\",\"5\"],[\"64509.5\",\"58.18\",\"0\",\"1\"],[\"64509.9\",\"86.55\",\"0\",\"4\"],[\"64511.1\",\"167.61\",\"0\",\"7\"],[\"64514.8\",\"60.79\",\"0\",\"6\"],[\"64515.8\",\"37.06\",\"0\",\"4\"],[\"64515.9\",\"47.94\",\"0\",\"4\"],[\"64516.7\",\"86.46\",\"0\",\"10\"],[\"64527.3\",\"0\",\"0\",\"0\"]],\"bids\":[[\"64482.2\",\"0.02\",\"0\",\"1\"],[\"64482.1\",\"32.23\",\"0\",\"4\"],[\"64480\",\"0.03\",\"0\",\"3\"],[\"64479.2\",\"0.01\",\"0\",\"1\"],[\"64472.3\",\"20.92\",\"0\",\"5\"],[\"64472\",\"0.02\",\"0\",\"2\"],[\"64471.9\",\"82.58\",\"0\",\"3\"],[\"64471.6\",\"0.34\",\"0\",\"2\"],[\"64470\",\"18.06\",\"0\",\"5\"],[\"64469\",\"1.6\",\"0\",\"1\"],[\"64468.1\",\"2.16\",\"0\",\"1\"],[\"64467.6\",\"3.03\",\"0\",\"4\"],[\"64467.4\",\"86.17\",\"0\",\"1\"],[\"64466.7\",\"33.81\",\"0\",\"1\"],[\"64465.7\",\"149.69\",\"0\",\"2\"],[\"64465.6\",\"74.75\",\"0\",\"5\"],[\"64465.5\",\"0\",\"0\",\"0\"],[\"64464.8\",\"20.09\",\"0\",\"2\"],[\"64464.5\",\"85.42\",\"0\",\"3\"],[\"64464.4\",\"0.01\",\"0\",\"1\"],[\"64463.2\",\"0\",\"0\",\"0\"],[\"64461.1\",\"58.25\",\"0\",\"2\"],[\"64461\",\"432.92\",\"0\",\"2\"],[\"64460.4\",\"0\",\"0\",\"0\"],[\"64431.6\",\"0.38\",\"0\",\"1\"],[\"64422.7\",\"0\",\"0\",\"0\"],[\"64422.6\",\"0\",\"0\",\"0\"],[\"64422.4\",\"0\",\"0\",\"0\"]],\"ts\":\"1782016055005\",\"checksum\":-2088108224,\"seqId\":325070101943,\"prevSeqId\":325070101882}]}"}
{"action": "update", "capture_sequence": 473, "channel": "books", "connection_sequence": 4, "event": null, "instId": "BTC-USDT-SWAP", "local_receive_ts": "2026-06-21T04:27:35Z", "monotonic_ns": 1643611011157848, "raw": "{\"arg\":{\"channel\":\"books\",\"instId\":\"BTC-USDT-SWAP\"},\"action\":\"update\",\"data\":[{\"asks\":[[\"64483\",\"674.14\",\"0\",\"55\"],[\"64497.2\",\"16.35\",\"0\",\"4\"],[\"64497.9\",\"0.01\",\"0\",\"1\"],[\"64498.9\",\"3.42\",\"0\",\"2\"],[\"64499.1\",\"3.43\",\"0\",\"8\"],[\"64504.3\",\"0.04\",\"0\",\"2\"],[\"64504.9\",\"0.41\",\"0\",\"4\"],[\"64508.9\",\"246.3\",\"0\",\"6\"],[\"64509.9\",\"1.21\",\"0\",\"3\"]],\"bids\":[[\"64480.8\",\"0.71\",\"0\",\"2\"],[\"64479.3\",\"0\",\"0\",\"0\"],[\"64473.7\",\"32.59\",\"0\",\"3\"],[\"64473.6\",\"83.77\",\"0\",\"4\"],[\"64473.5\",\"281.12\",\"0\",\"2\"],[\"64472.2\",\"0.31\",\"0\",\"1\"],[\"64471.9\",\"152.13\",\"0\",\"6\"],[\"64471.8\",\"0.02\",\"0\",\"1\"],[\"64471.6\",\"0.03\",\"0\",\"1\"],[\"64471.5\",\"13.98\",\"0\",\"3\"],[\"64470.4\",\"421.41\",\"0\",\"2\"],[\"64470.3\",\"165.06\",\"0\",\"5\"],[\"64470.2\",\"533.76\",\"0\",\"2\"],[\"64468.7\",\"147.31\",\"0\",\"7\"],[\"64464.5\",\"0.02\",\"0\",\"2\"],[\"64463.7\",\"0.02\",\"0\",\"1\"],[\"64463.2\",\"85.4\",\"0\",\"1\"],[\"64463.1\",\"3.19\",\"0\",\"2\"],[\"64461.5\",\"0.02\",\"0\",\"2\"],[\"64460.9\",\"95.52\",\"0\",\"3\"],[\"64459.5\",\"15.67\",\"0\",\"2\"],[\"64459.4\",\"38.83\",\"0\",\"1\"],[\"64456.1\",\"249.79\",\"0\",\"3\"],[\"64452.6\",\"512.2\",\"0\",\"3\"],[\"64450.5\",\"0.01\",\"0\",\"1\"],[\"64423.2\",\"0\",\"0\",\"0\"],[\"64423.1\",\"0\",\"0\",\"0\"],[\"64423\",\"0\",\"0\",\"0\"],[\"64422.8\",\"0\",\"0\",\"0\"]],\"ts\":\"1782016055105\",\"checksum\":-938256026,\"seqId\":325070102009,\"prevSeqId\":325070101943}]}"}
{"action": "update", "capture_sequence": 474, "channel": "books", "connection_sequence": 4, "event": null, "instId": "BTC-USDT-SWAP", "local_receive_ts": "2026-06-21T04:27:35Z", "monotonic_ns": 1643611116985817, "raw": "{\"arg\":{\"channel\":\"books\",\"instId\":\"BTC-USDT-SWAP\"},\"action\":\"update\",\"data\":[{\"asks\":[[\"64483\",\"538.01\",\"0\",\"54\"],[\"64483.6\",\"63.51\",\"0\",\"2\"],[\"64485.2\",\"137.71\",\"0\",\"4\"],[\"64492.9\",\"19.38\",\"0\",\"2\"],[\"64493.1\",\"202.25\",\"0\",\"3\"],[\"64493.2\",\"8.07\",\"0\",\"5\"],[\"64493.9\",\"0\",\"0\",\"0\"],[\"64495.3\",\"1.03\",\"0\",\"3\"],[\"64495.4\",\"46.6\",\"0\",\"4\"],[\"64496.1\",\"0.06\",\"0\",\"3\"],[\"64497.2\",\"0.84\",\"0\",\"3\"],[\"64497.9\",\"15.52\",\"0\",\"2\"],[\"64499.3\",\"0\",\"0\",\"0\"],[\"64500.2\",\"31.05\",\"0\",\"3\"],[\"64501.7\",\"233.32\",\"0\",\"5\"],[\"64501.8\",\"59.01\",\"0\",\"6\"],[\"64502.4\",\"1.74\",\"0\",\"7\"],[\"64505\",\"200.82\",\"0\",\"4\"],[\"64527.3\",\"0.05\",\"0\",\"5\"],[\"64527.4\",\"0.27\",\"0\",\"2\"]],\"bids\":[[\"64482.9\",\"451.9\",\"0\",\"22\"],[\"64482.1\",\"32.44\",\"0\",\"4\"],[\"64480.9\",\"0.01\",\"0\",\"1\"],[\"64479.4\",\"0\",\"0\",\"0\"],[\"64478.6\",\"38.21\",\"0\",\"1\"],[\"64478\",\"1.56\",\"0\",\"1\"],[\"64477.7\",\"0.02\",\"0\",\"2\"],[\"64477.6\",\"0.02\",\"0\",\"2\"],[\"64477.4\",\"1.57\",\"0\",\"2\"],[\"64476.9\",\"4.18\",\"0\",\"4\"],[\"64476.7\",\"1.57\",\"0\",\"2\"],[\"64476.2\",\"79.12\",\"0\",\"4\"],[\"64475.7\",\"1.56\",\"0\",\"1\"],[\"64475.6\",\"47.31\",\"0\",\"2\"],[\"64475.5\",\"0\",\"0\",\"0\"],[\"64475.3\",\"1.56\",\"0\",\"1\"],[\"64474.8\",\"1.57\",\"0\",\"2\"],[\"64474.3\",\"4.66\",\"0\",\"2\"],[\"64473.8\",\"2.35\",\"0\",\"4\"],[\"64473.7\",\"31.82\",\"0\",\"2\"],[\"64473.6\",\"46.54\",\"0\",\"1\"],[\"64473.3\",\"1.57\",\"0\",\"2\"],[\"64468.7\",\"78.07\",\"0\",\"5\"],[\"64463.3\",\"31.05\",\"0\",\"1\"],[\"64462.3\",\"232.91\",\"0\",\"1\"],[\"64462.2\",\"0\",\"0\",\"0\"],[\"64461\",\"200\",\"0\",\"1\"],[\"64458.3\",\"0.53\",\"0\",\"4\"],[\"64457.9\",\"37.24\",\"0\",\"4\"],[\"64453.1\",\"0\",\"0\",\"0\"],[\"64423.8\",\"0\",\"0\",\"0\"],[\"64423.5\",\"0\",\"0\",\"0\"],[\"64423.3\",\"0\",\"0\",\"0\"]],\"ts\":\"1782016055205\",\"checksum\":837746448,\"seqId\":325070102093,\"prevSeqId\":325070102009}]}"}
{"action": null, "capture_sequence": 475, "channel": "trades", "connection_sequence": 4, "event": null, "instId": "BTC-USDT-SWAP", "local_receive_ts": "2026-06-21T04:27:35Z", "monotonic_ns": 1643611172449982, "raw": "{\"arg\":{\"channel\":\"trades\",\"instId\":\"BTC-USDT-SWAP\"},\"data\":[{\"instId\":\"BTC-USDT-SWAP\",\"tradeId\":\"2718750422\",\"px\":\"64482.9\",\"sz\":\"0.78\",\"side\":\"sell\",\"ts\":\"1782016055268\",\"count\":\"1\",\"source\":\"0\",\"seqId\":325070102173}]}"}
{"action": "update", "capture_sequence": 476, "channel": "books", "connection_sequence": 4, "event": null, "instId": "BTC-USDT-SWAP", "local_receive_ts": "2026-06-21T04:27:35Z", "monotonic_ns": 1643611218460686, "raw": "{\"arg\":{\"channel\":\"books\",\"instId\":\"BTC-USDT-SWAP\"},\"action\":\"update\",\"data\":[{\"asks\":[[\"64483\",\"261.17\",\"0\",\"40\"],[\"64485.2\",\"1.58\",\"0\",\"3\"],[\"64486.2\",\"0.17\",\"0\",\"6\"],[\"64489.7\",\"0.8\",\"0\",\"1\"],[\"64490.1\",\"0.31\",\"0\",\"3\"],[\"64490.7\",\"0.06\",\"0\",\"2\"],[\"64492.8\",\"0.44\",\"0\",\"9\"],[\"64493.8\",\"0.03\",\"0\",\"2\"],[\"64495.4\",\"4.06\",\"0\",\"4\"],[\"64495.9\",\"9.01\",\"0\",\"5\"],[\"64496\",\"5.1\",\"0\",\"5\"],[\"64497.9\",\"0.01\",\"0\",\"1\"],[\"64498.2\",\"15.55\",\"0\",\"4\"],[\"64499.1\",\"3.41\",\"0\",\"6\"],[\"64500\",\"3463.89\",\"0\",\"1038\"],[\"64500.1\",\"0.05\",\"0\",\"4\"],[\"64500.3\",\"2.78\",\"0\",\"5\"],[\"64502.4\",\"0.2\",\"0\",\"7\"],[\"64503.4\",\"1.55\",\"0\",\"1\"],[\"64505.1\",\"0.02\",\"0\",\"2\"],[\"64505.9\",\"0.78\",\"0\",\"2\"],[\"64508.9\",\"160.96\",\"0\",\"5\"],[\"64509.4\",\"85.34\",\"0\",\"1\"],[\"64513.3\",\"23.83\",\"0\",\"9\"],[\"64516.7\",\"0.36\",\"0\",\"9\"],[\"64517.6\",\"25.58\",\"0\",\"2\"],[\"64517.9\",\"86.25\",\"0\",\"4\"],[\"64520\",\"78.62\",\"0\",\"63\"],[\"64521.1\",\"0.02\",\"0\",\"2\"],[\"64527.3\",\"0\",\"0\",\"0\"],[\"64527.4\",\"0\",\"0\",\"0\"]],\"bids\":[[\"64482.9\",\"886.34\",\"0\",\"28\"],[\"64482.8\",\"5.95\",\"0\",\"12\"],[\"64482.2\",\"112.35\",\"0\",\"2\"],[\"64481.9\",\"1.56\",\"0\",\"1\"],[\"64481\",\"1.56\",\"0\",\"1\"],[\"64480.5\",\"1.56\",\"0\",\"1\"],[\"64480\",\"1.59\",\"0\",\"4\"],[\"64479.1\",\"3.76\",\"0\",\"2\"],[\"64478.7\",\"120.23\",\"0\",\"2\"],[\"64478.6\",\"42.16\",\"0\",\"2\"],[\"64478.3\",\"1.57\",\"0\",\"2\"],[\"64478\",\"0.01\",\"0\",\"1\"],[\"64477.7\",\"48.12\",\"0\",\"4\"],[\"64477.4\",\"0.01\",\"0\",\"1\"],[\"64477.2\",\"77.54\",\"0\",\"1\"],[\"64477.1\",\"1.57\",\"0\",\"2\"],[\"64477\",\"120.23\",\"0\",\"2\"],[\"64476.7\",\"0.01\",\"0\",\"1\"],[\"64476.2\",\"1.58\",\"0\",\"3\"],[\"64475.3\",\"0\",\"0\",\"0\"],[\"64474.8\",\"0.01\",\"0\",\"1\"],[\"64474.3\",\"0\",\"0\",\"0\"],[\"64473.8\",\"0.79\",\"0\",\"3\"],[\"64473.3\",\"0.01\",\"0\",\"1\"],[\"64472.2\",\"0.33\",\"0\",\"2\"],[\"64471.8\",\"0\",\"0\",\"0\"],[\"64466.9\",\"0.77\",\"0\",\"1\"],[\"64465.7\",\"148.92\",\"0\",\"1\"],[\"64464.7\",\"0\",\"0\",\"0\"],[\"64463.9\",\"85.4\",\"0\",\"1\"],[\"64463.2\",\"0\",\"0\",\"0\"],[\"64463.1\",\"3.17\",\"0\",\"1\"],[\"64462.9\",\"0.02\",\"0\",\"1\"],[\"64452.6\",\"512.18\",\"0\",\"2\"],[\"64452.5\",\"31.34\",\"0\",\"5\"],[\"64438\",\"18.87\",\"0\",\"1\"],[\"64424.2\",\"0\",\"0\",\"0\"],[\"64424\",\"0\",\"0\",\"0\"],[\"64423.9\",\"0\",\"0\",\"0\"]],\"ts\":\"1782016055305\",\"checksum\":-1966862910,\"seqId\":325070102273,\"prevSeqId\":325070102093}]}"}
{"action": null, "capture_sequence": 477, "channel": "trades", "connection_sequence": 4, "event": null, "instId": "BTC-USDT-SWAP", "local_receive_ts": "2026-06-21T04:27:35Z", "monotonic_ns": 1643611229551672, "raw": "{\"arg\":{\"channel\":\"trades\",\"instId\":\"BTC-USDT-SWAP\"},\"data\":[{\"instId\":\"BTC-USDT-SWAP\",\"tradeId\":\"2718750423\",\"px\":\"64482.9\",\"sz\":\"0.06\",\"side\":\"sell\",\"ts\":\"1782016055325\",\"count\":\"1\",\"source\":\"0\",\"seqId\":325070102575}]}"}
{"action": null, "capture_sequence": 478, "channel": "trades", "connection_sequence": 4, "event": null, "instId": "BTC-USDT-SWAP", "local_receive_ts": "2026-06-21T04:27:35Z", "monotonic_ns": 1643611233972731, "raw": "{\"arg\":{\"channel\":\"trades\",\"instId\":\"BTC-USDT-SWAP\"},\"data\":[{\"instId\":\"BTC-USDT-SWAP\",\"tradeId\":\"2718750424\",\"px\":\"64483\",\"sz\":\"0.02\",\"side\":\"buy\",\"ts\":\"1782016055330\",\"count\":\"1\",\"source\":\"0\",\"seqId\":325070102601}]}"}
{"action": "update", "capture_sequence": 479, "channel": "books", "connection_sequence": 4, "event": null, "instId": "BTC-USDT-SWAP", "local_receive_ts": "2026-06-21T04:27:35Z", "monotonic_ns": 1643611333271983, "raw": "{\"arg\":{\"channel\":\"books\",\"instId\":\"BTC-USDT-SWAP\"},\"action\":\"update\",\"data\":[{\"asks\":[[\"64483\",\"196.15\",\"0\",\"31\"],[\"64483.1\",\"0.64\",\"0\",\"5\"],[\"64483.5\",\"0\",\"0\",\"0\"],[\"64483.6\",\"0\",\"0\",\"0\"],[\"64484\",\"7.07\",\"0\",\"4\"],[\"64484.4\",\"0.02\",\"0\",\"2\"],[\"64484.5\",\"1.87\",\"0\",\"5\"],[\"64484.7\",\"0\",\"0\",\"0\"],[\"64484.9\",\"0.02\",\"0\",\"2\"],[\"64485.1\",\"57.94\",\"0\",\"1\"],[\"64485.2\",\"120.24\",\"0\",\"3\"],[\"64485.3\",\"7.75\",\"0\",\"1\"],[\"64485.4\",\"0.4\",\"0\",\"1\"],[\"64485.6\",\"0\",\"0\",\"0\"],[\"64485.7\",\"0.14\",\"0\",\"3\"],[\"64486.1\",\"0\",\"0\",\"0\"],[\"64486.3\",\"0.97\",\"0\",\"2\"],[\"64486.5\",\"91.05\",\"0\",\"2\"],[\"64486.8\",\"0.19\",\"0\",\"3\"],[\"64487.1\",\"136.66\",\"0\",\"5\"],[\"64487.5\",\"0.04\",\"0\",\"3\"],[\"64487.9\",\"0.51\",\"0\",\"2\"],[\"64488.6\",\"0.02\",\"0\",\"2\"],[\"64489.2\",\"0\",\"0\",\"0\"],[\"64489.6\",\"53.95\",\"0\",\"3\"],[\"64490\",\"57.33\",\"0\",\"20\"],[\"64490.1\",\"0.3\",\"0\",\"2\"],[\"64490.5\",\"4.57\",\"0\",\"5\"],[\"64491\",\"0.01\",\"0\",\"1\"],[\"64491.5\",\"1.66\",\"0\",\"2\"],[\"64491.9\",\"1.86\",\"0\",\"5\"],[\"64492.1\",\"7.7\",\"0\",\"2\"],[\"64492.4\",\"1.64\",\"0\",\"7\"],[\"64492.5\",\"0.05\",\"0\",\"3\"],[\"64492.6\",\"0\",\"0\",\"0\"],[\"64492.8\",\"1.21\",\"0\",\"10\"],[\"64492.9\",\"20.94\",\"0\",\"3\"],[\"64493\",\"19.9\",\"0\",\"6\"],[\"64493.2\",\"0.07\",\"0\",\"4\"],[\"64494.4\",\"0.72\",\"0\",\"7\"],[\"64494.6\",\"5.05\",\"0\",\"5\"],[\"64495.3\",\"0.26\",\"0\",\"2\"],[\"64495.4\",\"0.06\",\"0\",\"3\"],[\"64495.7\",\"11.36\",\"0\",\"4\"],[\"64495.9\",\"0.96\",\"0\",\"4\"],[\"64496.2\",\"46.54\",\"0\",\"1\"],[\"64496.9\",\"12\",\"0\",\"2\"],[\"64497.6\",\"4.13\",\"0\",\"4\"],[\"64498\",\"24.4\",\"0\",\"3\"],[\"64498.2\",\"8.21\",\"0\",\"5\"],[\"64498.7\",\"1.86\",\"0\",\"3\"],[\"64498.8\",\"496.71\",\"0\",\"4\"],[\"64499.1\",\"6.51\",\"0\",\"7\"],[\"64499.9\",\"1134.18\",\"0\",\"4\"],[\"64500\",\"3463.88\",\"0\",\"1037\"],[\"64500.1\",\"0.06\",\"0\",\"5\"],[\"64500.2\",\"0.02\",\"0\",\"2\"],[\"64501.7\",\"0.55\",\"0\",\"4\"],[\"64502.1\",\"31.04\",\"0\",\"2\"],[\"64502.4\",\"0.19\",\"0\",\"6\"],[\"64503.4\",\"0\",\"0\",\"0\"],[\"64504.3\",\"0.05\",\"0\",\"3\"],[\"64504.4\",\"233.89\",\"0\",\"5\"],[\"64504.9\",\"0.1\",\"0\",\"3\"],[\"64505\",\"0.82\",\"0\",\"3\"],[\"64505.7\",\"0.56\",\"0\",\"1\"],[\"64505.9\",\"0.01\",\"0\",\"1\"],[\"64506.1\",\"32.68\",\"0\",\"3\"],[\"64508.9\",\"96.47\",\"0\",\"4\"],[\"64509.3\",\"1.36\",\"0\",\"7\"],[\"64509.4\",\"0\",\"0\",\"0\"],[\"64509.5\",\"33.79\",\"0\",\"1\"],[\"64510\",\"71.08\",\"0\",\"29\"],[\"64511.1\",\"18.79\",\"0\",\"6\"],[\"64514.5\",\"144.25\",\"0\",\"7\"],[\"64515.8\",\"16.99\",\"0\",\"3\"],[\"64517.2\",\"0.77\",\"0\",\"6\"],[\"64517.9\",\"0.15\",\"0\",\"3\"],[\"64520.2\",\"20.07\",\"0\",\"2\"],[\"64521.1\",\"0.01\",\"0\",\"1\"],[\"64521.4\",\"46.84\",\"0\",\"2\"],[\"64522.6\",\"87.64\",\"0\",\"4\"],[\"64523.2\",\"0.02\",\"0\",\"2\"],[\"64524\",\"0.06\",\"0\",\"5\"],[\"64527.3\",\"0.05\",\"0\",\"5\"],[\"64527.4\",\"0.27\",\"0\",\"2\"],[\"64527.5\",\"0.19\",\"0\",\"5\"]],\"bids\":[[\"64482.9\",\"729.92\",\"0\",\"33\"],[\"64482.5\",\"0.02\",\"0\",\"1\"],[\"64482.4\",\"36.46\",\"0\",\"2\"],[\"64482.3\",\"0.7\",\"0\",\"1\"],[\"64482.2\",\"0\",\"0\",\"0\"],[\"64482.1\",\"0.05\",\"0\",\"3\"],[\"64482\",\"107.77\",\"0\",\"4\"],[\"64481.7\",\"2.2\",\"0\",\"1\"],[\"64480.8\",\"0.01\",\"0\",\"1\"],[\"64480\",\"1.6\",\"0\",\"5\"],[\"64479.9\",\"46.67\",\"0\",\"3\"],[\"64479.8\",\"46.24\",\"0\",\"2\"],[\"64479.7\",\"77.55\",\"0\",\"2\"],[\"64479.6\",\"11.44\",\"0\",\"3\"],[\"64479.4\",\"3.1\",\"0\",\"1\"],[\"64479.1\",\"1.56\",\"0\",\"1\"],[\"64478.7\",\"0.01\",\"0\",\"1\"],[\"64478.6\",\"0\",\"0\",\"0\"],[\"64478.5\",\"0.01\",\"0\",\"1\"],[\"64478.4\",\"0\",\"0\",\"0\"],[\"64477.9\",\"1.15\",\"0\",\"1\"],[\"64477.6\",\"0.01\",\"0\",\"1\"],[\"64477.5\",\"0.3\",\"0\",\"1\"],[\"64477.2\",\"0\",\"0\",\"0\"],[\"64477\",\"0.01\",\"0\",\"1\"],[\"64476.9\",\"4.02\",\"0\",\"3\"],[\"64476.8\",\"156.57\",\"0\",\"2\"],[\"64476.7\",\"246.59\",\"0\",\"4\"],[\"64476.6\",\"13.96\",\"0\",\"2\"],[\"64476.4\",\"0.32\",\"0\",\"2\"],[\"64476\",\"0.06\",\"0\",\"3\"],[\"64475.7\",\"0.24\",\"0\",\"2\"],[\"64475.6\",\"46.54\",\"0\",\"1\"],[\"64475.1\",\"138.15\",\"0\",\"5\"],[\"64473.8\",\"14.03\",\"0\",\"4\"],[\"64473.7\",\"0\",\"0\",\"0\"],[\"64473.5\",\"97.98\",\"0\",\"1\"],[\"64472.7\",\"0.02\",\"0\",\"2\"],[\"64472.3\",\"15.91\",\"0\",\"2\"],[\"64472.2\",\"0\",\"0\",\"0\"],[\"64472.1\",\"7.04\",\"0\",\"4\"],[\"64472\",\"86.18\",\"0\",\"3\"],[\"64471.9\",\"99.55\",\"0\",\"3\"],[\"64471.7\",\"0\",\"0\",\"0\"],[\"64471.5\",\"7.76\",\"0\",\"2\"],[\"64471.2\",\"50.44\",\"0\",\"2\"],[\"64470.6\",\"0.77\",\"0\",\"1\"],[\"64470.5\",\"65.64\",\"0\",\"4\"],[\"64470.1\",\"0.77\",\"0\",\"1\"],[\"64470\",\"18.36\",\"0\",\"6\"],[\"64469.5\",\"20.09\",\"0\",\"2\"],[\"64469.1\",\"85.4\",\"0\",\"2\"],[\"64467.4\",\"0\",\"0\",\"0\"],[\"64467\",\"195.57\",\"0\",\"3\"],[\"64466.9\",\"0.02\",\"0\",\"1\"],[\"64466.7\",\"0\",\"0\",\"0\"],[\"64466.5\",\"0.02\",\"0\",\"1\"],[\"64465.7\",\"58.22\",\"0\",\"1\"],[\"64464.8\",\"0.01\",\"0\",\"1\"],[\"64464.5\",\"31.07\",\"0\",\"3\"],[\"64464.4\",\"232.92\",\"0\",\"2\"],[\"64463.9\",\"0\",\"0\",\"0\"],[\"64463.3\",\"0\",\"0\",\"0\"],[\"64463.1\",\"3.21\",\"0\",\"1\"],[\"64462.9\",\"0\",\"0\",\"0\"],[\"64462.3\",\"0\",\"0\",\"0\"],[\"64461.5\",\"0.04\",\"0\",\"3\"],[\"64461.1\",\"0.02\",\"0\",\"1\"],[\"64460.9\",\"132.73\",\"0\",\"5\"],[\"64457.9\",\"0.01\",\"0\",\"1\"],[\"64457\",\"527.72\",\"0\",\"4\"],[\"64454.5\",\"0.03\",\"0\",\"2\"],[\"64452.5\",\"31.32\",\"0\",\"4\"],[\"64449\",\"0.02\",\"0\",\"2\"],[\"64446.7\",\"208.61\",\"0\",\"4\"],[\"64442\",\"15.01\",\"0\",\"2\"],[\"64440\",\"23.47\",\"0\",\"18\"],[\"64438.1\",\"42.74\",\"0\",\"6\"],[\"64437.7\",\"0\",\"0\",\"0\"],[\"64427.2\",\"15.55\",\"0\",\"2\"],[\"64424.2\",\"1.21\",\"0\",\"2\"],[\"64424\",\"1.36\",\"0\",\"4\"],[\"64423.9\",\"1.25\",\"0\",\"2\"],[\"64423.8\",\"60.49\",\"0\",\"2\"]],\"ts\":\"1782016055405\",\"checksum\":-625660567,\"seqId\":325070102835,\"prevSeqId\":325070102273}]}"}
{"action": null, "capture_sequence": 480, "channel": "trades", "connection_sequence": 4, "event": null, "instId": "BTC-USDT-SWAP", "local_receive_ts": "2026-06-21T04:27:35Z", "monotonic_ns": 1643611333884400, "raw": "{\"arg\":{\"channel\":\"trades\",\"instId\":\"BTC-USDT-SWAP\"},\"data\":[{\"instId\":\"BTC-USDT-SWAP\",\"tradeId\":\"2718750426\",\"px\":\"64483\",\"sz\":\"1.91\",\"side\":\"buy\",\"ts\":\"1782016055405\",\"count\":\"2\",\"source\":\"0\",\"seqId\":325070102839}]}"}
{"action": null, "capture_sequence": 481, "channel": "trades", "connection_sequence": 4, "event": null, "instId": "BTC-USDT-SWAP", "local_receive_ts": "2026-06-21T04:27:35Z", "monotonic_ns": 1643611355997538, "raw": "{\"arg\":{\"channel\":\"trades\",\"instId\":\"BTC-USDT-SWAP\"},\"data\":[{\"instId\":\"BTC-USDT-SWAP\",\"tradeId\":\"2718750427\",\"px\":\"64482.9\",\"sz\":\"0.46\",\"side\":\"sell\",\"ts\":\"1782016055452\",\"count\":\"1\",\"source\":\"0\",\"seqId\":325070102879}]}"}
{"action": "update", "capture_sequence": 482, "channel": "books", "connection_sequence": 4, "event": null, "instId": "BTC-USDT-SWAP", "local_receive_ts": "2026-06-21T04:27:35Z", "monotonic_ns": 1643611416541052, "raw": "{\"arg\":{\"channel\":\"books\",\"instId\":\"BTC-USDT-SWAP\"},\"action\":\"update\",\"data\":[{\"asks\":[[\"64483\",\"194.26\",\"0\",\"31\"],[\"64485.2\",\"0.02\",\"0\",\"2\"],[\"64489.9\",\"38.23\",\"0\",\"2\"],[\"64491.4\",\"12.33\",\"0\",\"3\"],[\"64499.9\",\"1118.67\",\"0\",\"3\"],[\"64500.4\",\"15.54\",\"0\",\"4\"],[\"64505.6\",\"59.46\",\"0\",\"5\"],[\"64506.1\",\"31.13\",\"0\",\"2\"],[\"64507.9\",\"34.06\",\"0\",\"5\"],[\"64509.5\",\"0\",\"0\",\"0\"],[\"64512.1\",\"122.57\",\"0\",\"5\"],[\"64513.3\",\"24.68\",\"0\",\"10\"],[\"64514.5\",\"58.92\",\"0\",\"6\"],[\"64517.2\",\"0.76\",\"0\",\"5\"],[\"64526\",\"1.15\",\"0\",\"3\"],[\"64527.6\",\"16.48\",\"0\",\"5\"]],\"bids\":[[\"64482.9\",\"727.9\",\"0\",\"32\"],[\"64482.4\",\"36.47\",\"0\",\"3\"],[\"64480.9\",\"0\",\"0\",\"0\"],[\"64479.7\",\"0.01\",\"0\",\"1\"],[\"64479.2\",\"77.55\",\"0\",\"2\"],[\"64473.2\",\"13.31\",\"0\",\"3\"],[\"64472.5\",\"4.78\",\"0\",\"2\"],[\"64472.2\",\"1.92\",\"0\",\"1\"],[\"64472\",\"0.02\",\"0\",\"2\"],[\"64471.9\",\"0\",\"0\",\"0\"],[\"64471.7\",\"2.76\",\"0\",\"1\"],[\"64471.3\",\"47.03\",\"0\",\"2\"],[\"64471.1\",\"2.88\",\"0\",\"1\"],[\"64470.5\",\"86.94\",\"0\",\"3\"],[\"64470\",\"16.76\",\"0\",\"5\"],[\"64469.4\",\"0\",\"0\",\"0\"],[\"64469.1\",\"0.01\",\"0\",\"1\"],[\"64469\",\"35.41\",\"0\",\"2\"],[\"64466.7\",\"85.39\",\"0\",\"1\"],[\"64466.5\",\"0\",\"0\",\"0\"],[\"64465.5\",\"0.02\",\"0\",\"1\"],[\"64465\",\"200\",\"0\",\"1\"],[\"64464.7\",\"1\",\"0\",\"1\"],[\"64461.5\",\"0.02\",\"0\",\"2\"],[\"64460.9\",\"132.75\",\"0\",\"6\"],[\"64459.5\",\"15.65\",\"0\",\"1\"],[\"64457.9\",\"0.03\",\"0\",\"2\"],[\"64424\",\"0\",\"0\",\"0\"],[\"64423.9\",\"0\",\"0\",\"0\"],[\"64423.8\",\"0\",\"0\",\"0\"]],\"ts\":\"1782016055505\",\"checksum\":-734540251,\"seqId\":325070102911,\"prevSeqId\":325070102835}]}"}
{"action": null, "capture_sequence": 483, "channel": "trades", "connection_sequence": 4, "event": null, "instId": "BTC-USDT-SWAP", "local_receive_ts": "2026-06-21T04:27:35Z", "monotonic_ns": 1643611441697662, "raw": "{\"arg\":{\"channel\":\"trades\",\"instId\":\"BTC-USDT-SWAP\"},\"data\":[{\"instId\":\"BTC-USDT-SWAP\",\"tradeId\":\"2718750428\",\"px\":\"64482.9\",\"sz\":\"0.1\",\"side\":\"sell\",\"ts\":\"1782016055537\",\"count\":\"1\",\"source\":\"0\",\"seqId\":325070102937}]}"}
{"action": "update", "capture_sequence": 484, "channel": "books", "connection_sequence": 4, "event": null, "instId": "BTC-USDT-SWAP", "local_receive_ts": "2026-06-21T04:27:35Z", "monotonic_ns": 1643611509454202, "raw": "{\"arg\":{\"channel\":\"books\",\"instId\":\"BTC-USDT-SWAP\"},\"action\":\"update\",\"data\":[{\"asks\":[[\"64485.1\",\"20.2\",\"0\",\"1\"],[\"64488.2\",\"4.73\",\"0\",\"3\"],[\"64498.2\",\"8.04\",\"0\",\"4\"],[\"64498.6\",\"0.46\",\"0\",\"7\"],[\"64505\",\"200.82\",\"0\",\"4\"],[\"64508.3\",\"0.77\",\"0\",\"1\"],[\"64509.3\",\"0.59\",\"0\",\"6\"],[\"64516.5\",\"197.9\",\"0\",\"3\"],[\"64518.5\",\"20.07\",\"0\",\"2\"],[\"64520.2\",\"0.01\",\"0\",\"1\"],[\"64520.9\",\"86.12\",\"0\",\"3\"],[\"64522.6\",\"1.54\",\"0\",\"3\"],[\"64527.6\",\"0\",\"0\",\"0\"]],\"bids\":[[\"64482.9\",\"727.8\",\"0\",\"32\"],[\"64481.8\",\"0.01\",\"0\",\"1\"],[\"64478.7\",\"0\",\"0\",\"0\"],[\"64472.9\",\"1.6\",\"0\",\"1\"],[\"64471.9\",\"2.16\",\"0\",\"1\"],[\"64471.4\",\"3.01\",\"0\",\"2\"],[\"64471.2\",\"136.6\",\"0\",\"3\"],[\"64471.1\",\"151.79\",\"0\",\"2\"],[\"64470.6\",\"3.47\",\"0\",\"2\"],[\"64470.5\",\"0.78\",\"0\",\"2\"],[\"64470.1\",\"0\",\"0\",\"0\"],[\"64469.5\",\"0.01\",\"0\",\"1\"],[\"64469.1\",\"0.78\",\"0\",\"2\"],[\"64468.7\",\"76.39\",\"0\",\"4\"],[\"64468\",\"20.1\",\"0\",\"3\"],[\"64467.9\",\"0.01\",\"0\",\"1\"],[\"64467.3\",\"95.53\",\"0\",\"2\"],[\"64424.2\",\"0\",\"0\",\"0\"]],\"ts\":\"1782016055605\",\"checksum\":1689615258,\"seqId\":325070102972,\"prevSeqId\":325070102911}]}"}
{"action": "update", "capture_sequence": 485, "channel": "books", "connection_sequence": 4, "event": null, "instId": "BTC-USDT-SWAP", "local_receive_ts": "2026-06-21T04:27:35Z", "monotonic_ns": 1643611609653496, "raw": "{\"arg\":{\"channel\":\"books\",\"instId\":\"BTC-USDT-SWAP\"},\"action\":\"update\",\"data\":[{\"asks\":[[\"64502.1\",\"0.01\",\"0\",\"1\"],[\"64502.9\",\"311.75\",\"0\",\"8\"],[\"64519.7\",\"96.91\",\"0\",\"8\"],[\"64520.9\",\"0.02\",\"0\",\"2\"],[\"64525.4\",\"11.33\",\"0\",\"2\"],[\"64526.5\",\"60.01\",\"0\",\"4\"]],\"bids\":[[\"64471.2\",\"50.44\",\"0\",\"2\"],[\"64470\",\"102.92\",\"0\",\"6\"],[\"64469\",\"33.81\",\"0\",\"1\"],[\"64468.4\",\"0\",\"0\",\"0\"],[\"64467.6\",\"0.03\",\"0\",\"3\"],[\"64466.8\",\"0.01\",\"0\",\"1\"],[\"64465.8\",\"31.05\",\"0\",\"1\"],[\"64464.5\",\"0.02\",\"0\",\"2\"]],\"ts\":\"1782016055705\",\"checksum\":1689615258,\"seqId\":325070103002,\"prevSeqId\":325070102972}]}"}
{"action": null, "capture_sequence": 486, "channel": "trades", "connection_sequence": 4, "event": null, "instId": "BTC-USDT-SWAP", "local_receive_ts": "2026-06-21T04:27:35Z", "monotonic_ns": 1643611668235021, "raw": "{\"arg\":{\"channel\":\"trades\",\"instId\":\"BTC-USDT-SWAP\"},\"data\":[{\"instId\":\"BTC-USDT-SWAP\",\"tradeId\":\"2718750429\",\"px\":\"64483\",\"sz\":\"1.55\",\"side\":\"buy\",\"ts\":\"1782016055764\",\"count\":\"1\",\"source\":\"0\",\"seqId\":325070103020}]}"}
{"action": "update", "capture_sequence": 487, "channel": "books", "connection_sequence": 4, "event": null, "instId": "BTC-USDT-SWAP", "local_receive_ts": "2026-06-21T04:27:35Z", "monotonic_ns": 1643611709427145, "raw": "{\"arg\":{\"channel\":\"books\",\"instId\":\"BTC-USDT-SWAP\"},\"action\":\"update\",\"data\":[{\"asks\":[[\"64483\",\"192.71\",\"0\",\"31\"],[\"64484.6\",\"1.21\",\"0\",\"2\"]],\"bids\":[[\"64481.9\",\"2.33\",\"0\",\"2\"],[\"64481.1\",\"0.01\",\"0\",\"1\"],[\"64468.1\",\"0\",\"0\",\"0\"],[\"64455.9\",\"0\",\"0\",\"0\"],[\"64424.2\",\"1.21\",\"0\",\"2\"]],\"ts\":\"1782016055805\",\"checksum\":1994338346,\"seqId\":325070103038,\"prevSeqId\":325070103002}]}"}
{"action": "update", "capture_sequence": 488, "channel": "books", "connection_sequence": 4, "event": null, "instId": "BTC-USDT-SWAP", "local_receive_ts": "2026-06-21T04:27:36Z", "monotonic_ns": 1643611809212837, "raw": "{\"arg\":{\"channel\":\"books\",\"instId\":\"BTC-USDT-SWAP\"},\"action\":\"update\",\"data\":[{\"asks\":[[\"64484.8\",\"0.02\",\"0\",\"2\"],[\"64484.9\",\"20.81\",\"0\",\"2\"],[\"64485.1\",\"0\",\"0\",\"0\"],[\"64492.8\",\"0.44\",\"0\",\"9\"],[\"64492.9\",\"21.43\",\"0\",\"4\"],[\"64498.8\",\"496.55\",\"0\",\"3\"],[\"64525.4\",\"11.18\",\"0\",\"1\"]],\"bids\":[[\"64482.9\",\"716.38\",\"0\",\"31\"],[\"64471.7\",\"33.81\",\"0\",\"2\"],[\"64471.3\",\"16.75\",\"0\",\"2\"],[\"64470.6\",\"2.7\",\"0\",\"1\"],[\"64463.1\",\"0\",\"0\",\"0\"],[\"64462.1\",\"14.43\",\"0\",\"2\"],[\"64424\",\"1.36\",\"0\",\"4\"]],\"ts\":\"1782016055905\",\"checksum\":1687173901,\"seqId\":325070103081,\"prevSeqId\":325070103038}]}"}
{"action": null, "capture_sequence": 489, "channel": "trades", "connection_sequence": 4, "event": null, "instId": "BTC-USDT-SWAP", "local_receive_ts": "2026-06-21T04:27:36Z", "monotonic_ns": 1643611819613062, "raw": "{\"arg\":{\"channel\":\"trades\",\"instId\":\"BTC-USDT-SWAP\"},\"data\":[{\"instId\":\"BTC-USDT-SWAP\",\"tradeId\":\"2718750430\",\"px\":\"64483\",\"sz\":\"0.36\",\"side\":\"buy\",\"ts\":\"1782016055915\",\"count\":\"1\",\"source\":\"0\",\"seqId\":325070103083}]}"}
{"action": "update", "capture_sequence": 490, "channel": "books", "connection_sequence": 4, "event": null, "instId": "BTC-USDT-SWAP", "local_receive_ts": "2026-06-21T04:27:36Z", "monotonic_ns": 1643611916527892, "raw": "{\"arg\":{\"channel\":\"books\",\"instId\":\"BTC-USDT-SWAP\"},\"action\":\"update\",\"data\":[{\"asks\":[[\"64483\",\"269.89\",\"0\",\"32\"],[\"64484.6\",\"2.77\",\"0\",\"3\"],[\"64485.6\",\"1.56\",\"0\",\"1\"],[\"64494.3\",\"1.88\",\"0\",\"5\"],[\"64498.8\",\"496.71\",\"0\",\"4\"],[\"64499.6\",\"60.67\",\"0\",\"3\"],[\"64500\",\"3463.87\",\"0\",\"1036\"],[\"64500.4\",\"15.55\",\"0\",\"5\"],[\"64502.8\",\"88.1\",\"0\",\"4\"],[\"64502.9\",\"391.16\",\"0\",\"6\"],[\"64503.8\",\"232.77\",\"0\",\"1\"],[\"64504.4\",\"1.13\",\"0\",\"4\"],[\"64505.3\",\"2.71\",\"0\",\"3\"],[\"64505.6\",\"57.91\",\"0\",\"4\"],[\"64507.7\",\"33.86\",\"0\",\"5\"],[\"64507.9\",\"0.27\",\"0\",\"4\"],[\"64511.9\",\"85.47\",\"0\",\"2\"],[\"64512.1\",\"37.24\",\"0\",\"4\"],[\"64512.6\",\"116.92\",\"0\",\"8\"],[\"64514.5\",\"0.74\",\"0\",\"5\"],[\"64525.3\",\"0.02\",\"0\",\"2\"],[\"64526.5\",\"60\",\"0\",\"3\"],[\"64527.4\",\"0\",\"0\",\"0\"],[\"64527.5\",\"0\",\"0\",\"0\"]],\"bids\":[[\"64482.9\",\"717.94\",\"0\",\"32\"],[\"64479.2\",\"0.01\",\"0\",\"1\"],[\"64478.4\",\"77.54\",\"0\",\"1\"],[\"64471.7\",\"2.76\",\"0\",\"1\"],[\"64471.5\",\"38.81\",\"0\",\"3\"],[\"64471.3\",\"17.52\",\"0\",\"3\"],[\"64470.5\",\"86.17\",\"0\",\"2\"],[\"64470\",\"16.76\",\"0\",\"5\"],[\"64469\",\"0\",\"0\",\"0\"],[\"64468.8\",\"45.14\",\"0\",\"2\"],[\"64466.9\",\"0\",\"0\",\"0\"],[\"64466.7\",\"0\",\"0\",\"0\"],[\"64465.9\",\"85.39\",\"0\",\"1\"],[\"64465.8\",\"0\",\"0\",\"0\"],[\"64465.7\",\"31.09\",\"0\",\"3\"],[\"64465.5\",\"0\",\"0\",\"0\"],[\"64464.6\",\"232.91\",\"0\",\"1\"],[\"64464.5\",\"58.24\",\"0\",\"3\"],[\"64464.4\",\"0.01\",\"0\",\"1\"],[\"64463.1\",\"3.21\",\"0\",\"1\"],[\"64461.5\",\"0.04\",\"0\",\"3\"],[\"64460.9\",\"132.73\",\"0\",\"5\"],[\"64459.5\",\"15.67\",\"0\",\"2\"],[\"64457.9\",\"0.01\",\"0\",\"1\"],[\"64454.9\",\"12.88\",\"0\",\"2\"],[\"64454.5\",\"0.01\",\"0\",\"1\"],[\"64423.9\",\"1.25\",\"0\",\"2\"]],\"ts\":\"1782016056005\",\"checksum\":1791648488,\"seqId\":325070103171,\"prevSeqId\":325070103081}]}"}
{"action": "update", "capture_sequence": 491, "channel": "books", "connection_sequence": 4, "event": null, "instId": "BTC-USDT-SWAP", "local_receive_ts": "2026-06-21T04:27:36Z", "monotonic_ns": 1643612021526232, "raw": "{\"arg\":{\"channel\":\"books\",\"instId\":\"BTC-USDT-SWAP\"},\"action\":\"update\",\"data\":[{\"asks\":[[\"64484.6\",\"1.21\",\"0\",\"2\"],[\"64485.1\",\"1.56\",\"0\",\"1\"],[\"64485.6\",\"0\",\"0\",\"0\"],[\"64486.6\",\"2.55\",\"0\",\"2\"],[\"64487\",\"6.67\",\"0\",\"5\"],[\"64492.9\",\"19.87\",\"0\",\"3\"],[\"64495\",\"1.5\",\"0\",\"9\"],[\"64495.7\",\"11.35\",\"0\",\"3\"],[\"64497.3\",\"41.31\",\"0\",\"5\"],[\"64498\",\"24.62\",\"0\",\"4\"],[\"64498.6\",\"0.29\",\"0\",\"6\"],[\"64500\",\"3459.22\",\"0\",\"1035\"],[\"64500.4\",\"0.04\",\"0\",\"4\"],[\"64500.6\",\"78.05\",\"0\",\"5\"],[\"64502.8\",\"57.07\",\"0\",\"3\"],[\"64502.9\",\"422.19\",\"0\",\"7\"],[\"64503.8\",\"0\",\"0\",\"0\"],[\"64504\",\"287.31\",\"0\",\"9\"],[\"64507.3\",\"0.8\",\"0\",\"3\"],[\"64508.3\",\"0\",\"0\",\"0\"],[\"64508.9\",\"96.78\",\"0\",\"5\"],[\"64509.3\",\"0.28\",\"0\",\"5\"],[\"64518\",\"123.1\",\"0\",\"13\"],[\"64518.5\",\"0.01\",\"0\",\"1\"],[\"64524.3\",\"15.66\",\"0\",\"2\"],[\"64525.3\",\"0.01\",\"0\",\"1\"],[\"64525.4\",\"11.33\",\"0\",\"2\"],[\"64527.4\",\"0.27\",\"0\",\"2\"],[\"64527.5\",\"0.19\",\"0\",\"5\"]],\"bids\":[[\"64471.6\",\"31.08\",\"0\",\"2\"],[\"64471.5\",\"7.76\",\"0\",\"2\"],[\"64469.1\",\"0.01\",\"0\",\"1\"],[\"64468.4\",\"0.77\",\"0\",\"1\"],[\"64468\",\"0.02\",\"0\",\"2\"],[\"64467.6\",\"20.11\",\"0\",\"4\"],[\"64466.7\",\"85.39\",\"0\",\"1\"],[\"64465.9\",\"0\",\"0\",\"0\"],[\"64465.8\",\"31.05\",\"0\",\"1\"],[\"64465.7\",\"0.04\",\"0\",\"2\"],[\"64465.1\",\"232.9\",\"0\",\"1\"],[\"64464.6\",\"0\",\"0\",\"0\"],[\"64464.5\",\"0.02\",\"0\",\"2\"],[\"64464.4\",\"58.23\",\"0\",\"2\"],[\"64424\",\"0\",\"0\",\"0\"],[\"64423.9\",\"0\",\"0\",\"0\"]],\"ts\":\"1782016056105\",\"checksum\":1459239269,\"seqId\":325070103311,\"prevSeqId\":325070103171}]}"}
{"action": "update", "capture_sequence": 492, "channel": "books", "connection_sequence": 4, "event": null, "instId": "BTC-USDT-SWAP", "local_receive_ts": "2026-06-21T04:27:36Z", "monotonic_ns": 1643612109847477, "raw": "{\"arg\":{\"channel\":\"books\",\"instId\":\"BTC-USDT-SWAP\"},\"action\":\"update\",\"data\":[{\"asks\":[[\"64485.1\",\"0\",\"0\",\"0\"],[\"64485.6\",\"1.56\",\"0\",\"1\"],[\"64492.4\",\"0.08\",\"0\",\"6\"],[\"64507.1\",\"0.83\",\"0\",\"5\"],[\"64507.3\",\"0.03\",\"0\",\"2\"],[\"64518\",\"103.04\",\"0\",\"12\"],[\"64518.1\",\"20.21\",\"0\",\"6\"]],\"bids\":[[\"64479.2\",\"77.55\",\"0\",\"2\"],[\"64478.4\",\"0\",\"0\",\"0\"],[\"64424\",\"1.36\",\"0\",\"4\"]],\"ts\":\"1782016056205\",\"checksum\":1188822908,\"seqId\":325070103333,\"prevSeqId\":325070103311}]}"}
{"action": "update", "capture_sequence": 493, "channel": "books", "connection_sequence": 4, "event": null, "instId": "BTC-USDT-SWAP", "local_receive_ts": "2026-06-21T04:27:36Z", "monotonic_ns": 1643612209937745, "raw": "{\"arg\":{\"channel\":\"books\",\"instId\":\"BTC-USDT-SWAP\"},\"action\":\"update\",\"data\":[{\"asks\":[[\"64483.8\",\"0.01\",\"0\",\"1\"],[\"64484.4\",\"1.58\",\"0\",\"3\"],[\"64484.8\",\"0.01\",\"0\",\"1\"],[\"64484.9\",\"54.02\",\"0\",\"2\"],[\"64485.2\",\"106.6\",\"0\",\"3\"],[\"64485.3\",\"9.31\",\"0\",\"2\"],[\"64485.6\",\"0\",\"0\",\"0\"],[\"64485.9\",\"6.99\",\"0\",\"3\"],[\"64486.4\",\"2.83\",\"0\",\"3\"],[\"64486.6\",\"0.99\",\"0\",\"1\"],[\"64487.5\",\"1.6\",\"0\",\"4\"],[\"64489.2\",\"60.51\",\"0\",\"1\"],[\"64489.5\",\"7.22\",\"0\",\"4\"],[\"64491.5\",\"0.1\",\"0\",\"1\"],[\"64491.9\",\"0.3\",\"0\",\"4\"],[\"64492.1\",\"1.5\",\"0\",\"1\"],[\"64492.9\",\"0.78\",\"0\",\"2\"],[\"64494.1\",\"0.01\",\"0\",\"1\"],[\"64495\",\"1.49\",\"0\",\"8\"],[\"64495.4\",\"19.15\",\"0\",\"4\"],[\"64500\",\"3459.23\",\"0\",\"1036\"],[\"64500.1\",\"0.05\",\"0\",\"4\"],[\"64504.1\",\"21.34\",\"0\",\"8\"],[\"64504.3\",\"0.04\",\"0\",\"2\"],[\"64507.7\",\"0.07\",\"0\",\"4\"],[\"64507.8\",\"67.92\",\"0\",\"6\"],[\"64523.4\",\"21.47\",\"0\",\"4\"],[\"64524.3\",\"15.65\",\"0\",\"1\"],[\"64527.4\",\"0\",\"0\",\"0\"],[\"64527.5\",\"0\",\"0\",\"0\"]],\"bids\":[[\"64469\",\"33.81\",\"0\",\"1\"],[\"64468.8\",\"11.33\",\"0\",\"1\"],[\"64435.1\",\"3.02\",\"0\",\"3\"],[\"64432.8\",\"0\",\"0\",\"0\"]],\"ts\":\"1782016056305\",\"checksum\":-1154987652,\"seqId\":325070103403,\"prevSeqId\":325070103333}]}"}
{"action": "update", "capture_sequence": 494, "channel": "books", "connection_sequence": 4, "event": null, "instId": "BTC-USDT-SWAP", "local_receive_ts": "2026-06-21T04:27:36Z", "monotonic_ns": 1643612316638375, "raw": "{\"arg\":{\"channel\":\"books\",\"instId\":\"BTC-USDT-SWAP\"},\"action\":\"update\",\"data\":[{\"asks\":[[\"64483\",\"323.85\",\"0\",\"33\"],[\"64483.8\",\"0\",\"0\",\"0\"],[\"64484.4\",\"0.02\",\"0\",\"2\"],[\"64484.8\",\"0.02\",\"0\",\"2\"],[\"64484.9\",\"87.75\",\"0\",\"3\"],[\"64485.1\",\"1.56\",\"0\",\"1\"],[\"64485.2\",\"0.02\",\"0\",\"2\"],[\"64485.3\",\"7.75\",\"0\",\"1\"],[\"64485.4\",\"136.53\",\"0\",\"2\"],[\"64485.6\",\"1.56\",\"0\",\"1\"],[\"64485.9\",\"5.43\",\"0\",\"2\"],[\"64486.1\",\"1.56\",\"0\",\"1\"],[\"64486.4\",\"1.27\",\"0\",\"2\"],[\"64486.6\",\"2.55\",\"0\",\"2\"],[\"64487.1\",\"0.53\",\"0\",\"4\"],[\"64488\",\"59.43\",\"0\",\"28\"],[\"64488.5\",\"1.56\",\"0\",\"1\"],[\"64488.7\",\"6.24\",\"0\",\"2\"],[\"64489.2\",\"154.17\",\"0\",\"2\"],[\"64489.5\",\"1.02\",\"0\",\"3\"],[\"64489.6\",\"52.39\",\"0\",\"2\"],[\"64490\",\"55.77\",\"0\",\"19\"],[\"64490.5\",\"3.01\",\"0\",\"4\"],[\"64492.9\",\"0.01\",\"0\",\"1\"],[\"64495.4\",\"19.92\",\"0\",\"5\"],[\"64498.8\",\"496.55\",\"0\",\"3\"],[\"64503.8\",\"232.77\",\"0\",\"1\"],[\"64504\",\"54.55\",\"0\",\"8\"],[\"64505.2\",\"17.2\",\"0\",\"2\"],[\"64505.3\",\"1.16\",\"0\",\"2\"],[\"64527\",\"0\",\"0\",\"0\"],[\"64527.1\",\"0\",\"0\",\"0\"],[\"64527.2\",\"0\",\"0\",\"0\"],[\"64527.3\",\"0\",\"0\",\"0\"]],\"bids\":[[\"64482.9\",\"717.97\",\"0\",\"32\"],[\"64482.8\",\"3.95\",\"0\",\"11\"],[\"64479.2\",\"0.01\",\"0\",\"1\"],[\"64478.4\",\"77.54\",\"0\",\"1\"],[\"64468.4\",\"0\",\"0\",\"0\"],[\"64467.7\",\"0.77\",\"0\",\"1\"],[\"64466.7\",\"0\",\"0\",\"0\"],[\"64465.9\",\"85.39\",\"0\",\"1\"],[\"64465.1\",\"0\",\"0\",\"0\"],[\"64464.5\",\"232.93\",\"0\",\"3\"],[\"64463.1\",\"0\",\"0\",\"0\"],[\"64423.9\",\"1.25\",\"0\",\"2\"]],\"ts\":\"1782016056405\",\"checksum\":557796117,\"seqId\":325070103509,\"prevSeqId\":325070103403}]}"}
{"action": null, "capture_sequence": 495, "channel": "trades", "connection_sequence": 4, "event": null, "instId": "BTC-USDT-SWAP", "local_receive_ts": "2026-06-21T04:27:36Z", "monotonic_ns": 1643612342829827, "raw": "{\"arg\":{\"channel\":\"trades\",\"instId\":\"BTC-USDT-SWAP\"},\"data\":[{\"instId\":\"BTC-USDT-SWAP\",\"tradeId\":\"2718750431\",\"px\":\"64483\",\"sz\":\"0.02\",\"side\":\"buy\",\"ts\":\"1782016056439\",\"count\":\"1\",\"source\":\"0\",\"seqId\":325070103559}]}"}
{"action": "update", "capture_sequence": 496, "channel": "books", "connection_sequence": 4, "event": null, "instId": "BTC-USDT-SWAP", "local_receive_ts": "2026-06-21T04:27:36Z", "monotonic_ns": 1643612417286737, "raw": "{\"arg\":{\"channel\":\"books\",\"instId\":\"BTC-USDT-SWAP\"},\"action\":\"update\",\"data\":[{\"asks\":[[\"64483\",\"269.97\",\"0\",\"33\"],[\"64484.9\",\"54.02\",\"0\",\"2\"],[\"64485.1\",\"0\",\"0\",\"0\"],[\"64485.6\",\"0\",\"0\",\"0\"],[\"64486.1\",\"0\",\"0\",\"0\"],[\"64486.6\",\"0.99\",\"0\",\"1\"],[\"64487\",\"5.11\",\"0\",\"4\"],[\"64487.5\",\"0.04\",\"0\",\"3\"],[\"64489.2\",\"246.48\",\"0\",\"3\"],[\"64489.6\",\"53.95\",\"0\",\"3\"],[\"64492.9\",\"0.78\",\"0\",\"2\"],[\"64493.2\",\"0.08\",\"0\",\"5\"],[\"64494.1\",\"0\",\"0\",\"0\"],[\"64495.4\",\"19.15\",\"0\",\"4\"],[\"64496.4\",\"0.19\",\"0\",\"3\"],[\"64497.3\",\"41.14\",\"0\",\"4\"],[\"64498.9\",\"3.58\",\"0\",\"3\"],[\"64503.6\",\"0.03\",\"0\",\"3\"],[\"64504.1\",\"21.33\",\"0\",\"7\"],[\"64505.2\",\"15.65\",\"0\",\"1\"],[\"64505.5\",\"75.36\",\"0\",\"4\"],[\"64508.6\",\"0.32\",\"0\",\"2\"],[\"64508.9\",\"96.47\",\"0\",\"4\"],[\"64512.6\",\"58.74\",\"0\",\"7\"],[\"64512.9\",\"75.97\",\"0\",\"5\"],[\"64518.1\",\"0.15\",\"0\",\"5\"],[\"64518.3\",\"20.08\",\"0\",\"3\"],[\"64522.8\",\"15.72\",\"0\",\"5\"],[\"64523.4\",\"21.46\",\"0\",\"3\"],[\"64527\",\"0.17\",\"0\",\"3\"],[\"64527.1\",\"0.46\",\"0\",\"1\"],[\"64527.2\",\"0.18\",\"0\",\"4\"],[\"64527.3\",\"0.05\",\"0\",\"5\"]],\"bids\":[[\"64482.9\",\"716.89\",\"0\",\"32\"],[\"64481.9\",\"0.77\",\"0\",\"1\"],[\"64481.2\",\"0.31\",\"0\",\"1\"],[\"64481.1\",\"1.56\",\"0\",\"1\"],[\"64481\",\"0\",\"0\",\"0\"],[\"64479.6\",\"13\",\"0\",\"4\"],[\"64479.2\",\"77.55\",\"0\",\"2\"],[\"64478.4\",\"0\",\"0\",\"0\"],[\"64476.4\",\"0.01\",\"0\",\"1\"],[\"64475.7\",\"0.55\",\"0\",\"3\"],[\"64467.8\",\"20.64\",\"0\",\"3\"],[\"64467.6\",\"0.03\",\"0\",\"3\"],[\"64464.8\",\"58.23\",\"0\",\"2\"],[\"64464.4\",\"0.01\",\"0\",\"1\"],[\"64463\",\"22.12\",\"0\",\"4\"],[\"64423.8\",\"60.49\",\"0\",\"2\"]],\"ts\":\"1782016056505\",\"checksum\":-1294632500,\"seqId\":325070103669,\"prevSeqId\":325070103509}]}"}
{"action": null, "capture_sequence": 497, "channel": "trades", "connection_sequence": 4, "event": null, "instId": "BTC-USDT-SWAP", "local_receive_ts": "2026-06-21T04:27:36Z", "monotonic_ns": 1643612448887734, "raw": "{\"arg\":{\"channel\":\"trades\",\"instId\":\"BTC-USDT-SWAP\"},\"data\":[{\"instId\":\"BTC-USDT-SWAP\",\"tradeId\":\"2718750432\",\"px\":\"64482.9\",\"sz\":\"0.06\",\"side\":\"sell\",\"ts\":\"1782016056545\",\"count\":\"1\",\"source\":\"0\",\"seqId\":325070103763}]}"}
{"action": "update", "capture_sequence": 498, "channel": "books", "connection_sequence": 4, "event": null, "instId": "BTC-USDT-SWAP", "local_receive_ts": "2026-06-21T04:27:36Z", "monotonic_ns": 1643612509822129, "raw": "{\"arg\":{\"channel\":\"books\",\"instId\":\"BTC-USDT-SWAP\"},\"action\":\"update\",\"data\":[{\"asks\":[[\"64488\",\"57.87\",\"0\",\"27\"],[\"64488.5\",\"0\",\"0\",\"0\"],[\"64493.2\",\"0.07\",\"0\",\"4\"],[\"64494.1\",\"0.01\",\"0\",\"1\"],[\"64503.6\",\"0.02\",\"0\",\"2\"],[\"64503.9\",\"15.66\",\"0\",\"2\"],[\"64511.9\",\"0.14\",\"0\",\"1\"],[\"64512\",\"88.21\",\"0\",\"14\"],[\"64518.1\",\"20.21\",\"0\",\"6\"],[\"64518.3\",\"0.02\",\"0\",\"2\"],[\"64522.8\",\"15.71\",\"0\",\"4\"],[\"64523\",\"0.01\",\"0\",\"1\"],[\"64527.3\",\"0\",\"0\",\"0\"]],\"bids\":[[\"64482.9\",\"716.83\",\"0\",\"32\"],[\"64481.2\",\"0.32\",\"0\",\"2\"],[\"64476.2\",\"1.89\",\"0\",\"4\"],[\"64475.7\",\"0.24\",\"0\",\"2\"],[\"64469\",\"0\",\"0\",\"0\"],[\"64468.9\",\"34.11\",\"0\",\"2\"],[\"64467.9\",\"0.78\",\"0\",\"2\"],[\"64467.8\",\"0.56\",\"0\",\"2\"],[\"64467.7\",\"20.08\",\"0\",\"1\"],[\"64466.7\",\"85.39\",\"0\",\"1\"],[\"64465.9\",\"0\",\"0\",\"0\"],[\"64423.5\",\"381.6\",\"0\",\"2\"]],\"ts\":\"1782016056605\",\"checksum\":-77102574,\"seqId\":325070103823,\"prevSeqId\":325070103669}]}"}
{"action": "update", "capture_sequence": 499, "channel": "books", "connection_sequence": 4, "event": null, "instId": "BTC-USDT-SWAP", "local_receive_ts": "2026-06-21T04:27:36Z", "monotonic_ns": 1643612609454052, "raw": "{\"arg\":{\"channel\":\"books\",\"instId\":\"BTC-USDT-SWAP\"},\"action\":\"update\",\"data\":[{\"asks\":[[\"64483\",\"280.13\",\"0\",\"35\"],[\"64492.9\",\"19.83\",\"0\",\"3\"],[\"64494.6\",\"27.05\",\"0\",\"6\"],[\"64495.4\",\"0.06\",\"0\",\"3\"],[\"64496.4\",\"0.02\",\"0\",\"2\"],[\"64497.1\",\"3.11\",\"0\",\"2\"],[\"64497.3\",\"41.31\",\"0\",\"5\"],[\"64499.1\",\"3.41\",\"0\",\"6\"],[\"64507.8\",\"34.13\",\"0\",\"5\"],[\"64508.3\",\"0.31\",\"0\",\"1\"],[\"64508.6\",\"33.8\",\"0\",\"2\"],[\"64511.9\",\"85.47\",\"0\",\"2\"],[\"64512\",\"2.88\",\"0\",\"13\"],[\"64518\",\"123.1\",\"0\",\"13\"],[\"64518.1\",\"0.15\",\"0\",\"5\"],[\"64525.4\",\"11.18\",\"0\",\"1\"],[\"64527.2\",\"0\",\"0\",\"0\"]],\"bids\":[[\"64481.2\",\"0.01\",\"0\",\"1\"],[\"64481.1\",\"0\",\"0\",\"0\"],[\"64480.9\",\"0.31\",\"0\",\"1\"],[\"64476.2\",\"1.58\",\"0\",\"3\"],[\"64475.7\",\"0.55\",\"0\",\"3\"],[\"64469\",\"33.81\",\"0\",\"1\"],[\"64468.9\",\"0.3\",\"0\",\"1\"],[\"64467.9\",\"0.01\",\"0\",\"1\"],[\"64467.7\",\"0\",\"0\",\"0\"],[\"64467.6\",\"20.88\",\"0\",\"5\"]],\"ts\":\"1782016056705\",\"checksum\":-1031090886,\"seqId\":325070103955,\"prevSeqId\":325070103823}]}"}
{"action": null, "capture_sequence": 500, "channel": "trades", "connection_sequence": 4, "event": null, "instId": "BTC-USDT-SWAP", "local_receive_ts": "2026-06-21T04:27:36Z", "monotonic_ns": 1643612665590556, "raw": "{\"arg\":{\"channel\":\"trades\",\"instId\":\"BTC-USDT-SWAP\"},\"data\":[{\"instId\":\"BTC-USDT-SWAP\",\"tradeId\":\"2718750433\",\"px\":\"64482.9\",\"sz\":\"0.5\",\"side\":\"sell\",\"ts\":\"1782016056761\",\"count\":\"1\",\"source\":\"0\",\"seqId\":325070104020}]}"}
{"action": "update", "capture_sequence": 501, "channel": "books", "connection_sequence": 4, "event": null, "instId": "BTC-USDT-SWAP", "local_receive_ts": "2026-06-21T04:27:36Z", "monotonic_ns": 1643612709632804, "raw": "{\"arg\":{\"channel\":\"books\",\"instId\":\"BTC-USDT-SWAP\"},\"action\":\"update\",\"data\":[{\"asks\":[[\"64484.9\",\"20.81\",\"0\",\"2\"],[\"64485.4\",\"0.4\",\"0\",\"1\"],[\"64486.5\",\"156.36\",\"0\",\"3\"],[\"64487.5\",\"136.17\",\"0\",\"4\"],[\"64492.9\",\"0.78\",\"0\",\"2\"],[\"64495.4\",\"19.05\",\"0\",\"4\"],[\"64507.1\",\"0.06\",\"0\",\"4\"],[\"64507.7\",\"0.84\",\"0\",\"5\"],[\"64508.3\",\"0\",\"0\",\"0\"],[\"64508.4\",\"35.72\",\"0\",\"7\"],[\"64508.6\",\"0.01\",\"0\",\"1\"],[\"64511.9\",\"0.14\",\"0\",\"1\"],[\"64512.5\",\"86.49\",\"0\",\"7\"],[\"64512.9\",\"17.79\",\"0\",\"4\"],[\"64514.3\",\"58.29\",\"0\",\"6\"],[\"64518\",\"103.04\",\"0\",\"12\"],[\"64518.1\",\"20.21\",\"0\",\"6\"],[\"64519.8\",\"122.39\",\"0\",\"7\"],[\"64527.2\",\"0.18\",\"0\",\"4\"]],\"bids\":[[\"64482.9\",\"727.68\",\"0\",\"33\"],[\"64481.3\",\"0.31\",\"0\",\"1\"],[\"64480.9\",\"0\",\"0\",\"0\"],[\"64473.5\",\"143.01\",\"0\",\"2\"],[\"64471.7\",\"33.81\",\"0\",\"2\"],[\"64471.6\",\"0.03\",\"0\",\"1\"],[\"64468.4\",\"0.77\",\"0\",\"1\"],[\"64467.7\",\"20.08\",\"0\",\"1\"],[\"64467.6\",\"0.03\",\"0\",\"3\"],[\"64467.3\",\"180.92\",\"0\",\"3\"],[\"64466.7\",\"0\",\"0\",\"0\"],[\"64465.9\",\"58.22\",\"0\",\"1\"],[\"64464.8\",\"0.01\",\"0\",\"1\"],[\"64423.8\",\"0\",\"0\",\"0\"],[\"64423.5\",\"0\",\"0\",\"0\"]],\"ts\":\"1782016056805\",\"checksum\":-1901810706,\"seqId\":325070104132,\"prevSeqId\":325070103955}]}"}
{"action": "update", "capture_sequence": 502, "channel": "books", "connection_sequence": 4, "event": null, "instId": "BTC-USDT-SWAP", "local_receive_ts": "2026-06-21T04:27:37Z", "monotonic_ns": 1643612809850752, "raw": "{\"arg\":{\"channel\":\"books\",\"instId\":\"BTC-USDT-SWAP\"},\"action\":\"update\",\"data\":[{\"asks\":[[\"64483\",\"270.13\",\"0\",\"34\"],[\"64493.2\",\"0.08\",\"0\",\"5\"],[\"64494.1\",\"0\",\"0\",\"0\"],[\"64497.3\",\"41.14\",\"0\",\"4\"],[\"64497.4\",\"0.25\",\"0\",\"2\"],[\"64500\",\"3459.24\",\"0\",\"1037\"],[\"64500.4\",\"0.03\",\"0\",\"3\"],[\"64503.6\",\"0.03\",\"0\",\"3\"],[\"64503.9\",\"15.65\",\"0\",\"1\"],[\"64519.8\",\"89.37\",\"0\",\"5\"],[\"64522.9\",\"58.87\",\"0\",\"3\"],[\"64523\",\"0\",\"0\",\"0\"],[\"64527.3\",\"0.05\",\"0\",\"5\"],[\"64527.4\",\"0.27\",\"0\",\"2\"]],\"bids\":[[\"64482.9\",\"724.8\",\"0\",\"32\"],[\"64482.8\",\"6.55\",\"0\",\"12\"],[\"64481.3\",\"0\",\"0\",\"0\"],[\"64481\",\"0.31\",\"0\",\"1\"],[\"64476.2\",\"1.6\",\"0\",\"4\"],[\"64476\",\"0.04\",\"0\",\"2\"],[\"64466.9\",\"0.02\",\"0\",\"1\"],[\"64466.5\",\"0.02\",\"0\",\"1\"],[\"64465.7\",\"0\",\"0\",\"0\"],[\"64439\",\"0.02\",\"0\",\"1\"],[\"64438.1\",\"42.72\",\"0\",\"5\"],[\"64424\",\"0\",\"0\",\"0\"],[\"64423.9\",\"0\",\"0\",\"0\"]],\"ts\":\"1782016056905\",\"checksum\":479488990,\"seqId\":325070104239,\"prevSeqId\":325070104132}]}"}
{"action": "update", "capture_sequence": 503, "channel": "books", "connection_sequence": 4, "event": null, "instId": "BTC-USDT-SWAP", "local_receive_ts": "2026-06-21T04:27:37Z", "monotonic_ns": 1643612909587677, "raw": "{\"arg\":{\"channel\":\"books\",\"instId\":\"BTC-USDT-SWAP\"},\"action\":\"update\",\"data\":[{\"asks\":[[\"64483\",\"271.69\",\"0\",\"35\"],[\"64483.5\",\"1.56\",\"0\",\"1\"],[\"64484\",\"8.63\",\"0\",\"5\"],[\"64484.5\",\"3.43\",\"0\",\"6\"],[\"64485\",\"3.56\",\"0\",\"2\"],[\"64485.4\",\"1.96\",\"0\",\"2\"],[\"64485.9\",\"6.99\",\"0\",\"3\"],[\"64506.5\",\"103.89\",\"0\",\"3\"],[\"64512.4\",\"85.41\",\"0\",\"2\"],[\"64512.5\",\"1.16\",\"0\",\"6\"],[\"64513.7\",\"58.19\",\"0\",\"2\"],[\"64514.3\",\"0.11\",\"0\",\"5\"],[\"64527.4\",\"0\",\"0\",\"0\"]],\"bids\":[[\"64482\",\"109.33\",\"0\",\"5\"],[\"64481\",\"0\",\"0\",\"0\"],[\"64480.9\",\"0.31\",\"0\",\"1\"],[\"64471.7\",\"2.76\",\"0\",\"1\"],[\"64471.6\",\"31.08\",\"0\",\"2\"],[\"64467.3\",\"95.53\",\"0\",\"2\"],[\"64466.7\",\"85.39\",\"0\",\"1\"],[\"64465.9\",\"0\",\"0\",\"0\"],[\"64465.5\",\"58.22\",\"0\",\"1\"],[\"64424.2\",\"0\",\"0\",\"0\"]],\"ts\":\"1782016057005\",\"checksum\":168146638,\"seqId\":325070104334,\"prevSeqId\":325070104239}]}"}
{"action": null, "capture_sequence": 504, "channel": "trades", "connection_sequence": 4, "event": null, "instId": "BTC-USDT-SWAP", "local_receive_ts": "2026-06-21T04:27:37Z", "monotonic_ns": 1643612915043509, "raw": "{\"arg\":{\"channel\":\"trades\",\"instId\":\"BTC-USDT-SWAP\"},\"data\":[{\"instId\":\"BTC-USDT-SWAP\",\"tradeId\":\"2718750434\",\"px\":\"64482.9\",\"sz\":\"0.13\",\"side\":\"sell\",\"ts\":\"1782016057011\",\"count\":\"1\",\"source\":\"0\",\"seqId\":325070104349}]}"}
{"action": "update", "capture_sequence": 505, "channel": "books", "connection_sequence": 4, "event": null, "instId": "BTC-USDT-SWAP", "local_receive_ts": "2026-06-21T04:27:37Z", "monotonic_ns": 1643613009514951, "raw": "{\"arg\":{\"channel\":\"books\",\"instId\":\"BTC-USDT-SWAP\"},\"action\":\"update\",\"data\":[{\"asks\":[[\"64483\",\"270.13\",\"0\",\"34\"],[\"64483.2\",\"1.56\",\"0\",\"1\"],[\"64483.5\",\"0\",\"0\",\"0\"],[\"64483.6\",\"0.01\",\"0\",\"1\"],[\"64483.7\",\"1.57\",\"0\",\"2\"],[\"64484\",\"7.07\",\"0\",\"4\"],[\"64484.3\",\"0.01\",\"0\",\"1\"],[\"64484.4\",\"1.57\",\"0\",\"2\"],[\"64484.5\",\"1.87\",\"0\",\"5\"],[\"64484.8\",\"0.01\",\"0\",\"1\"],[\"64486.4\",\"2.83\",\"0\",\"3\"],[\"64486.9\",\"1.68\",\"0\",\"3\"],[\"64487.4\",\"2.06\",\"0\",\"7\"],[\"64487.8\",\"1.66\",\"0\",\"5\"],[\"64489.1\",\"0.04\",\"0\",\"3\"],[\"64489.6\",\"52.39\",\"0\",\"2\"],[\"64497.3\",\"41.31\",\"0\",\"5\"],[\"64497.4\",\"0.08\",\"0\",\"1\"],[\"64500\",\"3458.68\",\"0\",\"1036\"],[\"64508.4\",\"35.41\",\"0\",\"6\"],[\"64508.8\",\"0.35\",\"0\",\"3\"],[\"64527.2\",\"0\",\"0\",\"0\"],[\"64527.3\",\"0\",\"0\",\"0\"]],\"bids\":[[\"64482.9\",\"729.49\",\"0\",\"33\"],[\"64481.5\",\"1.56\",\"0\",\"1\"],[\"64481.2\",\"0\",\"0\",\"0\"],[\"64480.6\",\"0.01\",\"0\",\"1\"],[\"64476.3\",\"8.31\",\"0\",\"2\"],[\"64476.2\",\"0.04\",\"0\",\"3\"],[\"64475.7\",\"0.24\",\"0\",\"2\"],[\"64471.6\",\"0.03\",\"0\",\"1\"],[\"64471.5\",\"38.81\",\"0\",\"3\"],[\"64424.4\",\"0\",\"0\",\"0\"]],\"ts\":\"1782016057105\",\"checksum\":-2068211171,\"seqId\":325070104497,\"prevSeqId\":325070104334}]}"}
{"action": "update", "capture_sequence": 506, "channel": "books", "connection_sequence": 4, "event": null, "instId": "BTC-USDT-SWAP", "local_receive_ts": "2026-06-21T04:27:37Z", "monotonic_ns": 1643613109439171, "raw": "{\"arg\":{\"channel\":\"books\",\"instId\":\"BTC-USDT-SWAP\"},\"action\":\"update\",\"data\":[{\"asks\":[[\"64483.2\",\"0.01\",\"0\",\"1\"],[\"64483.3\",\"1.6\",\"0\",\"2\"],[\"64483.6\",\"0\",\"0\",\"0\"],[\"64483.7\",\"0.01\",\"0\",\"1\"],[\"64483.8\",\"0.01\",\"0\",\"1\"],[\"64483.9\",\"1.58\",\"0\",\"3\"],[\"64484.3\",\"0\",\"0\",\"0\"],[\"64498.9\",\"3.42\",\"0\",\"2\"],[\"64500.6\",\"62.54\",\"0\",\"4\"],[\"64500.8\",\"15.87\",\"0\",\"2\"],[\"64527.2\",\"0.18\",\"0\",\"4\"]],\"bids\":[[\"64482\",\"107.77\",\"0\",\"4\"],[\"64481.5\",\"0\",\"0\",\"0\"],[\"64476.6\",\"15.52\",\"0\",\"3\"],[\"64471.5\",\"7.76\",\"0\",\"2\"],[\"64471.4\",\"34.06\",\"0\",\"3\"],[\"64466.6\",\"31.09\",\"0\",\"3\"],[\"64466.5\",\"0\",\"0\",\"0\"],[\"64464.1\",\"0.02\",\"0\",\"1\"],[\"64463.7\",\"0\",\"0\",\"0\"],[\"64463\",\"18.97\",\"0\",\"3\"],[\"64460.6\",\"0.03\",\"0\",\"2\"],[\"64459.5\",\"15.65\",\"0\",\"1\"],[\"64424.4\",\"280.36\",\"0\",\"3\"],[\"64424.2\",\"1.21\",\"0\",\"2\"]],\"ts\":\"1782016057205\",\"checksum\":-641928802,\"seqId\":325070104666,\"prevSeqId\":325070104497}]}"}
{"action": "update", "capture_sequence": 507, "channel": "books", "connection_sequence": 4, "event": null, "instId": "BTC-USDT-SWAP", "local_receive_ts": "2026-06-21T04:27:37Z", "monotonic_ns": 1643613209492365, "raw": "{\"arg\":{\"channel\":\"books\",\"instId\":\"BTC-USDT-SWAP\"},\"action\":\"update\",\"data\":[{\"asks\":[[\"64483\",\"280.44\",\"0\",\"36\"],[\"64483.2\",\"0\",\"0\",\"0\"],[\"64483.3\",\"0.04\",\"0\",\"1\"],[\"64483.8\",\"0\",\"0\",\"0\"],[\"64483.9\",\"0.02\",\"0\",\"2\"],[\"64484.3\",\"0.01\",\"0\",\"1\"],[\"64484.4\",\"1.58\",\"0\",\"3\"],[\"64498.9\",\"3.58\",\"0\",\"3\"],[\"64527.3\",\"0.05\",\"0\",\"5\"]],\"bids\":[[\"64481.3\",\"1.56\",\"0\",\"1\"],[\"64471.8\",\"31.05\",\"0\",\"1\"],[\"64471.4\",\"3.01\",\"0\",\"2\"],[\"64463\",\"22.12\",\"0\",\"4\"],[\"64424.4\",\"0\",\"0\",\"0\"],[\"64424.2\",\"0\",\"0\",\"0\"]],\"ts\":\"1782016057305\",\"checksum\":486605003,\"seqId\":325070104754,\"prevSeqId\":325070104666}]}"}
{"action": null, "capture_sequence": 508, "channel": "trades", "connection_sequence": 4, "event": null, "instId": "BTC-USDT-SWAP", "local_receive_ts": "2026-06-21T04:27:37Z", "monotonic_ns": 1643613258650404, "raw": "{\"arg\":{\"channel\":\"trades\",\"instId\":\"BTC-USDT-SWAP\"},\"data\":[{\"instId\":\"BTC-USDT-SWAP\",\"tradeId\":\"2718750435\",\"px\":\"64482.9\",\"sz\":\"7.56\",\"side\":\"sell\",\"ts\":\"1782016057354\",\"count\":\"1\",\"source\":\"0\",\"seqId\":325070104807}]}"}
{"action": null, "capture_sequence": 509, "channel": "trades", "connection_sequence": 4, "event": null, "instId": "BTC-USDT-SWAP", "local_receive_ts": "2026-06-21T04:27:37Z", "monotonic_ns": 1643613293480020, "raw": "{\"arg\":{\"channel\":\"trades\",\"instId\":\"BTC-USDT-SWAP\"},\"data\":[{\"instId\":\"BTC-USDT-SWAP\",\"tradeId\":\"2718750436\",\"px\":\"64482.9\",\"sz\":\"2.95\",\"side\":\"sell\",\"ts\":\"1782016057389\",\"count\":\"1\",\"source\":\"0\",\"seqId\":325070104930}]}"}
{"action": "update", "capture_sequence": 510, "channel": "books", "connection_sequence": 4, "event": null, "instId": "BTC-USDT-SWAP", "local_receive_ts": "2026-06-21T04:27:37Z", "monotonic_ns": 1643613317229608, "raw": "{\"arg\":{\"channel\":\"books\",\"instId\":\"BTC-USDT-SWAP\"},\"action\":\"update\",\"data\":[{\"asks\":[[\"64483\",\"270.44\",\"0\",\"35\"],[\"64484.9\",\"60.64\",\"0\",\"3\"],[\"64485.9\",\"143.12\",\"0\",\"4\"],[\"64487.5\",\"0.04\",\"0\",\"3\"],[\"64488.9\",\"0.33\",\"0\",\"6\"],[\"64489.5\",\"0.02\",\"0\",\"2\"],[\"64489.6\",\"63.74\",\"0\",\"3\"],[\"64489.9\",\"37.23\",\"0\",\"1\"],[\"64490.2\",\"0\",\"0\",\"0\"],[\"64490.5\",\"1.81\",\"0\",\"3\"],[\"64490.8\",\"30.53\",\"0\",\"2\"],[\"64491.3\",\"0.01\",\"0\",\"1\"],[\"64491.7\",\"0.02\",\"0\",\"2\"],[\"64492\",\"0.04\",\"0\",\"4\"],[\"64492.1\",\"0\",\"0\",\"0\"],[\"64492.9\",\"0.01\",\"0\",\"1\"],[\"64493\",\"20.67\",\"0\",\"7\"],[\"64493.2\",\"0.07\",\"0\",\"4\"],[\"64494.1\",\"0.01\",\"0\",\"1\"],[\"64495.4\",\"19.15\",\"0\",\"4\"],[\"64497.2\",\"1.01\",\"0\",\"4\"],[\"64497.3\",\"41.14\",\"0\",\"4\"],[\"64500.8\",\"0.36\",\"0\",\"1\"],[\"64501.4\",\"15.52\",\"0\",\"2\"],[\"64502.9\",\"391.16\",\"0\",\"6\"],[\"64503.4\",\"31.03\",\"0\",\"1\"],[\"64503.6\",\"0.02\",\"0\",\"2\"],[\"64503.8\",\"0\",\"0\",\"0\"],[\"64503.9\",\"15.66\",\"0\",\"2\"],[\"64504.4\",\"233.89\",\"0\",\"5\"],[\"64505.4\",\"60.78\",\"0\",\"5\"],[\"64505.5\",\"73.81\",\"0\",\"3\"],[\"64507.1\",\"0.83\",\"0\",\"5\"],[\"64507.7\",\"0.07\",\"0\",\"4\"],[\"64512.5\",\"0.16\",\"0\",\"5\"],[\"64512.9\",\"75.97\",\"0\",\"5\"],[\"64513.2\",\"0.15\",\"0\",\"4\"],[\"64513.5\",\"0.6\",\"0\",\"3\"],[\"64513.7\",\"0.01\",\"0\",\"1\"],[\"64513.8\",\"0.01\",\"0\",\"1\"],[\"64514.1\",\"0.03\",\"0\",\"3\"],[\"64514.4\",\"15.7\",\"0\",\"4\"],[\"64514.9\",\"496.61\",\"0\",\"4\"],[\"64515.3\",\"0.01\",\"0\",\"1\"],[\"64515.6\",\"0.09\",\"0\",\"4\"],[\"64515.7\",\"60.35\",\"0\",\"3\"],[\"64522.9\",\"58.86\",\"0\",\"2\"],[\"64523\",\"0.01\",\"0\",\"1\"]],\"bids\":[[\"64482.9\",\"707.63\",\"0\",\"32\"],[\"64481.3\",\"0\",\"0\",\"0\"],[\"64480.6\",\"0\",\"0\",\"0\"],[\"64480.5\",\"0\",\"0\",\"0\"],[\"64480\",\"0.04\",\"0\",\"4\"],[\"64479.6\",\"11.44\",\"0\",\"3\"],[\"64479.2\",\"0.01\",\"0\",\"1\"],[\"64479.1\",\"0\",\"0\",\"0\"],[\"64478.4\",\"77.54\",\"0\",\"1\"],[\"64476.5\",\"0.02\",\"0\",\"1\"],[\"64476.2\",\"0.02\",\"0\",\"2\"],[\"64473.8\",\"12.43\",\"0\",\"3\"],[\"64473.2\",\"11.41\",\"0\",\"2\"],[\"64472.9\",\"0\",\"0\",\"0\"],[\"64472.5\",\"3.1\",\"0\",\"1\"],[\"64472.2\",\"0\",\"0\",\"0\"],[\"64471.9\",\"0\",\"0\",\"0\"],[\"64471.8\",\"0\",\"0\",\"0\"],[\"64471.7\",\"31.05\",\"0\",\"1\"],[\"64471.4\",\"0.01\",\"0\",\"1\"],[\"64471.1\",\"148.91\",\"0\",\"1\"],[\"64470.6\",\"0\",\"0\",\"0\"],[\"64468.4\",\"0\",\"0\",\"0\"],[\"64467.8\",\"1.33\",\"0\",\"3\"],[\"64466.9\",\"0\",\"0\",\"0\"],[\"64466.6\",\"31.11\",\"0\",\"4\"],[\"64465.8\",\"0\",\"0\",\"0\"],[\"64465.7\",\"31.05\",\"0\",\"1\"],[\"64465.5\",\"0\",\"0\",\"0\"],[\"64465.1\",\"232.9\",\"0\",\"1\"],[\"64464.8\",\"58.23\",\"0\",\"2\"],[\"64464.5\",\"0.02\",\"0\",\"2\"],[\"64426.3\",\"0\",\"0\",\"0\"],[\"64425.7\",\"2.01\",\"0\",\"1\"],[\"64425.3\",\"2\",\"0\",\"1\"],[\"64425\",\"1.87\",\"0\",\"7\"],[\"64424.7\",\"0\",\"0\",\"0\"],[\"64424.4\",\"279.16\",\"0\",\"2\"],[\"64424.2\",\"0.01\",\"0\",\"1\"],[\"64424\",\"1.36\",\"0\",\"4\"],[\"64423.9\",\"0.05\",\"0\",\"1\"],[\"64423.8\",\"60.49\",\"0\",\"2\"],[\"64423.5\",\"380.4\",\"0\",\"1\"],[\"64423.3\",\"512.29\",\"0\",\"3\"],[\"64423.2\",\"37.23\",\"0\",\"1\"],[\"64423.1\",\"92.81\",\"0\",\"2\"],[\"64423\",\"1.59\",\"0\",\"6\"],[\"64422.8\",\"0.01\",\"0\",\"1\"]],\"ts\":\"1782016057405\",\"checksum\":521755179,\"seqId\":325070104963,\"prevSeqId\":325070104754}]}"}
{"action": null, "capture_sequence": 511, "channel": "trades", "connection_sequence": 4, "event": null, "instId": "BTC-USDT-SWAP", "local_receive_ts": "2026-06-21T04:27:37Z", "monotonic_ns": 1643613394740470, "raw": "{\"arg\":{\"channel\":\"trades\",\"instId\":\"BTC-USDT-SWAP\"},\"data\":[{\"instId\":\"BTC-USDT-SWAP\",\"tradeId\":\"2718750437\",\"px\":\"64483\",\"sz\":\"1.12\",\"side\":\"buy\",\"ts\":\"1782016057491\",\"count\":\"1\",\"source\":\"0\",\"seqId\":325070105049}]}"}
{"action": "update", "capture_sequence": 512, "channel": "books", "connection_sequence": 4, "event": null, "instId": "BTC-USDT-SWAP", "local_receive_ts": "2026-06-21T04:27:37Z", "monotonic_ns": 1643613409835026, "raw": "{\"arg\":{\"channel\":\"books\",\"instId\":\"BTC-USDT-SWAP\"},\"action\":\"update\",\"data\":[{\"asks\":[[\"64483\",\"269.32\",\"0\",\"35\"],[\"64484.3\",\"0\",\"0\",\"0\"],[\"64484.4\",\"0.02\",\"0\",\"2\"],[\"64484.8\",\"0.02\",\"0\",\"2\"],[\"64489.5\",\"1.02\",\"0\",\"3\"],[\"64490.2\",\"1.2\",\"0\",\"1\"],[\"64490.5\",\"3.01\",\"0\",\"4\"],[\"64491.3\",\"1.21\",\"0\",\"2\"],[\"64491.9\",\"1.5\",\"0\",\"5\"],[\"64500.8\",\"15.87\",\"0\",\"2\"],[\"64501.4\",\"0.01\",\"0\",\"1\"],[\"64513.1\",\"2.56\",\"0\",\"3\"],[\"64513.8\",\"1.21\",\"0\",\"2\"],[\"64514.1\",\"1.23\",\"0\",\"4\"],[\"64514.9\",\"497.81\",\"0\",\"5\"],[\"64515.5\",\"76.66\",\"0\",\"8\"]],\"bids\":[[\"64482.9\",\"707.38\",\"0\",\"32\"],[\"64480\",\"0.05\",\"0\",\"5\"],[\"64479.2\",\"0\",\"0\",\"0\"],[\"64473.3\",\"1.91\",\"0\",\"2\"],[\"64472.7\",\"1.7\",\"0\",\"3\"],[\"64472.4\",\"9.92\",\"0\",\"2\"],[\"64471.8\",\"2.76\",\"0\",\"1\"],[\"64471.2\",\"53.32\",\"0\",\"3\"],[\"64466.6\",\"31.09\",\"0\",\"3\"],[\"64465.6\",\"74.77\",\"0\",\"6\"],[\"64464.1\",\"0\",\"0\",\"0\"],[\"64463.7\",\"0.02\",\"0\",\"1\"],[\"64460.6\",\"0.01\",\"0\",\"1\"],[\"64459.5\",\"15.67\",\"0\",\"2\"],[\"64426.1\",\"20.87\",\"0\",\"3\"],[\"64425.5\",\"12.26\",\"0\",\"2\"],[\"64425.1\",\"1.2\",\"0\",\"1\"],[\"64424.6\",\"1.21\",\"0\",\"2\"],[\"64424\",\"2.56\",\"0\",\"5\"],[\"64422.8\",\"0\",\"0\",\"0\"]],\"ts\":\"1782016057505\",\"checksum\":-684855972,\"seqId\":325070105073,\"prevSeqId\":325070104963}]}"}
{"action": null, "capture_sequence": 513, "channel": "trades", "connection_sequence": 4, "event": null, "instId": "BTC-USDT-SWAP", "local_receive_ts": "2026-06-21T04:27:37Z", "monotonic_ns": 1643613441479640, "raw": "{\"arg\":{\"channel\":\"trades\",\"instId\":\"BTC-USDT-SWAP\"},\"data\":[{\"instId\":\"BTC-USDT-SWAP\",\"tradeId\":\"2718750438\",\"px\":\"64483\",\"sz\":\"0.02\",\"side\":\"buy\",\"ts\":\"1782016057537\",\"count\":\"1\",\"source\":\"0\",\"seqId\":325070105102}]}"}
{"action": "update", "capture_sequence": 514, "channel": "books", "connection_sequence": 4, "event": null, "instId": "BTC-USDT-SWAP", "local_receive_ts": "2026-06-21T04:27:37Z", "monotonic_ns": 1643613516460690, "raw": "{\"arg\":{\"channel\":\"books\",\"instId\":\"BTC-USDT-SWAP\"},\"action\":\"update\",\"data\":[{\"asks\":[[\"64483\",\"466.45\",\"0\",\"39\"],[\"64488.9\",\"1.33\",\"0\",\"7\"],[\"64489.9\",\"38.23\",\"0\",\"2\"],[\"64490.8\",\"31.73\",\"0\",\"3\"],[\"64491.7\",\"1.22\",\"0\",\"3\"],[\"64492.1\",\"1.5\",\"0\",\"1\"],[\"64493\",\"1.3\",\"0\",\"3\"],[\"64494.4\",\"19.2\",\"0\",\"9\"],[\"64495.4\",\"19.92\",\"0\",\"5\"],[\"64497.2\",\"0.84\",\"0\",\"3\"],[\"64497.3\",\"41.31\",\"0\",\"5\"],[\"64499.2\",\"4.9\",\"0\",\"3\"],[\"64500.2\",\"15.53\",\"0\",\"3\"],[\"64500.8\",\"0.36\",\"0\",\"1\"],[\"64503.8\",\"232.77\",\"0\",\"1\"],[\"64504.4\",\"1.13\",\"0\",\"4\"],[\"64508.6\",\"0.32\",\"0\",\"2\"],[\"64508.8\",\"0.04\",\"0\",\"2\"],[\"64511.9\",\"85.47\",\"0\",\"2\"],[\"64512.4\",\"0.08\",\"0\",\"1\"],[\"64512.5\",\"1.16\",\"0\",\"6\"],[\"64513.5\",\"1.6\",\"0\",\"4\"],[\"64514.4\",\"16.9\",\"0\",\"5\"],[\"64515.3\",\"1.21\",\"0\",\"2\"],[\"64515.7\",\"61.85\",\"0\",\"4\"],[\"64527.2\",\"0\",\"0\",\"0\"],[\"64527.3\",\"0\",\"0\",\"0\"]],\"bids\":[[\"64482.9\",\"638.86\",\"0\",\"31\"],[\"64480.9\",\"0\",\"0\",\"0\"],[\"64480.1\",\"0.31\",\"0\",\"1\"],[\"64479.9\",\"46.68\",\"0\",\"4\"],[\"64476.3\",\"8\",\"0\",\"1\"],[\"64475.7\",\"0.31\",\"0\",\"1\"],[\"64474\",\"1.61\",\"0\",\"2\"],[\"64473\",\"13.6\",\"0\",\"3\"],[\"64472\",\"2.18\",\"0\",\"3\"],[\"64471.7\",\"0\",\"0\",\"0\"],[\"64471.6\",\"3.03\",\"0\",\"2\"],[\"64471.4\",\"0.78\",\"0\",\"2\"],[\"64471.3\",\"47.8\",\"0\",\"3\"],[\"64470.8\",\"49.3\",\"0\",\"2\"],[\"64470.5\",\"5.02\",\"0\",\"4\"],[\"64470\",\"102.92\",\"0\",\"6\"],[\"64466.7\",\"0\",\"0\",\"0\"],[\"64465.8\",\"85.39\",\"0\",\"1\"],[\"64465.1\",\"0\",\"0\",\"0\"],[\"64464.7\",\"0\",\"0\",\"0\"],[\"64464.4\",\"232.92\",\"0\",\"2\"],[\"64450.7\",\"3.92\",\"0\",\"3\"],[\"64426.8\",\"1.06\",\"0\",\"2\"],[\"64425.8\",\"1\",\"0\",\"1\"],[\"64424.8\",\"1.2\",\"0\",\"1\"],[\"64424.4\",\"280.36\",\"0\",\"3\"],[\"64423.5\",\"381.9\",\"0\",\"2\"],[\"64422.8\",\"0.01\",\"0\",\"1\"]],\"ts\":\"1782016057605\",\"checksum\":-141468197,\"seqId\":325070105225,\"prevSeqId\":325070105073}]}"}
{"action": null, "capture_sequence": 515, "channel": "trades", "connection_sequence": 4, "event": null, "instId": "BTC-USDT-SWAP", "local_receive_ts": "2026-06-21T04:27:37Z", "monotonic_ns": 1643613592475675, "raw": "{\"arg\":{\"channel\":\"trades\",\"instId\":\"BTC-USDT-SWAP\"},\"data\":[{\"instId\":\"BTC-USDT-SWAP\",\"tradeId\":\"2718750439\",\"px\":\"64482.9\",\"sz\":\"0.1\",\"side\":\"sell\",\"ts\":\"1782016057688\",\"count\":\"1\",\"source\":\"0\",\"seqId\":325070105303}]}"}
{"action": "update", "capture_sequence": 516, "channel": "books", "connection_sequence": 4, "event": null, "instId": "BTC-USDT-SWAP", "local_receive_ts": "2026-06-21T04:27:37Z", "monotonic_ns": 1643613609821737, "raw": "{\"arg\":{\"channel\":\"books\",\"instId\":\"BTC-USDT-SWAP\"},\"action\":\"update\",\"data\":[{\"asks\":[[\"64483\",\"456.45\",\"0\",\"38\"],[\"64483.1\",\"14.09\",\"0\",\"7\"],[\"64483.2\",\"1.8\",\"0\",\"1\"],[\"64484.1\",\"0.4\",\"0\",\"1\"],[\"64484.4\",\"0\",\"0\",\"0\"],[\"64484.5\",\"0.07\",\"0\",\"4\"],[\"64485\",\"2\",\"0\",\"1\"],[\"64485.2\",\"0.03\",\"0\",\"3\"],[\"64485.4\",\"0\",\"0\",\"0\"],[\"64485.9\",\"141.56\",\"0\",\"3\"],[\"64486.4\",\"1.27\",\"0\",\"2\"],[\"64486.9\",\"0.12\",\"0\",\"2\"],[\"64487.4\",\"0.5\",\"0\",\"6\"],[\"64487.8\",\"0.1\",\"0\",\"4\"],[\"64491.5\",\"0.11\",\"0\",\"2\"],[\"64494.1\",\"0\",\"0\",\"0\"],[\"64500.2\",\"0.02\",\"0\",\"2\"],[\"64500.5\",\"18\",\"0\",\"3\"],[\"64503\",\"15.96\",\"0\",\"4\"],[\"64503.9\",\"15.65\",\"0\",\"1\"],[\"64522.8\",\"15.72\",\"0\",\"5\"],[\"64523\",\"0\",\"0\",\"0\"],[\"64527.2\",\"0.18\",\"0\",\"4\"],[\"64527.3\",\"0.05\",\"0\",\"5\"]],\"bids\":[[\"64482.9\",\"638.76\",\"0\",\"31\"],[\"64480.8\",\"0.32\",\"0\",\"2\"],[\"64480.1\",\"0\",\"0\",\"0\"],[\"64476.5\",\"0\",\"0\",\"0\"],[\"64475.5\",\"0.02\",\"0\",\"1\"],[\"64466.6\",\"31.07\",\"0\",\"2\"],[\"64465.5\",\"0.02\",\"0\",\"1\"],[\"64464.7\",\"1\",\"0\",\"1\"],[\"64454.9\",\"12.86\",\"0\",\"1\"],[\"64454.5\",\"0.03\",\"0\",\"2\"],[\"64439\",\"0\",\"0\",\"0\"],[\"64438.1\",\"42.74\",\"0\",\"6\"]],\"ts\":\"1782016057705\",\"checksum\":-310189611,\"seqId\":325070105308,\"prevSeqId\":325070105225}]}"}
{"action": "update", "capture_sequence": 517, "channel": "books", "connection_sequence": 4, "event": null, "instId": "BTC-USDT-SWAP", "local_receive_ts": "2026-06-21T04:27:37Z", "monotonic_ns": 1643613709365547, "raw": "{\"arg\":{\"channel\":\"books\",\"instId\":\"BTC-USDT-SWAP\"},\"action\":\"update\",\"data\":[{\"asks\":[[\"64483\",\"456.55\",\"0\",\"39\"],[\"64491.5\",\"0.1\",\"0\",\"1\"],[\"64492.3\",\"0.04\",\"0\",\"2\"],[\"64495.9\",\"1.13\",\"0\",\"5\"],[\"64497.3\",\"41.14\",\"0\",\"4\"],[\"64505.3\",\"2.71\",\"0\",\"3\"],[\"64505.4\",\"59.23\",\"0\",\"4\"]],\"bids\":[[\"64478.6\",\"83.76\",\"0\",\"2\"],[\"64478.4\",\"0\",\"0\",\"0\"],[\"64478.3\",\"0.01\",\"0\",\"1\"],[\"64476.9\",\"16.43\",\"0\",\"4\"],[\"64473.8\",\"0.02\",\"0\",\"2\"]],\"ts\":\"1782016057805\",\"checksum\":-160683407,\"seqId\":325070105334,\"prevSeqId\":325070105308}]}"}
{"action": "update", "capture_sequence": 518, "channel": "books", "connection_sequence": 4, "event": null, "instId": "BTC-USDT-SWAP", "local_receive_ts": "2026-06-21T04:27:38Z", "monotonic_ns": 1643613809461550, "raw": "{\"arg\":{\"channel\":\"books\",\"instId\":\"BTC-USDT-SWAP\"},\"action\":\"update\",\"data\":[{\"asks\":[[\"64483\",\"332.94\",\"0\",\"37\"],[\"64483.1\",\"14.1\",\"0\",\"8\"],[\"64492.3\",\"0.03\",\"0\",\"1\"],[\"64493\",\"2.07\",\"0\",\"4\"],[\"64493.2\",\"0.08\",\"0\",\"5\"],[\"64494.6\",\"5.05\",\"0\",\"5\"],[\"64495.4\",\"19.15\",\"0\",\"4\"],[\"64500.5\",\"2.49\",\"0\",\"2\"],[\"64501.4\",\"15.52\",\"0\",\"2\"],[\"64505.3\",\"1.16\",\"0\",\"2\"],[\"64505.6\",\"59.46\",\"0\",\"5\"]],\"bids\":[[\"64482.9\",\"714.62\",\"0\",\"32\"],[\"64482.8\",\"3.95\",\"0\",\"11\"],[\"64480.9\",\"0.31\",\"0\",\"1\"],[\"64480.8\",\"0.01\",\"0\",\"1\"],[\"64478.7\",\"77.54\",\"0\",\"1\"],[\"64478.6\",\"6.22\",\"0\",\"1\"],[\"64476.2\",\"0.04\",\"0\",\"3\"],[\"64475.5\",\"0\",\"0\",\"0\"],[\"64471.7\",\"31.05\",\"0\",\"1\"],[\"64471.3\",\"16.75\",\"0\",\"2\"],[\"64465.7\",\"31.07\",\"0\",\"2\"],[\"64465.5\",\"0\",\"0\",\"0\"],[\"64454.9\",\"12.88\",\"0\",\"2\"],[\"64454.5\",\"0.01\",\"0\",\"1\"],[\"64449\",\"0.03\",\"0\",\"3\"],[\"64446.7\",\"208.6\",\"0\",\"3\"],[\"64439\",\"0.02\",\"0\",\"1\"],[\"64438.1\",\"42.72\",\"0\",\"5\"],[\"64423\",\"0\",\"0\",\"0\"],[\"64422.8\",\"0\",\"0\",\"0\"]],\"ts\":\"1782016057905\",\"checksum\":-725159594,\"seqId\":325070105386,\"prevSeqId\":325070105334}]}"}
{"action": "update", "capture_sequence": 519, "channel": "books", "connection_sequence": 4, "event": null, "instId": "BTC-USDT-SWAP", "local_receive_ts": "2026-06-21T04:27:38Z", "monotonic_ns": 1643613910301204, "raw": "{\"arg\":{\"channel\":\"books\",\"instId\":\"BTC-USDT-SWAP\"},\"action\":\"update\",\"data\":[{\"asks\":[[\"64483\",\"334.5\",\"0\",\"38\"],[\"64483.5\",\"1.56\",\"0\",\"1\"],[\"64484\",\"8.63\",\"0\",\"5\"],[\"64484.5\",\"1.63\",\"0\",\"5\"],[\"64485\",\"3.56\",\"0\",\"2\"],[\"64485.4\",\"1.56\",\"0\",\"1\"],[\"64485.9\",\"143.12\",\"0\",\"4\"],[\"64486.4\",\"2.83\",\"0\",\"3\"],[\"64493\",\"1.3\",\"0\",\"3\"],[\"64495.4\",\"19.92\",\"0\",\"5\"],[\"64495.9\",\"0.96\",\"0\",\"4\"],[\"64496.4\",\"0.19\",\"0\",\"3\"],[\"64500.8\",\"15.87\",\"0\",\"2\"],[\"64501.4\",\"0.01\",\"0\",\"1\"],[\"64503.8\",\"0\",\"0\",\"0\"],[\"64503.9\",\"248.42\",\"0\",\"2\"],[\"64505.5\",\"75.36\",\"0\",\"4\"],[\"64505.6\",\"57.91\",\"0\",\"4\"],[\"64508\",\"48.34\",\"0\",\"10\"],[\"64508.4\",\"1.62\",\"0\",\"5\"],[\"64511.9\",\"0.14\",\"0\",\"1\"],[\"64512.2\",\"96.56\",\"0\",\"4\"],[\"64512.9\",\"17.79\",\"0\",\"4\"],[\"64513\",\"68.55\",\"0\",\"4\"],[\"64527.3\",\"0\",\"0\",\"0\"]],\"bids\":[[\"64480.5\",\"1.56\",\"0\",\"1\"],[\"64480\",\"1.61\",\"0\",\"6\"],[\"64479.5\",\"1.56\",\"0\",\"1\"],[\"64479.1\",\"1.56\",\"0\",\"1\"],[\"64478.6\",\"7.78\",\"0\",\"2\"],[\"64471.7\",\"0\",\"0\",\"0\"],[\"64471.6\",\"34.08\",\"0\",\"3\"],[\"64471.4\",\"0.01\",\"0\",\"1\"],[\"64471.3\",\"17.52\",\"0\",\"3\"],[\"64470.5\",\"91.18\",\"0\",\"5\"],[\"64470\",\"16.76\",\"0\",\"5\"],[\"64466.7\",\"85.39\",\"0\",\"1\"],[\"64465.8\",\"0\",\"0\",\"0\"],[\"64465.1\",\"291.12\",\"0\",\"2\"],[\"64464.8\",\"0.01\",\"0\",\"1\"],[\"64464.4\",\"0.01\",\"0\",\"1\"],[\"64423.3\",\"0\",\"0\",\"0\"],[\"64423.2\",\"0\",\"0\",\"0\"],[\"64423.1\",\"0\",\"0\",\"0\"]],\"ts\":\"1782016058005\",\"checksum\":-1012301871,\"seqId\":325070105438,\"prevSeqId\":325070105386}]}"}
{"action": null, "capture_sequence": 520, "channel": "trades", "connection_sequence": 4, "event": null, "instId": "BTC-USDT-SWAP", "local_receive_ts": "2026-06-21T04:27:38Z", "monotonic_ns": 1643613934500807, "raw": "{\"arg\":{\"channel\":\"trades\",\"instId\":\"BTC-USDT-SWAP\"},\"data\":[{\"instId\":\"BTC-USDT-SWAP\",\"tradeId\":\"2718750444\",\"px\":\"64482.9\",\"sz\":\"34.81\",\"side\":\"sell\",\"ts\":\"1782016058030\",\"count\":\"5\",\"source\":\"0\",\"seqId\":325070105497}]}"}
{"action": "update", "capture_sequence": 521, "channel": "books", "connection_sequence": 4, "event": null, "instId": "BTC-USDT-SWAP", "local_receive_ts": "2026-06-21T04:27:38Z", "monotonic_ns": 1643614017215738, "raw": "{\"arg\":{\"channel\":\"books\",\"instId\":\"BTC-USDT-SWAP\"},\"action\":\"update\",\"data\":[{\"asks\":[[\"64483\",\"453.75\",\"0\",\"40\"],[\"64483.4\",\"0.01\",\"0\",\"1\"],[\"64484.8\",\"0.01\",\"0\",\"1\"],[\"64492.5\",\"22.05\",\"0\",\"4\"],[\"64500.2\",\"15.53\",\"0\",\"3\"],[\"64500.8\",\"0.36\",\"0\",\"1\"],[\"64502.2\",\"114.94\",\"0\",\"7\"],[\"64503.4\",\"232.77\",\"0\",\"1\"],[\"64503.9\",\"15.65\",\"0\",\"1\"],[\"64504.9\",\"1.65\",\"0\",\"4\"],[\"64505.5\",\"73.81\",\"0\",\"3\"],[\"64506.7\",\"0.96\",\"0\",\"16\"],[\"64507.1\",\"0.06\",\"0\",\"4\"],[\"64507.8\",\"67.92\",\"0\",\"6\"],[\"64508\",\"14.55\",\"0\",\"9\"],[\"64511.9\",\"85.47\",\"0\",\"2\"],[\"64512.2\",\"11.23\",\"0\",\"3\"],[\"64512.6\",\"116.92\",\"0\",\"8\"],[\"64513\",\"10.37\",\"0\",\"3\"],[\"64517.8\",\"20.16\",\"0\",\"4\"],[\"64518.1\",\"0.15\",\"0\",\"5\"],[\"64527.2\",\"0\",\"0\",\"0\"]],\"bids\":[[\"64482.9\",\"603.95\",\"0\",\"27\"],[\"64480.9\",\"0\",\"0\",\"0\"],[\"64480.5\",\"0\",\"0\",\"0\"],[\"64480.1\",\"0.31\",\"0\",\"1\"],[\"64480\",\"0.05\",\"0\",\"5\"],[\"64479.5\",\"0\",\"0\",\"0\"],[\"64479.1\",\"0\",\"0\",\"0\"],[\"64478.1\",\"1.56\",\"0\",\"1\"],[\"64477.7\",\"46.56\",\"0\",\"3\"],[\"64477.6\",\"1.57\",\"0\",\"2\"],[\"64476.2\",\"0.02\",\"0\",\"2\"],[\"64476.1\",\"67.44\",\"0\",\"2\"],[\"64476\",\"0.06\",\"0\",\"3\"],[\"64475.6\",\"48.1\",\"0\",\"2\"],[\"64475.1\",\"139.71\",\"0\",\"6\"],[\"64474.7\",\"1.57\",\"0\",\"2\"],[\"64471.6\",\"3.03\",\"0\",\"2\"],[\"64471.4\",\"31.06\",\"0\",\"2\"],[\"64470.5\",\"5.02\",\"0\",\"4\"],[\"64470.4\",\"507.57\",\"0\",\"3\"],[\"64467.8\",\"0.56\",\"0\",\"2\"],[\"64467.7\",\"0.77\",\"0\",\"1\"],[\"64467.4\",\"20.08\",\"0\",\"1\"],[\"64466.7\",\"0\",\"0\",\"0\"],[\"64466.5\",\"0.04\",\"0\",\"2\"],[\"64465.8\",\"85.39\",\"0\",\"1\"],[\"64465.7\",\"0\",\"0\",\"0\"],[\"64465.6\",\"74.75\",\"0\",\"5\"],[\"64465.1\",\"31.05\",\"0\",\"1\"],[\"64464.4\",\"291.14\",\"0\",\"3\"],[\"64464.1\",\"0.02\",\"0\",\"1\"],[\"64463.7\",\"0\",\"0\",\"0\"],[\"64439\",\"0\",\"0\",\"0\"],[\"64438.8\",\"4.15\",\"0\",\"2\"],[\"64423.3\",\"512.29\",\"0\",\"3\"],[\"64423.2\",\"37.23\",\"0\",\"1\"]],\"ts\":\"1782016058105\",\"checksum\":-1107976288,\"seqId\":325070105626,\"prevSeqId\":325070105438}]}"}
{"action": "update", "capture_sequence": 522, "channel": "books", "connection_sequence": 4, "event": null, "instId": "BTC-USDT-SWAP", "local_receive_ts": "2026-06-21T04:27:38Z", "monotonic_ns": 1643614109569573, "raw": "{\"arg\":{\"channel\":\"books\",\"instId\":\"BTC-USDT-SWAP\"},\"action\":\"update\",\"data\":[{\"asks\":[[\"64491.5\",\"0.11\",\"0\",\"2\"],[\"64493.2\",\"0.07\",\"0\",\"4\"],[\"64495.9\",\"1.13\",\"0\",\"5\"],[\"64496.4\",\"0.02\",\"0\",\"2\"],[\"64502.2\",\"83.91\",\"0\",\"6\"],[\"64502.4\",\"31.22\",\"0\",\"7\"],[\"64507.7\",\"33.86\",\"0\",\"5\"],[\"64507.8\",\"34.13\",\"0\",\"5\"],[\"64508.3\",\"0.31\",\"0\",\"1\"],[\"64508.6\",\"0.01\",\"0\",\"1\"],[\"64517.8\",\"0.1\",\"0\",\"3\"],[\"64518\",\"123.1\",\"0\",\"13\"],[\"64527.1\",\"0\",\"0\",\"0\"]],\"bids\":[[\"64480.8\",\"0.32\",\"0\",\"2\"],[\"64480.1\",\"0\",\"0\",\"0\"],[\"64476\",\"0.04\",\"0\",\"2\"],[\"64475.5\",\"0.02\",\"0\",\"1\"],[\"64469\",\"0\",\"0\",\"0\"],[\"64468.9\",\"34.11\",\"0\",\"2\"],[\"64467.7\",\"0\",\"0\",\"0\"],[\"64467.6\",\"20.88\",\"0\",\"5\"],[\"64467.4\",\"0\",\"0\",\"0\"],[\"64466.7\",\"85.39\",\"0\",\"1\"],[\"64466.5\",\"0\",\"0\",\"0\"],[\"64465.8\",\"0\",\"0\",\"0\"],[\"64465.5\",\"31.09\",\"0\",\"3\"],[\"64465.1\",\"0\",\"0\",\"0\"],[\"64464.1\",\"0\",\"0\",\"0\"],[\"64463.7\",\"0.02\",\"0\",\"1\"],[\"64454.9\",\"12.86\",\"0\",\"1\"],[\"64454.5\",\"0.03\",\"0\",\"2\"],[\"64438.8\",\"4.13\",\"0\",\"1\"],[\"64438.1\",\"42.74\",\"0\",\"6\"],[\"64423.1\",\"92.81\",\"0\",\"2\"],[\"64423\",\"1.59\",\"0\",\"6\"],[\"64422.8\",\"0.01\",\"0\",\"1\"],[\"64422.7\",\"3.4\",\"0\",\"3\"]],\"ts\":\"1782016058205\",\"checksum\":-1657397611,\"seqId\":325070105688,\"prevSeqId\":325070105626}]}"}
{"action": null, "capture_sequence": 523, "channel": "trades", "connection_sequence": 4, "event": null, "instId": "BTC-USDT-SWAP", "local_receive_ts": "2026-06-21T04:27:38Z", "monotonic_ns": 1643614120371660, "raw": "{\"arg\":{\"channel\":\"trades\",\"instId\":\"BTC-USDT-SWAP\"},\"data\":[{\"instId\":\"BTC-USDT-SWAP\",\"tradeId\":\"2718750445\",\"px\":\"64482.9\",\"sz\":\"0.18\",\"side\":\"sell\",\"ts\":\"1782016058216\",\"count\":\"1\",\"source\":\"0\",\"seqId\":325070105696}]}"}
{"action": "update", "capture_sequence": 524, "channel": "books", "connection_sequence": 4, "event": null, "instId": "BTC-USDT-SWAP", "local_receive_ts": "2026-06-21T04:27:38Z", "monotonic_ns": 1643614214666671, "raw": "{\"arg\":{\"channel\":\"books\",\"instId\":\"BTC-USDT-SWAP\"},\"action\":\"update\",\"data\":[{\"asks\":[[\"64483\",\"455.75\",\"0\",\"41\"],[\"64503.4\",\"0\",\"0\",\"0\"],[\"64503.8\",\"232.77\",\"0\",\"1\"],[\"64511.9\",\"0.14\",\"0\",\"1\"],[\"64512.1\",\"122.57\",\"0\",\"5\"]],\"bids\":[[\"64482.9\",\"653.77\",\"0\",\"28\"],[\"64480.9\",\"0.31\",\"0\",\"1\"],[\"64480.8\",\"0.01\",\"0\",\"1\"],[\"64478.6\",\"6.22\",\"0\",\"1\"],[\"64478.1\",\"0\",\"0\",\"0\"],[\"64478\",\"1.57\",\"0\",\"2\"],[\"64476\",\"0.06\",\"0\",\"3\"],[\"64475.5\",\"0\",\"0\",\"0\"],[\"64474.2\",\"1.56\",\"0\",\"1\"],[\"64471.4\",\"0.01\",\"0\",\"1\"],[\"64471.3\",\"48.57\",\"0\",\"4\"],[\"64464.5\",\"232.93\",\"0\",\"3\"],[\"64464.4\",\"58.23\",\"0\",\"2\"],[\"64454.8\",\"10.02\",\"0\",\"2\"],[\"64454.5\",\"0.01\",\"0\",\"1\"]],\"ts\":\"1782016058305\",\"checksum\":1951131503,\"seqId\":325070105781,\"prevSeqId\":325070105688}]}"}
{"action": "update", "capture_sequence": 525, "channel": "books", "connection_sequence": 4, "event": null, "instId": "BTC-USDT-SWAP", "local_receive_ts": "2026-06-21T04:27:38Z", "monotonic_ns": 1643614309884312, "raw": "{\"arg\":{\"channel\":\"books\",\"instId\":\"BTC-USDT-SWAP\"},\"action\":\"update\",\"data\":[{\"asks\":[],\"bids\":[[\"64482.8\",\"7.15\",\"0\",\"12\"],[\"64479.2\",\"1.56\",\"0\",\"1\"],[\"64478.5\",\"1.57\",\"0\",\"2\"],[\"64478.1\",\"1.56\",\"0\",\"1\"],[\"64478\",\"0.01\",\"0\",\"1\"],[\"64477.6\",\"0.01\",\"0\",\"1\"],[\"64477.5\",\"1.86\",\"0\",\"2\"],[\"64474.7\",\"0.01\",\"0\",\"1\"],[\"64474.2\",\"0\",\"0\",\"0\"],[\"64422.7\",\"0\",\"0\",\"0\"]],\"ts\":\"1782016058405\",\"checksum\":2104803869,\"seqId\":325070105804,\"prevSeqId\":325070105781}]}"}
{"action": "update", "capture_sequence": 526, "channel": "books", "connection_sequence": 4, "event": null, "instId": "BTC-USDT-SWAP", "local_receive_ts": "2026-06-21T04:27:38Z", "monotonic_ns": 1643614409816407, "raw": "{\"arg\":{\"channel\":\"books\",\"instId\":\"BTC-USDT-SWAP\"},\"action\":\"update\",\"data\":[{\"asks\":[[\"64498.9\",\"3.42\",\"0\",\"2\"],[\"64502.4\",\"0.19\",\"0\",\"6\"],[\"64502.7\",\"31.06\",\"0\",\"4\"],[\"64504.9\",\"0.1\",\"0\",\"3\"],[\"64505.2\",\"17.2\",\"0\",\"2\"]],\"bids\":[[\"64482.9\",\"647.27\",\"0\",\"27\"],[\"64479.2\",\"0\",\"0\",\"0\"],[\"64478.5\",\"0.01\",\"0\",\"1\"],[\"64478.1\",\"0\",\"0\",\"0\"],[\"64465.7\",\"31.05\",\"0\",\"1\"],[\"64465.5\",\"0.04\",\"0\",\"2\"],[\"64463\",\"18.97\",\"0\",\"3\"],[\"64422.7\",\"3.4\",\"0\",\"3\"]],\"ts\":\"1782016058505\",\"checksum\":1056483404,\"seqId\":325070105830,\"prevSeqId\":325070105804}]}"}
{"action": "update", "capture_sequence": 527, "channel": "books", "connection_sequence": 4, "event": null, "instId": "BTC-USDT-SWAP", "local_receive_ts": "2026-06-21T04:27:38Z", "monotonic_ns": 1643614509535789, "raw": "{\"arg\":{\"channel\":\"books\",\"instId\":\"BTC-USDT-SWAP\"},\"action\":\"update\",\"data\":[{\"asks\":[[\"64483\",\"390.46\",\"0\",\"40\"],[\"64498.8\",\"496.71\",\"0\",\"4\"],[\"64500.2\",\"0.02\",\"0\",\"2\"],[\"64500.6\",\"78.05\",\"0\",\"5\"],[\"64512.1\",\"37.24\",\"0\",\"4\"],[\"64512.4\",\"85.41\",\"0\",\"2\"],[\"64512.6\",\"58.74\",\"0\",\"7\"],[\"64512.9\",\"75.97\",\"0\",\"5\"]],\"bids\":[[\"64482.9\",\"723.43\",\"0\",\"29\"],[\"64465.1\",\"58.22\",\"0\",\"1\"],[\"64464.4\",\"0.01\",\"0\",\"1\"],[\"64463\",\"22.11\",\"0\",\"4\"],[\"64422.7\",\"0\",\"0\",\"0\"]],\"ts\":\"1782016058605\",\"checksum\":1811377037,\"seqId\":325070105857,\"prevSeqId\":325070105830}]}"}
{"action": null, "capture_sequence": 528, "channel": "trades", "connection_sequence": 4, "event": null, "instId": "BTC-USDT-SWAP", "local_receive_ts": "2026-06-21T04:27:38Z", "monotonic_ns": 1643614584786646, "raw": "{\"arg\":{\"channel\":\"trades\",\"instId\":\"BTC-USDT-SWAP\"},\"data\":[{\"instId\":\"BTC-USDT-SWAP\",\"tradeId\":\"2718750446\",\"px\":\"64483\",\"sz\":\"0.02\",\"side\":\"buy\",\"ts\":\"1782016058681\",\"count\":\"1\",\"source\":\"0\",\"seqId\":325070105879}]}"}
{"action": "update", "capture_sequence": 529, "channel": "books", "connection_sequence": 4, "event": null, "instId": "BTC-USDT-SWAP", "local_receive_ts": "2026-06-21T04:27:38Z", "monotonic_ns": 1643614610626517, "raw": "{\"arg\":{\"channel\":\"books\",\"instId\":\"BTC-USDT-SWAP\"},\"action\":\"update\",\"data\":[{\"asks\":[[\"64483\",\"388.88\",\"0\",\"39\"],[\"64483.4\",\"0\",\"0\",\"0\"],[\"64483.5\",\"0\",\"0\",\"0\"],[\"64484\",\"7.07\",\"0\",\"4\"],[\"64484.5\",\"0.07\",\"0\",\"4\"],[\"64484.8\",\"0.02\",\"0\",\"2\"],[\"64485\",\"2\",\"0\",\"1\"],[\"64491.5\",\"0.1\",\"0\",\"1\"],[\"64493.2\",\"0.08\",\"0\",\"5\"],[\"64508.3\",\"0\",\"0\",\"0\"],[\"64508.6\",\"0.32\",\"0\",\"2\"],[\"64527.1\",\"0.46\",\"0\",\"1\"],[\"64527.2\",\"0.18\",\"0\",\"4\"],[\"64527.3\",\"0.05\",\"0\",\"5\"]],\"bids\":[[\"64476.5\",\"0.02\",\"0\",\"1\"],[\"64476\",\"0.04\",\"0\",\"2\"],[\"64466.6\",\"31.11\",\"0\",\"4\"],[\"64465.5\",\"0\",\"0\",\"0\"],[\"64464.1\",\"0.02\",\"0\",\"1\"],[\"64463.7\",\"0\",\"0\",\"0\"],[\"64460.6\",\"0.03\",\"0\",\"2\"],[\"64459.5\",\"15.65\",\"0\",\"1\"],[\"64454.9\",\"12.88\",\"0\",\"2\"],[\"64454.8\",\"10\",\"0\",\"1\"],[\"64439\",\"0.02\",\"0\",\"1\"],[\"64438.1\",\"42.72\",\"0\",\"5\"],[\"64422.8\",\"0\",\"0\",\"0\"]],\"ts\":\"1782016058705\",\"checksum\":-1268125913,\"seqId\":325070105888,\"prevSeqId\":325070105857}]}"}
{"action": null, "capture_sequence": 530, "channel": "trades", "connection_sequence": 4, "event": null, "instId": "BTC-USDT-SWAP", "local_receive_ts": "2026-06-21T04:27:38Z", "monotonic_ns": 1643614636723347, "raw": "{\"arg\":{\"channel\":\"trades\",\"instId\":\"BTC-USDT-SWAP\"},\"data\":[{\"instId\":\"BTC-USDT-SWAP\",\"tradeId\":\"2718750447\",\"px\":\"64483\",\"sz\":\"0.01\",\"side\":\"buy\",\"ts\":\"1782016058732\",\"count\":\"1\",\"source\":\"0\",\"seqId\":325070105933}]}"}
{"action": "update", "capture_sequence": 531, "channel": "books", "connection_sequence": 4, "event": null, "instId": "BTC-USDT-SWAP", "local_receive_ts": "2026-06-21T04:27:38Z", "monotonic_ns": 1643614709786299, "raw": "{\"arg\":{\"channel\":\"books\",\"instId\":\"BTC-USDT-SWAP\"},\"action\":\"update\",\"data\":[{\"asks\":[[\"64483\",\"334.91\",\"0\",\"38\"],[\"64485.4\",\"0\",\"0\",\"0\"],[\"64485.9\",\"141.56\",\"0\",\"3\"],[\"64486.4\",\"1.27\",\"0\",\"2\"],[\"64502.4\",\"31.22\",\"0\",\"7\"],[\"64502.7\",\"0.03\",\"0\",\"3\"],[\"64504.9\",\"1.65\",\"0\",\"4\"],[\"64505.2\",\"15.65\",\"0\",\"1\"],[\"64507.7\",\"0.07\",\"0\",\"4\"],[\"64508.3\",\"33.79\",\"0\",\"1\"],[\"64518\",\"103.04\",\"0\",\"12\"],[\"64518.5\",\"20.07\",\"0\",\"2\"]],\"bids\":[[\"64482.9\",\"730.99\",\"0\",\"29\"],[\"64480.9\",\"0\",\"0\",\"0\"],[\"64480.8\",\"0.32\",\"0\",\"2\"],[\"64479.4\",\"0\",\"0\",\"0\"],[\"64477.4\",\"3.11\",\"0\",\"2\"],[\"64476.5\",\"0\",\"0\",\"0\"],[\"64476\",\"0.06\",\"0\",\"3\"],[\"64469\",\"33.81\",\"0\",\"1\"],[\"64468.9\",\"0.3\",\"0\",\"1\"],[\"64467.9\",\"20.09\",\"0\",\"2\"],[\"64467.6\",\"0.8\",\"0\",\"4\"],[\"64466.6\",\"31.09\",\"0\",\"3\"],[\"64465.7\",\"0\",\"0\",\"0\"],[\"64465.5\",\"31.07\",\"0\",\"2\"],[\"64464.5\",\"0.02\",\"0\",\"2\"],[\"64464.4\",\"232.92\",\"0\",\"2\"],[\"64464.1\",\"0\",\"0\",\"0\"],[\"64463.8\",\"342.02\",\"0\",\"3\"],[\"64449\",\"0.02\",\"0\",\"2\"],[\"64446.7\",\"208.61\",\"0\",\"4\"],[\"64439\",\"0\",\"0\",\"0\"],[\"64438.1\",\"42.74\",\"0\",\"6\"],[\"64422.8\",\"0.01\",\"0\",\"1\"],[\"64422.7\",\"3.4\",\"0\",\"3\"],[\"64422.6\",\"0.02\",\"0\",\"2\"],[\"64422.4\",\"0.02\",\"0\",\"2\"]],\"ts\":\"1782016058805\",\"checksum\":1538581772,\"seqId\":325070106050,\"prevSeqId\":325070105888}]}"}
{"action": null, "capture_sequence": 532, "channel": "trades", "connection_sequence": 4, "event": null, "instId": "BTC-USDT-SWAP", "local_receive_ts": "2026-06-21T04:27:38Z", "monotonic_ns": 1643614778340376, "raw": "{\"arg\":{\"channel\":\"trades\",\"instId\":\"BTC-USDT-SWAP\"},\"data\":[{\"instId\":\"BTC-USDT-SWAP\",\"tradeId\":\"2718750452\",\"px\":\"64482.9\",\"sz\":\"1\",\"side\":\"sell\",\"ts\":\"1782016058874\",\"count\":\"5\",\"source\":\"0\",\"seqId\":325070106114}]}"}
{"action": "update", "capture_sequence": 533, "channel": "books", "connection_sequence": 4, "event": null, "instId": "BTC-USDT-SWAP", "local_receive_ts": "2026-06-21T04:27:39Z", "monotonic_ns": 1643614809545988, "raw": "{\"arg\":{\"channel\":\"books\",\"instId\":\"BTC-USDT-SWAP\"},\"action\":\"update\",\"data\":[{\"asks\":[[\"64483\",\"334.89\",\"0\",\"37\"],[\"64495.9\",\"0.96\",\"0\",\"4\"],[\"64496.4\",\"0.19\",\"0\",\"3\"],[\"64506.7\",\"0.19\",\"0\",\"15\"],[\"64506.8\",\"1.82\",\"0\",\"5\"]],\"bids\":[[\"64482.9\",\"730\",\"0\",\"26\"],[\"64468\",\"0.79\",\"0\",\"3\"],[\"64467.6\",\"0.03\",\"0\",\"3\"]],\"ts\":\"1782016058905\",\"checksum\":-1855254375,\"seqId\":325070106135,\"prevSeqId\":325070106050}]}"}
{"action": "update", "capture_sequence": 534, "channel": "books", "connection_sequence": 4, "event": null, "instId": "BTC-USDT-SWAP", "local_receive_ts": "2026-06-21T04:27:39Z", "monotonic_ns": 1643614909588796, "raw": "{\"arg\":{\"channel\":\"books\",\"instId\":\"BTC-USDT-SWAP\"},\"action\":\"update\",\"data\":[{\"asks\":[[\"64483\",\"346.45\",\"0\",\"39\"],[\"64483.5\",\"1.56\",\"0\",\"1\"],[\"64484\",\"8.63\",\"0\",\"5\"],[\"64484.5\",\"1.63\",\"0\",\"5\"],[\"64485\",\"3.56\",\"0\",\"2\"],[\"64485.4\",\"1.56\",\"0\",\"1\"],[\"64485.9\",\"143.12\",\"0\",\"4\"],[\"64486.4\",\"2.83\",\"0\",\"3\"],[\"64492.5\",\"0.05\",\"0\",\"3\"],[\"64527.2\",\"0\",\"0\",\"0\"],[\"64527.3\",\"0\",\"0\",\"0\"]],\"bids\":[[\"64481.1\",\"1.56\",\"0\",\"1\"],[\"64480.8\",\"0.01\",\"0\",\"1\"],[\"64480.4\",\"1.56\",\"0\",\"1\"],[\"64480.1\",\"0.31\",\"0\",\"1\"],[\"64480\",\"1.61\",\"0\",\"6\"],[\"64422.7\",\"0\",\"0\",\"0\"],[\"64422.6\",\"0\",\"0\",\"0\"],[\"64422.4\",\"0\",\"0\",\"0\"]],\"ts\":\"1782016059005\",\"checksum\":1162716400,\"seqId\":325070106232,\"prevSeqId\":325070106135}]}"}
{"action": "update", "capture_sequence": 535, "channel": "books", "connection_sequence": 4, "event": null, "instId": "BTC-USDT-SWAP", "local_receive_ts": "2026-06-21T04:27:39Z", "monotonic_ns": 1643615009531765, "raw": "{\"arg\":{\"channel\":\"books\",\"instId\":\"BTC-USDT-SWAP\"},\"action\":\"update\",\"data\":[{\"asks\":[[\"64483\",\"336.47\",\"0\",\"39\"],[\"64483.4\",\"0.01\",\"0\",\"1\"],[\"64484.8\",\"0.01\",\"0\",\"1\"],[\"64486.9\",\"1.68\",\"0\",\"3\"],[\"64500.2\",\"15.53\",\"0\",\"3\"],[\"64500.6\",\"62.54\",\"0\",\"4\"],[\"64527.1\",\"0\",\"0\",\"0\"]],\"bids\":[[\"64481.3\",\"1.56\",\"0\",\"1\"],[\"64481.1\",\"0\",\"0\",\"0\"],[\"64480.7\",\"1.57\",\"0\",\"2\"],[\"64480.4\",\"0\",\"0\",\"0\"],[\"64480\",\"0.05\",\"0\",\"5\"],[\"64479.7\",\"1.57\",\"0\",\"2\"],[\"64479.2\",\"1.56\",\"0\",\"1\"]],\"ts\":\"1782016059105\",\"checksum\":-569092391,\"seqId\":325070106372,\"prevSeqId\":325070106232}]}"}
{"action": null, "capture_sequence": 536, "channel": "trades", "connection_sequence": 4, "event": null, "instId": "BTC-USDT-SWAP", "local_receive_ts": "2026-06-21T04:27:39Z", "monotonic_ns": 1643615013285914, "raw": "{\"arg\":{\"channel\":\"trades\",\"instId\":\"BTC-USDT-SWAP\"},\"data\":[{\"instId\":\"BTC-USDT-SWAP\",\"tradeId\":\"2718750453\",\"px\":\"64483\",\"sz\":\"0.38\",\"side\":\"buy\",\"ts\":\"1782016059109\",\"count\":\"1\",\"source\":\"0\",\"seqId\":325070106378}]}"}
{"action": "update", "capture_sequence": 537, "channel": "books", "connection_sequence": 4, "event": null, "instId": "BTC-USDT-SWAP", "local_receive_ts": "2026-06-21T04:27:39Z", "monotonic_ns": 1643615109615842, "raw": "{\"arg\":{\"channel\":\"books\",\"instId\":\"BTC-USDT-SWAP\"},\"action\":\"update\",\"data\":[{\"asks\":[[\"64483\",\"344.63\",\"0\",\"40\"],[\"64483.4\",\"0\",\"0\",\"0\"],[\"64483.5\",\"0\",\"0\",\"0\"],[\"64484\",\"7.07\",\"0\",\"4\"],[\"64484.5\",\"0.07\",\"0\",\"4\"],[\"64484.8\",\"0.02\",\"0\",\"2\"],[\"64485\",\"2\",\"0\",\"1\"],[\"64485.4\",\"0\",\"0\",\"0\"],[\"64487.4\",\"2.06\",\"0\",\"7\"],[\"64487.8\",\"1.66\",\"0\",\"5\"],[\"64488.3\",\"1.58\",\"0\",\"3\"],[\"64488.8\",\"51.56\",\"0\",\"2\"],[\"64489.3\",\"4.81\",\"0\",\"5\"],[\"64489.7\",\"2.36\",\"0\",\"2\"],[\"64492.5\",\"22.05\",\"0\",\"4\"],[\"64527.1\",\"0.46\",\"0\",\"1\"],[\"64527.2\",\"0.18\",\"0\",\"4\"],[\"64527.3\",\"0.05\",\"0\",\"5\"]],\"bids\":[[\"64482.9\",\"731.56\",\"0\",\"27\"],[\"64476.2\",\"0.33\",\"0\",\"3\"],[\"64475.7\",\"0\",\"0\",\"0\"],[\"64475.1\",\"138.15\",\"0\",\"5\"],[\"64422.7\",\"3.4\",\"0\",\"3\"]],\"ts\":\"1782016059205\",\"checksum\":1319970469,\"seqId\":325070106492,\"prevSeqId\":325070106372}]}"}
{"action": null, "capture_sequence": 538, "channel": "trades", "connection_sequence": 4, "event": null, "instId": "BTC-USDT-SWAP", "local_receive_ts": "2026-06-21T04:27:39Z", "monotonic_ns": 1643615114043002, "raw": "{\"arg\":{\"channel\":\"trades\",\"instId\":\"BTC-USDT-SWAP\"},\"data\":[{\"instId\":\"BTC-USDT-SWAP\",\"tradeId\":\"2718750482\",\"px\":\"64483\",\"sz\":\"100\",\"side\":\"buy\",\"ts\":\"1782016059210\",\"count\":\"29\",\"source\":\"0\",\"seqId\":325070106563}]}"}
{"action": null, "capture_sequence": 539, "channel": "trades", "connection_sequence": 4, "event": null, "instId": "BTC-USDT-SWAP", "local_receive_ts": "2026-06-21T04:27:39Z", "monotonic_ns": 1643615160457008, "raw": "{\"arg\":{\"channel\":\"trades\",\"instId\":\"BTC-USDT-SWAP\"},\"data\":[{\"instId\":\"BTC-USDT-SWAP\",\"tradeId\":\"2718750483\",\"px\":\"64483\",\"sz\":\"0.28\",\"side\":\"buy\",\"ts\":\"1782016059256\",\"count\":\"1\",\"source\":\"0\",\"seqId\":325070106730}]}"}
{"action": "update", "capture_sequence": 540, "channel": "books", "connection_sequence": 4, "event": null, "instId": "BTC-USDT-SWAP", "local_receive_ts": "2026-06-21T04:27:39Z", "monotonic_ns": 1643615216230637, "raw": "{\"arg\":{\"channel\":\"books\",\"instId\":\"BTC-USDT-SWAP\"},\"action\":\"update\",\"data\":[{\"asks\":[[\"64483\",\"244.74\",\"0\",\"14\"],[\"64483.1\",\"14.09\",\"0\",\"7\"],[\"64483.2\",\"0\",\"0\",\"0\"],[\"64484.1\",\"0\",\"0\",\"0\"],[\"64484.5\",\"0.08\",\"0\",\"5\"],[\"64484.6\",\"3.01\",\"0\",\"3\"],[\"64484.9\",\"20.81\",\"0\",\"2\"],[\"64485.5\",\"0.41\",\"0\",\"2\"],[\"64485.9\",\"5.43\",\"0\",\"2\"],[\"64486.4\",\"1.27\",\"0\",\"2\"],[\"64486.5\",\"91.05\",\"0\",\"2\"],[\"64486.9\",\"0.12\",\"0\",\"2\"],[\"64487.4\",\"0.5\",\"0\",\"6\"],[\"64487.8\",\"0.1\",\"0\",\"4\"],[\"64487.9\",\"6.71\",\"0\",\"3\"],[\"64488\",\"194\",\"0\",\"28\"],[\"64488.3\",\"0.02\",\"0\",\"2\"],[\"64488.7\",\"0.04\",\"0\",\"1\"],[\"64488.8\",\"50\",\"0\",\"1\"],[\"64489.1\",\"1.6\",\"0\",\"4\"],[\"64489.2\",\"0\",\"0\",\"0\"],[\"64489.3\",\"3.25\",\"0\",\"4\"],[\"64489.6\",\"53.95\",\"0\",\"3\"],[\"64489.7\",\"0.8\",\"0\",\"1\"],[\"64490.1\",\"1.86\",\"0\",\"3\"],[\"64490.6\",\"18.56\",\"0\",\"5\"],[\"64491\",\"1.57\",\"0\",\"2\"],[\"64491.5\",\"1.66\",\"0\",\"2\"],[\"64492\",\"1.6\",\"0\",\"5\"],[\"64492.5\",\"23.61\",\"0\",\"5\"],[\"64493\",\"2.07\",\"0\",\"4\"],[\"64493.1\",\"148.54\",\"0\",\"3\"],[\"64493.2\",\"0.07\",\"0\",\"4\"],[\"64493.9\",\"19.05\",\"0\",\"1\"],[\"64494.1\",\"0.01\",\"0\",\"1\"],[\"64494.9\",\"14.97\",\"0\",\"6\"],[\"64495.4\",\"0.06\",\"0\",\"3\"],[\"64496.4\",\"0.02\",\"0\",\"2\"],[\"64498\",\"24.4\",\"0\",\"3\"],[\"64498.1\",\"2.33\",\"0\",\"4\"],[\"64498.8\",\"496.88\",\"0\",\"5\"],[\"64500.2\",\"0.02\",\"0\",\"2\"],[\"64500.8\",\"15.87\",\"0\",\"2\"],[\"64502.4\",\"0.19\",\"0\",\"6\"],[\"64502.9\",\"422.19\",\"0\",\"7\"],[\"64503\",\"15.95\",\"0\",\"3\"],[\"64503.6\",\"0.03\",\"0\",\"3\"],[\"64504.9\",\"0.1\",\"0\",\"3\"],[\"64505.4\",\"60.78\",\"0\",\"5\"],[\"64506.8\",\"1.05\",\"0\",\"4\"],[\"64507.1\",\"0.83\",\"0\",\"5\"],[\"64508.3\",\"0\",\"0\",\"0\"],[\"64508.5\",\"76.25\",\"0\",\"4\"],[\"64510.5\",\"61.2\",\"0\",\"5\"],[\"64512.2\",\"96.56\",\"0\",\"4\"],[\"64512.4\",\"0.08\",\"0\",\"1\"],[\"64512.9\",\"17.79\",\"0\",\"4\"],[\"64513.4\",\"73.86\",\"0\",\"4\"],[\"64514\",\"18.26\",\"0\",\"3\"],[\"64527.4\",\"0.27\",\"0\",\"2\"],[\"64527.5\",\"0.19\",\"0\",\"5\"]],\"bids\":[[\"64480.9\",\"0.31\",\"0\",\"1\"],[\"64480.1\",\"0\",\"0\",\"0\"],[\"64478.8\",\"77.54\",\"0\",\"1\"],[\"64478.7\",\"0\",\"0\",\"0\"],[\"64476.6\",\"15.54\",\"0\",\"4\"],[\"64476.2\",\"0.02\",\"0\",\"2\"],[\"64476\",\"0.04\",\"0\",\"2\"],[\"64475.7\",\"0.31\",\"0\",\"1\"],[\"64470.5\",\"91.18\",\"0\",\"5\"],[\"64470.4\",\"421.41\",\"0\",\"2\"],[\"64468.3\",\"47.31\",\"0\",\"2\"],[\"64468\",\"0.02\",\"0\",\"2\"],[\"64466.6\",\"31.11\",\"0\",\"4\"],[\"64465.7\",\"31.05\",\"0\",\"1\"],[\"64465.5\",\"58.22\",\"0\",\"1\"],[\"64465.1\",\"0\",\"0\",\"0\"],[\"64439\",\"0.02\",\"0\",\"1\"],[\"64438.1\",\"42.72\",\"0\",\"5\"],[\"64422.8\",\"0\",\"0\",\"0\"],[\"64422.7\",\"0\",\"0\",\"0\"]],\"ts\":\"1782016059305\",\"checksum\":1810715165,\"seqId\":325070106810,\"prevSeqId\":325070106492}]}"}
{"action": "update", "capture_sequence": 541, "channel": "books", "connection_sequence": 4, "event": null, "instId": "BTC-USDT-SWAP", "local_receive_ts": "2026-06-21T04:27:39Z", "monotonic_ns": 1643615309767789, "raw": "{\"arg\":{\"channel\":\"books\",\"instId\":\"BTC-USDT-SWAP\"},\"action\":\"update\",\"data\":[{\"asks\":[[\"64483\",\"174.14\",\"0\",\"14\"],[\"64487.6\",\"2.2\",\"0\",\"1\"],[\"64493\",\"19.9\",\"0\",\"6\"],[\"64493.1\",\"151.24\",\"0\",\"4\"],[\"64493.9\",\"0\",\"0\",\"0\"],[\"64494.1\",\"0\",\"0\",\"0\"],[\"64494.4\",\"0.6\",\"0\",\"6\"],[\"64494.9\",\"12.07\",\"0\",\"5\"],[\"64495.4\",\"19.91\",\"0\",\"5\"],[\"64495.7\",\"11.36\",\"0\",\"4\"],[\"64495.8\",\"34.99\",\"0\",\"4\"],[\"64498.1\",\"0.03\",\"0\",\"3\"],[\"64499.9\",\"1121.57\",\"0\",\"4\"],[\"64500\",\"3458.67\",\"0\",\"1035\"],[\"64500.1\",\"0.06\",\"0\",\"5\"],[\"64500.2\",\"15.53\",\"0\",\"3\"],[\"64500.8\",\"0.36\",\"0\",\"1\"],[\"64503.6\",\"0.02\",\"0\",\"2\"],[\"64504.3\",\"0.05\",\"0\",\"3\"],[\"64508.7\",\"147.7\",\"0\",\"9\"],[\"64510.5\",\"59.3\",\"0\",\"4\"],[\"64512.2\",\"11.23\",\"0\",\"3\"],[\"64512.5\",\"86.49\",\"0\",\"7\"],[\"64514\",\"15.66\",\"0\",\"2\"],[\"64522.8\",\"15.71\",\"0\",\"4\"],[\"64523.8\",\"0.03\",\"0\",\"2\"],[\"64527.6\",\"16.48\",\"0\",\"5\"]],\"bids\":[[\"64482.9\",\"742.91\",\"0\",\"28\"],[\"64482.8\",\"3.95\",\"0\",\"11\"],[\"64471.4\",\"31.06\",\"0\",\"2\"],[\"64471.3\",\"17.52\",\"0\",\"3\"],[\"64468.3\",\"46.54\",\"0\",\"1\"],[\"64468\",\"0.79\",\"0\",\"3\"],[\"64467.2\",\"155.29\",\"0\",\"2\"],[\"64466.9\",\"0.02\",\"0\",\"1\"],[\"64466.7\",\"0\",\"0\",\"0\"],[\"64466.6\",\"31.09\",\"0\",\"3\"]],\"ts\":\"1782016059405\",\"checksum\":636457910,\"seqId\":325070106926,\"prevSeqId\":325070106810}]}"}
{"action": null, "capture_sequence": 542, "channel": "trades", "connection_sequence": 4, "event": null, "instId": "BTC-USDT-SWAP", "local_receive_ts": "2026-06-21T04:27:39Z", "monotonic_ns": 1643615368136692, "raw": "{\"arg\":{\"channel\":\"trades\",\"instId\":\"BTC-USDT-SWAP\"},\"data\":[{\"instId\":\"BTC-USDT-SWAP\",\"tradeId\":\"2718750484\",\"px\":\"64482.9\",\"sz\":\"0.07\",\"side\":\"sell\",\"ts\":\"1782016059464\",\"count\":\"1\",\"source\":\"0\",\"seqId\":325070106991}]}"}
{"action": "update", "capture_sequence": 543, "channel": "books", "connection_sequence": 4, "event": null, "instId": "BTC-USDT-SWAP", "local_receive_ts": "2026-06-21T04:27:39Z", "monotonic_ns": 1643615410443991, "raw": "{\"arg\":{\"channel\":\"books\",\"instId\":\"BTC-USDT-SWAP\"},\"action\":\"update\",\"data\":[{\"asks\":[[\"64483\",\"184.14\",\"0\",\"15\"],[\"64484.9\",\"58.79\",\"0\",\"3\"],[\"64486.4\",\"137.4\",\"0\",\"3\"],[\"64486.5\",\"53.51\",\"0\",\"2\"],[\"64487.9\",\"0.51\",\"0\",\"2\"],[\"64488\",\"57.87\",\"0\",\"27\"],[\"64489.1\",\"0.04\",\"0\",\"3\"],[\"64489.6\",\"52.39\",\"0\",\"2\"],[\"64492.1\",\"7.7\",\"0\",\"2\"],[\"64492.9\",\"0.78\",\"0\",\"2\"],[\"64495.4\",\"19.14\",\"0\",\"4\"],[\"64495.8\",\"167.02\",\"0\",\"6\"],[\"64498.8\",\"496.55\",\"0\",\"3\"],[\"64499\",\"333.26\",\"0\",\"22\"],[\"64500.2\",\"0.02\",\"0\",\"2\"],[\"64500.6\",\"78.05\",\"0\",\"5\"],[\"64508.6\",\"0.01\",\"0\",\"1\"],[\"64508.7\",\"15.67\",\"0\",\"7\"],[\"64509.5\",\"0.31\",\"0\",\"1\"],[\"64512.4\",\"85.41\",\"0\",\"2\"],[\"64512.5\",\"1.16\",\"0\",\"6\"],[\"64523.8\",\"0.02\",\"0\",\"1\"],[\"64526.2\",\"6.58\",\"0\",\"3\"],[\"64527.6\",\"0\",\"0\",\"0\"]],\"bids\":[[\"64482.9\",\"741.3\",\"0\",\"27\"],[\"64476.4\",\"0.32\",\"0\",\"2\"],[\"64475.7\",\"0\",\"0\",\"0\"],[\"64467.2\",\"69.9\",\"0\",\"1\"],[\"64466.9\",\"0\",\"0\",\"0\"],[\"64466.7\",\"85.39\",\"0\",\"1\"],[\"64466.6\",\"31.11\",\"0\",\"4\"],[\"64463\",\"18.97\",\"0\",\"3\"],[\"64422.8\",\"0.01\",\"0\",\"1\"]],\"ts\":\"1782016059505\",\"checksum\":493428087,\"seqId\":325070107033,\"prevSeqId\":325070106926}]}"}
{"action": "update", "capture_sequence": 544, "channel": "books", "connection_sequence": 4, "event": null, "instId": "BTC-USDT-SWAP", "local_receive_ts": "2026-06-21T04:27:39Z", "monotonic_ns": 1643615509624449, "raw": "{\"arg\":{\"channel\":\"books\",\"instId\":\"BTC-USDT-SWAP\"},\"action\":\"update\",\"data\":[{\"asks\":[[\"64483.1\",\"14.1\",\"0\",\"8\"],[\"64498.9\",\"3.57\",\"0\",\"3\"],[\"64500\",\"3458.66\",\"0\",\"1034\"],[\"64500.4\",\"0.04\",\"0\",\"4\"]],\"bids\":[[\"64481.3\",\"0\",\"0\",\"0\"],[\"64480.7\",\"0.01\",\"0\",\"1\"],[\"64470.5\",\"5.02\",\"0\",\"4\"],[\"64470\",\"102.92\",\"0\",\"6\"],[\"64468\",\"0.02\",\"0\",\"2\"],[\"64467.6\",\"0.8\",\"0\",\"4\"],[\"64467.1\",\"116.46\",\"0\",\"2\"],[\"64466.7\",\"0\",\"0\",\"0\"],[\"64466.6\",\"31.09\",\"0\",\"3\"],[\"64465.7\",\"31.07\",\"0\",\"2\"],[\"64464.1\",\"0.02\",\"0\",\"1\"],[\"64463.8\",\"342\",\"0\",\"2\"],[\"64463\",\"22.09\",\"0\",\"4\"],[\"64422.7\",\"3.4\",\"0\",\"3\"]],\"ts\":\"1782016059605\",\"checksum\":2106786465,\"seqId\":325070107144,\"prevSeqId\":325070107033}]}"}
{"action": null, "capture_sequence": 545, "channel": "trades", "connection_sequence": 4, "event": null, "instId": "BTC-USDT-SWAP", "local_receive_ts": "2026-06-21T04:27:39Z", "monotonic_ns": 1643615601113547, "raw": "{\"arg\":{\"channel\":\"trades\",\"instId\":\"BTC-USDT-SWAP\"},\"data\":[{\"instId\":\"BTC-USDT-SWAP\",\"tradeId\":\"2718750485\",\"px\":\"64483\",\"sz\":\"0.02\",\"side\":\"buy\",\"ts\":\"1782016059697\",\"count\":\"1\",\"source\":\"0\",\"seqId\":325070107215}]}"}
{"action": "update", "capture_sequence": 546, "channel": "books", "connection_sequence": 4, "event": null, "instId": "BTC-USDT-SWAP", "local_receive_ts": "2026-06-21T04:27:39Z", "monotonic_ns": 1643615609830815, "raw": "{\"arg\":{\"channel\":\"books\",\"instId\":\"BTC-USDT-SWAP\"},\"action\":\"update\",\"data\":[{\"asks\":[[\"64483\",\"184.12\",\"0\",\"15\"],[\"64498.8\",\"496.72\",\"0\",\"4\"],[\"64499\",\"333.09\",\"0\",\"21\"],[\"64504.7\",\"3.71\",\"0\",\"2\"]],\"bids\":[],\"ts\":\"1782016059705\",\"checksum\":-1417559218,\"seqId\":325070107222,\"prevSeqId\":325070107144}]}"}
{"action": "update", "capture_sequence": 547, "channel": "books", "connection_sequence": 4, "event": null, "instId": "BTC-USDT-SWAP", "local_receive_ts": "2026-06-21T04:27:40Z", "monotonic_ns": 1643615809390822, "raw": "{\"arg\":{\"channel\":\"books\",\"instId\":\"BTC-USDT-SWAP\"},\"action\":\"update\",\"data\":[{\"asks\":[[\"64483\",\"174.12\",\"0\",\"14\"]],\"bids\":[[\"64482.9\",\"808.12\",\"0\",\"28\"],[\"64482.8\",\"7.55\",\"0\",\"12\"]],\"ts\":\"1782016059905\",\"checksum\":-152425634,\"seqId\":325070107384,\"prevSeqId\":325070107222}]}"}
{"action": null, "capture_sequence": 548, "channel": "trades", "connection_sequence": 4, "event": null, "instId": "BTC-USDT-SWAP", "local_receive_ts": "2026-06-21T04:27:40Z", "monotonic_ns": 1643615815139767, "raw": "{\"arg\":{\"channel\":\"trades\",\"instId\":\"BTC-USDT-SWAP\"},\"data\":[{\"instId\":\"BTC-USDT-SWAP\",\"tradeId\":\"2718750486\",\"px\":\"64482.9\",\"sz\":\"0.1\",\"side\":\"sell\",\"ts\":\"1782016059911\",\"count\":\"1\",\"source\":\"0\",\"seqId\":325070107392}]}"}
{"action": null, "capture_sequence": 549, "channel": "trades", "connection_sequence": 4, "event": null, "instId": "BTC-USDT-SWAP", "local_receive_ts": "2026-06-21T04:27:40Z", "monotonic_ns": 1643615839681448, "raw": "{\"arg\":{\"channel\":\"trades\",\"instId\":\"BTC-USDT-SWAP\"},\"data\":[{\"instId\":\"BTC-USDT-SWAP\",\"tradeId\":\"2718750487\",\"px\":\"64483\",\"sz\":\"48.64\",\"side\":\"buy\",\"ts\":\"1782016059935\",\"count\":\"1\",\"source\":\"0\",\"seqId\":325070107409}]}"}
