{"action": "update", "capture_sequence": 129, "channel": "books", "connection_sequence": 1, "event": null, "instId": "BTC-USDT-SWAP", "local_receive_ts": "2026-06-21T04:27:07Z", "monotonic_ns": 1643583218691339, "raw": "{\"arg\":{\"channel\":\"books\",\"instId\":\"BTC-USDT-SWAP\"},\"action\":\"update\",\"data\":[{\"asks\":[[\"64479.9\",\"0\",\"0\",\"0\"],[\"64480\",\"118.98\",\"0\",\"10\"],[\"64480.6\",\"0\",\"0\",\"0\"],[\"64481.2\",\"0\",\"0\",\"0\"],[\"64481.9\",\"0.02\",\"0\",\"2\"],[\"64482\",\"0.03\",\"0\",\"1\"],[\"64482.1\",\"0.01\",\"0\",\"1\"],[\"64482.2\",\"0\",\"0\",\"0\"],[\"64482.7\",\"1.01\",\"0\",\"2\"],[\"64482.8\",\"0.02\",\"0\",\"2\"],[\"64482.9\",\"3.19\",\"0\",\"3\"],[\"64483.1\",\"0.62\",\"0\",\"3\"],[\"64483.5\",\"13.97\",\"0\",\"4\"],[\"64484.2\",\"0.01\",\"0\",\"1\"],[\"64484.4\",\"0\",\"0\",\"0\"],[\"64484.5\",\"136.19\",\"0\",\"4\"],[\"64484.7\",\"0\",\"0\",\"0\"],[\"64485\",\"41.95\",\"0\",\"2\"],[\"64485.4\",\"0\",\"0\",\"0\"],[\"64485.9\",\"6.92\",\"0\",\"2\"],[\"64486\",\"66.61\",\"0\",\"7\"],[\"64486.2\",\"0.17\",\"0\",\"6\"],[\"64486.4\",\"1.28\",\"0\",\"3\"],[\"64486.9\",\"0.11\",\"0\",\"1\"],[\"64487.4\",\"0.8\",\"0\",\"7\"],[\"64487.8\",\"0.1\",\"0\",\"4\"],[\"64488.3\",\"0.02\",\"0\",\"2\"],[\"64488.7\",\"0.04\",\"0\",\"1\"],[\"64489.4\",\"2.93\",\"0\",\"5\"],[\"64489.6\",\"0.12\",\"0\",\"2\"],[\"64489.8\",\"152.84\",\"0\",\"4\"],[\"64490\",\"60.15\",\"0\",\"21\"],[\"64490.3\",\"1\",\"0\",\"1\"],[\"64490.4\",\"0.03\",\"0\",\"3\"],[\"64490.5\",\"1.51\",\"0\",\"2\"],[\"64490.8\",\"0.02\",\"0\",\"1\"],[\"64491\",\"64.49\",\"0\",\"2\"],[\"64491.1\",\"0\",\"0\",\"0\"],[\"64491.7\",\"20.71\",\"0\",\"4\"],[\"64492.1\",\"0\",\"0\",\"0\"],[\"64492.4\",\"33.92\",\"0\",\"10\"],[\"64492.6\",\"0.01\",\"0\",\"1\"],[\"64493.1\",\"32.65\",\"0\",\"6\"],[\"64493.3\",\"24.11\",\"0\",\"6\"],[\"64494.2\",\"0.12\",\"0\",\"1\"],[\"64495.6\",\"0.01\",\"0\",\"1\"],[\"64495.8\",\"0.21\",\"0\",\"4\"],[\"64495.9\",\"1.61\",\"0\",\"4\"],[\"64496.6\",\"31.68\",\"0\",\"2\"],[\"64499.3\",\"15.51\",\"0\",\"1\"],[\"64499.7\",\"35.37\",\"0\",\"5\"],[\"64500.2\",\"0.02\",\"0\",\"2\"],[\"64500.3\",\"2.78\",\"0\",\"5\"],[\"64500.6\",\"0.39\",\"0\",\"3\"],[\"64500.7\",\"3.91\",\"0\",\"1\"],[\"64501.1\",\"0.36\",\"0\",\"3\"],[\"64501.5\",\"1.57\",\"0\",\"4\"],[\"64501.9\",\"31.11\",\"0\",\"2\"],[\"64502.1\",\"0.01\",\"0\",\"1\"],[\"64502.4\",\"232.96\",\"0\",\"7\"],[\"64502.7\",\"1.88\",\"0\",\"4\"],[\"64502.9\",\"280.51\",\"0\",\"7\"],[\"64503.4\",\"1.55\",\"0\",\"1\"],[\"64505.7\",\"132.59\",\"0\",\"3\"],[\"64507.4\",\"27.31\",\"0\",\"5\"],[\"64509\",\"249.45\",\"0\",\"4\"],[\"64512.1\",\"0.04\",\"0\",\"3\"],[\"64513.8\",\"85.34\",\"0\",\"2\"],[\"64513.9\",\"0.12\",\"0\",\"1\"],[\"64514.1\",\"0.02\",\"0\",\"2\"],[\"64515.4\",\"58.64\",\"0\",\"6\"],[\"64518\",\"111.05\",\"0\",\"14\"],[\"64519\",\"20.73\",\"0\",\"5\"],[\"64519.7\",\"10.81\",\"0\",\"7\"],[\"64519.8\",\"122.39\",\"0\",\"7\"],[\"64519.9\",\"582.66\",\"0\",\"3\"],[\"64520\",\"78.62\",\"0\",\"63\"],[\"64521.1\",\"0.01\",\"0\",\"1\"],[\"64525.7\",\"0.03\",\"0\",\"1\"],[\"64525.8\",\"0.02\",\"0\",\"2\"],[\"64525.9\",\"2.69\",\"0\",\"4\"]],\"bids\":[[\"64479.9\",\"1498.8\",\"0\",\"69\"],[\"64479.8\",\"253.57\",\"0\",\"19\"],[\"64479.7\",\"29.96\",\"0\",\"6\"],[\"64479.4\",\"0.03\",\"0\",\"2\"],[\"64479.3\",\"1.57\",\"0\",\"2\"],[\"64479.1\",\"0.01\",\"0\",\"1\"],[\"64478.7\",\"0.76\",\"0\",\"1\"],[\"64478.6\",\"0.31\",\"0\",\"1\"],[\"64476.9\",\"0.03\",\"0\",\"3\"],[\"64476.6\",\"77.55\",\"0\",\"2\"],[\"64476.5\",\"14.49\",\"0\",\"2\"],[\"64476.4\",\"0\",\"0\",\"0\"],[\"64476.3\",\"1.57\",\"0\",\"2\"],[\"64475.3\",\"0.24\",\"0\",\"2\"],[\"64474.1\",\"6.23\",\"0\",\"2\"],[\"64472.9\",\"4.77\",\"0\",\"1\"],[\"64471.3\",\"1.15\",\"0\",\"1\"],[\"64470.4\",\"4\",\"0\",\"1\"],[\"64470.2\",\"32.59\",\"0\",\"3\"],[\"64470.1\",\"86.16\",\"0\",\"1\"],[\"64469.9\",\"33.81\",\"0\",\"1\"],[\"64469.4\",\"46.54\",\"0\",\"1\"],[\"64468.4\",\"20.39\",\"0\",\"2\"],[\"64468.3\",\"0.77\",\"0\",\"1\"],[\"64467.8\",\"0.01\",\"0\",\"1\"],[\"64467.6\",\"0.02\",\"0\",\"2\"],[\"64467.5\",\"85.42\",\"0\",\"3\"],[\"64467.1\",\"31.22\",\"0\",\"2\"],[\"64466.3\",\"58.22\",\"0\",\"1\"],[\"64465.4\",\"557.51\",\"0\",\"7\"],[\"64464.7\",\"0\",\"0\",\"0\"],[\"64463.9\",\"31.05\",\"0\",\"1\"],[\"64463.4\",\"232.91\",\"0\",\"1\"],[\"64462.7\",\"18.95\",\"0\",\"1\"],[\"64461.7\",\"0.01\",\"0\",\"1\"],[\"64461.6\",\"0\",\"0\",\"0\"],[\"64461.4\",\"0.03\",\"0\",\"3\"],[\"64461.2\",\"0.06\",\"0\",\"3\"],[\"64460.6\",\"0.01\",\"0\",\"1\"],[\"64459.3\",\"39.02\",\"0\",\"3\"],[\"64459.1\",\"46.54\",\"0\",\"1\"],[\"64454\",\"15.71\",\"0\",\"4\"],[\"64452.7\",\"323.57\",\"0\",\"4\"],[\"64448.2\",\"17.05\",\"0\",\"1\"],[\"64447.9\",\"3.63\",\"0\",\"1\"],[\"64445.9\",\"0\",\"0\",\"0\"],[\"64444.6\",\"496.54\",\"0\",\"2\"],[\"64441.6\",\"15.81\",\"0\",\"3\"],[\"64440.9\",\"15.5\",\"0\",\"2\"],[\"64440.7\",\"0\",\"0\",\"0\"],[\"64438.5\",\"0.01\",\"0\",\"1\"],[\"64437.8\",\"46.55\",\"0\",\"2\"],[\"64437.6\",\"155.92\",\"0\",\"2\"],[\"64436.3\",\"0\",\"0\",\"0\"],[\"64434.7\",\"98.85\",\"0\",\"3\"],[\"64434\",\"15.46\",\"0\",\"1\"],[\"64430.5\",\"0\",\"0\",\"0\"],[\"64429.1\",\"0.02\",\"0\",\"1\"],[\"64428.6\",\"1.04\",\"0\",\"3\"],[\"64427\",\"282.24\",\"0\",\"6\"],[\"64423.5\",\"19.6\",\"0\",\"1\"],[\"64422\",\"0\",\"0\",\"0\"],[\"64421.9\",\"0\",\"0\",\"0\"],[\"64421.8\",\"0\",\"0\",\"0\"],[\"64421.6\",\"0\",\"0\",\"0\"],[\"64421.5\",\"0\",\"0\",\"0\"],[\"64421.3\",\"0\",\"0\",\"0\"],[\"64421.2\",\"0\",\"0\",\"0\"]],\"ts\":\"1782016027305\",\"checksum\":185903199,\"seqId\":325070072126,\"prevSeqId\":325070071286}]}"}
{"action": "update", "capture_sequence": 130, "channel": "books", "connection_sequence": 1, "event": null, "instId": "BTC-USDT-SWAP", "local_receive_ts": "2026-06-21T04:27:07Z", "monotonic_ns": 1643583313437276, "raw": "{\"arg\":{\"channel\":\"books\",\"instId\":\"BTC-USDT-SWAP\"},\"action\":\"update\",\"data\":[{\"asks\":[[\"64480\",\"86.11\",\"0\",\"13\"],[\"64481.5\",\"0.03\",\"0\",\"2\"],[\"64481.9\",\"0.01\",\"0\",\"1\"],[\"64482.8\",\"0.03\",\"0\",\"3\"],[\"64483.4\",\"1.02\",\"0\",\"3\"],[\"64483.5\",\"13.96\",\"0\",\"3\"],[\"64485.6\",\"15.52\",\"0\",\"1\"],[\"64486\",\"51.09\",\"0\",\"6\"],[\"64486.6\",\"57.56\",\"0\",\"2\"],[\"64486.8\",\"0.96\",\"0\",\"4\"],[\"64487.7\",\"0.01\",\"0\",\"1\"],[\"64487.8\",\"30.53\",\"0\",\"5\"],[\"64488.2\",\"4.46\",\"0\",\"3\"],[\"64491\",\"0.01\",\"0\",\"1\"],[\"64492.1\",\"0.15\",\"0\",\"1\"],[\"64492.3\",\"15.96\",\"0\",\"3\"],[\"64492.4\",\"18.68\",\"0\",\"9\"],[\"64492.6\",\"0\",\"0\",\"0\"],[\"64493.1\",\"28.45\",\"0\",\"5\"],[\"64493.6\",\"0.01\",\"0\",\"1\"],[\"64495.9\",\"0.84\",\"0\",\"3\"],[\"64500\",\"3456.28\",\"0\",\"1035\"],[\"64501.1\",\"0.05\",\"0\",\"2\"],[\"64501.6\",\"2.2\",\"0\",\"4\"],[\"64502.9\",\"280.5\",\"0\",\"6\"],[\"64503\",\"15.96\",\"0\",\"4\"],[\"64505.7\",\"0.56\",\"0\",\"1\"],[\"64507.3\",\"0.03\",\"0\",\"2\"],[\"64507.9\",\"1.04\",\"0\",\"5\"],[\"64523.3\",\"186.35\",\"0\",\"4\"],[\"64525.8\",\"0\",\"0\",\"0\"],[\"64525.9\",\"0\",\"0\",\"0\"]],\"bids\":[[\"64479.9\",\"1386.75\",\"0\",\"64\"],[\"64479.8\",\"252.82\",\"0\",\"19\"],[\"64479.2\",\"78.68\",\"0\",\"2\"],[\"64478.7\",\"0\",\"0\",\"0\"],[\"64478.6\",\"0\",\"0\",\"0\"],[\"64476.6\",\"77.56\",\"0\",\"3\"],[\"64474.1\",\"37.28\",\"0\",\"3\"],[\"64473.9\",\"46.55\",\"0\",\"2\"],[\"64470.2\",\"1.54\",\"0\",\"2\"],[\"64469.2\",\"154.79\",\"0\",\"4\"],[\"64469\",\"1.9\",\"0\",\"1\"],[\"64468.9\",\"1.38\",\"0\",\"3\"],[\"64468.4\",\"21.76\",\"0\",\"2\"],[\"64468.3\",\"0\",\"0\",\"0\"],[\"64467.6\",\"2.78\",\"0\",\"3\"],[\"64467\",\"383.8\",\"0\",\"3\"],[\"64466.9\",\"167.72\",\"0\",\"6\"],[\"64465.6\",\"28.21\",\"0\",\"4\"],[\"64464.1\",\"2.78\",\"0\",\"2\"],[\"64463.7\",\"0\",\"0\",\"0\"],[\"64461.7\",\"1.01\",\"0\",\"2\"],[\"64461.2\",\"0.04\",\"0\",\"2\"],[\"64459.1\",\"49.68\",\"0\",\"2\"],[\"64457.9\",\"0.03\",\"0\",\"2\"],[\"64457.4\",\"11.19\",\"0\",\"2\"],[\"64456.9\",\"0\",\"0\",\"0\"],[\"64456.2\",\"21.88\",\"0\",\"3\"],[\"64452.7\",\"323.76\",\"0\",\"5\"],[\"64446.8\",\"41.94\",\"0\",\"2\"],[\"64444.8\",\"10.32\",\"0\",\"3\"],[\"64444.5\",\"156.73\",\"0\",\"4\"],[\"64440.1\",\"512.18\",\"0\",\"2\"],[\"64439.5\",\"0\",\"0\",\"0\"],[\"64439\",\"0\",\"0\",\"0\"],[\"64422\",\"0.01\",\"0\",\"1\"],[\"64421.9\",\"0.01\",\"0\",\"1\"],[\"64421.8\",\"0.03\",\"0\",\"2\"],[\"64421.6\",\"15.65\",\"0\",\"1\"],[\"64421.5\",\"0.01\",\"0\",\"1\"],[\"64421.3\",\"0.03\",\"0\",\"2\"]],\"ts\":\"1782016027405\",\"checksum\":1390467547,\"seqId\":325070072258,\"prevSeqId\":325070072126}]}"}
{"action": "update", "capture_sequence": 131, "channel": "books", "connection_sequence": 1, "event": null, "instId": "BTC-USDT-SWAP", "local_receive_ts": "2026-06-21T04:27:07Z", "monotonic_ns": 1643583413392667, "raw": "{\"arg\":{\"channel\":\"books\",\"instId\":\"BTC-USDT-SWAP\"},\"action\":\"update\",\"data\":[{\"asks\":[[\"64480\",\"86.12\",\"0\",\"14\"],[\"64484.9\",\"15.67\",\"0\",\"2\"],[\"64485.6\",\"0\",\"0\",\"0\"],[\"64492.3\",\"15.19\",\"0\",\"2\"],[\"64492.4\",\"19.45\",\"0\",\"10\"],[\"64492.6\",\"60.6\",\"0\",\"1\"],[\"64495\",\"24.44\",\"0\",\"10\"],[\"64495.8\",\"0.04\",\"0\",\"3\"],[\"64496.9\",\"0\",\"0\",\"0\"],[\"64497.4\",\"45.31\",\"0\",\"3\"],[\"64497.8\",\"4.18\",\"0\",\"3\"],[\"64503.4\",\"0\",\"0\",\"0\"],[\"64504.3\",\"1.59\",\"0\",\"3\"],[\"64505.7\",\"132.59\",\"0\",\"3\"],[\"64507.1\",\"0.83\",\"0\",\"5\"],[\"64507.3\",\"33.82\",\"0\",\"3\"],[\"64507.9\",\"0.27\",\"0\",\"4\"],[\"64509\",\"215.66\",\"0\",\"3\"],[\"64511.9\",\"85.47\",\"0\",\"2\"],[\"64513.8\",\"0.01\",\"0\",\"1\"],[\"64513.9\",\"58.3\",\"0\",\"2\"],[\"64515.4\",\"0.46\",\"0\",\"5\"],[\"64518.7\",\"20.06\",\"0\",\"1\"],[\"64519\",\"0.67\",\"0\",\"4\"],[\"64525.8\",\"0.02\",\"0\",\"2\"]],\"bids\":[[\"64479.9\",\"1398.91\",\"0\",\"65\"],[\"64479.8\",\"240.43\",\"0\",\"18\"],[\"64478.9\",\"0.01\",\"0\",\"1\"],[\"64478.8\",\"1.56\",\"0\",\"1\"],[\"64477.1\",\"77.56\",\"0\",\"3\"],[\"64476.6\",\"0.02\",\"0\",\"2\"],[\"64474.1\",\"38.82\",\"0\",\"5\"],[\"64470.2\",\"0\",\"0\",\"0\"],[\"64469.9\",\"0\",\"0\",\"0\"],[\"64469.7\",\"25.16\",\"0\",\"4\"],[\"64468.9\",\"0.61\",\"0\",\"2\"],[\"64468.7\",\"86.35\",\"0\",\"8\"],[\"64468.4\",\"1.68\",\"0\",\"1\"],[\"64468.2\",\"116.81\",\"0\",\"4\"],[\"64467.8\",\"2.17\",\"0\",\"2\"],[\"64467.5\",\"0.03\",\"0\",\"2\"],[\"64467.3\",\"98.53\",\"0\",\"3\"],[\"64466.9\",\"170.6\",\"0\",\"7\"],[\"64466.5\",\"18.68\",\"0\",\"2\"],[\"64466.3\",\"85.39\",\"0\",\"1\"],[\"64464.9\",\"31.06\",\"0\",\"1\"],[\"64464.7\",\"58.22\",\"0\",\"1\"],[\"64464.1\",\"0.02\",\"0\",\"1\"],[\"64463.5\",\"0.01\",\"0\",\"1\"],[\"64440.2\",\"354.51\",\"0\",\"2\"],[\"64439.9\",\"46.54\",\"0\",\"1\"]],\"ts\":\"1782016027505\",\"checksum\":-1820747345,\"seqId\":325070072340,\"prevSeqId\":325070072258}]}"}
{"action": null, "capture_sequence": 132, "channel": "trades", "connection_sequence": 1, "event": null, "instId": "BTC-USDT-SWAP", "local_receive_ts": "2026-06-21T04:27:07Z", "monotonic_ns": 1643583455183001, "raw": "{\"arg\":{\"channel\":\"trades\",\"instId\":\"BTC-USDT-SWAP\"},\"data\":[{\"instId\":\"BTC-USDT-SWAP\",\"tradeId\":\"2718750206\",\"px\":\"64480\",\"sz\":\"86.12\",\"side\":\"buy\",\"ts\":\"1782016027551\",\"count\":\"14\",\"source\":\"0\",\"seqId\":325070072403}]}"}
{"action": null, "capture_sequence": 133, "channel": "trades", "connection_sequence": 1, "event": null, "instId": "BTC-USDT-SWAP", "local_receive_ts": "2026-06-21T04:27:07Z", "monotonic_ns": 1643583461812504, "raw": "{\"arg\":{\"channel\":\"trades\",\"instId\":\"BTC-USDT-SWAP\"},\"data\":[{\"instId\":\"BTC-USDT-SWAP\",\"tradeId\":\"2718750207\",\"px\":\"64480.1\",\"sz\":\"0.01\",\"side\":\"buy\",\"ts\":\"1782016027553\",\"count\":\"1\",\"source\":\"0\",\"seqId\":325070072450}]}"}
{"action": null, "capture_sequence": 134, "channel": "trades", "connection_sequence": 1, "event": null, "instId": "BTC-USDT-SWAP", "local_receive_ts": "2026-06-21T04:27:07Z", "monotonic_ns": 1643583462091164, "raw": "{\"arg\":{\"channel\":\"trades\",\"instId\":\"BTC-USDT-SWAP\"},\"data\":[{\"instId\":\"BTC-USDT-SWAP\",\"tradeId\":\"2718750208\",\"px\":\"64481\",\"sz\":\"0.01\",\"side\":\"buy\",\"ts\":\"1782016027553\",\"count\":\"1\",\"source\":\"0\",\"seqId\":325070072450}]}"}
{"action": null, "capture_sequence": 135, "channel": "trades", "connection_sequence": 1, "event": null, "instId": "BTC-USDT-SWAP", "local_receive_ts": "2026-06-21T04:27:07Z", "monotonic_ns": 1643583462212452, "raw": "{\"arg\":{\"channel\":\"trades\",\"instId\":\"BTC-USDT-SWAP\"},\"data\":[{\"instId\":\"BTC-USDT-SWAP\",\"tradeId\":\"2718750210\",\"px\":\"64481.5\",\"sz\":\"0.03\",\"side\":\"buy\",\"ts\":\"1782016027553\",\"count\":\"2\",\"source\":\"0\",\"seqId\":325070072450}]}"}
{"action": null, "capture_sequence": 136, "channel": "trades", "connection_sequence": 1, "event": null, "instId": "BTC-USDT-SWAP", "local_receive_ts": "2026-06-21T04:27:07Z", "monotonic_ns": 1643583462321754, "raw": "{\"arg\":{\"channel\":\"trades\",\"instId\":\"BTC-USDT-SWAP\"},\"data\":[{\"instId\":\"BTC-USDT-SWAP\",\"tradeId\":\"2718750213\",\"px\":\"64481.8\",\"sz\":\"0.04\",\"side\":\"buy\",\"ts\":\"1782016027553\",\"count\":\"3\",\"source\":\"0\",\"seqId\":325070072450}]}"}
{"action": null, "capture_sequence": 137, "channel": "trades", "connection_sequence": 1, "event": null, "instId": "BTC-USDT-SWAP", "local_receive_ts": "2026-06-21T04:27:07Z", "monotonic_ns": 1643583462423912, "raw": "{\"arg\":{\"channel\":\"trades\",\"instId\":\"BTC-USDT-SWAP\"},\"data\":[{\"instId\":\"BTC-USDT-SWAP\",\"tradeId\":\"2718750214\",\"px\":\"64481.9\",\"sz\":\"0.01\",\"side\":\"buy\",\"ts\":\"1782016027553\",\"count\":\"1\",\"source\":\"0\",\"seqId\":325070072450}]}"}
{"action": null, "capture_sequence": 138, "channel": "trades", "connection_sequence": 1, "event": null, "instId": "BTC-USDT-SWAP", "local_receive_ts": "2026-06-21T04:27:07Z", "monotonic_ns": 1643583462523227, "raw": "{\"arg\":{\"channel\":\"trades\",\"instId\":\"BTC-USDT-SWAP\"},\"data\":[{\"instId\":\"BTC-USDT-SWAP\",\"tradeId\":\"2718750215\",\"px\":\"64482\",\"sz\":\"0.03\",\"side\":\"buy\",\"ts\":\"1782016027553\",\"count\":\"1\",\"source\":\"0\",\"seqId\":325070072450}]}"}
{"action": null, "capture_sequence": 139, "channel": "trades", "connection_sequence": 1, "event": null, "instId": "BTC-USDT-SWAP", "local_receive_ts": "2026-06-21T04:27:07Z", "monotonic_ns": 1643583462631117, "raw": "{\"arg\":{\"channel\":\"trades\",\"instId\":\"BTC-USDT-SWAP\"},\"data\":[{\"instId\":\"BTC-USDT-SWAP\",\"tradeId\":\"2718750216\",\"px\":\"64482.1\",\"sz\":\"0.01\",\"side\":\"buy\",\"ts\":\"1782016027553\",\"count\":\"1\",\"source\":\"0\",\"seqId\":325070072450}]}"}
{"action": null, "capture_sequence": 140, "channel": "trades", "connection_sequence": 1, "event": null, "instId": "BTC-USDT-SWAP", "local_receive_ts": "2026-06-21T04:27:07Z", "monotonic_ns": 1643583462731494, "raw": "{\"arg\":{\"channel\":\"trades\",\"instId\":\"BTC-USDT-SWAP\"},\"data\":[{\"instId\":\"BTC-USDT-SWAP\",\"tradeId\":\"2718750217\",\"px\":\"64482.5\",\"sz\":\"0.02\",\"side\":\"buy\",\"ts\":\"1782016027553\",\"count\":\"1\",\"source\":\"0\",\"seqId\":325070072450}]}"}
{"action": null, "capture_sequence": 141, "channel": "trades", "connection_sequence": 1, "event": null, "instId": "BTC-USDT-SWAP", "local_receive_ts": "2026-06-21T04:27:07Z", "monotonic_ns": 1643583462833079, "raw": "{\"arg\":{\"channel\":\"trades\",\"instId\":\"BTC-USDT-SWAP\"},\"data\":[{\"instId\":\"BTC-USDT-SWAP\",\"tradeId\":\"2718750219\",\"px\":\"64482.6\",\"sz\":\"0.02\",\"side\":\"buy\",\"ts\":\"1782016027553\",\"count\":\"2\",\"source\":\"0\",\"seqId\":325070072450}]}"}
{"action": null, "capture_sequence": 142, "channel": "trades", "connection_sequence": 1, "event": null, "instId": "BTC-USDT-SWAP", "local_receive_ts": "2026-06-21T04:27:07Z", "monotonic_ns": 1643583462931328, "raw": "{\"arg\":{\"channel\":\"trades\",\"instId\":\"BTC-USDT-SWAP\"},\"data\":[{\"instId\":\"BTC-USDT-SWAP\",\"tradeId\":\"2718750221\",\"px\":\"64482.7\",\"sz\":\"1.01\",\"side\":\"buy\",\"ts\":\"1782016027553\",\"count\":\"2\",\"source\":\"0\",\"seqId\":325070072494}]}"}
{"action": null, "capture_sequence": 143, "channel": "trades", "connection_sequence": 1, "event": null, "instId": "BTC-USDT-SWAP", "local_receive_ts": "2026-06-21T04:27:07Z", "monotonic_ns": 1643583463046332, "raw": "{\"arg\":{\"channel\":\"trades\",\"instId\":\"BTC-USDT-SWAP\"},\"data\":[{\"instId\":\"BTC-USDT-SWAP\",\"tradeId\":\"2718750224\",\"px\":\"64482.8\",\"sz\":\"0.03\",\"side\":\"buy\",\"ts\":\"1782016027553\",\"count\":\"3\",\"source\":\"0\",\"seqId\":325070072494}]}"}
{"action": null, "capture_sequence": 144, "channel": "trades", "connection_sequence": 1, "event": null, "instId": "BTC-USDT-SWAP", "local_receive_ts": "2026-06-21T04:27:07Z", "monotonic_ns": 1643583463151595, "raw": "{\"arg\":{\"channel\":\"trades\",\"instId\":\"BTC-USDT-SWAP\"},\"data\":[{\"instId\":\"BTC-USDT-SWAP\",\"tradeId\":\"2718750225\",\"px\":\"64482.9\",\"sz\":\"0.01\",\"side\":\"buy\",\"ts\":\"1782016027556\",\"count\":\"1\",\"source\":\"0\",\"seqId\":325070073346}]}"}
{"action": "update", "capture_sequence": 145, "channel": "books", "connection_sequence": 1, "event": null, "instId": "BTC-USDT-SWAP", "local_receive_ts": "2026-06-21T04:27:07Z", "monotonic_ns": 1643583532597699, "raw": "{\"arg\":{\"channel\":\"books\",\"instId\":\"BTC-USDT-SWAP\"},\"action\":\"update\",\"data\":[{\"asks\":[[\"64480\",\"0\",\"0\",\"0\"],[\"64480.1\",\"0\",\"0\",\"0\"],[\"64481\",\"0\",\"0\",\"0\"],[\"64481.5\",\"0\",\"0\",\"0\"],[\"64481.8\",\"0\",\"0\",\"0\"],[\"64481.9\",\"0\",\"0\",\"0\"],[\"64482\",\"0\",\"0\",\"0\"],[\"64482.1\",\"0\",\"0\",\"0\"],[\"64482.5\",\"0\",\"0\",\"0\"],[\"64482.6\",\"0\",\"0\",\"0\"],[\"64482.7\",\"0\",\"0\",\"0\"],[\"64482.8\",\"0\",\"0\",\"0\"],[\"64482.9\",\"0\",\"0\",\"0\"],[\"64483\",\"10.03\",\"0\",\"4\"],[\"64483.3\",\"0.04\",\"0\",\"1\"],[\"64483.4\",\"0\",\"0\",\"0\"],[\"64483.5\",\"0\",\"0\",\"0\"],[\"64483.6\",\"0\",\"0\",\"0\"],[\"64483.7\",\"0.01\",\"0\",\"1\"],[\"64483.9\",\"0.01\",\"0\",\"1\"],[\"64484\",\"0.51\",\"0\",\"2\"],[\"64484.2\",\"0\",\"0\",\"0\"],[\"64484.3\",\"0\",\"0\",\"0\"],[\"64484.5\",\"0.06\",\"0\",\"3\"],[\"64484.6\",\"1.21\",\"0\",\"2\"],[\"64484.8\",\"0.03\",\"0\",\"3\"],[\"64484.9\",\"41.02\",\"0\",\"3\"],[\"64485\",\"41.96\",\"0\",\"3\"],[\"64485.1\",\"0\",\"0\",\"0\"],[\"64485.2\",\"0.03\",\"0\",\"3\"],[\"64485.4\",\"0.01\",\"0\",\"1\"],[\"64485.5\",\"0.01\",\"0\",\"1\"],[\"64485.7\",\"0.35\",\"0\",\"5\"],[\"64485.8\",\"1.2\",\"0\",\"6\"],[\"64485.9\",\"20.63\",\"0\",\"2\"],[\"64486.2\",\"0.16\",\"0\",\"5\"],[\"64486.4\",\"1.27\",\"0\",\"2\"],[\"64486.6\",\"65.31\",\"0\",\"3\"],[\"64487.4\",\"0.5\",\"0\",\"6\"],[\"64487.5\",\"16.06\",\"0\",\"5\"],[\"64487.8\",\"0.1\",\"0\",\"4\"],[\"64488.2\",\"3.96\",\"0\",\"2\"],[\"64488.7\",\"6.24\",\"0\",\"2\"],[\"64489.3\",\"23.24\",\"0\",\"4\"],[\"64489.5\",\"0.02\",\"0\",\"2\"],[\"64489.7\",\"0.8\",\"0\",\"1\"],[\"64490\",\"56.15\",\"0\",\"20\"],[\"64490.5\",\"137.94\",\"0\",\"4\"],[\"64490.6\",\"31.51\",\"0\",\"4\"],[\"64490.9\",\"0.95\",\"0\",\"4\"],[\"64491.7\",\"15.94\",\"0\",\"3\"],[\"64492.3\",\"0.03\",\"0\",\"1\"],[\"64492.4\",\"0.08\",\"0\",\"6\"],[\"64492.8\",\"0.44\",\"0\",\"9\"],[\"64493.3\",\"20.11\",\"0\",\"6\"],[\"64493.6\",\"0\",\"0\",\"0\"],[\"64494.1\",\"0.01\",\"0\",\"1\"],[\"64494.6\",\"13.05\",\"0\",\"6\"],[\"64495\",\"1.49\",\"0\",\"8\"],[\"64495.8\",\"34.99\",\"0\",\"4\"],[\"64495.9\",\"19.44\",\"0\",\"6\"],[\"64496.2\",\"3.93\",\"0\",\"1\"],[\"64496.3\",\"543.62\",\"0\",\"7\"],[\"64496.4\",\"496.55\",\"0\",\"3\"],[\"64497.4\",\"37.31\",\"0\",\"2\"],[\"64498\",\"24.62\",\"0\",\"4\"],[\"64498.1\",\"20.03\",\"0\",\"6\"],[\"64498.5\",\"23.45\",\"0\",\"5\"],[\"64498.8\",\"0.02\",\"0\",\"2\"],[\"64499.1\",\"3.41\",\"0\",\"6\"],[\"64499.3\",\"0\",\"0\",\"0\"],[\"64501.2\",\"0.03\",\"0\",\"3\"],[\"64501.4\",\"15.52\",\"0\",\"2\"],[\"64501.6\",\"1.89\",\"0\",\"3\"],[\"64501.9\",\"0.08\",\"0\",\"1\"],[\"64502.2\",\"0.13\",\"0\",\"5\"],[\"64502.4\",\"0.19\",\"0\",\"6\"],[\"64502.7\",\"0.03\",\"0\",\"3\"],[\"64503\",\"15.95\",\"0\",\"3\"],[\"64503.1\",\"40\",\"0\",\"9\"],[\"64504.1\",\"15.12\",\"0\",\"7\"],[\"64504.2\",\"527.98\",\"0\",\"5\"],[\"64504.3\",\"0.04\",\"0\",\"2\"],[\"64505\",\"233.58\",\"0\",\"4\"],[\"64505.5\",\"5.78\",\"0\",\"3\"],[\"64505.7\",\"0.56\",\"0\",\"1\"],[\"64507\",\"1.61\",\"0\",\"2\"],[\"64507.1\",\"0.06\",\"0\",\"4\"],[\"64507.3\",\"0.03\",\"0\",\"2\"],[\"64507.4\",\"27.27\",\"0\",\"1\"],[\"64508.7\",\"15.67\",\"0\",\"7\"],[\"64508.9\",\"161.73\",\"0\",\"5\"],[\"64509.8\",\"34.57\",\"0\",\"3\"],[\"64510.7\",\"1.02\",\"0\",\"3\"],[\"64511.6\",\"0\",\"0\",\"0\"],[\"64511.9\",\"0.14\",\"0\",\"1\"],[\"64513.6\",\"10\",\"0\",\"1\"],[\"64513.9\",\"0.12\",\"0\",\"1\"],[\"64514.1\",\"0.03\",\"0\",\"3\"],[\"64515.4\",\"85.79\",\"0\",\"6\"],[\"64518\",\"111.04\",\"0\",\"13\"],[\"64518.7\",\"0\",\"0\",\"0\"],[\"64518.9\",\"58.18\",\"0\",\"2\"],[\"64519.3\",\"15.7\",\"0\",\"3\"],[\"64519.8\",\"89.37\",\"0\",\"5\"],[\"64519.9\",\"496.56\",\"0\",\"2\"],[\"64520.8\",\"20.1\",\"0\",\"3\"],[\"64520.9\",\"0.02\",\"0\",\"2\"],[\"64521.3\",\"46.5\",\"0\",\"2\"],[\"64521.5\",\"7.76\",\"0\",\"8\"],[\"64523.1\",\"86.11\",\"0\",\"2\"],[\"64523.3\",\"186.34\",\"0\",\"3\"],[\"64523.6\",\"0.03\",\"0\",\"1\"],[\"64523.7\",\"43.33\",\"0\",\"3\"],[\"64524.4\",\"0\",\"0\",\"0\"],[\"64525.9\",\"2.69\",\"0\",\"4\"],[\"64526\",\"1.15\",\"0\",\"3\"],[\"64526.1\",\"15.65\",\"0\",\"1\"],[\"64526.2\",\"6.57\",\"0\",\"2\"],[\"64526.3\",\"2.95\",\"0\",\"1\"],[\"64526.4\",\"46.54\",\"0\",\"1\"],[\"64526.5\",\"60\",\"0\",\"3\"],[\"64526.6\",\"14.22\",\"0\",\"3\"],[\"64526.7\",\"0.01\",\"0\",\"1\"],[\"64526.8\",\"0.37\",\"0\",\"2\"],[\"64526.9\",\"40.21\",\"0\",\"5\"],[\"64527\",\"0.17\",\"0\",\"3\"],[\"64527.1\",\"0.46\",\"0\",\"1\"],[\"64527.2\",\"0.17\",\"0\",\"3\"],[\"64527.3\",\"0.05\",\"0\",\"5\"],[\"64527.4\",\"0.27\",\"0\",\"2\"],[\"64527.5\",\"0.19\",\"0\",\"5\"],[\"64527.6\",\"16.48\",\"0\",\"5\"],[\"64527.7\",\"496.55\",\"0\",\"2\"],[\"64527.8\",\"0.03\",\"0\",\"2\"],[\"64527.9\",\"0.01\",\"0\",\"1\"]],\"bids\":[[\"64482.9\",\"1053.92\",\"0\",\"65\"],[\"64482.8\",\"167.91\",\"0\",\"5\"],[\"64482.5\",\"0.02\",\"0\",\"1\"],[\"64482.2\",\"0.33\",\"0\",\"2\"],[\"64482.1\",\"46.56\",\"0\",\"2\"],[\"64482\",\"5.01\",\"0\",\"2\"],[\"64481.6\",\"0.01\",\"0\",\"1\"],[\"64481.4\",\"12\",\"0\",\"2\"],[\"64481\",\"0.03\",\"0\",\"2\"],[\"64480.9\",\"71.8\",\"0\",\"1\"],[\"64480.1\",\"77.55\",\"0\",\"2\"],[\"64480\",\"326.87\",\"0\",\"9\"],[\"64479.9\",\"36.51\",\"0\",\"7\"],[\"64479.8\",\"214.95\",\"0\",\"12\"],[\"64479.7\",\"0.59\",\"0\",\"2\"],[\"64479.6\",\"0.01\",\"0\",\"1\"],[\"64479.5\",\"0\",\"0\",\"0\"],[\"64479.4\",\"0.01\",\"0\",\"1\"],[\"64479.2\",\"78.37\",\"0\",\"1\"],[\"64479.1\",\"0\",\"0\",\"0\"],[\"64479\",\"0\",\"0\",\"0\"],[\"64477.7\",\"16.26\",\"0\",\"6\"],[\"64477.5\",\"0.3\",\"0\",\"1\"],[\"64477.4\",\"0.01\",\"0\",\"1\"],[\"64477.1\",\"0.02\",\"0\",\"2\"],[\"64477\",\"4.65\",\"0\",\"2\"],[\"64476.9\",\"0.02\",\"0\",\"2\"],[\"64476.8\",\"0\",\"0\",\"0\"],[\"64476.5\",\"11.4\",\"0\",\"1\"],[\"64475.5\",\"1.87\",\"0\",\"1\"],[\"64475.1\",\"69.62\",\"0\",\"3\"],[\"64475\",\"68.83\",\"0\",\"2\"],[\"64474.4\",\"0\",\"0\",\"0\"],[\"64474.2\",\"3.1\",\"0\",\"3\"],[\"64474.1\",\"37.28\",\"0\",\"3\"],[\"64473.9\",\"46.57\",\"0\",\"3\"],[\"64473.4\",\"0.3\",\"0\",\"1\"],[\"64472.3\",\"0.01\",\"0\",\"1\"],[\"64472.1\",\"0.02\",\"0\",\"2\"],[\"64472\",\"70.33\",\"0\",\"5\"],[\"64471.7\",\"30.92\",\"0\",\"2\"],[\"64471.6\",\"0.03\",\"0\",\"1\"],[\"64471.5\",\"86.17\",\"0\",\"2\"],[\"64471.3\",\"0.38\",\"0\",\"1\"],[\"64470.5\",\"34.9\",\"0\",\"4\"],[\"64470.3\",\"32.09\",\"0\",\"4\"],[\"64470.1\",\"0\",\"0\",\"0\"],[\"64469.9\",\"95.77\",\"0\",\"3\"],[\"64469.6\",\"85.4\",\"0\",\"2\"],[\"64469.4\",\"58.97\",\"0\",\"3\"],[\"64469.3\",\"498.45\",\"0\",\"2\"],[\"64469.2\",\"154.77\",\"0\",\"3\"],[\"64468.9\",\"0.3\",\"0\",\"1\"],[\"64468.8\",\"11.33\",\"0\",\"1\"],[\"64468.7\",\"86.09\",\"0\",\"7\"],[\"64468.2\",\"62.15\",\"0\",\"1\"],[\"64467.6\",\"2.79\",\"0\",\"4\"],[\"64466.9\",\"3.32\",\"0\",\"3\"],[\"64466.8\",\"18.96\",\"0\",\"2\"],[\"64466.4\",\"31.05\",\"0\",\"1\"],[\"64466.3\",\"0\",\"0\",\"0\"],[\"64466.2\",\"0.01\",\"0\",\"1\"],[\"64466.1\",\"233.28\",\"0\",\"2\"],[\"64466\",\"37.25\",\"0\",\"5\"],[\"64465.9\",\"0\",\"0\",\"0\"],[\"64465.7\",\"6.22\",\"0\",\"1\"],[\"64465.4\",\"507.87\",\"0\",\"3\"],[\"64465.3\",\"46.58\",\"0\",\"4\"],[\"64464.7\",\"1\",\"0\",\"1\"],[\"64463.9\",\"0\",\"0\",\"0\"],[\"64463.8\",\"347.78\",\"0\",\"2\"],[\"64463.6\",\"0.13\",\"0\",\"2\"],[\"64463.4\",\"0\",\"0\",\"0\"],[\"64462.8\",\"15.65\",\"0\",\"1\"],[\"64462.7\",\"0\",\"0\",\"0\"],[\"64462.5\",\"0\",\"0\",\"0\"],[\"64461.7\",\"0.01\",\"0\",\"1\"],[\"64461.4\",\"14.24\",\"0\",\"4\"],[\"64460.8\",\"154.63\",\"0\",\"4\"],[\"64460.5\",\"0\",\"0\",\"0\"],[\"64458\",\"76.93\",\"0\",\"2\"],[\"64457.9\",\"0.01\",\"0\",\"1\"],[\"64457.2\",\"14.15\",\"0\",\"1\"],[\"64457.1\",\"419.23\",\"0\",\"5\"],[\"64457\",\"574.33\",\"0\",\"6\"],[\"64456.9\",\"0.02\",\"0\",\"1\"],[\"64456.5\",\"0.81\",\"0\",\"2\"],[\"64456.4\",\"15.65\",\"0\",\"1\"],[\"64456.3\",\"37.24\",\"0\",\"2\"],[\"64455.8\",\"15.66\",\"0\",\"2\"],[\"64455.2\",\"16.19\",\"0\",\"6\"],[\"64455\",\"46.54\",\"0\",\"1\"],[\"64454.6\",\"31.31\",\"0\",\"3\"],[\"64454.5\",\"0.01\",\"0\",\"1\"],[\"64453.9\",\"38.83\",\"0\",\"1\"],[\"64453.1\",\"0.5\",\"0\",\"1\"],[\"64452.7\",\"309.55\",\"0\",\"4\"],[\"64452\",\"10.16\",\"0\",\"5\"],[\"64451.1\",\"21.6\",\"0\",\"2\"],[\"64450.6\",\"155.91\",\"0\",\"1\"],[\"64450.3\",\"0.03\",\"0\",\"2\"],[\"64449.9\",\"273.58\",\"0\",\"3\"],[\"64449.5\",\"0.01\",\"0\",\"1\"],[\"64449\",\"0.02\",\"0\",\"2\"],[\"64447.9\",\"0\",\"0\",\"0\"],[\"64446.7\",\"6.22\",\"0\",\"3\"],[\"64446\",\"35.77\",\"0\",\"6\"],[\"64445.6\",\"0\",\"0\",\"0\"],[\"64444.5\",\"156.71\",\"0\",\"3\"],[\"64444.2\",\"10.01\",\"0\",\"2\"],[\"64444.1\",\"159.26\",\"0\",\"5\"],[\"64442\",\"15.01\",\"0\",\"2\"],[\"64441.1\",\"1.57\",\"0\",\"1\"],[\"64440.9\",\"0.01\",\"0\",\"1\"],[\"64440.6\",\"0\",\"0\",\"0\"],[\"64440.1\",\"496.53\",\"0\",\"1\"],[\"64440\",\"23.43\",\"0\",\"17\"],[\"64439.8\",\"92.79\",\"0\",\"1\"],[\"64439.6\",\"0\",\"0\",\"0\"],[\"64438.7\",\"0\",\"0\",\"0\"],[\"64437.6\",\"0.01\",\"0\",\"1\"],[\"64437.2\",\"15.46\",\"0\",\"2\"],[\"64435\",\"164.23\",\"0\",\"4\"],[\"64434.5\",\"0\",\"0\",\"0\"],[\"64434.4\",\"20\",\"0\",\"1\"],[\"64434\",\"0\",\"0\",\"0\"],[\"64431.9\",\"517.26\",\"0\",\"2\"],[\"64430.2\",\"15.73\",\"0\",\"2\"],[\"64430.1\",\"0\",\"0\",\"0\"],[\"64429.8\",\"0.01\",\"0\",\"1\"],[\"64428\",\"341.64\",\"0\",\"5\"],[\"64427.9\",\"0\",\"0\",\"0\"],[\"64427\",\"266.81\",\"0\",\"5\"],[\"64423.8\",\"294.94\",\"0\",\"4\"],[\"64423.3\",\"512.29\",\"0\",\"3\"],[\"64422.5\",\"0\",\"0\",\"0\"],[\"64422.2\",\"0\",\"0\",\"0\"],[\"64422\",\"0\",\"0\",\"0\"],[\"64421.9\",\"0\",\"0\",\"0\"],[\"64421.8\",\"0\",\"0\",\"0\"],[\"64421.6\",\"0\",\"0\",\"0\"],[\"64421.5\",\"0\",\"0\",\"0\"],[\"64421.3\",\"0\",\"0\",\"0\"]],\"ts\":\"1782016027605\",\"checksum\":-1683647010,\"seqId\":325070074599,\"prevSeqId\":325070072340}]}"}
{"action": null, "capture_sequence": 146, "channel": "trades", "connection_sequence": 1, "event": null, "instId": "BTC-USDT-SWAP", "local_receive_ts": "2026-06-21T04:27:07Z", "monotonic_ns": 1643583591056118, "raw": "{\"arg\":{\"channel\":\"trades\",\"instId\":\"BTC-USDT-SWAP\"},\"data\":[{\"instId\":\"BTC-USDT-SWAP\",\"tradeId\":\"2718750227\",\"px\":\"64482.9\",\"sz\":\"0.18\",\"side\":\"sell\",\"ts\":\"1782016027688\",\"count\":\"2\",\"source\":\"0\",\"seqId\":325070074956}]}"}
{"action": "update", "capture_sequence": 147, "channel": "books", "connection_sequence": 1, "event": null, "instId": "BTC-USDT-SWAP", "local_receive_ts": "2026-06-21T04:27:07Z", "monotonic_ns": 1643583618317473, "raw": "{\"arg\":{\"channel\":\"books\",\"instId\":\"BTC-USDT-SWAP\"},\"action\":\"update\",\"data\":[{\"asks\":[[\"64483\",\"116.19\",\"0\",\"8\"],[\"64484.8\",\"0.79\",\"0\",\"3\"],[\"64484.9\",\"45.34\",\"0\",\"4\"],[\"64485.8\",\"0.43\",\"0\",\"5\"],[\"64485.9\",\"5.43\",\"0\",\"2\"],[\"64486\",\"52.08\",\"0\",\"6\"],[\"64486.6\",\"130.22\",\"0\",\"3\"],[\"64486.9\",\"1.11\",\"0\",\"2\"],[\"64487.5\",\"0.54\",\"0\",\"4\"],[\"64487.9\",\"17.23\",\"0\",\"4\"],[\"64489\",\"155.23\",\"0\",\"9\"],[\"64489.1\",\"1.54\",\"0\",\"4\"],[\"64490.1\",\"18.18\",\"0\",\"4\"],[\"64490.5\",\"1.81\",\"0\",\"3\"],[\"64493.1\",\"41.62\",\"0\",\"6\"],[\"64495.2\",\"1.32\",\"0\",\"3\"],[\"64495.8\",\"167.02\",\"0\",\"6\"],[\"64496.7\",\"0.01\",\"0\",\"1\"],[\"64497.6\",\"0.13\",\"0\",\"3\"],[\"64497.8\",\"4.01\",\"0\",\"2\"],[\"64498\",\"24.4\",\"0\",\"3\"],[\"64498.6\",\"0.29\",\"0\",\"6\"],[\"64502.7\",\"0.2\",\"0\",\"4\"],[\"64502.9\",\"280.72\",\"0\",\"7\"],[\"64503.1\",\"39.69\",\"0\",\"8\"],[\"64503.2\",\"0.3\",\"0\",\"2\"],[\"64503.4\",\"31.03\",\"0\",\"1\"],[\"64503.8\",\"0.31\",\"0\",\"1\"],[\"64504.1\",\"247.87\",\"0\",\"7\"],[\"64504.2\",\"496.95\",\"0\",\"4\"],[\"64504.3\",\"0.05\",\"0\",\"3\"],[\"64505\",\"0.82\",\"0\",\"3\"],[\"64505.9\",\"2.56\",\"0\",\"3\"],[\"64507\",\"0.06\",\"0\",\"1\"],[\"64507.7\",\"33.86\",\"0\",\"5\"],[\"64509.8\",\"0.78\",\"0\",\"2\"],[\"64513.2\",\"85.48\",\"0\",\"5\"],[\"64514.5\",\"0.74\",\"0\",\"5\"],[\"64515.4\",\"0.46\",\"0\",\"5\"],[\"64515.6\",\"58.27\",\"0\",\"5\"],[\"64518.9\",\"0.01\",\"0\",\"1\"],[\"64519.3\",\"35.76\",\"0\",\"4\"],[\"64520.8\",\"0.04\",\"0\",\"2\"],[\"64520.9\",\"86.12\",\"0\",\"3\"],[\"64521.6\",\"0.02\",\"0\",\"2\"],[\"64523.1\",\"0.01\",\"0\",\"1\"],[\"64523.3\",\"186.35\",\"0\",\"4\"],[\"64523.4\",\"39.42\",\"0\",\"4\"],[\"64523.7\",\"43.32\",\"0\",\"2\"],[\"64524\",\"0.06\",\"0\",\"5\"],[\"64526\",\"1.16\",\"0\",\"4\"],[\"64526.6\",\"14.23\",\"0\",\"4\"],[\"64527.2\",\"0.18\",\"0\",\"4\"],[\"64527.8\",\"0\",\"0\",\"0\"],[\"64527.9\",\"0\",\"0\",\"0\"]],\"bids\":[[\"64482.9\",\"931.4\",\"0\",\"60\"],[\"64482.8\",\"170.01\",\"0\",\"10\"],[\"64482.7\",\"0.02\",\"0\",\"1\"],[\"64482.6\",\"1.91\",\"0\",\"2\"],[\"64482.5\",\"5\",\"0\",\"1\"],[\"64482.2\",\"0.02\",\"0\",\"1\"],[\"64482.1\",\"46.54\",\"0\",\"1\"],[\"64481.4\",\"12.01\",\"0\",\"3\"],[\"64481.2\",\"0.77\",\"0\",\"1\"],[\"64481.1\",\"0.31\",\"0\",\"1\"],[\"64481\",\"0.01\",\"0\",\"1\"],[\"64480.8\",\"0.01\",\"0\",\"1\"],[\"64480.7\",\"0.01\",\"0\",\"1\"],[\"64480.1\",\"0.01\",\"0\",\"1\"],[\"64480\",\"321.89\",\"0\",\"9\"],[\"64479.9\",\"35.71\",\"0\",\"4\"],[\"64479.8\",\"195.68\",\"0\",\"6\"],[\"64479.6\",\"0.02\",\"0\",\"2\"],[\"64479.5\",\"7.19\",\"0\",\"1\"],[\"64479\",\"0.01\",\"0\",\"1\"],[\"64478.9\",\"77.55\",\"0\",\"2\"],[\"64474.2\",\"1.56\",\"0\",\"1\"],[\"64472.5\",\"69.9\",\"0\",\"1\"],[\"64472.1\",\"0.82\",\"0\",\"3\"],[\"64472\",\"0.02\",\"0\",\"2\"],[\"64471.7\",\"0.3\",\"0\",\"1\"],[\"64471.5\",\"0.01\",\"0\",\"1\"],[\"64471.4\",\"46.55\",\"0\",\"2\"],[\"64470.5\",\"1.09\",\"0\",\"3\"],[\"64470.3\",\"12.01\",\"0\",\"3\"],[\"64470.2\",\"1.54\",\"0\",\"2\"],[\"64470.1\",\"86.16\",\"0\",\"1\"],[\"64469.9\",\"170\",\"0\",\"5\"],[\"64469.8\",\"84.34\",\"0\",\"2\"],[\"64469.7\",\"25.18\",\"0\",\"5\"],[\"64469.6\",\"0.01\",\"0\",\"1\"],[\"64468.9\",\"20.38\",\"0\",\"2\"],[\"64468.5\",\"33.81\",\"0\",\"1\"],[\"64467.8\",\"2.72\",\"0\",\"3\"],[\"64467.7\",\"85.39\",\"0\",\"1\"],[\"64467.2\",\"0.02\",\"0\",\"1\"],[\"64466.9\",\"2.88\",\"0\",\"1\"],[\"64466.4\",\"0\",\"0\",\"0\"],[\"64466.1\",\"58.6\",\"0\",\"2\"],[\"64465.7\",\"6.24\",\"0\",\"2\"],[\"64465.5\",\"31.05\",\"0\",\"1\"],[\"64465.3\",\"46.56\",\"0\",\"3\"],[\"64465.2\",\"232.9\",\"0\",\"1\"],[\"64464.3\",\"0\",\"0\",\"0\"],[\"64464.1\",\"0\",\"0\",\"0\"],[\"64463\",\"0.02\",\"0\",\"2\"],[\"64462.4\",\"0.01\",\"0\",\"1\"],[\"64460.3\",\"0\",\"0\",\"0\"],[\"64457\",\"574.34\",\"0\",\"6\"],[\"64456.9\",\"0\",\"0\",\"0\"],[\"64455.3\",\"10\",\"0\",\"1\"],[\"64452.8\",\"30.93\",\"0\",\"4\"],[\"64451.7\",\"201.97\",\"0\",\"3\"],[\"64451.6\",\"25.68\",\"0\",\"5\"],[\"64449.8\",\"83.77\",\"0\",\"2\"],[\"64444\",\"15.69\",\"0\",\"4\"],[\"64443.9\",\"1.83\",\"0\",\"2\"],[\"64442.1\",\"62.19\",\"0\",\"2\"],[\"64441.7\",\"0\",\"0\",\"0\"],[\"64441.3\",\"0\",\"0\",\"0\"],[\"64440.9\",\"0\",\"0\",\"0\"],[\"64431.2\",\"0.38\",\"0\",\"1\"],[\"64428.2\",\"15.65\",\"0\",\"1\"],[\"64423.8\",\"293.11\",\"0\",\"3\"],[\"64423.5\",\"0\",\"0\",\"0\"],[\"64423.2\",\"0\",\"0\",\"0\"],[\"64423.1\",\"0\",\"0\",\"0\"],[\"64423\",\"0\",\"0\",\"0\"],[\"64422.8\",\"0\",\"0\",\"0\"],[\"64422.7\",\"0\",\"0\",\"0\"],[\"64422.6\",\"0\",\"0\",\"0\"],[\"64422.4\",\"0\",\"0\",\"0\"],[\"64422.3\",\"0\",\"0\",\"0\"]],\"ts\":\"1782016027705\",\"checksum\":1985751294,\"seqId\":325070074987,\"prevSeqId\":325070074599}]}"}
{"action": null, "capture_sequence": 148, "channel": "trades", "connection_sequence": 1, "event": null, "instId": "BTC-USDT-SWAP", "local_receive_ts": "2026-06-21T04:27:07Z", "monotonic_ns": 1643583685449437, "raw": "{\"arg\":{\"channel\":\"trades\",\"instId\":\"BTC-USDT-SWAP\"},\"data\":[{\"instId\":\"BTC-USDT-SWAP\",\"tradeId\":\"2718750228\",\"px\":\"64482.9\",\"sz\":\"1.47\",\"side\":\"sell\",\"ts\":\"1782016027782\",\"count\":\"1\",\"source\":\"0\",\"seqId\":325070075058}]}"}
{"action": "update", "capture_sequence": 149, "channel": "books", "connection_sequence": 1, "event": null, "instId": "BTC-USDT-SWAP", "local_receive_ts": "2026-06-21T04:27:07Z", "monotonic_ns": 1643583713341333, "raw": "{\"arg\":{\"channel\":\"books\",\"instId\":\"BTC-USDT-SWAP\"},\"action\":\"update\",\"data\":[{\"asks\":[[\"64483\",\"116.21\",\"0\",\"9\"],[\"64484\",\"0.55\",\"0\",\"3\"],[\"64484.5\",\"0.07\",\"0\",\"4\"],[\"64484.7\",\"0.01\",\"0\",\"1\"],[\"64484.8\",\"15.99\",\"0\",\"4\"],[\"64484.9\",\"30.32\",\"0\",\"3\"],[\"64485.8\",\"0.42\",\"0\",\"4\"],[\"64486.2\",\"0.17\",\"0\",\"6\"],[\"64486.6\",\"131.22\",\"0\",\"4\"],[\"64487.3\",\"1.24\",\"0\",\"3\"],[\"64487.4\",\"16.02\",\"0\",\"7\"],[\"64487.6\",\"1.2\",\"0\",\"1\"],[\"64487.9\",\"1.71\",\"0\",\"3\"],[\"64488.3\",\"1.22\",\"0\",\"3\"],[\"64489.3\",\"23.25\",\"0\",\"5\"],[\"64492.5\",\"93.49\",\"0\",\"4\"],[\"64500\",\"3456.29\",\"0\",\"1036\"],[\"64503.3\",\"232.79\",\"0\",\"3\"],[\"64504.1\",\"15.11\",\"0\",\"6\"],[\"64504.2\",\"511.1\",\"0\",\"6\"],[\"64505.6\",\"59.46\",\"0\",\"5\"],[\"64505.9\",\"1.01\",\"0\",\"2\"],[\"64508.4\",\"2.39\",\"0\",\"6\"],[\"64509.8\",\"0.01\",\"0\",\"1\"],[\"64518\",\"103.04\",\"0\",\"12\"],[\"64518.5\",\"20.07\",\"0\",\"2\"],[\"64519.3\",\"15.7\",\"0\",\"3\"],[\"64520.7\",\"38.4\",\"0\",\"2\"],[\"64527.6\",\"0\",\"0\",\"0\"],[\"64527.7\",\"0\",\"0\",\"0\"]],\"bids\":[[\"64482.9\",\"929.95\",\"0\",\"61\"],[\"64482.8\",\"160.01\",\"0\",\"9\"],[\"64481.1\",\"0\",\"0\",\"0\"],[\"64480.2\",\"0.31\",\"0\",\"1\"],[\"64479.9\",\"39.04\",\"0\",\"6\"],[\"64479.8\",\"195.69\",\"0\",\"7\"],[\"64479.7\",\"0\",\"0\",\"0\"],[\"64478.9\",\"0.01\",\"0\",\"1\"],[\"64478.4\",\"77.54\",\"0\",\"1\"],[\"64473.5\",\"42.85\",\"0\",\"1\"],[\"64470.5\",\"0.32\",\"0\",\"2\"],[\"64470.3\",\"160.92\",\"0\",\"4\"],[\"64469.7\",\"25.16\",\"0\",\"4\"],[\"64469.6\",\"0.78\",\"0\",\"2\"],[\"64468.9\",\"0.3\",\"0\",\"1\"],[\"64468.1\",\"15.96\",\"0\",\"2\"],[\"64467.9\",\"20.09\",\"0\",\"2\"],[\"64467.2\",\"0\",\"0\",\"0\"],[\"64466\",\"37.27\",\"0\",\"6\"],[\"64465.7\",\"6.22\",\"0\",\"1\"],[\"64465.2\",\"0\",\"0\",\"0\"],[\"64465.1\",\"24.02\",\"0\",\"3\"],[\"64465\",\"200\",\"0\",\"1\"],[\"64464.6\",\"0\",\"0\",\"0\"],[\"64464.3\",\"232.91\",\"0\",\"1\"],[\"64461\",\"0\",\"0\",\"0\"],[\"64455.3\",\"56.54\",\"0\",\"2\"],[\"64448.1\",\"0\",\"0\",\"0\"],[\"64442.9\",\"0\",\"0\",\"0\"],[\"64442.5\",\"10\",\"0\",\"1\"],[\"64423.9\",\"0.05\",\"0\",\"1\"],[\"64423.2\",\"37.23\",\"0\",\"1\"],[\"64423.1\",\"92.81\",\"0\",\"2\"],[\"64423\",\"1.59\",\"0\",\"6\"],[\"64422.8\",\"2.29\",\"0\",\"2\"]],\"ts\":\"1782016027805\",\"checksum\":1634242436,\"seqId\":325070075072,\"prevSeqId\":325070074987}]}"}
{"action": "update", "capture_sequence": 150, "channel": "books", "connection_sequence": 1, "event": null, "instId": "BTC-USDT-SWAP", "local_receive_ts": "2026-06-21T04:27:08Z", "monotonic_ns": 1643583808648015, "raw": "{\"arg\":{\"channel\":\"books\",\"instId\":\"BTC-USDT-SWAP\"},\"action\":\"update\",\"data\":[{\"asks\":[[\"64483\",\"79.85\",\"0\",\"9\"],[\"64483.1\",\"0.63\",\"0\",\"4\"],[\"64485\",\"41.95\",\"0\",\"2\"],[\"64485.4\",\"0\",\"0\",\"0\"],[\"64485.7\",\"0.34\",\"0\",\"4\"],[\"64487.4\",\"0.5\",\"0\",\"6\"],[\"64487.9\",\"17.23\",\"0\",\"4\"],[\"64488.8\",\"51.2\",\"0\",\"2\"],[\"64489\",\"156.43\",\"0\",\"10\"],[\"64500.7\",\"4.08\",\"0\",\"2\"],[\"64502.7\",\"0.03\",\"0\",\"3\"],[\"64503.3\",\"234.67\",\"0\",\"4\"],[\"64505.5\",\"3.91\",\"0\",\"2\"],[\"64527.6\",\"16.48\",\"0\",\"5\"]],\"bids\":[[\"64482.8\",\"96.2\",\"0\",\"10\"],[\"64479.9\",\"35.71\",\"0\",\"4\"]],\"ts\":\"1782016027905\",\"checksum\":1315781840,\"seqId\":325070075102,\"prevSeqId\":325070075072}]}"}
{"action": null, "capture_sequence": 151, "channel": "trades", "connection_sequence": 2, "event": "subscribe", "instId": "BTC-USDT-SWAP", "local_receive_ts": "2026-06-21T04:27:09Z", "monotonic_ns": 1643585230489978, "raw": "{\"event\":\"subscribe\",\"arg\":{\"channel\":\"trades\",\"instId\":\"BTC-USDT-SWAP\"},\"connId\":\"c032d9dc\"}"}
{"action": null, "capture_sequence": 152, "channel": "books", "connection_sequence": 2, "event": "subscribe", "instId": "BTC-USDT-SWAP", "local_receive_ts": "2026-06-21T04:27:09Z", "monotonic_ns": 1643585230658014, "raw": "{\"event\":\"subscribe\",\"arg\":{\"channel\":\"books\",\"instId\":\"BTC-USDT-SWAP\"},\"connId\":\"c032d9dc\"}"}
{"action": null, "capture_sequence": 153, "channel": "trades", "connection_sequence": 2, "event": null, "instId": "BTC-USDT-SWAP", "local_receive_ts": "2026-06-21T04:27:09Z", "monotonic_ns": 1643585294338390, "raw": "{\"arg\":{\"channel\":\"trades\",\"instId\":\"BTC-USDT-SWAP\"},\"data\":[{\"instId\":\"BTC-USDT-SWAP\",\"tradeId\":\"2718750239\",\"px\":\"64482.9\",\"sz\":\"0.06\",\"side\":\"sell\",\"ts\":\"1782016029375\",\"count\":\"1\",\"source\":\"0\",\"seqId\":325070076227}]}"}
{"action": "snapshot", "capture_sequence": 154, "channel": "books", "connection_sequence": 2, "event": null, "instId": "BTC-USDT-SWAP", "local_receive_ts": "2026-06-21T04:27:09Z", "monotonic_ns": 1643585654249357, "raw": "{\"arg\":{\"channel\":\"books\",\"instId\":\"BTC-USDT-SWAP\"},\"action\":\"snapshot\",\"data\":[{\"asks\":[[\"64483\",\"144.48\",\"0\",\"11\"],[\"64483.1\",\"0.62\",\"0\",\"3\"],[\"64483.2\",\"1.56\",\"0\",\"1\"],[\"64483.3\",\"0.04\",\"0\",\"1\"],[\"64483.7\",\"0.01\",\"0\",\"1\"],[\"64483.9\",\"0.01\",\"0\",\"1\"],[\"64484\",\"0.55\",\"0\",\"3\"],[\"64484.1\",\"0.02\",\"0\",\"1\"],[\"64484.5\",\"0.07\",\"0\",\"4\"],[\"64484.6\",\"77.94\",\"0\",\"4\"],[\"64484.7\",\"0.02\",\"0\",\"2\"],[\"64484.8\",\"16.04\",\"0\",\"4\"],[\"64484.9\",\"0.01\",\"0\",\"1\"],[\"64485\",\"43.51\",\"0\",\"3\"],[\"64485.2\",\"0.02\",\"0\",\"2\"],[\"64485.5\",\"0.01\",\"0\",\"1\"],[\"64485.7\",\"0.34\",\"0\",\"4\"],[\"64485.8\",\"1.98\",\"0\",\"5\"],[\"64485.9\",\"5.43\",\"0\",\"2\"],[\"64486\",\"52.08\",\"0\",\"6\"],[\"64486.2\",\"16.09\",\"0\",\"8\"],[\"64486.3\",\"0.01\",\"0\",\"1\"],[\"64486.4\",\"1.27\",\"0\",\"2\"],[\"64486.5\",\"0.01\",\"0\",\"1\"],[\"64486.6\",\"131.22\",\"0\",\"4\"],[\"64486.8\",\"0.2\",\"0\",\"4\"],[\"64486.9\",\"2.67\",\"0\",\"3\"],[\"64487\",\"5.11\",\"0\",\"4\"],[\"64487.1\",\"0.53\",\"0\",\"4\"],[\"64487.2\",\"0.03\",\"0\",\"2\"],[\"64487.3\",\"1.24\",\"0\",\"3\"],[\"64487.4\",\"2.06\",\"0\",\"7\"],[\"64487.5\",\"0.04\",\"0\",\"3\"],[\"64487.6\",\"1.2\",\"0\",\"1\"],[\"64487.7\",\"0.01\",\"0\",\"1\"],[\"64487.8\",\"0.1\",\"0\",\"4\"],[\"64487.9\",\"3.27\",\"0\",\"4\"],[\"64488\",\"57.87\",\"0\",\"27\"],[\"64488.1\",\"0.66\",\"0\",\"1\"],[\"64488.2\",\"3.96\",\"0\",\"2\"],[\"64488.3\",\"1.22\",\"0\",\"3\"],[\"64488.4\",\"5.67\",\"0\",\"6\"],[\"64488.6\",\"0.02\",\"0\",\"2\"],[\"64488.7\",\"7.44\",\"0\",\"3\"],[\"64488.8\",\"51.56\",\"0\",\"2\"],[\"64488.9\",\"0.33\",\"0\",\"6\"],[\"64489\",\"156.43\",\"0\",\"10\"],[\"64489.1\",\"0.04\",\"0\",\"3\"],[\"64489.2\",\"1.5\",\"0\",\"1\"],[\"64489.3\",\"24.81\",\"0\",\"6\"],[\"64489.4\",\"2.93\",\"0\",\"5\"],[\"64489.5\",\"0.02\",\"0\",\"2\"],[\"64489.6\",\"0.62\",\"0\",\"3\"],[\"64489.7\",\"0.8\",\"0\",\"1\"],[\"64489.8\",\"154.4\",\"0\",\"5\"],[\"64490\",\"56.15\",\"0\",\"20\"],[\"64490.1\",\"18.88\",\"0\",\"4\"],[\"64490.3\",\"1\",\"0\",\"1\"],[\"64490.4\",\"1.59\",\"0\",\"4\"],[\"64490.5\",\"1.81\",\"0\",\"3\"],[\"64490.6\",\"31.51\",\"0\",\"4\"],[\"64490.7\",\"0.06\",\"0\",\"2\"],[\"64490.8\",\"0.02\",\"0\",\"1\"],[\"64490.9\",\"0.45\",\"0\",\"3\"],[\"64491\",\"0.01\",\"0\",\"1\"],[\"64491.2\",\"1.01\",\"0\",\"2\"],[\"64491.3\",\"0.01\",\"0\",\"1\"],[\"64491.4\",\"0.02\",\"0\",\"2\"],[\"64491.5\",\"0.1\",\"0\",\"1\"],[\"64491.6\",\"1.25\",\"0\",\"5\"],[\"64491.7\",\"15.94\",\"0\",\"3\"],[\"64491.8\",\"0.05\",\"0\",\"1\"],[\"64491.9\",\"0.3\",\"0\",\"4\"],[\"64492\",\"0.04\",\"0\",\"4\"],[\"64492.2\",\"0.91\",\"0\",\"7\"],[\"64492.3\",\"0.03\",\"0\",\"1\"],[\"64492.4\",\"0.08\",\"0\",\"6\"],[\"64492.5\",\"93.49\",\"0\",\"4\"],[\"64492.6\",\"60.6\",\"0\",\"1\"],[\"64492.7\",\"99.88\",\"0\",\"3\"],[\"64492.8\",\"0.44\",\"0\",\"9\"],[\"64492.9\",\"0.01\",\"0\",\"1\"],[\"64493\",\"1.3\",\"0\",\"3\"],[\"64493.1\",\"41.62\",\"0\",\"6\"],[\"64493.2\",\"0.07\",\"0\",\"4\"],[\"64493.3\",\"20.27\",\"0\",\"7\"],[\"64493.4\",\"0.32\",\"0\",\"5\"],[\"64493.5\",\"134.25\",\"0\",\"5\"],[\"64493.6\",\"0.02\",\"0\",\"1\"],[\"64493.7\",\"1.25\",\"0\",\"3\"],[\"64493.8\",\"0.03\",\"0\",\"2\"],[\"64494\",\"238.94\",\"0\",\"6\"],[\"64494.1\",\"0.01\",\"0\",\"1\"],[\"64494.2\",\"4.89\",\"0\",\"2\"],[\"64494.3\",\"0.08\",\"0\",\"4\"],[\"64494.4\",\"0.22\",\"0\",\"5\"],[\"64494.6\",\"13.05\",\"0\",\"6\"],[\"64494.7\",\"24.05\",\"0\",\"5\"],[\"64494.8\",\"0.07\",\"0\",\"1\"],[\"64494.9\",\"0.07\",\"0\",\"3\"],[\"64495\",\"1.49\",\"0\",\"8\"],[\"64495.1\",\"0.07\",\"0\",\"3\"],[\"64495.2\",\"2.12\",\"0\",\"3\"],[\"64495.3\",\"0.26\",\"0\",\"2\"],[\"64495.4\",\"22.06\",\"0\",\"4\"],[\"64495.5\",\"0.14\",\"0\",\"5\"],[\"64495.6\",\"0.01\",\"0\",\"1\"],[\"64495.7\",\"29.95\",\"0\",\"6\"],[\"64495.8\",\"167.02\",\"0\",\"6\"],[\"64495.9\",\"0.84\",\"0\",\"3\"],[\"64496\",\"104.13\",\"0\",\"6\"],[\"64496.1\",\"0.06\",\"0\",\"3\"],[\"64496.2\",\"3.93\",\"0\",\"1\"],[\"64496.3\",\"590.16\",\"0\",\"8\"],[\"64496.4\",\"496.55\",\"0\",\"3\"],[\"64496.6\",\"31.68\",\"0\",\"2\"],[\"64496.7\",\"0.01\",\"0\",\"1\"],[\"64496.8\",\"29.39\",\"0\",\"3\"],[\"64497\",\"18.82\",\"0\",\"6\"],[\"64497.1\",\"0.01\",\"0\",\"1\"],[\"64497.2\",\"0.84\",\"0\",\"3\"],[\"64497.3\",\"41.14\",\"0\",\"4\"],[\"64497.4\",\"37.31\",\"0\",\"2\"],[\"64497.5\",\"0.33\",\"0\",\"3\"],[\"64497.6\",\"0.13\",\"0\",\"3\"],[\"64497.8\",\"4.01\",\"0\",\"2\"],[\"64497.9\",\"0.01\",\"0\",\"1\"],[\"64498\",\"24.4\",\"0\",\"3\"],[\"64498.1\",\"20.03\",\"0\",\"6\"],[\"64498.2\",\"0.04\",\"0\",\"3\"],[\"64498.3\",\"84.77\",\"0\",\"6\"],[\"64498.5\",\"23.45\",\"0\",\"5\"],[\"64498.6\",\"0.29\",\"0\",\"6\"],[\"64498.7\",\"2.86\",\"0\",\"4\"],[\"64498.8\",\"0.02\",\"0\",\"2\"],[\"64498.9\",\"49.96\",\"0\",\"3\"],[\"64499\",\"333.09\",\"0\",\"21\"],[\"64499.1\",\"3.41\",\"0\",\"6\"],[\"64499.2\",\"0.01\",\"0\",\"1\"],[\"64499.4\",\"1.73\",\"0\",\"3\"],[\"64499.6\",\"59.37\",\"0\",\"3\"],[\"64499.7\",\"35.37\",\"0\",\"5\"],[\"64499.8\",\"16.59\",\"0\",\"3\"],[\"64499.9\",\"1114.67\",\"0\",\"2\"],[\"64500\",\"3456.31\",\"0\",\"1037\"],[\"64500.1\",\"0.05\",\"0\",\"4\"],[\"64500.2\",\"0.02\",\"0\",\"2\"],[\"64500.3\",\"3.58\",\"0\",\"6\"],[\"64500.4\",\"0.03\",\"0\",\"3\"],[\"64500.5\",\"2.66\",\"0\",\"3\"],[\"64500.6\",\"0.39\",\"0\",\"3\"],[\"64500.7\",\"3.91\",\"0\",\"1\"],[\"64500.8\",\"0.36\",\"0\",\"1\"],[\"64500.9\",\"41.86\",\"0\",\"4\"],[\"64501\",\"0.27\",\"0\",\"3\"],[\"64501.1\",\"0.05\",\"0\",\"2\"],[\"64501.2\",\"0.03\",\"0\",\"3\"],[\"64501.3\",\"0.02\",\"0\",\"1\"],[\"64501.4\",\"0.01\",\"0\",\"1\"],[\"64501.5\",\"1.57\",\"0\",\"4\"],[\"64501.6\",\"1.89\",\"0\",\"3\"],[\"64501.7\",\"0.55\",\"0\",\"4\"],[\"64501.8\",\"91.08\",\"0\",\"8\"],[\"64501.9\",\"0.08\",\"0\",\"1\"],[\"64502\",\"2.12\",\"0\",\"6\"],[\"64502.1\",\"0.01\",\"0\",\"1\"],[\"64502.2\",\"0.13\",\"0\",\"5\"],[\"64502.3\",\"11.26\",\"0\",\"4\"],[\"64502.4\",\"0.19\",\"0\",\"6\"],[\"64502.5\",\"70.1\",\"0\",\"4\"],[\"64502.6\",\"15.66\",\"0\",\"2\"],[\"64502.7\",\"31.06\",\"0\",\"4\"],[\"64502.8\",\"57.07\",\"0\",\"3\"],[\"64502.9\",\"280.72\",\"0\",\"7\"],[\"64503\",\"15.95\",\"0\",\"3\"],[\"64503.1\",\"39.69\",\"0\",\"8\"],[\"64503.2\",\"0.61\",\"0\",\"3\"],[\"64503.3\",\"1.9\",\"0\",\"3\"],[\"64503.4\",\"232.77\",\"0\",\"1\"],[\"64503.5\",\"63.73\",\"0\",\"7\"],[\"64503.6\",\"0.02\",\"0\",\"2\"],[\"64503.7\",\"0.29\",\"0\",\"2\"],[\"64503.9\",\"15.65\",\"0\",\"1\"],[\"64504\",\"54.55\",\"0\",\"8\"],[\"64504.1\",\"15.11\",\"0\",\"6\"],[\"64504.2\",\"511.1\",\"0\",\"6\"],[\"64504.3\",\"0.04\",\"0\",\"2\"],[\"64504.4\",\"1.13\",\"0\",\"4\"],[\"64504.5\",\"58.15\",\"0\",\"5\"],[\"64504.6\",\"2.5\",\"0\",\"1\"],[\"64504.7\",\"0.01\",\"0\",\"1\"],[\"64504.8\",\"0.11\",\"0\",\"5\"],[\"64504.9\",\"0.1\",\"0\",\"3\"],[\"64505\",\"0.82\",\"0\",\"3\"],[\"64505.1\",\"0.02\",\"0\",\"2\"],[\"64505.2\",\"17.2\",\"0\",\"2\"],[\"64505.3\",\"2.66\",\"0\",\"4\"],[\"64505.4\",\"59.23\",\"0\",\"4\"],[\"64505.5\",\"3.91\",\"0\",\"2\"],[\"64505.6\",\"57.91\",\"0\",\"4\"],[\"64505.7\",\"0.56\",\"0\",\"1\"],[\"64505.8\",\"0.08\",\"0\",\"1\"],[\"64505.9\",\"0.01\",\"0\",\"1\"],[\"64506\",\"10.07\",\"0\",\"5\"],[\"64506.1\",\"6.28\",\"0\",\"2\"],[\"64506.2\",\"0.03\",\"0\",\"2\"],[\"64506.3\",\"52.86\",\"0\",\"3\"],[\"64506.4\",\"200.97\",\"0\",\"4\"],[\"64506.5\",\"15.72\",\"0\",\"2\"],[\"64506.6\",\"10.15\",\"0\",\"3\"],[\"64506.7\",\"0.19\",\"0\",\"15\"],[\"64506.8\",\"2.32\",\"0\",\"6\"],[\"64506.9\",\"38.85\",\"0\",\"3\"],[\"64507\",\"0.06\",\"0\",\"1\"],[\"64507.1\",\"0.06\",\"0\",\"4\"],[\"64507.2\",\"14.03\",\"0\",\"2\"],[\"64507.3\",\"0.03\",\"0\",\"2\"],[\"64507.4\",\"27.27\",\"0\",\"1\"],[\"64507.5\",\"0.13\",\"0\",\"6\"],[\"64507.6\",\"0.03\",\"0\",\"2\"],[\"64507.7\",\"33.86\",\"0\",\"5\"],[\"64507.8\",\"34.13\",\"0\",\"5\"],[\"64507.9\",\"0.27\",\"0\",\"4\"],[\"64508\",\"37.26\",\"0\",\"10\"],[\"64508.1\",\"0.82\",\"0\",\"3\"],[\"64508.2\",\"59.01\",\"0\",\"5\"],[\"64508.4\",\"1.62\",\"0\",\"5\"],[\"64508.5\",\"42.46\",\"0\",\"3\"],[\"64508.6\",\"0.01\",\"0\",\"1\"],[\"64508.7\",\"15.67\",\"0\",\"7\"],[\"64508.8\",\"357.61\",\"0\",\"3\"],[\"64508.9\",\"160.53\",\"0\",\"4\"],[\"64509\",\"215.66\",\"0\",\"3\"],[\"64509.1\",\"0.03\",\"0\",\"3\"],[\"64509.3\",\"0.28\",\"0\",\"5\"],[\"64509.6\",\"16.68\",\"0\",\"4\"],[\"64509.8\",\"0.01\",\"0\",\"1\"],[\"64509.9\",\"1.21\",\"0\",\"3\"],[\"64510\",\"71.08\",\"0\",\"29\"],[\"64510.1\",\"0.01\",\"0\",\"1\"],[\"64510.2\",\"16.65\",\"0\",\"2\"],[\"64510.3\",\"1\",\"0\",\"1\"],[\"64510.4\",\"0.53\",\"0\",\"4\"],[\"64510.5\",\"60.3\",\"0\",\"5\"],[\"64510.6\",\"0.19\",\"0\",\"2\"],[\"64510.7\",\"1.02\",\"0\",\"3\"],[\"64510.8\",\"0.02\",\"0\",\"1\"],[\"64510.9\",\"1.27\",\"0\",\"5\"],[\"64511\",\"24.52\",\"0\",\"7\"],[\"64511.1\",\"18.79\",\"0\",\"6\"],[\"64511.2\",\"1.22\",\"0\",\"3\"],[\"64511.3\",\"0.93\",\"0\",\"7\"],[\"64511.4\",\"15.78\",\"0\",\"4\"],[\"64511.5\",\"1.5\",\"0\",\"7\"],[\"64511.7\",\"0.02\",\"0\",\"2\"],[\"64511.8\",\"6.2\",\"0\",\"1\"],[\"64511.9\",\"1.34\",\"0\",\"2\"],[\"64512\",\"2.88\",\"0\",\"13\"],[\"64512.1\",\"0.04\",\"0\",\"3\"],[\"64512.2\",\"11.23\",\"0\",\"3\"],[\"64512.3\",\"66.74\",\"0\",\"7\"],[\"64512.4\",\"0.08\",\"0\",\"1\"],[\"64512.5\",\"85.49\",\"0\",\"6\"],[\"64512.6\",\"59.44\",\"0\",\"7\"],[\"64512.7\",\"91.6\",\"0\",\"3\"],[\"64512.8\",\"1.5\",\"0\",\"1\"],[\"64512.9\",\"17.79\",\"0\",\"4\"],[\"64513\",\"10.37\",\"0\",\"3\"],[\"64513.1\",\"1.56\",\"0\",\"2\"],[\"64513.2\",\"0.15\",\"0\",\"4\"],[\"64513.3\",\"1.97\",\"0\",\"9\"],[\"64513.4\",\"15.68\",\"0\",\"3\"],[\"64513.5\",\"0.6\",\"0\",\"3\"],[\"64513.6\",\"10\",\"0\",\"1\"],[\"64513.7\",\"0.01\",\"0\",\"1\"],[\"64513.8\",\"0.01\",\"0\",\"1\"],[\"64513.9\",\"58.3\",\"0\",\"2\"],[\"64514\",\"15.66\",\"0\",\"2\"],[\"64514.1\",\"0.03\",\"0\",\"3\"],[\"64514.2\",\"1.07\",\"0\",\"4\"],[\"64514.3\",\"0.11\",\"0\",\"5\"],[\"64514.4\",\"15.7\",\"0\",\"4\"],[\"64514.5\",\"0.74\",\"0\",\"5\"],[\"64514.6\",\"15.68\",\"0\",\"2\"],[\"64514.7\",\"0.01\",\"0\",\"1\"],[\"64514.8\",\"60.79\",\"0\",\"6\"],[\"64514.9\",\"496.61\",\"0\",\"4\"],[\"64515\",\"0.04\",\"0\",\"2\"],[\"64515.2\",\"15.66\",\"0\",\"2\"],[\"64515.3\",\"0.01\",\"0\",\"1\"],[\"64515.4\",\"0.46\",\"0\",\"5\"],[\"64515.5\",\"75.46\",\"0\",\"7\"],[\"64515.6\",\"0.09\",\"0\",\"4\"],[\"64515.7\",\"59.35\",\"0\",\"2\"],[\"64515.8\",\"16.99\",\"0\",\"3\"],[\"64515.9\",\"47.94\",\"0\",\"4\"],[\"64516\",\"500.05\",\"0\",\"6\"],[\"64516.1\",\"0.04\",\"0\",\"4\"],[\"64516.2\",\"15.65\",\"0\",\"1\"],[\"64516.3\",\"2.16\",\"0\",\"3\"],[\"64516.4\",\"16.74\",\"0\",\"9\"],[\"64516.5\",\"49.1\",\"0\",\"2\"],[\"64516.6\",\"208.86\",\"0\",\"3\"],[\"64516.7\",\"149.16\",\"0\",\"10\"],[\"64516.8\",\"6.26\",\"0\",\"3\"],[\"64516.9\",\"14.05\",\"0\",\"4\"],[\"64517\",\"17.37\",\"0\",\"20\"],[\"64517.1\",\"0.18\",\"0\",\"1\"],[\"64517.2\",\"0.76\",\"0\",\"5\"],[\"64517.4\",\"0.03\",\"0\",\"2\"],[\"64517.6\",\"25.58\",\"0\",\"2\"],[\"64517.7\",\"18.68\",\"0\",\"4\"],[\"64517.8\",\"0.1\",\"0\",\"3\"],[\"64517.9\",\"0.15\",\"0\",\"3\"],[\"64518\",\"103.04\",\"0\",\"12\"],[\"64518.1\",\"4.88\",\"0\",\"6\"],[\"64518.2\",\"15.68\",\"0\",\"2\"],[\"64518.3\",\"20.08\",\"0\",\"3\"],[\"64518.4\",\"76.16\",\"0\",\"4\"],[\"64518.5\",\"0.01\",\"0\",\"1\"],[\"64518.6\",\"0.11\",\"0\",\"8\"],[\"64518.8\",\"74.74\",\"0\",\"4\"],[\"64518.9\",\"0.01\",\"0\",\"1\"],[\"64519\",\"0.67\",\"0\",\"4\"],[\"64519.1\",\"43.07\",\"0\",\"2\"],[\"64519.2\",\"0.48\",\"0\",\"7\"],[\"64519.3\",\"15.7\",\"0\",\"3\"],[\"64519.4\",\"0.06\",\"0\",\"2\"],[\"64519.5\",\"54.3\",\"0\",\"6\"],[\"64519.6\",\"0.02\",\"0\",\"2\"],[\"64519.7\",\"96.91\",\"0\",\"8\"],[\"64519.8\",\"89.37\",\"0\",\"5\"],[\"64519.9\",\"496.56\",\"0\",\"2\"],[\"64520\",\"78.62\",\"0\",\"63\"],[\"64520.1\",\"0.02\",\"0\",\"2\"],[\"64520.2\",\"0.01\",\"0\",\"1\"],[\"64520.3\",\"0.05\",\"0\",\"3\"],[\"64520.4\",\"1.19\",\"0\",\"7\"],[\"64520.5\",\"0.04\",\"0\",\"3\"],[\"64520.6\",\"0.02\",\"0\",\"2\"],[\"64520.7\",\"38.4\",\"0\",\"2\"],[\"64520.8\",\"0.04\",\"0\",\"2\"],[\"64520.9\",\"0.02\",\"0\",\"2\"],[\"64521\",\"121.98\",\"0\",\"8\"],[\"64521.1\",\"0.02\",\"0\",\"2\"],[\"64521.3\",\"46.5\",\"0\",\"2\"],[\"64521.4\",\"0.35\",\"0\",\"1\"],[\"64521.5\",\"7.76\",\"0\",\"8\"],[\"64521.6\",\"0.02\",\"0\",\"2\"],[\"64521.7\",\"0.06\",\"0\",\"3\"],[\"64521.8\",\"2.44\",\"0\",\"4\"],[\"64521.9\",\"16.99\",\"0\",\"2\"],[\"64522\",\"5.18\",\"0\",\"10\"],[\"64522.1\",\"11.33\",\"0\",\"1\"],[\"64522.2\",\"0.15\",\"0\",\"8\"],[\"64522.3\",\"0.01\",\"0\",\"1\"],[\"64522.4\",\"0.42\",\"0\",\"1\"],[\"64522.5\",\"0.01\",\"0\",\"1\"],[\"64522.6\",\"1.54\",\"0\",\"3\"],[\"64522.7\",\"46.54\",\"0\",\"1\"],[\"64522.8\",\"15.71\",\"0\",\"4\"],[\"64522.9\",\"58.86\",\"0\",\"2\"],[\"64523.1\",\"0.01\",\"0\",\"1\"],[\"64523.2\",\"0.02\",\"0\",\"2\"],[\"64523.3\",\"186.34\",\"0\",\"3\"],[\"64523.4\",\"39.42\",\"0\",\"4\"],[\"64523.6\",\"0.03\",\"0\",\"1\"],[\"64523.7\",\"43.32\",\"0\",\"2\"],[\"64523.8\",\"0.02\",\"0\",\"1\"],[\"64524\",\"0.06\",\"0\",\"5\"],[\"64524.1\",\"2.51\",\"0\",\"2\"],[\"64524.2\",\"0.03\",\"0\",\"1\"],[\"64524.3\",\"15.65\",\"0\",\"1\"],[\"64524.5\",\"0.17\",\"0\",\"3\"],[\"64524.6\",\"15.68\",\"0\",\"2\"],[\"64524.7\",\"0.02\",\"0\",\"1\"],[\"64524.8\",\"3.05\",\"0\",\"5\"],[\"64524.9\",\"2.19\",\"0\",\"7\"],[\"64525\",\"2.51\",\"0\",\"18\"],[\"64525.1\",\"0.46\",\"0\",\"1\"],[\"64525.2\",\"55.22\",\"0\",\"2\"],[\"64525.3\",\"0.01\",\"0\",\"1\"],[\"64525.4\",\"11.18\",\"0\",\"1\"],[\"64525.5\",\"0.02\",\"0\",\"1\"],[\"64525.6\",\"37.24\",\"0\",\"2\"],[\"64525.7\",\"0.03\",\"0\",\"1\"],[\"64525.8\",\"0.02\",\"0\",\"2\"],[\"64525.9\",\"2.69\",\"0\",\"4\"],[\"64526\",\"1.16\",\"0\",\"4\"],[\"64526.1\",\"15.65\",\"0\",\"1\"],[\"64526.2\",\"6.57\",\"0\",\"2\"],[\"64526.3\",\"2.95\",\"0\",\"1\"],[\"64526.4\",\"46.54\",\"0\",\"1\"],[\"64526.5\",\"60\",\"0\",\"3\"],[\"64526.6\",\"14.23\",\"0\",\"4\"],[\"64526.7\",\"0.01\",\"0\",\"1\"],[\"64526.8\",\"0.37\",\"0\",\"2\"],[\"64526.9\",\"40.21\",\"0\",\"5\"],[\"64527\",\"0.17\",\"0\",\"3\"],[\"64527.1\",\"0.46\",\"0\",\"1\"]],\"bids\":[[\"64482.9\",\"1048.07\",\"0\",\"65\"],[\"64482.8\",\"96.7\",\"0\",\"11\"],[\"64482.7\",\"0.02\",\"0\",\"1\"],[\"64482.6\",\"3.31\",\"0\",\"3\"],[\"64482.5\",\"5\",\"0\",\"1\"],[\"64482.1\",\"0.03\",\"0\",\"2\"],[\"64482\",\"5.02\",\"0\",\"3\"],[\"64481.8\",\"3.09\",\"0\",\"1\"],[\"64481.6\",\"0.01\",\"0\",\"1\"],[\"64481.4\",\"12.01\",\"0\",\"3\"],[\"64481.2\",\"3.09\",\"0\",\"1\"],[\"64481\",\"0.01\",\"0\",\"1\"],[\"64480.9\",\"71.8\",\"0\",\"1\"],[\"64480.8\",\"0.01\",\"0\",\"1\"],[\"64480.7\",\"0.01\",\"0\",\"1\"],[\"64480.4\",\"0.31\",\"0\",\"1\"],[\"64480.3\",\"1.56\",\"0\",\"1\"],[\"64480.1\",\"0.01\",\"0\",\"1\"],[\"64480\",\"286.28\",\"0\",\"8\"],[\"64479.9\",\"10.01\",\"0\",\"2\"],[\"64479.8\",\"96.85\",\"0\",\"7\"],[\"64479.7\",\"0.02\",\"0\",\"1\"],[\"64479.6\",\"0.02\",\"0\",\"2\"],[\"64479.5\",\"7.19\",\"0\",\"1\"],[\"64479.3\",\"1.57\",\"0\",\"2\"],[\"64479.2\",\"78.37\",\"0\",\"1\"],[\"64479\",\"0.01\",\"0\",\"1\"],[\"64478.8\",\"1.56\",\"0\",\"1\"],[\"64478.5\",\"0.01\",\"0\",\"1\"],[\"64478.3\",\"0.01\",\"0\",\"1\"],[\"64478\",\"0.01\",\"0\",\"1\"],[\"64477.9\",\"77.54\",\"0\",\"1\"],[\"64477.8\",\"1.56\",\"0\",\"1\"],[\"64477.7\",\"13.17\",\"0\",\"5\"],[\"64477.6\",\"0.01\",\"0\",\"1\"],[\"64477.5\",\"0.3\",\"0\",\"1\"],[\"64477.4\",\"0.01\",\"0\",\"1\"],[\"64477.1\",\"0.02\",\"0\",\"2\"],[\"64477\",\"1.56\",\"0\",\"1\"],[\"64476.9\",\"0.02\",\"0\",\"2\"],[\"64476.7\",\"0.01\",\"0\",\"1\"],[\"64476.6\",\"0.02\",\"0\",\"2\"],[\"64476.5\",\"11.4\",\"0\",\"1\"],[\"64476.3\",\"1.57\",\"0\",\"2\"],[\"64476.2\",\"291.69\",\"0\",\"3\"],[\"64476\",\"0.05\",\"0\",\"3\"],[\"64475.9\",\"46.56\",\"0\",\"3\"],[\"64475.8\",\"37.24\",\"0\",\"2\"],[\"64475.7\",\"1.56\",\"0\",\"1\"],[\"64475.5\",\"1.87\",\"0\",\"1\"],[\"64475.4\",\"0.02\",\"0\",\"2\"],[\"64475.3\",\"0.24\",\"0\",\"2\"],[\"64475.1\",\"69.62\",\"0\",\"3\"],[\"64475\",\"68.83\",\"0\",\"2\"],[\"64474.8\",\"0.01\",\"0\",\"1\"],[\"64474.7\",\"0.01\",\"0\",\"1\"],[\"64474.1\",\"37.28\",\"0\",\"3\"],[\"64474\",\"496.54\",\"0\",\"2\"],[\"64473.9\",\"46.57\",\"0\",\"3\"],[\"64473.8\",\"0.02\",\"0\",\"2\"],[\"64473.6\",\"246.97\",\"0\",\"3\"],[\"64473.5\",\"42.85\",\"0\",\"1\"],[\"64473.4\",\"0.3\",\"0\",\"1\"],[\"64473.3\",\"0.01\",\"0\",\"1\"],[\"64473.2\",\"11.41\",\"0\",\"2\"],[\"64472.9\",\"4.77\",\"0\",\"1\"],[\"64472.7\",\"3.92\",\"0\",\"3\"],[\"64472.5\",\"69.9\",\"0\",\"1\"],[\"64472.3\",\"0.01\",\"0\",\"1\"],[\"64472.1\",\"0.82\",\"0\",\"3\"],[\"64472\",\"0.02\",\"0\",\"2\"],[\"64471.7\",\"0.3\",\"0\",\"1\"],[\"64471.6\",\"0.03\",\"0\",\"1\"],[\"64471.5\",\"0.01\",\"0\",\"1\"],[\"64471.4\",\"46.55\",\"0\",\"2\"],[\"64471.3\",\"0.38\",\"0\",\"1\"],[\"64470.9\",\"1.61\",\"0\",\"2\"],[\"64470.7\",\"0.02\",\"0\",\"2\"],[\"64470.5\",\"0.32\",\"0\",\"2\"],[\"64470.4\",\"4.77\",\"0\",\"2\"],[\"64470.3\",\"160.92\",\"0\",\"4\"],[\"64470.2\",\"2.67\",\"0\",\"2\"],[\"64470\",\"237.27\",\"0\",\"4\"],[\"64469.9\",\"171.6\",\"0\",\"6\"],[\"64469.8\",\"84.34\",\"0\",\"2\"],[\"64469.7\",\"23.66\",\"0\",\"3\"],[\"64469.6\",\"1.69\",\"0\",\"2\"],[\"64469.5\",\"355.53\",\"0\",\"3\"],[\"64469.4\",\"58.95\",\"0\",\"2\"],[\"64469.3\",\"584.62\",\"0\",\"3\"],[\"64469.2\",\"154.79\",\"0\",\"4\"],[\"64469.1\",\"0.01\",\"0\",\"1\"],[\"64468.9\",\"2.46\",\"0\",\"2\"],[\"64468.8\",\"11.33\",\"0\",\"1\"],[\"64468.7\",\"87.25\",\"0\",\"7\"],[\"64468.6\",\"33.81\",\"0\",\"1\"],[\"64468.5\",\"3\",\"0\",\"1\"],[\"64468.2\",\"62.15\",\"0\",\"1\"],[\"64468.1\",\"18.82\",\"0\",\"2\"],[\"64468\",\"0.02\",\"0\",\"2\"],[\"64467.9\",\"0.01\",\"0\",\"1\"],[\"64467.8\",\"20.64\",\"0\",\"3\"],[\"64467.7\",\"0.79\",\"0\",\"2\"],[\"64467.6\",\"2.73\",\"0\",\"4\"],[\"64467.5\",\"0.03\",\"0\",\"2\"],[\"64467.4\",\"46.54\",\"0\",\"1\"],[\"64467.3\",\"103.03\",\"0\",\"2\"],[\"64467.1\",\"31.22\",\"0\",\"2\"],[\"64467\",\"383.8\",\"0\",\"3\"],[\"64466.8\",\"18.96\",\"0\",\"2\"],[\"64466.6\",\"85.4\",\"0\",\"2\"],[\"64466.5\",\"15.98\",\"0\",\"1\"],[\"64466.2\",\"0.01\",\"0\",\"1\"],[\"64466.1\",\"0.38\",\"0\",\"1\"],[\"64466\",\"37.25\",\"0\",\"5\"],[\"64465.7\",\"6.22\",\"0\",\"1\"],[\"64465.6\",\"28.21\",\"0\",\"4\"],[\"64465.4\",\"507.87\",\"0\",\"3\"],[\"64465.3\",\"46.58\",\"0\",\"4\"],[\"64465.1\",\"24\",\"0\",\"2\"],[\"64465\",\"200\",\"0\",\"1\"],[\"64464.9\",\"31.08\",\"0\",\"2\"],[\"64464.8\",\"0.01\",\"0\",\"1\"],[\"64464.7\",\"1\",\"0\",\"1\"],[\"64464.6\",\"58.22\",\"0\",\"1\"],[\"64464.5\",\"31.07\",\"0\",\"3\"],[\"64464.4\",\"0.01\",\"0\",\"1\"],[\"64464.3\",\"232.91\",\"0\",\"1\"],[\"64464.2\",\"155.57\",\"0\",\"5\"],[\"64464\",\"0.06\",\"0\",\"4\"],[\"64463.8\",\"347.78\",\"0\",\"2\"],[\"64463.6\",\"0.13\",\"0\",\"2\"],[\"64463.5\",\"0.01\",\"0\",\"1\"],[\"64463.3\",\"46.54\",\"0\",\"1\"],[\"64463.1\",\"37.23\",\"0\",\"1\"],[\"64463\",\"0.02\",\"0\",\"2\"],[\"64462.8\",\"15.65\",\"0\",\"1\"],[\"64462.6\",\"3.11\",\"0\",\"2\"],[\"64462.4\",\"0.01\",\"0\",\"1\"],[\"64462.1\",\"11.33\",\"0\",\"1\"],[\"64462\",\"0.01\",\"0\",\"1\"],[\"64461.9\",\"0.01\",\"0\",\"1\"],[\"64461.7\",\"0.01\",\"0\",\"1\"],[\"64461.5\",\"0.02\",\"0\",\"2\"],[\"64461.4\",\"14.24\",\"0\",\"4\"],[\"64461.3\",\"496.57\",\"0\",\"2\"],[\"64461.2\",\"0.04\",\"0\",\"2\"],[\"64461.1\",\"46.56\",\"0\",\"2\"],[\"64460.9\",\"95.5\",\"0\",\"2\"],[\"64460.8\",\"154.63\",\"0\",\"4\"],[\"64460.7\",\"44.95\",\"0\",\"2\"],[\"64460.6\",\"3.2\",\"0\",\"2\"],[\"64460.1\",\"3.91\",\"0\",\"2\"],[\"64460\",\"0.31\",\"0\",\"3\"],[\"64459.7\",\"0.01\",\"0\",\"1\"],[\"64459.6\",\"71.03\",\"0\",\"1\"],[\"64459.5\",\"15.65\",\"0\",\"1\"],[\"64459.4\",\"38.83\",\"0\",\"1\"],[\"64459.3\",\"39.02\",\"0\",\"3\"],[\"64459.2\",\"0.01\",\"0\",\"1\"],[\"64459.1\",\"46.54\",\"0\",\"1\"],[\"64458.9\",\"0.01\",\"0\",\"1\"],[\"64458.7\",\"18.13\",\"0\",\"2\"],[\"64458.6\",\"0.16\",\"0\",\"2\"],[\"64458.4\",\"2.61\",\"0\",\"2\"],[\"64458.3\",\"0.03\",\"0\",\"3\"],[\"64458\",\"76.93\",\"0\",\"2\"],[\"64457.9\",\"0.01\",\"0\",\"1\"],[\"64457.6\",\"0.01\",\"0\",\"1\"],[\"64457.5\",\"0.01\",\"0\",\"1\"],[\"64457.4\",\"11.19\",\"0\",\"2\"],[\"64457.2\",\"14.15\",\"0\",\"1\"],[\"64457.1\",\"415.22\",\"0\",\"3\"],[\"64457\",\"574.34\",\"0\",\"6\"],[\"64456.6\",\"0.08\",\"0\",\"2\"],[\"64456.5\",\"8.31\",\"0\",\"2\"],[\"64456.4\",\"15.65\",\"0\",\"1\"],[\"64456.3\",\"37.24\",\"0\",\"2\"],[\"64456.2\",\"21.88\",\"0\",\"3\"],[\"64456.1\",\"249.79\",\"0\",\"3\"],[\"64456\",\"10.02\",\"0\",\"3\"],[\"64455.8\",\"15.66\",\"0\",\"2\"],[\"64455.7\",\"0.3\",\"0\",\"2\"],[\"64455.6\",\"37.69\",\"0\",\"2\"],[\"64455.5\",\"31.3\",\"0\",\"2\"],[\"64455.3\",\"56.54\",\"0\",\"2\"],[\"64455.2\",\"16.19\",\"0\",\"6\"],[\"64455\",\"46.54\",\"0\",\"1\"],[\"64454.8\",\"10\",\"0\",\"1\"],[\"64454.7\",\"0.03\",\"0\",\"2\"],[\"64454.6\",\"31.31\",\"0\",\"3\"],[\"64454.5\",\"0.01\",\"0\",\"1\"],[\"64454.4\",\"62.16\",\"0\",\"2\"],[\"64454.3\",\"10\",\"0\",\"1\"],[\"64454.2\",\"38.83\",\"0\",\"1\"],[\"64454.1\",\"0.2\",\"0\",\"1\"],[\"64454\",\"15.71\",\"0\",\"4\"],[\"64453.9\",\"38.83\",\"0\",\"1\"],[\"64453.6\",\"0.04\",\"0\",\"2\"],[\"64453.4\",\"15.67\",\"0\",\"3\"],[\"64453.3\",\"0.12\",\"0\",\"12\"],[\"64453.1\",\"0.5\",\"0\",\"1\"],[\"64452.9\",\"16.71\",\"0\",\"2\"],[\"64452.8\",\"29.87\",\"0\",\"3\"],[\"64452.7\",\"309.36\",\"0\",\"3\"],[\"64452.6\",\"515.18\",\"0\",\"3\"],[\"64452.5\",\"31.32\",\"0\",\"4\"],[\"64452.3\",\"0.15\",\"0\",\"1\"],[\"64452.2\",\"15.65\",\"0\",\"1\"],[\"64452.1\",\"10.02\",\"0\",\"3\"],[\"64452\",\"10.16\",\"0\",\"5\"],[\"64451.8\",\"46.54\",\"0\",\"1\"],[\"64451.7\",\"201.97\",\"0\",\"3\"],[\"64451.6\",\"25.68\",\"0\",\"5\"],[\"64451.5\",\"61.97\",\"0\",\"2\"],[\"64451.3\",\"15.65\",\"0\",\"1\"],[\"64451.2\",\"0.01\",\"0\",\"1\"],[\"64451.1\",\"21.6\",\"0\",\"2\"],[\"64451\",\"0.02\",\"0\",\"2\"],[\"64450.8\",\"15.65\",\"0\",\"1\"],[\"64450.7\",\"0.04\",\"0\",\"2\"],[\"64450.6\",\"155.91\",\"0\",\"1\"],[\"64450.5\",\"0.01\",\"0\",\"1\"],[\"64450.4\",\"15.43\",\"0\",\"1\"],[\"64450.3\",\"0.03\",\"0\",\"2\"],[\"64450.1\",\"0.18\",\"0\",\"2\"],[\"64450\",\"22.84\",\"0\",\"20\"],[\"64449.9\",\"273.58\",\"0\",\"3\"],[\"64449.8\",\"83.77\",\"0\",\"2\"],[\"64449.7\",\"0.04\",\"0\",\"1\"],[\"64449.6\",\"15.65\",\"0\",\"1\"],[\"64449.5\",\"0.01\",\"0\",\"1\"],[\"64449.4\",\"0.01\",\"0\",\"1\"],[\"64449.3\",\"6.22\",\"0\",\"1\"],[\"64449.2\",\"15.65\",\"0\",\"1\"],[\"64449\",\"0.02\",\"0\",\"2\"],[\"64448.9\",\"0.52\",\"0\",\"2\"],[\"64448.8\",\"0.07\",\"0\",\"1\"],[\"64448.5\",\"512.19\",\"0\",\"3\"],[\"64448.4\",\"5.06\",\"0\",\"3\"],[\"64448.3\",\"10.03\",\"0\",\"3\"],[\"64448.2\",\"17.05\",\"0\",\"1\"],[\"64448\",\"426.87\",\"0\",\"9\"],[\"64447.9\",\"3.1\",\"0\",\"1\"],[\"64447.8\",\"46.55\",\"0\",\"2\"],[\"64447.7\",\"16.53\",\"0\",\"2\"],[\"64447.6\",\"0.01\",\"0\",\"1\"],[\"64447.5\",\"0.01\",\"0\",\"1\"],[\"64447.1\",\"0.01\",\"0\",\"1\"],[\"64447\",\"15.65\",\"0\",\"1\"],[\"64446.8\",\"38.84\",\"0\",\"1\"],[\"64446.7\",\"6.22\",\"0\",\"3\"],[\"64446.6\",\"11.18\",\"0\",\"1\"],[\"64446.5\",\"0.02\",\"0\",\"2\"],[\"64446.3\",\"15.65\",\"0\",\"1\"],[\"64446.2\",\"0.07\",\"0\",\"1\"],[\"64446\",\"35.77\",\"0\",\"6\"],[\"64445.8\",\"0.01\",\"0\",\"1\"],[\"64445.7\",\"0.02\",\"0\",\"2\"],[\"64445.5\",\"357.5\",\"0\",\"1\"],[\"64445.4\",\"15.65\",\"0\",\"1\"],[\"64445.3\",\"10.03\",\"0\",\"4\"],[\"64445\",\"0.01\",\"0\",\"1\"],[\"64444.8\",\"10.32\",\"0\",\"3\"],[\"64444.7\",\"342.07\",\"0\",\"3\"],[\"64444.6\",\"496.54\",\"0\",\"2\"],[\"64444.5\",\"156.71\",\"0\",\"3\"],[\"64444.4\",\"37.24\",\"0\",\"2\"],[\"64444.3\",\"0.01\",\"0\",\"1\"],[\"64444.2\",\"10.01\",\"0\",\"2\"],[\"64444.1\",\"159.26\",\"0\",\"5\"],[\"64444\",\"15.69\",\"0\",\"4\"],[\"64443.9\",\"1.83\",\"0\",\"2\"],[\"64443.8\",\"0.01\",\"0\",\"1\"],[\"64443.7\",\"10\",\"0\",\"1\"],[\"64443.3\",\"0.02\",\"0\",\"2\"],[\"64443.2\",\"10.01\",\"0\",\"2\"],[\"64443\",\"15.66\",\"0\",\"2\"],[\"64442.8\",\"0.01\",\"0\",\"1\"],[\"64442.7\",\"0.01\",\"0\",\"1\"],[\"64442.6\",\"15.65\",\"0\",\"1\"],[\"64442.5\",\"10\",\"0\",\"1\"],[\"64442.1\",\"62.19\",\"0\",\"2\"],[\"64442\",\"15.01\",\"0\",\"2\"],[\"64441.9\",\"0.02\",\"0\",\"1\"],[\"64441.6\",\"15.81\",\"0\",\"3\"],[\"64441.4\",\"15.66\",\"0\",\"2\"],[\"64441.3\",\"0.38\",\"0\",\"1\"],[\"64441.2\",\"208.93\",\"0\",\"1\"],[\"64441.1\",\"1.57\",\"0\",\"1\"],[\"64440.4\",\"6.23\",\"0\",\"2\"],[\"64440.3\",\"11.02\",\"0\",\"3\"],[\"64440.2\",\"354.51\",\"0\",\"2\"],[\"64440.1\",\"496.53\",\"0\",\"1\"],[\"64440\",\"23.47\",\"0\",\"18\"],[\"64439.9\",\"46.54\",\"0\",\"1\"],[\"64439.8\",\"92.79\",\"0\",\"1\"],[\"64439.7\",\"15.65\",\"0\",\"1\"],[\"64439.4\",\"93.87\",\"0\",\"2\"],[\"64439.1\",\"97.71\",\"0\",\"2\"],[\"64438.9\",\"0.01\",\"0\",\"1\"],[\"64438.8\",\"4.13\",\"0\",\"1\"],[\"64438.5\",\"0.01\",\"0\",\"1\"],[\"64438.4\",\"0.01\",\"0\",\"1\"],[\"64438.2\",\"304.51\",\"0\",\"2\"],[\"64438.1\",\"23.69\",\"0\",\"3\"],[\"64437.8\",\"46.55\",\"0\",\"2\"],[\"64437.6\",\"0.01\",\"0\",\"1\"],[\"64437.2\",\"15.46\",\"0\",\"2\"],[\"64437.1\",\"0.29\",\"0\",\"1\"],[\"64436.9\",\"0.01\",\"0\",\"1\"],[\"64436.8\",\"0.79\",\"0\",\"1\"],[\"64436.7\",\"0.54\",\"0\",\"2\"],[\"64436.6\",\"0.01\",\"0\",\"1\"],[\"64436.5\",\"11.29\",\"0\",\"1\"],[\"64436.4\",\"17.99\",\"0\",\"2\"],[\"64436.1\",\"10\",\"0\",\"1\"],[\"64435.9\",\"496.53\",\"0\",\"1\"],[\"64435.8\",\"247.26\",\"0\",\"4\"],[\"64435.6\",\"4.64\",\"0\",\"1\"],[\"64435.5\",\"0.02\",\"0\",\"1\"],[\"64435.2\",\"0.02\",\"0\",\"2\"],[\"64435.1\",\"0.01\",\"0\",\"1\"],[\"64435\",\"164.23\",\"0\",\"4\"],[\"64434.9\",\"0.05\",\"0\",\"1\"],[\"64434.8\",\"15.65\",\"0\",\"1\"],[\"64434.7\",\"98.85\",\"0\",\"3\"],[\"64434.6\",\"1.16\",\"0\",\"1\"],[\"64434.4\",\"20\",\"0\",\"1\"],[\"64434.3\",\"0.02\",\"0\",\"2\"],[\"64434.2\",\"0.01\",\"0\",\"1\"],[\"64434.1\",\"0.35\",\"0\",\"2\"],[\"64433.9\",\"37.23\",\"0\",\"1\"],[\"64433.8\",\"6.22\",\"0\",\"1\"],[\"64433.4\",\"0.01\",\"0\",\"1\"],[\"64433.3\",\"0.04\",\"0\",\"2\"],[\"64433.2\",\"11.29\",\"0\",\"1\"],[\"64433.1\",\"15.65\",\"0\",\"1\"],[\"64433\",\"1.73\",\"0\",\"1\"],[\"64432.6\",\"0.06\",\"0\",\"3\"],[\"64432.5\",\"0.01\",\"0\",\"1\"],[\"64432.3\",\"0.02\",\"0\",\"2\"],[\"64432.2\",\"61.75\",\"0\",\"2\"],[\"64432.1\",\"298.07\",\"0\",\"2\"],[\"64432\",\"263.28\",\"0\",\"4\"],[\"64431.9\",\"517.26\",\"0\",\"2\"],[\"64431.5\",\"15.65\",\"0\",\"1\"],[\"64431.4\",\"60.49\",\"0\",\"2\"],[\"64431.3\",\"92.79\",\"0\",\"1\"],[\"64431.1\",\"24.84\",\"0\",\"2\"],[\"64431\",\"4.06\",\"0\",\"17\"],[\"64430.6\",\"0.77\",\"0\",\"1\"],[\"64430.4\",\"113.91\",\"0\",\"3\"],[\"64430.3\",\"1.01\",\"0\",\"2\"],[\"64430.2\",\"15.73\",\"0\",\"2\"],[\"64430\",\"51.55\",\"0\",\"3\"],[\"64429.9\",\"12.37\",\"0\",\"4\"],[\"64429.8\",\"0.01\",\"0\",\"1\"],[\"64429.4\",\"0.02\",\"0\",\"1\"],[\"64429.2\",\"0.11\",\"0\",\"1\"],[\"64429.1\",\"0.02\",\"0\",\"1\"],[\"64428.9\",\"0.03\",\"0\",\"2\"],[\"64428.8\",\"0.01\",\"0\",\"1\"],[\"64428.6\",\"1.04\",\"0\",\"3\"],[\"64428.4\",\"37.23\",\"0\",\"1\"],[\"64428.2\",\"15.65\",\"0\",\"1\"],[\"64428.1\",\"0.65\",\"0\",\"2\"],[\"64428\",\"341.6\",\"0\",\"4\"],[\"64427.8\",\"543.07\",\"0\",\"2\"],[\"64427.7\",\"0.01\",\"0\",\"1\"],[\"64427.3\",\"6.23\",\"0\",\"2\"],[\"64427.2\",\"0.02\",\"0\",\"2\"],[\"64427\",\"266.81\",\"0\",\"5\"],[\"64426.8\",\"0.06\",\"0\",\"1\"],[\"64426.7\",\"0.12\",\"0\",\"12\"],[\"64426.6\",\"0.01\",\"0\",\"1\"],[\"64426.5\",\"0.04\",\"0\",\"1\"],[\"64426.1\",\"19.87\",\"0\",\"2\"],[\"64426\",\"0.02\",\"0\",\"1\"],[\"64425.7\",\"2.01\",\"0\",\"1\"],[\"64425.6\",\"3.91\",\"0\",\"2\"],[\"64425.5\",\"11.06\",\"0\",\"1\"],[\"64425.4\",\"0.07\",\"0\",\"1\"],[\"64425.3\",\"2\",\"0\",\"1\"],[\"64425\",\"1.87\",\"0\",\"7\"],[\"64424.9\",\"15.66\",\"0\",\"2\"],[\"64424.6\",\"0.01\",\"0\",\"1\"],[\"64424.4\",\"46.54\",\"0\",\"1\"],[\"64424.2\",\"0.01\",\"0\",\"1\"],[\"64424\",\"3.64\",\"0\",\"5\"],[\"64423.9\",\"0.05\",\"0\",\"1\"],[\"64423.8\",\"293.11\",\"0\",\"3\"],[\"64423.7\",\"1\",\"0\",\"1\"],[\"64423.3\",\"512.29\",\"0\",\"3\"],[\"64423.2\",\"37.23\",\"0\",\"1\"],[\"64423.1\",\"92.81\",\"0\",\"2\"],[\"64423\",\"2.59\",\"0\",\"7\"],[\"64422.8\",\"2.29\",\"0\",\"2\"],[\"64422.7\",\"4.4\",\"0\",\"4\"],[\"64422.6\",\"0.02\",\"0\",\"2\"]],\"ts\":\"1782016029605\",\"checksum\":-2123517227,\"seqId\":325070076474,\"prevSeqId\":-1}]}"}
{"action": "update", "capture_sequence": 155, "channel": "books", "connection_sequence": 2, "event": null, "instId": "BTC-USDT-SWAP", "local_receive_ts": "2026-06-21T04:27:09Z", "monotonic_ns": 1643585655187066, "raw": "{\"arg\":{\"channel\":\"books\",\"instId\":\"BTC-USDT-SWAP\"},\"action\":\"update\",\"data\":[{\"asks\":[[\"64483\",\"144.49\",\"0\",\"12\"],[\"64483.1\",\"0.63\",\"0\",\"4\"],[\"64483.2\",\"0\",\"0\",\"0\"],[\"64484.4\",\"38.01\",\"0\",\"4\"],[\"64484.6\",\"1.21\",\"0\",\"2\"],[\"64484.7\",\"0.01\",\"0\",\"1\"],[\"64484.8\",\"0\",\"0\",\"0\"],[\"64484.9\",\"0.02\",\"0\",\"2\"],[\"64485.7\",\"0.35\",\"0\",\"5\"],[\"64485.9\",\"21.46\",\"0\",\"4\"],[\"64487.8\",\"77.64\",\"0\",\"5\"],[\"64489.6\",\"1.39\",\"0\",\"4\"],[\"64490.4\",\"0.03\",\"0\",\"3\"],[\"64493.3\",\"20.11\",\"0\",\"6\"],[\"64503.3\",\"1.91\",\"0\",\"4\"],[\"64503.5\",\"63.72\",\"0\",\"6\"],[\"64527.2\",\"0.18\",\"0\",\"4\"]],\"bids\":[[\"64480.8\",\"1.57\",\"0\",\"2\"],[\"64460.6\",\"0.01\",\"0\",\"1\"],[\"64459.7\",\"3.18\",\"0\",\"2\"],[\"64454.1\",\"0\",\"0\",\"0\"],[\"64423.5\",\"19.6\",\"0\",\"1\"],[\"64422.7\",\"23.42\",\"0\",\"5\"],[\"64422.6\",\"18.89\",\"0\",\"3\"]],\"ts\":\"1782016029705\",\"checksum\":-1773020602,\"seqId\":325070076550,\"prevSeqId\":325070076474}]}"}
{"action": "update", "capture_sequence": 156, "channel": "books", "connection_sequence": 2, "event": null, "instId": "BTC-USDT-SWAP", "local_receive_ts": "2026-06-21T04:27:09Z", "monotonic_ns": 1643585724601819, "raw": "{\"arg\":{\"channel\":\"books\",\"instId\":\"BTC-USDT-SWAP\"},\"action\":\"update\",\"data\":[{\"asks\":[[\"64483\",\"133.89\",\"0\",\"11\"],[\"64484.3\",\"0.01\",\"0\",\"1\"],[\"64484.4\",\"36.44\",\"0\",\"2\"],[\"64484.7\",\"0\",\"0\",\"0\"],[\"64485\",\"41.95\",\"0\",\"2\"],[\"64485.7\",\"0.34\",\"0\",\"4\"],[\"64485.8\",\"0.43\",\"0\",\"5\"],[\"64486.9\",\"1.11\",\"0\",\"2\"],[\"64492.5\",\"93.65\",\"0\",\"5\"]],\"bids\":[[\"64453.3\",\"0.31\",\"0\",\"13\"],[\"64423.5\",\"0\",\"0\",\"0\"],[\"64422.7\",\"4.4\",\"0\",\"4\"],[\"64422.6\",\"0.02\",\"0\",\"2\"],[\"64422.4\",\"1366.68\",\"0\",\"4\"]],\"ts\":\"1782016029805\",\"checksum\":1876401546,\"seqId\":325070076574,\"prevSeqId\":325070076550}]}"}
{"action": "update", "capture_sequence": 157, "channel": "books", "connection_sequence": 2, "event": null, "instId": "BTC-USDT-SWAP", "local_receive_ts": "2026-06-21T04:27:10Z", "monotonic_ns": 1643585824742233, "raw": "{\"arg\":{\"channel\":\"books\",\"instId\":\"BTC-USDT-SWAP\"},\"action\":\"update\",\"data\":[{\"asks\":[],\"bids\":[[\"64482.9\",\"1048.84\",\"0\",\"66\"],[\"64455\",\"285.9\",\"0\",\"2\"]],\"ts\":\"1782016029905\",\"checksum\":-616013145,\"seqId\":325070076583,\"prevSeqId\":325070076574}]}"}
{"action": "update", "capture_sequence": 158, "channel": "books", "connection_sequence": 2, "event": null, "instId": "BTC-USDT-SWAP", "local_receive_ts": "2026-06-21T04:27:10Z", "monotonic_ns": 1643585924986725, "raw": "{\"arg\":{\"channel\":\"books\",\"instId\":\"BTC-USDT-SWAP\"},\"action\":\"update\",\"data\":[{\"asks\":[[\"64486.6\",\"132.78\",\"0\",\"5\"],[\"64490.2\",\"1.56\",\"0\",\"1\"],[\"64490.7\",\"1.62\",\"0\",\"3\"],[\"64492.5\",\"93.49\",\"0\",\"4\"],[\"64492.6\",\"60.76\",\"0\",\"2\"],[\"64505.2\",\"15.65\",\"0\",\"1\"],[\"64505.3\",\"4.21\",\"0\",\"5\"],[\"64507.6\",\"33.82\",\"0\",\"3\"],[\"64507.7\",\"0.07\",\"0\",\"4\"],[\"64512.1\",\"85.37\",\"0\",\"4\"],[\"64512.5\",\"0.16\",\"0\",\"5\"],[\"64527.2\",\"0\",\"0\",\"0\"]],\"bids\":[[\"64482.9\",\"1050.42\",\"0\",\"68\"],[\"64469.6\",\"87.86\",\"0\",\"3\"],[\"64469.3\",\"498.45\",\"0\",\"2\"],[\"64459.8\",\"3.17\",\"0\",\"1\"],[\"64459.7\",\"0.01\",\"0\",\"1\"],[\"64453.4\",\"15.86\",\"0\",\"4\"],[\"64453.3\",\"0.12\",\"0\",\"12\"],[\"64422.4\",\"0\",\"0\",\"0\"]],\"ts\":\"1782016030005\",\"checksum\":759320585,\"seqId\":325070076615,\"prevSeqId\":325070076583}]}"}
{"action": null, "capture_sequence": 159, "channel": "trades", "connection_sequence": 2, "event": null, "instId": "BTC-USDT-SWAP", "local_receive_ts": "2026-06-21T04:27:10Z", "monotonic_ns": 1643586014228996, "raw": "{\"arg\":{\"channel\":\"trades\",\"instId\":\"BTC-USDT-SWAP\"},\"data\":[{\"instId\":\"BTC-USDT-SWAP\",\"tradeId\":\"2718750240\",\"px\":\"64483\",\"sz\":\"0.01\",\"side\":\"buy\",\"ts\":\"1782016030092\",\"count\":\"1\",\"source\":\"0\",\"seqId\":325070076687}]}"}
{"action": "update", "capture_sequence": 160, "channel": "books", "connection_sequence": 2, "event": null, "instId": "BTC-USDT-SWAP", "local_receive_ts": "2026-06-21T04:27:10Z", "monotonic_ns": 1643586025105339, "raw": "{\"arg\":{\"channel\":\"books\",\"instId\":\"BTC-USDT-SWAP\"},\"action\":\"update\",\"data\":[{\"asks\":[[\"64483\",\"133.88\",\"0\",\"11\"],[\"64484.3\",\"0.02\",\"0\",\"2\"],[\"64484.4\",\"36.43\",\"0\",\"1\"],[\"64486.2\",\"0.57\",\"0\",\"7\"],[\"64486.6\",\"146.74\",\"0\",\"5\"],[\"64487.4\",\"0.5\",\"0\",\"6\"],[\"64487.9\",\"1.71\",\"0\",\"3\"],[\"64488.8\",\"50\",\"0\",\"1\"],[\"64489.3\",\"23.25\",\"0\",\"5\"],[\"64489.8\",\"152.84\",\"0\",\"4\"],[\"64491.2\",\"2.57\",\"0\",\"3\"],[\"64491.7\",\"17.5\",\"0\",\"4\"],[\"64492.2\",\"2.47\",\"0\",\"8\"],[\"64492.6\",\"62.32\",\"0\",\"3\"],[\"64493.1\",\"43.18\",\"0\",\"7\"],[\"64493.6\",\"1.59\",\"0\",\"3\"],[\"64494.1\",\"0\",\"0\",\"0\"],[\"64499.8\",\"1.08\",\"0\",\"2\"],[\"64499.9\",\"1130.18\",\"0\",\"3\"],[\"64503.2\",\"0.62\",\"0\",\"4\"],[\"64503.3\",\"1.9\",\"0\",\"3\"],[\"64516.6\",\"0.7\",\"0\",\"2\"],[\"64527.2\",\"0.18\",\"0\",\"4\"]],\"bids\":[[\"64482\",\"5.01\",\"0\",\"2\"],[\"64467.8\",\"1.33\",\"0\",\"3\"],[\"64467.7\",\"20.1\",\"0\",\"2\"],[\"64465.5\",\"0.02\",\"0\",\"1\"],[\"64465.3\",\"46.56\",\"0\",\"3\"],[\"64464.6\",\"0\",\"0\",\"0\"],[\"64464.5\",\"0.02\",\"0\",\"2\"],[\"64464.4\",\"89.28\",\"0\",\"3\"],[\"64444.4\",\"37.26\",\"0\",\"3\"],[\"64444\",\"15.67\",\"0\",\"3\"],[\"64441.2\",\"0\",\"0\",\"0\"],[\"64422.4\",\"1366.68\",\"0\",\"4\"]],\"ts\":\"1782016030105\",\"checksum\":-927626149,\"seqId\":325070076706,\"prevSeqId\":325070076615}]}"}
{"action": "update", "capture_sequence": 161, "channel": "books", "connection_sequence": 2, "event": null, "instId": "BTC-USDT-SWAP", "local_receive_ts": "2026-06-21T04:27:10Z", "monotonic_ns": 1643586124965171, "raw": "{\"arg\":{\"channel\":\"books\",\"instId\":\"BTC-USDT-SWAP\"},\"action\":\"update\",\"data\":[{\"asks\":[[\"64483\",\"133.91\",\"0\",\"12\"],[\"64486.6\",\"131.22\",\"0\",\"4\"],[\"64487.2\",\"15.55\",\"0\",\"3\"],[\"64490.2\",\"0\",\"0\",\"0\"],[\"64490.7\",\"0.06\",\"0\",\"2\"],[\"64491.2\",\"1.01\",\"0\",\"2\"],[\"64494.1\",\"1.56\",\"0\",\"1\"],[\"64494.5\",\"1.56\",\"0\",\"1\"],[\"64521.1\",\"0.01\",\"0\",\"1\"],[\"64522.2\",\"0.16\",\"0\",\"9\"],[\"64527.2\",\"0\",\"0\",\"0\"]],\"bids\":[[\"64441.3\",\"0\",\"0\",\"0\"],[\"64441.2\",\"0.38\",\"0\",\"1\"]],\"ts\":\"1782016030205\",\"checksum\":326213409,\"seqId\":325070076775,\"prevSeqId\":325070076706}]}"}
{"action": "update", "capture_sequence": 162, "channel": "books", "connection_sequence": 2, "event": null, "instId": "BTC-USDT-SWAP", "local_receive_ts": "2026-06-21T04:27:10Z", "monotonic_ns": 1643586224395556, "raw": "{\"arg\":{\"channel\":\"books\",\"instId\":\"BTC-USDT-SWAP\"},\"action\":\"update\",\"data\":[{\"asks\":[[\"64487.2\",\"0.03\",\"0\",\"2\"],[\"64490.3\",\"2.56\",\"0\",\"2\"],[\"64490.7\",\"1.62\",\"0\",\"3\"],[\"64491.2\",\"2.57\",\"0\",\"3\"],[\"64491.7\",\"15.94\",\"0\",\"3\"],[\"64495\",\"3.05\",\"0\",\"9\"],[\"64519.2\",\"202.65\",\"0\",\"8\"],[\"64521.1\",\"0.02\",\"0\",\"2\"],[\"64522.2\",\"0.15\",\"0\",\"8\"]],\"bids\":[[\"64464.8\",\"31.06\",\"0\",\"2\"],[\"64464.4\",\"58.23\",\"0\",\"2\"],[\"64446.6\",\"221.69\",\"0\",\"2\"],[\"64444.5\",\"156.73\",\"0\",\"4\"],[\"64444.4\",\"37.24\",\"0\",\"2\"],[\"64422.5\",\"395.33\",\"0\",\"1\"],[\"64422.4\",\"0\",\"0\",\"0\"]],\"ts\":\"1782016030305\",\"checksum\":326213409,\"seqId\":325070076827,\"prevSeqId\":325070076775}]}"}
{"action": null, "capture_sequence": 163, "channel": "trades", "connection_sequence": 2, "event": null, "instId": "BTC-USDT-SWAP", "local_receive_ts": "2026-06-21T04:27:10Z", "monotonic_ns": 1643586267139159, "raw": "{\"arg\":{\"channel\":\"trades\",\"instId\":\"BTC-USDT-SWAP\"},\"data\":[{\"instId\":\"BTC-USDT-SWAP\",\"tradeId\":\"2718750241\",\"px\":\"64482.9\",\"sz\":\"1\",\"side\":\"sell\",\"ts\":\"1782016030346\",\"count\":\"1\",\"source\":\"0\",\"seqId\":325070076850}]}"}
{"action": null, "capture_sequence": 164, "channel": "trades", "connection_sequence": 2, "event": null, "instId": "BTC-USDT-SWAP", "local_receive_ts": "2026-06-21T04:27:10Z", "monotonic_ns": 1643586318171019, "raw": "{\"arg\":{\"channel\":\"trades\",\"instId\":\"BTC-USDT-SWAP\"},\"data\":[{\"instId\":\"BTC-USDT-SWAP\",\"tradeId\":\"2718750242\",\"px\":\"64483\",\"sz\":\"0.01\",\"side\":\"buy\",\"ts\":\"1782016030399\",\"count\":\"1\",\"source\":\"0\",\"seqId\":325070076910}]}"}
{"action": "update", "capture_sequence": 165, "channel": "books", "connection_sequence": 2, "event": null, "instId": "BTC-USDT-SWAP", "local_receive_ts": "2026-06-21T04:27:10Z", "monotonic_ns": 1643586334379651, "raw": "{\"arg\":{\"channel\":\"books\",\"instId\":\"BTC-USDT-SWAP\"},\"action\":\"update\",\"data\":[{\"asks\":[[\"64483\",\"133.9\",\"0\",\"12\"],[\"64483.4\",\"0.01\",\"0\",\"1\"],[\"64484.7\",\"0.01\",\"0\",\"1\"],[\"64484.9\",\"0.01\",\"0\",\"1\"],[\"64485.8\",\"0.42\",\"0\",\"4\"],[\"64486.1\",\"0.01\",\"0\",\"1\"],[\"64487.3\",\"137.37\",\"0\",\"4\"],[\"64487.8\",\"79.2\",\"0\",\"6\"],[\"64488.2\",\"5.52\",\"0\",\"3\"],[\"64488.7\",\"9\",\"0\",\"4\"],[\"64489\",\"20.3\",\"0\",\"9\"],[\"64489.3\",\"24.81\",\"0\",\"6\"],[\"64492.6\",\"60.76\",\"0\",\"2\"],[\"64493.1\",\"41.62\",\"0\",\"6\"],[\"64493.6\",\"0.03\",\"0\",\"2\"],[\"64494.1\",\"0\",\"0\",\"0\"],[\"64494.5\",\"0\",\"0\",\"0\"],[\"64495\",\"1.49\",\"0\",\"8\"],[\"64505.2\",\"17.2\",\"0\",\"2\"],[\"64505.3\",\"2.66\",\"0\",\"4\"],[\"64527.1\",\"0\",\"0\",\"0\"]],\"bids\":[[\"64482.9\",\"1049.42\",\"0\",\"68\"],[\"64481.9\",\"0.01\",\"0\",\"1\"],[\"64478.5\",\"77.55\",\"0\",\"2\"],[\"64478.4\",\"1.56\",\"0\",\"1\"],[\"64477.9\",\"0\",\"0\",\"0\"],[\"64476.3\",\"0.01\",\"0\",\"1\"],[\"64475.7\",\"0\",\"0\",\"0\"],[\"64464.8\",\"0.01\",\"0\",\"1\"],[\"64464.5\",\"31.07\",\"0\",\"3\"]],\"ts\":\"1782016030405\",\"checksum\":-702630140,\"seqId\":325070076919,\"prevSeqId\":325070076827}]}"}
{"action": "update", "capture_sequence": 166, "channel": "books", "connection_sequence": 2, "event": null, "instId": "BTC-USDT-SWAP", "local_receive_ts": "2026-06-21T04:27:10Z", "monotonic_ns": 1643586424361648, "raw": "{\"arg\":{\"channel\":\"books\",\"instId\":\"BTC-USDT-SWAP\"},\"action\":\"update\",\"data\":[{\"asks\":[[\"64483.4\",\"0\",\"0\",\"0\"],[\"64484.7\",\"0\",\"0\",\"0\"],[\"64484.9\",\"0.02\",\"0\",\"2\"],[\"64485.8\",\"120.65\",\"0\",\"6\"],[\"64486.5\",\"6.21\",\"0\",\"2\"],[\"64488.7\",\"2.8\",\"0\",\"3\"],[\"64492.5\",\"93.64\",\"0\",\"5\"],[\"64492.6\",\"60.6\",\"0\",\"1\"],[\"64505.2\",\"15.65\",\"0\",\"1\"],[\"64505.3\",\"4.21\",\"0\",\"5\"],[\"64527.1\",\"0.46\",\"0\",\"1\"],[\"64527.2\",\"0.18\",\"0\",\"4\"]],\"bids\":[[\"64459.9\",\"3.14\",\"0\",\"1\"],[\"64459.8\",\"0\",\"0\",\"0\"],[\"64453.6\",\"0.23\",\"0\",\"3\"],[\"64453.4\",\"15.67\",\"0\",\"3\"]],\"ts\":\"1782016030505\",\"checksum\":742401216,\"seqId\":325070076977,\"prevSeqId\":325070076919}]}"}
{"action": null, "capture_sequence": 167, "channel": "trades", "connection_sequence": 2, "event": null, "instId": "BTC-USDT-SWAP", "local_receive_ts": "2026-06-21T04:27:10Z", "monotonic_ns": 1643586438421636, "raw": "{\"arg\":{\"channel\":\"trades\",\"instId\":\"BTC-USDT-SWAP\"},\"data\":[{\"instId\":\"BTC-USDT-SWAP\",\"tradeId\":\"2718750243\",\"px\":\"64482.9\",\"sz\":\"0.06\",\"side\":\"sell\",\"ts\":\"1782016030519\",\"count\":\"1\",\"source\":\"0\",\"seqId\":325070077007}]}"}
{"action": "update", "capture_sequence": 168, "channel": "books", "connection_sequence": 2, "event": null, "instId": "BTC-USDT-SWAP", "local_receive_ts": "2026-06-21T04:27:10Z", "monotonic_ns": 1643586531783839, "raw": "{\"arg\":{\"channel\":\"books\",\"instId\":\"BTC-USDT-SWAP\"},\"action\":\"update\",\"data\":[{\"asks\":[[\"64483\",\"187.86\",\"0\",\"13\"],[\"64484.4\",\"31.33\",\"0\",\"1\"],[\"64485.1\",\"1.56\",\"0\",\"1\"],[\"64485.8\",\"0.43\",\"0\",\"5\"],[\"64485.9\",\"5.43\",\"0\",\"2\"],[\"64486.5\",\"0.01\",\"0\",\"1\"],[\"64486.6\",\"132.78\",\"0\",\"5\"],[\"64487.1\",\"2.09\",\"0\",\"5\"],[\"64487.8\",\"1.66\",\"0\",\"5\"],[\"64489.2\",\"7.7\",\"0\",\"2\"],[\"64492.2\",\"0.91\",\"0\",\"7\"],[\"64492.4\",\"16.1\",\"0\",\"8\"],[\"64495.6\",\"18.61\",\"0\",\"4\"],[\"64495.7\",\"11.35\",\"0\",\"3\"],[\"64499.7\",\"35.54\",\"0\",\"6\"],[\"64500.5\",\"2.49\",\"0\",\"2\"],[\"64502.9\",\"281.03\",\"0\",\"8\"],[\"64503\",\"248.73\",\"0\",\"5\"],[\"64503.2\",\"0.3\",\"0\",\"2\"],[\"64503.4\",\"0\",\"0\",\"0\"],[\"64505.1\",\"1.57\",\"0\",\"3\"],[\"64505.3\",\"2.66\",\"0\",\"4\"],[\"64513.2\",\"58.33\",\"0\",\"5\"],[\"64513.9\",\"0.12\",\"0\",\"1\"],[\"64519.1\",\"129.17\",\"0\",\"3\"],[\"64519.7\",\"10.81\",\"0\",\"7\"]],\"bids\":[[\"64482.9\",\"1047.78\",\"0\",\"67\"],[\"64482\",\"5.02\",\"0\",\"3\"],[\"64481.9\",\"1.57\",\"0\",\"2\"],[\"64481.3\",\"1.56\",\"0\",\"1\"],[\"64480.8\",\"0.01\",\"0\",\"1\"],[\"64480.5\",\"1.56\",\"0\",\"1\"],[\"64480.4\",\"0\",\"0\",\"0\"],[\"64480.3\",\"0\",\"0\",\"0\"],[\"64480.2\",\"0.31\",\"0\",\"1\"],[\"64479.8\",\"87.54\",\"0\",\"6\"],[\"64478.5\",\"0.01\",\"0\",\"1\"],[\"64477.9\",\"77.54\",\"0\",\"1\"],[\"64475.9\",\"46.55\",\"0\",\"2\"],[\"64467.7\",\"20.08\",\"0\",\"1\"],[\"64467.3\",\"103.05\",\"0\",\"3\"],[\"64465.5\",\"0\",\"0\",\"0\"],[\"64465.3\",\"46.58\",\"0\",\"4\"],[\"64464.9\",\"31.06\",\"0\",\"1\"],[\"64464.8\",\"0.03\",\"0\",\"2\"],[\"64464.7\",\"0\",\"0\",\"0\"]],\"ts\":\"1782016030605\",\"checksum\":-949098464,\"seqId\":325070077114,\"prevSeqId\":325070076977}]}"}
{"action": "update", "capture_sequence": 169, "channel": "books", "connection_sequence": 2, "event": null, "instId": "BTC-USDT-SWAP", "local_receive_ts": "2026-06-21T04:27:10Z", "monotonic_ns": 1643586632210068, "raw": "{\"arg\":{\"channel\":\"books\",\"instId\":\"BTC-USDT-SWAP\"},\"action\":\"update\",\"data\":[{\"asks\":[[\"64485.1\",\"0\",\"0\",\"0\"],[\"64485.4\",\"0.01\",\"0\",\"1\"],[\"64485.5\",\"1.57\",\"0\",\"2\"],[\"64485.8\",\"0.42\",\"0\",\"4\"],[\"64491.2\",\"1.01\",\"0\",\"2\"],[\"64492.4\",\"16.12\",\"0\",\"8\"],[\"64495.3\",\"18.86\",\"0\",\"5\"],[\"64495.6\",\"0.01\",\"0\",\"1\"],[\"64502.9\",\"280.72\",\"0\",\"7\"],[\"64503\",\"15.96\",\"0\",\"4\"],[\"64503.4\",\"233.08\",\"0\",\"2\"],[\"64505.1\",\"0.02\",\"0\",\"2\"],[\"64505.2\",\"17.2\",\"0\",\"2\"],[\"64506.7\",\"0.96\",\"0\",\"16\"],[\"64506.8\",\"1.55\",\"0\",\"5\"],[\"64507.3\",\"33.82\",\"0\",\"3\"],[\"64507.6\",\"0.03\",\"0\",\"2\"],[\"64513.2\",\"0.15\",\"0\",\"4\"],[\"64513.4\",\"73.86\",\"0\",\"4\"],[\"64517.3\",\"20.06\",\"0\",\"1\"],[\"64518.3\",\"0.02\",\"0\",\"2\"],[\"64518.7\",\"86.1\",\"0\",\"1\"],[\"64519.1\",\"43.07\",\"0\",\"2\"],[\"64520.1\",\"0.03\",\"0\",\"3\"],[\"64521.1\",\"0.01\",\"0\",\"1\"],[\"64527\",\"0\",\"0\",\"0\"],[\"64527.1\",\"0\",\"0\",\"0\"],[\"64527.2\",\"0\",\"0\",\"0\"]],\"bids\":[[\"64481.9\",\"0.01\",\"0\",\"1\"],[\"64481.5\",\"0.01\",\"0\",\"1\"],[\"64478.5\",\"77.55\",\"0\",\"2\"],[\"64477.9\",\"0\",\"0\",\"0\"],[\"64476\",\"0.04\",\"0\",\"2\"],[\"64469.6\",\"1.69\",\"0\",\"2\"],[\"64468.8\",\"97.5\",\"0\",\"2\"],[\"64468.6\",\"0\",\"0\",\"0\"],[\"64468.3\",\"33.81\",\"0\",\"1\"],[\"64468\",\"0.04\",\"0\",\"3\"],[\"64467.8\",\"0.56\",\"0\",\"2\"],[\"64467.7\",\"0.77\",\"0\",\"1\"],[\"64467.3\",\"103.03\",\"0\",\"2\"],[\"64466.8\",\"104.35\",\"0\",\"3\"],[\"64466.7\",\"20.08\",\"0\",\"1\"],[\"64466.6\",\"0.01\",\"0\",\"1\"],[\"64464.7\",\"1\",\"0\",\"1\"],[\"64464.6\",\"58.22\",\"0\",\"1\"],[\"64464.4\",\"0.01\",\"0\",\"1\"],[\"64422.7\",\"0\",\"0\",\"0\"],[\"64422.6\",\"0\",\"0\",\"0\"],[\"64422.5\",\"0\",\"0\",\"0\"]],\"ts\":\"1782016030705\",\"checksum\":1802956734,\"seqId\":325070077305,\"prevSeqId\":325070077114}]}"}
{"action": "update", "capture_sequence": 170, "channel": "books", "connection_sequence": 2, "event": null, "instId": "BTC-USDT-SWAP", "local_receive_ts": "2026-06-21T04:27:10Z", "monotonic_ns": 1643586725418681, "raw": "{\"arg\":{\"channel\":\"books\",\"instId\":\"BTC-USDT-SWAP\"},\"action\":\"update\",\"data\":[{\"asks\":[[\"64483\",\"225.01\",\"0\",\"15\"],[\"64485.5\",\"0.01\",\"0\",\"1\"],[\"64493.6\",\"0.02\",\"0\",\"1\"],[\"64494.1\",\"0.01\",\"0\",\"1\"],[\"64503\",\"248.72\",\"0\",\"4\"],[\"64503.4\",\"0.31\",\"0\",\"1\"],[\"64503.5\",\"63.73\",\"0\",\"7\"],[\"64505.1\",\"1.57\",\"0\",\"3\"],[\"64505.2\",\"15.65\",\"0\",\"1\"],[\"64517.3\",\"0\",\"0\",\"0\"],[\"64518.3\",\"20.08\",\"0\",\"3\"],[\"64518.7\",\"0\",\"0\",\"0\"],[\"64519.7\",\"96.91\",\"0\",\"8\"],[\"64520.1\",\"0.02\",\"0\",\"2\"],[\"64521.1\",\"0.02\",\"0\",\"2\"],[\"64527\",\"0.17\",\"0\",\"3\"]],\"bids\":[[\"64481.9\",\"0\",\"0\",\"0\"],[\"64481.8\",\"0\",\"0\",\"0\"],[\"64481.4\",\"12.02\",\"0\",\"4\"],[\"64481.3\",\"0\",\"0\",\"0\"],[\"64481.2\",\"0\",\"0\",\"0\"],[\"64479.7\",\"3.11\",\"0\",\"2\"],[\"64479\",\"3.1\",\"0\",\"2\"],[\"64478.5\",\"0.01\",\"0\",\"1\"],[\"64477.9\",\"77.54\",\"0\",\"1\"],[\"64469.6\",\"87.86\",\"0\",\"3\"],[\"64468.8\",\"11.33\",\"0\",\"1\"],[\"64468\",\"0.02\",\"0\",\"2\"],[\"64467.8\",\"20.64\",\"0\",\"3\"],[\"64467.4\",\"46.56\",\"0\",\"2\"],[\"64466.7\",\"0\",\"0\",\"0\"],[\"64464.3\",\"0\",\"0\",\"0\"],[\"64463.9\",\"232.91\",\"0\",\"1\"],[\"64423.5\",\"19.6\",\"0\",\"1\"],[\"64422.7\",\"23.42\",\"0\",\"5\"],[\"64422.6\",\"18.89\",\"0\",\"3\"],[\"64422.5\",\"395.33\",\"0\",\"1\"]],\"ts\":\"1782016030805\",\"checksum\":626724724,\"seqId\":325070077352,\"prevSeqId\":325070077305}]}"}
{"action": null, "capture_sequence": 171, "channel": "trades", "connection_sequence": 2, "event": null, "instId": "BTC-USDT-SWAP", "local_receive_ts": "2026-06-21T04:27:10Z", "monotonic_ns": 1643586735040851, "raw": "{\"arg\":{\"channel\":\"trades\",\"instId\":\"BTC-USDT-SWAP\"},\"data\":[{\"instId\":\"BTC-USDT-SWAP\",\"tradeId\":\"2718750244\",\"px\":\"64483\",\"sz\":\"0.4\",\"side\":\"buy\",\"ts\":\"1782016030816\",\"count\":\"1\",\"source\":\"0\",\"seqId\":325070077365}]}"}
{"action": "update", "capture_sequence": 172, "channel": "books", "connection_sequence": 2, "event": null, "instId": "BTC-USDT-SWAP", "local_receive_ts": "2026-06-21T04:27:11Z", "monotonic_ns": 1643586824764097, "raw": "{\"arg\":{\"channel\":\"books\",\"instId\":\"BTC-USDT-SWAP\"},\"action\":\"update\",\"data\":[{\"asks\":[[\"64483\",\"224.71\",\"0\",\"16\"],[\"64485.4\",\"0\",\"0\",\"0\"],[\"64485.8\",\"0.43\",\"0\",\"5\"],[\"64486.6\",\"131.22\",\"0\",\"4\"],[\"64487.1\",\"0.53\",\"0\",\"4\"],[\"64487.8\",\"0.1\",\"0\",\"4\"],[\"64488.2\",\"3.96\",\"0\",\"2\"],[\"64488.7\",\"1.24\",\"0\",\"2\"],[\"64489.3\",\"23.25\",\"0\",\"5\"],[\"64499.4\",\"1.9\",\"0\",\"4\"],[\"64499.7\",\"35.37\",\"0\",\"5\"],[\"64503\",\"15.95\",\"0\",\"3\"],[\"64503.4\",\"233.08\",\"0\",\"2\"],[\"64505.1\",\"0.02\",\"0\",\"2\"],[\"64505.2\",\"17.2\",\"0\",\"2\"],[\"64527.1\",\"0.46\",\"0\",\"1\"]],\"bids\":[[\"64482\",\"5.01\",\"0\",\"2\"],[\"64478.5\",\"77.55\",\"0\",\"2\"],[\"64477.9\",\"0\",\"0\",\"0\"],[\"64464.3\",\"232.91\",\"0\",\"1\"],[\"64463.9\",\"0\",\"0\",\"0\"],[\"64422.4\",\"1366.68\",\"0\",\"4\"]],\"ts\":\"1782016030905\",\"checksum\":-1766521747,\"seqId\":325070077380,\"prevSeqId\":325070077352}]}"}
{"action": "update", "capture_sequence": 173, "channel": "books", "connection_sequence": 2, "event": null, "instId": "BTC-USDT-SWAP", "local_receive_ts": "2026-06-21T04:27:11Z", "monotonic_ns": 1643586924629610, "raw": "{\"arg\":{\"channel\":\"books\",\"instId\":\"BTC-USDT-SWAP\"},\"action\":\"update\",\"data\":[{\"asks\":[[\"64483.1\",\"0.62\",\"0\",\"3\"],[\"64488.4\",\"7.23\",\"0\",\"7\"],[\"64488.9\",\"1.89\",\"0\",\"7\"],[\"64489.4\",\"4.49\",\"0\",\"6\"],[\"64491.2\",\"2.57\",\"0\",\"3\"],[\"64491.7\",\"17.5\",\"0\",\"4\"],[\"64492.2\",\"2.47\",\"0\",\"8\"]],\"bids\":[[\"64482.9\",\"1049.34\",\"0\",\"68\"],[\"64472.9\",\"0\",\"0\",\"0\"],[\"64467.7\",\"0.79\",\"0\",\"2\"],[\"64467.4\",\"46.54\",\"0\",\"1\"],[\"64422.3\",\"0.06\",\"0\",\"6\"]],\"ts\":\"1782016031005\",\"checksum\":-190378850,\"seqId\":325070077402,\"prevSeqId\":325070077380}]}"}
{"action": "update", "capture_sequence": 174, "channel": "books", "connection_sequence": 2, "event": null, "instId": "BTC-USDT-SWAP", "local_receive_ts": "2026-06-21T04:27:11Z", "monotonic_ns": 1643587024755771, "raw": "{\"arg\":{\"channel\":\"books\",\"instId\":\"BTC-USDT-SWAP\"},\"action\":\"update\",\"data\":[{\"asks\":[[\"64488.4\",\"5.67\",\"0\",\"6\"],[\"64488.9\",\"0.33\",\"0\",\"6\"],[\"64489.3\",\"24.81\",\"0\",\"6\"],[\"64489.4\",\"2.93\",\"0\",\"5\"],[\"64489.8\",\"154.4\",\"0\",\"5\"],[\"64492.7\",\"101.44\",\"0\",\"4\"],[\"64493.1\",\"43.18\",\"0\",\"7\"],[\"64502.9\",\"281.03\",\"0\",\"8\"],[\"64503.4\",\"232.77\",\"0\",\"1\"]],\"bids\":[[\"64480.5\",\"4.02\",\"0\",\"2\"],[\"64479.9\",\"12.47\",\"0\",\"3\"],[\"64479.7\",\"0.02\",\"0\",\"1\"],[\"64479\",\"0.01\",\"0\",\"1\"],[\"64470.5\",\"0.01\",\"0\",\"1\"],[\"64470.4\",\"5.08\",\"0\",\"3\"]],\"ts\":\"1782016031105\",\"checksum\":-472780156,\"seqId\":325070077432,\"prevSeqId\":325070077402}]}"}
{"action": "update", "capture_sequence": 175, "channel": "books", "connection_sequence": 2, "event": null, "instId": "BTC-USDT-SWAP", "local_receive_ts": "2026-06-21T04:27:11Z", "monotonic_ns": 1643587124510268, "raw": "{\"arg\":{\"channel\":\"books\",\"instId\":\"BTC-USDT-SWAP\"},\"action\":\"update\",\"data\":[{\"asks\":[[\"64483\",\"224.72\",\"0\",\"16\"],[\"64486.2\",\"1.57\",\"0\",\"8\"],[\"64487.1\",\"78.07\",\"0\",\"5\"],[\"64488.7\",\"2.8\",\"0\",\"3\"],[\"64493.1\",\"41.62\",\"0\",\"6\"]],\"bids\":[],\"ts\":\"1782016031205\",\"checksum\":-2112535423,\"seqId\":325070077447,\"prevSeqId\":325070077432}]}"}
{"action": null, "capture_sequence": 176, "channel": "trades", "connection_sequence": 2, "event": null, "instId": "BTC-USDT-SWAP", "local_receive_ts": "2026-06-21T04:27:11Z", "monotonic_ns": 1643587205389892, "raw": "{\"arg\":{\"channel\":\"trades\",\"instId\":\"BTC-USDT-SWAP\"},\"data\":[{\"instId\":\"BTC-USDT-SWAP\",\"tradeId\":\"2718750245\",\"px\":\"64482.9\",\"sz\":\"2.36\",\"side\":\"sell\",\"ts\":\"1782016031286\",\"count\":\"1\",\"source\":\"0\",\"seqId\":325070077456}]}"}
{"action": "update", "capture_sequence": 177, "channel": "books", "connection_sequence": 2, "event": null, "instId": "BTC-USDT-SWAP", "local_receive_ts": "2026-06-21T04:27:11Z", "monotonic_ns": 1643587224578839, "raw": "{\"arg\":{\"channel\":\"books\",\"instId\":\"BTC-USDT-SWAP\"},\"action\":\"update\",\"data\":[{\"asks\":[[\"64485.5\",\"0.02\",\"0\",\"2\"],[\"64485.6\",\"1.56\",\"0\",\"1\"],[\"64485.8\",\"0.42\",\"0\",\"4\"],[\"64488.7\",\"1.24\",\"0\",\"2\"],[\"64488.8\",\"51.56\",\"0\",\"2\"],[\"64527.1\",\"0\",\"0\",\"0\"]],\"bids\":[[\"64482.9\",\"1045.42\",\"0\",\"67\"],[\"64482.4\",\"0.02\",\"0\",\"1\"],[\"64482.3\",\"1.56\",\"0\",\"1\"],[\"64482.1\",\"0.01\",\"0\",\"1\"],[\"64481.4\",\"12.01\",\"0\",\"3\"],[\"64480.6\",\"0.01\",\"0\",\"1\"],[\"64480\",\"286.29\",\"0\",\"9\"],[\"64423.5\",\"0\",\"0\",\"0\"],[\"64422.7\",\"4.4\",\"0\",\"4\"],[\"64422.6\",\"0.02\",\"0\",\"2\"],[\"64422.4\",\"0\",\"0\",\"0\"],[\"64422.3\",\"0\",\"0\",\"0\"]],\"ts\":\"1782016031305\",\"checksum\":-272185442,\"seqId\":325070077482,\"prevSeqId\":325070077447}]}"}
{"action": null, "capture_sequence": 178, "channel": "trades", "connection_sequence": 2, "event": null, "instId": "BTC-USDT-SWAP", "local_receive_ts": "2026-06-21T04:27:11Z", "monotonic_ns": 1643587302750685, "raw": "{\"arg\":{\"channel\":\"trades\",\"instId\":\"BTC-USDT-SWAP\"},\"data\":[{\"instId\":\"BTC-USDT-SWAP\",\"tradeId\":\"2718750246\",\"px\":\"64483\",\"sz\":\"10\",\"side\":\"buy\",\"ts\":\"1782016031383\",\"count\":\"1\",\"source\":\"0\",\"seqId\":325070077502}]}"}
{"action": "update", "capture_sequence": 179, "channel": "books", "connection_sequence": 2, "event": null, "instId": "BTC-USDT-SWAP", "local_receive_ts": "2026-06-21T04:27:11Z", "monotonic_ns": 1643587324794720, "raw": "{\"arg\":{\"channel\":\"books\",\"instId\":\"BTC-USDT-SWAP\"},\"action\":\"update\",\"data\":[{\"asks\":[[\"64483\",\"214.72\",\"0\",\"16\"],[\"64485.5\",\"0.01\",\"0\",\"1\"],[\"64485.6\",\"0\",\"0\",\"0\"],[\"64485.8\",\"0.43\",\"0\",\"5\"],[\"64488.8\",\"50\",\"0\",\"1\"],[\"64489.3\",\"23.25\",\"0\",\"5\"],[\"64489.8\",\"152.84\",\"0\",\"4\"],[\"64490\",\"57.71\",\"0\",\"21\"],[\"64490.3\",\"1\",\"0\",\"1\"],[\"64490.5\",\"3.37\",\"0\",\"4\"],[\"64490.7\",\"0.06\",\"0\",\"2\"],[\"64491\",\"1.57\",\"0\",\"2\"],[\"64491.2\",\"1.01\",\"0\",\"2\"],[\"64493.1\",\"43.18\",\"0\",\"7\"],[\"64493.6\",\"1.58\",\"0\",\"2\"],[\"64494.1\",\"1.57\",\"0\",\"2\"],[\"64494.6\",\"14.61\",\"0\",\"7\"],[\"64499.9\",\"1114.67\",\"0\",\"2\"],[\"64500.2\",\"15.53\",\"0\",\"3\"],[\"64505.3\",\"1.66\",\"0\",\"3\"],[\"64514.7\",\"1.01\",\"0\",\"2\"],[\"64527.1\",\"0.46\",\"0\",\"1\"]],\"bids\":[[\"64482.8\",\"98.26\",\"0\",\"12\"],[\"64467.7\",\"0.77\",\"0\",\"1\"],[\"64467.3\",\"103.05\",\"0\",\"3\"]],\"ts\":\"1782016031405\",\"checksum\":-463460850,\"seqId\":325070077522,\"prevSeqId\":325070077482}]}"}
{"action": "update", "capture_sequence": 180, "channel": "books", "connection_sequence": 2, "event": null, "instId": "BTC-USDT-SWAP", "local_receive_ts": "2026-06-21T04:27:11Z", "monotonic_ns": 1643587424593115, "raw": "{\"arg\":{\"channel\":\"books\",\"instId\":\"BTC-USDT-SWAP\"},\"action\":\"update\",\"data\":[{\"asks\":[[\"64485.6\",\"1.56\",\"0\",\"1\"],[\"64487.1\",\"79.63\",\"0\",\"6\"],[\"64488.7\",\"2.8\",\"0\",\"3\"],[\"64489.5\",\"1.58\",\"0\",\"3\"],[\"64492.5\",\"93.65\",\"0\",\"5\"],[\"64492.7\",\"99.88\",\"0\",\"3\"],[\"64493.1\",\"41.62\",\"0\",\"6\"],[\"64493.6\",\"0.02\",\"0\",\"1\"],[\"64494.1\",\"0.01\",\"0\",\"1\"],[\"64494.6\",\"13.05\",\"0\",\"6\"],[\"64499.4\",\"1.73\",\"0\",\"3\"],[\"64499.5\",\"0.17\",\"0\",\"1\"],[\"64527\",\"0\",\"0\",\"0\"],[\"64527.1\",\"0\",\"0\",\"0\"]],\"bids\":[[\"64459.9\",\"3.22\",\"0\",\"1\"],[\"64453.6\",\"0.24\",\"0\",\"3\"]],\"ts\":\"1782016031505\",\"checksum\":1701635791,\"seqId\":325070077585,\"prevSeqId\":325070077522}]}"}
{"action": "update", "capture_sequence": 181, "channel": "books", "connection_sequence": 2, "event": null, "instId": "BTC-USDT-SWAP", "local_receive_ts": "2026-06-21T04:27:11Z", "monotonic_ns": 1643587524579859, "raw": "{\"arg\":{\"channel\":\"books\",\"instId\":\"BTC-USDT-SWAP\"},\"action\":\"update\",\"data\":[{\"asks\":[[\"64485.6\",\"0\",\"0\",\"0\"],[\"64500.4\",\"2.14\",\"0\",\"4\"],[\"64503.3\",\"0.02\",\"0\",\"2\"],[\"64513.3\",\"60.15\",\"0\",\"10\"],[\"64513.4\",\"15.68\",\"0\",\"3\"],[\"64527\",\"0.17\",\"0\",\"3\"]],\"bids\":[[\"64482.9\",\"1057.42\",\"0\",\"68\"],[\"64479.8\",\"75.54\",\"0\",\"5\"],[\"64470.5\",\"0.32\",\"0\",\"2\"],[\"64470.4\",\"4.77\",\"0\",\"2\"],[\"64469.9\",\"257.77\",\"0\",\"7\"],[\"64469.6\",\"1.69\",\"0\",\"2\"],[\"64467.9\",\"0.78\",\"0\",\"2\"],[\"64467.7\",\"0\",\"0\",\"0\"],[\"64466.9\",\"85.39\",\"0\",\"1\"],[\"64466.8\",\"18.96\",\"0\",\"2\"],[\"64464.6\",\"0\",\"0\",\"0\"],[\"64464.4\",\"58.23\",\"0\",\"2\"],[\"64431.1\",\"0.77\",\"0\",\"1\"],[\"64430.8\",\"23.04\",\"0\",\"1\"]],\"ts\":\"1782016031605\",\"checksum\":778010404,\"seqId\":325070077686,\"prevSeqId\":325070077585}]}"}
{"action": null, "capture_sequence": 182, "channel": "trades", "connection_sequence": 2, "event": null, "instId": "BTC-USDT-SWAP", "local_receive_ts": "2026-06-21T04:27:11Z", "monotonic_ns": 1643587607254128, "raw": "{\"arg\":{\"channel\":\"trades\",\"instId\":\"BTC-USDT-SWAP\"},\"data\":[{\"instId\":\"BTC-USDT-SWAP\",\"tradeId\":\"2718750247\",\"px\":\"64483\",\"sz\":\"10\",\"side\":\"buy\",\"ts\":\"1782016031688\",\"count\":\"1\",\"source\":\"0\",\"seqId\":325070077740}]}"}
{"action": "update", "capture_sequence": 183, "channel": "books", "connection_sequence": 2, "event": null, "instId": "BTC-USDT-SWAP", "local_receive_ts": "2026-06-21T04:27:11Z", "monotonic_ns": 1643587624391533, "raw": "{\"arg\":{\"channel\":\"books\",\"instId\":\"BTC-USDT-SWAP\"},\"action\":\"update\",\"data\":[{\"asks\":[[\"64483\",\"204.72\",\"0\",\"16\"],[\"64487.1\",\"78.07\",\"0\",\"5\"],[\"64488.7\",\"1.24\",\"0\",\"2\"],[\"64492.7\",\"101.44\",\"0\",\"4\"],[\"64493.1\",\"43.18\",\"0\",\"7\"],[\"64493.3\",\"16.11\",\"0\",\"5\"],[\"64494.2\",\"8.89\",\"0\",\"3\"],[\"64494.6\",\"5.05\",\"0\",\"5\"],[\"64497.6\",\"8.13\",\"0\",\"4\"],[\"64502.9\",\"280.72\",\"0\",\"7\"],[\"64503.4\",\"233.08\",\"0\",\"2\"],[\"64512.1\",\"0.04\",\"0\",\"3\"],[\"64512.2\",\"96.56\",\"0\",\"4\"]],\"bids\":[[\"64482.9\",\"1057.44\",\"0\",\"69\"],[\"64480.6\",\"0.32\",\"0\",\"2\"],[\"64480.2\",\"0\",\"0\",\"0\"],[\"64479.8\",\"75.5\",\"0\",\"4\"],[\"64470\",\"323.44\",\"0\",\"5\"],[\"64469.9\",\"171.6\",\"0\",\"6\"],[\"64464.6\",\"58.22\",\"0\",\"1\"],[\"64464.4\",\"0.01\",\"0\",\"1\"]],\"ts\":\"1782016031705\",\"checksum\":-61072949,\"seqId\":325070077759,\"prevSeqId\":325070077686}]}"}
{"action": null, "capture_sequence": 184, "channel": "trades", "connection_sequence": 2, "event": null, "instId": "BTC-USDT-SWAP", "local_receive_ts": "2026-06-21T04:27:11Z", "monotonic_ns": 1643587667502971, "raw": "{\"arg\":{\"channel\":\"trades\",\"instId\":\"BTC-USDT-SWAP\"},\"data\":[{\"instId\":\"BTC-USDT-SWAP\",\"tradeId\":\"2718750248\",\"px\":\"64482.9\",\"sz\":\"0.06\",\"side\":\"sell\",\"ts\":\"1782016031748\",\"count\":\"1\",\"source\":\"0\",\"seqId\":325070077815}]}"}
{"action": null, "capture_sequence": 185, "channel": "trades", "connection_sequence": 2, "event": null, "instId": "BTC-USDT-SWAP", "local_receive_ts": "2026-06-21T04:27:11Z", "monotonic_ns": 1643587694290418, "raw": "{\"arg\":{\"channel\":\"trades\",\"instId\":\"BTC-USDT-SWAP\"},\"data\":[{\"instId\":\"BTC-USDT-SWAP\",\"tradeId\":\"2718750249\",\"px\":\"64483\",\"sz\":\"5.19\",\"side\":\"buy\",\"ts\":\"1782016031775\",\"count\":\"1\",\"source\":\"0\",\"seqId\":325070077842}]}"}
{"action": "update", "capture_sequence": 186, "channel": "books", "connection_sequence": 2, "event": null, "instId": "BTC-USDT-SWAP", "local_receive_ts": "2026-06-21T04:27:11Z", "monotonic_ns": 1643587724393051, "raw": "{\"arg\":{\"channel\":\"books\",\"instId\":\"BTC-USDT-SWAP\"},\"action\":\"update\",\"data\":[{\"asks\":[[\"64483\",\"207.35\",\"0\",\"16\"],[\"64492.4\",\"16.1\",\"0\",\"8\"],[\"64492.7\",\"99.88\",\"0\",\"3\"],[\"64493.1\",\"41.62\",\"0\",\"6\"],[\"64499.5\",\"0\",\"0\",\"0\"],[\"64499.7\",\"35.54\",\"0\",\"6\"],[\"64502.7\",\"0.03\",\"0\",\"3\"],[\"64503.1\",\"70.72\",\"0\",\"9\"],[\"64505.2\",\"15.65\",\"0\",\"1\"],[\"64505.3\",\"3.21\",\"0\",\"4\"],[\"64507.3\",\"0.03\",\"0\",\"2\"],[\"64508.1\",\"34.61\",\"0\",\"4\"],[\"64513.3\",\"1.97\",\"0\",\"9\"],[\"64513.5\",\"58.78\",\"0\",\"4\"],[\"64527.1\",\"0.46\",\"0\",\"1\"]],\"bids\":[[\"64482.9\",\"1057.38\",\"0\",\"69\"],[\"64482.8\",\"96.7\",\"0\",\"11\"],[\"64482.4\",\"0\",\"0\",\"0\"],[\"64482.3\",\"0\",\"0\",\"0\"],[\"64482.1\",\"0.03\",\"0\",\"2\"],[\"64469\",\"33.81\",\"0\",\"1\"],[\"64468.3\",\"0\",\"0\",\"0\"],[\"64465.2\",\"31.05\",\"0\",\"1\"],[\"64464.6\",\"0\",\"0\",\"0\"],[\"64464.5\",\"0.02\",\"0\",\"2\"],[\"64464.4\",\"58.23\",\"0\",\"2\"],[\"64423.5\",\"19.6\",\"0\",\"1\"],[\"64422.7\",\"23.42\",\"0\",\"5\"],[\"64422.6\",\"18.89\",\"0\",\"3\"],[\"64422.4\",\"1366.68\",\"0\",\"4\"]],\"ts\":\"1782016031805\",\"checksum\":-859893302,\"seqId\":325070077854,\"prevSeqId\":325070077759}]}"}
{"action": null, "capture_sequence": 187, "channel": "trades", "connection_sequence": 2, "event": null, "instId": "BTC-USDT-SWAP", "local_receive_ts": "2026-06-21T04:27:11Z", "monotonic_ns": 1643587775827564, "raw": "{\"arg\":{\"channel\":\"trades\",\"instId\":\"BTC-USDT-SWAP\"},\"data\":[{\"instId\":\"BTC-USDT-SWAP\",\"tradeId\":\"2718750250\",\"px\":\"64483\",\"sz\":\"0.19\",\"side\":\"buy\",\"ts\":\"1782016031856\",\"count\":\"1\",\"source\":\"0\",\"seqId\":325070077856}]}"}
{"action": "update", "capture_sequence": 188, "channel": "books", "connection_sequence": 2, "event": null, "instId": "BTC-USDT-SWAP", "local_receive_ts": "2026-06-21T04:27:12Z", "monotonic_ns": 1643587824387569, "raw": "{\"arg\":{\"channel\":\"books\",\"instId\":\"BTC-USDT-SWAP\"},\"action\":\"update\",\"data\":[{\"asks\":[[\"64483\",\"207.16\",\"0\",\"16\"]],\"bids\":[],\"ts\":\"1782016031905\",\"checksum\":-940417453,\"seqId\":325070077856,\"prevSeqId\":325070077854}]}"}
{"action": "update", "capture_sequence": 189, "channel": "books", "connection_sequence": 2, "event": null, "instId": "BTC-USDT-SWAP", "local_receive_ts": "2026-06-21T04:27:12Z", "monotonic_ns": 1643587932556602, "raw": "{\"arg\":{\"channel\":\"books\",\"instId\":\"BTC-USDT-SWAP\"},\"action\":\"update\",\"data\":[{\"asks\":[[\"64483\",\"206.46\",\"0\",\"17\"],[\"64487.3\",\"138.93\",\"0\",\"5\"],[\"64487.7\",\"1.57\",\"0\",\"2\"],[\"64488.2\",\"5.52\",\"0\",\"3\"],[\"64488.7\",\"2.8\",\"0\",\"3\"],[\"64489.2\",\"9.26\",\"0\",\"3\"],[\"64489.5\",\"0.02\",\"0\",\"2\"],[\"64490\",\"56.15\",\"0\",\"20\"],[\"64490.5\",\"1.81\",\"0\",\"3\"],[\"64494.2\",\"4.89\",\"0\",\"2\"],[\"64495.2\",\"6.12\",\"0\",\"4\"],[\"64499.6\",\"65.59\",\"0\",\"4\"],[\"64499.7\",\"35.37\",\"0\",\"5\"],[\"64500.4\",\"0.03\",\"0\",\"3\"],[\"64500.6\",\"0.56\",\"0\",\"4\"],[\"64502.3\",\"42.29\",\"0\",\"5\"],[\"64502.9\",\"282.85\",\"0\",\"8\"],[\"64503\",\"248.72\",\"0\",\"4\"],[\"64503.1\",\"39.69\",\"0\",\"8\"],[\"64503.4\",\"0\",\"0\",\"0\"],[\"64503.8\",\"0.31\",\"0\",\"1\"],[\"64506.7\",\"0.19\",\"0\",\"15\"],[\"64507\",\"33.85\",\"0\",\"2\"],[\"64507.3\",\"0.8\",\"0\",\"3\"],[\"64508.1\",\"0.82\",\"0\",\"3\"],[\"64511.7\",\"85.35\",\"0\",\"3\"],[\"64512.2\",\"11.23\",\"0\",\"3\"],[\"64513.5\",\"0.6\",\"0\",\"3\"],[\"64514.1\",\"58.21\",\"0\",\"4\"],[\"64517.6\",\"45.64\",\"0\",\"3\"],[\"64518.3\",\"0.02\",\"0\",\"2\"],[\"64518.7\",\"86.1\",\"0\",\"1\"],[\"64519.7\",\"10.81\",\"0\",\"7\"],[\"64524.6\",\"0.01\",\"0\",\"1\"],[\"64527.1\",\"0\",\"0\",\"0\"]],\"bids\":[[\"64482.9\",\"1058.94\",\"0\",\"70\"],[\"64471\",\"0.31\",\"0\",\"1\"],[\"64470.5\",\"0.01\",\"0\",\"1\"],[\"64470\",\"237.27\",\"0\",\"4\"],[\"64469.4\",\"145.12\",\"0\",\"3\"],[\"64469\",\"0\",\"0\",\"0\"],[\"64468.3\",\"0.77\",\"0\",\"1\"],[\"64467.9\",\"33.82\",\"0\",\"2\"],[\"64467.8\",\"0.56\",\"0\",\"2\"],[\"64467.2\",\"20.08\",\"0\",\"1\"],[\"64466.9\",\"0\",\"0\",\"0\"],[\"64466.1\",\"85.77\",\"0\",\"2\"],[\"64465.2\",\"58.22\",\"0\",\"1\"],[\"64464.4\",\"31.06\",\"0\",\"2\"],[\"64422.4\",\"0\",\"0\",\"0\"]],\"ts\":\"1782016032005\",\"checksum\":-1215203088,\"seqId\":325070077993,\"prevSeqId\":325070077856}]}"}
{"action": "update", "capture_sequence": 190, "channel": "books", "connection_sequence": 2, "event": null, "instId": "BTC-USDT-SWAP", "local_receive_ts": "2026-06-21T04:27:12Z", "monotonic_ns": 1643588033484860, "raw": "{\"arg\":{\"channel\":\"books\",\"instId\":\"BTC-USDT-SWAP\"},\"action\":\"update\",\"data\":[{\"asks\":[[\"64483\",\"199.64\",\"0\",\"17\"],[\"64487.3\",\"137.37\",\"0\",\"4\"],[\"64487.4\",\"2.06\",\"0\",\"7\"],[\"64487.7\",\"0.01\",\"0\",\"1\"],[\"64488.1\",\"2.22\",\"0\",\"2\"],[\"64488.2\",\"3.96\",\"0\",\"2\"],[\"64488.7\",\"1.24\",\"0\",\"2\"],[\"64489.6\",\"2.95\",\"0\",\"5\"],[\"64490.1\",\"20.44\",\"0\",\"5\"],[\"64492.4\",\"16.09\",\"0\",\"8\"],[\"64492.7\",\"101.44\",\"0\",\"4\"],[\"64493.6\",\"0.03\",\"0\",\"2\"],[\"64494.1\",\"0\",\"0\",\"0\"],[\"64499.8\",\"16.59\",\"0\",\"3\"],[\"64500.2\",\"0.02\",\"0\",\"2\"],[\"64500.8\",\"2.51\",\"0\",\"2\"],[\"64502.3\",\"11.26\",\"0\",\"4\"],[\"64502.4\",\"31.22\",\"0\",\"7\"],[\"64502.9\",\"513.49\",\"0\",\"8\"],[\"64503\",\"15.96\",\"0\",\"4\"],[\"64503.4\",\"0.31\",\"0\",\"1\"],[\"64503.5\",\"63.72\",\"0\",\"6\"],[\"64503.8\",\"0\",\"0\",\"0\"],[\"64505.3\",\"1.66\",\"0\",\"3\"],[\"64505.5\",\"5.46\",\"0\",\"3\"],[\"64506.8\",\"2.32\",\"0\",\"6\"],[\"64507\",\"0.06\",\"0\",\"1\"],[\"64507.3\",\"0.03\",\"0\",\"2\"],[\"64507.7\",\"33.86\",\"0\",\"5\"],[\"64511.7\",\"0.02\",\"0\",\"2\"],[\"64512.5\",\"85.49\",\"0\",\"6\"],[\"64513.4\",\"73.86\",\"0\",\"4\"],[\"64514.1\",\"0.03\",\"0\",\"3\"],[\"64517.6\",\"25.58\",\"0\",\"2\"],[\"64518.5\",\"20.07\",\"0\",\"2\"],[\"64518.7\",\"0\",\"0\",\"0\"],[\"64519.7\",\"96.91\",\"0\",\"8\"],[\"64520.1\",\"0.03\",\"0\",\"3\"],[\"64521.1\",\"0.01\",\"0\",\"1\"],[\"64527.1\",\"0.46\",\"0\",\"1\"],[\"64527.2\",\"0.18\",\"0\",\"4\"]],\"bids\":[[\"64479.8\",\"75.52\",\"0\",\"5\"],[\"64479.7\",\"0\",\"0\",\"0\"],[\"64471\",\"0\",\"0\",\"0\"],[\"64470.5\",\"1.09\",\"0\",\"3\"],[\"64470.4\",\"4\",\"0\",\"1\"],[\"64470.1\",\"621.95\",\"0\",\"2\"],[\"64469.6\",\"1.71\",\"0\",\"3\"],[\"64469.5\",\"0.03\",\"0\",\"2\"],[\"64469.4\",\"58.95\",\"0\",\"2\"],[\"64469.2\",\"154.75\",\"0\",\"2\"],[\"64468.8\",\"45.14\",\"0\",\"2\"],[\"64468.6\",\"0.02\",\"0\",\"1\"],[\"64468.3\",\"0\",\"0\",\"0\"],[\"64467.9\",\"20.09\",\"0\",\"2\"],[\"64467.7\",\"0.77\",\"0\",\"1\"],[\"64467.3\",\"103.03\",\"0\",\"2\"],[\"64467.2\",\"0\",\"0\",\"0\"],[\"64467.1\",\"116.61\",\"0\",\"3\"],[\"64466.9\",\"0.02\",\"0\",\"1\"],[\"64466.1\",\"0.38\",\"0\",\"1\"],[\"64465.3\",\"46.56\",\"0\",\"3\"],[\"64465.2\",\"0\",\"0\",\"0\"],[\"64465\",\"200.02\",\"0\",\"2\"],[\"64464.8\",\"0.01\",\"0\",\"1\"],[\"64464.5\",\"31.07\",\"0\",\"3\"],[\"64464.4\",\"58.23\",\"0\",\"2\"],[\"64464.3\",\"0\",\"0\",\"0\"],[\"64463.9\",\"232.91\",\"0\",\"1\"],[\"64457.3\",\"0.02\",\"0\",\"1\"],[\"64457\",\"574.32\",\"0\",\"5\"]],\"ts\":\"1782016032105\",\"checksum\":-464011670,\"seqId\":325070078243,\"prevSeqId\":325070077993}]}"}
{"action": "update", "capture_sequence": 191, "channel": "books", "connection_sequence": 2, "event": null, "instId": "BTC-USDT-SWAP", "local_receive_ts": "2026-06-21T04:27:12Z", "monotonic_ns": 1643588124619430, "raw": "{\"arg\":{\"channel\":\"books\",\"instId\":\"BTC-USDT-SWAP\"},\"action\":\"update\",\"data\":[{\"asks\":[[\"64484.4\",\"50.31\",\"0\",\"2\"],[\"64486.2\",\"79.11\",\"0\",\"9\"],[\"64487.1\",\"0.53\",\"0\",\"4\"],[\"64487.4\",\"0.5\",\"0\",\"6\"],[\"64487.6\",\"2.76\",\"0\",\"2\"],[\"64488.6\",\"1.58\",\"0\",\"3\"],[\"64489.1\",\"1.6\",\"0\",\"4\"],[\"64489.2\",\"7.7\",\"0\",\"2\"],[\"64492.7\",\"99.88\",\"0\",\"3\"],[\"64502.4\",\"0.19\",\"0\",\"6\"],[\"64502.7\",\"31.06\",\"0\",\"4\"],[\"64502.9\",\"280.72\",\"0\",\"7\"],[\"64503.4\",\"233.08\",\"0\",\"2\"],[\"64507.6\",\"33.82\",\"0\",\"3\"],[\"64507.7\",\"0.07\",\"0\",\"4\"],[\"64513.4\",\"15.68\",\"0\",\"3\"],[\"64513.9\",\"58.3\",\"0\",\"2\"]],\"bids\":[[\"64482.9\",\"1062.2\",\"0\",\"70\"],[\"64479.8\",\"75.5\",\"0\",\"4\"],[\"64479.7\",\"0.02\",\"0\",\"1\"],[\"64469.6\",\"1.69\",\"0\",\"2\"],[\"64469.3\",\"498.47\",\"0\",\"3\"],[\"64468.8\",\"11.33\",\"0\",\"1\"],[\"64468.6\",\"33.83\",\"0\",\"2\"],[\"64464.8\",\"58.23\",\"0\",\"2\"],[\"64464.4\",\"0.01\",\"0\",\"1\"],[\"64464.3\",\"232.91\",\"0\",\"1\"],[\"64463.9\",\"0\",\"0\",\"0\"],[\"64457.3\",\"0\",\"0\",\"0\"],[\"64457\",\"574.34\",\"0\",\"6\"],[\"64423.5\",\"0\",\"0\",\"0\"],[\"64422.7\",\"4.4\",\"0\",\"4\"],[\"64422.6\",\"0.02\",\"0\",\"2\"],[\"64422.4\",\"1366.68\",\"0\",\"4\"]],\"ts\":\"1782016032205\",\"checksum\":1471867571,\"seqId\":325070078314,\"prevSeqId\":325070078243}]}"}
{"action": "update", "capture_sequence": 192, "channel": "books", "connection_sequence": 2, "event": null, "instId": "BTC-USDT-SWAP", "local_receive_ts": "2026-06-21T04:27:12Z", "monotonic_ns": 1643588225379605, "raw": "{\"arg\":{\"channel\":\"books\",\"instId\":\"BTC-USDT-SWAP\"},\"action\":\"update\",\"data\":[{\"asks\":[[\"64487.6\",\"1.2\",\"0\",\"1\"],[\"64488.1\",\"0.66\",\"0\",\"1\"],[\"64488.6\",\"0.02\",\"0\",\"2\"],[\"64488.7\",\"2.8\",\"0\",\"3\"],[\"64492.7\",\"101.44\",\"0\",\"4\"],[\"64493.1\",\"43.18\",\"0\",\"7\"],[\"64499.7\",\"35.54\",\"0\",\"6\"],[\"64499.8\",\"1.08\",\"0\",\"2\"],[\"64500.2\",\"15.53\",\"0\",\"3\"],[\"64500.6\",\"0.39\",\"0\",\"3\"]],\"bids\":[],\"ts\":\"1782016032305\",\"checksum\":1471867571,\"seqId\":325070078339,\"prevSeqId\":325070078314}]}"}
{"action": "update", "capture_sequence": 193, "channel": "books", "connection_sequence": 2, "event": null, "instId": "BTC-USDT-SWAP", "local_receive_ts": "2026-06-21T04:27:12Z", "monotonic_ns": 1643588326485530, "raw": "{\"arg\":{\"channel\":\"books\",\"instId\":\"BTC-USDT-SWAP\"},\"action\":\"update\",\"data\":[{\"asks\":[[\"64483\",\"199.83\",\"0\",\"18\"],[\"64488\",\"59.43\",\"0\",\"28\"],[\"64502.7\",\"31.37\",\"0\",\"5\"],[\"64503.4\",\"232.77\",\"0\",\"1\"],[\"64507.4\",\"61.06\",\"0\",\"2\"],[\"64507.6\",\"0.03\",\"0\",\"2\"],[\"64512.1\",\"85.37\",\"0\",\"4\"],[\"64512.5\",\"0.16\",\"0\",\"5\"],[\"64518.5\",\"0.01\",\"0\",\"1\"],[\"64519.1\",\"63.13\",\"0\",\"3\"],[\"64519.7\",\"10.81\",\"0\",\"7\"],[\"64520.9\",\"86.12\",\"0\",\"3\"]],\"bids\":[[\"64473.5\",\"62.05\",\"0\",\"2\"],[\"64470.5\",\"0.78\",\"0\",\"2\"],[\"64470.4\",\"90.16\",\"0\",\"2\"],[\"64470.2\",\"2.98\",\"0\",\"3\"],[\"64470.1\",\"535.79\",\"0\",\"1\"],[\"64468.7\",\"107.33\",\"0\",\"8\"],[\"64468.6\",\"0.02\",\"0\",\"1\"],[\"64468.3\",\"33.81\",\"0\",\"1\"],[\"64468\",\"0.79\",\"0\",\"3\"],[\"64467.9\",\"0.01\",\"0\",\"1\"],[\"64467.7\",\"0\",\"0\",\"0\"],[\"64467.1\",\"31.22\",\"0\",\"2\"],[\"64466.6\",\"85.4\",\"0\",\"2\"]],\"ts\":\"1782016032405\",\"checksum\":606533727,\"seqId\":325070078404,\"prevSeqId\":325070078339}]}"}
{"action": "update", "capture_sequence": 194, "channel": "books", "connection_sequence": 2, "event": null, "instId": "BTC-USDT-SWAP", "local_receive_ts": "2026-06-21T04:27:12Z", "monotonic_ns": 1643588431991171, "raw": "{\"arg\":{\"channel\":\"books\",\"instId\":\"BTC-USDT-SWAP\"},\"action\":\"update\",\"data\":[{\"asks\":[[\"64488\",\"57.87\",\"0\",\"27\"],[\"64488.3\",\"2.78\",\"0\",\"4\"],[\"64488.7\",\"1.24\",\"0\",\"2\"],[\"64488.8\",\"51.56\",\"0\",\"2\"],[\"64489.1\",\"0.04\",\"0\",\"3\"],[\"64489.4\",\"4.49\",\"0\",\"6\"],[\"64489.6\",\"1.39\",\"0\",\"4\"],[\"64492.5\",\"93.49\",\"0\",\"4\"],[\"64502.7\",\"0.03\",\"0\",\"3\"],[\"64502.8\",\"88.1\",\"0\",\"4\"],[\"64503.3\",\"0.33\",\"0\",\"3\"],[\"64506.7\",\"0.96\",\"0\",\"16\"],[\"64506.8\",\"1.55\",\"0\",\"5\"],[\"64513.2\",\"58.33\",\"0\",\"5\"],[\"64513.9\",\"0.12\",\"0\",\"1\"],[\"64518.1\",\"24.94\",\"0\",\"7\"],[\"64519.1\",\"129.17\",\"0\",\"3\"],[\"64520.1\",\"0.02\",\"0\",\"2\"],[\"64520.9\",\"0.02\",\"0\",\"2\"],[\"64521\",\"121.99\",\"0\",\"9\"],[\"64524.7\",\"15.81\",\"0\",\"2\"]],\"bids\":[[\"64479.8\",\"75.52\",\"0\",\"5\"],[\"64479.7\",\"0\",\"0\",\"0\"],[\"64473.5\",\"42.85\",\"0\",\"1\"],[\"64470.6\",\"0.31\",\"0\",\"1\"],[\"64470.4\",\"4\",\"0\",\"1\"],[\"64470.2\",\"2.67\",\"0\",\"2\"],[\"64469.6\",\"1.71\",\"0\",\"3\"],[\"64469.5\",\"0.01\",\"0\",\"1\"],[\"64469.4\",\"145.12\",\"0\",\"3\"],[\"64468.7\",\"87.25\",\"0\",\"7\"],[\"64468\",\"0.02\",\"0\",\"2\"],[\"64467.7\",\"20.85\",\"0\",\"2\"],[\"64466.9\",\"0\",\"0\",\"0\"],[\"64466.5\",\"16\",\"0\",\"2\"],[\"64465\",\"231.05\",\"0\",\"2\"],[\"64464.9\",\"31.08\",\"0\",\"2\"],[\"64464.8\",\"0.01\",\"0\",\"1\"],[\"64464.5\",\"0.02\",\"0\",\"2\"],[\"64464.4\",\"58.23\",\"0\",\"2\"],[\"64459.9\",\"0\",\"0\",\"0\"],[\"64457.1\",\"415.24\",\"0\",\"4\"],[\"64457\",\"574.32\",\"0\",\"5\"],[\"64453.6\",\"0.04\",\"0\",\"2\"],[\"64423.5\",\"19.6\",\"0\",\"1\"],[\"64422.7\",\"23.42\",\"0\",\"5\"],[\"64422.6\",\"18.89\",\"0\",\"3\"]],\"ts\":\"1782016032505\",\"checksum\":2075926223,\"seqId\":325070078498,\"prevSeqId\":325070078404}]}"}
{"action": "update", "capture_sequence": 195, "channel": "books", "connection_sequence": 2, "event": null, "instId": "BTC-USDT-SWAP", "local_receive_ts": "2026-06-21T04:27:12Z", "monotonic_ns": 1643588524721583, "raw": "{\"arg\":{\"channel\":\"books\",\"instId\":\"BTC-USDT-SWAP\"},\"action\":\"update\",\"data\":[{\"asks\":[[\"64486.1\",\"1.57\",\"0\",\"2\"],[\"64487.6\",\"2.76\",\"0\",\"2\"],[\"64488.1\",\"2.22\",\"0\",\"2\"],[\"64488.3\",\"1.22\",\"0\",\"3\"],[\"64488.6\",\"1.58\",\"0\",\"3\"],[\"64488.8\",\"50\",\"0\",\"1\"],[\"64492.5\",\"93.64\",\"0\",\"5\"],[\"64493.1\",\"41.62\",\"0\",\"6\"]],\"bids\":[[\"64460\",\"3.41\",\"0\",\"4\"],[\"64453.6\",\"0.23\",\"0\",\"3\"]],\"ts\":\"1782016032605\",\"checksum\":-1392824515,\"seqId\":325070078525,\"prevSeqId\":325070078498}]}"}
{"action": null, "capture_sequence": 196, "channel": "trades", "connection_sequence": 2, "event": null, "instId": "BTC-USDT-SWAP", "local_receive_ts": "2026-06-21T04:27:12Z", "monotonic_ns": 1643588574948944, "raw": "{\"arg\":{\"channel\":\"trades\",\"instId\":\"BTC-USDT-SWAP\"},\"data\":[{\"instId\":\"BTC-USDT-SWAP\",\"tradeId\":\"2718750251\",\"px\":\"64482.9\",\"sz\":\"0.06\",\"side\":\"sell\",\"ts\":\"1782016032655\",\"count\":\"1\",\"source\":\"0\",\"seqId\":325070078539}]}"}
{"action": null, "capture_sequence": 197, "channel": "trades", "connection_sequence": 2, "event": null, "instId": "BTC-USDT-SWAP", "local_receive_ts": "2026-06-21T04:27:12Z", "monotonic_ns": 1643588596875346, "raw": "{\"arg\":{\"channel\":\"trades\",\"instId\":\"BTC-USDT-SWAP\"},\"data\":[{\"instId\":\"BTC-USDT-SWAP\",\"tradeId\":\"2718750253\",\"px\":\"64482.9\",\"sz\":\"5.43\",\"side\":\"sell\",\"ts\":\"1782016032677\",\"count\":\"2\",\"source\":\"0\",\"seqId\":325070078566}]}"}
{"action": "update", "capture_sequence": 198, "channel": "books", "connection_sequence": 2, "event": null, "instId": "BTC-USDT-SWAP", "local_receive_ts": "2026-06-21T04:27:12Z", "monotonic_ns": 1643588624993069, "raw": "{\"arg\":{\"channel\":\"books\",\"instId\":\"BTC-USDT-SWAP\"},\"action\":\"update\",\"data\":[{\"asks\":[[\"64485.3\",\"0.01\",\"0\",\"1\"],[\"64485.4\",\"1.56\",\"0\",\"1\"],[\"64485.8\",\"0.42\",\"0\",\"4\"],[\"64486.1\",\"0.01\",\"0\",\"1\"],[\"64492.2\",\"0.91\",\"0\",\"7\"],[\"64492.7\",\"99.88\",\"0\",\"3\"],[\"64524.7\",\"0.02\",\"0\",\"1\"],[\"64527.1\",\"0\",\"0\",\"0\"],[\"64527.2\",\"0\",\"0\",\"0\"]],\"bids\":[[\"64482.9\",\"1055.15\",\"0\",\"68\"],[\"64481.1\",\"1.56\",\"0\",\"1\"],[\"64480.5\",\"2.46\",\"0\",\"1\"],[\"64480.4\",\"1.56\",\"0\",\"1\"],[\"64476.5\",\"12.96\",\"0\",\"2\"],[\"64423.5\",\"0\",\"0\",\"0\"],[\"64422.7\",\"4.4\",\"0\",\"4\"],[\"64422.6\",\"0.02\",\"0\",\"2\"],[\"64422.4\",\"0\",\"0\",\"0\"]],\"ts\":\"1782016032705\",\"checksum\":956488634,\"seqId\":325070078591,\"prevSeqId\":325070078525}]}"}
{"action": "update", "capture_sequence": 199, "channel": "books", "connection_sequence": 2, "event": null, "instId": "BTC-USDT-SWAP", "local_receive_ts": "2026-06-21T04:27:12Z", "monotonic_ns": 1643588724785380, "raw": "{\"arg\":{\"channel\":\"books\",\"instId\":\"BTC-USDT-SWAP\"},\"action\":\"update\",\"data\":[{\"asks\":[[\"64485.3\",\"0\",\"0\",\"0\"],[\"64485.4\",\"0\",\"0\",\"0\"],[\"64485.8\",\"0.43\",\"0\",\"5\"],[\"64492.5\",\"93.49\",\"0\",\"4\"],[\"64527.1\",\"0.46\",\"0\",\"1\"],[\"64527.2\",\"0.18\",\"0\",\"4\"]],\"bids\":[[\"64481.1\",\"0\",\"0\",\"0\"],[\"64470\",\"237.69\",\"0\",\"5\"],[\"64469.9\",\"171.18\",\"0\",\"5\"],[\"64460\",\"0.31\",\"0\",\"3\"],[\"64453.6\",\"0.04\",\"0\",\"2\"],[\"64422.4\",\"1366.68\",\"0\",\"4\"]],\"ts\":\"1782016032805\",\"checksum\":-1906863367,\"seqId\":325070078625,\"prevSeqId\":325070078591}]}"}
{"action": "update", "capture_sequence": 200, "channel": "books", "connection_sequence": 2, "event": null, "instId": "BTC-USDT-SWAP", "local_receive_ts": "2026-06-21T04:27:13Z", "monotonic_ns": 1643588824564151, "raw": "{\"arg\":{\"channel\":\"books\",\"instId\":\"BTC-USDT-SWAP\"},\"action\":\"update\",\"data\":[{\"asks\":[[\"64492.6\",\"60.75\",\"0\",\"2\"]],\"bids\":[[\"64480.4\",\"0\",\"0\",\"0\"],[\"64479.8\",\"73.96\",\"0\",\"4\"],[\"64460.1\",\"7.01\",\"0\",\"3\"],[\"64453.7\",\"0.19\",\"0\",\"1\"]],\"ts\":\"1782016032905\",\"checksum\":570890995,\"seqId\":325070078635,\"prevSeqId\":325070078625}]}"}
{"action": "update", "capture_sequence": 201, "channel": "books", "connection_sequence": 2, "event": null, "instId": "BTC-USDT-SWAP", "local_receive_ts": "2026-06-21T04:27:13Z", "monotonic_ns": 1643588924432856, "raw": "{\"arg\":{\"channel\":\"books\",\"instId\":\"BTC-USDT-SWAP\"},\"action\":\"update\",\"data\":[{\"asks\":[[\"64486.3\",\"1.57\",\"0\",\"2\"],[\"64519.1\",\"43.07\",\"0\",\"2\"],[\"64519.7\",\"96.91\",\"0\",\"8\"]],\"bids\":[[\"64482.9\",\"1056.71\",\"0\",\"69\"],[\"64482.3\",\"1.56\",\"0\",\"1\"],[\"64481.9\",\"1.56\",\"0\",\"1\"],[\"64470\",\"323.86\",\"0\",\"6\"],[\"64469.4\",\"58.95\",\"0\",\"2\"],[\"64422.5\",\"0\",\"0\",\"0\"],[\"64422.4\",\"0\",\"0\",\"0\"]],\"ts\":\"1782016033005\",\"checksum\":-2145065224,\"seqId\":325070078648,\"prevSeqId\":325070078635}]}"}
{"action": "update", "capture_sequence": 202, "channel": "books", "connection_sequence": 2, "event": null, "instId": "BTC-USDT-SWAP", "local_receive_ts": "2026-06-21T04:27:13Z", "monotonic_ns": 1643589024924311, "raw": "{\"arg\":{\"channel\":\"books\",\"instId\":\"BTC-USDT-SWAP\"},\"action\":\"update\",\"data\":[{\"asks\":[[\"64483\",\"277.48\",\"0\",\"19\"],[\"64485.6\",\"1.56\",\"0\",\"1\"],[\"64486.2\",\"1.57\",\"0\",\"8\"],[\"64486.3\",\"0.01\",\"0\",\"1\"],[\"64486.4\",\"2.83\",\"0\",\"3\"],[\"64486.9\",\"2.67\",\"0\",\"3\"],[\"64487.4\",\"2.06\",\"0\",\"7\"],[\"64487.6\",\"1.2\",\"0\",\"1\"],[\"64500.2\",\"0.02\",\"0\",\"2\"],[\"64500.4\",\"15.54\",\"0\",\"4\"],[\"64503.4\",\"0\",\"0\",\"0\"],[\"64503.8\",\"232.77\",\"0\",\"1\"],[\"64505.1\",\"1.57\",\"0\",\"3\"],[\"64505.5\",\"3.91\",\"0\",\"2\"],[\"64519.1\",\"129.17\",\"0\",\"3\"],[\"64519.7\",\"10.81\",\"0\",\"7\"],[\"64527.2\",\"0\",\"0\",\"0\"]],\"bids\":[[\"64482.9\",\"1037.17\",\"0\",\"68\"],[\"64482.4\",\"0.02\",\"0\",\"1\"],[\"64482.1\",\"0.01\",\"0\",\"1\"],[\"64478.2\",\"13.95\",\"0\",\"1\"],[\"64470\",\"237.69\",\"0\",\"5\"],[\"64469.4\",\"145.12\",\"0\",\"3\"],[\"64464.5\",\"232.93\",\"0\",\"3\"],[\"64464.3\",\"0\",\"0\",\"0\"],[\"64422.6\",\"0\",\"0\",\"0\"]],\"ts\":\"1782016033105\",\"checksum\":1952528529,\"seqId\":325070078718,\"prevSeqId\":325070078648}]}"}
{"action": "update", "capture_sequence": 203, "channel": "books", "connection_sequence": 2, "event": null, "instId": "BTC-USDT-SWAP", "local_receive_ts": "2026-06-21T04:27:13Z", "monotonic_ns": 1643589125487443, "raw": "{\"arg\":{\"channel\":\"books\",\"instId\":\"BTC-USDT-SWAP\"},\"action\":\"update\",\"data\":[{\"asks\":[[\"64484.4\",\"31.33\",\"0\",\"1\"],[\"64485.2\",\"0.03\",\"0\",\"3\"],[\"64485.3\",\"1.56\",\"0\",\"1\"],[\"64485.6\",\"0\",\"0\",\"0\"],[\"64485.8\",\"0.42\",\"0\",\"4\"],[\"64485.9\",\"6.99\",\"0\",\"3\"],[\"64491\",\"0.01\",\"0\",\"1\"],[\"64491.7\",\"15.94\",\"0\",\"3\"],[\"64498.7\",\"2.03\",\"0\",\"4\"],[\"64499.7\",\"35.37\",\"0\",\"5\"],[\"64500.4\",\"0.03\",\"0\",\"3\"],[\"64500.8\",\"18.02\",\"0\",\"3\"],[\"64502.8\",\"57.07\",\"0\",\"3\"],[\"64503.6\",\"31.05\",\"0\",\"3\"],[\"64504.5\",\"59.15\",\"0\",\"6\"],[\"64524.8\",\"19.1\",\"0\",\"6\"]],\"bids\":[[\"64482.9\",\"1035.62\",\"0\",\"67\"],[\"64482.8\",\"96.72\",\"0\",\"12\"],[\"64482.7\",\"1.58\",\"0\",\"2\"],[\"64482.4\",\"0\",\"0\",\"0\"],[\"64482.3\",\"0\",\"0\",\"0\"],[\"64482\",\"6.57\",\"0\",\"3\"],[\"64481.9\",\"0\",\"0\",\"0\"],[\"64481.5\",\"1.57\",\"0\",\"2\"],[\"64481\",\"1.57\",\"0\",\"2\"],[\"64480.6\",\"0.01\",\"0\",\"1\"],[\"64480.2\",\"0.31\",\"0\",\"1\"],[\"64465.7\",\"37.27\",\"0\",\"2\"],[\"64465\",\"200\",\"0\",\"1\"],[\"64422.6\",\"0.02\",\"0\",\"2\"],[\"64422.5\",\"395.33\",\"0\",\"1\"]],\"ts\":\"1782016033205\",\"checksum\":2130214911,\"seqId\":325070078807,\"prevSeqId\":325070078718}]}"}
{"action": "update", "capture_sequence": 204, "channel": "books", "connection_sequence": 2, "event": null, "instId": "BTC-USDT-SWAP", "local_receive_ts": "2026-06-21T04:27:13Z", "monotonic_ns": 1643589224736821, "raw": "{\"arg\":{\"channel\":\"books\",\"instId\":\"BTC-USDT-SWAP\"},\"action\":\"update\",\"data\":[{\"asks\":[[\"64485.2\",\"0.02\",\"0\",\"2\"],[\"64485.3\",\"0\",\"0\",\"0\"],[\"64485.8\",\"0.43\",\"0\",\"5\"],[\"64485.9\",\"5.43\",\"0\",\"2\"],[\"64486.4\",\"1.27\",\"0\",\"2\"],[\"64486.5\",\"1.57\",\"0\",\"2\"],[\"64490.6\",\"33.07\",\"0\",\"5\"],[\"64491.1\",\"1.56\",\"0\",\"1\"],[\"64496.3\",\"506.38\",\"0\",\"7\"],[\"64499.6\",\"81.1\",\"0\",\"5\"],[\"64500.8\",\"2.51\",\"0\",\"2\"],[\"64502.2\",\"83.91\",\"0\",\"6\"],[\"64502.3\",\"42.29\",\"0\",\"5\"],[\"64502.8\",\"289.84\",\"0\",\"4\"],[\"64503.6\",\"0.02\",\"0\",\"2\"],[\"64503.8\",\"0\",\"0\",\"0\"],[\"64505.1\",\"0.02\",\"0\",\"2\"],[\"64505.3\",\"3.21\",\"0\",\"4\"],[\"64527.2\",\"0.18\",\"0\",\"4\"]],\"bids\":[[\"64480.6\",\"0.32\",\"0\",\"2\"],[\"64480.2\",\"0\",\"0\",\"0\"],[\"64474.1\",\"6.23\",\"0\",\"2\"],[\"64470.5\",\"31.83\",\"0\",\"3\"],[\"64465.7\",\"6.22\",\"0\",\"1\"],[\"64464.5\",\"31.07\",\"0\",\"3\"],[\"64463.9\",\"232.91\",\"0\",\"1\"]],\"ts\":\"1782016033305\",\"checksum\":1106210764,\"seqId\":325070078860,\"prevSeqId\":325070078807}]}"}
{"action": null, "capture_sequence": 205, "channel": "trades", "connection_sequence": 2, "event": null, "instId": "BTC-USDT-SWAP", "local_receive_ts": "2026-06-21T04:27:13Z", "monotonic_ns": 1643589294303706, "raw": "{\"arg\":{\"channel\":\"trades\",\"instId\":\"BTC-USDT-SWAP\"},\"data\":[{\"instId\":\"BTC-USDT-SWAP\",\"tradeId\":\"2718750254\",\"px\":\"64482.9\",\"sz\":\"1.54\",\"side\":\"sell\",\"ts\":\"1782016033375\",\"count\":\"1\",\"source\":\"0\",\"seqId\":325070078887}]}"}
{"action": "update", "capture_sequence": 206, "channel": "books", "connection_sequence": 2, "event": null, "instId": "BTC-USDT-SWAP", "local_receive_ts": "2026-06-21T04:27:13Z", "monotonic_ns": 1643589324998257, "raw": "{\"arg\":{\"channel\":\"books\",\"instId\":\"BTC-USDT-SWAP\"},\"action\":\"update\",\"data\":[{\"asks\":[[\"64483\",\"277.47\",\"0\",\"19\"],[\"64484.5\",\"1.63\",\"0\",\"5\"],[\"64485.4\",\"0.01\",\"0\",\"1\"],[\"64485.5\",\"1.57\",\"0\",\"2\"],[\"64485.8\",\"0.42\",\"0\",\"4\"],[\"64486\",\"53.65\",\"0\",\"8\"],[\"64490.6\",\"31.51\",\"0\",\"4\"],[\"64491.1\",\"0\",\"0\",\"0\"],[\"64499.6\",\"65.59\",\"0\",\"4\"],[\"64499.9\",\"1130.18\",\"0\",\"3\"],[\"64502.8\",\"57.07\",\"0\",\"3\"],[\"64503.4\",\"232.77\",\"0\",\"1\"],[\"64526\",\"1.15\",\"0\",\"3\"],[\"64527.2\",\"0\",\"0\",\"0\"]],\"bids\":[[\"64482.9\",\"1035.18\",\"0\",\"68\"],[\"64482.8\",\"96.7\",\"0\",\"11\"],[\"64482.7\",\"0.02\",\"0\",\"1\"],[\"64482.1\",\"0.03\",\"0\",\"2\"],[\"64476.7\",\"4.78\",\"0\",\"2\"],[\"64474.1\",\"37.28\",\"0\",\"3\"],[\"64470.5\",\"0.78\",\"0\",\"2\"],[\"64464.3\",\"232.91\",\"0\",\"1\"],[\"64463.9\",\"0\",\"0\",\"0\"]],\"ts\":\"1782016033405\",\"checksum\":-49396196,\"seqId\":325070078913,\"prevSeqId\":325070078860}]}"}
{"action": null, "capture_sequence": 207, "channel": "trades", "connection_sequence": 2, "event": null, "instId": "BTC-USDT-SWAP", "local_receive_ts": "2026-06-21T04:27:13Z", "monotonic_ns": 1643589351686848, "raw": "{\"arg\":{\"channel\":\"trades\",\"instId\":\"BTC-USDT-SWAP\"},\"data\":[{\"instId\":\"BTC-USDT-SWAP\",\"tradeId\":\"2718750255\",\"px\":\"64482.9\",\"sz\":\"1.34\",\"side\":\"sell\",\"ts\":\"1782016033432\",\"count\":\"1\",\"source\":\"0\",\"seqId\":325070078930}]}"}
{"action": "update", "capture_sequence": 208, "channel": "books", "connection_sequence": 2, "event": null, "instId": "BTC-USDT-SWAP", "local_receive_ts": "2026-06-21T04:27:13Z", "monotonic_ns": 1643589432987649, "raw": "{\"arg\":{\"channel\":\"books\",\"instId\":\"BTC-USDT-SWAP\"},\"action\":\"update\",\"data\":[{\"asks\":[[\"64483\",\"430.69\",\"0\",\"26\"],[\"64483.1\",\"2.18\",\"0\",\"4\"],[\"64483.5\",\"0.01\",\"0\",\"1\"],[\"64483.6\",\"1.56\",\"0\",\"1\"],[\"64484\",\"0.56\",\"0\",\"4\"],[\"64484.1\",\"1.58\",\"0\",\"2\"],[\"64484.4\",\"69.19\",\"0\",\"2\"],[\"64484.5\",\"0.07\",\"0\",\"4\"],[\"64484.8\",\"1.56\",\"0\",\"1\"],[\"64484.9\",\"0.01\",\"0\",\"1\"],[\"64485.3\",\"1.56\",\"0\",\"1\"],[\"64485.4\",\"0\",\"0\",\"0\"],[\"64485.5\",\"0.01\",\"0\",\"1\"],[\"64485.7\",\"136.47\",\"0\",\"5\"],[\"64486.6\",\"67.37\",\"0\",\"4\"],[\"64487.3\",\"1.24\",\"0\",\"3\"],[\"64488.6\",\"0.02\",\"0\",\"2\"],[\"64489.4\",\"2.93\",\"0\",\"5\"],[\"64490.1\",\"18.88\",\"0\",\"4\"],[\"64492.6\",\"60.6\",\"0\",\"1\"],[\"64493.4\",\"0.33\",\"0\",\"6\"],[\"64493.6\",\"0.02\",\"0\",\"1\"],[\"64495.2\",\"24.72\",\"0\",\"7\"],[\"64495.3\",\"0.26\",\"0\",\"2\"],[\"64502.5\",\"70.41\",\"0\",\"5\"],[\"64502.7\",\"232.8\",\"0\",\"4\"],[\"64503.3\",\"0.02\",\"0\",\"2\"],[\"64503.4\",\"0\",\"0\",\"0\"],[\"64504.9\",\"1.65\",\"0\",\"4\"],[\"64505.3\",\"1.66\",\"0\",\"3\"],[\"64506\",\"10.84\",\"0\",\"6\"],[\"64506.7\",\"0.19\",\"0\",\"15\"],[\"64511.8\",\"91.53\",\"0\",\"2\"],[\"64511.9\",\"59.52\",\"0\",\"3\"],[\"64512.1\",\"0.04\",\"0\",\"3\"],[\"64513.2\",\"0.15\",\"0\",\"4\"],[\"64517.3\",\"20.06\",\"0\",\"1\"],[\"64518.1\",\"4.88\",\"0\",\"6\"],[\"64518.7\",\"86.1\",\"0\",\"1\"],[\"64519.1\",\"43.07\",\"0\",\"2\"],[\"64520.1\",\"0.03\",\"0\",\"3\"],[\"64521\",\"121.98\",\"0\",\"8\"],[\"64526.8\",\"0\",\"0\",\"0\"],[\"64526.9\",\"0\",\"0\",\"0\"],[\"64527\",\"0\",\"0\",\"0\"],[\"64527.1\",\"0\",\"0\",\"0\"]],\"bids\":[[\"64482.9\",\"963.95\",\"0\",\"65\"],[\"64482.8\",\"63.18\",\"0\",\"10\"],[\"64482.2\",\"0.01\",\"0\",\"1\"],[\"64482\",\"5.01\",\"0\",\"2\"],[\"64481.5\",\"0.01\",\"0\",\"1\"],[\"64481\",\"0\",\"0\",\"0\"],[\"64480.9\",\"0\",\"0\",\"0\"],[\"64480.6\",\"0.01\",\"0\",\"1\"],[\"64480.5\",\"4.02\",\"0\",\"2\"],[\"64480.1\",\"0.32\",\"0\",\"2\"],[\"64480\",\"215.55\",\"0\",\"9\"],[\"64479.8\",\"73.94\",\"0\",\"3\"],[\"64478.5\",\"0.01\",\"0\",\"1\"],[\"64478.4\",\"1.58\",\"0\",\"2\"],[\"64477.9\",\"77.54\",\"0\",\"1\"],[\"64476.3\",\"1.55\",\"0\",\"3\"],[\"64475.3\",\"12.65\",\"0\",\"3\"],[\"64474.1\",\"6.23\",\"0\",\"2\"],[\"64470.6\",\"0\",\"0\",\"0\"],[\"64470.5\",\"31.06\",\"0\",\"2\"],[\"64470.2\",\"1.9\",\"0\",\"1\"],[\"64470.1\",\"536.1\",\"0\",\"2\"],[\"64469.6\",\"1.69\",\"0\",\"2\"],[\"64469.4\",\"46.54\",\"0\",\"1\"],[\"64469.3\",\"498.45\",\"0\",\"2\"],[\"64469.2\",\"154.79\",\"0\",\"4\"],[\"64468.8\",\"97.5\",\"0\",\"2\"],[\"64468.6\",\"0\",\"0\",\"0\"],[\"64468\",\"0.04\",\"0\",\"3\"],[\"64467.7\",\"0\",\"0\",\"0\"],[\"64467.2\",\"0.77\",\"0\",\"1\"],[\"64466.9\",\"20.08\",\"0\",\"1\"],[\"64466.6\",\"0.01\",\"0\",\"1\"],[\"64466.5\",\"15.98\",\"0\",\"1\"],[\"64466.1\",\"85.77\",\"0\",\"2\"],[\"64465.5\",\"0.02\",\"0\",\"1\"],[\"64464.7\",\"0\",\"0\",\"0\"],[\"64464.4\",\"0.01\",\"0\",\"1\"],[\"64464.3\",\"0\",\"0\",\"0\"],[\"64463.4\",\"232.91\",\"0\",\"1\"],[\"64463.2\",\"58.22\",\"0\",\"1\"],[\"64460.1\",\"3.91\",\"0\",\"2\"],[\"64457.1\",\"415.22\",\"0\",\"3\"],[\"64457\",\"574.34\",\"0\",\"6\"],[\"64453.7\",\"0\",\"0\",\"0\"],[\"64422.4\",\"1366.68\",\"0\",\"4\"]],\"ts\":\"1782016033505\",\"checksum\":1612788660,\"seqId\":325070079080,\"prevSeqId\":325070078913}]}"}
{"action": "update", "capture_sequence": 209, "channel": "books", "connection_sequence": 2, "event": null, "instId": "BTC-USDT-SWAP", "local_receive_ts": "2026-06-21T04:27:13Z", "monotonic_ns": 1643589532113428, "raw": "{\"arg\":{\"channel\":\"books\",\"instId\":\"BTC-USDT-SWAP\"},\"action\":\"update\",\"data\":[{\"asks\":[[\"64483\",\"469.55\",\"0\",\"28\"],[\"64483.1\",\"0.62\",\"0\",\"3\"],[\"64483.5\",\"0\",\"0\",\"0\"],[\"64483.6\",\"0\",\"0\",\"0\"],[\"64484.7\",\"0.01\",\"0\",\"1\"],[\"64488.6\",\"1.58\",\"0\",\"3\"],[\"64488.7\",\"7.44\",\"0\",\"3\"],[\"64489.2\",\"62.36\",\"0\",\"2\"],[\"64492.6\",\"60.76\",\"0\",\"2\"],[\"64493.4\",\"0.32\",\"0\",\"5\"],[\"64493.6\",\"0.03\",\"0\",\"2\"],[\"64497.7\",\"0.17\",\"0\",\"1\"],[\"64498\",\"24.62\",\"0\",\"4\"],[\"64498.7\",\"1.86\",\"0\",\"3\"],[\"64499.8\",\"16.59\",\"0\",\"3\"],[\"64499.9\",\"1114.67\",\"0\",\"2\"],[\"64502.3\",\"11.26\",\"0\",\"4\"],[\"64502.4\",\"0.5\",\"0\",\"7\"],[\"64502.5\",\"101.13\",\"0\",\"5\"]],\"bids\":[[\"64482.9\",\"962.44\",\"0\",\"63\"],[\"64480.5\",\"2.46\",\"0\",\"1\"],[\"64480.1\",\"0.01\",\"0\",\"1\"],[\"64480\",\"213.99\",\"0\",\"8\"],[\"64479.9\",\"12.78\",\"0\",\"4\"],[\"64478.4\",\"1.56\",\"0\",\"1\"],[\"64477.6\",\"0.03\",\"0\",\"2\"],[\"64476.3\",\"31.05\",\"0\",\"2\"],[\"64476\",\"1.6\",\"0\",\"3\"],[\"64475.6\",\"1.56\",\"0\",\"1\"],[\"64470.5\",\"0.01\",\"0\",\"1\"],[\"64470.4\",\"5.54\",\"0\",\"3\"],[\"64470.1\",\"535.79\",\"0\",\"1\"],[\"64469.8\",\"84.65\",\"0\",\"3\"],[\"64468\",\"0.02\",\"0\",\"2\"],[\"64467.2\",\"0.79\",\"0\",\"2\"],[\"64465.5\",\"0\",\"0\",\"0\"],[\"64465.3\",\"46.58\",\"0\",\"4\"],[\"64464.9\",\"31.06\",\"0\",\"1\"],[\"64464.5\",\"0.02\",\"0\",\"2\"],[\"64464.3\",\"31.05\",\"0\",\"1\"],[\"64464.2\",\"155.59\",\"0\",\"6\"],[\"64460.1\",\"7.04\",\"0\",\"3\"],[\"64453.7\",\"0.19\",\"0\",\"1\"],[\"64422.5\",\"0\",\"0\",\"0\"],[\"64422.4\",\"0\",\"0\",\"0\"]],\"ts\":\"1782016033605\",\"checksum\":2074170772,\"seqId\":325070079209,\"prevSeqId\":325070079080}]}"}
{"action": "update", "capture_sequence": 210, "channel": "books", "connection_sequence": 2, "event": null, "instId": "BTC-USDT-SWAP", "local_receive_ts": "2026-06-21T04:27:13Z", "monotonic_ns": 1643589624472935, "raw": "{\"arg\":{\"channel\":\"books\",\"instId\":\"BTC-USDT-SWAP\"},\"action\":\"update\",\"data\":[{\"asks\":[[\"64492.7\",\"99.89\",\"0\",\"4\"],[\"64493.6\",\"0.02\",\"0\",\"1\"],[\"64496.3\",\"506.55\",\"0\",\"8\"],[\"64497.7\",\"0\",\"0\",\"0\"],[\"64502.8\",\"57.08\",\"0\",\"4\"],[\"64503\",\"15.95\",\"0\",\"3\"],[\"64511.9\",\"1.34\",\"0\",\"2\"],[\"64512.6\",\"117.62\",\"0\",\"8\"],[\"64520\",\"78.63\",\"0\",\"64\"],[\"64520.1\",\"0.02\",\"0\",\"2\"],[\"64526.8\",\"0.37\",\"0\",\"2\"]],\"bids\":[[\"64482.9\",\"962.32\",\"0\",\"62\"],[\"64479.3\",\"0.01\",\"0\",\"1\"],[\"64478.8\",\"0\",\"0\",\"0\"],[\"64478.4\",\"0\",\"0\",\"0\"],[\"64477.8\",\"0\",\"0\",\"0\"],[\"64477.6\",\"0.01\",\"0\",\"1\"],[\"64476.4\",\"0.02\",\"0\",\"1\"],[\"64464.7\",\"1\",\"0\",\"1\"],[\"64463.9\",\"58.22\",\"0\",\"1\"],[\"64463.2\",\"0\",\"0\",\"0\"],[\"64422.5\",\"395.33\",\"0\",\"1\"]],\"ts\":\"1782016033705\",\"checksum\":1518541753,\"seqId\":325070079306,\"prevSeqId\":325070079209}]}"}
{"action": null, "capture_sequence": 211, "channel": "trades", "connection_sequence": 2, "event": null, "instId": "BTC-USDT-SWAP", "local_receive_ts": "2026-06-21T04:27:13Z", "monotonic_ns": 1643589645153198, "raw": "{\"arg\":{\"channel\":\"trades\",\"instId\":\"BTC-USDT-SWAP\"},\"data\":[{\"instId\":\"BTC-USDT-SWAP\",\"tradeId\":\"2718750256\",\"px\":\"64482.9\",\"sz\":\"0.06\",\"side\":\"sell\",\"ts\":\"1782016033726\",\"count\":\"1\",\"source\":\"0\",\"seqId\":325070079322}]}"}
{"action": "update", "capture_sequence": 212, "channel": "books", "connection_sequence": 2, "event": null, "instId": "BTC-USDT-SWAP", "local_receive_ts": "2026-06-21T04:27:13Z", "monotonic_ns": 1643589724806292, "raw": "{\"arg\":{\"channel\":\"books\",\"instId\":\"BTC-USDT-SWAP\"},\"action\":\"update\",\"data\":[{\"asks\":[[\"64483\",\"479.55\",\"0\",\"29\"]],\"bids\":[[\"64482.9\",\"962.26\",\"0\",\"62\"],[\"64482.2\",\"0\",\"0\",\"0\"],[\"64479.9\",\"12.79\",\"0\",\"5\"],[\"64422.4\",\"1366.68\",\"0\",\"4\"]],\"ts\":\"1782016033805\",\"checksum\":853772913,\"seqId\":325070079398,\"prevSeqId\":325070079306}]}"}
{"action": "update", "capture_sequence": 213, "channel": "books", "connection_sequence": 2, "event": null, "instId": "BTC-USDT-SWAP", "local_receive_ts": "2026-06-21T04:27:14Z", "monotonic_ns": 1643589824491488, "raw": "{\"arg\":{\"channel\":\"books\",\"instId\":\"BTC-USDT-SWAP\"},\"action\":\"update\",\"data\":[{\"asks\":[[\"64483\",\"440.7\",\"0\",\"28\"],[\"64489.6\",\"12.57\",\"0\",\"5\"],[\"64496.2\",\"4.1\",\"0\",\"2\"],[\"64496.3\",\"506.38\",\"0\",\"7\"],[\"64511.8\",\"6.2\",\"0\",\"1\"],[\"64512.5\",\"85.49\",\"0\",\"6\"],[\"64517.3\",\"0\",\"0\",\"0\"],[\"64518.3\",\"20.08\",\"0\",\"3\"],[\"64518.7\",\"0\",\"0\",\"0\"],[\"64519.7\",\"96.91\",\"0\",\"8\"],[\"64526.9\",\"40.21\",\"0\",\"5\"],[\"64527\",\"0.17\",\"0\",\"3\"]],\"bids\":[[\"64470\",\"323.85\",\"0\",\"6\"],[\"64468.8\",\"11.33\",\"0\",\"1\"],[\"64467.7\",\"20.08\",\"0\",\"1\"],[\"64467\",\"469.19\",\"0\",\"4\"],[\"64466.9\",\"0\",\"0\",\"0\"],[\"64466.1\",\"0.38\",\"0\",\"1\"]],\"ts\":\"1782016033905\",\"checksum\":392396450,\"seqId\":325070079483,\"prevSeqId\":325070079398}]}"}
{"action": "update", "capture_sequence": 214, "channel": "books", "connection_sequence": 2, "event": null, "instId": "BTC-USDT-SWAP", "local_receive_ts": "2026-06-21T04:27:14Z", "monotonic_ns": 1643589932863743, "raw": "{\"arg\":{\"channel\":\"books\",\"instId\":\"BTC-USDT-SWAP\"},\"action\":\"update\",\"data\":[{\"asks\":[[\"64483\",\"366.66\",\"0\",\"27\"],[\"64484\",\"0.55\",\"0\",\"3\"],[\"64484.1\",\"0.02\",\"0\",\"1\"],[\"64484.7\",\"0\",\"0\",\"0\"],[\"64484.8\",\"1.57\",\"0\",\"2\"],[\"64484.9\",\"11.64\",\"0\",\"3\"],[\"64486\",\"52.65\",\"0\",\"7\"],[\"64486.6\",\"66.37\",\"0\",\"3\"],[\"64486.9\",\"1.67\",\"0\",\"2\"],[\"64487.3\",\"0.04\",\"0\",\"2\"],[\"64487.6\",\"0\",\"0\",\"0\"],[\"64487.9\",\"0.51\",\"0\",\"2\"],[\"64488.3\",\"0.02\",\"0\",\"2\"],[\"64488.7\",\"6.24\",\"0\",\"2\"],[\"64489\",\"19.1\",\"0\",\"8\"],[\"64489.2\",\"60.86\",\"0\",\"1\"],[\"64489.6\",\"1.39\",\"0\",\"4\"],[\"64492.7\",\"99.88\",\"0\",\"3\"],[\"64492.8\",\"0.45\",\"0\",\"10\"],[\"64500\",\"3456.35\",\"0\",\"1038\"],[\"64502.5\",\"70.1\",\"0\",\"4\"],[\"64502.7\",\"31.06\",\"0\",\"4\"],[\"64502.8\",\"57.07\",\"0\",\"3\"],[\"64503\",\"15.96\",\"0\",\"4\"],[\"64503.4\",\"232.77\",\"0\",\"1\"],[\"64504.9\",\"0.1\",\"0\",\"3\"],[\"64505.1\",\"1.57\",\"0\",\"3\"],[\"64506\",\"10.07\",\"0\",\"5\"],[\"64506.5\",\"16.49\",\"0\",\"3\"],[\"64507.4\",\"27.27\",\"0\",\"1\"],[\"64507.7\",\"33.86\",\"0\",\"5\"],[\"64509.6\",\"15.68\",\"0\",\"3\"],[\"64510.2\",\"15.65\",\"0\",\"1\"],[\"64510.5\",\"59.3\",\"0\",\"4\"],[\"64510.9\",\"0.07\",\"0\",\"4\"],[\"64511.2\",\"0.02\",\"0\",\"2\"],[\"64511.5\",\"0.3\",\"0\",\"6\"],[\"64511.9\",\"0.14\",\"0\",\"1\"],[\"64512.3\",\"65.54\",\"0\",\"6\"],[\"64512.6\",\"58.24\",\"0\",\"6\"],[\"64512.8\",\"0\",\"0\",\"0\"],[\"64513.2\",\"58.33\",\"0\",\"5\"],[\"64527.1\",\"0.46\",\"0\",\"1\"],[\"64527.2\",\"0.18\",\"0\",\"4\"]],\"bids\":[[\"64482.9\",\"1034.72\",\"0\",\"63\"],[\"64482.3\",\"1.56\",\"0\",\"1\"],[\"64481.8\",\"1.56\",\"0\",\"1\"],[\"64481.3\",\"1.56\",\"0\",\"1\"],[\"64480.9\",\"1.56\",\"0\",\"1\"],[\"64480.2\",\"0.31\",\"0\",\"1\"],[\"64479.9\",\"12.48\",\"0\",\"4\"],[\"64478.3\",\"77.55\",\"0\",\"2\"],[\"64478.2\",\"13.97\",\"0\",\"2\"],[\"64477.9\",\"0\",\"0\",\"0\"],[\"64476.4\",\"0\",\"0\",\"0\"],[\"64470.9\",\"0.01\",\"0\",\"1\"],[\"64470.2\",\"86.16\",\"0\",\"1\"],[\"64470\",\"237.69\",\"0\",\"5\"],[\"64469.9\",\"169.58\",\"0\",\"4\"],[\"64469.6\",\"0.01\",\"0\",\"1\"],[\"64469.3\",\"496.53\",\"0\",\"1\"],[\"64468.9\",\"34.11\",\"0\",\"2\"],[\"64468.7\",\"84.49\",\"0\",\"6\"],[\"64468.5\",\"0\",\"0\",\"0\"],[\"64468.3\",\"0\",\"0\",\"0\"],[\"64468.1\",\"15.94\",\"0\",\"1\"],[\"64467.7\",\"20.85\",\"0\",\"2\"],[\"64467.6\",\"0.03\",\"0\",\"3\"],[\"64467.3\",\"103.05\",\"0\",\"3\"],[\"64467.2\",\"0\",\"0\",\"0\"],[\"64467.1\",\"116.61\",\"0\",\"3\"],[\"64467\",\"383.8\",\"0\",\"3\"],[\"64464.8\",\"31.08\",\"0\",\"3\"],[\"64464.4\",\"58.23\",\"0\",\"2\"],[\"64464.3\",\"232.91\",\"0\",\"1\"],[\"64464.2\",\"155.57\",\"0\",\"5\"],[\"64463.9\",\"0\",\"0\",\"0\"],[\"64463.4\",\"0\",\"0\",\"0\"],[\"64423.7\",\"0\",\"0\",\"0\"],[\"64423.5\",\"19.6\",\"0\",\"1\"],[\"64423\",\"1.59\",\"0\",\"6\"],[\"64422.7\",\"22.42\",\"0\",\"4\"],[\"64422.6\",\"18.89\",\"0\",\"3\"],[\"64422.4\",\"1365.48\",\"0\",\"3\"],[\"64422.3\",\"0.14\",\"0\",\"14\"],[\"64422.2\",\"11.2\",\"0\",\"3\"]],\"ts\":\"1782016034005\",\"checksum\":-1851355178,\"seqId\":325070079653,\"prevSeqId\":325070079483}]}"}
{"action": null, "capture_sequence": 215, "channel": "trades", "connection_sequence": 2, "event": null, "instId": "BTC-USDT-SWAP", "local_receive_ts": "2026-06-21T04:27:14Z", "monotonic_ns": 1643589987941952, "raw": "{\"arg\":{\"channel\":\"trades\",\"instId\":\"BTC-USDT-SWAP\"},\"data\":[{\"instId\":\"BTC-USDT-SWAP\",\"tradeId\":\"2718750257\",\"px\":\"64482.9\",\"sz\":\"0.1\",\"side\":\"sell\",\"ts\":\"1782016034068\",\"count\":\"1\",\"source\":\"0\",\"seqId\":325070079864}]}"}
{"action": "update", "capture_sequence": 216, "channel": "books", "connection_sequence": 2, "event": null, "instId": "BTC-USDT-SWAP", "local_receive_ts": "2026-06-21T04:27:14Z", "monotonic_ns": 1643590032866736, "raw": "{\"arg\":{\"channel\":\"books\",\"instId\":\"BTC-USDT-SWAP\"},\"action\":\"update\",\"data\":[{\"asks\":[[\"64483\",\"435.1\",\"0\",\"28\"],[\"64483.4\",\"0.01\",\"0\",\"1\"],[\"64483.9\",\"0.02\",\"0\",\"2\"],[\"64484.4\",\"70.75\",\"0\",\"3\"],[\"64484.8\",\"0\",\"0\",\"0\"],[\"64484.9\",\"11.63\",\"0\",\"2\"],[\"64486.2\",\"2.57\",\"0\",\"9\"],[\"64487.2\",\"1.03\",\"0\",\"3\"],[\"64488.2\",\"5.16\",\"0\",\"3\"],[\"64489\",\"20.3\",\"0\",\"9\"],[\"64489.1\",\"1.6\",\"0\",\"4\"],[\"64489.3\",\"24.45\",\"0\",\"6\"],[\"64489.5\",\"1.52\",\"0\",\"3\"],[\"64496.2\",\"3.93\",\"0\",\"1\"],[\"64497.2\",\"3.12\",\"0\",\"4\"],[\"64497.7\",\"0.17\",\"0\",\"1\"],[\"64499.6\",\"81.1\",\"0\",\"5\"],[\"64499.8\",\"1.08\",\"0\",\"2\"],[\"64500.8\",\"0.36\",\"0\",\"1\"],[\"64502.3\",\"42.29\",\"0\",\"5\"],[\"64502.7\",\"0.03\",\"0\",\"3\"],[\"64502.8\",\"289.84\",\"0\",\"4\"],[\"64502.9\",\"280.73\",\"0\",\"8\"],[\"64503\",\"15.95\",\"0\",\"3\"],[\"64503.4\",\"0\",\"0\",\"0\"],[\"64504.7\",\"1.56\",\"0\",\"2\"],[\"64505.1\",\"0.02\",\"0\",\"2\"],[\"64506.3\",\"53.63\",\"0\",\"4\"],[\"64506.5\",\"15.72\",\"0\",\"2\"],[\"64507.6\",\"33.82\",\"0\",\"3\"],[\"64507.7\",\"0.07\",\"0\",\"4\"],[\"64509.8\",\"1.01\",\"0\",\"2\"],[\"64510.8\",\"1.02\",\"0\",\"2\"],[\"64511.8\",\"7.4\",\"0\",\"2\"],[\"64512.1\",\"85.37\",\"0\",\"4\"],[\"64512.5\",\"0.16\",\"0\",\"5\"],[\"64512.6\",\"117.62\",\"0\",\"8\"],[\"64512.9\",\"18.99\",\"0\",\"5\"],[\"64513.1\",\"3.06\",\"0\",\"3\"],[\"64513.2\",\"0.15\",\"0\",\"4\"],[\"64513.3\",\"1.12\",\"0\",\"8\"],[\"64518.1\",\"24.94\",\"0\",\"7\"],[\"64518.3\",\"0.02\",\"0\",\"2\"],[\"64519.1\",\"129.17\",\"0\",\"3\"],[\"64519.7\",\"10.81\",\"0\",\"7\"]],\"bids\":[[\"64482.9\",\"962.16\",\"0\",\"62\"],[\"64482.3\",\"0\",\"0\",\"0\"],[\"64481.8\",\"0\",\"0\",\"0\"],[\"64481.7\",\"1.56\",\"0\",\"1\"],[\"64481.3\",\"0\",\"0\",\"0\"],[\"64481.1\",\"1.56\",\"0\",\"1\"],[\"64480.9\",\"0\",\"0\",\"0\"],[\"64480.2\",\"1.56\",\"0\",\"1\"],[\"64479.9\",\"2.79\",\"0\",\"4\"],[\"64479.4\",\"1.56\",\"0\",\"1\"],[\"64478.9\",\"1.56\",\"0\",\"1\"],[\"64478.5\",\"1.57\",\"0\",\"2\"],[\"64478.3\",\"0.01\",\"0\",\"1\"],[\"64478.2\",\"13.95\",\"0\",\"1\"],[\"64478\",\"1.57\",\"0\",\"2\"],[\"64477.8\",\"77.54\",\"0\",\"1\"],[\"64476.4\",\"0.02\",\"0\",\"1\"],[\"64476.3\",\"1.55\",\"0\",\"3\"],[\"64476\",\"0.04\",\"0\",\"2\"],[\"64475.6\",\"0\",\"0\",\"0\"],[\"64475.5\",\"0\",\"0\",\"0\"],[\"64472.7\",\"6.2\",\"0\",\"4\"],[\"64471.3\",\"1.98\",\"0\",\"2\"],[\"64470.4\",\"35.05\",\"0\",\"2\"],[\"64470.3\",\"162.52\",\"0\",\"5\"],[\"64470.2\",\"0\",\"0\",\"0\"],[\"64470\",\"323.86\",\"0\",\"6\"],[\"64469.3\",\"498.69\",\"0\",\"2\"],[\"64468.9\",\"3.3\",\"0\",\"2\"],[\"64468.6\",\"33.81\",\"0\",\"1\"],[\"64468.5\",\"2.88\",\"0\",\"1\"],[\"64468\",\"2.72\",\"0\",\"3\"],[\"64467.7\",\"20.08\",\"0\",\"1\"],[\"64467.5\",\"0.8\",\"0\",\"3\"],[\"64467.1\",\"31.22\",\"0\",\"2\"],[\"64466.6\",\"85.4\",\"0\",\"2\"],[\"64464.8\",\"0.01\",\"0\",\"1\"],[\"64464.4\",\"0.01\",\"0\",\"1\"],[\"64464.3\",\"31.07\",\"0\",\"2\"],[\"64464\",\"58.28\",\"0\",\"5\"],[\"64463.9\",\"232.91\",\"0\",\"1\"],[\"64424.1\",\"1\",\"0\",\"1\"],[\"64423.1\",\"93.81\",\"0\",\"3\"],[\"64422.4\",\"0\",\"0\",\"0\"],[\"64422.3\",\"0\",\"0\",\"0\"],[\"64422.2\",\"0\",\"0\",\"0\"]],\"ts\":\"1782016034105\",\"checksum\":616703906,\"seqId\":325070079979,\"prevSeqId\":325070079653}]}"}
{"action": "update", "capture_sequence": 217, "channel": "books", "connection_sequence": 2, "event": null, "instId": "BTC-USDT-SWAP", "local_receive_ts": "2026-06-21T04:27:14Z", "monotonic_ns": 1643590125114524, "raw": "{\"arg\":{\"channel\":\"books\",\"instId\":\"BTC-USDT-SWAP\"},\"action\":\"update\",\"data\":[{\"asks\":[[\"64483\",\"446.64\",\"0\",\"29\"],[\"64483.4\",\"0\",\"0\",\"0\"],[\"64483.7\",\"0.02\",\"0\",\"2\"],[\"64483.8\",\"1.56\",\"0\",\"1\"],[\"64483.9\",\"0.01\",\"0\",\"1\"],[\"64484.4\",\"69.19\",\"0\",\"2\"],[\"64484.8\",\"0.01\",\"0\",\"1\"],[\"64486.2\",\"3.57\",\"0\",\"10\"],[\"64486.9\",\"2.67\",\"0\",\"3\"],[\"64487.5\",\"1.24\",\"0\",\"4\"],[\"64499.3\",\"15.51\",\"0\",\"1\"],[\"64499.6\",\"65.59\",\"0\",\"4\"],[\"64502.7\",\"232.8\",\"0\",\"4\"],[\"64502.8\",\"57.07\",\"0\",\"3\"],[\"64510.5\",\"60.3\",\"0\",\"5\"],[\"64511.1\",\"19.99\",\"0\",\"7\"],[\"64513.3\",\"1.97\",\"0\",\"9\"],[\"64518.1\",\"4.88\",\"0\",\"6\"],[\"64518.3\",\"20.08\",\"0\",\"3\"],[\"64527.1\",\"0\",\"0\",\"0\"],[\"64527.2\",\"0\",\"0\",\"0\"]],\"bids\":[[\"64481.7\",\"0\",\"0\",\"0\"],[\"64481.1\",\"0\",\"0\",\"0\"],[\"64480.2\",\"0\",\"0\",\"0\"],[\"64479.4\",\"0\",\"0\",\"0\"],[\"64477.5\",\"1.86\",\"0\",\"2\"],[\"64476\",\"1.6\",\"0\",\"3\"],[\"64475.6\",\"1.56\",\"0\",\"1\"],[\"64470.6\",\"1.9\",\"0\",\"1\"],[\"64470\",\"325.54\",\"0\",\"7\"],[\"64463.9\",\"0\",\"0\",\"0\"],[\"64463.4\",\"232.91\",\"0\",\"1\"],[\"64441.2\",\"0\",\"0\",\"0\"],[\"64423.4\",\"1\",\"0\",\"1\"],[\"64422.8\",\"3.49\",\"0\",\"3\"],[\"64422.4\",\"1365.48\",\"0\",\"3\"],[\"64422.3\",\"0.14\",\"0\",\"14\"]],\"ts\":\"1782016034205\",\"checksum\":1365927541,\"seqId\":325070080181,\"prevSeqId\":325070079979}]}"}
{"action": null, "capture_sequence": 218, "channel": "trades", "connection_sequence": 2, "event": null, "instId": "BTC-USDT-SWAP", "local_receive_ts": "2026-06-21T04:27:14Z", "monotonic_ns": 1643590134919632, "raw": "{\"arg\":{\"channel\":\"trades\",\"instId\":\"BTC-USDT-SWAP\"},\"data\":[{\"instId\":\"BTC-USDT-SWAP\",\"tradeId\":\"2718750258\",\"px\":\"64483\",\"sz\":\"3.77\",\"side\":\"buy\",\"ts\":\"1782016034215\",\"count\":\"1\",\"source\":\"0\",\"seqId\":325070080209}]}"}
{"action": null, "capture_sequence": 219, "channel": "trades", "connection_sequence": 2, "event": null, "instId": "BTC-USDT-SWAP", "local_receive_ts": "2026-06-21T04:27:14Z", "monotonic_ns": 1643590155733362, "raw": "{\"arg\":{\"channel\":\"trades\",\"instId\":\"BTC-USDT-SWAP\"},\"data\":[{\"instId\":\"BTC-USDT-SWAP\",\"tradeId\":\"2718750259\",\"px\":\"64483\",\"sz\":\"6.52\",\"side\":\"buy\",\"ts\":\"1782016034236\",\"count\":\"1\",\"source\":\"0\",\"seqId\":325070080249}]}"}
{"action": "update", "capture_sequence": 220, "channel": "books", "connection_sequence": 2, "event": null, "instId": "BTC-USDT-SWAP", "local_receive_ts": "2026-06-21T04:27:14Z", "monotonic_ns": 1643590241599067, "raw": "{\"arg\":{\"channel\":\"books\",\"instId\":\"BTC-USDT-SWAP\"},\"action\":\"update\",\"data\":[{\"asks\":[[\"64483\",\"227.7\",\"0\",\"25\"],[\"64483.7\",\"0.01\",\"0\",\"1\"],[\"64483.8\",\"0\",\"0\",\"0\"],[\"64484.1\",\"0\",\"0\",\"0\"],[\"64484.3\",\"0\",\"0\",\"0\"],[\"64484.4\",\"0\",\"0\",\"0\"],[\"64484.8\",\"0.02\",\"0\",\"2\"],[\"64484.9\",\"42.72\",\"0\",\"4\"],[\"64485.3\",\"0\",\"0\",\"0\"],[\"64485.7\",\"0.34\",\"0\",\"4\"],[\"64485.8\",\"0.43\",\"0\",\"5\"],[\"64486\",\"51.08\",\"0\",\"5\"],[\"64486.2\",\"3.56\",\"0\",\"9\"],[\"64486.5\",\"0.01\",\"0\",\"1\"],[\"64486.6\",\"98.53\",\"0\",\"4\"],[\"64486.9\",\"1.11\",\"0\",\"2\"],[\"64487.4\",\"0.5\",\"0\",\"6\"],[\"64487.8\",\"1.3\",\"0\",\"5\"],[\"64488.1\",\"0.66\",\"0\",\"1\"],[\"64488.6\",\"1.22\",\"0\",\"3\"],[\"64489.1\",\"0.04\",\"0\",\"3\"],[\"64489.2\",\"0\",\"0\",\"0\"],[\"64489.3\",\"160.57\",\"0\",\"6\"],[\"64489.8\",\"67\",\"0\",\"4\"],[\"64490\",\"55.77\",\"0\",\"19\"],[\"64490.1\",\"3\",\"0\",\"3\"],[\"64490.9\",\"0.07\",\"0\",\"2\"],[\"64491.7\",\"0.02\",\"0\",\"2\"],[\"64492.2\",\"38.14\",\"0\",\"8\"],[\"64492.3\",\"18.63\",\"0\",\"4\"],[\"64492.4\",\"0.08\",\"0\",\"6\"],[\"64492.5\",\"0.05\",\"0\",\"3\"],[\"64492.7\",\"0.3\",\"0\",\"2\"],[\"64492.8\",\"0.44\",\"0\",\"9\"],[\"64493\",\"17.18\",\"0\",\"4\"],[\"64493.3\",\"0.03\",\"0\",\"3\"],[\"64493.4\",\"16.32\",\"0\",\"7\"],[\"64494.1\",\"0.01\",\"0\",\"1\"],[\"64494.6\",\"20.97\",\"0\",\"6\"],[\"64495.2\",\"6.12\",\"0\",\"4\"],[\"64495.5\",\"0.26\",\"0\",\"6\"],[\"64495.9\",\"47.38\",\"0\",\"4\"],[\"64496.2\",\"19.89\",\"0\",\"2\"],[\"64496.3\",\"459.84\",\"0\",\"6\"],[\"64496.4\",\"0.02\",\"0\",\"2\"],[\"64496.7\",\"0.18\",\"0\",\"2\"],[\"64497.2\",\"1.22\",\"0\",\"4\"],[\"64497.7\",\"0\",\"0\",\"0\"],[\"64498.1\",\"8.03\",\"0\",\"4\"],[\"64498.2\",\"0.42\",\"0\",\"4\"],[\"64498.8\",\"543.09\",\"0\",\"4\"],[\"64498.9\",\"3.42\",\"0\",\"2\"],[\"64499.2\",\"12.01\",\"0\",\"3\"],[\"64499.3\",\"0\",\"0\",\"0\"],[\"64499.5\",\"6.22\",\"0\",\"1\"],[\"64499.6\",\"74.88\",\"0\",\"4\"],[\"64499.7\",\"19.72\",\"0\",\"4\"],[\"64500.5\",\"4.78\",\"0\",\"3\"],[\"64502.2\",\"114.94\",\"0\",\"7\"],[\"64502.3\",\"11.26\",\"0\",\"4\"],[\"64502.4\",\"0.19\",\"0\",\"6\"],[\"64502.7\",\"0.03\",\"0\",\"3\"],[\"64502.8\",\"289.84\",\"0\",\"4\"],[\"64502.9\",\"280.72\",\"0\",\"7\"],[\"64503.6\",\"0.03\",\"0\",\"3\"],[\"64503.8\",\"0.31\",\"0\",\"1\"],[\"64504.7\",\"0.01\",\"0\",\"1\"],[\"64505.3\",\"1.16\",\"0\",\"2\"],[\"64505.6\",\"59.46\",\"0\",\"5\"],[\"64506.3\",\"15.66\",\"0\",\"2\"],[\"64507.5\",\"0.9\",\"0\",\"7\"],[\"64507.6\",\"0.03\",\"0\",\"2\"],[\"64508.6\",\"33.8\",\"0\",\"2\"],[\"64511.5\",\"1.5\",\"0\",\"7\"],[\"64512.1\",\"37.24\",\"0\",\"4\"],[\"64512.2\",\"12.43\",\"0\",\"4\"],[\"64512.6\",\"59.44\",\"0\",\"7\"],[\"64513.9\",\"85.45\",\"0\",\"2\"],[\"64515.4\",\"58.64\",\"0\",\"6\"],[\"64516\",\"500.55\",\"0\",\"7\"],[\"64517.2\",\"0.77\",\"0\",\"6\"],[\"64518.3\",\"0.02\",\"0\",\"2\"],[\"64519.1\",\"43.07\",\"0\",\"2\"],[\"64519.8\",\"109.43\",\"0\",\"6\"],[\"64520\",\"78.62\",\"0\",\"63\"],[\"64520.9\",\"86.12\",\"0\",\"3\"],[\"64523\",\"0.01\",\"0\",\"1\"],[\"64526\",\"1.16\",\"0\",\"4\"],[\"64527.1\",\"0.46\",\"0\",\"1\"],[\"64527.2\",\"0.18\",\"0\",\"4\"],[\"64527.3\",\"0.05\",\"0\",\"5\"],[\"64527.4\",\"0.27\",\"0\",\"2\"]],\"bids\":[[\"64482.9\",\"1033.53\",\"0\",\"63\"],[\"64480.9\",\"0.31\",\"0\",\"1\"],[\"64480.1\",\"1.57\",\"0\",\"2\"],[\"64479.9\",\"2.48\",\"0\",\"3\"],[\"64479.5\",\"8.75\",\"0\",\"2\"],[\"64478.9\",\"1.58\",\"0\",\"2\"],[\"64478.6\",\"77.54\",\"0\",\"1\"],[\"64477.8\",\"0\",\"0\",\"0\"],[\"64476.4\",\"1.54\",\"0\",\"2\"],[\"64476.3\",\"31.05\",\"0\",\"2\"],[\"64476.1\",\"2.29\",\"0\",\"1\"],[\"64475.6\",\"0\",\"0\",\"0\"],[\"64475.3\",\"0.24\",\"0\",\"2\"],[\"64474.5\",\"15.9\",\"0\",\"1\"],[\"64473.5\",\"63.31\",\"0\",\"2\"],[\"64472.9\",\"15.94\",\"0\",\"1\"],[\"64472.7\",\"3.92\",\"0\",\"3\"],[\"64472.5\",\"73\",\"0\",\"2\"],[\"64471.3\",\"17.96\",\"0\",\"3\"],[\"64470.7\",\"0.33\",\"0\",\"3\"],[\"64470.4\",\"90.16\",\"0\",\"2\"],[\"64470\",\"239.37\",\"0\",\"6\"],[\"64469.8\",\"84.34\",\"0\",\"2\"],[\"64469.7\",\"9.68\",\"0\",\"3\"],[\"64469.5\",\"33.82\",\"0\",\"2\"],[\"64469.4\",\"66.62\",\"0\",\"2\"],[\"64469.1\",\"2.77\",\"0\",\"2\"],[\"64468.6\",\"0.77\",\"0\",\"1\"],[\"64468.3\",\"85.39\",\"0\",\"1\"],[\"64468.1\",\"0\",\"0\",\"0\"],[\"64467.7\",\"0\",\"0\",\"0\"],[\"64467.5\",\"0.03\",\"0\",\"2\"],[\"64467\",\"282.31\",\"0\",\"3\"],[\"64466.6\",\"0.01\",\"0\",\"1\"],[\"64466.5\",\"0\",\"0\",\"0\"],[\"64466.1\",\"58.6\",\"0\",\"2\"],[\"64465\",\"0\",\"0\",\"0\"],[\"64464.4\",\"31.06\",\"0\",\"2\"],[\"64464.3\",\"12.43\",\"0\",\"2\"],[\"64464\",\"0.06\",\"0\",\"4\"],[\"64463.9\",\"232.91\",\"0\",\"1\"],[\"64463.4\",\"0\",\"0\",\"0\"],[\"64462.6\",\"0.01\",\"0\",\"1\"],[\"64448\",\"493.83\",\"0\",\"8\"],[\"64446.2\",\"42.38\",\"0\",\"2\"],[\"64444.5\",\"156.71\",\"0\",\"3\"],[\"64444.4\",\"37.26\",\"0\",\"3\"],[\"64441.2\",\"0.38\",\"0\",\"1\"],[\"64434.7\",\"56.54\",\"0\",\"2\"],[\"64422.4\",\"1366.68\",\"0\",\"4\"],[\"64422.3\",\"0\",\"0\",\"0\"]],\"ts\":\"1782016034305\",\"checksum\":1270832847,\"seqId\":325070080609,\"prevSeqId\":325070080181}]}"}
{"action": "update", "capture_sequence": 221, "channel": "books", "connection_sequence": 2, "event": null, "instId": "BTC-USDT-SWAP", "local_receive_ts": "2026-06-21T04:27:14Z", "monotonic_ns": 1643590337307076, "raw": "{\"arg\":{\"channel\":\"books\",\"instId\":\"BTC-USDT-SWAP\"},\"action\":\"update\",\"data\":[{\"asks\":[[\"64483\",\"180.74\",\"0\",\"23\"],[\"64484.9\",\"11.64\",\"0\",\"3\"],[\"64486.2\",\"2.56\",\"0\",\"8\"],[\"64486.6\",\"8.74\",\"0\",\"2\"],[\"64486.9\",\"0.11\",\"0\",\"1\"],[\"64487.2\",\"0.03\",\"0\",\"2\"],[\"64487.5\",\"0.04\",\"0\",\"3\"],[\"64487.8\",\"0.1\",\"0\",\"4\"],[\"64487.9\",\"94.22\",\"0\",\"3\"],[\"64488.2\",\"3.96\",\"0\",\"2\"],[\"64488.6\",\"0.02\",\"0\",\"2\"],[\"64489\",\"19.1\",\"0\",\"8\"],[\"64489.3\",\"159.37\",\"0\",\"5\"],[\"64489.5\",\"0.02\",\"0\",\"2\"],[\"64493.1\",\"13.62\",\"0\",\"3\"],[\"64494.1\",\"0\",\"0\",\"0\"],[\"64494.2\",\"0.12\",\"0\",\"1\"],[\"64494.9\",\"12.07\",\"0\",\"5\"],[\"64495.4\",\"0.06\",\"0\",\"3\"],[\"64495.8\",\"34.99\",\"0\",\"4\"],[\"64496.1\",\"0.07\",\"0\",\"4\"],[\"64496.3\",\"475.84\",\"0\",\"7\"],[\"64499.6\",\"59.37\",\"0\",\"3\"],[\"64500\",\"3456.34\",\"0\",\"1037\"],[\"64500.1\",\"0.06\",\"0\",\"5\"],[\"64501.4\",\"15.52\",\"0\",\"2\"],[\"64502.2\",\"83.91\",\"0\",\"6\"],[\"64502.5\",\"0.2\",\"0\",\"3\"],[\"64502.8\",\"57.07\",\"0\",\"3\"],[\"64503.6\",\"0.02\",\"0\",\"2\"],[\"64503.8\",\"31.34\",\"0\",\"2\"],[\"64504.6\",\"2.51\",\"0\",\"2\"],[\"64505.1\",\"232.78\",\"0\",\"3\"],[\"64505.5\",\"73.81\",\"0\",\"3\"],[\"64505.6\",\"57.91\",\"0\",\"4\"],[\"64506.3\",\"17.21\",\"0\",\"3\"],[\"64506.4\",\"139.6\",\"0\",\"4\"],[\"64508.6\",\"0.01\",\"0\",\"1\"],[\"64508.7\",\"181.49\",\"0\",\"10\"],[\"64508.8\",\"0.04\",\"0\",\"2\"],[\"64513.2\",\"85.48\",\"0\",\"5\"],[\"64513.9\",\"0.12\",\"0\",\"1\"],[\"64519\",\"20.73\",\"0\",\"5\"],[\"64519.8\",\"89.37\",\"0\",\"5\"],[\"64521.3\",\"0.01\",\"0\",\"1\"],[\"64522.7\",\"403.98\",\"0\",\"2\"],[\"64523\",\"0\",\"0\",\"0\"],[\"64525.3\",\"0.02\",\"0\",\"2\"],[\"64527.5\",\"0.19\",\"0\",\"5\"],[\"64527.6\",\"16.48\",\"0\",\"5\"]],\"bids\":[[\"64482.9\",\"1047.84\",\"0\",\"65\"],[\"64482.8\",\"39.77\",\"0\",\"10\"],[\"64481.7\",\"0.31\",\"0\",\"1\"],[\"64480.9\",\"0\",\"0\",\"0\"],[\"64480\",\"183.74\",\"0\",\"8\"],[\"64479.8\",\"83.25\",\"0\",\"4\"],[\"64479.6\",\"77.56\",\"0\",\"3\"],[\"64479.5\",\"1.56\",\"0\",\"1\"],[\"64479.1\",\"0.02\",\"0\",\"1\"],[\"64478.9\",\"1.56\",\"0\",\"1\"],[\"64478.6\",\"0\",\"0\",\"0\"],[\"64478.2\",\"0\",\"0\",\"0\"],[\"64476.3\",\"187.08\",\"0\",\"6\"],[\"64471.4\",\"46.86\",\"0\",\"3\"],[\"64470.7\",\"0.02\",\"0\",\"2\"],[\"64469.9\",\"71.36\",\"0\",\"3\"],[\"64469.5\",\"0.01\",\"0\",\"1\"],[\"64469.4\",\"46.54\",\"0\",\"1\"],[\"64468.6\",\"20.85\",\"0\",\"2\"],[\"64468.3\",\"0\",\"0\",\"0\"],[\"64468.2\",\"62.17\",\"0\",\"2\"],[\"64467.5\",\"85.42\",\"0\",\"3\"],[\"64467.3\",\"103.03\",\"0\",\"2\"],[\"64466.1\",\"89.65\",\"0\",\"3\"],[\"64465.8\",\"232.9\",\"0\",\"1\"],[\"64465.6\",\"40.62\",\"0\",\"5\"],[\"64465.1\",\"0\",\"0\",\"0\"],[\"64464.4\",\"0.01\",\"0\",\"1\"],[\"64464.3\",\"0\",\"0\",\"0\"],[\"64463.9\",\"0\",\"0\",\"0\"],[\"64463.8\",\"347.8\",\"0\",\"3\"],[\"64457\",\"574.32\",\"0\",\"5\"],[\"64456.9\",\"0.02\",\"0\",\"1\"],[\"64454.9\",\"17.05\",\"0\",\"1\"],[\"64448.2\",\"0\",\"0\",\"0\"],[\"64446.6\",\"222.46\",\"0\",\"3\"],[\"64444.4\",\"37.24\",\"0\",\"2\"],[\"64444.3\",\"0.03\",\"0\",\"2\"],[\"64441.6\",\"35.81\",\"0\",\"4\"],[\"64433.6\",\"0.77\",\"0\",\"1\"],[\"64430.6\",\"0\",\"0\",\"0\"],[\"64430.4\",\"93.91\",\"0\",\"2\"],[\"64422.3\",\"0.14\",\"0\",\"14\"],[\"64422.2\",\"11.2\",\"0\",\"3\"],[\"64422.1\",\"1.2\",\"0\",\"1\"]],\"ts\":\"1782016034405\",\"checksum\":1671660258,\"seqId\":325070080820,\"prevSeqId\":325070080609}]}"}
{"action": "update", "capture_sequence": 222, "channel": "books", "connection_sequence": 2, "event": null, "instId": "BTC-USDT-SWAP", "local_receive_ts": "2026-06-21T04:27:14Z", "monotonic_ns": 1643590432665687, "raw": "{\"arg\":{\"channel\":\"books\",\"instId\":\"BTC-USDT-SWAP\"},\"action\":\"update\",\"data\":[{\"asks\":[[\"64484.9\",\"42.42\",\"0\",\"4\"],[\"64486.2\",\"2.57\",\"0\",\"9\"],[\"64487.4\",\"98.57\",\"0\",\"8\"],[\"64487.5\",\"136.17\",\"0\",\"4\"],[\"64487.9\",\"0.51\",\"0\",\"2\"],[\"64488.7\",\"0.04\",\"0\",\"1\"],[\"64488.9\",\"1.33\",\"0\",\"7\"],[\"64489.3\",\"23.25\",\"0\",\"5\"],[\"64489.9\",\"1\",\"0\",\"1\"],[\"64490.8\",\"1.22\",\"0\",\"2\"],[\"64491.7\",\"1.22\",\"0\",\"3\"],[\"64492.1\",\"1.5\",\"0\",\"1\"],[\"64492.6\",\"60.6\",\"0\",\"1\"],[\"64495.8\",\"167.02\",\"0\",\"6\"],[\"64495.9\",\"47.39\",\"0\",\"5\"],[\"64496.1\",\"0.06\",\"0\",\"3\"],[\"64496.7\",\"0.01\",\"0\",\"1\"],[\"64498\",\"24.4\",\"0\",\"3\"],[\"64500\",\"3456.33\",\"0\",\"1036\"],[\"64500.1\",\"0.23\",\"0\",\"6\"],[\"64500.4\",\"0.04\",\"0\",\"4\"],[\"64504.3\",\"0.05\",\"0\",\"3\"],[\"64504.6\",\"2.5\",\"0\",\"1\"],[\"64506.4\",\"0.03\",\"0\",\"3\"],[\"64507.3\",\"0.8\",\"0\",\"3\"],[\"64507.4\",\"61.06\",\"0\",\"2\"],[\"64507.5\",\"0.13\",\"0\",\"6\"],[\"64508.7\",\"15.67\",\"0\",\"7\"],[\"64512.8\",\"85.33\",\"0\",\"1\"],[\"64513.2\",\"0.15\",\"0\",\"4\"],[\"64518.9\",\"20.07\",\"0\",\"2\"],[\"64519\",\"0.67\",\"0\",\"4\"],[\"64519.8\",\"175.47\",\"0\",\"6\"],[\"64520.9\",\"0.02\",\"0\",\"2\"],[\"64523.4\",\"39.43\",\"0\",\"5\"],[\"64525.3\",\"0.01\",\"0\",\"1\"],[\"64527.4\",\"0\",\"0\",\"0\"],[\"64527.5\",\"0\",\"0\",\"0\"],[\"64527.6\",\"0\",\"0\",\"0\"]],\"bids\":[[\"64479.1\",\"0\",\"0\",\"0\"],[\"64477.6\",\"0.03\",\"0\",\"2\"],[\"64476.3\",\"55.05\",\"0\",\"4\"],[\"64471.4\",\"46.55\",\"0\",\"2\"],[\"64470.7\",\"0.33\",\"0\",\"3\"],[\"64469.9\",\"169.58\",\"0\",\"4\"],[\"64468.6\",\"33.81\",\"0\",\"1\"],[\"64468.3\",\"20.85\",\"0\",\"2\"],[\"64468.2\",\"62.15\",\"0\",\"1\"],[\"64467.4\",\"46.56\",\"0\",\"2\"],[\"64465.7\",\"6.24\",\"0\",\"2\"],[\"64465.3\",\"46.56\",\"0\",\"3\"],[\"64464.1\",\"0.02\",\"0\",\"1\"],[\"64464\",\"200.06\",\"0\",\"5\"],[\"64463.8\",\"347.78\",\"0\",\"2\"],[\"64460.1\",\"3.91\",\"0\",\"2\"],[\"64454.9\",\"12.86\",\"0\",\"1\"],[\"64453.7\",\"0\",\"0\",\"0\"],[\"64448.5\",\"515.29\",\"0\",\"4\"],[\"64447.9\",\"0\",\"0\",\"0\"],[\"64444.4\",\"37.26\",\"0\",\"3\"],[\"64444.3\",\"0.01\",\"0\",\"1\"],[\"64422.3\",\"0.01\",\"0\",\"1\"],[\"64422\",\"0.01\",\"0\",\"1\"]],\"ts\":\"1782016034505\",\"checksum\":-1089679688,\"seqId\":325070080952,\"prevSeqId\":325070080820}]}"}
{"action": null, "capture_sequence": 223, "channel": "trades", "connection_sequence": 2, "event": null, "instId": "BTC-USDT-SWAP", "local_receive_ts": "2026-06-21T04:27:14Z", "monotonic_ns": 1643590432975204, "raw": "{\"arg\":{\"channel\":\"trades\",\"instId\":\"BTC-USDT-SWAP\"},\"data\":[{\"instId\":\"BTC-USDT-SWAP\",\"tradeId\":\"2718750260\",\"px\":\"64482.9\",\"sz\":\"1.48\",\"side\":\"sell\",\"ts\":\"1782016034505\",\"count\":\"1\",\"source\":\"0\",\"seqId\":325070080954}]}"}
{"action": "update", "capture_sequence": 224, "channel": "books", "connection_sequence": 2, "event": null, "instId": "BTC-USDT-SWAP", "local_receive_ts": "2026-06-21T04:27:14Z", "monotonic_ns": 1643590524727609, "raw": "{\"arg\":{\"channel\":\"books\",\"instId\":\"BTC-USDT-SWAP\"},\"action\":\"update\",\"data\":[{\"asks\":[[\"64486.8\",\"0.19\",\"0\",\"3\"],[\"64489.5\",\"1.02\",\"0\",\"3\"],[\"64490.2\",\"1.2\",\"0\",\"1\"],[\"64492.5\",\"0.21\",\"0\",\"4\"],[\"64503.8\",\"31.03\",\"0\",\"1\"],[\"64504.5\",\"59.46\",\"0\",\"7\"],[\"64513.9\",\"58.3\",\"0\",\"2\"],[\"64515.4\",\"0.46\",\"0\",\"5\"],[\"64527.3\",\"0\",\"0\",\"0\"]],\"bids\":[[\"64482.9\",\"1046.36\",\"0\",\"65\"],[\"64478.1\",\"2.3\",\"0\",\"1\"],[\"64476.1\",\"0\",\"0\",\"0\"],[\"64471.5\",\"0.32\",\"0\",\"2\"],[\"64470.7\",\"0.02\",\"0\",\"2\"],[\"64466.1\",\"31.43\",\"0\",\"2\"],[\"64465\",\"58.22\",\"0\",\"1\"],[\"64463.7\",\"3.1\",\"0\",\"1\"],[\"64460.1\",\"7.12\",\"0\",\"3\"],[\"64453.8\",\"0.2\",\"0\",\"1\"],[\"64448.5\",\"512.19\",\"0\",\"3\"],[\"64422.2\",\"0\",\"0\",\"0\"],[\"64422.1\",\"0\",\"0\",\"0\"],[\"64422\",\"0\",\"0\",\"0\"]],\"ts\":\"1782016034605\",\"checksum\":300843102,\"seqId\":325070080983,\"prevSeqId\":325070080952}]}"}
{"action": "update", "capture_sequence": 225, "channel": "books", "connection_sequence": 2, "event": null, "instId": "BTC-USDT-SWAP", "local_receive_ts": "2026-06-21T04:27:14Z", "monotonic_ns": 1643590625541580, "raw": "{\"arg\":{\"channel\":\"books\",\"instId\":\"BTC-USDT-SWAP\"},\"action\":\"update\",\"data\":[{\"asks\":[[\"64490.5\",\"3.01\",\"0\",\"4\"],[\"64491.3\",\"1.21\",\"0\",\"2\"],[\"64491.9\",\"1.5\",\"0\",\"5\"],[\"64494.8\",\"0.45\",\"0\",\"2\"],[\"64498.2\",\"0.04\",\"0\",\"3\"],[\"64511\",\"25.02\",\"0\",\"8\"],[\"64516\",\"500.05\",\"0\",\"6\"],[\"64517.2\",\"0.76\",\"0\",\"5\"]],\"bids\":[],\"ts\":\"1782016034705\",\"checksum\":300843102,\"seqId\":325070080997,\"prevSeqId\":325070080983}]}"}
{"action": null, "capture_sequence": 226, "channel": "trades", "connection_sequence": 2, "event": null, "instId": "BTC-USDT-SWAP", "local_receive_ts": "2026-06-21T04:27:14Z", "monotonic_ns": 1643590647360050, "raw": "{\"arg\":{\"channel\":\"trades\",\"instId\":\"BTC-USDT-SWAP\"},\"data\":[{\"instId\":\"BTC-USDT-SWAP\",\"tradeId\":\"2718750262\",\"px\":\"64482.9\",\"sz\":\"31.61\",\"side\":\"sell\",\"ts\":\"1782016034728\",\"count\":\"2\",\"source\":\"0\",\"seqId\":325070081001}]}"}
{"action": null, "capture_sequence": 227, "channel": "trades", "connection_sequence": 2, "event": null, "instId": "BTC-USDT-SWAP", "local_receive_ts": "2026-06-21T04:27:14Z", "monotonic_ns": 1643590711784521, "raw": "{\"arg\":{\"channel\":\"trades\",\"instId\":\"BTC-USDT-SWAP\"},\"data\":[{\"instId\":\"BTC-USDT-SWAP\",\"tradeId\":\"2718750263\",\"px\":\"64483\",\"sz\":\"1\",\"side\":\"buy\",\"ts\":\"1782016034792\",\"count\":\"1\",\"source\":\"0\",\"seqId\":325070081028}]}"}
{"action": "update", "capture_sequence": 228, "channel": "books", "connection_sequence": 2, "event": null, "instId": "BTC-USDT-SWAP", "local_receive_ts": "2026-06-21T04:27:14Z", "monotonic_ns": 1643590724482396, "raw": "{\"arg\":{\"channel\":\"books\",\"instId\":\"BTC-USDT-SWAP\"},\"action\":\"update\",\"data\":[{\"asks\":[[\"64483\",\"179.76\",\"0\",\"24\"],[\"64486.9\",\"0.12\",\"0\",\"2\"],[\"64493.3\",\"0.41\",\"0\",\"4\"],[\"64497.2\",\"0.84\",\"0\",\"3\"],[\"64500\",\"3456.34\",\"0\",\"1037\"],[\"64500.1\",\"0.22\",\"0\",\"5\"],[\"64512\",\"88.21\",\"0\",\"14\"],[\"64512.8\",\"0\",\"0\",\"0\"],[\"64518.1\",\"24.94\",\"0\",\"7\"],[\"64518.9\",\"0.01\",\"0\",\"1\"],[\"64523.4\",\"39.42\",\"0\",\"4\"],[\"64524.4\",\"0.01\",\"0\",\"1\"]],\"bids\":[[\"64482.9\",\"1014.75\",\"0\",\"64\"],[\"64477.6\",\"0.01\",\"0\",\"1\"],[\"64476.4\",\"1.56\",\"0\",\"3\"],[\"64468.3\",\"0.77\",\"0\",\"1\"],[\"64467.7\",\"20.08\",\"0\",\"1\"],[\"64467.5\",\"0.03\",\"0\",\"2\"],[\"64466.2\",\"85.4\",\"0\",\"2\"],[\"64457\",\"574.34\",\"0\",\"6\"],[\"64456.9\",\"0\",\"0\",\"0\"],[\"64444.5\",\"156.73\",\"0\",\"4\"],[\"64444.4\",\"37.24\",\"0\",\"2\"],[\"64422.3\",\"0.02\",\"0\",\"2\"]],\"ts\":\"1782016034805\",\"checksum\":-1184191509,\"seqId\":325070081029,\"prevSeqId\":325070080997}]}"}
{"action": null, "capture_sequence": 229, "channel": "trades", "connection_sequence": 2, "event": null, "instId": "BTC-USDT-SWAP", "local_receive_ts": "2026-06-21T04:27:14Z", "monotonic_ns": 1643590734667095, "raw": "{\"arg\":{\"channel\":\"trades\",\"instId\":\"BTC-USDT-SWAP\"},\"data\":[{\"instId\":\"BTC-USDT-SWAP\",\"tradeId\":\"2718750264\",\"px\":\"64482.9\",\"sz\":\"0.06\",\"side\":\"sell\",\"ts\":\"1782016034815\",\"count\":\"1\",\"source\":\"0\",\"seqId\":325070081035}]}"}
{"action": "update", "capture_sequence": 230, "channel": "books", "connection_sequence": 2, "event": null, "instId": "BTC-USDT-SWAP", "local_receive_ts": "2026-06-21T04:27:15Z", "monotonic_ns": 1643590824401612, "raw": "{\"arg\":{\"channel\":\"books\",\"instId\":\"BTC-USDT-SWAP\"},\"action\":\"update\",\"data\":[{\"asks\":[[\"64499.9\",\"1114.84\",\"0\",\"3\"],[\"64500.1\",\"0.05\",\"0\",\"4\"],[\"64506.2\",\"1.58\",\"0\",\"3\"],[\"64506.3\",\"15.66\",\"0\",\"2\"]],\"bids\":[[\"64482.9\",\"1014.69\",\"0\",\"64\"],[\"64481.7\",\"0\",\"0\",\"0\"],[\"64481.5\",\"0.32\",\"0\",\"2\"],[\"64479.6\",\"0.02\",\"0\",\"2\"],[\"64479.3\",\"77.55\",\"0\",\"2\"],[\"64422.2\",\"11.2\",\"0\",\"3\"]],\"ts\":\"1782016034905\",\"checksum\":1363476521,\"seqId\":325070081045,\"prevSeqId\":325070081029}]}"}
{"action": "update", "capture_sequence": 231, "channel": "books", "connection_sequence": 2, "event": null, "instId": "BTC-USDT-SWAP", "local_receive_ts": "2026-06-21T04:27:15Z", "monotonic_ns": 1643590924752434, "raw": "{\"arg\":{\"channel\":\"books\",\"instId\":\"BTC-USDT-SWAP\"},\"action\":\"update\",\"data\":[{\"asks\":[[\"64486.1\",\"1.57\",\"0\",\"2\"],[\"64486.6\",\"10.3\",\"0\",\"3\"],[\"64487.1\",\"2.09\",\"0\",\"5\"],[\"64487.5\",\"137.73\",\"0\",\"5\"],[\"64488\",\"59.43\",\"0\",\"28\"],[\"64488.5\",\"1.56\",\"0\",\"1\"],[\"64489\",\"20.66\",\"0\",\"9\"],[\"64489.5\",\"2.58\",\"0\",\"4\"],[\"64527.2\",\"0\",\"0\",\"0\"]],\"bids\":[[\"64482.9\",\"1016.25\",\"0\",\"65\"],[\"64481.5\",\"0.01\",\"0\",\"1\"],[\"64480.9\",\"0.31\",\"0\",\"1\"],[\"64422.3\",\"0.01\",\"0\",\"1\"],[\"64422.2\",\"0\",\"0\",\"0\"]],\"ts\":\"1782016035005\",\"checksum\":-1683373816,\"seqId\":325070081076,\"prevSeqId\":325070081045}]}"}
{"action": null, "capture_sequence": 232, "channel": "trades", "connection_sequence": 2, "event": null, "instId": "BTC-USDT-SWAP", "local_receive_ts": "2026-06-21T04:27:15Z", "monotonic_ns": 1643590954236336, "raw": "{\"arg\":{\"channel\":\"trades\",\"instId\":\"BTC-USDT-SWAP\"},\"data\":[{\"instId\":\"BTC-USDT-SWAP\",\"tradeId\":\"2718750265\",\"px\":\"64483\",\"sz\":\"10.28\",\"side\":\"buy\",\"ts\":\"1782016035035\",\"count\":\"1\",\"source\":\"0\",\"seqId\":325070081092}]}"}
{"action": "update", "capture_sequence": 233, "channel": "books", "connection_sequence": 2, "event": null, "instId": "BTC-USDT-SWAP", "local_receive_ts": "2026-06-21T04:27:15Z", "monotonic_ns": 1643591024767062, "raw": "{\"arg\":{\"channel\":\"books\",\"instId\":\"BTC-USDT-SWAP\"},\"action\":\"update\",\"data\":[{\"asks\":[[\"64483\",\"169.48\",\"0\",\"24\"],[\"64486.1\",\"0.01\",\"0\",\"1\"],[\"64486.6\",\"8.74\",\"0\",\"2\"],[\"64487.1\",\"0.53\",\"0\",\"4\"],[\"64487.5\",\"136.17\",\"0\",\"4\"],[\"64489\",\"19.1\",\"0\",\"8\"],[\"64489.5\",\"1.02\",\"0\",\"3\"],[\"64489.6\",\"2.95\",\"0\",\"5\"],[\"64490.1\",\"4.56\",\"0\",\"4\"],[\"64490.6\",\"33.07\",\"0\",\"5\"],[\"64491.1\",\"1.56\",\"0\",\"1\"],[\"64491.6\",\"2.81\",\"0\",\"6\"],[\"64492\",\"1.6\",\"0\",\"5\"],[\"64492.5\",\"1.77\",\"0\",\"5\"],[\"64493\",\"18.74\",\"0\",\"5\"],[\"64495.8\",\"34.99\",\"0\",\"4\"],[\"64504.5\",\"59.15\",\"0\",\"6\"],[\"64504.9\",\"0.41\",\"0\",\"4\"],[\"64513.6\",\"0\",\"0\",\"0\"],[\"64513.8\",\"10.01\",\"0\",\"2\"],[\"64518.9\",\"46.5\",\"0\",\"2\"]],\"bids\":[[\"64469.9\",\"37.55\",\"0\",\"2\"],[\"64469.5\",\"0.39\",\"0\",\"2\"],[\"64467.4\",\"46.54\",\"0\",\"1\"],[\"64467\",\"282.33\",\"0\",\"4\"],[\"64466.1\",\"31.05\",\"0\",\"1\"],[\"64465.7\",\"6.22\",\"0\",\"1\"],[\"64465.3\",\"46.58\",\"0\",\"4\"],[\"64464.1\",\"0\",\"0\",\"0\"],[\"64463.9\",\"0.02\",\"0\",\"1\"],[\"64460.3\",\"2.28\",\"0\",\"1\"],[\"64422.8\",\"1.21\",\"0\",\"2\"],[\"64422.3\",\"0\",\"0\",\"0\"]],\"ts\":\"1782016035105\",\"checksum\":-1659607002,\"seqId\":325070081166,\"prevSeqId\":325070081076}]}"}
{"action": "update", "capture_sequence": 234, "channel": "books", "connection_sequence": 2, "event": null, "instId": "BTC-USDT-SWAP", "local_receive_ts": "2026-06-21T04:27:15Z", "monotonic_ns": 1643591124609248, "raw": "{\"arg\":{\"channel\":\"books\",\"instId\":\"BTC-USDT-SWAP\"},\"action\":\"update\",\"data\":[{\"asks\":[[\"64486.2\",\"3.57\",\"0\",\"10\"],[\"64488\",\"57.87\",\"0\",\"27\"],[\"64488.5\",\"0\",\"0\",\"0\"],[\"64489.6\",\"1.39\",\"0\",\"4\"],[\"64490.1\",\"3\",\"0\",\"3\"],[\"64495.8\",\"167.02\",\"0\",\"6\"],[\"64499.9\",\"1114.67\",\"0\",\"2\"],[\"64500.1\",\"0.22\",\"0\",\"5\"],[\"64527.2\",\"0.18\",\"0\",\"4\"]],\"bids\":[[\"64470\",\"39.37\",\"0\",\"5\"],[\"64469.9\",\"169.58\",\"0\",\"4\"]],\"ts\":\"1782016035205\",\"checksum\":2118144966,\"seqId\":325070081204,\"prevSeqId\":325070081166}]}"}
{"action": "update", "capture_sequence": 235, "channel": "books", "connection_sequence": 2, "event": null, "instId": "BTC-USDT-SWAP", "local_receive_ts": "2026-06-21T04:27:15Z", "monotonic_ns": 1643591224574723, "raw": "{\"arg\":{\"channel\":\"books\",\"instId\":\"BTC-USDT-SWAP\"},\"action\":\"update\",\"data\":[{\"asks\":[[\"64487.2\",\"1.59\",\"0\",\"3\"],[\"64487.7\",\"1.57\",\"0\",\"2\"],[\"64488.2\",\"5.52\",\"0\",\"3\"],[\"64488.8\",\"51.56\",\"0\",\"2\"],[\"64489.3\",\"24.81\",\"0\",\"6\"],[\"64490\",\"57.33\",\"0\",\"20\"],[\"64492.5\",\"0.21\",\"0\",\"4\"],[\"64493\",\"17.18\",\"0\",\"4\"]],\"bids\":[[\"64482.9\",\"1016.22\",\"0\",\"65\"]],\"ts\":\"1782016035305\",\"checksum\":-2123753860,\"seqId\":325070081260,\"prevSeqId\":325070081204}]}"}
{"action": null, "capture_sequence": 236, "channel": "trades", "connection_sequence": 2, "event": null, "instId": "BTC-USDT-SWAP", "local_receive_ts": "2026-06-21T04:27:15Z", "monotonic_ns": 1643591244531490, "raw": "{\"arg\":{\"channel\":\"trades\",\"instId\":\"BTC-USDT-SWAP\"},\"data\":[{\"instId\":\"BTC-USDT-SWAP\",\"tradeId\":\"2718750266\",\"px\":\"64482.9\",\"sz\":\"1.78\",\"side\":\"sell\",\"ts\":\"1782016035325\",\"count\":\"1\",\"source\":\"0\",\"seqId\":325070081277}]}"}
{"action": "update", "capture_sequence": 237, "channel": "books", "connection_sequence": 2, "event": null, "instId": "BTC-USDT-SWAP", "local_receive_ts": "2026-06-21T04:27:15Z", "monotonic_ns": 1643591332645875, "raw": "{\"arg\":{\"channel\":\"books\",\"instId\":\"BTC-USDT-SWAP\"},\"action\":\"update\",\"data\":[{\"asks\":[[\"64483\",\"236.74\",\"0\",\"25\"],[\"64484.1\",\"0.01\",\"0\",\"1\"],[\"64484.7\",\"0.01\",\"0\",\"1\"],[\"64484.8\",\"1.58\",\"0\",\"3\"],[\"64484.9\",\"42.41\",\"0\",\"3\"],[\"64485.4\",\"1.56\",\"0\",\"1\"],[\"64485.8\",\"0.42\",\"0\",\"4\"],[\"64485.9\",\"6.99\",\"0\",\"3\"],[\"64487.2\",\"0.03\",\"0\",\"2\"],[\"64487.7\",\"0.01\",\"0\",\"1\"],[\"64487.8\",\"1.66\",\"0\",\"5\"],[\"64488.2\",\"3.96\",\"0\",\"2\"],[\"64488.3\",\"1.58\",\"0\",\"3\"],[\"64491.1\",\"0\",\"0\",\"0\"],[\"64491.6\",\"1.25\",\"0\",\"5\"],[\"64492\",\"0.04\",\"0\",\"4\"],[\"64493.4\",\"1.09\",\"0\",\"6\"],[\"64495.7\",\"21.33\",\"0\",\"4\"],[\"64500.8\",\"15.87\",\"0\",\"2\"],[\"64501.4\",\"0.01\",\"0\",\"1\"],[\"64503.8\",\"263.8\",\"0\",\"2\"],[\"64504.3\",\"0.36\",\"0\",\"4\"],[\"64504.9\",\"0.1\",\"0\",\"3\"],[\"64505.1\",\"0.02\",\"0\",\"2\"],[\"64505.9\",\"1.56\",\"0\",\"2\"],[\"64506.2\",\"0.03\",\"0\",\"2\"],[\"64507.2\",\"47.82\",\"0\",\"3\"],[\"64507.4\",\"27.27\",\"0\",\"1\"],[\"64512.6\",\"117.62\",\"0\",\"8\"],[\"64513.9\",\"0.12\",\"0\",\"1\"],[\"64519.1\",\"129.17\",\"0\",\"3\"],[\"64519.8\",\"89.37\",\"0\",\"5\"],[\"64527.1\",\"0\",\"0\",\"0\"],[\"64527.2\",\"0\",\"0\",\"0\"]],\"bids\":[[\"64482.9\",\"941.59\",\"0\",\"63\"],[\"64482.5\",\"5.02\",\"0\",\"2\"],[\"64482.4\",\"1.56\",\"0\",\"1\"],[\"64482.1\",\"0.01\",\"0\",\"1\"],[\"64481.9\",\"1.56\",\"0\",\"1\"],[\"64479.3\",\"0.01\",\"0\",\"1\"],[\"64479\",\"77.55\",\"0\",\"2\"],[\"64476.5\",\"13.73\",\"0\",\"3\"],[\"64476.4\",\"31.83\",\"0\",\"3\"],[\"64476.3\",\"24.01\",\"0\",\"3\"],[\"64476\",\"0.04\",\"0\",\"2\"],[\"64470.4\",\"4\",\"0\",\"1\"],[\"64469.4\",\"132.71\",\"0\",\"2\"],[\"64468.6\",\"0\",\"0\",\"0\"],[\"64468.4\",\"33.81\",\"0\",\"1\"],[\"64465.8\",\"0\",\"0\",\"0\"],[\"64465\",\"232.91\",\"0\",\"1\"],[\"64463.9\",\"58.24\",\"0\",\"2\"],[\"64423.5\",\"0\",\"0\",\"0\"],[\"64422.7\",\"3.4\",\"0\",\"3\"],[\"64422.6\",\"0.02\",\"0\",\"2\"]],\"ts\":\"1782016035405\",\"checksum\":540992505,\"seqId\":325070081376,\"prevSeqId\":325070081260}]}"}
{"action": "update", "capture_sequence": 238, "channel": "books", "connection_sequence": 2, "event": null, "instId": "BTC-USDT-SWAP", "local_receive_ts": "2026-06-21T04:27:15Z", "monotonic_ns": 1643591424924256, "raw": "{\"arg\":{\"channel\":\"books\",\"instId\":\"BTC-USDT-SWAP\"},\"action\":\"update\",\"data\":[{\"asks\":[[\"64483\",\"293.71\",\"0\",\"26\"],[\"64483.8\",\"0.01\",\"0\",\"1\"],[\"64483.9\",\"1.57\",\"0\",\"2\"],[\"64484.1\",\"0\",\"0\",\"0\"],[\"64484.4\",\"0.01\",\"0\",\"1\"],[\"64484.5\",\"1.63\",\"0\",\"5\"],[\"64484.7\",\"0\",\"0\",\"0\"],[\"64484.8\",\"0.02\",\"0\",\"2\"],[\"64484.9\",\"43.97\",\"0\",\"4\"],[\"64485.4\",\"0\",\"0\",\"0\"],[\"64485.6\",\"1.56\",\"0\",\"1\"],[\"64485.9\",\"5.43\",\"0\",\"2\"],[\"64486.1\",\"1.57\",\"0\",\"2\"],[\"64486.6\",\"10.3\",\"0\",\"3\"],[\"64487\",\"6.67\",\"0\",\"5\"],[\"64487.3\",\"6.24\",\"0\",\"3\"],[\"64487.4\",\"92.37\",\"0\",\"7\"],[\"64489.3\",\"23.25\",\"0\",\"5\"],[\"64490\",\"55.77\",\"0\",\"19\"],[\"64490.6\",\"31.51\",\"0\",\"4\"],[\"64492.3\",\"0.03\",\"0\",\"1\"],[\"64493.4\",\"11.08\",\"0\",\"7\"],[\"64495.6\",\"22.01\",\"0\",\"2\"],[\"64495.7\",\"11.35\",\"0\",\"3\"],[\"64496.1\",\"18.66\",\"0\",\"6\"],[\"64498.9\",\"3.59\",\"0\",\"3\"],[\"64500.1\",\"0.05\",\"0\",\"4\"]],\"bids\":[[\"64482.9\",\"927.64\",\"0\",\"62\"],[\"64482.5\",\"5\",\"0\",\"1\"],[\"64482.4\",\"0\",\"0\",\"0\"],[\"64482.1\",\"0.03\",\"0\",\"2\"],[\"64478.1\",\"16.25\",\"0\",\"2\"],[\"64460.1\",\"3.91\",\"0\",\"2\"],[\"64422.3\",\"0.02\",\"0\",\"2\"]],\"ts\":\"1782016035505\",\"checksum\":1276294313,\"seqId\":325070081431,\"prevSeqId\":325070081376}]}"}
{"action": "update", "capture_sequence": 239, "channel": "books", "connection_sequence": 2, "event": null, "instId": "BTC-USDT-SWAP", "local_receive_ts": "2026-06-21T04:27:15Z", "monotonic_ns": 1643591532103505, "raw": "{\"arg\":{\"channel\":\"books\",\"instId\":\"BTC-USDT-SWAP\"},\"action\":\"update\",\"data\":[{\"asks\":[[\"64483\",\"434.19\",\"0\",\"30\"],[\"64484.9\",\"81.9\",\"0\",\"5\"],[\"64485.9\",\"141.56\",\"0\",\"3\"],[\"64487.3\",\"0.04\",\"0\",\"2\"],[\"64487.4\",\"51.57\",\"0\",\"7\"],[\"64487.5\",\"0.04\",\"0\",\"3\"],[\"64488.8\",\"50\",\"0\",\"1\"],[\"64489.7\",\"7\",\"0\",\"2\"],[\"64492.5\",\"0.05\",\"0\",\"3\"],[\"64493.4\",\"11.15\",\"0\",\"7\"],[\"64493.5\",\"186.37\",\"0\",\"6\"],[\"64495.7\",\"29.95\",\"0\",\"6\"],[\"64496.1\",\"0.06\",\"0\",\"3\"],[\"64497.4\",\"37.47\",\"0\",\"3\"],[\"64498.1\",\"8.2\",\"0\",\"5\"],[\"64498.9\",\"3.42\",\"0\",\"2\"],[\"64503\",\"46.98\",\"0\",\"4\"],[\"64503.8\",\"232.77\",\"0\",\"1\"],[\"64505.5\",\"75.36\",\"0\",\"4\"],[\"64505.9\",\"0.01\",\"0\",\"1\"],[\"64506.5\",\"16.49\",\"0\",\"3\"],[\"64507.3\",\"0.03\",\"0\",\"2\"],[\"64516.8\",\"26.33\",\"0\",\"4\"],[\"64518.1\",\"4.88\",\"0\",\"6\"],[\"64518.3\",\"86.12\",\"0\",\"3\"],[\"64519.1\",\"43.07\",\"0\",\"2\"],[\"64519.2\",\"0.48\",\"0\",\"7\"]],\"bids\":[[\"64481.9\",\"0\",\"0\",\"0\"],[\"64480.1\",\"0.01\",\"0\",\"1\"],[\"64479.8\",\"73.94\",\"0\",\"3\"],[\"64479.5\",\"0\",\"0\",\"0\"],[\"64479\",\"0.01\",\"0\",\"1\"],[\"64478.6\",\"77.54\",\"0\",\"1\"],[\"64469.4\",\"46.54\",\"0\",\"1\"],[\"64468.8\",\"97.5\",\"0\",\"2\"],[\"64468.3\",\"0\",\"0\",\"0\"],[\"64467.7\",\"0\",\"0\",\"0\"],[\"64467.5\",\"0.8\",\"0\",\"3\"],[\"64466.3\",\"20.08\",\"0\",\"1\"],[\"64466.1\",\"0\",\"0\",\"0\"],[\"64465.1\",\"31.05\",\"0\",\"1\"],[\"64464.3\",\"3.22\",\"0\",\"1\"],[\"64446.6\",\"11.95\",\"0\",\"2\"],[\"64422.5\",\"0\",\"0\",\"0\"],[\"64422.2\",\"11.2\",\"0\",\"3\"],[\"64422.1\",\"1.2\",\"0\",\"1\"]],\"ts\":\"1782016035605\",\"checksum\":-1000221701,\"seqId\":325070081542,\"prevSeqId\":325070081431}]}"}
{"action": "update", "capture_sequence": 240, "channel": "books", "connection_sequence": 2, "event": null, "instId": "BTC-USDT-SWAP", "local_receive_ts": "2026-06-21T04:27:15Z", "monotonic_ns": 1643591624471373, "raw": "{\"arg\":{\"channel\":\"books\",\"instId\":\"BTC-USDT-SWAP\"},\"action\":\"update\",\"data\":[{\"asks\":[[\"64483\",\"369.93\",\"0\",\"29\"],[\"64505.5\",\"73.81\",\"0\",\"3\"],[\"64505.9\",\"1.56\",\"0\",\"2\"],[\"64506.8\",\"92.77\",\"0\",\"6\"],[\"64516.8\",\"6.26\",\"0\",\"3\"],[\"64517.5\",\"20.06\",\"0\",\"1\"],[\"64527\",\"0\",\"0\",\"0\"]],\"bids\":[[\"64479.3\",\"77.55\",\"0\",\"2\"],[\"64478.6\",\"0\",\"0\",\"0\"],[\"64478.1\",\"13.95\",\"0\",\"1\"],[\"64476.1\",\"2.4\",\"0\",\"1\"],[\"64466.9\",\"20.08\",\"0\",\"1\"],[\"64466.3\",\"0\",\"0\",\"0\"]],\"ts\":\"1782016035705\",\"checksum\":1429179027,\"seqId\":325070081622,\"prevSeqId\":325070081542}]}"}
{"action": "update", "capture_sequence": 241, "channel": "books", "connection_sequence": 2, "event": null, "instId": "BTC-USDT-SWAP", "local_receive_ts": "2026-06-21T04:27:15Z", "monotonic_ns": 1643591724280238, "raw": "{\"arg\":{\"channel\":\"books\",\"instId\":\"BTC-USDT-SWAP\"},\"action\":\"update\",\"data\":[{\"asks\":[[\"64483\",\"379.93\",\"0\",\"30\"],[\"64483.8\",\"0\",\"0\",\"0\"],[\"64483.9\",\"0.01\",\"0\",\"1\"],[\"64484.9\",\"81.91\",\"0\",\"6\"],[\"64497.2\",\"1.01\",\"0\",\"4\"],[\"64498\",\"24.62\",\"0\",\"4\"],[\"64498.1\",\"8.03\",\"0\",\"4\"],[\"64518.3\",\"0.02\",\"0\",\"2\"],[\"64519.7\",\"96.91\",\"0\",\"8\"],[\"64520\",\"291.43\",\"0\",\"64\"],[\"64527\",\"0.17\",\"0\",\"3\"]],\"bids\":[[\"64469.4\",\"132.71\",\"0\",\"2\"],[\"64468.8\",\"11.33\",\"0\",\"1\"],[\"64464.3\",\"0\",\"0\",\"0\"],[\"64448.7\",\"18.87\",\"0\",\"1\"],[\"64448.5\",\"716.63\",\"0\",\"4\"],[\"64424.5\",\"378.91\",\"0\",\"1\"],[\"64422.1\",\"0\",\"0\",\"0\"]],\"ts\":\"1782016035805\",\"checksum\":1017542169,\"seqId\":325070081711,\"prevSeqId\":325070081622}]}"}
{"action": null, "capture_sequence": 242, "channel": "trades", "connection_sequence": 2, "event": null, "instId": "BTC-USDT-SWAP", "local_receive_ts": "2026-06-21T04:27:16Z", "monotonic_ns": 1643591798323868, "raw": "{\"arg\":{\"channel\":\"trades\",\"instId\":\"BTC-USDT-SWAP\"},\"data\":[{\"instId\":\"BTC-USDT-SWAP\",\"tradeId\":\"2718750267\",\"px\":\"64482.9\",\"sz\":\"0.06\",\"side\":\"sell\",\"ts\":\"1782016035879\",\"count\":\"1\",\"source\":\"0\",\"seqId\":325070081763}]}"}
{"action": "update", "capture_sequence": 243, "channel": "books", "connection_sequence": 2, "event": null, "instId": "BTC-USDT-SWAP", "local_receive_ts": "2026-06-21T04:27:16Z", "monotonic_ns": 1643591824435608, "raw": "{\"arg\":{\"channel\":\"books\",\"instId\":\"BTC-USDT-SWAP\"},\"action\":\"update\",\"data\":[{\"asks\":[[\"64483\",\"369.93\",\"0\",\"29\"]],\"bids\":[[\"64482.9\",\"927.58\",\"0\",\"62\"],[\"64464.3\",\"3.22\",\"0\",\"1\"],[\"64422.2\",\"0\",\"0\",\"0\"]],\"ts\":\"1782016035905\",\"checksum\":-277968131,\"seqId\":325070081780,\"prevSeqId\":325070081711}]}"}
{"action": "update", "capture_sequence": 244, "channel": "books", "connection_sequence": 2, "event": null, "instId": "BTC-USDT-SWAP", "local_receive_ts": "2026-06-21T04:27:16Z", "monotonic_ns": 1643591924932795, "raw": "{\"arg\":{\"channel\":\"books\",\"instId\":\"BTC-USDT-SWAP\"},\"action\":\"update\",\"data\":[{\"asks\":[[\"64483\",\"459.03\",\"0\",\"32\"],[\"64486\",\"51.09\",\"0\",\"6\"],[\"64497.1\",\"0.18\",\"0\",\"2\"],[\"64497.2\",\"0.84\",\"0\",\"3\"],[\"64500.6\",\"15.9\",\"0\",\"4\"],[\"64500.8\",\"0.36\",\"0\",\"1\"],[\"64504.3\",\"0.05\",\"0\",\"3\"],[\"64504.5\",\"59.46\",\"0\",\"7\"],[\"64507.2\",\"14.03\",\"0\",\"2\"],[\"64507.6\",\"33.82\",\"0\",\"3\"],[\"64512.6\",\"59.44\",\"0\",\"7\"],[\"64512.8\",\"58.18\",\"0\",\"1\"],[\"64526\",\"1.15\",\"0\",\"3\"],[\"64527\",\"0\",\"0\",\"0\"]],\"bids\":[[\"64482.9\",\"930.04\",\"0\",\"63\"],[\"64482.5\",\"5.02\",\"0\",\"2\"],[\"64482.4\",\"2.46\",\"0\",\"1\"],[\"64482.1\",\"0.01\",\"0\",\"1\"],[\"64480.6\",\"0\",\"0\",\"0\"],[\"64480.5\",\"0\",\"0\",\"0\"],[\"64480\",\"183.73\",\"0\",\"7\"],[\"64479.9\",\"0.02\",\"0\",\"2\"],[\"64479.6\",\"1.58\",\"0\",\"3\"],[\"64479.3\",\"0.01\",\"0\",\"1\"],[\"64479.2\",\"79.93\",\"0\",\"2\"],[\"64478.9\",\"0\",\"0\",\"0\"],[\"64478.6\",\"77.54\",\"0\",\"1\"],[\"64476\",\"1.6\",\"0\",\"3\"],[\"64470\",\"125.53\",\"0\",\"6\"],[\"64469.4\",\"46.54\",\"0\",\"1\"],[\"64468.6\",\"33.81\",\"0\",\"1\"],[\"64468.4\",\"0\",\"0\",\"0\"],[\"64466.2\",\"0.01\",\"0\",\"1\"],[\"64466.1\",\"85.39\",\"0\",\"1\"],[\"64464.3\",\"61.44\",\"0\",\"2\"],[\"64463.9\",\"0.02\",\"0\",\"1\"]],\"ts\":\"1782016036005\",\"checksum\":-911809020,\"seqId\":325070081879,\"prevSeqId\":325070081780}]}"}
{"action": null, "capture_sequence": 245, "channel": "trades", "connection_sequence": 2, "event": null, "instId": "BTC-USDT-SWAP", "local_receive_ts": "2026-06-21T04:27:16Z", "monotonic_ns": 1643591963057399, "raw": "{\"arg\":{\"channel\":\"trades\",\"instId\":\"BTC-USDT-SWAP\"},\"data\":[{\"instId\":\"BTC-USDT-SWAP\",\"tradeId\":\"2718750268\",\"px\":\"64483\",\"sz\":\"0.01\",\"side\":\"buy\",\"ts\":\"1782016036044\",\"count\":\"1\",\"source\":\"0\",\"seqId\":325070081949}]}"}
{"action": "update", "capture_sequence": 246, "channel": "books", "connection_sequence": 2, "event": null, "instId": "BTC-USDT-SWAP", "local_receive_ts": "2026-06-21T04:27:16Z", "monotonic_ns": 1643592032631209, "raw": "{\"arg\":{\"channel\":\"books\",\"instId\":\"BTC-USDT-SWAP\"},\"action\":\"update\",\"data\":[{\"asks\":[[\"64483\",\"447.46\",\"0\",\"30\"],[\"64484.4\",\"0\",\"0\",\"0\"],[\"64484.5\",\"0.07\",\"0\",\"4\"],[\"64485.5\",\"0.02\",\"0\",\"2\"],[\"64488.8\",\"51.56\",\"0\",\"2\"],[\"64489.3\",\"24.81\",\"0\",\"6\"],[\"64494.1\",\"0.01\",\"0\",\"1\"],[\"64495.9\",\"47.38\",\"0\",\"4\"],[\"64500\",\"3456.35\",\"0\",\"1038\"],[\"64500.4\",\"0.03\",\"0\",\"3\"],[\"64500.6\",\"0.39\",\"0\",\"3\"],[\"64500.8\",\"15.87\",\"0\",\"2\"],[\"64503\",\"15.95\",\"0\",\"3\"],[\"64503.4\",\"31.03\",\"0\",\"1\"],[\"64503.6\",\"0.03\",\"0\",\"3\"],[\"64503.8\",\"0\",\"0\",\"0\"],[\"64503.9\",\"248.42\",\"0\",\"2\"],[\"64504.3\",\"0.04\",\"0\",\"2\"],[\"64506.2\",\"0.8\",\"0\",\"3\"],[\"64506.5\",\"15.72\",\"0\",\"2\"],[\"64512.8\",\"0\",\"0\",\"0\"],[\"64512.9\",\"77.17\",\"0\",\"6\"],[\"64517.5\",\"0\",\"0\",\"0\"],[\"64518.3\",\"20.08\",\"0\",\"3\"],[\"64522.8\",\"15.72\",\"0\",\"5\"],[\"64524.4\",\"0\",\"0\",\"0\"],[\"64527\",\"0.17\",\"0\",\"3\"],[\"64527.1\",\"0.46\",\"0\",\"1\"],[\"64527.2\",\"0.18\",\"0\",\"4\"]],\"bids\":[[\"64482.9\",\"927.58\",\"0\",\"62\"],[\"64482.8\",\"39.79\",\"0\",\"11\"],[\"64482.7\",\"1.58\",\"0\",\"2\"],[\"64482.5\",\"5\",\"0\",\"1\"],[\"64482.4\",\"0\",\"0\",\"0\"],[\"64480.5\",\"4.02\",\"0\",\"2\"],[\"64479.9\",\"2.48\",\"0\",\"3\"],[\"64479.6\",\"0.03\",\"0\",\"3\"],[\"64479.5\",\"1.56\",\"0\",\"1\"],[\"64479.4\",\"0.01\",\"0\",\"1\"],[\"64479.3\",\"77.55\",\"0\",\"2\"],[\"64479.2\",\"78.37\",\"0\",\"1\"],[\"64479\",\"1.57\",\"0\",\"2\"],[\"64478.6\",\"0\",\"0\",\"0\"],[\"64476.4\",\"31.81\",\"0\",\"2\"],[\"64476.1\",\"2.42\",\"0\",\"2\"],[\"64469.2\",\"154.75\",\"0\",\"2\"],[\"64469.1\",\"2.81\",\"0\",\"4\"],[\"64467.7\",\"20.08\",\"0\",\"1\"],[\"64467.5\",\"0.03\",\"0\",\"2\"],[\"64467.4\",\"47.31\",\"0\",\"2\"],[\"64467\",\"404.62\",\"0\",\"4\"],[\"64466.9\",\"0.02\",\"0\",\"1\"],[\"64465.7\",\"37.27\",\"0\",\"2\"],[\"64465.1\",\"0\",\"0\",\"0\"],[\"64464.4\",\"58.23\",\"0\",\"2\"],[\"64464.3\",\"0\",\"0\",\"0\"],[\"64463.9\",\"0\",\"0\",\"0\"],[\"64463.8\",\"347.8\",\"0\",\"3\"],[\"64457\",\"574.32\",\"0\",\"5\"],[\"64456.9\",\"0.02\",\"0\",\"1\"],[\"64444.5\",\"156.71\",\"0\",\"3\"],[\"64444\",\"15.69\",\"0\",\"4\"],[\"64423.5\",\"19.6\",\"0\",\"1\"],[\"64422.7\",\"22.42\",\"0\",\"4\"],[\"64422.3\",\"0\",\"0\",\"0\"]],\"ts\":\"1782016036105\",\"checksum\":-666694015,\"seqId\":325070082029,\"prevSeqId\":325070081879}]}"}
{"action": "update", "capture_sequence": 247, "channel": "books", "connection_sequence": 2, "event": null, "instId": "BTC-USDT-SWAP", "local_receive_ts": "2026-06-21T04:27:16Z", "monotonic_ns": 1643592127923039, "raw": "{\"arg\":{\"channel\":\"books\",\"instId\":\"BTC-USDT-SWAP\"},\"action\":\"update\",\"data\":[{\"asks\":[[\"64484.3\",\"1.56\",\"0\",\"1\"],[\"64484.7\",\"0.01\",\"0\",\"1\"],[\"64484.8\",\"1.58\",\"0\",\"3\"],[\"64484.9\",\"80.35\",\"0\",\"5\"],[\"64485.5\",\"0.01\",\"0\",\"1\"],[\"64496.4\",\"0.19\",\"0\",\"3\"],[\"64497.1\",\"0.01\",\"0\",\"1\"],[\"64506.2\",\"0.03\",\"0\",\"2\"],[\"64506.4\",\"0.8\",\"0\",\"4\"],[\"64527.1\",\"0\",\"0\",\"0\"],[\"64527.2\",\"0\",\"0\",\"0\"]],\"bids\":[[\"64482.8\",\"39.77\",\"0\",\"10\"],[\"64482.7\",\"0.02\",\"0\",\"1\"],[\"64482.3\",\"0.02\",\"0\",\"1\"],[\"64482.2\",\"1.56\",\"0\",\"1\"],[\"64476\",\"0.04\",\"0\",\"2\"],[\"64467.5\",\"0.8\",\"0\",\"3\"],[\"64467.4\",\"46.54\",\"0\",\"1\"],[\"64464.3\",\"3.22\",\"0\",\"1\"],[\"64423.5\",\"0\",\"0\",\"0\"],[\"64422.7\",\"3.4\",\"0\",\"3\"],[\"64422.6\",\"0\",\"0\",\"0\"],[\"64422.4\",\"0\",\"0\",\"0\"]],\"ts\":\"1782016036205\",\"checksum\":1593758264,\"seqId\":325070082189,\"prevSeqId\":325070082029}]}"}
{"action": "update", "capture_sequence": 248, "channel": "books", "connection_sequence": 2, "event": null, "instId": "BTC-USDT-SWAP", "local_receive_ts": "2026-06-21T04:27:16Z", "monotonic_ns": 1643592224669251, "raw": "{\"arg\":{\"channel\":\"books\",\"instId\":\"BTC-USDT-SWAP\"},\"action\":\"update\",\"data\":[{\"asks\":[[\"64483\",\"457.46\",\"0\",\"31\"],[\"64484.3\",\"0\",\"0\",\"0\"],[\"64484.7\",\"0\",\"0\",\"0\"],[\"64484.8\",\"0.02\",\"0\",\"2\"],[\"64485.1\",\"0.01\",\"0\",\"1\"],[\"64485.2\",\"1.58\",\"0\",\"3\"],[\"64485.6\",\"0\",\"0\",\"0\"],[\"64485.9\",\"143.12\",\"0\",\"4\"],[\"64486.1\",\"0.01\",\"0\",\"1\"],[\"64486.4\",\"2.83\",\"0\",\"3\"],[\"64486.6\",\"8.74\",\"0\",\"2\"],[\"64489.8\",\"68.56\",\"0\",\"5\"],[\"64490.2\",\"2.76\",\"0\",\"2\"],[\"64512.9\",\"18.99\",\"0\",\"5\"],[\"64513.2\",\"58.33\",\"0\",\"5\"],[\"64527.1\",\"0.46\",\"0\",\"1\"],[\"64527.2\",\"0.18\",\"0\",\"4\"]],\"bids\":[[\"64482.9\",\"914.11\",\"0\",\"61\"],[\"64482.8\",\"41.33\",\"0\",\"11\"]],\"ts\":\"1782016036305\",\"checksum\":-1791878416,\"seqId\":325070082290,\"prevSeqId\":325070082189}]}"}
{"action": null, "capture_sequence": 249, "channel": "trades", "connection_sequence": 2, "event": null, "instId": "BTC-USDT-SWAP", "local_receive_ts": "2026-06-21T04:27:16Z", "monotonic_ns": 1643592288689803, "raw": "{\"arg\":{\"channel\":\"trades\",\"instId\":\"BTC-USDT-SWAP\"},\"data\":[{\"instId\":\"BTC-USDT-SWAP\",\"tradeId\":\"2718750269\",\"px\":\"64483\",\"sz\":\"3.56\",\"side\":\"buy\",\"ts\":\"1782016036369\",\"count\":\"1\",\"source\":\"0\",\"seqId\":325070082369}]}"}
{"action": "update", "capture_sequence": 250, "channel": "books", "connection_sequence": 2, "event": null, "instId": "BTC-USDT-SWAP", "local_receive_ts": "2026-06-21T04:27:16Z", "monotonic_ns": 1643592325216577, "raw": "{\"arg\":{\"channel\":\"books\",\"instId\":\"BTC-USDT-SWAP\"},\"action\":\"update\",\"data\":[{\"asks\":[[\"64483\",\"400.11\",\"0\",\"30\"],[\"64485.1\",\"0\",\"0\",\"0\"],[\"64485.2\",\"0.02\",\"0\",\"2\"],[\"64485.8\",\"0.43\",\"0\",\"5\"],[\"64485.9\",\"141.56\",\"0\",\"3\"],[\"64486.4\",\"1.27\",\"0\",\"2\"],[\"64486.9\",\"1.68\",\"0\",\"3\"],[\"64487\",\"5.11\",\"0\",\"4\"],[\"64487.4\",\"53.13\",\"0\",\"8\"],[\"64490.2\",\"1.2\",\"0\",\"1\"],[\"64496.2\",\"20.06\",\"0\",\"3\"],[\"64496.4\",\"0.02\",\"0\",\"2\"],[\"64503.4\",\"0\",\"0\",\"0\"],[\"64503.6\",\"31.06\",\"0\",\"4\"],[\"64504.1\",\"15.42\",\"0\",\"7\"],[\"64504.5\",\"59.15\",\"0\",\"6\"],[\"64507.4\",\"61.06\",\"0\",\"2\"],[\"64507.6\",\"0.03\",\"0\",\"2\"],[\"64518.3\",\"0.02\",\"0\",\"2\"],[\"64518.9\",\"66.56\",\"0\",\"3\"],[\"64519.7\",\"10.81\",\"0\",\"7\"],[\"64519.8\",\"122.39\",\"0\",\"7\"],[\"64519.9\",\"582.66\",\"0\",\"3\"],[\"64527.3\",\"0.05\",\"0\",\"5\"],[\"64527.4\",\"0.27\",\"0\",\"2\"]],\"bids\":[[\"64482.9\",\"927.56\",\"0\",\"62\"],[\"64482.8\",\"39.77\",\"0\",\"10\"],[\"64482.3\",\"0\",\"0\",\"0\"],[\"64482.2\",\"0\",\"0\",\"0\"],[\"64482.1\",\"0.03\",\"0\",\"2\"],[\"64470.4\",\"90.16\",\"0\",\"2\"],[\"64470\",\"39.37\",\"0\",\"5\"],[\"64468.3\",\"20.08\",\"0\",\"1\"],[\"64467.7\",\"0\",\"0\",\"0\"],[\"64465.8\",\"31.05\",\"0\",\"1\"],[\"64465.7\",\"6.22\",\"0\",\"1\"],[\"64441.2\",\"0\",\"0\",\"0\"],[\"64440.5\",\"0.38\",\"0\",\"1\"],[\"64423.5\",\"19.6\",\"0\",\"1\"],[\"64422.7\",\"22.42\",\"0\",\"4\"]],\"ts\":\"1782016036405\",\"checksum\":328119413,\"seqId\":325070082477,\"prevSeqId\":325070082290}]}"}
{"action": "update", "capture_sequence": 251, "channel": "books", "connection_sequence": 2, "event": null, "instId": "BTC-USDT-SWAP", "local_receive_ts": "2026-06-21T04:27:16Z", "monotonic_ns": 1643592424944191, "raw": "{\"arg\":{\"channel\":\"books\",\"instId\":\"BTC-USDT-SWAP\"},\"action\":\"update\",\"data\":[{\"asks\":[[\"64483\",\"444.16\",\"0\",\"31\"],[\"64495.3\",\"5.03\",\"0\",\"3\"],[\"64503.6\",\"31.05\",\"0\",\"3\"],[\"64504\",\"54.56\",\"0\",\"9\"],[\"64504.1\",\"15.11\",\"0\",\"6\"],[\"64504.3\",\"0.35\",\"0\",\"3\"],[\"64506.2\",\"0.8\",\"0\",\"3\"],[\"64506.4\",\"0.03\",\"0\",\"3\"],[\"64507.4\",\"27.27\",\"0\",\"1\"],[\"64508.4\",\"35.41\",\"0\",\"6\"],[\"64513\",\"68.55\",\"0\",\"4\"],[\"64513.2\",\"0.15\",\"0\",\"4\"],[\"64518.9\",\"46.5\",\"0\",\"2\"],[\"64519\",\"20.73\",\"0\",\"5\"]],\"bids\":[[\"64469.6\",\"33.82\",\"0\",\"2\"],[\"64469.2\",\"154.77\",\"0\",\"3\"],[\"64469.1\",\"2.79\",\"0\",\"3\"],[\"64468.6\",\"20.08\",\"0\",\"1\"],[\"64468.3\",\"0\",\"0\",\"0\"],[\"64467.5\",\"0.03\",\"0\",\"2\"],[\"64467.2\",\"0.77\",\"0\",\"1\"],[\"64444.4\",\"37.26\",\"0\",\"3\"],[\"64444\",\"15.67\",\"0\",\"3\"],[\"64423.5\",\"0\",\"0\",\"0\"],[\"64422.7\",\"3.4\",\"0\",\"3\"],[\"64422.6\",\"0.02\",\"0\",\"2\"]],\"ts\":\"1782016036505\",\"checksum\":1110854904,\"seqId\":325070082658,\"prevSeqId\":325070082477}]}"}
{"action": "update", "capture_sequence": 252, "channel": "books", "connection_sequence": 2, "event": null, "instId": "BTC-USDT-SWAP", "local_receive_ts": "2026-06-21T04:27:16Z", "monotonic_ns": 1643592524712379, "raw": "{\"arg\":{\"channel\":\"books\",\"instId\":\"BTC-USDT-SWAP\"},\"action\":\"update\",\"data\":[{\"asks\":[[\"64496.2\",\"19.89\",\"0\",\"2\"],[\"64496.9\",\"0.17\",\"0\",\"1\"],[\"64497.4\",\"37.31\",\"0\",\"2\"],[\"64504.3\",\"0.04\",\"0\",\"2\"],[\"64504.9\",\"0.41\",\"0\",\"4\"],[\"64507.3\",\"33.82\",\"0\",\"3\"],[\"64508.4\",\"1.62\",\"0\",\"5\"],[\"64511.9\",\"85.47\",\"0\",\"2\"],[\"64512\",\"2.88\",\"0\",\"13\"],[\"64518\",\"123.1\",\"0\",\"13\"],[\"64519\",\"0.67\",\"0\",\"4\"],[\"64519.7\",\"96.91\",\"0\",\"8\"],[\"64519.8\",\"89.37\",\"0\",\"5\"],[\"64519.9\",\"496.56\",\"0\",\"2\"],[\"64527.4\",\"0\",\"0\",\"0\"]],\"bids\":[[\"64482.9\",\"997.08\",\"0\",\"64\"],[\"64472.2\",\"0.31\",\"0\",\"1\"],[\"64471.5\",\"0.01\",\"0\",\"1\"],[\"64470.4\",\"4\",\"0\",\"1\"],[\"64470\",\"125.53\",\"0\",\"6\"],[\"64469.6\",\"0.01\",\"0\",\"1\"],[\"64468.6\",\"0\",\"0\",\"0\"],[\"64468.4\",\"33.81\",\"0\",\"1\"],[\"64467.6\",\"20.11\",\"0\",\"4\"],[\"64464.3\",\"0\",\"0\",\"0\"]],\"ts\":\"1782016036605\",\"checksum\":511810089,\"seqId\":325070082790,\"prevSeqId\":325070082658}]}"}
{"action": null, "capture_sequence": 253, "channel": "trades", "connection_sequence": 2, "event": null, "instId": "BTC-USDT-SWAP", "local_receive_ts": "2026-06-21T04:27:16Z", "monotonic_ns": 1643592596647789, "raw": "{\"arg\":{\"channel\":\"trades\",\"instId\":\"BTC-USDT-SWAP\"},\"data\":[{\"instId\":\"BTC-USDT-SWAP\",\"tradeId\":\"2718750270\",\"px\":\"64483\",\"sz\":\"0.01\",\"side\":\"buy\",\"ts\":\"1782016036677\",\"count\":\"1\",\"source\":\"0\",\"seqId\":325070082910}]}"}
{"action": "update", "capture_sequence": 254, "channel": "books", "connection_sequence": 2, "event": null, "instId": "BTC-USDT-SWAP", "local_receive_ts": "2026-06-21T04:27:16Z", "monotonic_ns": 1643592632368847, "raw": "{\"arg\":{\"channel\":\"books\",\"instId\":\"BTC-USDT-SWAP\"},\"action\":\"update\",\"data\":[{\"asks\":[[\"64483\",\"500.74\",\"0\",\"33\"],[\"64487.4\",\"72.66\",\"0\",\"9\"],[\"64487.8\",\"13.97\",\"0\",\"6\"],[\"64489.2\",\"153.78\",\"0\",\"2\"],[\"64489.6\",\"12.4\",\"0\",\"5\"],[\"64489.7\",\"0.8\",\"0\",\"1\"],[\"64493.1\",\"0.45\",\"0\",\"2\"],[\"64493.4\",\"17.35\",\"0\",\"8\"],[\"64495.5\",\"18.86\",\"0\",\"9\"],[\"64495.7\",\"11.35\",\"0\",\"3\"],[\"64497.4\",\"37.47\",\"0\",\"3\"],[\"64500.2\",\"15.53\",\"0\",\"3\"],[\"64500.8\",\"0.36\",\"0\",\"1\"],[\"64502.7\",\"31.06\",\"0\",\"4\"],[\"64503.4\",\"232.77\",\"0\",\"1\"],[\"64503.6\",\"0.02\",\"0\",\"2\"],[\"64503.9\",\"15.65\",\"0\",\"1\"],[\"64505.3\",\"2.71\",\"0\",\"3\"],[\"64505.9\",\"0.01\",\"0\",\"1\"],[\"64512.5\",\"58.34\",\"0\",\"6\"],[\"64513\",\"10.37\",\"0\",\"3\"],[\"64518\",\"103.04\",\"0\",\"12\"],[\"64518.1\",\"24.94\",\"0\",\"7\"],[\"64527.2\",\"0\",\"0\",\"0\"],[\"64527.3\",\"0\",\"0\",\"0\"]],\"bids\":[[\"64482.9\",\"898.16\",\"0\",\"62\"],[\"64482.8\",\"25.94\",\"0\",\"10\"],[\"64480.9\",\"0\",\"0\",\"0\"],[\"64480.6\",\"0.31\",\"0\",\"1\"],[\"64480.5\",\"2.46\",\"0\",\"1\"],[\"64480\",\"108.73\",\"0\",\"6\"],[\"64479.6\",\"0.02\",\"0\",\"2\"],[\"64479.5\",\"0\",\"0\",\"0\"],[\"64479.4\",\"0\",\"0\",\"0\"],[\"64479.3\",\"0.01\",\"0\",\"1\"],[\"64479\",\"0.01\",\"0\",\"1\"],[\"64478.5\",\"0.01\",\"0\",\"1\"],[\"64478.2\",\"77.54\",\"0\",\"1\"],[\"64478\",\"0.01\",\"0\",\"1\"],[\"64477.5\",\"0.3\",\"0\",\"1\"],[\"64474.1\",\"18.64\",\"0\",\"3\"],[\"64467.7\",\"20.08\",\"0\",\"1\"],[\"64467.6\",\"0.03\",\"0\",\"3\"],[\"64465.8\",\"0\",\"0\",\"0\"],[\"64465.6\",\"28.21\",\"0\",\"4\"],[\"64465.1\",\"31.05\",\"0\",\"1\"],[\"64465\",\"0\",\"0\",\"0\"],[\"64464.4\",\"232.92\",\"0\",\"2\"],[\"64464.3\",\"3.17\",\"0\",\"1\"],[\"64463.8\",\"406.02\",\"0\",\"4\"],[\"64423.5\",\"19.6\",\"0\",\"1\"],[\"64422.7\",\"22.42\",\"0\",\"4\"],[\"64422.6\",\"0\",\"0\",\"0\"]],\"ts\":\"1782016036705\",\"checksum\":1535570034,\"seqId\":325070082962,\"prevSeqId\":325070082790}]}"}
{"action": "update", "capture_sequence": 255, "channel": "books", "connection_sequence": 2, "event": null, "instId": "BTC-USDT-SWAP", "local_receive_ts": "2026-06-21T04:27:16Z", "monotonic_ns": 1643592725370562, "raw": "{\"arg\":{\"channel\":\"books\",\"instId\":\"BTC-USDT-SWAP\"},\"action\":\"update\",\"data\":[{\"asks\":[[\"64483\",\"510.46\",\"0\",\"33\"],[\"64484.8\",\"0.42\",\"0\",\"3\"],[\"64486.2\",\"3.17\",\"0\",\"9\"],[\"64488.2\",\"4.36\",\"0\",\"3\"],[\"64489.6\",\"11.9\",\"0\",\"4\"],[\"64490.2\",\"9.2\",\"0\",\"2\"],[\"64493.1\",\"0.46\",\"0\",\"3\"],[\"64494.1\",\"0\",\"0\",\"0\"],[\"64496\",\"104.3\",\"0\",\"7\"],[\"64496.9\",\"0\",\"0\",\"0\"],[\"64497.6\",\"0.13\",\"0\",\"3\"],[\"64503\",\"15.96\",\"0\",\"4\"],[\"64504\",\"54.55\",\"0\",\"8\"],[\"64527.2\",\"0.18\",\"0\",\"4\"],[\"64527.3\",\"0.05\",\"0\",\"5\"]],\"bids\":[[\"64480.6\",\"0\",\"0\",\"0\"],[\"64480.2\",\"0.31\",\"0\",\"1\"],[\"64470.2\",\"86.16\",\"0\",\"1\"],[\"64470\",\"39.37\",\"0\",\"5\"],[\"64469.2\",\"154.75\",\"0\",\"2\"],[\"64469.1\",\"2.81\",\"0\",\"4\"],[\"64465.1\",\"0\",\"0\",\"0\"],[\"64465\",\"31.05\",\"0\",\"1\"],[\"64444.4\",\"37.24\",\"0\",\"2\"],[\"64444\",\"15.69\",\"0\",\"4\"],[\"64423.5\",\"0\",\"0\",\"0\"],[\"64422.7\",\"3.4\",\"0\",\"3\"]],\"ts\":\"1782016036805\",\"checksum\":-1605950218,\"seqId\":325070083095,\"prevSeqId\":325070082962}]}"}
{"action": null, "capture_sequence": 256, "channel": "trades", "connection_sequence": 2, "event": null, "instId": "BTC-USDT-SWAP", "local_receive_ts": "2026-06-21T04:27:17Z", "monotonic_ns": 1643592819313835, "raw": "{\"arg\":{\"channel\":\"trades\",\"instId\":\"BTC-USDT-SWAP\"},\"data\":[{\"instId\":\"BTC-USDT-SWAP\",\"tradeId\":\"2718750271\",\"px\":\"64482.9\",\"sz\":\"0.06\",\"side\":\"sell\",\"ts\":\"1782016036900\",\"count\":\"1\",\"source\":\"0\",\"seqId\":325070083167}]}"}
{"action": "update", "capture_sequence": 257, "channel": "books", "connection_sequence": 2, "event": null, "instId": "BTC-USDT-SWAP", "local_receive_ts": "2026-06-21T04:27:17Z", "monotonic_ns": 1643592824391579, "raw": "{\"arg\":{\"channel\":\"books\",\"instId\":\"BTC-USDT-SWAP\"},\"action\":\"update\",\"data\":[{\"asks\":[[\"64483\",\"500.44\",\"0\",\"31\"],[\"64489.3\",\"4.81\",\"0\",\"5\"]],\"bids\":[[\"64482.9\",\"898.1\",\"0\",\"62\"],[\"64480.6\",\"0.01\",\"0\",\"1\"],[\"64480\",\"108.74\",\"0\",\"7\"],[\"64422.7\",\"0\",\"0\",\"0\"]],\"ts\":\"1782016036905\",\"checksum\":314118578,\"seqId\":325070083172,\"prevSeqId\":325070083095}]}"}
{"action": "update", "capture_sequence": 258, "channel": "books", "connection_sequence": 2, "event": null, "instId": "BTC-USDT-SWAP", "local_receive_ts": "2026-06-21T04:27:17Z", "monotonic_ns": 1643592924333351, "raw": "{\"arg\":{\"channel\":\"books\",\"instId\":\"BTC-USDT-SWAP\"},\"action\":\"update\",\"data\":[{\"asks\":[[\"64483\",\"502\",\"0\",\"32\"],[\"64490.2\",\"1.2\",\"0\",\"1\"],[\"64493.1\",\"0.45\",\"0\",\"2\"],[\"64493.5\",\"186.38\",\"0\",\"7\"],[\"64495.1\",\"8.07\",\"0\",\"4\"]],\"bids\":[[\"64480\",\"110.3\",\"0\",\"8\"],[\"64479.5\",\"1.56\",\"0\",\"1\"],[\"64479.1\",\"1.56\",\"0\",\"1\"],[\"64478.6\",\"1.56\",\"0\",\"1\"],[\"64478.1\",\"15.51\",\"0\",\"2\"],[\"64477.6\",\"1.57\",\"0\",\"2\"],[\"64423.1\",\"0\",\"0\",\"0\"],[\"64423\",\"0\",\"0\",\"0\"],[\"64422.8\",\"0\",\"0\",\"0\"]],\"ts\":\"1782016037005\",\"checksum\":1678886489,\"seqId\":325070083269,\"prevSeqId\":325070083172}]}"}
{"action": "update", "capture_sequence": 259, "channel": "books", "connection_sequence": 2, "event": null, "instId": "BTC-USDT-SWAP", "local_receive_ts": "2026-06-21T04:27:17Z", "monotonic_ns": 1643593025265921, "raw": "{\"arg\":{\"channel\":\"books\",\"instId\":\"BTC-USDT-SWAP\"},\"action\":\"update\",\"data\":[{\"asks\":[[\"64483\",\"500.56\",\"0\",\"33\"],[\"64483.2\",\"1.57\",\"0\",\"2\"],[\"64483.8\",\"0.01\",\"0\",\"1\"],[\"64483.9\",\"1.57\",\"0\",\"2\"],[\"64484.9\",\"80.34\",\"0\",\"4\"],[\"64485.8\",\"0.42\",\"0\",\"4\"],[\"64506.2\",\"0.03\",\"0\",\"2\"],[\"64506.5\",\"16.49\",\"0\",\"3\"],[\"64511.9\",\"0.14\",\"0\",\"1\"],[\"64512.5\",\"85.49\",\"0\",\"6\"],[\"64513.3\",\"60.15\",\"0\",\"10\"],[\"64518.1\",\"4.88\",\"0\",\"6\"],[\"64518.5\",\"20.07\",\"0\",\"2\"],[\"64527.2\",\"0\",\"0\",\"0\"],[\"64527.3\",\"0\",\"0\",\"0\"]],\"bids\":[[\"64481.4\",\"13.57\",\"0\",\"4\"],[\"64480.7\",\"1.57\",\"0\",\"2\"],[\"64480.3\",\"0.31\",\"0\",\"1\"],[\"64480.2\",\"1.56\",\"0\",\"1\"],[\"64480\",\"108.74\",\"0\",\"7\"],[\"64479.7\",\"1.56\",\"0\",\"1\"],[\"64479.5\",\"0\",\"0\",\"0\"],[\"64476.5\",\"12.17\",\"0\",\"2\"],[\"64470.4\",\"90.16\",\"0\",\"2\"],[\"64470.2\",\"0\",\"0\",\"0\"],[\"64467.9\",\"20.09\",\"0\",\"2\"],[\"64467.7\",\"0\",\"0\",\"0\"],[\"64467.5\",\"0.8\",\"0\",\"3\"],[\"64467.2\",\"0\",\"0\",\"0\"],[\"64467\",\"490.01\",\"0\",\"5\"],[\"64466.1\",\"0\",\"0\",\"0\"],[\"64464.8\",\"58.23\",\"0\",\"2\"],[\"64463.8\",\"347.8\",\"0\",\"3\"],[\"64423.1\",\"93.81\",\"0\",\"3\"],[\"64423\",\"1.59\",\"0\",\"6\"],[\"64422.8\",\"1.21\",\"0\",\"2\"]],\"ts\":\"1782016037105\",\"checksum\":-932912699,\"seqId\":325070083458,\"prevSeqId\":325070083269}]}"}
{"action": "update", "capture_sequence": 260, "channel": "books", "connection_sequence": 2, "event": null, "instId": "BTC-USDT-SWAP", "local_receive_ts": "2026-06-21T04:27:17Z", "monotonic_ns": 1643593124557302, "raw": "{\"arg\":{\"channel\":\"books\",\"instId\":\"BTC-USDT-SWAP\"},\"action\":\"update\",\"data\":[{\"asks\":[[\"64495.6\",\"0.01\",\"0\",\"1\"],[\"64495.9\",\"47.55\",\"0\",\"5\"],[\"64496\",\"104.13\",\"0\",\"6\"],[\"64498.5\",\"25.96\",\"0\",\"6\"],[\"64500.5\",\"2.49\",\"0\",\"2\"]],\"bids\":[[\"64481.4\",\"12.01\",\"0\",\"3\"],[\"64481.2\",\"1.56\",\"0\",\"1\"],[\"64480.7\",\"0.01\",\"0\",\"1\"],[\"64480.6\",\"1.57\",\"0\",\"2\"],[\"64422.8\",\"0\",\"0\",\"0\"]],\"ts\":\"1782016037205\",\"checksum\":-2083294702,\"seqId\":325070083543,\"prevSeqId\":325070083458}]}"}
{"action": "update", "capture_sequence": 261, "channel": "books", "connection_sequence": 2, "event": null, "instId": "BTC-USDT-SWAP", "local_receive_ts": "2026-06-21T04:27:17Z", "monotonic_ns": 1643593224389896, "raw": "{\"arg\":{\"channel\":\"books\",\"instId\":\"BTC-USDT-SWAP\"},\"action\":\"update\",\"data\":[{\"asks\":[[\"64499.8\",\"16.59\",\"0\",\"3\"],[\"64500.2\",\"0.02\",\"0\",\"2\"]],\"bids\":[[\"64482.9\",\"898.12\",\"0\",\"63\"],[\"64481.2\",\"0\",\"0\",\"0\"],[\"64479.8\",\"73.92\",\"0\",\"2\"],[\"64422.8\",\"1.21\",\"0\",\"2\"]],\"ts\":\"1782016037305\",\"checksum\":-156092035,\"seqId\":325070083652,\"prevSeqId\":325070083543}]}"}
{"action": "update", "capture_sequence": 262, "channel": "books", "connection_sequence": 2, "event": null, "instId": "BTC-USDT-SWAP", "local_receive_ts": "2026-06-21T04:27:17Z", "monotonic_ns": 1643593324788309, "raw": "{\"arg\":{\"channel\":\"books\",\"instId\":\"BTC-USDT-SWAP\"},\"action\":\"update\",\"data\":[{\"asks\":[[\"64483.2\",\"0\",\"0\",\"0\"],[\"64484.9\",\"80.35\",\"0\",\"5\"],[\"64491.2\",\"13.67\",\"0\",\"3\"],[\"64512.1\",\"122.57\",\"0\",\"5\"],[\"64512.5\",\"0.16\",\"0\",\"5\"],[\"64527.2\",\"0.18\",\"0\",\"4\"]],\"bids\":[[\"64482.9\",\"898.13\",\"0\",\"63\"],[\"64480.6\",\"0.01\",\"0\",\"1\"],[\"64480.2\",\"0\",\"0\",\"0\"],[\"64479.7\",\"0\",\"0\",\"0\"],[\"64479.1\",\"0\",\"0\",\"0\"],[\"64476.5\",\"13.73\",\"0\",\"3\"],[\"64476\",\"1.6\",\"0\",\"3\"],[\"64475.6\",\"1.56\",\"0\",\"1\"],[\"64467\",\"404.62\",\"0\",\"4\"],[\"64466.1\",\"85.39\",\"0\",\"1\"],[\"64422.7\",\"3.4\",\"0\",\"3\"]],\"ts\":\"1782016037405\",\"checksum\":996825496,\"seqId\":325070083773,\"prevSeqId\":325070083652}]}"}
{"action": null, "capture_sequence": 263, "channel": "trades", "connection_sequence": 2, "event": null, "instId": "BTC-USDT-SWAP", "local_receive_ts": "2026-06-21T04:27:17Z", "monotonic_ns": 1643593376665688, "raw": "{\"arg\":{\"channel\":\"trades\",\"instId\":\"BTC-USDT-SWAP\"},\"data\":[{\"instId\":\"BTC-USDT-SWAP\",\"tradeId\":\"2718750278\",\"px\":\"64483\",\"sz\":\"48.77\",\"side\":\"buy\",\"ts\":\"1782016037457\",\"count\":\"7\",\"source\":\"0\",\"seqId\":325070083842}]}"}
{"action": "update", "capture_sequence": 264, "channel": "books", "connection_sequence": 2, "event": null, "instId": "BTC-USDT-SWAP", "local_receive_ts": "2026-06-21T04:27:17Z", "monotonic_ns": 1643593424679782, "raw": "{\"arg\":{\"channel\":\"books\",\"instId\":\"BTC-USDT-SWAP\"},\"action\":\"update\",\"data\":[{\"asks\":[[\"64483\",\"459.33\",\"0\",\"29\"],[\"64483.8\",\"0\",\"0\",\"0\"],[\"64483.9\",\"0.01\",\"0\",\"1\"],[\"64484.9\",\"42.42\",\"0\",\"4\"],[\"64485.8\",\"0.43\",\"0\",\"5\"],[\"64485.9\",\"5.43\",\"0\",\"2\"],[\"64486.9\",\"0.12\",\"0\",\"2\"],[\"64487.3\",\"6.24\",\"0\",\"3\"],[\"64487.4\",\"126.29\",\"0\",\"7\"],[\"64487.7\",\"136.14\",\"0\",\"2\"],[\"64487.8\",\"12.41\",\"0\",\"5\"],[\"64488.3\",\"0.02\",\"0\",\"2\"],[\"64488.8\",\"50\",\"0\",\"1\"],[\"64493.4\",\"11.15\",\"0\",\"7\"],[\"64495.4\",\"18.66\",\"0\",\"6\"],[\"64495.5\",\"0.26\",\"0\",\"6\"],[\"64499.8\",\"1.08\",\"0\",\"2\"],[\"64500.2\",\"15.53\",\"0\",\"3\"],[\"64512.8\",\"58.18\",\"0\",\"1\"],[\"64513.3\",\"1.97\",\"0\",\"9\"]],\"bids\":[[\"64482.9\",\"935.61\",\"0\",\"64\"],[\"64480.3\",\"0\",\"0\",\"0\"],[\"64480.2\",\"0.31\",\"0\",\"1\"],[\"64478.6\",\"0\",\"0\",\"0\"],[\"64478.1\",\"13.95\",\"0\",\"1\"],[\"64464.8\",\"0.01\",\"0\",\"1\"],[\"64464.1\",\"58.22\",\"0\",\"1\"]],\"ts\":\"1782016037505\",\"checksum\":193865712,\"seqId\":325070083917,\"prevSeqId\":325070083773}]}"}
{"action": "update", "capture_sequence": 265, "channel": "books", "connection_sequence": 2, "event": null, "instId": "BTC-USDT-SWAP", "local_receive_ts": "2026-06-21T04:27:17Z", "monotonic_ns": 1643593524566764, "raw": "{\"arg\":{\"channel\":\"books\",\"instId\":\"BTC-USDT-SWAP\"},\"action\":\"update\",\"data\":[{\"asks\":[[\"64495.9\",\"47.38\",\"0\",\"4\"],[\"64496.6\",\"31.85\",\"0\",\"3\"],[\"64497.4\",\"37.31\",\"0\",\"2\"]],\"bids\":[[\"64482.9\",\"938.07\",\"0\",\"65\"],[\"64482.4\",\"0.03\",\"0\",\"2\"],[\"64482.3\",\"2.46\",\"0\",\"1\"],[\"64482.1\",\"0.01\",\"0\",\"1\"],[\"64480.6\",\"0\",\"0\",\"0\"],[\"64480.5\",\"0\",\"0\",\"0\"],[\"64480\",\"108.73\",\"0\",\"6\"],[\"64479.9\",\"0.02\",\"0\",\"2\"],[\"64478.3\",\"0.02\",\"0\",\"2\"],[\"64464.3\",\"0\",\"0\",\"0\"],[\"64422.6\",\"0.02\",\"0\",\"2\"]],\"ts\":\"1782016037605\",\"checksum\":1459770879,\"seqId\":325070083996,\"prevSeqId\":325070083917}]}"}
{"action": "update", "capture_sequence": 266, "channel": "books", "connection_sequence": 2, "event": null, "instId": "BTC-USDT-SWAP", "local_receive_ts": "2026-06-21T04:27:17Z", "monotonic_ns": 1643593624616542, "raw": "{\"arg\":{\"channel\":\"books\",\"instId\":\"BTC-USDT-SWAP\"},\"action\":\"update\",\"data\":[{\"asks\":[[\"64483\",\"462.03\",\"0\",\"30\"],[\"64490.1\",\"0.3\",\"0\",\"2\"],[\"64497.3\",\"41.29\",\"0\",\"5\"]],\"bids\":[[\"64464.4\",\"236.04\",\"0\",\"3\"]],\"ts\":\"1782016037705\",\"checksum\":-971246839,\"seqId\":325070084072,\"prevSeqId\":325070083996}]}"}
{"action": "update", "capture_sequence": 267, "channel": "books", "connection_sequence": 2, "event": null, "instId": "BTC-USDT-SWAP", "local_receive_ts": "2026-06-21T04:27:17Z", "monotonic_ns": 1643593724437102, "raw": "{\"arg\":{\"channel\":\"books\",\"instId\":\"BTC-USDT-SWAP\"},\"action\":\"update\",\"data\":[{\"asks\":[[\"64483\",\"472.03\",\"0\",\"31\"],[\"64496.3\",\"476.01\",\"0\",\"8\"],[\"64496.6\",\"31.68\",\"0\",\"2\"]],\"bids\":[],\"ts\":\"1782016037805\",\"checksum\":673891109,\"seqId\":325070084148,\"prevSeqId\":325070084072}]}"}
