{"action": null, "capture_sequence": 268, "channel": "trades", "connection_sequence": 2, "event": null, "instId": "BTC-USDT-SWAP", "local_receive_ts": "2026-06-21T04:27:17Z", "monotonic_ns": 1643593785453572, "raw": "{\"arg\":{\"channel\":\"trades\",\"instId\":\"BTC-USDT-SWAP\"},\"data\":[{\"instId\":\"BTC-USDT-SWAP\",\"tradeId\":\"2718750279\",\"px\":\"64482.9\",\"sz\":\"0.38\",\"side\":\"sell\",\"ts\":\"1782016037866\",\"count\":\"1\",\"source\":\"0\",\"seqId\":325070084228}]}"}
{"action": null, "capture_sequence": 269, "channel": "trades", "connection_sequence": 2, "event": null, "instId": "BTC-USDT-SWAP", "local_receive_ts": "2026-06-21T04:27:18Z", "monotonic_ns": 1643593818738199, "raw": "{\"arg\":{\"channel\":\"trades\",\"instId\":\"BTC-USDT-SWAP\"},\"data\":[{\"instId\":\"BTC-USDT-SWAP\",\"tradeId\":\"2718750280\",\"px\":\"64483\",\"sz\":\"20\",\"side\":\"buy\",\"ts\":\"1782016037899\",\"count\":\"1\",\"source\":\"0\",\"seqId\":325070084257}]}"}
{"action": "update", "capture_sequence": 270, "channel": "books", "connection_sequence": 2, "event": null, "instId": "BTC-USDT-SWAP", "local_receive_ts": "2026-06-21T04:27:18Z", "monotonic_ns": 1643593824818879, "raw": "{\"arg\":{\"channel\":\"books\",\"instId\":\"BTC-USDT-SWAP\"},\"action\":\"update\",\"data\":[{\"asks\":[[\"64483\",\"374.77\",\"0\",\"29\"],[\"64489.6\",\"0.89\",\"0\",\"3\"],[\"64497.3\",\"41.14\",\"0\",\"4\"],[\"64504.9\",\"0.1\",\"0\",\"3\"],[\"64505.9\",\"0.32\",\"0\",\"2\"],[\"64506.5\",\"15.72\",\"0\",\"2\"],[\"64507.3\",\"34.59\",\"0\",\"4\"],[\"64512.1\",\"37.24\",\"0\",\"4\"],[\"64512.8\",\"85.33\",\"0\",\"1\"],[\"64514.1\",\"58.21\",\"0\",\"4\"]],\"bids\":[[\"64482.9\",\"1002.64\",\"0\",\"66\"],[\"64480.9\",\"0.31\",\"0\",\"1\"],[\"64480.2\",\"0\",\"0\",\"0\"],[\"64476.3\",\"36.42\",\"0\",\"4\"],[\"64474.1\",\"6.23\",\"0\",\"2\"],[\"64473\",\"0.31\",\"0\",\"1\"],[\"64472.2\",\"0\",\"0\",\"0\"],[\"64468.5\",\"3.65\",\"0\",\"2\"],[\"64467.5\",\"85.42\",\"0\",\"3\"],[\"64466.1\",\"0\",\"0\",\"0\"],[\"64465.7\",\"64.44\",\"0\",\"2\"],[\"64464.4\",\"232.92\",\"0\",\"2\"],[\"64464.1\",\"0\",\"0\",\"0\"],[\"64423.5\",\"19.6\",\"0\",\"1\"],[\"64422.7\",\"22.42\",\"0\",\"4\"],[\"64422.4\",\"1366.68\",\"0\",\"4\"]],\"ts\":\"1782016037905\",\"checksum\":-41989203,\"seqId\":325070084259,\"prevSeqId\":325070084148}]}"}
{"action": "update", "capture_sequence": 271, "channel": "books", "connection_sequence": 2, "event": null, "instId": "BTC-USDT-SWAP", "local_receive_ts": "2026-06-21T04:27:18Z", "monotonic_ns": 1643593932913090, "raw": "{\"arg\":{\"channel\":\"books\",\"instId\":\"BTC-USDT-SWAP\"},\"action\":\"update\",\"data\":[{\"asks\":[[\"64483\",\"470.2\",\"0\",\"31\"],[\"64484.2\",\"1.56\",\"0\",\"1\"],[\"64484.8\",\"1.98\",\"0\",\"4\"],[\"64485.3\",\"1.56\",\"0\",\"1\"],[\"64485.8\",\"1.99\",\"0\",\"6\"],[\"64486.2\",\"4.73\",\"0\",\"10\"],[\"64486.7\",\"1.56\",\"0\",\"1\"],[\"64487.2\",\"1.59\",\"0\",\"3\"],[\"64493.5\",\"186.37\",\"0\",\"6\"],[\"64493.6\",\"0.03\",\"0\",\"2\"],[\"64496.3\",\"475.84\",\"0\",\"7\"],[\"64497.3\",\"41.46\",\"0\",\"6\"],[\"64505.2\",\"17.2\",\"0\",\"2\"],[\"64505.3\",\"1.16\",\"0\",\"2\"],[\"64506.8\",\"93.54\",\"0\",\"7\"],[\"64507.3\",\"0.03\",\"0\",\"2\"],[\"64507.6\",\"33.82\",\"0\",\"3\"],[\"64512.2\",\"97.76\",\"0\",\"5\"],[\"64512.8\",\"0\",\"0\",\"0\"],[\"64513.2\",\"58.33\",\"0\",\"5\"],[\"64513.8\",\"0.01\",\"0\",\"1\"],[\"64514.1\",\"10.03\",\"0\",\"4\"],[\"64518.3\",\"20.08\",\"0\",\"3\"],[\"64518.5\",\"0.01\",\"0\",\"1\"],[\"64519\",\"8.67\",\"0\",\"5\"],[\"64520.7\",\"30.4\",\"0\",\"1\"],[\"64527.1\",\"0\",\"0\",\"0\"],[\"64527.2\",\"0\",\"0\",\"0\"]],\"bids\":[[\"64482.9\",\"937.69\",\"0\",\"65\"],[\"64482.5\",\"6.56\",\"0\",\"2\"],[\"64482\",\"6.57\",\"0\",\"3\"],[\"64481.6\",\"1.57\",\"0\",\"2\"],[\"64480.9\",\"0\",\"0\",\"0\"],[\"64480.2\",\"0.31\",\"0\",\"1\"],[\"64468.8\",\"45.14\",\"0\",\"2\"],[\"64468.5\",\"2.88\",\"0\",\"1\"],[\"64468.4\",\"0\",\"0\",\"0\"],[\"64468\",\"3.49\",\"0\",\"4\"],[\"64467.5\",\"0.03\",\"0\",\"2\"],[\"64466.9\",\"85.41\",\"0\",\"2\"],[\"64465.7\",\"6.22\",\"0\",\"1\"],[\"64464.8\",\"58.23\",\"0\",\"2\"],[\"64464.4\",\"3.13\",\"0\",\"2\"],[\"64464.3\",\"232.91\",\"0\",\"1\"],[\"64463.9\",\"0.02\",\"0\",\"1\"],[\"64463.8\",\"347.78\",\"0\",\"2\"],[\"64444.3\",\"0.03\",\"0\",\"2\"],[\"64444\",\"15.67\",\"0\",\"3\"],[\"64422.4\",\"0\",\"0\",\"0\"]],\"ts\":\"1782016038005\",\"checksum\":-1030114272,\"seqId\":325070084398,\"prevSeqId\":325070084259}]}"}
{"action": "update", "capture_sequence": 272, "channel": "books", "connection_sequence": 2, "event": null, "instId": "BTC-USDT-SWAP", "local_receive_ts": "2026-06-21T04:27:18Z", "monotonic_ns": 1643594032765281, "raw": "{\"arg\":{\"channel\":\"books\",\"instId\":\"BTC-USDT-SWAP\"},\"action\":\"update\",\"data\":[{\"asks\":[[\"64483\",\"501.12\",\"0\",\"32\"],[\"64484.1\",\"1.56\",\"0\",\"1\"],[\"64484.2\",\"0\",\"0\",\"0\"],[\"64484.7\",\"0.01\",\"0\",\"1\"],[\"64485.8\",\"1.98\",\"0\",\"5\"],[\"64487.7\",\"137.7\",\"0\",\"3\"],[\"64488.2\",\"5.92\",\"0\",\"4\"],[\"64489.3\",\"3.25\",\"0\",\"4\"],[\"64489.8\",\"67\",\"0\",\"4\"],[\"64493.1\",\"0.46\",\"0\",\"3\"],[\"64493.6\",\"0.02\",\"0\",\"1\"],[\"64496.2\",\"20.06\",\"0\",\"3\"],[\"64497.3\",\"41.29\",\"0\",\"5\"],[\"64505.2\",\"15.65\",\"0\",\"1\"],[\"64505.3\",\"2.71\",\"0\",\"3\"],[\"64506.8\",\"92.77\",\"0\",\"6\"],[\"64507.3\",\"0.8\",\"0\",\"3\"],[\"64507.6\",\"0.03\",\"0\",\"2\"],[\"64507.9\",\"34.06\",\"0\",\"5\"],[\"64512.2\",\"12.43\",\"0\",\"4\"],[\"64512.9\",\"104.32\",\"0\",\"6\"],[\"64513.2\",\"0.15\",\"0\",\"4\"],[\"64513.9\",\"58.3\",\"0\",\"2\"],[\"64518.3\",\"0.02\",\"0\",\"2\"],[\"64518.9\",\"66.56\",\"0\",\"3\"],[\"64519.7\",\"10.81\",\"0\",\"7\"],[\"64519.8\",\"122.39\",\"0\",\"7\"],[\"64519.9\",\"582.66\",\"0\",\"3\"],[\"64527\",\"0\",\"0\",\"0\"]],\"bids\":[[\"64482\",\"5.01\",\"0\",\"2\"],[\"64481.7\",\"1.56\",\"0\",\"1\"],[\"64481.6\",\"0.01\",\"0\",\"1\"],[\"64481.3\",\"1.56\",\"0\",\"1\"],[\"64480.8\",\"1.57\",\"0\",\"2\"],[\"64480.4\",\"0.31\",\"0\",\"1\"],[\"64480.3\",\"1.56\",\"0\",\"1\"],[\"64480.2\",\"0\",\"0\",\"0\"],[\"64479.8\",\"75.48\",\"0\",\"3\"],[\"64475.6\",\"0\",\"0\",\"0\"],[\"64473.3\",\"0.32\",\"0\",\"2\"],[\"64473\",\"0\",\"0\",\"0\"],[\"64469.2\",\"154.77\",\"0\",\"3\"],[\"64469.1\",\"2.79\",\"0\",\"3\"],[\"64469\",\"33.81\",\"0\",\"1\"],[\"64468.8\",\"11.33\",\"0\",\"1\"],[\"64468.4\",\"20.08\",\"0\",\"1\"],[\"64468.3\",\"0.77\",\"0\",\"1\"],[\"64468\",\"2.72\",\"0\",\"3\"],[\"64467.9\",\"0.01\",\"0\",\"1\"],[\"64467.5\",\"85.42\",\"0\",\"3\"],[\"64466.9\",\"0.02\",\"0\",\"1\"],[\"64465.1\",\"58.22\",\"0\",\"1\"],[\"64464.8\",\"0.01\",\"0\",\"1\"],[\"64464.5\",\"232.93\",\"0\",\"3\"],[\"64464.3\",\"0\",\"0\",\"0\"],[\"64423.5\",\"0\",\"0\",\"0\"],[\"64422.8\",\"0\",\"0\",\"0\"],[\"64422.7\",\"0\",\"0\",\"0\"],[\"64422.6\",\"0\",\"0\",\"0\"]],\"ts\":\"1782016038105\",\"checksum\":-1001232355,\"seqId\":325070084670,\"prevSeqId\":325070084398}]}"}
{"action": null, "capture_sequence": 273, "channel": "trades", "connection_sequence": 2, "event": null, "instId": "BTC-USDT-SWAP", "local_receive_ts": "2026-06-21T04:27:18Z", "monotonic_ns": 1643594062727669, "raw": "{\"arg\":{\"channel\":\"trades\",\"instId\":\"BTC-USDT-SWAP\"},\"data\":[{\"instId\":\"BTC-USDT-SWAP\",\"tradeId\":\"2718750281\",\"px\":\"64483\",\"sz\":\"1.67\",\"side\":\"buy\",\"ts\":\"1782016038143\",\"count\":\"1\",\"source\":\"0\",\"seqId\":325070084755}]}"}
{"action": "update", "capture_sequence": 274, "channel": "books", "connection_sequence": 2, "event": null, "instId": "BTC-USDT-SWAP", "local_receive_ts": "2026-06-21T04:27:18Z", "monotonic_ns": 1643594140307832, "raw": "{\"arg\":{\"channel\":\"books\",\"instId\":\"BTC-USDT-SWAP\"},\"action\":\"update\",\"data\":[{\"asks\":[[\"64483\",\"499.45\",\"0\",\"32\"],[\"64484.1\",\"0\",\"0\",\"0\"],[\"64484.7\",\"0\",\"0\",\"0\"],[\"64484.8\",\"0.42\",\"0\",\"3\"],[\"64485.3\",\"0\",\"0\",\"0\"],[\"64485.8\",\"0.43\",\"0\",\"5\"],[\"64486.2\",\"3.17\",\"0\",\"9\"],[\"64487.2\",\"0.03\",\"0\",\"2\"],[\"64487.5\",\"1.6\",\"0\",\"4\"],[\"64487.7\",\"136.14\",\"0\",\"2\"],[\"64488.6\",\"1.58\",\"0\",\"3\"],[\"64489.1\",\"1.6\",\"0\",\"4\"],[\"64489.6\",\"2.45\",\"0\",\"4\"],[\"64490.1\",\"1.86\",\"0\",\"3\"],[\"64490.5\",\"4.57\",\"0\",\"5\"],[\"64491\",\"1.57\",\"0\",\"2\"],[\"64491.5\",\"1.66\",\"0\",\"2\"],[\"64512.5\",\"85.49\",\"0\",\"6\"],[\"64512.9\",\"18.99\",\"0\",\"5\"],[\"64513.3\",\"60.15\",\"0\",\"10\"],[\"64513.9\",\"0.12\",\"0\",\"1\"],[\"64518.3\",\"20.08\",\"0\",\"3\"],[\"64518.9\",\"46.5\",\"0\",\"2\"],[\"64527\",\"0.17\",\"0\",\"3\"],[\"64527.1\",\"0.46\",\"0\",\"1\"],[\"64527.2\",\"0.18\",\"0\",\"4\"]],\"bids\":[[\"64482.5\",\"5\",\"0\",\"1\"],[\"64482.3\",\"4.02\",\"0\",\"2\"],[\"64476\",\"0.04\",\"0\",\"2\"],[\"64473.3\",\"0.01\",\"0\",\"1\"],[\"64473\",\"0.31\",\"0\",\"1\"],[\"64468.4\",\"0\",\"0\",\"0\"],[\"64467.9\",\"20.09\",\"0\",\"2\"],[\"64467.5\",\"0.03\",\"0\",\"2\"],[\"64466.9\",\"85.41\",\"0\",\"2\"],[\"64465.1\",\"0\",\"0\",\"0\"],[\"64464.8\",\"58.23\",\"0\",\"2\"],[\"64422.8\",\"1.21\",\"0\",\"2\"]],\"ts\":\"1782016038205\",\"checksum\":-1771451177,\"seqId\":325070084870,\"prevSeqId\":325070084670}]}"}
{"action": null, "capture_sequence": 275, "channel": "trades", "connection_sequence": 2, "event": null, "instId": "BTC-USDT-SWAP", "local_receive_ts": "2026-06-21T04:27:18Z", "monotonic_ns": 1643594140564571, "raw": "{\"arg\":{\"channel\":\"trades\",\"instId\":\"BTC-USDT-SWAP\"},\"data\":[{\"instId\":\"BTC-USDT-SWAP\",\"tradeId\":\"2718750282\",\"px\":\"64482.9\",\"sz\":\"0.06\",\"side\":\"sell\",\"ts\":\"1782016038206\",\"count\":\"1\",\"source\":\"0\",\"seqId\":325070084875}]}"}
{"action": "update", "capture_sequence": 276, "channel": "books", "connection_sequence": 2, "event": null, "instId": "BTC-USDT-SWAP", "local_receive_ts": "2026-06-21T04:27:18Z", "monotonic_ns": 1643594224925309, "raw": "{\"arg\":{\"channel\":\"books\",\"instId\":\"BTC-USDT-SWAP\"},\"action\":\"update\",\"data\":[{\"asks\":[[\"64484.9\",\"79.3\",\"0\",\"5\"],[\"64486.1\",\"136.14\",\"0\",\"2\"],[\"64487.7\",\"0.01\",\"0\",\"1\"],[\"64493.4\",\"1.09\",\"0\",\"6\"],[\"64495.7\",\"21.32\",\"0\",\"4\"],[\"64505.9\",\"0.01\",\"0\",\"1\"],[\"64506.2\",\"0.34\",\"0\",\"3\"],[\"64506.8\",\"126.56\",\"0\",\"7\"],[\"64507.9\",\"0.27\",\"0\",\"4\"],[\"64511.4\",\"101.11\",\"0\",\"5\"],[\"64512.5\",\"0.16\",\"0\",\"5\"],[\"64513.3\",\"1.97\",\"0\",\"9\"],[\"64513.9\",\"58.3\",\"0\",\"2\"],[\"64517.5\",\"20.06\",\"0\",\"1\"],[\"64518.3\",\"0.02\",\"0\",\"2\"],[\"64518.7\",\"86.1\",\"0\",\"1\"],[\"64519.9\",\"496.56\",\"0\",\"2\"],[\"64527.1\",\"0\",\"0\",\"0\"],[\"64527.2\",\"0\",\"0\",\"0\"]],\"bids\":[[\"64482.9\",\"937.63\",\"0\",\"65\"],[\"64482.3\",\"2.46\",\"0\",\"1\"],[\"64481.7\",\"0\",\"0\",\"0\"],[\"64481.3\",\"0\",\"0\",\"0\"],[\"64480.8\",\"0.01\",\"0\",\"1\"],[\"64480.4\",\"0\",\"0\",\"0\"],[\"64480.3\",\"0\",\"0\",\"0\"],[\"64480.2\",\"0.31\",\"0\",\"1\"],[\"64473.6\",\"247.28\",\"0\",\"4\"],[\"64473\",\"0\",\"0\",\"0\"],[\"64470.4\",\"4\",\"0\",\"1\"],[\"64469.4\",\"132.71\",\"0\",\"2\"],[\"64469\",\"0\",\"0\",\"0\"],[\"64467.9\",\"33.82\",\"0\",\"2\"],[\"64467.1\",\"51.3\",\"0\",\"3\"],[\"64466.9\",\"0.02\",\"0\",\"1\"],[\"64466.1\",\"85.39\",\"0\",\"1\"],[\"64465.4\",\"566.09\",\"0\",\"4\"],[\"64464.8\",\"0.01\",\"0\",\"1\"],[\"64422.7\",\"3.4\",\"0\",\"3\"],[\"64422.6\",\"0.02\",\"0\",\"2\"],[\"64422.4\",\"1366.68\",\"0\",\"4\"],[\"64422.3\",\"0.04\",\"0\",\"4\"]],\"ts\":\"1782016038305\",\"checksum\":-624332155,\"seqId\":325070085018,\"prevSeqId\":325070084870}]}"}
{"action": "update", "capture_sequence": 277, "channel": "books", "connection_sequence": 2, "event": null, "instId": "BTC-USDT-SWAP", "local_receive_ts": "2026-06-21T04:27:18Z", "monotonic_ns": 1643594325239128, "raw": "{\"arg\":{\"channel\":\"books\",\"instId\":\"BTC-USDT-SWAP\"},\"action\":\"update\",\"data\":[{\"asks\":[[\"64483\",\"509.43\",\"0\",\"32\"],[\"64505.9\",\"0.32\",\"0\",\"2\"],[\"64506.2\",\"0.03\",\"0\",\"2\"],[\"64506.8\",\"92.77\",\"0\",\"6\"],[\"64507.7\",\"33.86\",\"0\",\"5\"],[\"64511.4\",\"15.78\",\"0\",\"4\"],[\"64512.5\",\"85.49\",\"0\",\"6\"],[\"64513.2\",\"58.33\",\"0\",\"5\"],[\"64513.9\",\"0.12\",\"0\",\"1\"],[\"64517.5\",\"0\",\"0\",\"0\"],[\"64518.5\",\"20.07\",\"0\",\"2\"],[\"64518.7\",\"0\",\"0\",\"0\"],[\"64519.7\",\"96.91\",\"0\",\"8\"],[\"64519.8\",\"89.37\",\"0\",\"5\"],[\"64527.1\",\"0.46\",\"0\",\"1\"],[\"64527.2\",\"0.18\",\"0\",\"4\"]],\"bids\":[[\"64482.9\",\"937.77\",\"0\",\"66\"],[\"64473.6\",\"246.97\",\"0\",\"3\"],[\"64473\",\"0.31\",\"0\",\"1\"],[\"64470.4\",\"90.16\",\"0\",\"2\"],[\"64469.4\",\"46.54\",\"0\",\"1\"],[\"64468.9\",\"37.11\",\"0\",\"3\"],[\"64467.9\",\"20.09\",\"0\",\"2\"],[\"64467.1\",\"31.22\",\"0\",\"2\"],[\"64466.9\",\"85.41\",\"0\",\"2\"],[\"64466.1\",\"0\",\"0\",\"0\"],[\"64465.4\",\"507.87\",\"0\",\"3\"],[\"64464.8\",\"58.23\",\"0\",\"2\"]],\"ts\":\"1782016038405\",\"checksum\":-1694412373,\"seqId\":325070085131,\"prevSeqId\":325070085018}]}"}
{"action": "update", "capture_sequence": 278, "channel": "books", "connection_sequence": 2, "event": null, "instId": "BTC-USDT-SWAP", "local_receive_ts": "2026-06-21T04:27:18Z", "monotonic_ns": 1643594424562665, "raw": "{\"arg\":{\"channel\":\"books\",\"instId\":\"BTC-USDT-SWAP\"},\"action\":\"update\",\"data\":[{\"asks\":[],\"bids\":[[\"64479.8\",\"73.92\",\"0\",\"2\"]],\"ts\":\"1782016038505\",\"checksum\":1496184509,\"seqId\":325070085199,\"prevSeqId\":325070085131}]}"}
{"action": null, "capture_sequence": 279, "channel": "trades", "connection_sequence": 2, "event": null, "instId": "BTC-USDT-SWAP", "local_receive_ts": "2026-06-21T04:27:18Z", "monotonic_ns": 1643594491671253, "raw": "{\"arg\":{\"channel\":\"trades\",\"instId\":\"BTC-USDT-SWAP\"},\"data\":[{\"instId\":\"BTC-USDT-SWAP\",\"tradeId\":\"2718750284\",\"px\":\"64483\",\"sz\":\"6.99\",\"side\":\"buy\",\"ts\":\"1782016038572\",\"count\":\"2\",\"source\":\"0\",\"seqId\":325070085317}]}"}
{"action": null, "capture_sequence": 280, "channel": "trades", "connection_sequence": 2, "event": null, "instId": "BTC-USDT-SWAP", "local_receive_ts": "2026-06-21T04:27:18Z", "monotonic_ns": 1643594509731961, "raw": "{\"arg\":{\"channel\":\"trades\",\"instId\":\"BTC-USDT-SWAP\"},\"data\":[{\"instId\":\"BTC-USDT-SWAP\",\"tradeId\":\"2718750285\",\"px\":\"64483\",\"sz\":\"30\",\"side\":\"buy\",\"ts\":\"1782016038590\",\"count\":\"1\",\"source\":\"0\",\"seqId\":325070085440}]}"}
{"action": "update", "capture_sequence": 281, "channel": "books", "connection_sequence": 2, "event": null, "instId": "BTC-USDT-SWAP", "local_receive_ts": "2026-06-21T04:27:18Z", "monotonic_ns": 1643594533373684, "raw": "{\"arg\":{\"channel\":\"books\",\"instId\":\"BTC-USDT-SWAP\"},\"action\":\"update\",\"data\":[{\"asks\":[[\"64483\",\"225.97\",\"0\",\"25\"],[\"64484.8\",\"0.02\",\"0\",\"2\"],[\"64484.9\",\"42.42\",\"0\",\"4\"],[\"64486\",\"51.08\",\"0\",\"5\"],[\"64486.1\",\"0.01\",\"0\",\"1\"],[\"64486.2\",\"3.57\",\"0\",\"10\"],[\"64486.7\",\"0\",\"0\",\"0\"],[\"64487.4\",\"88.94\",\"0\",\"7\"],[\"64487.5\",\"0.04\",\"0\",\"3\"],[\"64488.2\",\"3.96\",\"0\",\"2\"],[\"64488.5\",\"136.13\",\"0\",\"1\"],[\"64488.6\",\"0.02\",\"0\",\"2\"],[\"64489.1\",\"0.04\",\"0\",\"3\"],[\"64489.2\",\"0\",\"0\",\"0\"],[\"64489.6\",\"1.28\",\"0\",\"3\"],[\"64490.1\",\"0.3\",\"0\",\"2\"],[\"64490.5\",\"3.01\",\"0\",\"4\"],[\"64491\",\"0.01\",\"0\",\"1\"],[\"64491.5\",\"0.1\",\"0\",\"1\"],[\"64492.2\",\"0.91\",\"0\",\"7\"],[\"64493.4\",\"11.06\",\"0\",\"7\"],[\"64495.7\",\"11.35\",\"0\",\"3\"],[\"64495.8\",\"34.99\",\"0\",\"4\"],[\"64495.9\",\"0.84\",\"0\",\"3\"],[\"64497.3\",\"41.14\",\"0\",\"4\"],[\"64500\",\"3457.33\",\"0\",\"1039\"],[\"64500.2\",\"0.02\",\"0\",\"2\"],[\"64500.8\",\"15.87\",\"0\",\"2\"],[\"64502.7\",\"0.03\",\"0\",\"3\"],[\"64503.4\",\"0\",\"0\",\"0\"],[\"64503.6\",\"31.05\",\"0\",\"3\"],[\"64504.1\",\"247.87\",\"0\",\"7\"],[\"64505.3\",\"1.16\",\"0\",\"2\"],[\"64505.9\",\"0.01\",\"0\",\"1\"],[\"64506.2\",\"1.58\",\"0\",\"3\"],[\"64506.4\",\"0.34\",\"0\",\"4\"],[\"64507.3\",\"0.03\",\"0\",\"2\"],[\"64507.6\",\"0.8\",\"0\",\"3\"],[\"64507.7\",\"0.07\",\"0\",\"4\"],[\"64508.3\",\"33.79\",\"0\",\"1\"],[\"64508.7\",\"147.7\",\"0\",\"9\"],[\"64512.5\",\"0.16\",\"0\",\"5\"],[\"64513.2\",\"85.48\",\"0\",\"5\"],[\"64515.1\",\"58.18\",\"0\",\"1\"],[\"64518.1\",\"20.21\",\"0\",\"6\"],[\"64518.5\",\"0.01\",\"0\",\"1\"],[\"64518.9\",\"0.01\",\"0\",\"1\"],[\"64519.6\",\"86.12\",\"0\",\"3\"],[\"64519.7\",\"10.81\",\"0\",\"7\"],[\"64521.5\",\"3.16\",\"0\",\"7\"],[\"64524.8\",\"3.05\",\"0\",\"5\"]],\"bids\":[[\"64482.9\",\"1003.65\",\"0\",\"67\"],[\"64481.5\",\"0.32\",\"0\",\"2\"],[\"64480.2\",\"0\",\"0\",\"0\"],[\"64479.3\",\"77.55\",\"0\",\"2\"],[\"64478.3\",\"0.01\",\"0\",\"1\"],[\"64478.2\",\"0\",\"0\",\"0\"],[\"64474.1\",\"0.01\",\"0\",\"1\"],[\"64474\",\"496.85\",\"0\",\"3\"],[\"64473\",\"0\",\"0\",\"0\"],[\"64470.5\",\"6.23\",\"0\",\"2\"],[\"64470.4\",\"4\",\"0\",\"1\"],[\"64470.2\",\"86.16\",\"0\",\"1\"],[\"64469.4\",\"80.35\",\"0\",\"2\"],[\"64468.9\",\"3.3\",\"0\",\"2\"],[\"64468.6\",\"0.77\",\"0\",\"1\"],[\"64468.3\",\"0\",\"0\",\"0\"],[\"64467.9\",\"0.01\",\"0\",\"1\"],[\"64467.7\",\"20.08\",\"0\",\"1\"],[\"64467.5\",\"85.42\",\"0\",\"3\"],[\"64466.9\",\"0.02\",\"0\",\"1\"],[\"64466.1\",\"58.22\",\"0\",\"1\"],[\"64465.7\",\"31.05\",\"0\",\"1\"],[\"64465\",\"232.9\",\"0\",\"1\"],[\"64464.8\",\"0.01\",\"0\",\"1\"],[\"64464.5\",\"0.02\",\"0\",\"2\"],[\"64464.4\",\"0.01\",\"0\",\"1\"],[\"64423.5\",\"19.6\",\"0\",\"1\"],[\"64422.7\",\"22.42\",\"0\",\"4\"],[\"64422.3\",\"0\",\"0\",\"0\"]],\"ts\":\"1782016038605\",\"checksum\":1191171323,\"seqId\":325070085462,\"prevSeqId\":325070085199}]}"}
{"action": "update", "capture_sequence": 282, "channel": "books", "connection_sequence": 2, "event": null, "instId": "BTC-USDT-SWAP", "local_receive_ts": "2026-06-21T04:27:18Z", "monotonic_ns": 1643594624782445, "raw": "{\"arg\":{\"channel\":\"books\",\"instId\":\"BTC-USDT-SWAP\"},\"action\":\"update\",\"data\":[{\"asks\":[[\"64483\",\"225.99\",\"0\",\"26\"],[\"64493.1\",\"0.45\",\"0\",\"2\"],[\"64495.3\",\"5.04\",\"0\",\"4\"],[\"64496.2\",\"66.43\",\"0\",\"3\"],[\"64497.3\",\"41.29\",\"0\",\"5\"],[\"64498\",\"24.4\",\"0\",\"3\"],[\"64498.3\",\"84.94\",\"0\",\"7\"],[\"64500\",\"3457.32\",\"0\",\"1038\"],[\"64500.1\",\"0.06\",\"0\",\"5\"],[\"64500.8\",\"0.36\",\"0\",\"1\"],[\"64501.4\",\"15.52\",\"0\",\"2\"],[\"64503\",\"15.95\",\"0\",\"3\"],[\"64504.3\",\"0.05\",\"0\",\"3\"],[\"64507.6\",\"0.03\",\"0\",\"2\"],[\"64507.7\",\"0.84\",\"0\",\"5\"],[\"64518.1\",\"0.15\",\"0\",\"5\"],[\"64518.9\",\"20.07\",\"0\",\"2\"],[\"64519.6\",\"0.02\",\"0\",\"2\"],[\"64520.9\",\"86.12\",\"0\",\"3\"],[\"64521.5\",\"7.72\",\"0\",\"8\"],[\"64522.8\",\"15.71\",\"0\",\"4\"],[\"64523.4\",\"39.43\",\"0\",\"5\"]],\"bids\":[[\"64482.9\",\"1017.6\",\"0\",\"68\"],[\"64481.5\",\"0.01\",\"0\",\"1\"],[\"64480.9\",\"0.31\",\"0\",\"1\"],[\"64478.1\",\"0\",\"0\",\"0\"],[\"64474\",\"496.54\",\"0\",\"2\"],[\"64473.7\",\"0.31\",\"0\",\"1\"],[\"64470.4\",\"90.16\",\"0\",\"2\"],[\"64470.2\",\"0\",\"0\",\"0\"],[\"64468.9\",\"4.07\",\"0\",\"3\"],[\"64468.6\",\"0\",\"0\",\"0\"],[\"64468.3\",\"20.08\",\"0\",\"1\"],[\"64467.7\",\"0\",\"0\",\"0\"],[\"64464.4\",\"3.21\",\"0\",\"2\"],[\"64444.4\",\"37.26\",\"0\",\"3\"],[\"64444.3\",\"0.01\",\"0\",\"1\"],[\"64422.3\",\"0.04\",\"0\",\"4\"]],\"ts\":\"1782016038705\",\"checksum\":1964946050,\"seqId\":325070085530,\"prevSeqId\":325070085462}]}"}
{"action": "update", "capture_sequence": 283, "channel": "books", "connection_sequence": 2, "event": null, "instId": "BTC-USDT-SWAP", "local_receive_ts": "2026-06-21T04:27:18Z", "monotonic_ns": 1643594724521022, "raw": "{\"arg\":{\"channel\":\"books\",\"instId\":\"BTC-USDT-SWAP\"},\"action\":\"update\",\"data\":[{\"asks\":[[\"64483.1\",\"0.63\",\"0\",\"4\"],[\"64489.8\",\"49.44\",\"0\",\"4\"],[\"64491.2\",\"1.01\",\"0\",\"2\"],[\"64493.3\",\"19.01\",\"0\",\"7\"],[\"64495.4\",\"0.06\",\"0\",\"3\"],[\"64495.8\",\"167.02\",\"0\",\"6\"],[\"64500.6\",\"15.9\",\"0\",\"4\"],[\"64501.4\",\"0.01\",\"0\",\"1\"],[\"64508.7\",\"15.67\",\"0\",\"7\"],[\"64513.9\",\"58.3\",\"0\",\"2\"],[\"64515.1\",\"0\",\"0\",\"0\"],[\"64521.5\",\"3.16\",\"0\",\"7\"],[\"64527.3\",\"0.05\",\"0\",\"5\"]],\"bids\":[[\"64466.1\",\"0\",\"0\",\"0\"],[\"64465.4\",\"566.09\",\"0\",\"4\"],[\"64422.2\",\"11.03\",\"0\",\"3\"]],\"ts\":\"1782016038805\",\"checksum\":-1580752096,\"seqId\":325070085559,\"prevSeqId\":325070085530}]}"}
{"action": "update", "capture_sequence": 284, "channel": "books", "connection_sequence": 2, "event": null, "instId": "BTC-USDT-SWAP", "local_receive_ts": "2026-06-21T04:27:19Z", "monotonic_ns": 1643594824329930, "raw": "{\"arg\":{\"channel\":\"books\",\"instId\":\"BTC-USDT-SWAP\"},\"action\":\"update\",\"data\":[{\"asks\":[[\"64495.3\",\"5.03\",\"0\",\"3\"],[\"64495.8\",\"167.03\",\"0\",\"7\"],[\"64500\",\"3457.33\",\"0\",\"1039\"],[\"64500.1\",\"0.05\",\"0\",\"4\"],[\"64504.2\",\"511.11\",\"0\",\"7\"],[\"64504.3\",\"0.04\",\"0\",\"2\"],[\"64505.7\",\"2.11\",\"0\",\"2\"],[\"64506.2\",\"0.03\",\"0\",\"2\"],[\"64507.3\",\"0.8\",\"0\",\"3\"],[\"64507.7\",\"0.07\",\"0\",\"4\"],[\"64518.3\",\"24.73\",\"0\",\"4\"],[\"64518.9\",\"0.01\",\"0\",\"1\"],[\"64526\",\"1.16\",\"0\",\"4\"]],\"bids\":[[\"64479.3\",\"0.01\",\"0\",\"1\"],[\"64477.8\",\"77.54\",\"0\",\"1\"],[\"64468.9\",\"3.3\",\"0\",\"2\"],[\"64468.4\",\"0.77\",\"0\",\"1\"],[\"64468.3\",\"0\",\"0\",\"0\"],[\"64467.7\",\"20.08\",\"0\",\"1\"],[\"64422.3\",\"0\",\"0\",\"0\"],[\"64422.2\",\"0\",\"0\",\"0\"]],\"ts\":\"1782016038905\",\"checksum\":-1781990299,\"seqId\":325070085585,\"prevSeqId\":325070085559}]}"}
{"action": "update", "capture_sequence": 285, "channel": "books", "connection_sequence": 2, "event": null, "instId": "BTC-USDT-SWAP", "local_receive_ts": "2026-06-21T04:27:19Z", "monotonic_ns": 1643594924785439, "raw": "{\"arg\":{\"channel\":\"books\",\"instId\":\"BTC-USDT-SWAP\"},\"action\":\"update\",\"data\":[{\"asks\":[[\"64485.9\",\"6.99\",\"0\",\"3\"],[\"64486.3\",\"1.57\",\"0\",\"2\"],[\"64486.8\",\"1.75\",\"0\",\"4\"],[\"64487.3\",\"7.8\",\"0\",\"4\"],[\"64487.8\",\"13.97\",\"0\",\"6\"],[\"64488.2\",\"5.52\",\"0\",\"3\"],[\"64488.7\",\"1.6\",\"0\",\"2\"],[\"64489.2\",\"1.56\",\"0\",\"1\"],[\"64498.3\",\"84.77\",\"0\",\"6\"],[\"64499.3\",\"0.17\",\"0\",\"1\"],[\"64527.2\",\"0\",\"0\",\"0\"],[\"64527.3\",\"0\",\"0\",\"0\"]],\"bids\":[[\"64482.9\",\"1019.16\",\"0\",\"69\"],[\"64482.4\",\"1.59\",\"0\",\"3\"],[\"64481.9\",\"1.56\",\"0\",\"1\"],[\"64481.4\",\"13.57\",\"0\",\"4\"],[\"64480.9\",\"1.87\",\"0\",\"2\"],[\"64422.4\",\"0\",\"0\",\"0\"]],\"ts\":\"1782016039005\",\"checksum\":499373200,\"seqId\":325070085604,\"prevSeqId\":325070085585}]}"}
{"action": "update", "capture_sequence": 286, "channel": "books", "connection_sequence": 2, "event": null, "instId": "BTC-USDT-SWAP", "local_receive_ts": "2026-06-21T04:27:19Z", "monotonic_ns": 1643595024980971, "raw": "{\"arg\":{\"channel\":\"books\",\"instId\":\"BTC-USDT-SWAP\"},\"action\":\"update\",\"data\":[{\"asks\":[[\"64484.7\",\"0.01\",\"0\",\"1\"],[\"64485.6\",\"1.56\",\"0\",\"1\"],[\"64485.8\",\"0.42\",\"0\",\"4\"],[\"64485.9\",\"5.43\",\"0\",\"2\"],[\"64486.1\",\"1.57\",\"0\",\"2\"],[\"64486.3\",\"0.01\",\"0\",\"1\"],[\"64486.8\",\"0.19\",\"0\",\"3\"],[\"64489.7\",\"2.36\",\"0\",\"2\"],[\"64490.2\",\"2.76\",\"0\",\"2\"],[\"64490.6\",\"33.07\",\"0\",\"5\"],[\"64497.3\",\"41.14\",\"0\",\"4\"],[\"64503.8\",\"232.77\",\"0\",\"1\"],[\"64504.1\",\"15.11\",\"0\",\"6\"],[\"64512.1\",\"122.57\",\"0\",\"5\"],[\"64513.2\",\"0.15\",\"0\",\"4\"],[\"64518.9\",\"46.5\",\"0\",\"2\"],[\"64525.4\",\"26.59\",\"0\",\"2\"],[\"64526.9\",\"0\",\"0\",\"0\"],[\"64527\",\"0\",\"0\",\"0\"],[\"64527.1\",\"0\",\"0\",\"0\"]],\"bids\":[[\"64482.5\",\"5.02\",\"0\",\"2\"],[\"64482.4\",\"1.57\",\"0\",\"2\"],[\"64482\",\"5.02\",\"0\",\"3\"],[\"64481\",\"0.31\",\"0\",\"1\"],[\"64480.9\",\"1.56\",\"0\",\"1\"],[\"64469.2\",\"154.79\",\"0\",\"4\"],[\"64469.1\",\"2.77\",\"0\",\"2\"],[\"64467.5\",\"0.03\",\"0\",\"2\"],[\"64466.1\",\"85.39\",\"0\",\"1\"],[\"64465\",\"0\",\"0\",\"0\"],[\"64464.5\",\"232.93\",\"0\",\"3\"],[\"64464.4\",\"0.01\",\"0\",\"1\"],[\"64423.5\",\"0\",\"0\",\"0\"],[\"64422.7\",\"3.4\",\"0\",\"3\"]],\"ts\":\"1782016039105\",\"checksum\":-134460089,\"seqId\":325070085723,\"prevSeqId\":325070085604}]}"}
{"action": null, "capture_sequence": 287, "channel": "trades", "connection_sequence": 2, "event": null, "instId": "BTC-USDT-SWAP", "local_receive_ts": "2026-06-21T04:27:19Z", "monotonic_ns": 1643595097538981, "raw": "{\"arg\":{\"channel\":\"trades\",\"instId\":\"BTC-USDT-SWAP\"},\"data\":[{\"instId\":\"BTC-USDT-SWAP\",\"tradeId\":\"2718750286\",\"px\":\"64482.9\",\"sz\":\"0.67\",\"side\":\"sell\",\"ts\":\"1782016039178\",\"count\":\"1\",\"source\":\"0\",\"seqId\":325070085763}]}"}
{"action": "update", "capture_sequence": 288, "channel": "books", "connection_sequence": 2, "event": null, "instId": "BTC-USDT-SWAP", "local_receive_ts": "2026-06-21T04:27:19Z", "monotonic_ns": 1643595125251023, "raw": "{\"arg\":{\"channel\":\"books\",\"instId\":\"BTC-USDT-SWAP\"},\"action\":\"update\",\"data\":[{\"asks\":[[\"64483\",\"227.55\",\"0\",\"27\"],[\"64484.7\",\"0\",\"0\",\"0\"],[\"64484.9\",\"62.4\",\"0\",\"5\"],[\"64485\",\"43.51\",\"0\",\"3\"],[\"64485.6\",\"0\",\"0\",\"0\"],[\"64485.8\",\"0.43\",\"0\",\"5\"],[\"64485.9\",\"82.97\",\"0\",\"3\"],[\"64486.1\",\"0.01\",\"0\",\"1\"],[\"64486.4\",\"2.83\",\"0\",\"3\"],[\"64490.2\",\"1.2\",\"0\",\"1\"],[\"64490.6\",\"31.51\",\"0\",\"4\"],[\"64494.1\",\"0.01\",\"0\",\"1\"],[\"64495.8\",\"167.02\",\"0\",\"6\"],[\"64497.3\",\"41.29\",\"0\",\"5\"],[\"64499.3\",\"0\",\"0\",\"0\"],[\"64499.4\",\"1.9\",\"0\",\"4\"],[\"64503.9\",\"15.66\",\"0\",\"2\"],[\"64504.2\",\"511.1\",\"0\",\"6\"],[\"64505.6\",\"59.46\",\"0\",\"5\"],[\"64505.7\",\"0.56\",\"0\",\"1\"],[\"64521.6\",\"4.75\",\"0\",\"3\"],[\"64526.9\",\"40.21\",\"0\",\"5\"],[\"64527\",\"0.17\",\"0\",\"3\"]],\"bids\":[[\"64482.9\",\"1066.93\",\"0\",\"69\"],[\"64482.5\",\"5\",\"0\",\"1\"],[\"64482.4\",\"0.03\",\"0\",\"2\"],[\"64481.9\",\"0\",\"0\",\"0\"],[\"64481.6\",\"1.57\",\"0\",\"2\"],[\"64481.4\",\"12.01\",\"0\",\"3\"],[\"64480.9\",\"0\",\"0\",\"0\"],[\"64480.5\",\"1.56\",\"0\",\"1\"],[\"64480\",\"110.29\",\"0\",\"7\"],[\"64479.5\",\"1.56\",\"0\",\"1\"],[\"64479.1\",\"77.54\",\"0\",\"1\"],[\"64479\",\"1.57\",\"0\",\"2\"],[\"64478.5\",\"1.57\",\"0\",\"2\"],[\"64477.8\",\"0\",\"0\",\"0\"],[\"64476.2\",\"291.71\",\"0\",\"4\"],[\"64476.1\",\"2.4\",\"0\",\"1\"],[\"64464.4\",\"3.21\",\"0\",\"2\"]],\"ts\":\"1782016039205\",\"checksum\":1473889860,\"seqId\":325070085798,\"prevSeqId\":325070085723}]}"}
{"action": null, "capture_sequence": 289, "channel": "trades", "connection_sequence": 2, "event": null, "instId": "BTC-USDT-SWAP", "local_receive_ts": "2026-06-21T04:27:19Z", "monotonic_ns": 1643595135227498, "raw": "{\"arg\":{\"channel\":\"trades\",\"instId\":\"BTC-USDT-SWAP\"},\"data\":[{\"instId\":\"BTC-USDT-SWAP\",\"tradeId\":\"2718750287\",\"px\":\"64482.9\",\"sz\":\"0.06\",\"side\":\"sell\",\"ts\":\"1782016039216\",\"count\":\"1\",\"source\":\"0\",\"seqId\":325070085818}]}"}
{"action": "update", "capture_sequence": 290, "channel": "books", "connection_sequence": 2, "event": null, "instId": "BTC-USDT-SWAP", "local_receive_ts": "2026-06-21T04:27:19Z", "monotonic_ns": 1643595224557301, "raw": "{\"arg\":{\"channel\":\"books\",\"instId\":\"BTC-USDT-SWAP\"},\"action\":\"update\",\"data\":[{\"asks\":[[\"64483\",\"225.99\",\"0\",\"26\"],[\"64483.3\",\"1.6\",\"0\",\"2\"],[\"64484.4\",\"0.01\",\"0\",\"1\"],[\"64484.5\",\"1.63\",\"0\",\"5\"],[\"64485.8\",\"0.42\",\"0\",\"4\"],[\"64513.3\",\"1.12\",\"0\",\"8\"],[\"64521.6\",\"0.02\",\"0\",\"2\"],[\"64527\",\"0\",\"0\",\"0\"]],\"bids\":[[\"64482.9\",\"1067.23\",\"0\",\"70\"],[\"64481.6\",\"0.01\",\"0\",\"1\"],[\"64481\",\"1.56\",\"0\",\"1\"],[\"64480.9\",\"0.31\",\"0\",\"1\"],[\"64479.6\",\"1.58\",\"0\",\"3\"],[\"64479.5\",\"0\",\"0\",\"0\"]],\"ts\":\"1782016039305\",\"checksum\":1535278676,\"seqId\":325070085894,\"prevSeqId\":325070085798}]}"}
{"action": "update", "capture_sequence": 291, "channel": "books", "connection_sequence": 2, "event": null, "instId": "BTC-USDT-SWAP", "local_receive_ts": "2026-06-21T04:27:19Z", "monotonic_ns": 1643595324660571, "raw": "{\"arg\":{\"channel\":\"books\",\"instId\":\"BTC-USDT-SWAP\"},\"action\":\"update\",\"data\":[{\"asks\":[[\"64483.2\",\"0.01\",\"0\",\"1\"],[\"64484.9\",\"62.39\",\"0\",\"4\"],[\"64486.9\",\"94.6\",\"0\",\"3\"],[\"64487\",\"141.24\",\"0\",\"5\"],[\"64487.3\",\"1.6\",\"0\",\"3\"],[\"64487.4\",\"0.5\",\"0\",\"6\"],[\"64488.5\",\"0\",\"0\",\"0\"],[\"64492.5\",\"6.25\",\"0\",\"4\"]],\"bids\":[[\"64482.9\",\"1053.42\",\"0\",\"68\"],[\"64482.1\",\"0.03\",\"0\",\"2\"]],\"ts\":\"1782016039405\",\"checksum\":-1478088474,\"seqId\":325070085922,\"prevSeqId\":325070085894}]}"}
{"action": "update", "capture_sequence": 292, "channel": "books", "connection_sequence": 2, "event": null, "instId": "BTC-USDT-SWAP", "local_receive_ts": "2026-06-21T04:27:19Z", "monotonic_ns": 1643595424650928, "raw": "{\"arg\":{\"channel\":\"books\",\"instId\":\"BTC-USDT-SWAP\"},\"action\":\"update\",\"data\":[{\"asks\":[[\"64483.2\",\"0\",\"0\",\"0\"],[\"64483.3\",\"0.04\",\"0\",\"1\"],[\"64484.4\",\"0\",\"0\",\"0\"],[\"64484.5\",\"0.07\",\"0\",\"4\"],[\"64484.9\",\"62.4\",\"0\",\"5\"],[\"64485\",\"41.95\",\"0\",\"2\"],[\"64485.8\",\"0.43\",\"0\",\"5\"],[\"64513.3\",\"1.97\",\"0\",\"9\"],[\"64527\",\"0.17\",\"0\",\"3\"],[\"64527.1\",\"0.46\",\"0\",\"1\"]],\"bids\":[[\"64482.9\",\"1067.15\",\"0\",\"69\"]],\"ts\":\"1782016039505\",\"checksum\":-1269693478,\"seqId\":325070085932,\"prevSeqId\":325070085922}]}"}
{"action": "update", "capture_sequence": 293, "channel": "books", "connection_sequence": 2, "event": null, "instId": "BTC-USDT-SWAP", "local_receive_ts": "2026-06-21T04:27:19Z", "monotonic_ns": 1643595523936458, "raw": "{\"arg\":{\"channel\":\"books\",\"instId\":\"BTC-USDT-SWAP\"},\"action\":\"update\",\"data\":[{\"asks\":[],\"bids\":[[\"64478.1\",\"2.71\",\"0\",\"1\"],[\"64476.1\",\"0\",\"0\",\"0\"],[\"64464.4\",\"0.01\",\"0\",\"1\"]],\"ts\":\"1782016039605\",\"checksum\":-1269693478,\"seqId\":325070085938,\"prevSeqId\":325070085932}]}"}
{"action": "update", "capture_sequence": 294, "channel": "books", "connection_sequence": 2, "event": null, "instId": "BTC-USDT-SWAP", "local_receive_ts": "2026-06-21T04:27:19Z", "monotonic_ns": 1643595624380683, "raw": "{\"arg\":{\"channel\":\"books\",\"instId\":\"BTC-USDT-SWAP\"},\"action\":\"update\",\"data\":[{\"asks\":[],\"bids\":[[\"64481\",\"0\",\"0\",\"0\"],[\"64480.5\",\"0\",\"0\",\"0\"],[\"64464.4\",\"3.23\",\"0\",\"2\"],[\"64423.5\",\"19.6\",\"0\",\"1\"],[\"64422.7\",\"22.42\",\"0\",\"4\"],[\"64422.4\",\"1366.68\",\"0\",\"4\"]],\"ts\":\"1782016039705\",\"checksum\":-191497533,\"seqId\":325070085972,\"prevSeqId\":325070085938}]}"}
{"action": "update", "capture_sequence": 295, "channel": "books", "connection_sequence": 2, "event": null, "instId": "BTC-USDT-SWAP", "local_receive_ts": "2026-06-21T04:27:19Z", "monotonic_ns": 1643595724487744, "raw": "{\"arg\":{\"channel\":\"books\",\"instId\":\"BTC-USDT-SWAP\"},\"action\":\"update\",\"data\":[{\"asks\":[[\"64506.8\",\"93.54\",\"0\",\"7\"],[\"64507.3\",\"0.03\",\"0\",\"2\"]],\"bids\":[[\"64468.4\",\"0\",\"0\",\"0\"],[\"64467.8\",\"1.33\",\"0\",\"3\"],[\"64422.3\",\"0.05\",\"0\",\"5\"]],\"ts\":\"1782016039805\",\"checksum\":-191497533,\"seqId\":325070085980,\"prevSeqId\":325070085972}]}"}
{"action": "update", "capture_sequence": 296, "channel": "books", "connection_sequence": 2, "event": null, "instId": "BTC-USDT-SWAP", "local_receive_ts": "2026-06-21T04:27:20Z", "monotonic_ns": 1643595832300118, "raw": "{\"arg\":{\"channel\":\"books\",\"instId\":\"BTC-USDT-SWAP\"},\"action\":\"update\",\"data\":[{\"asks\":[[\"64488.9\",\"0.33\",\"0\",\"6\"],[\"64489.5\",\"0.02\",\"0\",\"2\"],[\"64489.9\",\"0\",\"0\",\"0\"],[\"64490.2\",\"0\",\"0\",\"0\"],[\"64490.5\",\"1.81\",\"0\",\"3\"],[\"64490.8\",\"0.02\",\"0\",\"1\"],[\"64491.3\",\"0.01\",\"0\",\"1\"],[\"64491.7\",\"0.02\",\"0\",\"2\"],[\"64491.9\",\"0.3\",\"0\",\"4\"],[\"64492.1\",\"0\",\"0\",\"0\"],[\"64495.6\",\"22.01\",\"0\",\"2\"],[\"64497.3\",\"41.14\",\"0\",\"4\"],[\"64509.8\",\"0.01\",\"0\",\"1\"],[\"64510.5\",\"59.3\",\"0\",\"4\"],[\"64510.8\",\"0.02\",\"0\",\"1\"],[\"64511.1\",\"18.79\",\"0\",\"6\"],[\"64511.5\",\"0.3\",\"0\",\"6\"],[\"64511.8\",\"6.2\",\"0\",\"1\"],[\"64512.2\",\"11.23\",\"0\",\"3\"],[\"64512.6\",\"58.24\",\"0\",\"6\"],[\"64512.9\",\"17.79\",\"0\",\"4\"],[\"64513.1\",\"1.56\",\"0\",\"2\"],[\"64527.2\",\"0.18\",\"0\",\"4\"],[\"64527.3\",\"0.05\",\"0\",\"5\"],[\"64527.4\",\"0.27\",\"0\",\"2\"]],\"bids\":[[\"64480\",\"108.73\",\"0\",\"6\"],[\"64471.3\",\"16.36\",\"0\",\"2\"],[\"64470.6\",\"0\",\"0\",\"0\"],[\"64470.3\",\"160.92\",\"0\",\"4\"],[\"64470\",\"37.69\",\"0\",\"4\"],[\"64469.7\",\"7.76\",\"0\",\"2\"],[\"64469.3\",\"496.53\",\"0\",\"1\"],[\"64469.1\",\"0.01\",\"0\",\"1\"],[\"64468.9\",\"0.3\",\"0\",\"1\"],[\"64468.5\",\"0\",\"0\",\"0\"],[\"64468\",\"0.02\",\"0\",\"2\"],[\"64464.4\",\"0.01\",\"0\",\"1\"],[\"64424.1\",\"0\",\"0\",\"0\"],[\"64423.4\",\"0\",\"0\",\"0\"],[\"64423.1\",\"92.81\",\"0\",\"2\"],[\"64422.8\",\"0.01\",\"0\",\"1\"],[\"64422.4\",\"1365.48\",\"0\",\"3\"],[\"64422.2\",\"11.03\",\"0\",\"3\"],[\"64422\",\"0.01\",\"0\",\"1\"],[\"64421.9\",\"0.01\",\"0\",\"1\"],[\"64421.8\",\"0.03\",\"0\",\"2\"]],\"ts\":\"1782016039905\",\"checksum\":-2041115940,\"seqId\":325070086055,\"prevSeqId\":325070085980}]}"}
{"action": "update", "capture_sequence": 297, "channel": "books", "connection_sequence": 2, "event": null, "instId": "BTC-USDT-SWAP", "local_receive_ts": "2026-06-21T04:27:20Z", "monotonic_ns": 1643595924658539, "raw": "{\"arg\":{\"channel\":\"books\",\"instId\":\"BTC-USDT-SWAP\"},\"action\":\"update\",\"data\":[{\"asks\":[[\"64483.6\",\"1.56\",\"0\",\"1\"],[\"64497.2\",\"1\",\"0\",\"4\"],[\"64503\",\"46.98\",\"0\",\"4\"],[\"64503.6\",\"0.02\",\"0\",\"2\"],[\"64507.6\",\"33.82\",\"0\",\"3\"],[\"64508.3\",\"0\",\"0\",\"0\"],[\"64512.3\",\"63.54\",\"0\",\"5\"],[\"64519.7\",\"96.91\",\"0\",\"8\"],[\"64520.9\",\"0.02\",\"0\",\"2\"]],\"bids\":[[\"64482.4\",\"1.59\",\"0\",\"3\"],[\"64481.9\",\"1.56\",\"0\",\"1\"],[\"64481.4\",\"13.57\",\"0\",\"4\"],[\"64479.9\",\"0.14\",\"0\",\"3\"],[\"64479.6\",\"0.02\",\"0\",\"2\"],[\"64469.4\",\"46.54\",\"0\",\"1\"],[\"64468.8\",\"45.14\",\"0\",\"2\"],[\"64466.9\",\"85.41\",\"0\",\"2\"],[\"64466.1\",\"0\",\"0\",\"0\"],[\"64465.4\",\"507.87\",\"0\",\"3\"],[\"64465\",\"58.22\",\"0\",\"1\"],[\"64464.5\",\"236.15\",\"0\",\"4\"],[\"64421.8\",\"0\",\"0\",\"0\"]],\"ts\":\"1782016040005\",\"checksum\":-1792065419,\"seqId\":325070086088,\"prevSeqId\":325070086055}]}"}
{"action": "update", "capture_sequence": 298, "channel": "books", "connection_sequence": 2, "event": null, "instId": "BTC-USDT-SWAP", "local_receive_ts": "2026-06-21T04:27:20Z", "monotonic_ns": 1643596024909084, "raw": "{\"arg\":{\"channel\":\"books\",\"instId\":\"BTC-USDT-SWAP\"},\"action\":\"update\",\"data\":[{\"asks\":[[\"64483\",\"227.64\",\"0\",\"28\"],[\"64483.6\",\"0\",\"0\",\"0\"],[\"64484.1\",\"0.01\",\"0\",\"1\"],[\"64484.2\",\"1.56\",\"0\",\"1\"],[\"64484.7\",\"0.01\",\"0\",\"1\"],[\"64484.8\",\"1.58\",\"0\",\"3\"],[\"64484.9\",\"62.39\",\"0\",\"4\"],[\"64485.4\",\"1.56\",\"0\",\"1\"],[\"64485.8\",\"0.42\",\"0\",\"4\"],[\"64489.7\",\"0.8\",\"0\",\"1\"],[\"64506.2\",\"0.34\",\"0\",\"3\"],[\"64506.4\",\"0.03\",\"0\",\"3\"],[\"64518.2\",\"35.74\",\"0\",\"3\"],[\"64518.3\",\"4.67\",\"0\",\"3\"],[\"64523\",\"0.01\",\"0\",\"1\"],[\"64523.4\",\"39.42\",\"0\",\"4\"],[\"64527.1\",\"0\",\"0\",\"0\"],[\"64527.2\",\"0\",\"0\",\"0\"],[\"64527.3\",\"0\",\"0\",\"0\"],[\"64527.4\",\"0\",\"0\",\"0\"]],\"bids\":[[\"64482.5\",\"5.02\",\"0\",\"2\"],[\"64482.4\",\"0.01\",\"0\",\"1\"],[\"64481.9\",\"0\",\"0\",\"0\"],[\"64480.9\",\"1.87\",\"0\",\"2\"],[\"64480.4\",\"1.56\",\"0\",\"1\"],[\"64464.6\",\"232.91\",\"0\",\"1\"],[\"64464.5\",\"3.24\",\"0\",\"3\"],[\"64421.9\",\"0\",\"0\",\"0\"]],\"ts\":\"1782016040105\",\"checksum\":631722747,\"seqId\":325070086146,\"prevSeqId\":325070086088}]}"}
{"action": "update", "capture_sequence": 299, "channel": "books", "connection_sequence": 2, "event": null, "instId": "BTC-USDT-SWAP", "local_receive_ts": "2026-06-21T04:27:20Z", "monotonic_ns": 1643596124869585, "raw": "{\"arg\":{\"channel\":\"books\",\"instId\":\"BTC-USDT-SWAP\"},\"action\":\"update\",\"data\":[{\"asks\":[[\"64483.7\",\"0.02\",\"0\",\"2\"],[\"64483.8\",\"1.56\",\"0\",\"1\"],[\"64484.1\",\"0\",\"0\",\"0\"],[\"64484.2\",\"0.01\",\"0\",\"1\"],[\"64484.3\",\"1.56\",\"0\",\"1\"],[\"64484.6\",\"1.22\",\"0\",\"3\"],[\"64484.7\",\"1.56\",\"0\",\"1\"],[\"64484.8\",\"0.01\",\"0\",\"1\"],[\"64485.8\",\"1.98\",\"0\",\"5\"],[\"64487\",\"141.4\",\"0\",\"6\"],[\"64488.7\",\"0.04\",\"0\",\"1\"],[\"64489.2\",\"0\",\"0\",\"0\"],[\"64498.5\",\"23.45\",\"0\",\"5\"],[\"64501.8\",\"93.84\",\"0\",\"9\"],[\"64513.8\",\"58.19\",\"0\",\"2\"],[\"64513.9\",\"0.12\",\"0\",\"1\"],[\"64523\",\"0\",\"0\",\"0\"],[\"64523.4\",\"39.43\",\"0\",\"5\"],[\"64527.1\",\"0.46\",\"0\",\"1\"]],\"bids\":[[\"64482.5\",\"5\",\"0\",\"1\"],[\"64482.4\",\"0.03\",\"0\",\"2\"],[\"64482\",\"5.01\",\"0\",\"2\"],[\"64481.6\",\"1.57\",\"0\",\"2\"],[\"64481.4\",\"12.01\",\"0\",\"3\"],[\"64481.1\",\"0.31\",\"0\",\"1\"],[\"64481\",\"0.01\",\"0\",\"1\"],[\"64480.9\",\"1.56\",\"0\",\"1\"],[\"64480.5\",\"1.56\",\"0\",\"1\"],[\"64480.4\",\"0\",\"0\",\"0\"],[\"64480\",\"110.29\",\"0\",\"7\"],[\"64478.1\",\"0\",\"0\",\"0\"],[\"64476\",\"1.6\",\"0\",\"3\"],[\"64474.6\",\"2.76\",\"0\",\"1\"],[\"64422.3\",\"0.01\",\"0\",\"1\"],[\"64422.2\",\"0\",\"0\",\"0\"],[\"64422\",\"0\",\"0\",\"0\"]],\"ts\":\"1782016040205\",\"checksum\":281837352,\"seqId\":325070086234,\"prevSeqId\":325070086146}]}"}
{"action": "update", "capture_sequence": 300, "channel": "books", "connection_sequence": 2, "event": null, "instId": "BTC-USDT-SWAP", "local_receive_ts": "2026-06-21T04:27:20Z", "monotonic_ns": 1643596224603648, "raw": "{\"arg\":{\"channel\":\"books\",\"instId\":\"BTC-USDT-SWAP\"},\"action\":\"update\",\"data\":[{\"asks\":[],\"bids\":[[\"64482.8\",\"26.14\",\"0\",\"11\"],[\"64481.6\",\"0.01\",\"0\",\"1\"],[\"64481.2\",\"1.56\",\"0\",\"1\"],[\"64480.9\",\"0\",\"0\",\"0\"],[\"64480.5\",\"0\",\"0\",\"0\"],[\"64479.5\",\"1.56\",\"0\",\"1\"],[\"64475.6\",\"1.56\",\"0\",\"1\"],[\"64452\",\"10.31\",\"0\",\"6\"],[\"64422.3\",\"0\",\"0\",\"0\"]],\"ts\":\"1782016040305\",\"checksum\":226072725,\"seqId\":325070086284,\"prevSeqId\":325070086234}]}"}
{"action": null, "capture_sequence": 301, "channel": "trades", "connection_sequence": 3, "event": "subscribe", "instId": "BTC-USDT-SWAP", "local_receive_ts": "2026-06-21T04:27:21Z", "monotonic_ns": 1643597543661246, "raw": "{\"event\":\"subscribe\",\"arg\":{\"channel\":\"trades\",\"instId\":\"BTC-USDT-SWAP\"},\"connId\":\"79f77446\"}"}
{"action": null, "capture_sequence": 302, "channel": "books", "connection_sequence": 3, "event": "subscribe", "instId": "BTC-USDT-SWAP", "local_receive_ts": "2026-06-21T04:27:21Z", "monotonic_ns": 1643597543905443, "raw": "{\"event\":\"subscribe\",\"arg\":{\"channel\":\"books\",\"instId\":\"BTC-USDT-SWAP\"},\"connId\":\"79f77446\"}"}
{"action": "snapshot", "capture_sequence": 303, "channel": "books", "connection_sequence": 3, "event": null, "instId": "BTC-USDT-SWAP", "local_receive_ts": "2026-06-21T04:27:22Z", "monotonic_ns": 1643597937800289, "raw": "{\"arg\":{\"channel\":\"books\",\"instId\":\"BTC-USDT-SWAP\"},\"action\":\"snapshot\",\"data\":[{\"asks\":[[\"64483\",\"152.77\",\"0\",\"15\"],[\"64483.1\",\"0.63\",\"0\",\"4\"],[\"64483.3\",\"0.04\",\"0\",\"1\"],[\"64483.7\",\"0.01\",\"0\",\"1\"],[\"64483.9\",\"0.01\",\"0\",\"1\"],[\"64484\",\"0.55\",\"0\",\"3\"],[\"64484.5\",\"0.07\",\"0\",\"4\"],[\"64484.6\",\"1.21\",\"0\",\"2\"],[\"64484.8\",\"0.02\",\"0\",\"2\"],[\"64484.9\",\"65.86\",\"0\",\"4\"],[\"64485\",\"41.95\",\"0\",\"2\"],[\"64485.2\",\"0.02\",\"0\",\"2\"],[\"64485.5\",\"0.01\",\"0\",\"1\"],[\"64485.7\",\"0.34\",\"0\",\"4\"],[\"64485.8\",\"0.43\",\"0\",\"5\"],[\"64485.9\",\"82.97\",\"0\",\"3\"],[\"64486\",\"51.08\",\"0\",\"5\"],[\"64486.1\",\"0.01\",\"0\",\"1\"],[\"64486.2\",\"3.56\",\"0\",\"9\"],[\"64486.3\",\"0.01\",\"0\",\"1\"],[\"64486.4\",\"1.27\",\"0\",\"2\"],[\"64486.5\",\"0.01\",\"0\",\"1\"],[\"64486.6\",\"8.74\",\"0\",\"2\"],[\"64486.8\",\"0.19\",\"0\",\"3\"],[\"64486.9\",\"94.6\",\"0\",\"3\"],[\"64487\",\"141.4\",\"0\",\"6\"],[\"64487.1\",\"0.53\",\"0\",\"4\"],[\"64487.2\",\"0.03\",\"0\",\"2\"],[\"64487.3\",\"0.04\",\"0\",\"2\"],[\"64487.4\",\"0.5\",\"0\",\"6\"],[\"64487.5\",\"0.04\",\"0\",\"3\"],[\"64487.7\",\"0.01\",\"0\",\"1\"],[\"64487.8\",\"12.41\",\"0\",\"5\"],[\"64487.9\",\"0.51\",\"0\",\"2\"],[\"64488\",\"57.87\",\"0\",\"27\"],[\"64488.1\",\"0.66\",\"0\",\"1\"],[\"64488.2\",\"3.96\",\"0\",\"2\"],[\"64488.3\",\"0.02\",\"0\",\"2\"],[\"64488.4\",\"5.67\",\"0\",\"6\"],[\"64488.6\",\"0.02\",\"0\",\"2\"],[\"64488.7\",\"0.04\",\"0\",\"1\"],[\"64488.8\",\"50\",\"0\",\"1\"],[\"64488.9\",\"1.33\",\"0\",\"7\"],[\"64489\",\"19.1\",\"0\",\"8\"],[\"64489.1\",\"0.04\",\"0\",\"3\"],[\"64489.3\",\"3.24\",\"0\",\"3\"],[\"64489.4\",\"2.93\",\"0\",\"5\"],[\"64489.5\",\"1.02\",\"0\",\"3\"],[\"64489.6\",\"1.28\",\"0\",\"3\"],[\"64489.7\",\"0.8\",\"0\",\"1\"],[\"64489.8\",\"49.44\",\"0\",\"4\"],[\"64489.9\",\"1\",\"0\",\"1\"],[\"64490\",\"55.77\",\"0\",\"19\"],[\"64490.1\",\"0.3\",\"0\",\"2\"],[\"64490.2\",\"1.2\",\"0\",\"1\"],[\"64490.3\",\"1\",\"0\",\"1\"],[\"64490.4\",\"0.03\",\"0\",\"3\"],[\"64490.5\",\"3.01\",\"0\",\"4\"],[\"64490.6\",\"31.51\",\"0\",\"4\"],[\"64490.7\",\"0.06\",\"0\",\"2\"],[\"64490.8\",\"1.22\",\"0\",\"2\"],[\"64490.9\",\"0.07\",\"0\",\"2\"],[\"64491\",\"0.01\",\"0\",\"1\"],[\"64491.2\",\"1.01\",\"0\",\"2\"],[\"64491.3\",\"1.21\",\"0\",\"2\"],[\"64491.4\",\"0.02\",\"0\",\"2\"],[\"64491.5\",\"0.1\",\"0\",\"1\"],[\"64491.6\",\"1.25\",\"0\",\"5\"],[\"64491.7\",\"1.22\",\"0\",\"3\"],[\"64491.8\",\"0.05\",\"0\",\"1\"],[\"64491.9\",\"1.5\",\"0\",\"5\"],[\"64492\",\"0.04\",\"0\",\"4\"],[\"64492.1\",\"1.5\",\"0\",\"1\"],[\"64492.2\",\"0.91\",\"0\",\"7\"],[\"64492.3\",\"0.03\",\"0\",\"1\"],[\"64492.4\",\"0.08\",\"0\",\"6\"],[\"64492.5\",\"6.25\",\"0\",\"4\"],[\"64492.6\",\"60.6\",\"0\",\"1\"],[\"64492.7\",\"0.3\",\"0\",\"2\"],[\"64492.8\",\"0.44\",\"0\",\"9\"],[\"64492.9\",\"0.01\",\"0\",\"1\"],[\"64493\",\"17.18\",\"0\",\"4\"],[\"64493.1\",\"0.45\",\"0\",\"2\"],[\"64493.2\",\"0.07\",\"0\",\"4\"],[\"64493.3\",\"18.63\",\"0\",\"6\"],[\"64493.4\",\"11.06\",\"0\",\"7\"],[\"64493.5\",\"186.37\",\"0\",\"6\"],[\"64493.6\",\"0.02\",\"0\",\"1\"],[\"64493.7\",\"1.25\",\"0\",\"3\"],[\"64493.8\",\"0.03\",\"0\",\"2\"],[\"64494\",\"238.94\",\"0\",\"6\"],[\"64494.2\",\"0.12\",\"0\",\"1\"],[\"64494.3\",\"0.08\",\"0\",\"4\"],[\"64494.4\",\"0.22\",\"0\",\"5\"],[\"64494.6\",\"20.97\",\"0\",\"6\"],[\"64494.7\",\"24.05\",\"0\",\"5\"],[\"64494.8\",\"0.45\",\"0\",\"2\"],[\"64494.9\",\"12.07\",\"0\",\"5\"],[\"64495\",\"1.49\",\"0\",\"8\"],[\"64495.1\",\"0.07\",\"0\",\"3\"],[\"64495.2\",\"6.12\",\"0\",\"4\"],[\"64495.3\",\"5.03\",\"0\",\"3\"],[\"64495.4\",\"0.06\",\"0\",\"3\"],[\"64495.5\",\"0.26\",\"0\",\"6\"],[\"64495.6\",\"22.01\",\"0\",\"2\"],[\"64495.7\",\"11.35\",\"0\",\"3\"],[\"64495.8\",\"34.99\",\"0\",\"4\"],[\"64495.9\",\"0.85\",\"0\",\"4\"],[\"64496\",\"104.13\",\"0\",\"6\"],[\"64496.1\",\"0.06\",\"0\",\"3\"],[\"64496.2\",\"19.89\",\"0\",\"2\"],[\"64496.3\",\"412.07\",\"0\",\"8\"],[\"64496.4\",\"0.02\",\"0\",\"2\"],[\"64496.6\",\"31.68\",\"0\",\"2\"],[\"64496.7\",\"0.01\",\"0\",\"1\"],[\"64496.8\",\"29.39\",\"0\",\"3\"],[\"64496.9\",\"46.54\",\"0\",\"1\"],[\"64497\",\"18.82\",\"0\",\"6\"],[\"64497.1\",\"0.01\",\"0\",\"1\"],[\"64497.2\",\"1\",\"0\",\"4\"],[\"64497.3\",\"41.14\",\"0\",\"4\"],[\"64497.4\",\"45.31\",\"0\",\"3\"],[\"64497.5\",\"0.33\",\"0\",\"3\"],[\"64497.6\",\"0.13\",\"0\",\"3\"],[\"64497.8\",\"4.01\",\"0\",\"2\"],[\"64497.9\",\"0.01\",\"0\",\"1\"],[\"64498\",\"24.4\",\"0\",\"3\"],[\"64498.1\",\"8.03\",\"0\",\"4\"],[\"64498.2\",\"0.04\",\"0\",\"3\"],[\"64498.3\",\"84.77\",\"0\",\"6\"],[\"64498.5\",\"23.45\",\"0\",\"5\"],[\"64498.6\",\"0.29\",\"0\",\"6\"],[\"64498.7\",\"1.86\",\"0\",\"3\"],[\"64498.8\",\"0.02\",\"0\",\"2\"],[\"64498.9\",\"546.49\",\"0\",\"4\"],[\"64499\",\"333.09\",\"0\",\"21\"],[\"64499.1\",\"3.41\",\"0\",\"6\"],[\"64499.2\",\"12.01\",\"0\",\"3\"],[\"64499.4\",\"1.73\",\"0\",\"3\"],[\"64499.6\",\"59.37\",\"0\",\"3\"],[\"64499.7\",\"19.72\",\"0\",\"4\"],[\"64499.8\",\"1.08\",\"0\",\"2\"],[\"64499.9\",\"1114.67\",\"0\",\"2\"],[\"64500\",\"3456.85\",\"0\",\"1036\"],[\"64500.1\",\"0.06\",\"0\",\"5\"],[\"64500.2\",\"0.02\",\"0\",\"2\"],[\"64500.3\",\"3.58\",\"0\",\"6\"],[\"64500.4\",\"0.04\",\"0\",\"4\"],[\"64500.5\",\"2.49\",\"0\",\"2\"],[\"64500.6\",\"0.39\",\"0\",\"3\"],[\"64500.7\",\"3.91\",\"0\",\"1\"],[\"64500.8\",\"0.53\",\"0\",\"2\"],[\"64500.9\",\"41.86\",\"0\",\"4\"],[\"64501\",\"0.27\",\"0\",\"3\"],[\"64501.1\",\"0.43\",\"0\",\"3\"],[\"64501.2\",\"0.03\",\"0\",\"3\"],[\"64501.3\",\"0.02\",\"0\",\"1\"],[\"64501.4\",\"15.52\",\"0\",\"2\"],[\"64501.5\",\"1.57\",\"0\",\"4\"],[\"64501.6\",\"1.89\",\"0\",\"3\"],[\"64501.7\",\"0.55\",\"0\",\"4\"],[\"64501.8\",\"91.08\",\"0\",\"8\"],[\"64501.9\",\"0.08\",\"0\",\"1\"],[\"64502\",\"2.12\",\"0\",\"6\"],[\"64502.1\",\"0.01\",\"0\",\"1\"],[\"64502.2\",\"83.91\",\"0\",\"6\"],[\"64502.3\",\"11.26\",\"0\",\"4\"],[\"64502.4\",\"0.19\",\"0\",\"6\"],[\"64502.5\",\"0.2\",\"0\",\"3\"],[\"64502.6\",\"15.66\",\"0\",\"2\"],[\"64502.7\",\"0.03\",\"0\",\"3\"],[\"64502.8\",\"57.07\",\"0\",\"3\"],[\"64502.9\",\"280.72\",\"0\",\"7\"],[\"64503\",\"15.95\",\"0\",\"3\"],[\"64503.1\",\"39.69\",\"0\",\"8\"],[\"64503.2\",\"0.3\",\"0\",\"2\"],[\"64503.3\",\"0.02\",\"0\",\"2\"],[\"64503.5\",\"63.72\",\"0\",\"6\"],[\"64503.6\",\"0.02\",\"0\",\"2\"],[\"64503.7\",\"0.29\",\"0\",\"2\"],[\"64503.8\",\"31.03\",\"0\",\"1\"],[\"64503.9\",\"18.56\",\"0\",\"2\"],[\"64504\",\"54.55\",\"0\",\"8\"],[\"64504.1\",\"15.11\",\"0\",\"6\"],[\"64504.2\",\"511.1\",\"0\",\"6\"],[\"64504.3\",\"0.05\",\"0\",\"3\"],[\"64504.4\",\"233.89\",\"0\",\"5\"],[\"64504.5\",\"59.15\",\"0\",\"6\"],[\"64504.6\",\"2.5\",\"0\",\"1\"],[\"64504.7\",\"0.01\",\"0\",\"1\"],[\"64504.8\",\"0.11\",\"0\",\"5\"],[\"64504.9\",\"0.1\",\"0\",\"3\"],[\"64505\",\"0.82\",\"0\",\"3\"],[\"64505.1\",\"0.02\",\"0\",\"2\"],[\"64505.2\",\"15.65\",\"0\",\"1\"],[\"64505.3\",\"1.16\",\"0\",\"2\"],[\"64505.4\",\"59.23\",\"0\",\"4\"],[\"64505.5\",\"73.81\",\"0\",\"3\"],[\"64505.6\",\"57.91\",\"0\",\"4\"],[\"64505.7\",\"0.56\",\"0\",\"1\"],[\"64505.8\",\"0.08\",\"0\",\"1\"],[\"64505.9\",\"0.01\",\"0\",\"1\"],[\"64506\",\"10.07\",\"0\",\"5\"],[\"64506.1\",\"6.28\",\"0\",\"2\"],[\"64506.2\",\"1.58\",\"0\",\"3\"],[\"64506.3\",\"15.66\",\"0\",\"2\"],[\"64506.4\",\"0.34\",\"0\",\"4\"],[\"64506.5\",\"15.72\",\"0\",\"2\"],[\"64506.6\",\"10.15\",\"0\",\"3\"],[\"64506.7\",\"0.19\",\"0\",\"15\"],[\"64506.8\",\"92.27\",\"0\",\"5\"],[\"64506.9\",\"38.85\",\"0\",\"3\"],[\"64507\",\"0.06\",\"0\",\"1\"],[\"64507.1\",\"0.06\",\"0\",\"4\"],[\"64507.2\",\"14.03\",\"0\",\"2\"],[\"64507.3\",\"0.03\",\"0\",\"2\"],[\"64507.4\",\"27.27\",\"0\",\"1\"],[\"64507.5\",\"0.13\",\"0\",\"6\"],[\"64507.6\",\"0.03\",\"0\",\"2\"],[\"64507.7\",\"0.84\",\"0\",\"5\"],[\"64507.8\",\"34.13\",\"0\",\"5\"],[\"64507.9\",\"0.27\",\"0\",\"4\"],[\"64508\",\"37.26\",\"0\",\"10\"],[\"64508.1\",\"34.61\",\"0\",\"4\"],[\"64508.2\",\"59.01\",\"0\",\"5\"],[\"64508.4\",\"1.62\",\"0\",\"5\"],[\"64508.5\",\"42.46\",\"0\",\"3\"],[\"64508.6\",\"0.01\",\"0\",\"1\"],[\"64508.7\",\"147.7\",\"0\",\"9\"],[\"64508.8\",\"0.04\",\"0\",\"2\"],[\"64508.9\",\"160.53\",\"0\",\"4\"],[\"64509\",\"215.66\",\"0\",\"3\"],[\"64509.1\",\"0.03\",\"0\",\"3\"],[\"64509.3\",\"0.28\",\"0\",\"5\"],[\"64509.6\",\"15.68\",\"0\",\"3\"],[\"64509.8\",\"0.01\",\"0\",\"1\"],[\"64509.9\",\"1.21\",\"0\",\"3\"],[\"64510\",\"71.08\",\"0\",\"29\"],[\"64510.1\",\"0.01\",\"0\",\"1\"],[\"64510.2\",\"15.65\",\"0\",\"1\"],[\"64510.3\",\"1\",\"0\",\"1\"],[\"64510.4\",\"0.53\",\"0\",\"4\"],[\"64510.5\",\"59.3\",\"0\",\"4\"],[\"64510.6\",\"0.19\",\"0\",\"2\"],[\"64510.7\",\"1.02\",\"0\",\"3\"],[\"64510.8\",\"0.02\",\"0\",\"1\"],[\"64510.9\",\"0.07\",\"0\",\"4\"],[\"64511\",\"25.02\",\"0\",\"8\"],[\"64511.1\",\"18.79\",\"0\",\"6\"],[\"64511.2\",\"0.02\",\"0\",\"2\"],[\"64511.3\",\"0.93\",\"0\",\"7\"],[\"64511.4\",\"15.78\",\"0\",\"4\"],[\"64511.5\",\"0.3\",\"0\",\"6\"],[\"64511.7\",\"0.02\",\"0\",\"2\"],[\"64511.8\",\"6.2\",\"0\",\"1\"],[\"64511.9\",\"0.14\",\"0\",\"1\"],[\"64512\",\"88.21\",\"0\",\"14\"],[\"64512.1\",\"37.24\",\"0\",\"4\"],[\"64512.2\",\"11.23\",\"0\",\"3\"],[\"64512.3\",\"63.54\",\"0\",\"5\"],[\"64512.4\",\"0.08\",\"0\",\"1\"],[\"64512.5\",\"1.16\",\"0\",\"6\"],[\"64512.6\",\"58.24\",\"0\",\"6\"],[\"64512.7\",\"91.6\",\"0\",\"3\"],[\"64512.9\",\"17.79\",\"0\",\"4\"],[\"64513\",\"10.37\",\"0\",\"3\"],[\"64513.1\",\"2.56\",\"0\",\"3\"],[\"64513.2\",\"0.15\",\"0\",\"4\"],[\"64513.3\",\"1.97\",\"0\",\"9\"],[\"64513.4\",\"15.68\",\"0\",\"3\"],[\"64513.5\",\"1.6\",\"0\",\"4\"],[\"64513.7\",\"0.01\",\"0\",\"1\"],[\"64513.8\",\"1.21\",\"0\",\"2\"],[\"64513.9\",\"0.12\",\"0\",\"1\"],[\"64514\",\"15.66\",\"0\",\"2\"],[\"64514.1\",\"11.23\",\"0\",\"5\"],[\"64514.2\",\"1.07\",\"0\",\"4\"],[\"64514.3\",\"0.11\",\"0\",\"5\"],[\"64514.4\",\"16.9\",\"0\",\"5\"],[\"64514.5\",\"58.92\",\"0\",\"6\"],[\"64514.6\",\"15.68\",\"0\",\"2\"],[\"64514.7\",\"1.01\",\"0\",\"2\"],[\"64514.8\",\"60.79\",\"0\",\"6\"],[\"64514.9\",\"497.81\",\"0\",\"5\"],[\"64515\",\"0.04\",\"0\",\"2\"],[\"64515.2\",\"15.66\",\"0\",\"2\"],[\"64515.3\",\"1.21\",\"0\",\"2\"],[\"64515.4\",\"0.46\",\"0\",\"5\"],[\"64515.5\",\"75.46\",\"0\",\"7\"],[\"64515.6\",\"1.29\",\"0\",\"5\"],[\"64515.7\",\"60.85\",\"0\",\"3\"],[\"64515.8\",\"16.99\",\"0\",\"3\"],[\"64515.9\",\"47.94\",\"0\",\"4\"],[\"64516\",\"500.05\",\"0\",\"6\"],[\"64516.1\",\"0.04\",\"0\",\"4\"],[\"64516.2\",\"15.65\",\"0\",\"1\"],[\"64516.3\",\"2.16\",\"0\",\"3\"],[\"64516.4\",\"16.74\",\"0\",\"9\"],[\"64516.5\",\"49.1\",\"0\",\"2\"],[\"64516.6\",\"0.7\",\"0\",\"2\"],[\"64516.7\",\"149.16\",\"0\",\"10\"],[\"64516.8\",\"6.26\",\"0\",\"3\"],[\"64516.9\",\"14.05\",\"0\",\"4\"],[\"64517\",\"17.37\",\"0\",\"20\"],[\"64517.1\",\"0.18\",\"0\",\"1\"],[\"64517.2\",\"0.76\",\"0\",\"5\"],[\"64517.4\",\"0.03\",\"0\",\"2\"],[\"64517.6\",\"25.58\",\"0\",\"2\"],[\"64517.7\",\"18.68\",\"0\",\"4\"],[\"64517.8\",\"0.1\",\"0\",\"3\"],[\"64517.9\",\"0.15\",\"0\",\"3\"],[\"64518\",\"103.54\",\"0\",\"13\"],[\"64518.1\",\"0.15\",\"0\",\"5\"],[\"64518.2\",\"15.68\",\"0\",\"2\"],[\"64518.3\",\"0.02\",\"0\",\"2\"],[\"64518.4\",\"76.16\",\"0\",\"4\"],[\"64518.5\",\"0.01\",\"0\",\"1\"],[\"64518.6\",\"0.11\",\"0\",\"8\"],[\"64518.8\",\"90.26\",\"0\",\"4\"],[\"64518.9\",\"46.5\",\"0\",\"2\"],[\"64519\",\"8.67\",\"0\",\"5\"],[\"64519.1\",\"43.07\",\"0\",\"2\"],[\"64519.2\",\"0.48\",\"0\",\"7\"],[\"64519.3\",\"15.7\",\"0\",\"3\"],[\"64519.4\",\"0.06\",\"0\",\"2\"],[\"64519.5\",\"54.3\",\"0\",\"6\"],[\"64519.6\",\"0.02\",\"0\",\"2\"],[\"64519.7\",\"96.91\",\"0\",\"8\"],[\"64519.8\",\"89.37\",\"0\",\"5\"],[\"64519.9\",\"496.56\",\"0\",\"2\"],[\"64520\",\"291.43\",\"0\",\"64\"],[\"64520.1\",\"0.02\",\"0\",\"2\"],[\"64520.2\",\"0.01\",\"0\",\"1\"],[\"64520.3\",\"0.05\",\"0\",\"3\"],[\"64520.4\",\"1.19\",\"0\",\"7\"],[\"64520.5\",\"0.04\",\"0\",\"3\"],[\"64520.6\",\"0.02\",\"0\",\"2\"],[\"64520.7\",\"30.4\",\"0\",\"1\"],[\"64520.8\",\"0.04\",\"0\",\"2\"],[\"64520.9\",\"0.02\",\"0\",\"2\"],[\"64521\",\"121.98\",\"0\",\"8\"],[\"64521.1\",\"0.01\",\"0\",\"1\"],[\"64521.3\",\"0.01\",\"0\",\"1\"],[\"64521.4\",\"0.35\",\"0\",\"1\"],[\"64521.5\",\"3.16\",\"0\",\"7\"],[\"64521.6\",\"0.02\",\"0\",\"2\"],[\"64521.7\",\"0.06\",\"0\",\"3\"],[\"64521.8\",\"2.44\",\"0\",\"4\"],[\"64521.9\",\"16.99\",\"0\",\"2\"],[\"64522\",\"5.18\",\"0\",\"10\"],[\"64522.1\",\"11.33\",\"0\",\"1\"],[\"64522.2\",\"0.15\",\"0\",\"8\"],[\"64522.3\",\"0.01\",\"0\",\"1\"],[\"64522.4\",\"0.42\",\"0\",\"1\"],[\"64522.5\",\"0.01\",\"0\",\"1\"],[\"64522.6\",\"1.54\",\"0\",\"3\"],[\"64522.7\",\"403.98\",\"0\",\"2\"],[\"64522.8\",\"15.71\",\"0\",\"4\"],[\"64522.9\",\"58.86\",\"0\",\"2\"],[\"64523.1\",\"0.01\",\"0\",\"1\"],[\"64523.2\",\"0.02\",\"0\",\"2\"],[\"64523.3\",\"186.34\",\"0\",\"3\"],[\"64523.4\",\"39.42\",\"0\",\"4\"],[\"64523.6\",\"0.03\",\"0\",\"1\"],[\"64523.7\",\"43.32\",\"0\",\"2\"],[\"64523.8\",\"0.02\",\"0\",\"1\"],[\"64524\",\"0.06\",\"0\",\"5\"],[\"64524.1\",\"2.51\",\"0\",\"2\"],[\"64524.2\",\"0.03\",\"0\",\"1\"],[\"64524.3\",\"15.65\",\"0\",\"1\"],[\"64524.5\",\"0.17\",\"0\",\"3\"],[\"64524.6\",\"0.01\",\"0\",\"1\"],[\"64524.7\",\"0.02\",\"0\",\"1\"],[\"64524.8\",\"3.05\",\"0\",\"5\"],[\"64524.9\",\"2.19\",\"0\",\"7\"],[\"64525\",\"2.51\",\"0\",\"18\"],[\"64525.1\",\"0.46\",\"0\",\"1\"],[\"64525.2\",\"55.22\",\"0\",\"2\"],[\"64525.3\",\"0.01\",\"0\",\"1\"],[\"64525.4\",\"26.59\",\"0\",\"2\"],[\"64525.5\",\"0.03\",\"0\",\"2\"],[\"64525.6\",\"37.24\",\"0\",\"2\"],[\"64525.7\",\"0.03\",\"0\",\"1\"],[\"64525.8\",\"0.02\",\"0\",\"2\"],[\"64525.9\",\"2.54\",\"0\",\"3\"],[\"64526\",\"1.16\",\"0\",\"4\"],[\"64526.1\",\"15.65\",\"0\",\"1\"],[\"64526.2\",\"6.57\",\"0\",\"2\"],[\"64526.3\",\"2.95\",\"0\",\"1\"],[\"64526.4\",\"46.54\",\"0\",\"1\"],[\"64526.5\",\"60\",\"0\",\"3\"],[\"64526.6\",\"14.23\",\"0\",\"4\"],[\"64526.7\",\"0.01\",\"0\",\"1\"],[\"64526.8\",\"0.37\",\"0\",\"2\"],[\"64526.9\",\"40.21\",\"0\",\"5\"],[\"64527\",\"0.17\",\"0\",\"3\"],[\"64527.1\",\"0.46\",\"0\",\"1\"],[\"64527.2\",\"0.18\",\"0\",\"4\"],[\"64527.3\",\"0.05\",\"0\",\"5\"],[\"64527.4\",\"0.27\",\"0\",\"2\"]],\"bids\":[[\"64482.9\",\"1067.06\",\"0\",\"70\"],[\"64482.8\",\"26.14\",\"0\",\"11\"],[\"64482.7\",\"0.02\",\"0\",\"1\"],[\"64482.6\",\"3.31\",\"0\",\"3\"],[\"64482.5\",\"5\",\"0\",\"1\"],[\"64482.4\",\"0.03\",\"0\",\"2\"],[\"64482.3\",\"2.46\",\"0\",\"1\"],[\"64482.1\",\"0.03\",\"0\",\"2\"],[\"64482\",\"5.01\",\"0\",\"2\"],[\"64481.6\",\"0.01\",\"0\",\"1\"],[\"64481.5\",\"0.01\",\"0\",\"1\"],[\"64481.4\",\"12.01\",\"0\",\"3\"],[\"64480.8\",\"0.01\",\"0\",\"1\"],[\"64480.7\",\"0.01\",\"0\",\"1\"],[\"64480.1\",\"0.01\",\"0\",\"1\"],[\"64480\",\"108.73\",\"0\",\"6\"],[\"64479.9\",\"0.14\",\"0\",\"3\"],[\"64479.8\",\"73.92\",\"0\",\"2\"],[\"64479.6\",\"0.02\",\"0\",\"2\"],[\"64479.3\",\"77.55\",\"0\",\"2\"],[\"64479.2\",\"78.37\",\"0\",\"1\"],[\"64479\",\"1.57\",\"0\",\"2\"],[\"64478.5\",\"1.57\",\"0\",\"2\"],[\"64478.3\",\"0.01\",\"0\",\"1\"],[\"64478\",\"0.01\",\"0\",\"1\"],[\"64477.7\",\"13.17\",\"0\",\"5\"],[\"64477.6\",\"1.57\",\"0\",\"2\"],[\"64477.5\",\"0.3\",\"0\",\"1\"],[\"64477.4\",\"0.01\",\"0\",\"1\"],[\"64477.3\",\"6.22\",\"0\",\"1\"],[\"64477.1\",\"0.02\",\"0\",\"2\"],[\"64477\",\"1.56\",\"0\",\"1\"],[\"64476.9\",\"0.02\",\"0\",\"2\"],[\"64476.7\",\"4.78\",\"0\",\"2\"],[\"64476.6\",\"0.02\",\"0\",\"2\"],[\"64476.5\",\"12.17\",\"0\",\"2\"],[\"64476.4\",\"31.81\",\"0\",\"2\"],[\"64476.3\",\"36.42\",\"0\",\"4\"],[\"64476.2\",\"291.71\",\"0\",\"4\"],[\"64476\",\"0.04\",\"0\",\"2\"],[\"64475.9\",\"46.55\",\"0\",\"2\"],[\"64475.8\",\"37.24\",\"0\",\"2\"],[\"64475.4\",\"0.02\",\"0\",\"2\"],[\"64475.3\",\"0.24\",\"0\",\"2\"],[\"64475.1\",\"69.62\",\"0\",\"3\"],[\"64475\",\"68.83\",\"0\",\"2\"],[\"64474.8\",\"0.01\",\"0\",\"1\"],[\"64474.7\",\"0.01\",\"0\",\"1\"],[\"64474.6\",\"2.76\",\"0\",\"1\"],[\"64474.5\",\"15.9\",\"0\",\"1\"],[\"64474.1\",\"0.01\",\"0\",\"1\"],[\"64474\",\"496.54\",\"0\",\"2\"],[\"64473.9\",\"46.57\",\"0\",\"3\"],[\"64473.8\",\"0.02\",\"0\",\"2\"],[\"64473.7\",\"0.31\",\"0\",\"1\"],[\"64473.6\",\"246.97\",\"0\",\"3\"],[\"64473.5\",\"63.31\",\"0\",\"2\"],[\"64473.4\",\"0.3\",\"0\",\"1\"],[\"64473.3\",\"0.01\",\"0\",\"1\"],[\"64473.2\",\"11.41\",\"0\",\"2\"],[\"64472.9\",\"15.94\",\"0\",\"1\"],[\"64472.7\",\"3.92\",\"0\",\"3\"],[\"64472.5\",\"73\",\"0\",\"2\"],[\"64472.3\",\"0.01\",\"0\",\"1\"],[\"64472.1\",\"0.82\",\"0\",\"3\"],[\"64472\",\"0.02\",\"0\",\"2\"],[\"64471.9\",\"1.6\",\"0\",\"1\"],[\"64471.7\",\"0.3\",\"0\",\"1\"],[\"64471.6\",\"0.03\",\"0\",\"1\"],[\"64471.5\",\"0.01\",\"0\",\"1\"],[\"64471.4\",\"46.55\",\"0\",\"2\"],[\"64471.3\",\"18.26\",\"0\",\"3\"],[\"64471\",\"1.6\",\"0\",\"1\"],[\"64470.9\",\"0.01\",\"0\",\"1\"],[\"64470.7\",\"1.7\",\"0\",\"3\"],[\"64470.5\",\"6.23\",\"0\",\"2\"],[\"64470.4\",\"90.16\",\"0\",\"2\"],[\"64470.3\",\"162.84\",\"0\",\"5\"],[\"64470.1\",\"535.79\",\"0\",\"1\"],[\"64470\",\"39.85\",\"0\",\"5\"],[\"64469.9\",\"169.58\",\"0\",\"4\"],[\"64469.8\",\"87.1\",\"0\",\"3\"],[\"64469.7\",\"7.76\",\"0\",\"2\"],[\"64469.6\",\"3.01\",\"0\",\"2\"],[\"64469.5\",\"0.39\",\"0\",\"2\"],[\"64469.4\",\"46.54\",\"0\",\"1\"],[\"64469.3\",\"530.34\",\"0\",\"2\"],[\"64469.2\",\"157.67\",\"0\",\"5\"],[\"64469.1\",\"0.01\",\"0\",\"1\"],[\"64468.9\",\"0.3\",\"0\",\"1\"],[\"64468.8\",\"11.33\",\"0\",\"1\"],[\"64468.7\",\"87.19\",\"0\",\"7\"],[\"64468.4\",\"0.77\",\"0\",\"1\"],[\"64468.3\",\"20.08\",\"0\",\"1\"],[\"64468.2\",\"62.15\",\"0\",\"1\"],[\"64468\",\"0.02\",\"0\",\"2\"],[\"64467.9\",\"0.01\",\"0\",\"1\"],[\"64467.8\",\"0.56\",\"0\",\"2\"],[\"64467.6\",\"0.03\",\"0\",\"3\"],[\"64467.5\",\"0.03\",\"0\",\"2\"],[\"64467.4\",\"46.54\",\"0\",\"1\"],[\"64467.3\",\"103.03\",\"0\",\"2\"],[\"64467.1\",\"31.22\",\"0\",\"2\"],[\"64467\",\"404.62\",\"0\",\"4\"],[\"64466.9\",\"0.02\",\"0\",\"1\"],[\"64466.8\",\"18.96\",\"0\",\"2\"],[\"64466.6\",\"0.01\",\"0\",\"1\"],[\"64466.3\",\"31.05\",\"0\",\"1\"],[\"64466.2\",\"58.23\",\"0\",\"2\"],[\"64466.1\",\"85.39\",\"0\",\"1\"],[\"64466\",\"37.25\",\"0\",\"5\"],[\"64465.6\",\"28.21\",\"0\",\"4\"],[\"64465.5\",\"232.9\",\"0\",\"1\"],[\"64465.4\",\"507.87\",\"0\",\"3\"],[\"64465.3\",\"46.58\",\"0\",\"4\"],[\"64464.9\",\"31.06\",\"0\",\"1\"],[\"64464.8\",\"0.01\",\"0\",\"1\"],[\"64464.5\",\"3.22\",\"0\",\"3\"],[\"64464.4\",\"0.01\",\"0\",\"1\"],[\"64464.2\",\"155.57\",\"0\",\"5\"],[\"64464\",\"200.06\",\"0\",\"5\"],[\"64463.9\",\"0.02\",\"0\",\"1\"],[\"64463.8\",\"347.78\",\"0\",\"2\"],[\"64463.7\",\"3.1\",\"0\",\"1\"],[\"64463.6\",\"0.13\",\"0\",\"2\"],[\"64463.5\",\"0.01\",\"0\",\"1\"],[\"64463.3\",\"46.54\",\"0\",\"1\"],[\"64463.1\",\"37.23\",\"0\",\"1\"],[\"64463\",\"0.02\",\"0\",\"2\"],[\"64462.8\",\"15.65\",\"0\",\"1\"],[\"64462.6\",\"0.01\",\"0\",\"1\"],[\"64462.4\",\"0.01\",\"0\",\"1\"],[\"64462.1\",\"11.33\",\"0\",\"1\"],[\"64462\",\"0.01\",\"0\",\"1\"],[\"64461.9\",\"0.01\",\"0\",\"1\"],[\"64461.7\",\"0.01\",\"0\",\"1\"],[\"64461.5\",\"0.02\",\"0\",\"2\"],[\"64461.4\",\"14.24\",\"0\",\"4\"],[\"64461.3\",\"496.57\",\"0\",\"2\"],[\"64461.2\",\"0.04\",\"0\",\"2\"],[\"64461.1\",\"46.56\",\"0\",\"2\"],[\"64460.9\",\"95.5\",\"0\",\"2\"],[\"64460.8\",\"154.63\",\"0\",\"4\"],[\"64460.7\",\"44.95\",\"0\",\"2\"],[\"64460.6\",\"0.01\",\"0\",\"1\"],[\"64460.3\",\"2.28\",\"0\",\"1\"],[\"64460.1\",\"3.91\",\"0\",\"2\"],[\"64460\",\"0.31\",\"0\",\"3\"],[\"64459.7\",\"0.01\",\"0\",\"1\"],[\"64459.6\",\"71.03\",\"0\",\"1\"],[\"64459.5\",\"15.65\",\"0\",\"1\"],[\"64459.4\",\"38.83\",\"0\",\"1\"],[\"64459.3\",\"39.02\",\"0\",\"3\"],[\"64459.2\",\"0.01\",\"0\",\"1\"],[\"64459.1\",\"46.54\",\"0\",\"1\"],[\"64458.9\",\"0.01\",\"0\",\"1\"],[\"64458.7\",\"18.13\",\"0\",\"2\"],[\"64458.6\",\"0.16\",\"0\",\"2\"],[\"64458.4\",\"2.61\",\"0\",\"2\"],[\"64458.3\",\"0.03\",\"0\",\"3\"],[\"64458\",\"76.93\",\"0\",\"2\"],[\"64457.9\",\"0.01\",\"0\",\"1\"],[\"64457.6\",\"0.01\",\"0\",\"1\"],[\"64457.5\",\"0.01\",\"0\",\"1\"],[\"64457.4\",\"11.19\",\"0\",\"2\"],[\"64457.2\",\"14.15\",\"0\",\"1\"],[\"64457.1\",\"415.22\",\"0\",\"3\"],[\"64457\",\"574.32\",\"0\",\"5\"],[\"64456.9\",\"0.02\",\"0\",\"1\"],[\"64456.6\",\"0.08\",\"0\",\"2\"],[\"64456.5\",\"8.31\",\"0\",\"2\"],[\"64456.4\",\"15.65\",\"0\",\"1\"],[\"64456.3\",\"37.24\",\"0\",\"2\"],[\"64456.2\",\"21.88\",\"0\",\"3\"],[\"64456.1\",\"249.79\",\"0\",\"3\"],[\"64456\",\"10.02\",\"0\",\"3\"],[\"64455.8\",\"15.66\",\"0\",\"2\"],[\"64455.7\",\"0.3\",\"0\",\"2\"],[\"64455.6\",\"37.69\",\"0\",\"2\"],[\"64455.5\",\"31.3\",\"0\",\"2\"],[\"64455.3\",\"56.54\",\"0\",\"2\"],[\"64455.2\",\"16.19\",\"0\",\"6\"],[\"64455\",\"285.9\",\"0\",\"2\"],[\"64454.9\",\"12.86\",\"0\",\"1\"],[\"64454.8\",\"10\",\"0\",\"1\"],[\"64454.7\",\"0.03\",\"0\",\"2\"],[\"64454.6\",\"31.31\",\"0\",\"3\"],[\"64454.5\",\"0.01\",\"0\",\"1\"],[\"64454.4\",\"62.16\",\"0\",\"2\"],[\"64454.3\",\"10\",\"0\",\"1\"],[\"64454.2\",\"38.83\",\"0\",\"1\"],[\"64454\",\"15.71\",\"0\",\"4\"],[\"64453.9\",\"38.83\",\"0\",\"1\"],[\"64453.8\",\"0.2\",\"0\",\"1\"],[\"64453.6\",\"0.04\",\"0\",\"2\"],[\"64453.4\",\"15.67\",\"0\",\"3\"],[\"64453.3\",\"0.12\",\"0\",\"12\"],[\"64453.1\",\"0.5\",\"0\",\"1\"],[\"64452.9\",\"16.71\",\"0\",\"2\"],[\"64452.8\",\"29.87\",\"0\",\"3\"],[\"64452.7\",\"309.36\",\"0\",\"3\"],[\"64452.6\",\"515.18\",\"0\",\"3\"],[\"64452.5\",\"31.32\",\"0\",\"4\"],[\"64452.3\",\"0.15\",\"0\",\"1\"],[\"64452.2\",\"15.65\",\"0\",\"1\"],[\"64452.1\",\"10.02\",\"0\",\"3\"],[\"64452\",\"10.31\",\"0\",\"6\"],[\"64451.8\",\"46.54\",\"0\",\"1\"],[\"64451.7\",\"201.97\",\"0\",\"3\"],[\"64451.6\",\"25.68\",\"0\",\"5\"],[\"64451.5\",\"61.97\",\"0\",\"2\"],[\"64451.3\",\"15.65\",\"0\",\"1\"],[\"64451.2\",\"0.01\",\"0\",\"1\"],[\"64451.1\",\"21.6\",\"0\",\"2\"],[\"64451\",\"0.02\",\"0\",\"2\"],[\"64450.8\",\"15.65\",\"0\",\"1\"],[\"64450.7\",\"0.04\",\"0\",\"2\"],[\"64450.6\",\"155.91\",\"0\",\"1\"],[\"64450.5\",\"0.01\",\"0\",\"1\"],[\"64450.4\",\"15.43\",\"0\",\"1\"],[\"64450.3\",\"0.03\",\"0\",\"2\"],[\"64450.1\",\"0.18\",\"0\",\"2\"],[\"64450\",\"22.84\",\"0\",\"20\"],[\"64449.9\",\"273.58\",\"0\",\"3\"],[\"64449.8\",\"83.77\",\"0\",\"2\"],[\"64449.7\",\"0.04\",\"0\",\"1\"],[\"64449.6\",\"15.65\",\"0\",\"1\"],[\"64449.5\",\"0.01\",\"0\",\"1\"],[\"64449.4\",\"0.01\",\"0\",\"1\"],[\"64449.3\",\"6.22\",\"0\",\"1\"],[\"64449.2\",\"15.65\",\"0\",\"1\"],[\"64449\",\"0.02\",\"0\",\"2\"],[\"64448.9\",\"0.52\",\"0\",\"2\"],[\"64448.8\",\"0.07\",\"0\",\"1\"],[\"64448.7\",\"18.87\",\"0\",\"1\"],[\"64448.5\",\"716.63\",\"0\",\"4\"],[\"64448.4\",\"5.06\",\"0\",\"3\"],[\"64448.3\",\"10.03\",\"0\",\"3\"],[\"64448\",\"493.83\",\"0\",\"8\"],[\"64447.8\",\"46.55\",\"0\",\"2\"],[\"64447.7\",\"16.53\",\"0\",\"2\"],[\"64447.6\",\"0.01\",\"0\",\"1\"],[\"64447.5\",\"0.01\",\"0\",\"1\"],[\"64447.1\",\"0.01\",\"0\",\"1\"],[\"64447\",\"15.65\",\"0\",\"1\"],[\"64446.8\",\"38.84\",\"0\",\"1\"],[\"64446.7\",\"6.22\",\"0\",\"3\"],[\"64446.6\",\"11.95\",\"0\",\"2\"],[\"64446.5\",\"0.02\",\"0\",\"2\"],[\"64446.3\",\"15.65\",\"0\",\"1\"],[\"64446.2\",\"42.38\",\"0\",\"2\"],[\"64446\",\"35.77\",\"0\",\"6\"],[\"64445.8\",\"0.01\",\"0\",\"1\"],[\"64445.7\",\"0.02\",\"0\",\"2\"],[\"64445.5\",\"357.5\",\"0\",\"1\"],[\"64445.4\",\"15.65\",\"0\",\"1\"],[\"64445.3\",\"10.03\",\"0\",\"4\"],[\"64445\",\"0.01\",\"0\",\"1\"],[\"64444.8\",\"10.32\",\"0\",\"3\"],[\"64444.7\",\"342.07\",\"0\",\"3\"],[\"64444.6\",\"496.54\",\"0\",\"2\"],[\"64444.5\",\"156.71\",\"0\",\"3\"],[\"64444.4\",\"37.26\",\"0\",\"3\"],[\"64444.3\",\"0.01\",\"0\",\"1\"],[\"64444.2\",\"10.01\",\"0\",\"2\"],[\"64444.1\",\"159.26\",\"0\",\"5\"],[\"64444\",\"15.67\",\"0\",\"3\"],[\"64443.9\",\"1.83\",\"0\",\"2\"],[\"64443.8\",\"0.01\",\"0\",\"1\"],[\"64443.7\",\"10\",\"0\",\"1\"],[\"64443.3\",\"0.02\",\"0\",\"2\"],[\"64443.2\",\"10.01\",\"0\",\"2\"],[\"64443\",\"15.66\",\"0\",\"2\"],[\"64442.8\",\"0.01\",\"0\",\"1\"],[\"64442.7\",\"0.01\",\"0\",\"1\"],[\"64442.6\",\"15.65\",\"0\",\"1\"],[\"64442.5\",\"10\",\"0\",\"1\"],[\"64442.1\",\"62.19\",\"0\",\"2\"],[\"64442\",\"15.01\",\"0\",\"2\"],[\"64441.9\",\"0.02\",\"0\",\"1\"],[\"64441.6\",\"35.81\",\"0\",\"4\"],[\"64441.4\",\"15.66\",\"0\",\"2\"],[\"64441.1\",\"1.57\",\"0\",\"1\"],[\"64440.5\",\"0.38\",\"0\",\"1\"],[\"64440.4\",\"6.23\",\"0\",\"2\"],[\"64440.3\",\"11.02\",\"0\",\"3\"],[\"64440.2\",\"354.51\",\"0\",\"2\"],[\"64440.1\",\"496.53\",\"0\",\"1\"],[\"64440\",\"23.47\",\"0\",\"18\"],[\"64439.9\",\"46.54\",\"0\",\"1\"],[\"64439.8\",\"92.79\",\"0\",\"1\"],[\"64439.7\",\"15.65\",\"0\",\"1\"],[\"64439.4\",\"93.87\",\"0\",\"2\"],[\"64439.1\",\"97.71\",\"0\",\"2\"],[\"64438.9\",\"0.01\",\"0\",\"1\"],[\"64438.8\",\"4.13\",\"0\",\"1\"],[\"64438.5\",\"0.01\",\"0\",\"1\"],[\"64438.4\",\"0.01\",\"0\",\"1\"],[\"64438.2\",\"304.51\",\"0\",\"2\"],[\"64438.1\",\"23.69\",\"0\",\"3\"],[\"64437.8\",\"46.55\",\"0\",\"2\"],[\"64437.6\",\"0.01\",\"0\",\"1\"],[\"64437.2\",\"15.46\",\"0\",\"2\"],[\"64437.1\",\"0.29\",\"0\",\"1\"],[\"64436.9\",\"0.01\",\"0\",\"1\"],[\"64436.8\",\"0.79\",\"0\",\"1\"],[\"64436.7\",\"0.54\",\"0\",\"2\"],[\"64436.6\",\"0.01\",\"0\",\"1\"],[\"64436.5\",\"11.29\",\"0\",\"1\"],[\"64436.4\",\"17.99\",\"0\",\"2\"],[\"64436.1\",\"10\",\"0\",\"1\"],[\"64435.9\",\"496.53\",\"0\",\"1\"],[\"64435.8\",\"247.26\",\"0\",\"4\"],[\"64435.6\",\"4.64\",\"0\",\"1\"],[\"64435.5\",\"0.02\",\"0\",\"1\"],[\"64435.2\",\"0.02\",\"0\",\"2\"],[\"64435.1\",\"0.01\",\"0\",\"1\"],[\"64435\",\"164.23\",\"0\",\"4\"],[\"64434.9\",\"0.05\",\"0\",\"1\"],[\"64434.8\",\"15.65\",\"0\",\"1\"],[\"64434.7\",\"56.54\",\"0\",\"2\"],[\"64434.6\",\"1.16\",\"0\",\"1\"],[\"64434.4\",\"20\",\"0\",\"1\"],[\"64434.3\",\"0.02\",\"0\",\"2\"],[\"64434.2\",\"0.01\",\"0\",\"1\"],[\"64434.1\",\"0.35\",\"0\",\"2\"],[\"64433.9\",\"37.23\",\"0\",\"1\"],[\"64433.8\",\"6.22\",\"0\",\"1\"],[\"64433.6\",\"0.77\",\"0\",\"1\"],[\"64433.4\",\"0.01\",\"0\",\"1\"],[\"64433.3\",\"0.04\",\"0\",\"2\"],[\"64433.2\",\"11.29\",\"0\",\"1\"],[\"64433.1\",\"15.65\",\"0\",\"1\"],[\"64433\",\"1.73\",\"0\",\"1\"],[\"64432.8\",\"0.01\",\"0\",\"1\"],[\"64432.6\",\"0.06\",\"0\",\"3\"],[\"64432.5\",\"0.01\",\"0\",\"1\"],[\"64432.3\",\"0.02\",\"0\",\"2\"],[\"64432.2\",\"61.75\",\"0\",\"2\"],[\"64432.1\",\"298.07\",\"0\",\"2\"],[\"64432\",\"263.28\",\"0\",\"4\"],[\"64431.9\",\"517.26\",\"0\",\"2\"],[\"64431.5\",\"15.65\",\"0\",\"1\"],[\"64431.4\",\"60.49\",\"0\",\"2\"],[\"64431.3\",\"92.79\",\"0\",\"1\"],[\"64431.1\",\"0.77\",\"0\",\"1\"],[\"64431\",\"4.06\",\"0\",\"17\"],[\"64430.8\",\"23.04\",\"0\",\"1\"],[\"64430.4\",\"93.91\",\"0\",\"2\"],[\"64430.3\",\"1.01\",\"0\",\"2\"],[\"64430.2\",\"15.73\",\"0\",\"2\"],[\"64430\",\"51.55\",\"0\",\"3\"],[\"64429.9\",\"12.37\",\"0\",\"4\"],[\"64429.8\",\"0.01\",\"0\",\"1\"],[\"64429.4\",\"0.02\",\"0\",\"1\"],[\"64429.2\",\"0.11\",\"0\",\"1\"],[\"64429.1\",\"0.02\",\"0\",\"1\"],[\"64428.9\",\"0.03\",\"0\",\"2\"],[\"64428.8\",\"0.01\",\"0\",\"1\"],[\"64428.6\",\"1.04\",\"0\",\"3\"],[\"64428.4\",\"37.23\",\"0\",\"1\"],[\"64428.2\",\"15.65\",\"0\",\"1\"],[\"64428.1\",\"0.65\",\"0\",\"2\"],[\"64428\",\"341.6\",\"0\",\"4\"],[\"64427.8\",\"543.07\",\"0\",\"2\"],[\"64427.7\",\"0.01\",\"0\",\"1\"],[\"64427.3\",\"6.23\",\"0\",\"2\"],[\"64427.2\",\"0.01\",\"0\",\"1\"],[\"64427\",\"266.81\",\"0\",\"5\"],[\"64426.8\",\"0.06\",\"0\",\"1\"],[\"64426.7\",\"0.12\",\"0\",\"12\"],[\"64426.6\",\"0.01\",\"0\",\"1\"],[\"64426.5\",\"0.04\",\"0\",\"1\"],[\"64426.1\",\"19.87\",\"0\",\"2\"],[\"64426\",\"0.02\",\"0\",\"1\"],[\"64425.7\",\"2.01\",\"0\",\"1\"],[\"64425.6\",\"3.91\",\"0\",\"2\"],[\"64425.5\",\"11.06\",\"0\",\"1\"],[\"64425.4\",\"0.07\",\"0\",\"1\"],[\"64425.3\",\"2\",\"0\",\"1\"],[\"64425\",\"1.87\",\"0\",\"7\"],[\"64424.9\",\"15.66\",\"0\",\"2\"],[\"64424.7\",\"1\",\"0\",\"1\"],[\"64424.6\",\"0.01\",\"0\",\"1\"],[\"64424.5\",\"378.91\",\"0\",\"1\"],[\"64424.4\",\"46.54\",\"0\",\"1\"],[\"64424.2\",\"0.01\",\"0\",\"1\"],[\"64424.1\",\"1\",\"0\",\"1\"],[\"64424\",\"3.64\",\"0\",\"5\"],[\"64423.9\",\"0.05\",\"0\",\"1\"],[\"64423.8\",\"294.11\",\"0\",\"4\"],[\"64423.4\",\"1.2\",\"0\",\"1\"],[\"64423.3\",\"512.29\",\"0\",\"3\"],[\"64423.2\",\"37.23\",\"0\",\"1\"],[\"64423.1\",\"94.01\",\"0\",\"3\"],[\"64423\",\"1.59\",\"0\",\"6\"],[\"64422.8\",\"1.21\",\"0\",\"2\"],[\"64422.7\",\"3.4\",\"0\",\"3\"],[\"64422.6\",\"1.22\",\"0\",\"3\"],[\"64422.4\",\"1365.48\",\"0\",\"3\"]],\"ts\":\"1782016041905\",\"checksum\":-1304454398,\"seqId\":325070087657,\"prevSeqId\":-1}]}"}
{"action": "update", "capture_sequence": 304, "channel": "books", "connection_sequence": 3, "event": null, "instId": "BTC-USDT-SWAP", "local_receive_ts": "2026-06-21T04:27:22Z", "monotonic_ns": 1643598039617900, "raw": "{\"arg\":{\"channel\":\"books\",\"instId\":\"BTC-USDT-SWAP\"},\"action\":\"update\",\"data\":[{\"asks\":[[\"64486\",\"52.64\",\"0\",\"6\"],[\"64486.2\",\"3.57\",\"0\",\"10\"],[\"64486.5\",\"1.57\",\"0\",\"2\"],[\"64487\",\"142.96\",\"0\",\"7\"],[\"64487.5\",\"1.6\",\"0\",\"4\"],[\"64488\",\"59.43\",\"0\",\"28\"],[\"64488.4\",\"7.23\",\"0\",\"7\"],[\"64488.9\",\"2.89\",\"0\",\"8\"],[\"64489.3\",\"3.25\",\"0\",\"4\"],[\"64489.4\",\"4.49\",\"0\",\"6\"],[\"64495\",\"1.5\",\"0\",\"9\"],[\"64495.8\",\"167.02\",\"0\",\"6\"],[\"64495.9\",\"0.84\",\"0\",\"3\"],[\"64500\",\"3456.86\",\"0\",\"1037\"],[\"64500.1\",\"0.05\",\"0\",\"4\"],[\"64506\",\"11.62\",\"0\",\"6\"],[\"64506.2\",\"0.03\",\"0\",\"2\"],[\"64506.4\",\"0.03\",\"0\",\"3\"],[\"64506.7\",\"0.5\",\"0\",\"16\"],[\"64507.7\",\"34.63\",\"0\",\"6\"],[\"64508.1\",\"0.82\",\"0\",\"3\"],[\"64508.7\",\"15.67\",\"0\",\"7\"],[\"64512\",\"2.88\",\"0\",\"13\"],[\"64512.4\",\"85.41\",\"0\",\"2\"],[\"64513.9\",\"58.3\",\"0\",\"2\"],[\"64514.5\",\"0.74\",\"0\",\"5\"],[\"64518.3\",\"20.08\",\"0\",\"3\"],[\"64518.8\",\"70.2\",\"0\",\"3\"],[\"64523.4\",\"39.43\",\"0\",\"5\"],[\"64525.5\",\"0.02\",\"0\",\"1\"]],\"bids\":[[\"64482.9\",\"1068.37\",\"0\",\"70\"],[\"64482.4\",\"1.59\",\"0\",\"3\"],[\"64481.9\",\"1.56\",\"0\",\"1\"],[\"64481.4\",\"13.57\",\"0\",\"4\"],[\"64474.1\",\"0.32\",\"0\",\"2\"],[\"64473.7\",\"0\",\"0\",\"0\"],[\"64469.3\",\"496.53\",\"0\",\"1\"],[\"64468.9\",\"34.11\",\"0\",\"2\"],[\"64468.3\",\"0\",\"0\",\"0\"],[\"64467.7\",\"20.08\",\"0\",\"1\"],[\"64466.9\",\"85.41\",\"0\",\"2\"],[\"64466.2\",\"0.01\",\"0\",\"1\"],[\"64466.1\",\"0\",\"0\",\"0\"],[\"64465.7\",\"58.22\",\"0\",\"1\"],[\"64464.7\",\"1\",\"0\",\"1\"],[\"64422.4\",\"0\",\"0\",\"0\"]],\"ts\":\"1782016042005\",\"checksum\":-277381997,\"seqId\":325070087716,\"prevSeqId\":325070087657}]}"}
{"action": "update", "capture_sequence": 305, "channel": "books", "connection_sequence": 3, "event": null, "instId": "BTC-USDT-SWAP", "local_receive_ts": "2026-06-21T04:27:22Z", "monotonic_ns": 1643598047581743, "raw": "{\"arg\":{\"channel\":\"books\",\"instId\":\"BTC-USDT-SWAP\"},\"action\":\"update\",\"data\":[{\"asks\":[[\"64485.1\",\"1.56\",\"0\",\"1\"],[\"64485.6\",\"0.01\",\"0\",\"1\"],[\"64485.7\",\"1.9\",\"0\",\"5\"],[\"64485.8\",\"0.42\",\"0\",\"4\"],[\"64486\",\"51.08\",\"0\",\"5\"],[\"64486.4\",\"2.83\",\"0\",\"3\"],[\"64486.5\",\"0.01\",\"0\",\"1\"],[\"64486.9\",\"96.16\",\"0\",\"4\"],[\"64487\",\"141.4\",\"0\",\"6\"],[\"64487.4\",\"2.06\",\"0\",\"7\"],[\"64487.5\",\"0.04\",\"0\",\"3\"],[\"64488\",\"57.87\",\"0\",\"27\"],[\"64488.4\",\"5.67\",\"0\",\"6\"],[\"64488.5\",\"1.56\",\"0\",\"1\"],[\"64488.9\",\"1.33\",\"0\",\"7\"],[\"64489.9\",\"2.56\",\"0\",\"2\"],[\"64490.3\",\"2.56\",\"0\",\"2\"],[\"64490.8\",\"2.78\",\"0\",\"3\"],[\"64494.8\",\"0.46\",\"0\",\"3\"],[\"64495\",\"1.49\",\"0\",\"8\"],[\"64497.8\",\"4.39\",\"0\",\"3\"],[\"64500\",\"3456.87\",\"0\",\"1038\"],[\"64500.4\",\"0.03\",\"0\",\"3\"],[\"64501.1\",\"0.05\",\"0\",\"2\"],[\"64501.8\",\"90.08\",\"0\",\"7\"],[\"64503.6\",\"31.05\",\"0\",\"3\"],[\"64503.8\",\"0\",\"0\",\"0\"],[\"64507.1\",\"0.83\",\"0\",\"5\"],[\"64507.6\",\"33.82\",\"0\",\"3\"],[\"64507.7\",\"0.07\",\"0\",\"4\"],[\"64512.3\",\"148.87\",\"0\",\"6\"],[\"64512.4\",\"0.08\",\"0\",\"1\"],[\"64515.7\",\"61.85\",\"0\",\"4\"],[\"64525\",\"2.66\",\"0\",\"19\"],[\"64527.3\",\"0\",\"0\",\"0\"],[\"64527.4\",\"0\",\"0\",\"0\"]],\"bids\":[[\"64482.5\",\"5.02\",\"0\",\"2\"],[\"64482.4\",\"1.57\",\"0\",\"2\"],[\"64482\",\"5.02\",\"0\",\"3\"],[\"64468.9\",\"0.3\",\"0\",\"1\"],[\"64468.8\",\"45.14\",\"0\",\"2\"],[\"64468.4\",\"0\",\"0\",\"0\"],[\"64468\",\"0.79\",\"0\",\"3\"],[\"64466.3\",\"0\",\"0\",\"0\"],[\"64466.1\",\"31.05\",\"0\",\"1\"],[\"64465.7\",\"0\",\"0\",\"0\"],[\"64465.6\",\"261.11\",\"0\",\"5\"],[\"64465.5\",\"58.22\",\"0\",\"1\"],[\"64465.4\",\"507.89\",\"0\",\"4\"],[\"64465.3\",\"46.56\",\"0\",\"3\"],[\"64422.4\",\"1365.48\",\"0\",\"3\"],[\"64422.3\",\"1.22\",\"0\",\"3\"]],\"ts\":\"1782016042105\",\"checksum\":-8037550,\"seqId\":325070087873,\"prevSeqId\":325070087716}]}"}
{"action": null, "capture_sequence": 306, "channel": "trades", "connection_sequence": 3, "event": null, "instId": "BTC-USDT-SWAP", "local_receive_ts": "2026-06-21T04:27:22Z", "monotonic_ns": 1643598053968509, "raw": "{\"arg\":{\"channel\":\"trades\",\"instId\":\"BTC-USDT-SWAP\"},\"data\":[{\"instId\":\"BTC-USDT-SWAP\",\"tradeId\":\"2718750311\",\"px\":\"64483\",\"sz\":\"5.05\",\"side\":\"buy\",\"ts\":\"1782016042149\",\"count\":\"6\",\"source\":\"0\",\"seqId\":325070087958}]}"}
{"action": "update", "capture_sequence": 307, "channel": "books", "connection_sequence": 3, "event": null, "instId": "BTC-USDT-SWAP", "local_receive_ts": "2026-06-21T04:27:22Z", "monotonic_ns": 1643598119807659, "raw": "{\"arg\":{\"channel\":\"books\",\"instId\":\"BTC-USDT-SWAP\"},\"action\":\"update\",\"data\":[{\"asks\":[[\"64483\",\"146.87\",\"0\",\"12\"],[\"64485.1\",\"0\",\"0\",\"0\"],[\"64485.6\",\"0\",\"0\",\"0\"],[\"64485.7\",\"0.34\",\"0\",\"4\"],[\"64485.8\",\"0.43\",\"0\",\"5\"],[\"64486.4\",\"1.27\",\"0\",\"2\"],[\"64486.9\",\"94.6\",\"0\",\"3\"],[\"64487.4\",\"0.5\",\"0\",\"6\"],[\"64487.8\",\"0.1\",\"0\",\"4\"],[\"64488.5\",\"0\",\"0\",\"0\"],[\"64488.8\",\"51.56\",\"0\",\"2\"],[\"64491.3\",\"2.77\",\"0\",\"3\"],[\"64491.8\",\"1.61\",\"0\",\"2\"],[\"64492.3\",\"1.59\",\"0\",\"2\"],[\"64492.7\",\"1.86\",\"0\",\"3\"],[\"64495.8\",\"34.99\",\"0\",\"4\"],[\"64497.2\",\"0.84\",\"0\",\"3\"],[\"64497.3\",\"41.29\",\"0\",\"5\"],[\"64497.4\",\"37.31\",\"0\",\"2\"],[\"64500\",\"3456.85\",\"0\",\"1036\"],[\"64500.1\",\"0.06\",\"0\",\"5\"],[\"64500.4\",\"0.04\",\"0\",\"4\"],[\"64501.3\",\"15.53\",\"0\",\"2\"],[\"64501.4\",\"0.01\",\"0\",\"1\"],[\"64504.3\",\"232.81\",\"0\",\"4\"],[\"64504.4\",\"1.13\",\"0\",\"4\"],[\"64506.7\",\"0.19\",\"0\",\"15\"],[\"64507\",\"0.37\",\"0\",\"2\"],[\"64507.1\",\"0.06\",\"0\",\"4\"],[\"64507.7\",\"0.84\",\"0\",\"5\"],[\"64508.7\",\"147.7\",\"0\",\"9\"],[\"64512.3\",\"63.54\",\"0\",\"5\"],[\"64512.5\",\"86.49\",\"0\",\"7\"],[\"64513.9\",\"0.12\",\"0\",\"1\"],[\"64514.6\",\"73.86\",\"0\",\"3\"],[\"64517.2\",\"0.77\",\"0\",\"6\"],[\"64518.3\",\"0.02\",\"0\",\"2\"],[\"64518.5\",\"20.07\",\"0\",\"2\"],[\"64518.9\",\"51.03\",\"0\",\"3\"],[\"64519.6\",\"4.76\",\"0\",\"3\"],[\"64522.1\",\"16.05\",\"0\",\"2\"],[\"64525\",\"2.51\",\"0\",\"18\"],[\"64525.4\",\"11.18\",\"0\",\"1\"],[\"64527.3\",\"0.05\",\"0\",\"5\"],[\"64527.4\",\"0.27\",\"0\",\"2\"],[\"64527.5\",\"0.19\",\"0\",\"5\"]],\"bids\":[[\"64482.9\",\"1074.58\",\"0\",\"71\"],[\"64477.3\",\"0\",\"0\",\"0\"],[\"64474.1\",\"6.54\",\"0\",\"3\"],[\"64470.5\",\"0.01\",\"0\",\"1\"],[\"64468.9\",\"1.07\",\"0\",\"2\"],[\"64468.8\",\"11.33\",\"0\",\"1\"],[\"64468.4\",\"33.81\",\"0\",\"1\"],[\"64468\",\"0.02\",\"0\",\"2\"],[\"64467.9\",\"20.09\",\"0\",\"2\"],[\"64467.7\",\"0\",\"0\",\"0\"],[\"64467.2\",\"85.39\",\"0\",\"1\"],[\"64466.9\",\"0.02\",\"0\",\"1\"],[\"64466.2\",\"58.23\",\"0\",\"2\"],[\"64465.6\",\"28.21\",\"0\",\"4\"],[\"64465.5\",\"232.9\",\"0\",\"1\"],[\"64464.5\",\"0.02\",\"0\",\"2\"],[\"64464.4\",\"3.14\",\"0\",\"2\"],[\"64464.2\",\"161.79\",\"0\",\"6\"]],\"ts\":\"1782016042205\",\"checksum\":469108410,\"seqId\":325070088108,\"prevSeqId\":325070087873}]}"}
{"action": null, "capture_sequence": 308, "channel": "trades", "connection_sequence": 3, "event": null, "instId": "BTC-USDT-SWAP", "local_receive_ts": "2026-06-21T04:27:22Z", "monotonic_ns": 1643598200102598, "raw": "{\"arg\":{\"channel\":\"trades\",\"instId\":\"BTC-USDT-SWAP\"},\"data\":[{\"instId\":\"BTC-USDT-SWAP\",\"tradeId\":\"2718750312\",\"px\":\"64483\",\"sz\":\"10.42\",\"side\":\"buy\",\"ts\":\"1782016042294\",\"count\":\"1\",\"source\":\"0\",\"seqId\":325070088440}]}"}
{"action": "update", "capture_sequence": 309, "channel": "books", "connection_sequence": 3, "event": null, "instId": "BTC-USDT-SWAP", "local_receive_ts": "2026-06-21T04:27:22Z", "monotonic_ns": 1643598227356746, "raw": "{\"arg\":{\"channel\":\"books\",\"instId\":\"BTC-USDT-SWAP\"},\"action\":\"update\",\"data\":[{\"asks\":[[\"64483\",\"85.02\",\"0\",\"9\"],[\"64484.9\",\"11.64\",\"0\",\"3\"],[\"64485.9\",\"5.43\",\"0\",\"2\"],[\"64486.2\",\"3.56\",\"0\",\"9\"],[\"64486.9\",\"80.86\",\"0\",\"4\"],[\"64487\",\"5.11\",\"0\",\"4\"],[\"64488\",\"57.86\",\"0\",\"26\"],[\"64488.7\",\"136.17\",\"0\",\"2\"],[\"64488.8\",\"50\",\"0\",\"1\"],[\"64489.4\",\"2.93\",\"0\",\"5\"],[\"64489.8\",\"24.12\",\"0\",\"4\"],[\"64489.9\",\"1\",\"0\",\"1\"],[\"64490.3\",\"1\",\"0\",\"1\"],[\"64490.6\",\"1.08\",\"0\",\"3\"],[\"64490.8\",\"1.22\",\"0\",\"2\"],[\"64491.3\",\"1.21\",\"0\",\"2\"],[\"64491.8\",\"0.05\",\"0\",\"1\"],[\"64492.3\",\"0.03\",\"0\",\"1\"],[\"64492.6\",\"0\",\"0\",\"0\"],[\"64492.7\",\"0.3\",\"0\",\"2\"],[\"64493.4\",\"14.99\",\"0\",\"8\"],[\"64493.5\",\"134.25\",\"0\",\"5\"],[\"64494.2\",\"0\",\"0\",\"0\"],[\"64494.8\",\"0.45\",\"0\",\"2\"],[\"64495.2\",\"4.02\",\"0\",\"3\"],[\"64495.3\",\"5.04\",\"0\",\"4\"],[\"64495.5\",\"37.49\",\"0\",\"7\"],[\"64496\",\"5.1\",\"0\",\"5\"],[\"64496.2\",\"15.96\",\"0\",\"1\"],[\"64496.6\",\"45.95\",\"0\",\"3\"],[\"64496.9\",\"0\",\"0\",\"0\"],[\"64497.4\",\"0.08\",\"0\",\"1\"],[\"64497.5\",\"0.45\",\"0\",\"4\"],[\"64497.8\",\"0.39\",\"0\",\"2\"],[\"64498.1\",\"0.03\",\"0\",\"3\"],[\"64498.8\",\"496.55\",\"0\",\"3\"],[\"64498.9\",\"3.42\",\"0\",\"2\"],[\"64499.2\",\"0.01\",\"0\",\"1\"],[\"64499.5\",\"46.54\",\"0\",\"1\"],[\"64499.6\",\"67.37\",\"0\",\"4\"],[\"64499.9\",\"1118.67\",\"0\",\"3\"],[\"64500\",\"3464.85\",\"0\",\"1037\"],[\"64500.3\",\"4.28\",\"0\",\"6\"],[\"64500.4\",\"0.21\",\"0\",\"5\"],[\"64500.8\",\"0.36\",\"0\",\"1\"],[\"64501.3\",\"0.02\",\"0\",\"1\"],[\"64501.4\",\"15.52\",\"0\",\"2\"],[\"64501.6\",\"13.89\",\"0\",\"5\"],[\"64501.8\",\"59.01\",\"0\",\"6\"],[\"64502.8\",\"10.53\",\"0\",\"2\"],[\"64503.6\",\"0.02\",\"0\",\"2\"],[\"64503.8\",\"31.03\",\"0\",\"1\"],[\"64503.9\",\"15.65\",\"0\",\"1\"],[\"64504.3\",\"0.05\",\"0\",\"3\"],[\"64504.4\",\"233.89\",\"0\",\"5\"],[\"64504.6\",\"1.5\",\"0\",\"1\"],[\"64505.9\",\"2.96\",\"0\",\"2\"],[\"64506\",\"10.07\",\"0\",\"5\"],[\"64506.1\",\"31.13\",\"0\",\"2\"],[\"64506.5\",\"17.27\",\"0\",\"3\"],[\"64507\",\"0.06\",\"0\",\"1\"],[\"64507.6\",\"0.03\",\"0\",\"2\"],[\"64507.7\",\"0.07\",\"0\",\"4\"],[\"64507.9\",\"0.58\",\"0\",\"5\"],[\"64508\",\"14.55\",\"0\",\"9\"],[\"64508.3\",\"0.77\",\"0\",\"1\"],[\"64508.9\",\"96.47\",\"0\",\"4\"],[\"64509\",\"15.66\",\"0\",\"2\"],[\"64510.2\",\"49.44\",\"0\",\"2\"],[\"64512.5\",\"1.16\",\"0\",\"6\"],[\"64512.6\",\"58.74\",\"0\",\"7\"],[\"64513.3\",\"24.68\",\"0\",\"10\"],[\"64514\",\"100.99\",\"0\",\"3\"],[\"64514.6\",\"15.68\",\"0\",\"2\"],[\"64518\",\"103.04\",\"0\",\"12\"],[\"64518.1\",\"58.32\",\"0\",\"6\"],[\"64518.5\",\"0.01\",\"0\",\"1\"],[\"64518.9\",\"4.54\",\"0\",\"2\"],[\"64519.7\",\"10.81\",\"0\",\"7\"],[\"64521.3\",\"20.07\",\"0\",\"2\"],[\"64522.1\",\"11.33\",\"0\",\"1\"],[\"64522.6\",\"87.64\",\"0\",\"4\"],[\"64523.4\",\"39.42\",\"0\",\"4\"],[\"64524.4\",\"0.01\",\"0\",\"1\"],[\"64527.5\",\"0\",\"0\",\"0\"]],\"bids\":[[\"64482.8\",\"48.75\",\"0\",\"13\"],[\"64480.1\",\"77.55\",\"0\",\"2\"],[\"64479.3\",\"0.01\",\"0\",\"1\"],[\"64478.6\",\"0.24\",\"0\",\"2\"],[\"64477.7\",\"59.77\",\"0\",\"6\"],[\"64477.1\",\"2.97\",\"0\",\"3\"],[\"64476.5\",\"19.92\",\"0\",\"3\"],[\"64475.3\",\"0\",\"0\",\"0\"],[\"64475.2\",\"0.31\",\"0\",\"1\"],[\"64474.8\",\"31.07\",\"0\",\"2\"],[\"64474.6\",\"0\",\"0\",\"0\"],[\"64474.1\",\"6.23\",\"0\",\"2\"],[\"64471.5\",\"86.17\",\"0\",\"2\"],[\"64471.4\",\"80.36\",\"0\",\"3\"],[\"64470.5\",\"20.09\",\"0\",\"2\"],[\"64470.4\",\"4\",\"0\",\"1\"],[\"64469.9\",\"95.77\",\"0\",\"3\"],[\"64469.7\",\"0.01\",\"0\",\"1\"],[\"64469.5\",\"1.16\",\"0\",\"3\"],[\"64468.9\",\"0.3\",\"0\",\"1\"],[\"64468.8\",\"96.72\",\"0\",\"2\"],[\"64468.4\",\"0\",\"0\",\"0\"],[\"64467.9\",\"0.01\",\"0\",\"1\"],[\"64467.2\",\"0\",\"0\",\"0\"],[\"64466.2\",\"0.01\",\"0\",\"1\"],[\"64464.9\",\"0\",\"0\",\"0\"],[\"64464\",\"0.06\",\"0\",\"4\"],[\"64461.9\",\"2.29\",\"0\",\"2\"],[\"64457.2\",\"0\",\"0\",\"0\"],[\"64457.1\",\"396.35\",\"0\",\"2\"],[\"64457\",\"527.72\",\"0\",\"4\"],[\"64448.6\",\"33.02\",\"0\",\"2\"],[\"64424\",\"1.36\",\"0\",\"4\"],[\"64423.5\",\"19.6\",\"0\",\"1\"],[\"64422.7\",\"22.42\",\"0\",\"4\"],[\"64422.2\",\"11.03\",\"0\",\"3\"],[\"64422\",\"1.21\",\"0\",\"2\"]],\"ts\":\"1782016042305\",\"checksum\":-586419546,\"seqId\":325070088483,\"prevSeqId\":325070088108}]}"}
{"action": null, "capture_sequence": 310, "channel": "trades", "connection_sequence": 3, "event": null, "instId": "BTC-USDT-SWAP", "local_receive_ts": "2026-06-21T04:27:22Z", "monotonic_ns": 1643598227689686, "raw": "{\"arg\":{\"channel\":\"trades\",\"instId\":\"BTC-USDT-SWAP\"},\"data\":[{\"instId\":\"BTC-USDT-SWAP\",\"tradeId\":\"2718750313\",\"px\":\"64483\",\"sz\":\"3.22\",\"side\":\"buy\",\"ts\":\"1782016042318\",\"count\":\"1\",\"source\":\"0\",\"seqId\":325070088531}]}"}
{"action": "update", "capture_sequence": 311, "channel": "books", "connection_sequence": 3, "event": null, "instId": "BTC-USDT-SWAP", "local_receive_ts": "2026-06-21T04:27:22Z", "monotonic_ns": 1643598317268959, "raw": "{\"arg\":{\"channel\":\"books\",\"instId\":\"BTC-USDT-SWAP\"},\"action\":\"update\",\"data\":[{\"asks\":[[\"64483\",\"117.65\",\"0\",\"10\"],[\"64486.2\",\"3.57\",\"0\",\"10\"],[\"64489.5\",\"2.58\",\"0\",\"4\"],[\"64490.7\",\"1.62\",\"0\",\"3\"],[\"64491.1\",\"1.56\",\"0\",\"1\"],[\"64491.6\",\"2.81\",\"0\",\"6\"],[\"64492.1\",\"3.06\",\"0\",\"2\"],[\"64492.6\",\"1.56\",\"0\",\"1\"],[\"64493.1\",\"2.01\",\"0\",\"3\"],[\"64494\",\"269.45\",\"0\",\"7\"],[\"64495.3\",\"5.03\",\"0\",\"3\"],[\"64495.6\",\"0.01\",\"0\",\"1\"],[\"64496.2\",\"62.5\",\"0\",\"2\"],[\"64496.4\",\"0.03\",\"0\",\"3\"],[\"64502.8\",\"57.07\",\"0\",\"3\"],[\"64504.1\",\"21.33\",\"0\",\"7\"],[\"64504.3\",\"0.04\",\"0\",\"2\"],[\"64505.5\",\"73.82\",\"0\",\"4\"],[\"64508.3\",\"33.79\",\"0\",\"1\"],[\"64508.4\",\"2.39\",\"0\",\"6\"],[\"64510.2\",\"15.65\",\"0\",\"1\"],[\"64513.9\",\"85.45\",\"0\",\"2\"],[\"64514\",\"15.66\",\"0\",\"2\"],[\"64514.1\",\"1.23\",\"0\",\"4\"],[\"64514.3\",\"10.11\",\"0\",\"6\"],[\"64515.1\",\"58.18\",\"0\",\"1\"],[\"64518.1\",\"0.15\",\"0\",\"5\"],[\"64519.2\",\"20.54\",\"0\",\"8\"],[\"64520.5\",\"86.14\",\"0\",\"4\"],[\"64521.3\",\"0.01\",\"0\",\"1\"],[\"64522.6\",\"1.54\",\"0\",\"3\"],[\"64524.4\",\"0\",\"0\",\"0\"],[\"64527.3\",\"0\",\"0\",\"0\"],[\"64527.4\",\"0\",\"0\",\"0\"]],\"bids\":[[\"64482.9\",\"1068.37\",\"0\",\"70\"],[\"64477.6\",\"1.59\",\"0\",\"3\"],[\"64476.2\",\"291.69\",\"0\",\"3\"],[\"64471.5\",\"0.01\",\"0\",\"1\"],[\"64471.4\",\"46.55\",\"0\",\"2\"],[\"64470.5\",\"0.01\",\"0\",\"1\"],[\"64470.4\",\"90.16\",\"0\",\"2\"],[\"64470.1\",\"395.28\",\"0\",\"1\"],[\"64469.9\",\"169.58\",\"0\",\"4\"],[\"64469.4\",\"80.35\",\"0\",\"2\"],[\"64468.8\",\"11.33\",\"0\",\"1\"],[\"64468.4\",\"20.08\",\"0\",\"1\"],[\"64468.3\",\"85.39\",\"0\",\"1\"],[\"64466.2\",\"58.23\",\"0\",\"2\"],[\"64448.7\",\"0\",\"0\",\"0\"],[\"64448.6\",\"0\",\"0\",\"0\"],[\"64448.5\",\"512.19\",\"0\",\"3\"],[\"64444.4\",\"37.24\",\"0\",\"2\"],[\"64440.1\",\"496.55\",\"0\",\"2\"],[\"64427.9\",\"18.87\",\"0\",\"1\"],[\"64426\",\"3.27\",\"0\",\"2\"],[\"64424.5\",\"0\",\"0\",\"0\"],[\"64422.6\",\"20.09\",\"0\",\"4\"],[\"64422.5\",\"14.15\",\"0\",\"1\"],[\"64422\",\"0\",\"0\",\"0\"]],\"ts\":\"1782016042405\",\"checksum\":-1163649811,\"seqId\":325070088688,\"prevSeqId\":325070088483}]}"}
{"action": null, "capture_sequence": 312, "channel": "trades", "connection_sequence": 3, "event": null, "instId": "BTC-USDT-SWAP", "local_receive_ts": "2026-06-21T04:27:22Z", "monotonic_ns": 1643598360330020, "raw": "{\"arg\":{\"channel\":\"trades\",\"instId\":\"BTC-USDT-SWAP\"},\"data\":[{\"instId\":\"BTC-USDT-SWAP\",\"tradeId\":\"2718750314\",\"px\":\"64482.9\",\"sz\":\"0.06\",\"side\":\"sell\",\"ts\":\"1782016042455\",\"count\":\"1\",\"source\":\"0\",\"seqId\":325070088719}]}"}
{"action": "update", "capture_sequence": 313, "channel": "books", "connection_sequence": 3, "event": null, "instId": "BTC-USDT-SWAP", "local_receive_ts": "2026-06-21T04:27:22Z", "monotonic_ns": 1643598416131094, "raw": "{\"arg\":{\"channel\":\"books\",\"instId\":\"BTC-USDT-SWAP\"},\"action\":\"update\",\"data\":[{\"asks\":[[\"64483\",\"128.27\",\"0\",\"12\"],[\"64490.8\",\"31.73\",\"0\",\"3\"],[\"64494\",\"238.94\",\"0\",\"6\"],[\"64495.6\",\"92.77\",\"0\",\"2\"],[\"64500.4\",\"0.04\",\"0\",\"4\"],[\"64500.9\",\"42.03\",\"0\",\"5\"],[\"64501.4\",\"0.01\",\"0\",\"1\"],[\"64502.5\",\"15.71\",\"0\",\"4\"],[\"64503.8\",\"0\",\"0\",\"0\"],[\"64504.4\",\"1.13\",\"0\",\"4\"],[\"64504.7\",\"31.04\",\"0\",\"2\"],[\"64505.1\",\"232.78\",\"0\",\"3\"],[\"64505.3\",\"1.17\",\"0\",\"3\"],[\"64505.5\",\"73.81\",\"0\",\"3\"],[\"64506.4\",\"1.58\",\"0\",\"4\"],[\"64506.5\",\"15.72\",\"0\",\"2\"],[\"64507.3\",\"0.34\",\"0\",\"3\"],[\"64507.7\",\"0.84\",\"0\",\"5\"],[\"64507.9\",\"0.27\",\"0\",\"4\"],[\"64508.4\",\"1.62\",\"0\",\"5\"],[\"64512.6\",\"144.07\",\"0\",\"8\"],[\"64513.9\",\"0.12\",\"0\",\"1\"],[\"64515\",\"200.04\",\"0\",\"3\"],[\"64518\",\"123.1\",\"0\",\"13\"],[\"64519.2\",\"0.48\",\"0\",\"7\"],[\"64527.3\",\"0.05\",\"0\",\"5\"]],\"bids\":[[\"64482.9\",\"1072.96\",\"0\",\"70\"],[\"64482.8\",\"27.14\",\"0\",\"12\"],[\"64482.4\",\"0.01\",\"0\",\"1\"],[\"64480.1\",\"0.01\",\"0\",\"1\"],[\"64479.9\",\"77.68\",\"0\",\"4\"],[\"64477.6\",\"1.57\",\"0\",\"2\"],[\"64476.4\",\"31.83\",\"0\",\"3\"],[\"64475.2\",\"0\",\"0\",\"0\"],[\"64474.6\",\"0.31\",\"0\",\"1\"],[\"64469.5\",\"0.39\",\"0\",\"2\"],[\"64468.4\",\"0.77\",\"0\",\"1\"],[\"64468.3\",\"0\",\"0\",\"0\"],[\"64467.6\",\"20.11\",\"0\",\"4\"],[\"64467.5\",\"31.08\",\"0\",\"3\"],[\"64467.2\",\"85.39\",\"0\",\"1\"],[\"64466.1\",\"0\",\"0\",\"0\"],[\"64465.7\",\"232.9\",\"0\",\"1\"],[\"64465.5\",\"0\",\"0\",\"0\"],[\"64449.5\",\"208.13\",\"0\",\"2\"],[\"64425.5\",\"399.49\",\"0\",\"2\"],[\"64422\",\"1.21\",\"0\",\"2\"]],\"ts\":\"1782016042505\",\"checksum\":9879595,\"seqId\":325070088748,\"prevSeqId\":325070088688}]}"}
{"action": "update", "capture_sequence": 314, "channel": "books", "connection_sequence": 3, "event": null, "instId": "BTC-USDT-SWAP", "local_receive_ts": "2026-06-21T04:27:22Z", "monotonic_ns": 1643598510958665, "raw": "{\"arg\":{\"channel\":\"books\",\"instId\":\"BTC-USDT-SWAP\"},\"action\":\"update\",\"data\":[{\"asks\":[[\"64483\",\"117.67\",\"0\",\"11\"],[\"64487.2\",\"77.57\",\"0\",\"3\"],[\"64504.3\",\"31.07\",\"0\",\"3\"],[\"64504.7\",\"0.01\",\"0\",\"1\"],[\"64506.8\",\"126.06\",\"0\",\"6\"],[\"64508.3\",\"0\",\"0\",\"0\"],[\"64511.3\",\"86.26\",\"0\",\"8\"],[\"64512.6\",\"58.74\",\"0\",\"7\"],[\"64527\",\"0.18\",\"0\",\"4\"],[\"64527.4\",\"0.27\",\"0\",\"2\"]],\"bids\":[[\"64482.5\",\"5\",\"0\",\"1\"],[\"64482.4\",\"0.03\",\"0\",\"2\"],[\"64469.4\",\"46.54\",\"0\",\"1\"],[\"64467.9\",\"33.82\",\"0\",\"2\"],[\"64467.5\",\"0.03\",\"0\",\"2\"],[\"64467.2\",\"0\",\"0\",\"0\"],[\"64466.9\",\"31.07\",\"0\",\"2\"],[\"64466.1\",\"85.39\",\"0\",\"1\"]],\"ts\":\"1782016042605\",\"checksum\":394865105,\"seqId\":325070088786,\"prevSeqId\":325070088748}]}"}
{"action": "update", "capture_sequence": 315, "channel": "books", "connection_sequence": 3, "event": null, "instId": "BTC-USDT-SWAP", "local_receive_ts": "2026-06-21T04:27:22Z", "monotonic_ns": 1643598610743045, "raw": "{\"arg\":{\"channel\":\"books\",\"instId\":\"BTC-USDT-SWAP\"},\"action\":\"update\",\"data\":[{\"asks\":[[\"64483\",\"138.28\",\"0\",\"13\"],[\"64488.8\",\"51.5\",\"0\",\"2\"],[\"64494.9\",\"13.57\",\"0\",\"6\"],[\"64496.3\",\"412.08\",\"0\",\"9\"],[\"64496.4\",\"0.02\",\"0\",\"2\"],[\"64500.3\",\"2.78\",\"0\",\"5\"],[\"64500.7\",\"4.08\",\"0\",\"2\"],[\"64500.9\",\"41.86\",\"0\",\"4\"],[\"64501.5\",\"17.08\",\"0\",\"5\"],[\"64502.5\",\"0.2\",\"0\",\"3\"],[\"64503.5\",\"65.32\",\"0\",\"7\"],[\"64504\",\"85.58\",\"0\",\"9\"],[\"64504.3\",\"0.04\",\"0\",\"2\"],[\"64504.6\",\"0\",\"0\",\"0\"],[\"64505.2\",\"15.66\",\"0\",\"2\"],[\"64505.3\",\"1.16\",\"0\",\"2\"],[\"64510.5\",\"60.8\",\"0\",\"5\"],[\"64511.3\",\"0.93\",\"0\",\"7\"],[\"64512\",\"202.88\",\"0\",\"14\"],[\"64512.4\",\"85.41\",\"0\",\"2\"],[\"64515\",\"0.04\",\"0\",\"2\"],[\"64518\",\"103.04\",\"0\",\"12\"],[\"64518.3\",\"20.08\",\"0\",\"3\"],[\"64522.1\",\"15.99\",\"0\",\"2\"],[\"64526.6\",\"14.24\",\"0\",\"5\"],[\"64527\",\"0.17\",\"0\",\"3\"],[\"64527.5\",\"0.19\",\"0\",\"5\"]],\"bids\":[[\"64467.9\",\"53.9\",\"0\",\"3\"],[\"64467.6\",\"0.03\",\"0\",\"3\"],[\"64466.9\",\"85.41\",\"0\",\"2\"],[\"64466.3\",\"31.05\",\"0\",\"1\"],[\"64466.1\",\"0\",\"0\",\"0\"],[\"64465\",\"200\",\"0\",\"1\"],[\"64444\",\"15.69\",\"0\",\"4\"],[\"64440.1\",\"496.53\",\"0\",\"1\"],[\"64422\",\"0\",\"0\",\"0\"]],\"ts\":\"1782016042705\",\"checksum\":-1657943334,\"seqId\":325070088845,\"prevSeqId\":325070088786}]}"}
{"action": "update", "capture_sequence": 316, "channel": "books", "connection_sequence": 3, "event": null, "instId": "BTC-USDT-SWAP", "local_receive_ts": "2026-06-21T04:27:22Z", "monotonic_ns": 1643598711165094, "raw": "{\"arg\":{\"channel\":\"books\",\"instId\":\"BTC-USDT-SWAP\"},\"action\":\"update\",\"data\":[{\"asks\":[[\"64483\",\"138.38\",\"0\",\"14\"],[\"64503.9\",\"18.62\",\"0\",\"2\"],[\"64505.9\",\"0.01\",\"0\",\"1\"],[\"64506.8\",\"92.27\",\"0\",\"5\"],[\"64508.4\",\"35.41\",\"0\",\"6\"],[\"64508.7\",\"15.67\",\"0\",\"7\"],[\"64513.3\",\"82.86\",\"0\",\"11\"],[\"64515.1\",\"0\",\"0\",\"0\"],[\"64527.1\",\"16\",\"0\",\"2\"],[\"64527.6\",\"16.48\",\"0\",\"5\"]],\"bids\":[[\"64482.9\",\"1066.75\",\"0\",\"69\"],[\"64469.6\",\"36.82\",\"0\",\"3\"],[\"64467.9\",\"0.01\",\"0\",\"1\"],[\"64467.7\",\"20.08\",\"0\",\"1\"],[\"64466.2\",\"0.01\",\"0\",\"1\"],[\"64465.1\",\"58.22\",\"0\",\"1\"],[\"64452\",\"10.16\",\"0\",\"5\"],[\"64438.9\",\"19.61\",\"0\",\"2\"],[\"64438.1\",\"42.71\",\"0\",\"4\"],[\"64438\",\"18.87\",\"0\",\"1\"],[\"64437.9\",\"14.15\",\"0\",\"1\"],[\"64437.8\",\"1411.73\",\"0\",\"3\"],[\"64423.5\",\"0\",\"0\",\"0\"],[\"64422.7\",\"3.4\",\"0\",\"3\"],[\"64422.6\",\"1.22\",\"0\",\"3\"],[\"64422.5\",\"0\",\"0\",\"0\"],[\"64422.4\",\"0.02\",\"0\",\"2\"],[\"64422.3\",\"0\",\"0\",\"0\"],[\"64422.2\",\"0\",\"0\",\"0\"]],\"ts\":\"1782016042805\",\"checksum\":1004124218,\"seqId\":325070088903,\"prevSeqId\":325070088845}]}"}
{"action": "update", "capture_sequence": 317, "channel": "books", "connection_sequence": 3, "event": null, "instId": "BTC-USDT-SWAP", "local_receive_ts": "2026-06-21T04:27:23Z", "monotonic_ns": 1643598810589761, "raw": "{\"arg\":{\"channel\":\"books\",\"instId\":\"BTC-USDT-SWAP\"},\"action\":\"update\",\"data\":[{\"asks\":[[\"64495.8\",\"167.02\",\"0\",\"6\"],[\"64500.5\",\"2.66\",\"0\",\"3\"],[\"64500.7\",\"3.91\",\"0\",\"1\"]],\"bids\":[[\"64482.9\",\"1067.2\",\"0\",\"70\"]],\"ts\":\"1782016042905\",\"checksum\":482920409,\"seqId\":325070088909,\"prevSeqId\":325070088903}]}"}
{"action": null, "capture_sequence": 318, "channel": "trades", "connection_sequence": 3, "event": null, "instId": "BTC-USDT-SWAP", "local_receive_ts": "2026-06-21T04:27:23Z", "monotonic_ns": 1643598840636908, "raw": "{\"arg\":{\"channel\":\"trades\",\"instId\":\"BTC-USDT-SWAP\"},\"data\":[{\"instId\":\"BTC-USDT-SWAP\",\"tradeId\":\"2718750315\",\"px\":\"64483\",\"sz\":\"5.5\",\"side\":\"buy\",\"ts\":\"1782016042935\",\"count\":\"1\",\"source\":\"0\",\"seqId\":325070089000}]}"}
{"action": "update", "capture_sequence": 319, "channel": "books", "connection_sequence": 3, "event": null, "instId": "BTC-USDT-SWAP", "local_receive_ts": "2026-06-21T04:27:23Z", "monotonic_ns": 1643598916182199, "raw": "{\"arg\":{\"channel\":\"books\",\"instId\":\"BTC-USDT-SWAP\"},\"action\":\"update\",\"data\":[{\"asks\":[[\"64483\",\"131.75\",\"0\",\"13\"],[\"64487.6\",\"1.56\",\"0\",\"1\"],[\"64488.1\",\"2.22\",\"0\",\"2\"],[\"64488.4\",\"141.8\",\"0\",\"7\"],[\"64488.6\",\"1.58\",\"0\",\"3\"],[\"64488.7\",\"0.04\",\"0\",\"1\"],[\"64488.9\",\"0.33\",\"0\",\"6\"],[\"64489.1\",\"1.6\",\"0\",\"4\"],[\"64489.5\",\"1.58\",\"0\",\"3\"],[\"64489.9\",\"0.16\",\"0\",\"1\"],[\"64490\",\"57.33\",\"0\",\"20\"],[\"64490.2\",\"0\",\"0\",\"0\"],[\"64490.5\",\"1.81\",\"0\",\"3\"],[\"64490.7\",\"0.06\",\"0\",\"2\"],[\"64490.8\",\"30.53\",\"0\",\"2\"],[\"64491.1\",\"0\",\"0\",\"0\"],[\"64491.3\",\"0.01\",\"0\",\"1\"],[\"64491.6\",\"2.25\",\"0\",\"6\"],[\"64491.7\",\"0.02\",\"0\",\"2\"],[\"64491.9\",\"0.3\",\"0\",\"4\"],[\"64492.1\",\"0\",\"0\",\"0\"],[\"64492.3\",\"1.23\",\"0\",\"2\"],[\"64492.8\",\"0.43\",\"0\",\"8\"],[\"64495.2\",\"0.02\",\"0\",\"2\"],[\"64495.8\",\"34.99\",\"0\",\"4\"],[\"64496.1\",\"46.6\",\"0\",\"4\"],[\"64496.2\",\"15.96\",\"0\",\"1\"],[\"64496.3\",\"349.92\",\"0\",\"7\"],[\"64496.4\",\"0.03\",\"0\",\"3\"],[\"64497.3\",\"41.3\",\"0\",\"5\"],[\"64497.9\",\"12.01\",\"0\",\"3\"],[\"64499.6\",\"59.37\",\"0\",\"3\"],[\"64500.6\",\"62.54\",\"0\",\"4\"],[\"64501.6\",\"1.89\",\"0\",\"3\"],[\"64503.2\",\"12.3\",\"0\",\"4\"],[\"64506.4\",\"0.03\",\"0\",\"3\"],[\"64507.1\",\"1.61\",\"0\",\"5\"],[\"64507.3\",\"0.03\",\"0\",\"2\"],[\"64508.1\",\"1.13\",\"0\",\"4\"],[\"64508.3\",\"33.79\",\"0\",\"1\"],[\"64508.4\",\"1.62\",\"0\",\"5\"],[\"64508.7\",\"147.7\",\"0\",\"9\"],[\"64513.3\",\"24.68\",\"0\",\"10\"],[\"64515.4\",\"58.64\",\"0\",\"6\"],[\"64516.7\",\"0.36\",\"0\",\"9\"],[\"64517.2\",\"0.76\",\"0\",\"5\"],[\"64518.3\",\"0.02\",\"0\",\"2\"],[\"64518.9\",\"24.6\",\"0\",\"3\"],[\"64520.4\",\"87.29\",\"0\",\"8\"],[\"64520.5\",\"0.04\",\"0\",\"3\"],[\"64526.6\",\"14.23\",\"0\",\"4\"],[\"64527.1\",\"0.46\",\"0\",\"1\"],[\"64527.7\",\"496.55\",\"0\",\"2\"]],\"bids\":[[\"64482.9\",\"1086.52\",\"0\",\"73\"],[\"64482.8\",\"48.28\",\"0\",\"13\"],[\"64482.4\",\"1.59\",\"0\",\"3\"],[\"64480.1\",\"77.55\",\"0\",\"2\"],[\"64479.9\",\"0.14\",\"0\",\"3\"],[\"64477.7\",\"47.77\",\"0\",\"4\"],[\"64477.6\",\"1.59\",\"0\",\"3\"],[\"64476.4\",\"31.81\",\"0\",\"2\"],[\"64475.2\",\"0.31\",\"0\",\"1\"],[\"64474.6\",\"0\",\"0\",\"0\"],[\"64470.4\",\"4\",\"0\",\"1\"],[\"64470.3\",\"13.93\",\"0\",\"4\"],[\"64470.2\",\"86.16\",\"0\",\"1\"],[\"64469.6\",\"3.01\",\"0\",\"2\"],[\"64469.5\",\"34.2\",\"0\",\"3\"],[\"64469.2\",\"157.65\",\"0\",\"4\"],[\"64469.1\",\"0.03\",\"0\",\"2\"],[\"64468.9\",\"1.07\",\"0\",\"2\"],[\"64468.4\",\"0\",\"0\",\"0\"],[\"64468.3\",\"20.08\",\"0\",\"1\"],[\"64467.7\",\"0\",\"0\",\"0\"],[\"64467.2\",\"143.61\",\"0\",\"2\"],[\"64466.9\",\"0.02\",\"0\",\"1\"],[\"64466.1\",\"2.28\",\"0\",\"1\"],[\"64465.1\",\"0\",\"0\",\"0\"],[\"64464.4\",\"3.23\",\"0\",\"2\"],[\"64452.7\",\"307.08\",\"0\",\"2\"],[\"64444\",\"15.67\",\"0\",\"3\"],[\"64443.9\",\"1.85\",\"0\",\"3\"],[\"64422.4\",\"0\",\"0\",\"0\"]],\"ts\":\"1782016043005\",\"checksum\":-1380608988,\"seqId\":325070089103,\"prevSeqId\":325070088909}]}"}
{"action": "update", "capture_sequence": 320, "channel": "books", "connection_sequence": 3, "event": null, "instId": "BTC-USDT-SWAP", "local_receive_ts": "2026-06-21T04:27:23Z", "monotonic_ns": 1643599011477210, "raw": "{\"arg\":{\"channel\":\"books\",\"instId\":\"BTC-USDT-SWAP\"},\"action\":\"update\",\"data\":[{\"asks\":[[\"64483\",\"131.77\",\"0\",\"14\"],[\"64485.3\",\"0.01\",\"0\",\"1\"],[\"64485.8\",\"0.42\",\"0\",\"4\"],[\"64486\",\"52.64\",\"0\",\"6\"],[\"64486.6\",\"10.3\",\"0\",\"3\"],[\"64487.1\",\"2.09\",\"0\",\"5\"],[\"64491.2\",\"5.01\",\"0\",\"3\"],[\"64491.9\",\"1.3\",\"0\",\"5\"],[\"64492.6\",\"1.2\",\"0\",\"1\"],[\"64493.1\",\"0.45\",\"0\",\"2\"],[\"64493.4\",\"16.19\",\"0\",\"9\"],[\"64493.8\",\"1.23\",\"0\",\"3\"],[\"64494\",\"240.14\",\"0\",\"7\"],[\"64497.9\",\"8.01\",\"0\",\"2\"],[\"64500.5\",\"2.49\",\"0\",\"2\"],[\"64500.6\",\"62.71\",\"0\",\"5\"],[\"64501.5\",\"1.57\",\"0\",\"4\"],[\"64502.1\",\"15.52\",\"0\",\"2\"],[\"64514.1\",\"59.41\",\"0\",\"5\"],[\"64515.4\",\"0.46\",\"0\",\"5\"],[\"64521.2\",\"46.49\",\"0\",\"1\"],[\"64527.6\",\"0\",\"0\",\"0\"],[\"64527.7\",\"0\",\"0\",\"0\"]],\"bids\":[[\"64482.9\",\"1080.31\",\"0\",\"72\"],[\"64482.5\",\"5.02\",\"0\",\"2\"],[\"64482.4\",\"1.57\",\"0\",\"2\"],[\"64467.2\",\"85.39\",\"0\",\"1\"],[\"64465.8\",\"58.22\",\"0\",\"1\"],[\"64422.6\",\"0\",\"0\",\"0\"]],\"ts\":\"1782016043105\",\"checksum\":657320030,\"seqId\":325070089185,\"prevSeqId\":325070089103}]}"}
{"action": "update", "capture_sequence": 321, "channel": "books", "connection_sequence": 3, "event": null, "instId": "BTC-USDT-SWAP", "local_receive_ts": "2026-06-21T04:27:23Z", "monotonic_ns": 1643599110521981, "raw": "{\"arg\":{\"channel\":\"books\",\"instId\":\"BTC-USDT-SWAP\"},\"action\":\"update\",\"data\":[{\"asks\":[[\"64485.3\",\"0\",\"0\",\"0\"],[\"64485.8\",\"0.43\",\"0\",\"5\"],[\"64486\",\"51.08\",\"0\",\"5\"],[\"64486.6\",\"8.74\",\"0\",\"2\"],[\"64490.5\",\"3.37\",\"0\",\"4\"],[\"64491\",\"1.01\",\"0\",\"2\"],[\"64492.9\",\"1.21\",\"0\",\"2\"],[\"64494.2\",\"1.5\",\"0\",\"1\"],[\"64520.7\",\"0\",\"0\",\"0\"],[\"64527.6\",\"16.48\",\"0\",\"5\"]],\"bids\":[[\"64482.9\",\"1080.47\",\"0\",\"73\"],[\"64468.7\",\"85.29\",\"0\",\"6\"]],\"ts\":\"1782016043205\",\"checksum\":967629408,\"seqId\":325070089228,\"prevSeqId\":325070089185}]}"}
{"action": "update", "capture_sequence": 322, "channel": "books", "connection_sequence": 3, "event": null, "instId": "BTC-USDT-SWAP", "local_receive_ts": "2026-06-21T04:27:23Z", "monotonic_ns": 1643599213582413, "raw": "{\"arg\":{\"channel\":\"books\",\"instId\":\"BTC-USDT-SWAP\"},\"action\":\"update\",\"data\":[{\"asks\":[[\"64484.9\",\"42.72\",\"0\",\"4\"],[\"64486.1\",\"1.57\",\"0\",\"2\"],[\"64486.8\",\"1.75\",\"0\",\"4\"],[\"64487.1\",\"0.53\",\"0\",\"4\"],[\"64487.5\",\"1.6\",\"0\",\"4\"],[\"64487.6\",\"0\",\"0\",\"0\"],[\"64488.1\",\"0.66\",\"0\",\"1\"],[\"64491\",\"2.57\",\"0\",\"3\"],[\"64491.5\",\"1.66\",\"0\",\"2\"],[\"64506.7\",\"0.96\",\"0\",\"16\"],[\"64506.9\",\"72.64\",\"0\",\"4\"],[\"64507.7\",\"0.07\",\"0\",\"4\"],[\"64508.3\",\"0\",\"0\",\"0\"],[\"64517.5\",\"20.06\",\"0\",\"1\"],[\"64518.9\",\"4.54\",\"0\",\"2\"],[\"64521.3\",\"148.8\",\"0\",\"2\"],[\"64526.5\",\"60.01\",\"0\",\"4\"],[\"64527.7\",\"496.55\",\"0\",\"2\"]],\"bids\":[[\"64482.9\",\"1098.71\",\"0\",\"75\"],[\"64482.8\",\"47.28\",\"0\",\"12\"],[\"64475.9\",\"195.45\",\"0\",\"3\"],[\"64469.5\",\"0.39\",\"0\",\"2\"],[\"64468.9\",\"0.3\",\"0\",\"1\"],[\"64468.3\",\"0\",\"0\",\"0\"],[\"64467.9\",\"33.82\",\"0\",\"2\"],[\"64467.5\",\"0.8\",\"0\",\"3\"],[\"64466.9\",\"20.1\",\"0\",\"2\"],[\"64422.6\",\"1.22\",\"0\",\"3\"]],\"ts\":\"1782016043305\",\"checksum\":-164407772,\"seqId\":325070089285,\"prevSeqId\":325070089228}]}"}
{"action": "update", "capture_sequence": 323, "channel": "books", "connection_sequence": 3, "event": null, "instId": "BTC-USDT-SWAP", "local_receive_ts": "2026-06-21T04:27:23Z", "monotonic_ns": 1643599315987321, "raw": "{\"arg\":{\"channel\":\"books\",\"instId\":\"BTC-USDT-SWAP\"},\"action\":\"update\",\"data\":[{\"asks\":[[\"64483\",\"131.79\",\"0\",\"15\"],[\"64483.3\",\"1.6\",\"0\",\"2\"],[\"64483.9\",\"0.02\",\"0\",\"2\"],[\"64484.5\",\"1.63\",\"0\",\"5\"],[\"64485.7\",\"1.9\",\"0\",\"5\"],[\"64485.8\",\"0.42\",\"0\",\"4\"],[\"64486.1\",\"0.01\",\"0\",\"1\"],[\"64486.3\",\"1.57\",\"0\",\"2\"],[\"64486.6\",\"144.87\",\"0\",\"3\"],[\"64487.9\",\"2.07\",\"0\",\"3\"],[\"64488\",\"57.87\",\"0\",\"27\"],[\"64488.4\",\"5.67\",\"0\",\"6\"],[\"64489.8\",\"35.55\",\"0\",\"5\"],[\"64490\",\"55.77\",\"0\",\"19\"],[\"64490.5\",\"1.81\",\"0\",\"3\"],[\"64491\",\"1.01\",\"0\",\"2\"],[\"64491.2\",\"18.59\",\"0\",\"4\"],[\"64491.5\",\"0.1\",\"0\",\"1\"],[\"64494.4\",\"0.6\",\"0\",\"6\"],[\"64495.8\",\"167.02\",\"0\",\"6\"],[\"64496.6\",\"31.68\",\"0\",\"2\"],[\"64497.8\",\"0.01\",\"0\",\"1\"],[\"64500.6\",\"62.54\",\"0\",\"4\"],[\"64500.7\",\"4.08\",\"0\",\"2\"],[\"64501.4\",\"15.52\",\"0\",\"2\"],[\"64501.7\",\"3.6\",\"0\",\"5\"],[\"64502.1\",\"0.01\",\"0\",\"1\"],[\"64503.9\",\"15.65\",\"0\",\"1\"],[\"64507\",\"0.37\",\"0\",\"2\"],[\"64508.1\",\"0.82\",\"0\",\"3\"],[\"64508.7\",\"15.67\",\"0\",\"7\"],[\"64511.9\",\"58.32\",\"0\",\"2\"],[\"64514.1\",\"1.23\",\"0\",\"4\"]],\"bids\":[[\"64482.9\",\"1097.16\",\"0\",\"74\"],[\"64482.5\",\"5\",\"0\",\"1\"],[\"64482.4\",\"0.03\",\"0\",\"2\"],[\"64482.2\",\"0.01\",\"0\",\"1\"],[\"64482\",\"6.57\",\"0\",\"3\"],[\"64481.9\",\"0\",\"0\",\"0\"],[\"64481.5\",\"1.57\",\"0\",\"2\"],[\"64481.4\",\"12.01\",\"0\",\"3\"],[\"64481\",\"1.56\",\"0\",\"1\"],[\"64480.5\",\"1.56\",\"0\",\"1\"],[\"64480\",\"110.29\",\"0\",\"7\"],[\"64479.5\",\"1.56\",\"0\",\"1\"],[\"64477.1\",\"0.02\",\"0\",\"2\"],[\"64475.2\",\"0\",\"0\",\"0\"],[\"64474.8\",\"34.12\",\"0\",\"3\"],[\"64474.2\",\"0.31\",\"0\",\"1\"],[\"64465.8\",\"0\",\"0\",\"0\"],[\"64463.4\",\"58.22\",\"0\",\"1\"],[\"64422.8\",\"0\",\"0\",\"0\"],[\"64422.7\",\"0\",\"0\",\"0\"],[\"64422.6\",\"0\",\"0\",\"0\"]],\"ts\":\"1782016043405\",\"checksum\":-1364702433,\"seqId\":325070089387,\"prevSeqId\":325070089285}]}"}
{"action": "update", "capture_sequence": 324, "channel": "books", "connection_sequence": 3, "event": null, "instId": "BTC-USDT-SWAP", "local_receive_ts": "2026-06-21T04:27:23Z", "monotonic_ns": 1643599415781217, "raw": "{\"arg\":{\"channel\":\"books\",\"instId\":\"BTC-USDT-SWAP\"},\"action\":\"update\",\"data\":[{\"asks\":[[\"64483\",\"283.25\",\"0\",\"20\"],[\"64483.1\",\"2.19\",\"0\",\"5\"],[\"64483.3\",\"0.04\",\"0\",\"1\"],[\"64483.5\",\"0.01\",\"0\",\"1\"],[\"64483.6\",\"1.56\",\"0\",\"1\"],[\"64483.9\",\"0.01\",\"0\",\"1\"],[\"64484.3\",\"0.01\",\"0\",\"1\"],[\"64484.4\",\"1.56\",\"0\",\"1\"],[\"64484.5\",\"0.07\",\"0\",\"4\"],[\"64484.9\",\"44.27\",\"0\",\"4\"],[\"64489.1\",\"0.04\",\"0\",\"3\"],[\"64489.5\",\"0.02\",\"0\",\"2\"],[\"64495\",\"1.5\",\"0\",\"9\"],[\"64496.4\",\"0.02\",\"0\",\"2\"],[\"64504.3\",\"0.05\",\"0\",\"3\"],[\"64505.2\",\"15.65\",\"0\",\"1\"],[\"64505.9\",\"1.56\",\"0\",\"2\"],[\"64507.1\",\"0.06\",\"0\",\"4\"],[\"64511.2\",\"85.35\",\"0\",\"3\"],[\"64512.4\",\"0.08\",\"0\",\"1\"],[\"64519.7\",\"96.91\",\"0\",\"8\"],[\"64520.4\",\"1.19\",\"0\",\"7\"],[\"64523.8\",\"0.03\",\"0\",\"2\"],[\"64526.5\",\"60\",\"0\",\"3\"],[\"64527.4\",\"0\",\"0\",\"0\"],[\"64527.5\",\"0\",\"0\",\"0\"],[\"64527.6\",\"0\",\"0\",\"0\"],[\"64527.7\",\"0\",\"0\",\"0\"]],\"bids\":[[\"64482.9\",\"1017.33\",\"0\",\"72\"],[\"64482.8\",\"26.14\",\"0\",\"11\"],[\"64482\",\"5.01\",\"0\",\"2\"],[\"64481.5\",\"0.01\",\"0\",\"1\"],[\"64481\",\"0\",\"0\",\"0\"],[\"64480.5\",\"0\",\"0\",\"0\"],[\"64480.1\",\"0.01\",\"0\",\"1\"],[\"64479.6\",\"77.56\",\"0\",\"3\"],[\"64478.1\",\"13.95\",\"0\",\"1\"],[\"64477.6\",\"1.57\",\"0\",\"2\"],[\"64476.3\",\"36.44\",\"0\",\"5\"],[\"64470.2\",\"0\",\"0\",\"0\"],[\"64469.9\",\"255.75\",\"0\",\"5\"],[\"64469.2\",\"157.67\",\"0\",\"5\"],[\"64469.1\",\"0.01\",\"0\",\"1\"],[\"64467.2\",\"0\",\"0\",\"0\"],[\"64465.8\",\"85.39\",\"0\",\"1\"],[\"64444\",\"15.69\",\"0\",\"4\"],[\"64443.9\",\"1.83\",\"0\",\"2\"],[\"64422.8\",\"1.21\",\"0\",\"2\"],[\"64422.7\",\"3.4\",\"0\",\"3\"]],\"ts\":\"1782016043505\",\"checksum\":-210891528,\"seqId\":325070089481,\"prevSeqId\":325070089387}]}"}
{"action": null, "capture_sequence": 325, "channel": "trades", "connection_sequence": 3, "event": null, "instId": "BTC-USDT-SWAP", "local_receive_ts": "2026-06-21T04:27:23Z", "monotonic_ns": 1643599418915724, "raw": "{\"arg\":{\"channel\":\"trades\",\"instId\":\"BTC-USDT-SWAP\"},\"data\":[{\"instId\":\"BTC-USDT-SWAP\",\"tradeId\":\"2718750316\",\"px\":\"64483\",\"sz\":\"1.43\",\"side\":\"buy\",\"ts\":\"1782016043513\",\"count\":\"1\",\"source\":\"0\",\"seqId\":325070089487}]}"}
{"action": null, "capture_sequence": 326, "channel": "trades", "connection_sequence": 3, "event": null, "instId": "BTC-USDT-SWAP", "local_receive_ts": "2026-06-21T04:27:23Z", "monotonic_ns": 1643599484932302, "raw": "{\"arg\":{\"channel\":\"trades\",\"instId\":\"BTC-USDT-SWAP\"},\"data\":[{\"instId\":\"BTC-USDT-SWAP\",\"tradeId\":\"2718750317\",\"px\":\"64482.9\",\"sz\":\"0.06\",\"side\":\"sell\",\"ts\":\"1782016043580\",\"count\":\"1\",\"source\":\"0\",\"seqId\":325070089530}]}"}
{"action": null, "capture_sequence": 327, "channel": "trades", "connection_sequence": 3, "event": null, "instId": "BTC-USDT-SWAP", "local_receive_ts": "2026-06-21T04:27:23Z", "monotonic_ns": 1643599489910684, "raw": "{\"arg\":{\"channel\":\"trades\",\"instId\":\"BTC-USDT-SWAP\"},\"data\":[{\"instId\":\"BTC-USDT-SWAP\",\"tradeId\":\"2718750318\",\"px\":\"64482.9\",\"sz\":\"1\",\"side\":\"sell\",\"ts\":\"1782016043584\",\"count\":\"1\",\"source\":\"0\",\"seqId\":325070089535}]}"}
{"action": null, "capture_sequence": 328, "channel": "trades", "connection_sequence": 3, "event": null, "instId": "BTC-USDT-SWAP", "local_receive_ts": "2026-06-21T04:27:23Z", "monotonic_ns": 1643599499798428, "raw": "{\"arg\":{\"channel\":\"trades\",\"instId\":\"BTC-USDT-SWAP\"},\"data\":[{\"instId\":\"BTC-USDT-SWAP\",\"tradeId\":\"2718750319\",\"px\":\"64482.9\",\"sz\":\"0.5\",\"side\":\"sell\",\"ts\":\"1782016043594\",\"count\":\"1\",\"source\":\"0\",\"seqId\":325070089546}]}"}
{"action": "update", "capture_sequence": 329, "channel": "books", "connection_sequence": 3, "event": null, "instId": "BTC-USDT-SWAP", "local_receive_ts": "2026-06-21T04:27:23Z", "monotonic_ns": 1643599510577532, "raw": "{\"arg\":{\"channel\":\"books\",\"instId\":\"BTC-USDT-SWAP\"},\"action\":\"update\",\"data\":[{\"asks\":[[\"64483\",\"406.57\",\"0\",\"21\"],[\"64483.1\",\"0.63\",\"0\",\"4\"],[\"64483.5\",\"0\",\"0\",\"0\"],[\"64483.6\",\"0\",\"0\",\"0\"],[\"64484.3\",\"0\",\"0\",\"0\"],[\"64484.4\",\"0\",\"0\",\"0\"],[\"64484.9\",\"42.72\",\"0\",\"4\"],[\"64485.6\",\"0.01\",\"0\",\"1\"],[\"64486.5\",\"91.05\",\"0\",\"2\"],[\"64486.9\",\"0.12\",\"0\",\"2\"],[\"64487.2\",\"0.03\",\"0\",\"2\"],[\"64489.9\",\"0\",\"0\",\"0\"],[\"64493.8\",\"2.21\",\"0\",\"4\"],[\"64498.4\",\"0.17\",\"0\",\"1\"],[\"64500\",\"3463.87\",\"0\",\"1036\"],[\"64500.7\",\"3.91\",\"0\",\"1\"],[\"64527.4\",\"0.27\",\"0\",\"2\"],[\"64527.5\",\"0.19\",\"0\",\"5\"],[\"64527.6\",\"16.48\",\"0\",\"5\"]],\"bids\":[[\"64482.9\",\"1016.9\",\"0\",\"72\"],[\"64482.8\",\"26.27\",\"0\",\"12\"],[\"64480\",\"108.73\",\"0\",\"6\"],[\"64479.6\",\"0.02\",\"0\",\"2\"],[\"64479.5\",\"0\",\"0\",\"0\"],[\"64479.3\",\"77.55\",\"0\",\"2\"],[\"64468.7\",\"79.09\",\"0\",\"5\"],[\"64464.7\",\"0\",\"0\",\"0\"],[\"64422.6\",\"1.22\",\"0\",\"3\"],[\"64422.4\",\"0.02\",\"0\",\"2\"]],\"ts\":\"1782016043605\",\"checksum\":262933347,\"seqId\":325070089555,\"prevSeqId\":325070089481}]}"}
{"action": "update", "capture_sequence": 330, "channel": "books", "connection_sequence": 3, "event": null, "instId": "BTC-USDT-SWAP", "local_receive_ts": "2026-06-21T04:27:23Z", "monotonic_ns": 1643599611161947, "raw": "{\"arg\":{\"channel\":\"books\",\"instId\":\"BTC-USDT-SWAP\"},\"action\":\"update\",\"data\":[{\"asks\":[[\"64495.8\",\"34.99\",\"0\",\"4\"]],\"bids\":[[\"64464.7\",\"1\",\"0\",\"1\"],[\"64422.4\",\"0\",\"0\",\"0\"]],\"ts\":\"1782016043705\",\"checksum\":262933347,\"seqId\":325070089631,\"prevSeqId\":325070089555}]}"}
{"action": "update", "capture_sequence": 331, "channel": "books", "connection_sequence": 3, "event": null, "instId": "BTC-USDT-SWAP", "local_receive_ts": "2026-06-21T04:27:23Z", "monotonic_ns": 1643599710371240, "raw": "{\"arg\":{\"channel\":\"books\",\"instId\":\"BTC-USDT-SWAP\"},\"action\":\"update\",\"data\":[{\"asks\":[[\"64483\",\"420.85\",\"0\",\"21\"],[\"64491.2\",\"14.59\",\"0\",\"3\"],[\"64494.6\",\"24.97\",\"0\",\"7\"],[\"64495.8\",\"167.02\",\"0\",\"6\"],[\"64497\",\"18.99\",\"0\",\"7\"],[\"64498\",\"24.62\",\"0\",\"4\"],[\"64498.4\",\"0\",\"0\",\"0\"],[\"64508.9\",\"178.47\",\"0\",\"5\"],[\"64517.2\",\"0.77\",\"0\",\"6\"],[\"64527.7\",\"496.55\",\"0\",\"2\"]],\"bids\":[[\"64482.8\",\"27.97\",\"0\",\"13\"],[\"64482.2\",\"0\",\"0\",\"0\"],[\"64479.4\",\"0.01\",\"0\",\"1\"]],\"ts\":\"1782016043805\",\"checksum\":-1985674988,\"seqId\":325070089717,\"prevSeqId\":325070089631}]}"}
{"action": null, "capture_sequence": 332, "channel": "trades", "connection_sequence": 3, "event": null, "instId": "BTC-USDT-SWAP", "local_receive_ts": "2026-06-21T04:27:23Z", "monotonic_ns": 1643599750794042, "raw": "{\"arg\":{\"channel\":\"trades\",\"instId\":\"BTC-USDT-SWAP\"},\"data\":[{\"instId\":\"BTC-USDT-SWAP\",\"tradeId\":\"2718750321\",\"px\":\"64482.9\",\"sz\":\"1.05\",\"side\":\"sell\",\"ts\":\"1782016043846\",\"count\":\"2\",\"source\":\"0\",\"seqId\":325070089755}]}"}
{"action": "update", "capture_sequence": 333, "channel": "books", "connection_sequence": 3, "event": null, "instId": "BTC-USDT-SWAP", "local_receive_ts": "2026-06-21T04:27:24Z", "monotonic_ns": 1643599810539580, "raw": "{\"arg\":{\"channel\":\"books\",\"instId\":\"BTC-USDT-SWAP\"},\"action\":\"update\",\"data\":[{\"asks\":[[\"64483\",\"484.82\",\"0\",\"24\"],[\"64484.9\",\"31.1\",\"0\",\"3\"],[\"64517.2\",\"0.76\",\"0\",\"5\"]],\"bids\":[[\"64482.9\",\"1019.85\",\"0\",\"72\"],[\"64472.8\",\"0.38\",\"0\",\"1\"],[\"64469.5\",\"0.01\",\"0\",\"1\"],[\"64422.6\",\"0\",\"0\",\"0\"]],\"ts\":\"1782016043905\",\"checksum\":709077291,\"seqId\":325070089798,\"prevSeqId\":325070089717}]}"}
{"action": null, "capture_sequence": 334, "channel": "trades", "connection_sequence": 3, "event": null, "instId": "BTC-USDT-SWAP", "local_receive_ts": "2026-06-21T04:27:24Z", "monotonic_ns": 1643599866501267, "raw": "{\"arg\":{\"channel\":\"trades\",\"instId\":\"BTC-USDT-SWAP\"},\"data\":[{\"instId\":\"BTC-USDT-SWAP\",\"tradeId\":\"2718750322\",\"px\":\"64482.9\",\"sz\":\"0.15\",\"side\":\"sell\",\"ts\":\"1782016043961\",\"count\":\"1\",\"source\":\"0\",\"seqId\":325070090112}]}"}
{"action": "update", "capture_sequence": 335, "channel": "books", "connection_sequence": 3, "event": null, "instId": "BTC-USDT-SWAP", "local_receive_ts": "2026-06-21T04:27:24Z", "monotonic_ns": 1643599927503897, "raw": "{\"arg\":{\"channel\":\"books\",\"instId\":\"BTC-USDT-SWAP\"},\"action\":\"update\",\"data\":[{\"asks\":[[\"64483\",\"799.66\",\"0\",\"36\"],[\"64483.1\",\"0.64\",\"0\",\"5\"],[\"64483.3\",\"0.44\",\"0\",\"2\"],[\"64483.4\",\"0.01\",\"0\",\"1\"],[\"64483.5\",\"1.56\",\"0\",\"1\"],[\"64484\",\"0.56\",\"0\",\"4\"],[\"64484.5\",\"39.62\",\"0\",\"6\"],[\"64484.8\",\"0\",\"0\",\"0\"],[\"64484.9\",\"0.02\",\"0\",\"2\"],[\"64486\",\"51.09\",\"0\",\"6\"],[\"64486.2\",\"16.53\",\"0\",\"10\"],[\"64486.3\",\"12.58\",\"0\",\"3\"],[\"64486.6\",\"0.99\",\"0\",\"1\"],[\"64489.2\",\"247.47\",\"0\",\"3\"],[\"64489.6\",\"11.12\",\"0\",\"2\"],[\"64489.7\",\"38.03\",\"0\",\"2\"],[\"64489.8\",\"34.36\",\"0\",\"4\"],[\"64491.2\",\"9.01\",\"0\",\"3\"],[\"64491.9\",\"1.42\",\"0\",\"6\"],[\"64492.6\",\"1.32\",\"0\",\"2\"],[\"64493.4\",\"16.51\",\"0\",\"10\"],[\"64493.5\",\"186.04\",\"0\",\"6\"],[\"64493.9\",\"46.54\",\"0\",\"1\"],[\"64494.3\",\"3.38\",\"0\",\"5\"],[\"64495\",\"1.49\",\"0\",\"8\"],[\"64495.5\",\"37.37\",\"0\",\"6\"],[\"64496.9\",\"0.17\",\"0\",\"1\"],[\"64497\",\"18.82\",\"0\",\"6\"],[\"64497.3\",\"41.29\",\"0\",\"5\"],[\"64497.5\",\"0.33\",\"0\",\"3\"],[\"64497.9\",\"15.52\",\"0\",\"2\"],[\"64498.6\",\"3.39\",\"0\",\"7\"],[\"64499.6\",\"62.17\",\"0\",\"3\"],[\"64500\",\"3463.89\",\"0\",\"1038\"],[\"64500.1\",\"0.05\",\"0\",\"4\"],[\"64500.4\",\"31.06\",\"0\",\"4\"],[\"64501.4\",\"0.01\",\"0\",\"1\"],[\"64501.7\",\"233.32\",\"0\",\"5\"],[\"64502.4\",\"1.74\",\"0\",\"7\"],[\"64502.5\",\"0.51\",\"0\",\"4\"],[\"64502.9\",\"280.73\",\"0\",\"8\"],[\"64503.1\",\"40.46\",\"0\",\"9\"],[\"64503.6\",\"33.81\",\"0\",\"3\"],[\"64504\",\"54.55\",\"0\",\"8\"],[\"64504.3\",\"0.04\",\"0\",\"2\"],[\"64505.1\",\"0.02\",\"0\",\"2\"],[\"64505.9\",\"0.01\",\"0\",\"1\"],[\"64506.7\",\"0.19\",\"0\",\"15\"],[\"64506.9\",\"38.85\",\"0\",\"3\"],[\"64507\",\"0.06\",\"0\",\"1\"],[\"64507.3\",\"58.21\",\"0\",\"3\"],[\"64507.9\",\"85.61\",\"0\",\"5\"],[\"64510.4\",\"0.03\",\"0\",\"3\"],[\"64511.2\",\"0.02\",\"0\",\"2\"],[\"64511.9\",\"0.14\",\"0\",\"1\"],[\"64513.5\",\"48.1\",\"0\",\"5\"],[\"64514.3\",\"30.18\",\"0\",\"7\"],[\"64515.4\",\"86.57\",\"0\",\"6\"],[\"64517.5\",\"0\",\"0\",\"0\"],[\"64519.7\",\"10.81\",\"0\",\"7\"],[\"64521.2\",\"0\",\"0\",\"0\"],[\"64521.3\",\"0.01\",\"0\",\"1\"],[\"64522.8\",\"15.72\",\"0\",\"5\"],[\"64523.8\",\"0.02\",\"0\",\"1\"],[\"64524\",\"0.05\",\"0\",\"4\"],[\"64526\",\"1.3\",\"0\",\"4\"],[\"64527.6\",\"0\",\"0\",\"0\"],[\"64527.7\",\"0\",\"0\",\"0\"]],\"bids\":[[\"64482.9\",\"370.36\",\"0\",\"34\"],[\"64482.8\",\"5.65\",\"0\",\"12\"],[\"64482.6\",\"3.29\",\"0\",\"2\"],[\"64482.5\",\"0\",\"0\",\"0\"],[\"64482.1\",\"0.02\",\"0\",\"1\"],[\"64482\",\"0\",\"0\",\"0\"],[\"64481.5\",\"0\",\"0\",\"0\"],[\"64481.4\",\"0.01\",\"0\",\"1\"],[\"64481.3\",\"0.03\",\"0\",\"2\"],[\"64481.2\",\"0.8\",\"0\",\"1\"],[\"64480.6\",\"0.01\",\"0\",\"1\"],[\"64480\",\"7.94\",\"0\",\"3\"],[\"64479.9\",\"0.13\",\"0\",\"2\"],[\"64479.8\",\"0.01\",\"0\",\"1\"],[\"64479.3\",\"0\",\"0\",\"0\"],[\"64479.2\",\"0\",\"0\",\"0\"],[\"64479\",\"0.02\",\"0\",\"2\"],[\"64478.9\",\"4.8\",\"0\",\"2\"],[\"64478.6\",\"0\",\"0\",\"0\"],[\"64478.5\",\"0.02\",\"0\",\"2\"],[\"64478.4\",\"8\",\"0\",\"1\"],[\"64478.2\",\"0.01\",\"0\",\"1\"],[\"64477.7\",\"0.02\",\"0\",\"2\"],[\"64477.6\",\"0.01\",\"0\",\"1\"],[\"64477.1\",\"0.01\",\"0\",\"1\"],[\"64477\",\"0\",\"0\",\"0\"],[\"64476.9\",\"4.01\",\"0\",\"2\"],[\"64476.7\",\"35.82\",\"0\",\"3\"],[\"64476.6\",\"13.2\",\"0\",\"4\"],[\"64476.5\",\"123.5\",\"0\",\"2\"],[\"64476.4\",\"0.77\",\"0\",\"1\"],[\"64476.3\",\"62.55\",\"0\",\"4\"],[\"64476.2\",\"0.01\",\"0\",\"1\"],[\"64476.1\",\"196.61\",\"0\",\"1\"],[\"64475.9\",\"77.55\",\"0\",\"2\"],[\"64475.1\",\"0\",\"0\",\"0\"],[\"64475\",\"0\",\"0\",\"0\"],[\"64474.8\",\"31.07\",\"0\",\"2\"],[\"64474.2\",\"46.54\",\"0\",\"1\"],[\"64474.1\",\"496.54\",\"0\",\"2\"],[\"64474\",\"0.03\",\"0\",\"2\"],[\"64473.9\",\"0.03\",\"0\",\"2\"],[\"64473.8\",\"0.01\",\"0\",\"1\"],[\"64473.6\",\"0\",\"0\",\"0\"],[\"64473.4\",\"0.42\",\"0\",\"2\"],[\"64472.7\",\"1.17\",\"0\",\"3\"],[\"64472.6\",\"0.12\",\"0\",\"1\"],[\"64472.5\",\"3.1\",\"0\",\"1\"],[\"64472.1\",\"3.92\",\"0\",\"4\"],[\"64471.9\",\"109.49\",\"0\",\"4\"],[\"64470.9\",\"16.01\",\"0\",\"2\"],[\"64470.8\",\"46.6\",\"0\",\"1\"],[\"64470.7\",\"7.92\",\"0\",\"4\"],[\"64470.1\",\"395.59\",\"0\",\"2\"],[\"64469.9\",\"169.58\",\"0\",\"4\"],[\"64469.2\",\"157.63\",\"0\",\"3\"],[\"64468.7\",\"109.5\",\"0\",\"6\"],[\"64467.9\",\"0.01\",\"0\",\"1\"],[\"64467.5\",\"0.03\",\"0\",\"2\"],[\"64467.3\",\"95.53\",\"0\",\"2\"],[\"64467.2\",\"69.9\",\"0\",\"1\"],[\"64467\",\"282.31\",\"0\",\"3\"],[\"64466.9\",\"0\",\"0\",\"0\"],[\"64466.3\",\"0\",\"0\",\"0\"],[\"64466\",\"0.02\",\"0\",\"2\"],[\"64465.8\",\"0\",\"0\",\"0\"],[\"64465.7\",\"0\",\"0\",\"0\"],[\"64465.5\",\"86.17\",\"0\",\"1\"],[\"64465.4\",\"507.87\",\"0\",\"3\"],[\"64465.3\",\"46.6\",\"0\",\"5\"],[\"64465\",\"0\",\"0\",\"0\"],[\"64464.8\",\"33.82\",\"0\",\"2\"],[\"64464.5\",\"3.24\",\"0\",\"3\"],[\"64464.4\",\"0.01\",\"0\",\"1\"],[\"64464.3\",\"0.77\",\"0\",\"1\"],[\"64463.9\",\"20.08\",\"0\",\"1\"],[\"64463.7\",\"0.02\",\"0\",\"1\"],[\"64463.4\",\"0\",\"0\",\"0\"],[\"64463.2\",\"31.05\",\"0\",\"1\"],[\"64462.4\",\"85.41\",\"0\",\"2\"],[\"64462.3\",\"232.91\",\"0\",\"1\"],[\"64461.2\",\"0.06\",\"0\",\"3\"],[\"64460.9\",\"132.73\",\"0\",\"5\"],[\"64459.5\",\"15.67\",\"0\",\"2\"],[\"64459.2\",\"58.24\",\"0\",\"2\"],[\"64456.9\",\"0\",\"0\",\"0\"],[\"64456.5\",\"0.81\",\"0\",\"2\"],[\"64452.6\",\"515.2\",\"0\",\"4\"],[\"64449\",\"0.03\",\"0\",\"3\"],[\"64446.7\",\"6.21\",\"0\",\"2\"],[\"64444\",\"15.67\",\"0\",\"3\"],[\"64442\",\"15.02\",\"0\",\"3\"],[\"64440.5\",\"0\",\"0\",\"0\"],[\"64440\",\"23.48\",\"0\",\"19\"],[\"64439\",\"0.02\",\"0\",\"1\"],[\"64431.6\",\"0.38\",\"0\",\"1\"],[\"64428\",\"326.06\",\"0\",\"3\"],[\"64422.6\",\"1.22\",\"0\",\"3\"],[\"64422.4\",\"0.02\",\"0\",\"2\"]],\"ts\":\"1782016044005\",\"checksum\":-1506801486,\"seqId\":325070090321,\"prevSeqId\":325070089798}]}"}
{"action": "update", "capture_sequence": 336, "channel": "books", "connection_sequence": 3, "event": null, "instId": "BTC-USDT-SWAP", "local_receive_ts": "2026-06-21T04:27:24Z", "monotonic_ns": 1643600016392652, "raw": "{\"arg\":{\"channel\":\"books\",\"instId\":\"BTC-USDT-SWAP\"},\"action\":\"update\",\"data\":[{\"asks\":[[\"64483\",\"666.6\",\"0\",\"36\"],[\"64484.4\",\"0.01\",\"0\",\"1\"],[\"64484.5\",\"39.61\",\"0\",\"5\"],[\"64486.3\",\"1.57\",\"0\",\"2\"],[\"64493.1\",\"0.46\",\"0\",\"3\"],[\"64493.4\",\"16.5\",\"0\",\"9\"],[\"64497.9\",\"0.01\",\"0\",\"1\"],[\"64498.4\",\"15.51\",\"0\",\"1\"],[\"64500.4\",\"0.03\",\"0\",\"3\"],[\"64500.8\",\"31.39\",\"0\",\"2\"],[\"64502.4\",\"0.19\",\"0\",\"6\"],[\"64502.5\",\"0.2\",\"0\",\"3\"],[\"64502.9\",\"280.72\",\"0\",\"7\"],[\"64503\",\"17.51\",\"0\",\"5\"],[\"64503.1\",\"39.69\",\"0\",\"8\"],[\"64503.6\",\"0.02\",\"0\",\"2\"],[\"64503.8\",\"1.08\",\"0\",\"2\"],[\"64504.1\",\"55.12\",\"0\",\"8\"],[\"64507.3\",\"0.03\",\"0\",\"2\"],[\"64507.9\",\"0.27\",\"0\",\"4\"],[\"64508.3\",\"58.18\",\"0\",\"1\"],[\"64509.5\",\"85.34\",\"0\",\"1\"],[\"64514.3\",\"10.11\",\"0\",\"6\"],[\"64515.1\",\"20.07\",\"0\",\"1\"],[\"64515.4\",\"0.46\",\"0\",\"5\"],[\"64517.9\",\"86.25\",\"0\",\"4\"],[\"64526.8\",\"3.46\",\"0\",\"3\"],[\"64527\",\"0\",\"0\",\"0\"],[\"64527.1\",\"0\",\"0\",\"0\"],[\"64527.2\",\"0\",\"0\",\"0\"],[\"64527.3\",\"0\",\"0\",\"0\"],[\"64527.4\",\"0\",\"0\",\"0\"],[\"64527.5\",\"0\",\"0\",\"0\"]],\"bids\":[[\"64482.9\",\"446.48\",\"0\",\"36\"],[\"64482.8\",\"5.67\",\"0\",\"13\"],[\"64482.7\",\"2.02\",\"0\",\"2\"],[\"64481.3\",\"0.01\",\"0\",\"1\"],[\"64480\",\"41.15\",\"0\",\"5\"],[\"64479.4\",\"0\",\"0\",\"0\"],[\"64478.5\",\"109.05\",\"0\",\"3\"],[\"64477\",\"0.01\",\"0\",\"1\"],[\"64476.9\",\"4.03\",\"0\",\"4\"],[\"64476.8\",\"0.77\",\"0\",\"1\"],[\"64476.6\",\"90.74\",\"0\",\"5\"],[\"64476.5\",\"7.75\",\"0\",\"1\"],[\"64476.4\",\"1.56\",\"0\",\"1\"],[\"64476.3\",\"62.54\",\"0\",\"3\"],[\"64476.1\",\"262.49\",\"0\",\"2\"],[\"64475.9\",\"1.57\",\"0\",\"2\"],[\"64475.5\",\"1.56\",\"0\",\"1\"],[\"64475.1\",\"138.3\",\"0\",\"4\"],[\"64475\",\"1.56\",\"0\",\"1\"],[\"64474.6\",\"0.38\",\"0\",\"1\"],[\"64474.5\",\"17.46\",\"0\",\"2\"],[\"64474\",\"1.59\",\"0\",\"3\"],[\"64473.8\",\"0.02\",\"0\",\"2\"],[\"64473.5\",\"64.87\",\"0\",\"3\"],[\"64471.9\",\"140.21\",\"0\",\"6\"],[\"64471.3\",\"17.88\",\"0\",\"2\"],[\"64471.1\",\"0.31\",\"0\",\"1\"],[\"64470.1\",\"395.28\",\"0\",\"1\"],[\"64467.4\",\"132.71\",\"0\",\"2\"],[\"64465.5\",\"0\",\"0\",\"0\"],[\"64464.7\",\"1.77\",\"0\",\"2\"],[\"64464.6\",\"20.08\",\"0\",\"1\"],[\"64464.3\",\"0\",\"0\",\"0\"],[\"64463.9\",\"0\",\"0\",\"0\"],[\"64463.5\",\"116.46\",\"0\",\"3\"],[\"64463.2\",\"0\",\"0\",\"0\"],[\"64462.4\",\"0.01\",\"0\",\"1\"],[\"64462.3\",\"0\",\"0\",\"0\"],[\"64462.2\",\"232.91\",\"0\",\"1\"],[\"64460.2\",\"58.23\",\"0\",\"1\"],[\"64459.5\",\"18.75\",\"0\",\"2\"],[\"64459.2\",\"0.01\",\"0\",\"1\"],[\"64459.1\",\"46.56\",\"0\",\"2\"],[\"64439\",\"0\",\"0\",\"0\"],[\"64438.1\",\"42.73\",\"0\",\"5\"],[\"64431.7\",\"0.38\",\"0\",\"1\"],[\"64431.6\",\"0\",\"0\",\"0\"],[\"64422.7\",\"0\",\"0\",\"0\"],[\"64422.6\",\"0\",\"0\",\"0\"],[\"64422.4\",\"0\",\"0\",\"0\"]],\"ts\":\"1782016044105\",\"checksum\":-852641539,\"seqId\":325070090649,\"prevSeqId\":325070090321}]}"}
{"action": null, "capture_sequence": 337, "channel": "trades", "connection_sequence": 3, "event": null, "instId": "BTC-USDT-SWAP", "local_receive_ts": "2026-06-21T04:27:24Z", "monotonic_ns": 1643600016717310, "raw": "{\"arg\":{\"channel\":\"trades\",\"instId\":\"BTC-USDT-SWAP\"},\"data\":[{\"instId\":\"BTC-USDT-SWAP\",\"tradeId\":\"2718750323\",\"px\":\"64482.9\",\"sz\":\"0.01\",\"side\":\"sell\",\"ts\":\"1782016044107\",\"count\":\"1\",\"source\":\"0\",\"seqId\":325070090651}]}"}
{"action": "update", "capture_sequence": 338, "channel": "books", "connection_sequence": 3, "event": null, "instId": "BTC-USDT-SWAP", "local_receive_ts": "2026-06-21T04:27:24Z", "monotonic_ns": 1643600117468656, "raw": "{\"arg\":{\"channel\":\"books\",\"instId\":\"BTC-USDT-SWAP\"},\"action\":\"update\",\"data\":[{\"asks\":[[\"64483\",\"422.59\",\"0\",\"35\"],[\"64484.5\",\"71.9\",\"0\",\"6\"],[\"64484.8\",\"0.01\",\"0\",\"1\"],[\"64484.9\",\"136.14\",\"0\",\"2\"],[\"64485.4\",\"0.77\",\"0\",\"1\"],[\"64493.1\",\"0.45\",\"0\",\"2\"],[\"64494\",\"240.15\",\"0\",\"8\"],[\"64495.9\",\"1.01\",\"0\",\"4\"],[\"64496.9\",\"0\",\"0\",\"0\"],[\"64498.4\",\"0\",\"0\",\"0\"],[\"64499.3\",\"15.51\",\"0\",\"1\"],[\"64500.8\",\"0.36\",\"0\",\"1\"],[\"64501.4\",\"31.04\",\"0\",\"2\"],[\"64501.7\",\"0.55\",\"0\",\"4\"],[\"64502.5\",\"232.97\",\"0\",\"4\"],[\"64503\",\"15.96\",\"0\",\"4\"],[\"64503.8\",\"0\",\"0\",\"0\"],[\"64504.1\",\"21.33\",\"0\",\"7\"],[\"64504.2\",\"512.65\",\"0\",\"7\"],[\"64504.9\",\"1.18\",\"0\",\"5\"],[\"64505.1\",\"33.81\",\"0\",\"3\"],[\"64508.3\",\"0\",\"0\",\"0\"],[\"64509.4\",\"58.18\",\"0\",\"1\"],[\"64509.5\",\"0\",\"0\",\"0\"],[\"64509.9\",\"86.55\",\"0\",\"4\"],[\"64515.1\",\"0\",\"0\",\"0\"],[\"64516.3\",\"22.23\",\"0\",\"4\"],[\"64516.5\",\"197.9\",\"0\",\"3\"],[\"64527\",\"0.17\",\"0\",\"3\"],[\"64527.1\",\"0.46\",\"0\",\"1\"]],\"bids\":[[\"64482.9\",\"498.93\",\"0\",\"37\"],[\"64482.8\",\"7.64\",\"0\",\"13\"],[\"64482.7\",\"0.02\",\"0\",\"1\"],[\"64480.1\",\"0.03\",\"0\",\"2\"],[\"64480\",\"122.05\",\"0\",\"4\"],[\"64479.6\",\"11.03\",\"0\",\"3\"],[\"64478.8\",\"31.81\",\"0\",\"2\"],[\"64478.7\",\"120.22\",\"0\",\"1\"],[\"64478.6\",\"48.1\",\"0\",\"2\"],[\"64478.5\",\"0.02\",\"0\",\"2\"],[\"64477.8\",\"79.1\",\"0\",\"2\"],[\"64477.7\",\"0.79\",\"0\",\"3\"],[\"64477.2\",\"1.56\",\"0\",\"1\"],[\"64476.8\",\"0\",\"0\",\"0\"],[\"64476.7\",\"6.34\",\"0\",\"3\"],[\"64476.6\",\"12.43\",\"0\",\"3\"],[\"64476.4\",\"0\",\"0\",\"0\"],[\"64476.3\",\"64.1\",\"0\",\"4\"],[\"64475.9\",\"0.01\",\"0\",\"1\"],[\"64475.1\",\"140.17\",\"0\",\"6\"],[\"64475\",\"0\",\"0\",\"0\"],[\"64473.5\",\"132.82\",\"0\",\"2\"],[\"64472\",\"0.33\",\"0\",\"3\"],[\"64471.9\",\"1.6\",\"0\",\"1\"],[\"64471.1\",\"148.91\",\"0\",\"1\"],[\"64468.8\",\"97.5\",\"0\",\"2\"],[\"64468.7\",\"79.09\",\"0\",\"5\"],[\"64467.4\",\"46.54\",\"0\",\"1\"],[\"64466.9\",\"0.02\",\"0\",\"1\"],[\"64466.7\",\"0.02\",\"0\",\"1\"],[\"64466.2\",\"33.82\",\"0\",\"2\"],[\"64465.8\",\"20.08\",\"0\",\"1\"],[\"64465.7\",\"0.77\",\"0\",\"1\"],[\"64465.3\",\"46.56\",\"0\",\"3\"],[\"64464.8\",\"0.01\",\"0\",\"1\"],[\"64464.7\",\"0\",\"0\",\"0\"],[\"64464.6\",\"85.4\",\"0\",\"1\"],[\"64464.1\",\"0.02\",\"0\",\"1\"],[\"64463.9\",\"31.05\",\"0\",\"1\"],[\"64463.7\",\"0\",\"0\",\"0\"],[\"64463.6\",\"233.04\",\"0\",\"3\"],[\"64463.5\",\"0.01\",\"0\",\"1\"],[\"64462.2\",\"0\",\"0\",\"0\"],[\"64462.1\",\"11.35\",\"0\",\"2\"],[\"64461.4\",\"51.47\",\"0\",\"7\"],[\"64461.2\",\"0.04\",\"0\",\"2\"],[\"64461\",\"58.23\",\"0\",\"1\"],[\"64460.9\",\"95.5\",\"0\",\"2\"],[\"64460.7\",\"44.97\",\"0\",\"3\"],[\"64460.2\",\"0\",\"0\",\"0\"],[\"64459.1\",\"46.54\",\"0\",\"1\"],[\"64454.9\",\"12.88\",\"0\",\"2\"],[\"64452.6\",\"515.18\",\"0\",\"3\"],[\"64440\",\"23.5\",\"0\",\"20\"],[\"64438.1\",\"42.71\",\"0\",\"4\"],[\"64431.7\",\"0\",\"0\",\"0\"],[\"64431.6\",\"0.38\",\"0\",\"1\"],[\"64423.3\",\"0\",\"0\",\"0\"],[\"64423.2\",\"0\",\"0\",\"0\"],[\"64423.1\",\"0\",\"0\",\"0\"],[\"64423\",\"0\",\"0\",\"0\"],[\"64422.8\",\"0\",\"0\",\"0\"]],\"ts\":\"1782016044205\",\"checksum\":-439913965,\"seqId\":325070090959,\"prevSeqId\":325070090649}]}"}
{"action": "update", "capture_sequence": 339, "channel": "books", "connection_sequence": 3, "event": null, "instId": "BTC-USDT-SWAP", "local_receive_ts": "2026-06-21T04:27:24Z", "monotonic_ns": 1643600217146512, "raw": "{\"arg\":{\"channel\":\"books\",\"instId\":\"BTC-USDT-SWAP\"},\"action\":\"update\",\"data\":[{\"asks\":[[\"64483\",\"476.55\",\"0\",\"36\"],[\"64488.7\",\"6.24\",\"0\",\"2\"],[\"64489.6\",\"63.4\",\"0\",\"3\"],[\"64489.8\",\"0.04\",\"0\",\"3\"],[\"64492.3\",\"23.23\",\"0\",\"3\"],[\"64492.5\",\"0.05\",\"0\",\"3\"],[\"64493.6\",\"0.03\",\"0\",\"2\"],[\"64494\",\"240.14\",\"0\",\"7\"],[\"64499.3\",\"0\",\"0\",\"0\"],[\"64499.6\",\"77.68\",\"0\",\"4\"],[\"64501.4\",\"0.01\",\"0\",\"1\"],[\"64501.9\",\"31.11\",\"0\",\"2\"],[\"64502.5\",\"0.2\",\"0\",\"3\"],[\"64502.7\",\"232.8\",\"0\",\"4\"],[\"64504.1\",\"22.88\",\"0\",\"8\"],[\"64504.2\",\"511.1\",\"0\",\"6\"],[\"64509.4\",\"0\",\"0\",\"0\"],[\"64509.9\",\"1.21\",\"0\",\"3\"],[\"64510.1\",\"58.19\",\"0\",\"2\"],[\"64510.6\",\"85.53\",\"0\",\"3\"],[\"64527.2\",\"0.18\",\"0\",\"4\"],[\"64527.3\",\"0.05\",\"0\",\"5\"]],\"bids\":[[\"64482.9\",\"496.43\",\"0\",\"36\"],[\"64482.8\",\"12.1\",\"0\",\"14\"],[\"64480.6\",\"0\",\"0\",\"0\"],[\"64480\",\"51.13\",\"0\",\"5\"],[\"64479.7\",\"0.01\",\"0\",\"1\"],[\"64478.8\",\"0\",\"0\",\"0\"],[\"64478.7\",\"0\",\"0\",\"0\"],[\"64478.6\",\"46.54\",\"0\",\"1\"],[\"64477.8\",\"0\",\"0\",\"0\"],[\"64477.7\",\"0.02\",\"0\",\"2\"],[\"64477.2\",\"0\",\"0\",\"0\"],[\"64477\",\"77.55\",\"0\",\"2\"],[\"64476.9\",\"4.02\",\"0\",\"3\"],[\"64476.4\",\"32.58\",\"0\",\"3\"],[\"64476.3\",\"62.54\",\"0\",\"3\"],[\"64476.2\",\"1.57\",\"0\",\"2\"],[\"64473.5\",\"99.54\",\"0\",\"2\"],[\"64468.8\",\"11.33\",\"0\",\"1\"],[\"64467.4\",\"132.71\",\"0\",\"2\"],[\"64466.7\",\"0\",\"0\",\"0\"],[\"64465.3\",\"46.58\",\"0\",\"4\"],[\"64464.7\",\"32.05\",\"0\",\"2\"],[\"64464.5\",\"3.26\",\"0\",\"4\"],[\"64464.1\",\"0\",\"0\",\"0\"],[\"64463.9\",\"0\",\"0\",\"0\"],[\"64463.7\",\"0.02\",\"0\",\"1\"],[\"64463.6\",\"0.13\",\"0\",\"2\"],[\"64463.4\",\"232.91\",\"0\",\"1\"],[\"64462.1\",\"11.33\",\"0\",\"1\"],[\"64461.5\",\"58.25\",\"0\",\"3\"],[\"64461\",\"200.02\",\"0\",\"2\"],[\"64460.7\",\"44.95\",\"0\",\"2\"],[\"64454.9\",\"12.86\",\"0\",\"1\"],[\"64453.8\",\"0.22\",\"0\",\"2\"],[\"64449\",\"0.02\",\"0\",\"2\"],[\"64446.7\",\"6.22\",\"0\",\"3\"],[\"64440\",\"23.47\",\"0\",\"18\"],[\"64439.7\",\"15.67\",\"0\",\"2\"],[\"64423.3\",\"512.29\",\"0\",\"3\"],[\"64423.2\",\"37.23\",\"0\",\"1\"],[\"64423.1\",\"94.01\",\"0\",\"3\"]],\"ts\":\"1782016044305\",\"checksum\":-1795416341,\"seqId\":325070091179,\"prevSeqId\":325070090959}]}"}
{"action": "update", "capture_sequence": 340, "channel": "books", "connection_sequence": 3, "event": null, "instId": "BTC-USDT-SWAP", "local_receive_ts": "2026-06-21T04:27:24Z", "monotonic_ns": 1643600310579323, "raw": "{\"arg\":{\"channel\":\"books\",\"instId\":\"BTC-USDT-SWAP\"},\"action\":\"update\",\"data\":[{\"asks\":[[\"64509\",\"215.66\",\"0\",\"3\"],[\"64512\",\"2.88\",\"0\",\"13\"],[\"64515.9\",\"68.01\",\"0\",\"5\"],[\"64516.3\",\"2.16\",\"0\",\"3\"]],\"bids\":[[\"64482.8\",\"7.64\",\"0\",\"13\"],[\"64480\",\"84.94\",\"0\",\"6\"],[\"64479.8\",\"0.78\",\"0\",\"2\"],[\"64477.2\",\"6.99\",\"0\",\"2\"],[\"64477.1\",\"139.86\",\"0\",\"4\"],[\"64477\",\"79.11\",\"0\",\"3\"],[\"64476.7\",\"4.78\",\"0\",\"2\"],[\"64476.4\",\"0\",\"0\",\"0\"],[\"64473.1\",\"1.56\",\"0\",\"1\"],[\"64466.9\",\"0\",\"0\",\"0\"],[\"64465.8\",\"0\",\"0\",\"0\"],[\"64465.4\",\"527.95\",\"0\",\"4\"],[\"64465.3\",\"46.6\",\"0\",\"5\"],[\"64464.5\",\"3.24\",\"0\",\"3\"],[\"64464.1\",\"0.02\",\"0\",\"1\"],[\"64463.7\",\"0\",\"0\",\"0\"],[\"64461.4\",\"51.49\",\"0\",\"8\"],[\"64461\",\"200\",\"0\",\"1\"],[\"64460.9\",\"95.52\",\"0\",\"3\"],[\"64423\",\"1.59\",\"0\",\"6\"]],\"ts\":\"1782016044405\",\"checksum\":-1639811433,\"seqId\":325070091290,\"prevSeqId\":325070091179}]}"}
{"action": "update", "capture_sequence": 341, "channel": "books", "connection_sequence": 3, "event": null, "instId": "BTC-USDT-SWAP", "local_receive_ts": "2026-06-21T04:27:24Z", "monotonic_ns": 1643600410601508, "raw": "{\"arg\":{\"channel\":\"books\",\"instId\":\"BTC-USDT-SWAP\"},\"action\":\"update\",\"data\":[{\"asks\":[[\"64483\",\"486.55\",\"0\",\"37\"]],\"bids\":[[\"64477.1\",\"141.42\",\"0\",\"5\"],[\"64477\",\"77.55\",\"0\",\"2\"],[\"64476.5\",\"9.31\",\"0\",\"2\"],[\"64476.2\",\"0.01\",\"0\",\"1\"],[\"64476\",\"1.6\",\"0\",\"3\"],[\"64475.6\",\"1.56\",\"0\",\"1\"],[\"64475.5\",\"0\",\"0\",\"0\"],[\"64475.1\",\"138.61\",\"0\",\"5\"]],\"ts\":\"1782016044505\",\"checksum\":36931090,\"seqId\":325070091391,\"prevSeqId\":325070091290}]}"}
{"action": "update", "capture_sequence": 342, "channel": "books", "connection_sequence": 3, "event": null, "instId": "BTC-USDT-SWAP", "local_receive_ts": "2026-06-21T04:27:24Z", "monotonic_ns": 1643600512252712, "raw": "{\"arg\":{\"channel\":\"books\",\"instId\":\"BTC-USDT-SWAP\"},\"action\":\"update\",\"data\":[{\"asks\":[[\"64504.9\",\"0.41\",\"0\",\"4\"],[\"64505.4\",\"60\",\"0\",\"5\"]],\"bids\":[[\"64482.9\",\"494.75\",\"0\",\"36\"],[\"64477.1\",\"139.86\",\"0\",\"4\"],[\"64476.5\",\"7.75\",\"0\",\"1\"],[\"64476\",\"0.04\",\"0\",\"2\"],[\"64466.3\",\"0.77\",\"0\",\"1\"],[\"64465.7\",\"0\",\"0\",\"0\"]],\"ts\":\"1782016044605\",\"checksum\":1109294029,\"seqId\":325070091471,\"prevSeqId\":325070091391}]}"}
{"action": "update", "capture_sequence": 343, "channel": "books", "connection_sequence": 3, "event": null, "instId": "BTC-USDT-SWAP", "local_receive_ts": "2026-06-21T04:27:24Z", "monotonic_ns": 1643600611330611, "raw": "{\"arg\":{\"channel\":\"books\",\"instId\":\"BTC-USDT-SWAP\"},\"action\":\"update\",\"data\":[{\"asks\":[[\"64483\",\"309.97\",\"0\",\"34\"],[\"64483.3\",\"0.04\",\"0\",\"1\"],[\"64484.7\",\"0.4\",\"0\",\"1\"],[\"64504.1\",\"21.33\",\"0\",\"7\"],[\"64504.7\",\"1.56\",\"0\",\"2\"],[\"64510.1\",\"0.01\",\"0\",\"1\"],[\"64510.9\",\"58.25\",\"0\",\"5\"],[\"64513.3\",\"23.83\",\"0\",\"9\"],[\"64515.9\",\"47.94\",\"0\",\"4\"],[\"64516.5\",\"217.97\",\"0\",\"4\"],[\"64527.3\",\"0\",\"0\",\"0\"]],\"bids\":[[\"64482.9\",\"566.8\",\"0\",\"39\"],[\"64482.8\",\"17.76\",\"0\",\"14\"],[\"64482.6\",\"4.09\",\"0\",\"3\"],[\"64481.2\",\"0\",\"0\",\"0\"],[\"64480.3\",\"0.8\",\"0\",\"1\"],[\"64480\",\"118.82\",\"0\",\"5\"],[\"64479.9\",\"0.14\",\"0\",\"3\"],[\"64478.9\",\"4\",\"0\",\"1\"],[\"64478.7\",\"120.22\",\"0\",\"1\"],[\"64478.2\",\"77.55\",\"0\",\"2\"],[\"64477.2\",\"18.63\",\"0\",\"2\"],[\"64477.1\",\"0.01\",\"0\",\"1\"],[\"64477\",\"0.01\",\"0\",\"1\"],[\"64476.6\",\"0.02\",\"0\",\"2\"],[\"64476.4\",\"32.58\",\"0\",\"3\"],[\"64468.8\",\"97.5\",\"0\",\"2\"],[\"64467.4\",\"46.54\",\"0\",\"1\"],[\"64465.7\",\"20.08\",\"0\",\"1\"],[\"64465.4\",\"507.87\",\"0\",\"3\"],[\"64462.2\",\"58.22\",\"0\",\"1\"],[\"64461.5\",\"0.02\",\"0\",\"2\"],[\"64423.3\",\"0\",\"0\",\"0\"],[\"64423.2\",\"0\",\"0\",\"0\"],[\"64423.1\",\"0\",\"0\",\"0\"],[\"64423\",\"0\",\"0\",\"0\"]],\"ts\":\"1782016044705\",\"checksum\":-1359809386,\"seqId\":325070091597,\"prevSeqId\":325070091471}]}"}
{"action": "update", "capture_sequence": 344, "channel": "books", "connection_sequence": 3, "event": null, "instId": "BTC-USDT-SWAP", "local_receive_ts": "2026-06-21T04:27:24Z", "monotonic_ns": 1643600711281651, "raw": "{\"arg\":{\"channel\":\"books\",\"instId\":\"BTC-USDT-SWAP\"},\"action\":\"update\",\"data\":[{\"asks\":[[\"64483\",\"501.82\",\"0\",\"38\"],[\"64484.3\",\"113.15\",\"0\",\"2\"],[\"64484.4\",\"120.23\",\"0\",\"2\"],[\"64484.5\",\"0.07\",\"0\",\"4\"],[\"64484.8\",\"0\",\"0\",\"0\"],[\"64497.3\",\"41.14\",\"0\",\"4\"],[\"64504.4\",\"2.68\",\"0\",\"5\"],[\"64504.7\",\"0.01\",\"0\",\"1\"],[\"64505.4\",\"59.23\",\"0\",\"4\"],[\"64506\",\"10.84\",\"0\",\"6\"],[\"64508.9\",\"96.47\",\"0\",\"4\"],[\"64509\",\"15.66\",\"0\",\"2\"]],\"bids\":[[\"64482.9\",\"495.23\",\"0\",\"38\"],[\"64482.8\",\"7.64\",\"0\",\"13\"],[\"64481.3\",\"0\",\"0\",\"0\"],[\"64480.4\",\"0.01\",\"0\",\"1\"],[\"64480\",\"55.28\",\"0\",\"5\"],[\"64478.7\",\"0\",\"0\",\"0\"],[\"64478.2\",\"0.01\",\"0\",\"1\"],[\"64477.3\",\"77.54\",\"0\",\"1\"],[\"64468.8\",\"11.33\",\"0\",\"1\"],[\"64467.4\",\"132.71\",\"0\",\"2\"],[\"64467.2\",\"70.67\",\"0\",\"2\"],[\"64466.3\",\"0\",\"0\",\"0\"],[\"64464.5\",\"0.02\",\"0\",\"2\"],[\"64423.3\",\"512.29\",\"0\",\"3\"]],\"ts\":\"1782016044805\",\"checksum\":279431120,\"seqId\":325070091701,\"prevSeqId\":325070091597}]}"}
{"action": "update", "capture_sequence": 345, "channel": "books", "connection_sequence": 3, "event": null, "instId": "BTC-USDT-SWAP", "local_receive_ts": "2026-06-21T04:27:25Z", "monotonic_ns": 1643600811502703, "raw": "{\"arg\":{\"channel\":\"books\",\"instId\":\"BTC-USDT-SWAP\"},\"action\":\"update\",\"data\":[{\"asks\":[[\"64483\",\"511.82\",\"0\",\"39\"],[\"64484.2\",\"0.01\",\"0\",\"1\"],[\"64484.3\",\"77.23\",\"0\",\"1\"],[\"64484.4\",\"0\",\"0\",\"0\"],[\"64484.8\",\"0.01\",\"0\",\"1\"],[\"64488.7\",\"0.04\",\"0\",\"1\"],[\"64491.7\",\"0.03\",\"0\",\"3\"],[\"64493.6\",\"0.02\",\"0\",\"1\"],[\"64493.8\",\"8.41\",\"0\",\"5\"],[\"64497.3\",\"41.29\",\"0\",\"5\"],[\"64502.9\",\"280.73\",\"0\",\"8\"],[\"64503\",\"15.95\",\"0\",\"3\"],[\"64505.9\",\"0.78\",\"0\",\"2\"],[\"64506\",\"10.07\",\"0\",\"5\"],[\"64508.9\",\"154.65\",\"0\",\"5\"],[\"64510.9\",\"0.07\",\"0\",\"4\"],[\"64513.3\",\"24.68\",\"0\",\"10\"],[\"64515.7\",\"81.92\",\"0\",\"5\"],[\"64516.5\",\"197.9\",\"0\",\"3\"],[\"64527.2\",\"0\",\"0\",\"0\"]],\"bids\":[[\"64482.9\",\"495.28\",\"0\",\"38\"],[\"64476.6\",\"0.01\",\"0\",\"1\"],[\"64476.5\",\"0\",\"0\",\"0\"],[\"64475.6\",\"0\",\"0\",\"0\"],[\"64470.2\",\"7.75\",\"0\",\"1\"],[\"64467.2\",\"69.9\",\"0\",\"1\"],[\"64466.3\",\"0.77\",\"0\",\"1\"],[\"64465.7\",\"0\",\"0\",\"0\"],[\"64464.8\",\"20.09\",\"0\",\"2\"],[\"64464.5\",\"3.24\",\"0\",\"3\"],[\"64462.2\",\"0\",\"0\",\"0\"],[\"64462\",\"200.01\",\"0\",\"2\"],[\"64461\",\"0\",\"0\",\"0\"],[\"64460.9\",\"153.75\",\"0\",\"4\"],[\"64454.8\",\"10.02\",\"0\",\"2\"],[\"64453.8\",\"0.2\",\"0\",\"1\"],[\"64440\",\"23.49\",\"0\",\"19\"],[\"64439.7\",\"15.65\",\"0\",\"1\"],[\"64423.2\",\"37.23\",\"0\",\"1\"],[\"64423.1\",\"94.01\",\"0\",\"3\"],[\"64423\",\"1.59\",\"0\",\"6\"]],\"ts\":\"1782016044905\",\"checksum\":1909022553,\"seqId\":325070091764,\"prevSeqId\":325070091701}]}"}
{"action": null, "capture_sequence": 346, "channel": "trades", "connection_sequence": 3, "event": null, "instId": "BTC-USDT-SWAP", "local_receive_ts": "2026-06-21T04:27:25Z", "monotonic_ns": 1643600847568360, "raw": "{\"arg\":{\"channel\":\"trades\",\"instId\":\"BTC-USDT-SWAP\"},\"data\":[{\"instId\":\"BTC-USDT-SWAP\",\"tradeId\":\"2718750324\",\"px\":\"64482.9\",\"sz\":\"0.06\",\"side\":\"sell\",\"ts\":\"1782016044942\",\"count\":\"1\",\"source\":\"0\",\"seqId\":325070091772}]}"}
{"action": "update", "capture_sequence": 347, "channel": "books", "connection_sequence": 3, "event": null, "instId": "BTC-USDT-SWAP", "local_receive_ts": "2026-06-21T04:27:25Z", "monotonic_ns": 1643600910581831, "raw": "{\"arg\":{\"channel\":\"books\",\"instId\":\"BTC-USDT-SWAP\"},\"action\":\"update\",\"data\":[{\"asks\":[[\"64483\",\"546.61\",\"0\",\"41\"],[\"64508.9\",\"178.33\",\"0\",\"5\"],[\"64510.1\",\"58.19\",\"0\",\"2\"],[\"64511\",\"225.02\",\"0\",\"9\"]],\"bids\":[[\"64482.9\",\"495.22\",\"0\",\"38\"],[\"64478.7\",\"0.01\",\"0\",\"1\"],[\"64474.5\",\"15.9\",\"0\",\"1\"],[\"64474\",\"0.03\",\"0\",\"2\"],[\"64473.5\",\"97.98\",\"0\",\"1\"],[\"64473.1\",\"0\",\"0\",\"0\"],[\"64462\",\"258.24\",\"0\",\"3\"],[\"64460.9\",\"95.52\",\"0\",\"3\"]],\"ts\":\"1782016045005\",\"checksum\":1789963137,\"seqId\":325070091799,\"prevSeqId\":325070091764}]}"}
{"action": null, "capture_sequence": 348, "channel": "trades", "connection_sequence": 3, "event": null, "instId": "BTC-USDT-SWAP", "local_receive_ts": "2026-06-21T04:27:25Z", "monotonic_ns": 1643600981583085, "raw": "{\"arg\":{\"channel\":\"trades\",\"instId\":\"BTC-USDT-SWAP\"},\"data\":[{\"instId\":\"BTC-USDT-SWAP\",\"tradeId\":\"2718750325\",\"px\":\"64482.9\",\"sz\":\"0.77\",\"side\":\"sell\",\"ts\":\"1782016045076\",\"count\":\"1\",\"source\":\"0\",\"seqId\":325070091827}]}"}
{"action": "update", "capture_sequence": 349, "channel": "books", "connection_sequence": 3, "event": null, "instId": "BTC-USDT-SWAP", "local_receive_ts": "2026-06-21T04:27:25Z", "monotonic_ns": 1643601010674287, "raw": "{\"arg\":{\"channel\":\"books\",\"instId\":\"BTC-USDT-SWAP\"},\"action\":\"update\",\"data\":[{\"asks\":[[\"64483\",\"548.15\",\"0\",\"42\"]],\"bids\":[[\"64482.9\",\"494.95\",\"0\",\"39\"],[\"64476.7\",\"6.34\",\"0\",\"3\"],[\"64476.2\",\"1.57\",\"0\",\"2\"],[\"64475.4\",\"1.58\",\"0\",\"3\"],[\"64474.9\",\"1.56\",\"0\",\"1\"],[\"64474.4\",\"1.56\",\"0\",\"1\"],[\"64473.9\",\"1.59\",\"0\",\"3\"],[\"64473.5\",\"99.54\",\"0\",\"2\"],[\"64423.1\",\"0\",\"0\",\"0\"],[\"64423\",\"0\",\"0\",\"0\"]],\"ts\":\"1782016045105\",\"checksum\":885943355,\"seqId\":325070091839,\"prevSeqId\":325070091799}]}"}
{"action": "update", "capture_sequence": 350, "channel": "books", "connection_sequence": 3, "event": null, "instId": "BTC-USDT-SWAP", "local_receive_ts": "2026-06-21T04:27:25Z", "monotonic_ns": 1643601112636809, "raw": "{\"arg\":{\"channel\":\"books\",\"instId\":\"BTC-USDT-SWAP\"},\"action\":\"update\",\"data\":[{\"asks\":[[\"64497.3\",\"41.3\",\"0\",\"5\"]],\"bids\":[[\"64482.9\",\"494.89\",\"0\",\"38\"],[\"64476.2\",\"0.01\",\"0\",\"1\"],[\"64473\",\"1.56\",\"0\",\"1\"],[\"64464.5\",\"3.2\",\"0\",\"3\"],[\"64423.2\",\"0\",\"0\",\"0\"]],\"ts\":\"1782016045205\",\"checksum\":-706538900,\"seqId\":325070091897,\"prevSeqId\":325070091839}]}"}
{"action": "update", "capture_sequence": 351, "channel": "books", "connection_sequence": 3, "event": null, "instId": "BTC-USDT-SWAP", "local_receive_ts": "2026-06-21T04:27:25Z", "monotonic_ns": 1643601210547785, "raw": "{\"arg\":{\"channel\":\"books\",\"instId\":\"BTC-USDT-SWAP\"},\"action\":\"update\",\"data\":[{\"asks\":[],\"bids\":[[\"64482.8\",\"5.94\",\"0\",\"12\"],[\"64476.7\",\"4.78\",\"0\",\"2\"],[\"64475.4\",\"0.02\",\"0\",\"2\"],[\"64474.9\",\"0\",\"0\",\"0\"],[\"64423.2\",\"37.23\",\"0\",\"1\"]],\"ts\":\"1782016045305\",\"checksum\":-1268557428,\"seqId\":325070091905,\"prevSeqId\":325070091897}]}"}
{"action": "update", "capture_sequence": 352, "channel": "books", "connection_sequence": 3, "event": null, "instId": "BTC-USDT-SWAP", "local_receive_ts": "2026-06-21T04:27:25Z", "monotonic_ns": 1643601310447707, "raw": "{\"arg\":{\"channel\":\"books\",\"instId\":\"BTC-USDT-SWAP\"},\"action\":\"update\",\"data\":[{\"asks\":[[\"64483\",\"551.15\",\"0\",\"45\"],[\"64483.9\",\"0.02\",\"0\",\"2\"],[\"64484\",\"7.08\",\"0\",\"5\"],[\"64484.8\",\"0\",\"0\",\"0\"],[\"64486.2\",\"13.53\",\"0\",\"7\"],[\"64527.2\",\"0.18\",\"0\",\"4\"]],\"bids\":[[\"64482.9\",\"494.18\",\"0\",\"37\"]],\"ts\":\"1782016045405\",\"checksum\":-886822117,\"seqId\":325070091925,\"prevSeqId\":325070091905}]}"}
{"action": "update", "capture_sequence": 353, "channel": "books", "connection_sequence": 3, "event": null, "instId": "BTC-USDT-SWAP", "local_receive_ts": "2026-06-21T04:27:25Z", "monotonic_ns": 1643601414525641, "raw": "{\"arg\":{\"channel\":\"books\",\"instId\":\"BTC-USDT-SWAP\"},\"action\":\"update\",\"data\":[{\"asks\":[[\"64505.9\",\"0.01\",\"0\",\"1\"],[\"64506.7\",\"0.96\",\"0\",\"16\"],[\"64510.2\",\"100.99\",\"0\",\"2\"],[\"64510.6\",\"0.19\",\"0\",\"2\"]],\"bids\":[[\"64482.9\",\"494.96\",\"0\",\"38\"],[\"64468.8\",\"97.5\",\"0\",\"2\"],[\"64467.5\",\"0.8\",\"0\",\"3\"],[\"64467.4\",\"46.54\",\"0\",\"1\"],[\"64466.3\",\"0\",\"0\",\"0\"],[\"64464.9\",\"85.4\",\"0\",\"1\"],[\"64464.6\",\"0\",\"0\",\"0\"],[\"64423.1\",\"94.01\",\"0\",\"3\"]],\"ts\":\"1782016045505\",\"checksum\":681832508,\"seqId\":325070091959,\"prevSeqId\":325070091925}]}"}
{"action": "update", "capture_sequence": 354, "channel": "books", "connection_sequence": 3, "event": null, "instId": "BTC-USDT-SWAP", "local_receive_ts": "2026-06-21T04:27:25Z", "monotonic_ns": 1643601510565232, "raw": "{\"arg\":{\"channel\":\"books\",\"instId\":\"BTC-USDT-SWAP\"},\"action\":\"update\",\"data\":[{\"asks\":[[\"64483\",\"551.25\",\"0\",\"46\"],[\"64491\",\"0.01\",\"0\",\"1\"],[\"64491.6\",\"1.25\",\"0\",\"5\"],[\"64491.9\",\"0.42\",\"0\",\"5\"],[\"64492.3\",\"22.03\",\"0\",\"2\"],[\"64492.6\",\"0.12\",\"0\",\"1\"],[\"64492.9\",\"0.01\",\"0\",\"1\"],[\"64493.4\",\"15.3\",\"0\",\"8\"],[\"64493.8\",\"7.21\",\"0\",\"4\"],[\"64494\",\"238.94\",\"0\",\"6\"],[\"64494.2\",\"0\",\"0\",\"0\"],[\"64512.5\",\"0.16\",\"0\",\"5\"],[\"64513.1\",\"1.56\",\"0\",\"2\"],[\"64513.5\",\"47.1\",\"0\",\"4\"],[\"64513.8\",\"0.01\",\"0\",\"1\"],[\"64514.1\",\"0.03\",\"0\",\"3\"],[\"64514.4\",\"15.7\",\"0\",\"4\"],[\"64514.9\",\"496.61\",\"0\",\"4\"],[\"64515.3\",\"0.01\",\"0\",\"1\"],[\"64515.6\",\"0.09\",\"0\",\"4\"],[\"64515.7\",\"80.42\",\"0\",\"4\"],[\"64527.3\",\"0.05\",\"0\",\"5\"]],\"bids\":[[\"64474.4\",\"0\",\"0\",\"0\"],[\"64471.9\",\"0\",\"0\",\"0\"],[\"64471.3\",\"15.98\",\"0\",\"1\"],[\"64471\",\"0\",\"0\",\"0\"],[\"64470.7\",\"6.24\",\"0\",\"3\"],[\"64470.3\",\"12.01\",\"0\",\"3\"],[\"64470\",\"37.69\",\"0\",\"4\"],[\"64469.8\",\"84.34\",\"0\",\"2\"],[\"64469.6\",\"0.01\",\"0\",\"1\"],[\"64469.2\",\"154.75\",\"0\",\"2\"],[\"64468.7\",\"76.39\",\"0\",\"4\"],[\"64424.7\",\"0\",\"0\",\"0\"],[\"64424.1\",\"0\",\"0\",\"0\"],[\"64423.8\",\"293.11\",\"0\",\"3\"],[\"64423.4\",\"0\",\"0\",\"0\"],[\"64423.1\",\"92.81\",\"0\",\"2\"],[\"64423\",\"1.59\",\"0\",\"6\"],[\"64422.8\",\"0.01\",\"0\",\"1\"],[\"64422.7\",\"3.4\",\"0\",\"3\"],[\"64422.6\",\"0.02\",\"0\",\"2\"],[\"64422.4\",\"0.02\",\"0\",\"2\"],[\"64422.3\",\"0.01\",\"0\",\"1\"]],\"ts\":\"1782016045605\",\"checksum\":1432259325,\"seqId\":325070092033,\"prevSeqId\":325070091959}]}"}
{"action": "update", "capture_sequence": 355, "channel": "books", "connection_sequence": 3, "event": null, "instId": "BTC-USDT-SWAP", "local_receive_ts": "2026-06-21T04:27:25Z", "monotonic_ns": 1643601610706775, "raw": "{\"arg\":{\"channel\":\"books\",\"instId\":\"BTC-USDT-SWAP\"},\"action\":\"update\",\"data\":[{\"asks\":[[\"64490.5\",\"3.01\",\"0\",\"4\"],[\"64491.3\",\"1.21\",\"0\",\"2\"],[\"64491.7\",\"1.23\",\"0\",\"4\"],[\"64492\",\"1.24\",\"0\",\"5\"],[\"64514.1\",\"1.23\",\"0\",\"4\"],[\"64514.9\",\"497.81\",\"0\",\"5\"],[\"64515.3\",\"1.21\",\"0\",\"2\"],[\"64515.6\",\"1.29\",\"0\",\"5\"]],\"bids\":[[\"64475.7\",\"1.56\",\"0\",\"1\"],[\"64475.2\",\"1.56\",\"0\",\"1\"],[\"64472\",\"0.02\",\"0\",\"2\"],[\"64471.6\",\"1.95\",\"0\",\"2\"],[\"64471.5\",\"0.32\",\"0\",\"2\"],[\"64471.1\",\"151.67\",\"0\",\"2\"],[\"64470.8\",\"49.6\",\"0\",\"2\"],[\"64470.4\",\"6.88\",\"0\",\"2\"],[\"64468.8\",\"11.33\",\"0\",\"1\"],[\"64467.4\",\"132.71\",\"0\",\"2\"],[\"64424.4\",\"47.74\",\"0\",\"2\"],[\"64423.8\",\"294.31\",\"0\",\"4\"],[\"64423.6\",\"1.2\",\"0\",\"1\"],[\"64423.2\",\"38.43\",\"0\",\"2\"],[\"64422.6\",\"0\",\"0\",\"0\"],[\"64422.4\",\"0\",\"0\",\"0\"],[\"64422.3\",\"0\",\"0\",\"0\"]],\"ts\":\"1782016045705\",\"checksum\":1432259325,\"seqId\":325070092081,\"prevSeqId\":325070092033}]}"}
{"action": "update", "capture_sequence": 356, "channel": "books", "connection_sequence": 3, "event": null, "instId": "BTC-USDT-SWAP", "local_receive_ts": "2026-06-21T04:27:25Z", "monotonic_ns": 1643601710806704, "raw": "{\"arg\":{\"channel\":\"books\",\"instId\":\"BTC-USDT-SWAP\"},\"action\":\"update\",\"data\":[{\"asks\":[[\"64488.9\",\"1.33\",\"0\",\"7\"],[\"64489.5\",\"1.02\",\"0\",\"3\"],[\"64489.9\",\"1\",\"0\",\"1\"],[\"64490.2\",\"1.2\",\"0\",\"1\"],[\"64490.8\",\"31.73\",\"0\",\"3\"],[\"64491.2\",\"1.01\",\"0\",\"2\"],[\"64492.1\",\"1.5\",\"0\",\"1\"],[\"64493.2\",\"8.07\",\"0\",\"5\"],[\"64509.5\",\"85.34\",\"0\",\"1\"],[\"64510.2\",\"15.65\",\"0\",\"1\"],[\"64512.5\",\"1.16\",\"0\",\"6\"],[\"64513.2\",\"1.15\",\"0\",\"5\"],[\"64513.5\",\"48.1\",\"0\",\"5\"],[\"64513.8\",\"1.21\",\"0\",\"2\"],[\"64514.4\",\"16.9\",\"0\",\"5\"],[\"64515.7\",\"81.92\",\"0\",\"5\"],[\"64527\",\"0\",\"0\",\"0\"],[\"64527.1\",\"0\",\"0\",\"0\"],[\"64527.2\",\"0\",\"0\",\"0\"],[\"64527.3\",\"0\",\"0\",\"0\"]],\"bids\":[[\"64482.8\",\"8.44\",\"0\",\"13\"],[\"64480\",\"84.11\",\"0\",\"6\"],[\"64477.5\",\"32.88\",\"0\",\"4\"],[\"64477.4\",\"120.23\",\"0\",\"2\"],[\"64476.4\",\"0\",\"0\",\"0\"],[\"64475.7\",\"0\",\"0\",\"0\"],[\"64475.2\",\"0\",\"0\",\"0\"],[\"64474.7\",\"1.57\",\"0\",\"2\"],[\"64473.2\",\"13.01\",\"0\",\"3\"],[\"64472.6\",\"2.02\",\"0\",\"2\"],[\"64472.2\",\"1.6\",\"0\",\"1\"],[\"64471.9\",\"1.68\",\"0\",\"1\"],[\"64471.3\",\"18.14\",\"0\",\"2\"],[\"64470\",\"40.39\",\"0\",\"5\"],[\"64464.9\",\"0\",\"0\",\"0\"],[\"64463.9\",\"85.4\",\"0\",\"1\"],[\"64426\",\"4.27\",\"0\",\"3\"],[\"64425.3\",\"3\",\"0\",\"2\"],[\"64425\",\"2.87\",\"0\",\"8\"],[\"64424.7\",\"1.2\",\"0\",\"1\"],[\"64424.1\",\"1.2\",\"0\",\"1\"],[\"64422.8\",\"1.51\",\"0\",\"2\"],[\"64422.7\",\"0\",\"0\",\"0\"]],\"ts\":\"1782016045805\",\"checksum\":-195428382,\"seqId\":325070092147,\"prevSeqId\":325070092081}]}"}
{"action": "update", "capture_sequence": 357, "channel": "books", "connection_sequence": 3, "event": null, "instId": "BTC-USDT-SWAP", "local_receive_ts": "2026-06-21T04:27:26Z", "monotonic_ns": 1643601810649073, "raw": "{\"arg\":{\"channel\":\"books\",\"instId\":\"BTC-USDT-SWAP\"},\"action\":\"update\",\"data\":[{\"asks\":[[\"64490.2\",\"1.21\",\"0\",\"2\"],[\"64491.7\",\"1.22\",\"0\",\"3\"],[\"64502.8\",\"57.08\",\"0\",\"4\"],[\"64502.9\",\"280.72\",\"0\",\"7\"],[\"64522.2\",\"0.16\",\"0\",\"9\"],[\"64522.8\",\"15.71\",\"0\",\"4\"]],\"bids\":[[\"64480\",\"55.28\",\"0\",\"5\"],[\"64477.6\",\"1.57\",\"0\",\"2\"],[\"64477.5\",\"0.3\",\"0\",\"1\"],[\"64477.4\",\"0.01\",\"0\",\"1\"],[\"64477.2\",\"20.19\",\"0\",\"3\"],[\"64476.7\",\"6.34\",\"0\",\"3\"],[\"64476.4\",\"32.58\",\"0\",\"3\"],[\"64476.2\",\"1.57\",\"0\",\"2\"],[\"64475.7\",\"1.56\",\"0\",\"1\"],[\"64474.7\",\"0.01\",\"0\",\"1\"],[\"64468.8\",\"97.5\",\"0\",\"2\"],[\"64467.4\",\"46.54\",\"0\",\"1\"],[\"64466.7\",\"0.02\",\"0\",\"1\"],[\"64465.3\",\"46.58\",\"0\",\"4\"],[\"64454.9\",\"12.88\",\"0\",\"2\"],[\"64454.8\",\"10\",\"0\",\"1\"],[\"64423.1\",\"0\",\"0\",\"0\"],[\"64423\",\"0\",\"0\",\"0\"],[\"64422.8\",\"0\",\"0\",\"0\"]],\"ts\":\"1782016045905\",\"checksum\":-1460283450,\"seqId\":325070092191,\"prevSeqId\":325070092147}]}"}
{"action": "update", "capture_sequence": 358, "channel": "books", "connection_sequence": 3, "event": null, "instId": "BTC-USDT-SWAP", "local_receive_ts": "2026-06-21T04:27:26Z", "monotonic_ns": 1643601910783738, "raw": "{\"arg\":{\"channel\":\"books\",\"instId\":\"BTC-USDT-SWAP\"},\"action\":\"update\",\"data\":[{\"asks\":[[\"64499.5\",\"62.05\",\"0\",\"2\"],[\"64499.6\",\"62.17\",\"0\",\"3\"],[\"64505.1\",\"0.02\",\"0\",\"2\"],[\"64505.6\",\"91.7\",\"0\",\"5\"],[\"64509.5\",\"0\",\"0\",\"0\"],[\"64510.1\",\"85.35\",\"0\",\"2\"],[\"64510.4\",\"58.21\",\"0\",\"4\"],[\"64515.7\",\"61.85\",\"0\",\"4\"],[\"64516.2\",\"35.72\",\"0\",\"2\"],[\"64527\",\"0.17\",\"0\",\"3\"]],\"bids\":[[\"64477.6\",\"0.01\",\"0\",\"1\"],[\"64477.3\",\"79.1\",\"0\",\"2\"],[\"64477.2\",\"18.63\",\"0\",\"2\"],[\"64475.3\",\"1.56\",\"0\",\"1\"],[\"64472\",\"0.33\",\"0\",\"3\"],[\"64471.5\",\"0.01\",\"0\",\"1\"],[\"64468.8\",\"11.33\",\"0\",\"1\"],[\"64467.4\",\"132.71\",\"0\",\"2\"],[\"64466.7\",\"0\",\"0\",\"0\"],[\"64465.7\",\"20.08\",\"0\",\"1\"],[\"64465.3\",\"46.6\",\"0\",\"5\"],[\"64464.9\",\"85.4\",\"0\",\"1\"],[\"64464.8\",\"0.01\",\"0\",\"1\"],[\"64464.7\",\"1\",\"0\",\"1\"],[\"64464.6\",\"31.05\",\"0\",\"1\"],[\"64463.9\",\"232.91\",\"0\",\"1\"],[\"64463.4\",\"0\",\"0\",\"0\"],[\"64462.2\",\"58.22\",\"0\",\"1\"],[\"64462\",\"200.01\",\"0\",\"2\"],[\"64423.6\",\"0\",\"0\",\"0\"],[\"64423.3\",\"0\",\"0\",\"0\"],[\"64423.2\",\"0\",\"0\",\"0\"]],\"ts\":\"1782016046005\",\"checksum\":-1460283450,\"seqId\":325070092262,\"prevSeqId\":325070092191}]}"}
{"action": null, "capture_sequence": 359, "channel": "trades", "connection_sequence": 3, "event": null, "instId": "BTC-USDT-SWAP", "local_receive_ts": "2026-06-21T04:27:26Z", "monotonic_ns": 1643601954584687, "raw": "{\"arg\":{\"channel\":\"trades\",\"instId\":\"BTC-USDT-SWAP\"},\"data\":[{\"instId\":\"BTC-USDT-SWAP\",\"tradeId\":\"2718750326\",\"px\":\"64482.9\",\"sz\":\"0.06\",\"side\":\"sell\",\"ts\":\"1782016046050\",\"count\":\"1\",\"source\":\"0\",\"seqId\":325070092374}]}"}
{"action": "update", "capture_sequence": 360, "channel": "books", "connection_sequence": 3, "event": null, "instId": "BTC-USDT-SWAP", "local_receive_ts": "2026-06-21T04:27:26Z", "monotonic_ns": 1643602011450495, "raw": "{\"arg\":{\"channel\":\"books\",\"instId\":\"BTC-USDT-SWAP\"},\"action\":\"update\",\"data\":[{\"asks\":[[\"64504.4\",\"1.13\",\"0\",\"4\"],[\"64504.7\",\"1.56\",\"0\",\"2\"],[\"64506.5\",\"16.49\",\"0\",\"3\"],[\"64506.7\",\"0.19\",\"0\",\"15\"],[\"64510.1\",\"0.01\",\"0\",\"1\"],[\"64510.4\",\"143.55\",\"0\",\"5\"],[\"64516.2\",\"15.65\",\"0\",\"1\"],[\"64516.3\",\"22.23\",\"0\",\"4\"]],\"bids\":[[\"64482.9\",\"494.9\",\"0\",\"38\"],[\"64478.2\",\"1.57\",\"0\",\"2\"],[\"64477.4\",\"77.55\",\"0\",\"2\"],[\"64477.3\",\"0\",\"0\",\"0\"],[\"64477.2\",\"20.19\",\"0\",\"3\"],[\"64475.7\",\"0\",\"0\",\"0\"],[\"64474.8\",\"32.63\",\"0\",\"3\"],[\"64472.2\",\"1.91\",\"0\",\"2\"],[\"64472\",\"0.02\",\"0\",\"2\"],[\"64468.8\",\"97.5\",\"0\",\"2\"],[\"64467.4\",\"46.54\",\"0\",\"1\"],[\"64464.9\",\"0\",\"0\",\"0\"],[\"64464.8\",\"116.46\",\"0\",\"3\"],[\"64464.6\",\"0\",\"0\",\"0\"],[\"64461.9\",\"2.31\",\"0\",\"3\"],[\"64461.4\",\"51.47\",\"0\",\"7\"],[\"64461\",\"0.02\",\"0\",\"1\"],[\"64460.9\",\"95.5\",\"0\",\"2\"],[\"64423.6\",\"1.2\",\"0\",\"1\"],[\"64423.3\",\"512.29\",\"0\",\"3\"],[\"64423.2\",\"38.43\",\"0\",\"2\"]],\"ts\":\"1782016046105\",\"checksum\":1359292778,\"seqId\":325070092443,\"prevSeqId\":325070092262}]}"}
{"action": null, "capture_sequence": 361, "channel": "trades", "connection_sequence": 3, "event": null, "instId": "BTC-USDT-SWAP", "local_receive_ts": "2026-06-21T04:27:26Z", "monotonic_ns": 1643602055318916, "raw": "{\"arg\":{\"channel\":\"trades\",\"instId\":\"BTC-USDT-SWAP\"},\"data\":[{\"instId\":\"BTC-USDT-SWAP\",\"tradeId\":\"2718750327\",\"px\":\"64482.9\",\"sz\":\"0.02\",\"side\":\"sell\",\"ts\":\"1782016046150\",\"count\":\"1\",\"source\":\"0\",\"seqId\":325070092505}]}"}
{"action": "update", "capture_sequence": 362, "channel": "books", "connection_sequence": 3, "event": null, "instId": "BTC-USDT-SWAP", "local_receive_ts": "2026-06-21T04:27:26Z", "monotonic_ns": 1643602110623407, "raw": "{\"arg\":{\"channel\":\"books\",\"instId\":\"BTC-USDT-SWAP\"},\"action\":\"update\",\"data\":[{\"asks\":[[\"64505.6\",\"57.91\",\"0\",\"4\"],[\"64506.2\",\"33.82\",\"0\",\"3\"],[\"64510.4\",\"0.03\",\"0\",\"3\"],[\"64510.8\",\"85.36\",\"0\",\"2\"],[\"64510.9\",\"58.25\",\"0\",\"5\"],[\"64516.3\",\"2.16\",\"0\",\"3\"],[\"64516.7\",\"20.43\",\"0\",\"10\"]],\"bids\":[[\"64482.9\",\"494.89\",\"0\",\"38\"],[\"64477.6\",\"77.55\",\"0\",\"2\"],[\"64477.5\",\"1.86\",\"0\",\"2\"],[\"64477.4\",\"0.01\",\"0\",\"1\"],[\"64477.2\",\"18.63\",\"0\",\"2\"],[\"64477\",\"1.57\",\"0\",\"2\"],[\"64476.7\",\"4.78\",\"0\",\"2\"],[\"64476.5\",\"1.56\",\"0\",\"1\"],[\"64476.2\",\"0.01\",\"0\",\"1\"],[\"64476.1\",\"264.05\",\"0\",\"3\"],[\"64469.4\",\"132.71\",\"0\",\"2\"],[\"64468.8\",\"11.33\",\"0\",\"1\"],[\"64467.3\",\"129.34\",\"0\",\"3\"],[\"64466.2\",\"20.09\",\"0\",\"2\"],[\"64465.7\",\"0\",\"0\",\"0\"],[\"64465.4\",\"593.26\",\"0\",\"4\"],[\"64464.8\",\"0.01\",\"0\",\"1\"],[\"64464.4\",\"31.06\",\"0\",\"2\"],[\"64464.1\",\"0\",\"0\",\"0\"],[\"64463.8\",\"347.8\",\"0\",\"3\"],[\"64461\",\"0\",\"0\",\"0\"],[\"64460.8\",\"154.65\",\"0\",\"5\"],[\"64423.1\",\"92.81\",\"0\",\"2\"],[\"64423\",\"1.59\",\"0\",\"6\"]],\"ts\":\"1782016046205\",\"checksum\":1858700108,\"seqId\":325070092518,\"prevSeqId\":325070092443}]}"}
{"action": "update", "capture_sequence": 363, "channel": "books", "connection_sequence": 3, "event": null, "instId": "BTC-USDT-SWAP", "local_receive_ts": "2026-06-21T04:27:26Z", "monotonic_ns": 1643602210655360, "raw": "{\"arg\":{\"channel\":\"books\",\"instId\":\"BTC-USDT-SWAP\"},\"action\":\"update\",\"data\":[{\"asks\":[[\"64516.7\",\"0.36\",\"0\",\"9\"],[\"64516.9\",\"34.12\",\"0\",\"5\"]],\"bids\":[[\"64482.8\",\"10.76\",\"0\",\"14\"],[\"64482.1\",\"0.04\",\"0\",\"2\"],[\"64482\",\"7.75\",\"0\",\"1\"],[\"64480.1\",\"0.01\",\"0\",\"1\"],[\"64478.2\",\"0.01\",\"0\",\"1\"],[\"64478.1\",\"91.49\",\"0\",\"2\"],[\"64477.6\",\"0.01\",\"0\",\"1\"],[\"64477.5\",\"0.3\",\"0\",\"1\"],[\"64477\",\"0.01\",\"0\",\"1\"],[\"64476.6\",\"31.05\",\"0\",\"2\"],[\"64476.5\",\"111.85\",\"0\",\"2\"],[\"64476.4\",\"1.54\",\"0\",\"2\"],[\"64474.3\",\"3.1\",\"0\",\"1\"],[\"64472.5\",\"4.66\",\"0\",\"2\"],[\"64472.1\",\"0.82\",\"0\",\"3\"],[\"64423.1\",\"0\",\"0\",\"0\"],[\"64423\",\"0\",\"0\",\"0\"]],\"ts\":\"1782016046305\",\"checksum\":-382240943,\"seqId\":325070092579,\"prevSeqId\":325070092518}]}"}
{"action": "update", "capture_sequence": 364, "channel": "books", "connection_sequence": 3, "event": null, "instId": "BTC-USDT-SWAP", "local_receive_ts": "2026-06-21T04:27:26Z", "monotonic_ns": 1643602310637964, "raw": "{\"arg\":{\"channel\":\"books\",\"instId\":\"BTC-USDT-SWAP\"},\"action\":\"update\",\"data\":[{\"asks\":[[\"64517.9\",\"0.15\",\"0\",\"3\"],[\"64518.3\",\"86.12\",\"0\",\"3\"]],\"bids\":[[\"64478.1\",\"13.95\",\"0\",\"1\"],[\"64477.5\",\"0.46\",\"0\",\"2\"],[\"64477.4\",\"1.55\",\"0\",\"3\"],[\"64477.3\",\"77.54\",\"0\",\"1\"],[\"64476.5\",\"110.29\",\"0\",\"1\"],[\"64476.4\",\"0\",\"0\",\"0\"],[\"64476.1\",\"262.49\",\"0\",\"2\"],[\"64475.3\",\"0\",\"0\",\"0\"],[\"64474.8\",\"31.07\",\"0\",\"2\"],[\"64469.9\",\"107.45\",\"0\",\"3\"],[\"64466.9\",\"0.02\",\"0\",\"1\"],[\"64466.7\",\"0.02\",\"0\",\"1\"],[\"64465.3\",\"46.56\",\"0\",\"3\"],[\"64464.1\",\"0.02\",\"0\",\"1\"],[\"64463.8\",\"347.78\",\"0\",\"2\"],[\"64463\",\"0.04\",\"0\",\"3\"],[\"64461.9\",\"2.29\",\"0\",\"2\"],[\"64461.2\",\"0.06\",\"0\",\"3\"],[\"64460.8\",\"154.63\",\"0\",\"4\"],[\"64423.3\",\"0\",\"0\",\"0\"],[\"64423.2\",\"0\",\"0\",\"0\"]],\"ts\":\"1782016046405\",\"checksum\":-382240943,\"seqId\":325070092614,\"prevSeqId\":325070092579}]}"}
{"action": "update", "capture_sequence": 365, "channel": "books", "connection_sequence": 3, "event": null, "instId": "BTC-USDT-SWAP", "local_receive_ts": "2026-06-21T04:27:26Z", "monotonic_ns": 1643602410811657, "raw": "{\"arg\":{\"channel\":\"books\",\"instId\":\"BTC-USDT-SWAP\"},\"action\":\"update\",\"data\":[{\"asks\":[[\"64499.3\",\"15.51\",\"0\",\"1\"],[\"64499.5\",\"46.54\",\"0\",\"1\"],[\"64501.6\",\"32.92\",\"0\",\"4\"],[\"64501.9\",\"0.08\",\"0\",\"1\"],[\"64502.5\",\"232.97\",\"0\",\"4\"],[\"64502.7\",\"0.03\",\"0\",\"3\"],[\"64510.8\",\"0.02\",\"0\",\"1\"],[\"64510.9\",\"85.4\",\"0\",\"5\"],[\"64511.2\",\"58.2\",\"0\",\"3\"],[\"64516.9\",\"14.05\",\"0\",\"4\"],[\"64517.7\",\"38.74\",\"0\",\"5\"],[\"64518.3\",\"0.02\",\"0\",\"2\"],[\"64519.7\",\"96.91\",\"0\",\"8\"],[\"64527\",\"0\",\"0\",\"0\"]],\"bids\":[[\"64477.4\",\"0.01\",\"0\",\"1\"],[\"64476.6\",\"0.01\",\"0\",\"1\"],[\"64476.5\",\"0\",\"0\",\"0\"],[\"64476.4\",\"32.58\",\"0\",\"3\"],[\"64470.2\",\"93.91\",\"0\",\"2\"],[\"64469.9\",\"169.58\",\"0\",\"4\"],[\"64469.4\",\"46.54\",\"0\",\"1\"],[\"64467.4\",\"80.35\",\"0\",\"2\"],[\"64467.3\",\"115.61\",\"0\",\"3\"],[\"64466.9\",\"0\",\"0\",\"0\"],[\"64466.7\",\"0.04\",\"0\",\"2\"],[\"64466.2\",\"0.01\",\"0\",\"1\"],[\"64465.5\",\"85.39\",\"0\",\"1\"],[\"64465.4\",\"507.87\",\"0\",\"3\"],[\"64464.4\",\"0.01\",\"0\",\"1\"],[\"64464.3\",\"31.05\",\"0\",\"1\"],[\"64463.9\",\"0\",\"0\",\"0\"],[\"64463.4\",\"232.91\",\"0\",\"1\"],[\"64463.2\",\"58.22\",\"0\",\"1\"],[\"64462.2\",\"0\",\"0\",\"0\"],[\"64423.6\",\"0\",\"0\",\"0\"]],\"ts\":\"1782016046505\",\"checksum\":-382240943,\"seqId\":325070092695,\"prevSeqId\":325070092614}]}"}
{"action": "update", "capture_sequence": 366, "channel": "books", "connection_sequence": 3, "event": null, "instId": "BTC-USDT-SWAP", "local_receive_ts": "2026-06-21T04:27:26Z", "monotonic_ns": 1643602510783325, "raw": "{\"arg\":{\"channel\":\"books\",\"instId\":\"BTC-USDT-SWAP\"},\"action\":\"update\",\"data\":[{\"asks\":[[\"64498.8\",\"512.06\",\"0\",\"4\"],[\"64499.3\",\"0\",\"0\",\"0\"],[\"64501.4\",\"31.04\",\"0\",\"2\"],[\"64501.6\",\"1.89\",\"0\",\"3\"],[\"64502.1\",\"232.78\",\"0\",\"2\"],[\"64502.5\",\"0.2\",\"0\",\"3\"],[\"64502.6\",\"15.67\",\"0\",\"3\"],[\"64502.8\",\"57.07\",\"0\",\"3\"],[\"64516.8\",\"26.33\",\"0\",\"4\"],[\"64517.7\",\"18.68\",\"0\",\"4\"],[\"64517.9\",\"86.25\",\"0\",\"4\"],[\"64519.7\",\"10.81\",\"0\",\"7\"],[\"64527\",\"0.17\",\"0\",\"3\"]],\"bids\":[[\"64480\",\"81.85\",\"0\",\"6\"],[\"64477.9\",\"1.56\",\"0\",\"1\"],[\"64477.5\",\"33.04\",\"0\",\"5\"],[\"64477.4\",\"112.51\",\"0\",\"3\"],[\"64476.9\",\"5.58\",\"0\",\"4\"],[\"64476.4\",\"0\",\"0\",\"0\"],[\"64475.6\",\"1.56\",\"0\",\"1\"],[\"64470.2\",\"7.75\",\"0\",\"1\"],[\"64469.3\",\"582.7\",\"0\",\"2\"],[\"64467.3\",\"95.53\",\"0\",\"2\"],[\"64466.7\",\"0\",\"0\",\"0\"],[\"64466.2\",\"20.09\",\"0\",\"2\"],[\"64465.4\",\"507.91\",\"0\",\"5\"],[\"64464.3\",\"0\",\"0\",\"0\"],[\"64463.9\",\"31.05\",\"0\",\"1\"],[\"64463.4\",\"0\",\"0\",\"0\"],[\"64463.2\",\"291.13\",\"0\",\"2\"],[\"64463\",\"0.02\",\"0\",\"2\"],[\"64461.9\",\"2.31\",\"0\",\"3\"],[\"64461.2\",\"0.04\",\"0\",\"2\"],[\"64461\",\"0.02\",\"0\",\"1\"]],\"ts\":\"1782016046605\",\"checksum\":1757933632,\"seqId\":325070092776,\"prevSeqId\":325070092695}]}"}
{"action": "update", "capture_sequence": 367, "channel": "books", "connection_sequence": 3, "event": null, "instId": "BTC-USDT-SWAP", "local_receive_ts": "2026-06-21T04:27:26Z", "monotonic_ns": 1643602610468662, "raw": "{\"arg\":{\"channel\":\"books\",\"instId\":\"BTC-USDT-SWAP\"},\"action\":\"update\",\"data\":[{\"asks\":[[\"64498.8\",\"496.55\",\"0\",\"3\"],[\"64499.3\",\"15.51\",\"0\",\"1\"],[\"64502.1\",\"0.01\",\"0\",\"1\"],[\"64502.3\",\"11.27\",\"0\",\"5\"],[\"64502.5\",\"232.97\",\"0\",\"4\"],[\"64502.6\",\"15.66\",\"0\",\"2\"],[\"64527\",\"0\",\"0\",\"0\"]],\"bids\":[[\"64477.9\",\"0\",\"0\",\"0\"],[\"64477.4\",\"110.95\",\"0\",\"2\"],[\"64476.9\",\"4.02\",\"0\",\"3\"],[\"64475.6\",\"0\",\"0\",\"0\"],[\"64475.1\",\"140.17\",\"0\",\"6\"],[\"64466.7\",\"0.04\",\"0\",\"2\"],[\"64465.4\",\"507.87\",\"0\",\"3\"],[\"64463.4\",\"232.91\",\"0\",\"1\"],[\"64463.2\",\"58.22\",\"0\",\"1\"],[\"64463.1\",\"37.25\",\"0\",\"2\"],[\"64461.9\",\"2.29\",\"0\",\"2\"],[\"64461.2\",\"0.06\",\"0\",\"3\"],[\"64461\",\"0\",\"0\",\"0\"],[\"64423.6\",\"1.2\",\"0\",\"1\"]],\"ts\":\"1782016046705\",\"checksum\":1757933632,\"seqId\":325070092799,\"prevSeqId\":325070092776}]}"}
{"action": "update", "capture_sequence": 368, "channel": "books", "connection_sequence": 3, "event": null, "instId": "BTC-USDT-SWAP", "local_receive_ts": "2026-06-21T04:27:26Z", "monotonic_ns": 1643602710447541, "raw": "{\"arg\":{\"channel\":\"books\",\"instId\":\"BTC-USDT-SWAP\"},\"action\":\"update\",\"data\":[{\"asks\":[],\"bids\":[[\"64482.8\",\"8.26\",\"0\",\"13\"]],\"ts\":\"1782016046805\",\"checksum\":-1451519605,\"seqId\":325070092804,\"prevSeqId\":325070092799}]}"}
{"action": "update", "capture_sequence": 369, "channel": "books", "connection_sequence": 3, "event": null, "instId": "BTC-USDT-SWAP", "local_receive_ts": "2026-06-21T04:27:27Z", "monotonic_ns": 1643602810403648, "raw": "{\"arg\":{\"channel\":\"books\",\"instId\":\"BTC-USDT-SWAP\"},\"action\":\"update\",\"data\":[{\"asks\":[[\"64483\",\"551.35\",\"0\",\"47\"],[\"64520\",\"78.62\",\"0\",\"63\"]],\"bids\":[[\"64475.1\",\"138.61\",\"0\",\"5\"],[\"64473.9\",\"0.03\",\"0\",\"2\"],[\"64449.5\",\"0.01\",\"0\",\"1\"],[\"64425.5\",\"11.06\",\"0\",\"1\"]],\"ts\":\"1782016046905\",\"checksum\":1147049600,\"seqId\":325070092815,\"prevSeqId\":325070092804}]}"}
{"action": null, "capture_sequence": 370, "channel": "trades", "connection_sequence": 3, "event": null, "instId": "BTC-USDT-SWAP", "local_receive_ts": "2026-06-21T04:27:27Z", "monotonic_ns": 1643602885297954, "raw": "{\"arg\":{\"channel\":\"trades\",\"instId\":\"BTC-USDT-SWAP\"},\"data\":[{\"instId\":\"BTC-USDT-SWAP\",\"tradeId\":\"2718750328\",\"px\":\"64482.9\",\"sz\":\"0.16\",\"side\":\"sell\",\"ts\":\"1782016046980\",\"count\":\"1\",\"source\":\"0\",\"seqId\":325070092837}]}"}
{"action": "update", "capture_sequence": 371, "channel": "books", "connection_sequence": 3, "event": null, "instId": "BTC-USDT-SWAP", "local_receive_ts": "2026-06-21T04:27:27Z", "monotonic_ns": 1643602916471667, "raw": "{\"arg\":{\"channel\":\"books\",\"instId\":\"BTC-USDT-SWAP\"},\"action\":\"update\",\"data\":[{\"asks\":[[\"64490.1\",\"0.31\",\"0\",\"3\"],[\"64490.2\",\"1.2\",\"0\",\"1\"],[\"64499.3\",\"0\",\"0\",\"0\"],[\"64499.8\",\"16.59\",\"0\",\"3\"],[\"64501.4\",\"0.01\",\"0\",\"1\"],[\"64502.1\",\"31.04\",\"0\",\"2\"],[\"64502.3\",\"11.26\",\"0\",\"4\"],[\"64502.5\",\"0.2\",\"0\",\"3\"],[\"64502.9\",\"513.49\",\"0\",\"8\"],[\"64503\",\"15.96\",\"0\",\"4\"],[\"64504.6\",\"0.31\",\"0\",\"1\"],[\"64504.9\",\"0.1\",\"0\",\"3\"],[\"64510.6\",\"58.37\",\"0\",\"3\"],[\"64510.9\",\"0.07\",\"0\",\"4\"],[\"64511.2\",\"0.02\",\"0\",\"2\"],[\"64511.7\",\"85.35\",\"0\",\"3\"],[\"64516.8\",\"6.26\",\"0\",\"3\"],[\"64517.6\",\"45.64\",\"0\",\"3\"],[\"64517.9\",\"213.25\",\"0\",\"4\"],[\"64519.7\",\"96.91\",\"0\",\"8\"],[\"64522.2\",\"0.15\",\"0\",\"8\"],[\"64522.8\",\"15.72\",\"0\",\"5\"]],\"bids\":[[\"64482.9\",\"494.73\",\"0\",\"38\"],[\"64480\",\"55.28\",\"0\",\"5\"],[\"64479.6\",\"0.02\",\"0\",\"2\"],[\"64477.5\",\"0.46\",\"0\",\"2\"],[\"64477.4\",\"0.01\",\"0\",\"1\"],[\"64476.4\",\"32.58\",\"0\",\"3\"],[\"64472.2\",\"1.6\",\"0\",\"1\"],[\"64472\",\"0.33\",\"0\",\"3\"],[\"64470\",\"126.55\",\"0\",\"6\"],[\"64469.3\",\"496.53\",\"0\",\"1\"],[\"64467.2\",\"89.98\",\"0\",\"2\"],[\"64466.9\",\"0.02\",\"0\",\"1\"],[\"64466.7\",\"0.02\",\"0\",\"1\"],[\"64466.3\",\"85.39\",\"0\",\"1\"],[\"64466.2\",\"0.01\",\"0\",\"1\"],[\"64465.5\",\"0\",\"0\",\"0\"],[\"64464.8\",\"31.06\",\"0\",\"2\"],[\"64464\",\"232.97\",\"0\",\"5\"],[\"64463.9\",\"0\",\"0\",\"0\"],[\"64463.4\",\"0\",\"0\",\"0\"],[\"64463.2\",\"0\",\"0\",\"0\"],[\"64462.2\",\"58.22\",\"0\",\"1\"],[\"64452.6\",\"512.18\",\"0\",\"2\"],[\"64446.7\",\"217.47\",\"0\",\"4\"]],\"ts\":\"1782016047005\",\"checksum\":1628683634,\"seqId\":325070092878,\"prevSeqId\":325070092815}]}"}
{"action": "update", "capture_sequence": 372, "channel": "books", "connection_sequence": 3, "event": null, "instId": "BTC-USDT-SWAP", "local_receive_ts": "2026-06-21T04:27:27Z", "monotonic_ns": 1643603011683628, "raw": "{\"arg\":{\"channel\":\"books\",\"instId\":\"BTC-USDT-SWAP\"},\"action\":\"update\",\"data\":[{\"asks\":[[\"64499.5\",\"62.05\",\"0\",\"2\"],[\"64499.8\",\"1.08\",\"0\",\"2\"],[\"64504.3\",\"1.59\",\"0\",\"3\"],[\"64504.6\",\"0\",\"0\",\"0\"],[\"64504.7\",\"0.01\",\"0\",\"1\"],[\"64505.1\",\"0.33\",\"0\",\"3\"],[\"64510.6\",\"143.71\",\"0\",\"4\"],[\"64511.7\",\"0.02\",\"0\",\"2\"],[\"64516.7\",\"20.43\",\"0\",\"10\"],[\"64517.6\",\"25.58\",\"0\",\"2\"],[\"64517.8\",\"86.2\",\"0\",\"4\"],[\"64519.7\",\"10.81\",\"0\",\"7\"],[\"64522.2\",\"0.16\",\"0\",\"9\"],[\"64522.8\",\"15.71\",\"0\",\"4\"],[\"64527\",\"0.17\",\"0\",\"3\"]],\"bids\":[[\"64478.3\",\"1.57\",\"0\",\"2\"],[\"64477.8\",\"77.54\",\"0\",\"1\"],[\"64477.3\",\"0\",\"0\",\"0\"],[\"64477\",\"1.57\",\"0\",\"2\"],[\"64476.6\",\"1.57\",\"0\",\"2\"],[\"64476.1\",\"264.05\",\"0\",\"3\"],[\"64475.6\",\"1.56\",\"0\",\"1\"],[\"64475.1\",\"140.17\",\"0\",\"6\"],[\"64472.3\",\"0.32\",\"0\",\"2\"],[\"64472\",\"0.02\",\"0\",\"2\"],[\"64470\",\"40.39\",\"0\",\"5\"],[\"64468.8\",\"97.5\",\"0\",\"2\"],[\"64467.2\",\"69.9\",\"0\",\"1\"],[\"64466.7\",\"0\",\"0\",\"0\"],[\"64466.3\",\"0\",\"0\",\"0\"],[\"64466.2\",\"20.09\",\"0\",\"2\"],[\"64465.4\",\"593.26\",\"0\",\"4\"],[\"64465.3\",\"46.58\",\"0\",\"4\"],[\"64463.1\",\"37.23\",\"0\",\"1\"],[\"64463\",\"0.04\",\"0\",\"3\"],[\"64451.8\",\"49.54\",\"0\",\"2\"],[\"64423.3\",\"512.29\",\"0\",\"3\"]],\"ts\":\"1782016047105\",\"checksum\":1628683634,\"seqId\":325070092986,\"prevSeqId\":325070092878}]}"}
{"action": null, "capture_sequence": 373, "channel": "trades", "connection_sequence": 3, "event": null, "instId": "BTC-USDT-SWAP", "local_receive_ts": "2026-06-21T04:27:27Z", "monotonic_ns": 1643603074338705, "raw": "{\"arg\":{\"channel\":\"trades\",\"instId\":\"BTC-USDT-SWAP\"},\"data\":[{\"instId\":\"BTC-USDT-SWAP\",\"tradeId\":\"2718750329\",\"px\":\"64482.9\",\"sz\":\"0.06\",\"side\":\"sell\",\"ts\":\"1782016047169\",\"count\":\"1\",\"source\":\"0\",\"seqId\":325070093038}]}"}
{"action": "update", "capture_sequence": 374, "channel": "books", "connection_sequence": 3, "event": null, "instId": "BTC-USDT-SWAP", "local_receive_ts": "2026-06-21T04:27:27Z", "monotonic_ns": 1643603110670569, "raw": "{\"arg\":{\"channel\":\"books\",\"instId\":\"BTC-USDT-SWAP\"},\"action\":\"update\",\"data\":[{\"asks\":[[\"64502.7\",\"232.8\",\"0\",\"4\"],[\"64502.9\",\"280.72\",\"0\",\"7\"]],\"bids\":[[\"64482.9\",\"494.53\",\"0\",\"38\"],[\"64480\",\"77.06\",\"0\",\"6\"],[\"64479.7\",\"0\",\"0\",\"0\"],[\"64478.3\",\"0.01\",\"0\",\"1\"],[\"64477.8\",\"0\",\"0\",\"0\"],[\"64477.5\",\"33.04\",\"0\",\"5\"],[\"64477.4\",\"107.45\",\"0\",\"2\"],[\"64477.3\",\"77.54\",\"0\",\"1\"],[\"64476.4\",\"0\",\"0\",\"0\"],[\"64474.6\",\"1.94\",\"0\",\"2\"],[\"64472.5\",\"3.1\",\"0\",\"1\"],[\"64466.9\",\"0\",\"0\",\"0\"],[\"64465.3\",\"46.6\",\"0\",\"5\"],[\"64464\",\"0.06\",\"0\",\"4\"],[\"64463.4\",\"232.91\",\"0\",\"1\"],[\"64463\",\"0.02\",\"0\",\"2\"],[\"64462\",\"200.03\",\"0\",\"3\"],[\"64461.2\",\"0.04\",\"0\",\"2\"],[\"64461\",\"0.02\",\"0\",\"1\"],[\"64423.2\",\"38.43\",\"0\",\"2\"]],\"ts\":\"1782016047205\",\"checksum\":-668344538,\"seqId\":325070093057,\"prevSeqId\":325070092986}]}"}
{"action": "update", "capture_sequence": 375, "channel": "books", "connection_sequence": 3, "event": null, "instId": "BTC-USDT-SWAP", "local_receive_ts": "2026-06-21T04:27:27Z", "monotonic_ns": 1643603210608986, "raw": "{\"arg\":{\"channel\":\"books\",\"instId\":\"BTC-USDT-SWAP\"},\"action\":\"update\",\"data\":[{\"asks\":[[\"64497.3\",\"41.14\",\"0\",\"4\"],[\"64497.4\",\"0.23\",\"0\",\"2\"],[\"64502.8\",\"57.08\",\"0\",\"4\"],[\"64503\",\"15.95\",\"0\",\"3\"]],\"bids\":[[\"64482.9\",\"494.59\",\"0\",\"40\"],[\"64482.8\",\"10.96\",\"0\",\"14\"],[\"64480\",\"78.62\",\"0\",\"7\"],[\"64479.4\",\"1.56\",\"0\",\"1\"],[\"64478.7\",\"1.57\",\"0\",\"2\"],[\"64478.3\",\"1.57\",\"0\",\"2\"],[\"64477.5\",\"34.6\",\"0\",\"6\"],[\"64477.1\",\"1.57\",\"0\",\"2\"],[\"64477\",\"0.01\",\"0\",\"1\"],[\"64474.6\",\"0.38\",\"0\",\"1\"],[\"64473.5\",\"97.98\",\"0\",\"1\"],[\"64473\",\"0\",\"0\",\"0\"],[\"64466.7\",\"0.02\",\"0\",\"1\"],[\"64465.3\",\"46.58\",\"0\",\"4\"],[\"64464.5\",\"0.02\",\"0\",\"2\"],[\"64464.4\",\"3.16\",\"0\",\"2\"],[\"64451.8\",\"46.54\",\"0\",\"1\"],[\"64423.2\",\"0\",\"0\",\"0\"]],\"ts\":\"1782016047305\",\"checksum\":1969653820,\"seqId\":325070093101,\"prevSeqId\":325070093057}]}"}
{"action": "update", "capture_sequence": 376, "channel": "books", "connection_sequence": 3, "event": null, "instId": "BTC-USDT-SWAP", "local_receive_ts": "2026-06-21T04:27:27Z", "monotonic_ns": 1643603316053279, "raw": "{\"arg\":{\"channel\":\"books\",\"instId\":\"BTC-USDT-SWAP\"},\"action\":\"update\",\"data\":[{\"asks\":[[\"64483\",\"433.47\",\"0\",\"45\"],[\"64484\",\"8.64\",\"0\",\"6\"],[\"64484.3\",\"35.72\",\"0\",\"1\"],[\"64484.9\",\"0.01\",\"0\",\"1\"],[\"64486.5\",\"154.5\",\"0\",\"3\"],[\"64486.7\",\"136.13\",\"0\",\"1\"],[\"64490.1\",\"0.3\",\"0\",\"2\"],[\"64493.4\",\"15.31\",\"0\",\"9\"],[\"64499.5\",\"46.54\",\"0\",\"1\"],[\"64499.9\",\"1134.18\",\"0\",\"4\"],[\"64502.8\",\"57.07\",\"0\",\"3\"],[\"64503\",\"15.96\",\"0\",\"4\"],[\"64504.3\",\"0.04\",\"0\",\"2\"],[\"64504.7\",\"1.56\",\"0\",\"2\"],[\"64505.1\",\"0.02\",\"0\",\"2\"],[\"64505.2\",\"15.96\",\"0\",\"2\"],[\"64506.5\",\"15.72\",\"0\",\"2\"],[\"64507.1\",\"0.83\",\"0\",\"5\"],[\"64510.6\",\"0.19\",\"0\",\"2\"],[\"64511.2\",\"85.35\",\"0\",\"3\"],[\"64512.1\",\"95.42\",\"0\",\"5\"],[\"64516.7\",\"0.36\",\"0\",\"9\"],[\"64517.3\",\"20.06\",\"0\",\"1\"],[\"64517.8\",\"0.1\",\"0\",\"3\"],[\"64518.3\",\"86.12\",\"0\",\"3\"],[\"64522.2\",\"0.15\",\"0\",\"8\"],[\"64522.8\",\"15.72\",\"0\",\"5\"],[\"64526.9\",\"0\",\"0\",\"0\"],[\"64527\",\"0\",\"0\",\"0\"]],\"bids\":[[\"64482.9\",\"540.6\",\"0\",\"42\"],[\"64482.8\",\"11.21\",\"0\",\"13\"],[\"64482.1\",\"0.05\",\"0\",\"3\"],[\"64480\",\"69.02\",\"0\",\"6\"],[\"64479.6\",\"11.44\",\"0\",\"3\"],[\"64479.5\",\"1.56\",\"0\",\"1\"],[\"64479.4\",\"0\",\"0\",\"0\"],[\"64478.7\",\"121.79\",\"0\",\"3\"],[\"64478.2\",\"77.55\",\"0\",\"2\"],[\"64477.5\",\"1.86\",\"0\",\"2\"],[\"64477.4\",\"0.01\",\"0\",\"1\"],[\"64477.3\",\"0\",\"0\",\"0\"],[\"64477.2\",\"6.22\",\"0\",\"1\"],[\"64476.6\",\"13.98\",\"0\",\"3\"],[\"64476.4\",\"32.58\",\"0\",\"3\"],[\"64475\",\"0.02\",\"0\",\"1\"],[\"64474\",\"0.01\",\"0\",\"1\"],[\"64472.7\",\"1.48\",\"0\",\"4\"],[\"64472.3\",\"0.01\",\"0\",\"1\"],[\"64469.4\",\"132.71\",\"0\",\"2\"],[\"64468.8\",\"11.33\",\"0\",\"1\"],[\"64467\",\"282.33\",\"0\",\"4\"],[\"64466.9\",\"0.02\",\"0\",\"1\"],[\"64466.7\",\"0\",\"0\",\"0\"],[\"64465.7\",\"85.39\",\"0\",\"1\"],[\"64465.4\",\"507.87\",\"0\",\"3\"],[\"64464.3\",\"58.22\",\"0\",\"1\"],[\"64464.1\",\"0\",\"0\",\"0\"],[\"64463.7\",\"0.02\",\"0\",\"1\"],[\"64462.2\",\"0\",\"0\",\"0\"],[\"64462\",\"200.01\",\"0\",\"2\"],[\"64461.2\",\"0.06\",\"0\",\"3\"],[\"64461\",\"0\",\"0\",\"0\"],[\"64455.1\",\"0.02\",\"0\",\"1\"],[\"64454.9\",\"12.86\",\"0\",\"1\"],[\"64454.5\",\"3.01\",\"0\",\"2\"],[\"64423.6\",\"0\",\"0\",\"0\"],[\"64423.3\",\"0\",\"0\",\"0\"]],\"ts\":\"1782016047405\",\"checksum\":467764779,\"seqId\":325070093351,\"prevSeqId\":325070093101}]}"}
{"action": null, "capture_sequence": 377, "channel": "trades", "connection_sequence": 3, "event": null, "instId": "BTC-USDT-SWAP", "local_receive_ts": "2026-06-21T04:27:27Z", "monotonic_ns": 1643603341431754, "raw": "{\"arg\":{\"channel\":\"trades\",\"instId\":\"BTC-USDT-SWAP\"},\"data\":[{\"instId\":\"BTC-USDT-SWAP\",\"tradeId\":\"2718750330\",\"px\":\"64483\",\"sz\":\"0.02\",\"side\":\"buy\",\"ts\":\"1782016047436\",\"count\":\"1\",\"source\":\"0\",\"seqId\":325070093406}]}"}
{"action": "update", "capture_sequence": 378, "channel": "books", "connection_sequence": 3, "event": null, "instId": "BTC-USDT-SWAP", "local_receive_ts": "2026-06-21T04:27:27Z", "monotonic_ns": 1643603414218552, "raw": "{\"arg\":{\"channel\":\"books\",\"instId\":\"BTC-USDT-SWAP\"},\"action\":\"update\",\"data\":[{\"asks\":[[\"64483\",\"487.41\",\"0\",\"46\"],[\"64499.3\",\"15.51\",\"0\",\"1\"],[\"64499.9\",\"1118.67\",\"0\",\"3\"],[\"64504.4\",\"2.68\",\"0\",\"5\"],[\"64504.7\",\"0.01\",\"0\",\"1\"],[\"64511.1\",\"76.97\",\"0\",\"7\"],[\"64512.1\",\"37.24\",\"0\",\"4\"],[\"64526.8\",\"0\",\"0\",\"0\"]],\"bids\":[[\"64480\",\"67.46\",\"0\",\"5\"],[\"64479.5\",\"0\",\"0\",\"0\"],[\"64478.7\",\"120.23\",\"0\",\"2\"],[\"64478.2\",\"0.01\",\"0\",\"1\"],[\"64477.6\",\"77.55\",\"0\",\"2\"],[\"64475\",\"0\",\"0\",\"0\"],[\"64474.7\",\"1.57\",\"0\",\"2\"],[\"64474\",\"0.03\",\"0\",\"2\"],[\"64467\",\"282.31\",\"0\",\"3\"],[\"64466.9\",\"0\",\"0\",\"0\"],[\"64465.6\",\"28.25\",\"0\",\"6\"],[\"64465.3\",\"46.56\",\"0\",\"3\"],[\"64464.3\",\"0\",\"0\",\"0\"],[\"64464.1\",\"0.02\",\"0\",\"1\"],[\"64463.7\",\"0\",\"0\",\"0\"],[\"64463.2\",\"58.22\",\"0\",\"1\"],[\"64463\",\"0.04\",\"0\",\"3\"],[\"64455.1\",\"0\",\"0\",\"0\"],[\"64454.9\",\"12.88\",\"0\",\"2\"],[\"64423.6\",\"1.2\",\"0\",\"1\"],[\"64423.3\",\"512.29\",\"0\",\"3\"],[\"64423.2\",\"38.43\",\"0\",\"2\"],[\"64423.1\",\"92.81\",\"0\",\"2\"]],\"ts\":\"1782016047505\",\"checksum\":316983779,\"seqId\":325070093474,\"prevSeqId\":325070093351}]}"}
{"action": "update", "capture_sequence": 379, "channel": "books", "connection_sequence": 3, "event": null, "instId": "BTC-USDT-SWAP", "local_receive_ts": "2026-06-21T04:27:27Z", "monotonic_ns": 1643603511805964, "raw": "{\"arg\":{\"channel\":\"books\",\"instId\":\"BTC-USDT-SWAP\"},\"action\":\"update\",\"data\":[{\"asks\":[[\"64483\",\"485.85\",\"0\",\"45\"],[\"64483.5\",\"0\",\"0\",\"0\"],[\"64492.4\",\"0.09\",\"0\",\"7\"],[\"64493.4\",\"15.3\",\"0\",\"8\"],[\"64502.9\",\"280.73\",\"0\",\"8\"],[\"64503\",\"15.95\",\"0\",\"3\"],[\"64510\",\"271.08\",\"0\",\"30\"],[\"64511\",\"25.02\",\"0\",\"8\"],[\"64526.8\",\"3.46\",\"0\",\"3\"]],\"bids\":[[\"64474.1\",\"496.56\",\"0\",\"3\"],[\"64474\",\"0.01\",\"0\",\"1\"],[\"64466.9\",\"0.02\",\"0\",\"1\"],[\"64465.6\",\"28.23\",\"0\",\"5\"],[\"64459.6\",\"169.56\",\"0\",\"2\"],[\"64457.6\",\"357.43\",\"0\",\"2\"],[\"64448\",\"264.99\",\"0\",\"7\"],[\"64445.5\",\"0\",\"0\",\"0\"],[\"64444.6\",\"496.53\",\"0\",\"1\"]],\"ts\":\"1782016047605\",\"checksum\":747213592,\"seqId\":325070093563,\"prevSeqId\":325070093474}]}"}
{"action": "update", "capture_sequence": 380, "channel": "books", "connection_sequence": 3, "event": null, "instId": "BTC-USDT-SWAP", "local_receive_ts": "2026-06-21T04:27:27Z", "monotonic_ns": 1643603610830174, "raw": "{\"arg\":{\"channel\":\"books\",\"instId\":\"BTC-USDT-SWAP\"},\"action\":\"update\",\"data\":[{\"asks\":[[\"64483\",\"428.59\",\"0\",\"43\"],[\"64483.4\",\"0\",\"0\",\"0\"],[\"64484.5\",\"0.47\",\"0\",\"5\"],[\"64484.9\",\"0.02\",\"0\",\"2\"],[\"64499.3\",\"0\",\"0\",\"0\"],[\"64499.6\",\"77.68\",\"0\",\"4\"],[\"64504.4\",\"1.13\",\"0\",\"4\"],[\"64504.7\",\"1.56\",\"0\",\"2\"],[\"64505.2\",\"15.65\",\"0\",\"1\"],[\"64505.6\",\"58.22\",\"0\",\"5\"],[\"64506.2\",\"0.03\",\"0\",\"2\"],[\"64506.8\",\"126.83\",\"0\",\"7\"],[\"64507.1\",\"0.06\",\"0\",\"4\"],[\"64510\",\"71.08\",\"0\",\"29\"],[\"64511.1\",\"18.79\",\"0\",\"6\"],[\"64511.2\",\"0.02\",\"0\",\"2\"],[\"64511.7\",\"85.35\",\"0\",\"3\"],[\"64512.2\",\"69.41\",\"0\",\"4\"],[\"64517\",\"37.44\",\"0\",\"21\"],[\"64517.3\",\"0\",\"0\",\"0\"],[\"64518.3\",\"0.02\",\"0\",\"2\"],[\"64519.7\",\"96.91\",\"0\",\"8\"],[\"64526.9\",\"40.21\",\"0\",\"5\"],[\"64527\",\"0.17\",\"0\",\"3\"],[\"64527.1\",\"0.46\",\"0\",\"1\"]],\"bids\":[[\"64482.8\",\"46.52\",\"0\",\"14\"],[\"64482.2\",\"1.6\",\"0\",\"1\"],[\"64480.7\",\"120.23\",\"0\",\"2\"],[\"64480.3\",\"0\",\"0\",\"0\"],[\"64478.4\",\"85.54\",\"0\",\"2\"],[\"64477.6\",\"0.01\",\"0\",\"1\"],[\"64473\",\"0.31\",\"0\",\"1\"],[\"64472.7\",\"1.17\",\"0\",\"3\"],[\"64469.9\",\"255.75\",\"0\",\"5\"],[\"64469.4\",\"46.54\",\"0\",\"1\"],[\"64467.9\",\"33.82\",\"0\",\"2\"],[\"64467.4\",\"46.54\",\"0\",\"1\"],[\"64466.4\",\"20.08\",\"0\",\"1\"],[\"64466.2\",\"85.4\",\"0\",\"2\"],[\"64465.7\",\"0\",\"0\",\"0\"],[\"64464.3\",\"58.22\",\"0\",\"1\"],[\"64463.2\",\"0\",\"0\",\"0\"],[\"64423.1\",\"0\",\"0\",\"0\"]],\"ts\":\"1782016047705\",\"checksum\":1274025590,\"seqId\":325070093714,\"prevSeqId\":325070093563}]}"}
{"action": "update", "capture_sequence": 381, "channel": "books", "connection_sequence": 3, "event": null, "instId": "BTC-USDT-SWAP", "local_receive_ts": "2026-06-21T04:27:27Z", "monotonic_ns": 1643603710830863, "raw": "{\"arg\":{\"channel\":\"books\",\"instId\":\"BTC-USDT-SWAP\"},\"action\":\"update\",\"data\":[{\"asks\":[[\"64492.4\",\"0.08\",\"0\",\"6\"],[\"64493.4\",\"15.31\",\"0\",\"9\"],[\"64497.4\",\"0.08\",\"0\",\"1\"],[\"64502.9\",\"280.72\",\"0\",\"7\"],[\"64503\",\"15.96\",\"0\",\"4\"],[\"64508.9\",\"96.47\",\"0\",\"4\"]],\"bids\":[[\"64482.8\",\"11.21\",\"0\",\"13\"],[\"64482.3\",\"2.48\",\"0\",\"2\"],[\"64482.1\",\"0.03\",\"0\",\"2\"],[\"64480.7\",\"0.01\",\"0\",\"1\"],[\"64480.4\",\"0\",\"0\",\"0\"],[\"64480\",\"93.33\",\"0\",\"6\"],[\"64476.9\",\"17.97\",\"0\",\"6\"],[\"64476.8\",\"31.04\",\"0\",\"1\"],[\"64476.7\",\"97.23\",\"0\",\"3\"],[\"64476.6\",\"1.57\",\"0\",\"2\"],[\"64476.4\",\"0\",\"0\",\"0\"],[\"64464.4\",\"0.01\",\"0\",\"1\"],[\"64456\",\"10.04\",\"0\",\"4\"],[\"64454.9\",\"12.86\",\"0\",\"1\"],[\"64423.1\",\"92.81\",\"0\",\"2\"]],\"ts\":\"1782016047805\",\"checksum\":286372172,\"seqId\":325070093809,\"prevSeqId\":325070093714}]}"}
{"action": "update", "capture_sequence": 382, "channel": "books", "connection_sequence": 3, "event": null, "instId": "BTC-USDT-SWAP", "local_receive_ts": "2026-06-21T04:27:28Z", "monotonic_ns": 1643603810656529, "raw": "{\"arg\":{\"channel\":\"books\",\"instId\":\"BTC-USDT-SWAP\"},\"action\":\"update\",\"data\":[{\"asks\":[[\"64483\",\"428.32\",\"0\",\"42\"],[\"64484\",\"7.08\",\"0\",\"5\"],[\"64497.4\",\"0.23\",\"0\",\"2\"],[\"64508.9\",\"160.96\",\"0\",\"5\"],[\"64511\",\"225.02\",\"0\",\"9\"]],\"bids\":[[\"64482\",\"7.76\",\"0\",\"2\"],[\"64464.4\",\"3.16\",\"0\",\"2\"],[\"64442\",\"15.01\",\"0\",\"2\"]],\"ts\":\"1782016047905\",\"checksum\":45395361,\"seqId\":325070093882,\"prevSeqId\":325070093809}]}"}
{"action": null, "capture_sequence": 383, "channel": "trades", "connection_sequence": 3, "event": null, "instId": "BTC-USDT-SWAP", "local_receive_ts": "2026-06-21T04:27:28Z", "monotonic_ns": 1643603852077033, "raw": "{\"arg\":{\"channel\":\"trades\",\"instId\":\"BTC-USDT-SWAP\"},\"data\":[{\"instId\":\"BTC-USDT-SWAP\",\"tradeId\":\"2718750331\",\"px\":\"64482.9\",\"sz\":\"0.77\",\"side\":\"sell\",\"ts\":\"1782016047947\",\"count\":\"1\",\"source\":\"0\",\"seqId\":325070093917}]}"}
{"action": "update", "capture_sequence": 384, "channel": "books", "connection_sequence": 3, "event": null, "instId": "BTC-USDT-SWAP", "local_receive_ts": "2026-06-21T04:27:28Z", "monotonic_ns": 1643603916455865, "raw": "{\"arg\":{\"channel\":\"books\",\"instId\":\"BTC-USDT-SWAP\"},\"action\":\"update\",\"data\":[{\"asks\":[[\"64483\",\"511.22\",\"0\",\"45\"],[\"64483.5\",\"1.56\",\"0\",\"1\"],[\"64484.3\",\"71.91\",\"0\",\"1\"],[\"64484.7\",\"0.41\",\"0\",\"2\"],[\"64484.8\",\"136.13\",\"0\",\"1\"],[\"64484.9\",\"0.01\",\"0\",\"1\"],[\"64486.7\",\"0\",\"0\",\"0\"],[\"64490.1\",\"0.31\",\"0\",\"3\"],[\"64493.4\",\"15.3\",\"0\",\"8\"],[\"64494.3\",\"0.48\",\"0\",\"5\"],[\"64499\",\"348.6\",\"0\",\"22\"],[\"64499.6\",\"59.27\",\"0\",\"3\"],[\"64501.4\",\"31.04\",\"0\",\"2\"],[\"64502.1\",\"0.01\",\"0\",\"1\"],[\"64502.2\",\"316.68\",\"0\",\"7\"],[\"64502.7\",\"0.03\",\"0\",\"3\"],[\"64502.8\",\"57.08\",\"0\",\"4\"],[\"64503\",\"15.95\",\"0\",\"3\"],[\"64504\",\"56.1\",\"0\",\"9\"],[\"64504.7\",\"0.01\",\"0\",\"1\"],[\"64505.1\",\"0.33\",\"0\",\"3\"],[\"64505.5\",\"107.6\",\"0\",\"4\"],[\"64505.6\",\"57.91\",\"0\",\"4\"],[\"64506.8\",\"93.04\",\"0\",\"6\"],[\"64509.9\",\"86.55\",\"0\",\"4\"],[\"64510.9\",\"58.25\",\"0\",\"5\"],[\"64511.7\",\"0.02\",\"0\",\"2\"],[\"64512.2\",\"11.23\",\"0\",\"3\"],[\"64516.1\",\"20.11\",\"0\",\"5\"],[\"64517\",\"17.37\",\"0\",\"20\"],[\"64517.8\",\"86.2\",\"0\",\"4\"],[\"64519.7\",\"10.81\",\"0\",\"7\"],[\"64522\",\"5.19\",\"0\",\"11\"],[\"64522.8\",\"15.71\",\"0\",\"4\"],[\"64527.1\",\"0\",\"0\",\"0\"]],\"bids\":[[\"64482.9\",\"539.83\",\"0\",\"42\"],[\"64482.3\",\"2.49\",\"0\",\"3\"],[\"64480\",\"67.46\",\"0\",\"5\"],[\"64478.7\",\"0.01\",\"0\",\"1\"],[\"64478.4\",\"8\",\"0\",\"1\"],[\"64478.3\",\"0.01\",\"0\",\"1\"],[\"64477.5\",\"79.38\",\"0\",\"4\"],[\"64477.4\",\"31.05\",\"0\",\"2\"],[\"64477.1\",\"0.01\",\"0\",\"1\"],[\"64476.9\",\"16.43\",\"0\",\"4\"],[\"64476.8\",\"0\",\"0\",\"0\"],[\"64476.6\",\"0.01\",\"0\",\"1\"],[\"64476.1\",\"262.49\",\"0\",\"2\"],[\"64475.6\",\"0\",\"0\",\"0\"],[\"64473\",\"0\",\"0\",\"0\"],[\"64472.3\",\"0.32\",\"0\",\"2\"],[\"64469.9\",\"169.58\",\"0\",\"4\"],[\"64467.9\",\"0.01\",\"0\",\"1\"],[\"64467.4\",\"132.71\",\"0\",\"2\"],[\"64466.4\",\"0\",\"0\",\"0\"],[\"64466.2\",\"33.82\",\"0\",\"2\"],[\"64465.7\",\"20.08\",\"0\",\"1\"],[\"64464.8\",\"0.01\",\"0\",\"1\"],[\"64464.5\",\"85.42\",\"0\",\"3\"],[\"64464.3\",\"31.05\",\"0\",\"1\"],[\"64462.9\",\"58.22\",\"0\",\"1\"],[\"64423\",\"1.59\",\"0\",\"6\"],[\"64422.8\",\"1.51\",\"0\",\"2\"]],\"ts\":\"1782016048005\",\"checksum\":-637274539,\"seqId\":325070094060,\"prevSeqId\":325070093882}]}"}
{"action": null, "capture_sequence": 385, "channel": "trades", "connection_sequence": 3, "event": null, "instId": "BTC-USDT-SWAP", "local_receive_ts": "2026-06-21T04:27:28Z", "monotonic_ns": 1643603944802493, "raw": "{\"arg\":{\"channel\":\"trades\",\"instId\":\"BTC-USDT-SWAP\"},\"data\":[{\"instId\":\"BTC-USDT-SWAP\",\"tradeId\":\"2718750332\",\"px\":\"64482.9\",\"sz\":\"0.37\",\"side\":\"sell\",\"ts\":\"1782016048040\",\"count\":\"1\",\"source\":\"0\",\"seqId\":325070094171}]}"}
{"action": "update", "capture_sequence": 386, "channel": "books", "connection_sequence": 3, "event": null, "instId": "BTC-USDT-SWAP", "local_receive_ts": "2026-06-21T04:27:28Z", "monotonic_ns": 1643604016283931, "raw": "{\"arg\":{\"channel\":\"books\",\"instId\":\"BTC-USDT-SWAP\"},\"action\":\"update\",\"data\":[{\"asks\":[[\"64483\",\"521.22\",\"0\",\"46\"],[\"64483.4\",\"0.01\",\"0\",\"1\"],[\"64484.7\",\"0.4\",\"0\",\"1\"],[\"64499\",\"333.09\",\"0\",\"21\"],[\"64499.3\",\"15.51\",\"0\",\"1\"],[\"64501.4\",\"0.01\",\"0\",\"1\"],[\"64501.6\",\"32.92\",\"0\",\"4\"],[\"64502.2\",\"83.91\",\"0\",\"6\"],[\"64502.5\",\"232.97\",\"0\",\"4\"],[\"64502.6\",\"15.67\",\"0\",\"3\"],[\"64502.8\",\"57.07\",\"0\",\"3\"],[\"64504\",\"54.55\",\"0\",\"8\"],[\"64504.1\",\"22.88\",\"0\",\"8\"],[\"64504.9\",\"0.41\",\"0\",\"4\"],[\"64505.1\",\"0.02\",\"0\",\"2\"],[\"64505.3\",\"34.95\",\"0\",\"3\"],[\"64505.5\",\"73.81\",\"0\",\"3\"],[\"64506.4\",\"0.8\",\"0\",\"4\"],[\"64506.8\",\"92.27\",\"0\",\"5\"],[\"64509.8\",\"85.35\",\"0\",\"2\"],[\"64509.9\",\"1.21\",\"0\",\"3\"],[\"64516\",\"520.12\",\"0\",\"7\"],[\"64516.1\",\"0.04\",\"0\",\"4\"],[\"64522\",\"5.18\",\"0\",\"10\"],[\"64522.2\",\"0.16\",\"0\",\"9\"],[\"64526.9\",\"0\",\"0\",\"0\"],[\"64527\",\"0\",\"0\",\"0\"]],\"bids\":[[\"64482.9\",\"539.41\",\"0\",\"41\"],[\"64477.5\",\"0.46\",\"0\",\"2\"],[\"64477.4\",\"32.59\",\"0\",\"4\"],[\"64477.3\",\"77.54\",\"0\",\"1\"],[\"64475.1\",\"138.61\",\"0\",\"5\"],[\"64474.7\",\"0.01\",\"0\",\"1\"],[\"64474.1\",\"496.54\",\"0\",\"2\"],[\"64474\",\"0.03\",\"0\",\"2\"],[\"64466.7\",\"0.02\",\"0\",\"1\"],[\"64466.3\",\"33.81\",\"0\",\"1\"],[\"64466.2\",\"0.01\",\"0\",\"1\"],[\"64465.7\",\"0\",\"0\",\"0\"],[\"64465.6\",\"48.29\",\"0\",\"5\"],[\"64464.6\",\"85.4\",\"0\",\"1\"],[\"64464.5\",\"31.07\",\"0\",\"3\"],[\"64464.3\",\"0\",\"0\",\"0\"],[\"64464.2\",\"161.81\",\"0\",\"7\"],[\"64464.1\",\"0\",\"0\",\"0\"],[\"64463.2\",\"0.02\",\"0\",\"1\"],[\"64463\",\"0.02\",\"0\",\"2\"],[\"64462.9\",\"0\",\"0\",\"0\"],[\"64462.2\",\"58.22\",\"0\",\"1\"],[\"64423\",\"0\",\"0\",\"0\"],[\"64422.8\",\"0\",\"0\",\"0\"]],\"ts\":\"1782016048105\",\"checksum\":-1742632671,\"seqId\":325070094334,\"prevSeqId\":325070094060}]}"}
{"action": "update", "capture_sequence": 387, "channel": "books", "connection_sequence": 3, "event": null, "instId": "BTC-USDT-SWAP", "local_receive_ts": "2026-06-21T04:27:28Z", "monotonic_ns": 1643604115965657, "raw": "{\"arg\":{\"channel\":\"books\",\"instId\":\"BTC-USDT-SWAP\"},\"action\":\"update\",\"data\":[{\"asks\":[[\"64499.3\",\"0\",\"0\",\"0\"],[\"64499.9\",\"1134.18\",\"0\",\"4\"],[\"64501.6\",\"1.89\",\"0\",\"3\"],[\"64502.4\",\"31.22\",\"0\",\"7\"],[\"64502.5\",\"0.2\",\"0\",\"3\"],[\"64502.6\",\"15.66\",\"0\",\"2\"],[\"64503\",\"248.73\",\"0\",\"5\"],[\"64504.7\",\"33.8\",\"0\",\"2\"],[\"64505.3\",\"1.16\",\"0\",\"2\"],[\"64506\",\"10.84\",\"0\",\"6\"],[\"64506.4\",\"0.03\",\"0\",\"3\"],[\"64509.5\",\"85.34\",\"0\",\"1\"],[\"64509.8\",\"0.01\",\"0\",\"1\"],[\"64510\",\"271.08\",\"0\",\"30\"],[\"64511\",\"25.02\",\"0\",\"8\"],[\"64515.8\",\"37.06\",\"0\",\"4\"],[\"64516\",\"500.05\",\"0\",\"6\"]],\"bids\":[[\"64478.4\",\"9.56\",\"0\",\"2\"],[\"64477.9\",\"1.56\",\"0\",\"1\"],[\"64477.5\",\"78\",\"0\",\"3\"],[\"64477.4\",\"1.57\",\"0\",\"2\"],[\"64477.3\",\"0\",\"0\",\"0\"],[\"64476.9\",\"17.99\",\"0\",\"5\"],[\"64476.8\",\"32.58\",\"0\",\"3\"],[\"64476.1\",\"264.05\",\"0\",\"3\"],[\"64475.7\",\"1.56\",\"0\",\"1\"],[\"64475.2\",\"1.56\",\"0\",\"1\"],[\"64474.7\",\"1.57\",\"0\",\"2\"],[\"64474.2\",\"48.1\",\"0\",\"2\"],[\"64474.1\",\"496.56\",\"0\",\"3\"],[\"64474\",\"0.01\",\"0\",\"1\"],[\"64472.3\",\"0.01\",\"0\",\"1\"],[\"64472\",\"0.33\",\"0\",\"3\"],[\"64467.5\",\"0.03\",\"0\",\"2\"],[\"64467.2\",\"70.67\",\"0\",\"2\"],[\"64466.9\",\"0.04\",\"0\",\"2\"],[\"64466.7\",\"0\",\"0\",\"0\"],[\"64466.3\",\"0\",\"0\",\"0\"],[\"64465.7\",\"33.81\",\"0\",\"1\"],[\"64465.6\",\"28.21\",\"0\",\"4\"],[\"64465.4\",\"527.95\",\"0\",\"4\"],[\"64464.9\",\"31.05\",\"0\",\"1\"],[\"64464.6\",\"0\",\"0\",\"0\"],[\"64464.5\",\"0.02\",\"0\",\"2\"],[\"64464\",\"232.97\",\"0\",\"5\"],[\"64463.9\",\"85.4\",\"0\",\"1\"],[\"64463.4\",\"0\",\"0\",\"0\"],[\"64423.2\",\"0\",\"0\",\"0\"],[\"64423.1\",\"0\",\"0\",\"0\"]],\"ts\":\"1782016048205\",\"checksum\":-817911276,\"seqId\":325070094517,\"prevSeqId\":325070094334}]}"}
{"action": null, "capture_sequence": 388, "channel": "trades", "connection_sequence": 3, "event": null, "instId": "BTC-USDT-SWAP", "local_receive_ts": "2026-06-21T04:27:28Z", "monotonic_ns": 1643604119418022, "raw": "{\"arg\":{\"channel\":\"trades\",\"instId\":\"BTC-USDT-SWAP\"},\"data\":[{\"instId\":\"BTC-USDT-SWAP\",\"tradeId\":\"2718750333\",\"px\":\"64483\",\"sz\":\"0.1\",\"side\":\"buy\",\"ts\":\"1782016048214\",\"count\":\"1\",\"source\":\"0\",\"seqId\":325070094538}]}"}
{"action": "update", "capture_sequence": 389, "channel": "books", "connection_sequence": 3, "event": null, "instId": "BTC-USDT-SWAP", "local_receive_ts": "2026-06-21T04:27:28Z", "monotonic_ns": 1643604210800763, "raw": "{\"arg\":{\"channel\":\"books\",\"instId\":\"BTC-USDT-SWAP\"},\"action\":\"update\",\"data\":[{\"asks\":[[\"64483\",\"521.22\",\"0\",\"47\"],[\"64501.9\",\"31.11\",\"0\",\"2\"],[\"64502.4\",\"0.19\",\"0\",\"6\"],[\"64504.7\",\"0.01\",\"0\",\"1\"],[\"64505.3\",\"34.95\",\"0\",\"3\"],[\"64509.8\",\"58.19\",\"0\",\"2\"],[\"64510.9\",\"0.07\",\"0\",\"4\"]],\"bids\":[[\"64478.4\",\"8\",\"0\",\"1\"],[\"64473.7\",\"1.56\",\"0\",\"1\"],[\"64466.2\",\"33.82\",\"0\",\"2\"],[\"64465.7\",\"0\",\"0\",\"0\"],[\"64464.9\",\"0\",\"0\",\"0\"],[\"64464.8\",\"31.06\",\"0\",\"2\"],[\"64462.2\",\"0\",\"0\",\"0\"],[\"64461.5\",\"58.25\",\"0\",\"3\"],[\"64423.2\",\"38.43\",\"0\",\"2\"],[\"64423.1\",\"92.81\",\"0\",\"2\"]],\"ts\":\"1782016048305\",\"checksum\":-1742632671,\"seqId\":325070094674,\"prevSeqId\":325070094517}]}"}
{"action": null, "capture_sequence": 390, "channel": "trades", "connection_sequence": 3, "event": null, "instId": "BTC-USDT-SWAP", "local_receive_ts": "2026-06-21T04:27:28Z", "monotonic_ns": 1643604212678189, "raw": "{\"arg\":{\"channel\":\"trades\",\"instId\":\"BTC-USDT-SWAP\"},\"data\":[{\"instId\":\"BTC-USDT-SWAP\",\"tradeId\":\"2718750334\",\"px\":\"64482.9\",\"sz\":\"0.06\",\"side\":\"sell\",\"ts\":\"1782016048307\",\"count\":\"1\",\"source\":\"0\",\"seqId\":325070094680}]}"}
{"action": null, "capture_sequence": 391, "channel": "trades", "connection_sequence": 3, "event": null, "instId": "BTC-USDT-SWAP", "local_receive_ts": "2026-06-21T04:27:28Z", "monotonic_ns": 1643604232637911, "raw": "{\"arg\":{\"channel\":\"trades\",\"instId\":\"BTC-USDT-SWAP\"},\"data\":[{\"instId\":\"BTC-USDT-SWAP\",\"tradeId\":\"2718750336\",\"px\":\"64482.9\",\"sz\":\"0.46\",\"side\":\"sell\",\"ts\":\"1782016048327\",\"count\":\"2\",\"source\":\"0\",\"seqId\":325070094717}]}"}
{"action": "update", "capture_sequence": 392, "channel": "books", "connection_sequence": 3, "event": null, "instId": "BTC-USDT-SWAP", "local_receive_ts": "2026-06-21T04:27:28Z", "monotonic_ns": 1643604310680588, "raw": "{\"arg\":{\"channel\":\"books\",\"instId\":\"BTC-USDT-SWAP\"},\"action\":\"update\",\"data\":[{\"asks\":[[\"64483\",\"511.22\",\"0\",\"46\"],[\"64499.5\",\"62.05\",\"0\",\"2\"],[\"64499.9\",\"1118.67\",\"0\",\"3\"],[\"64502.7\",\"232.8\",\"0\",\"4\"],[\"64503\",\"15.96\",\"0\",\"4\"],[\"64509.5\",\"0\",\"0\",\"0\"],[\"64509.8\",\"0.01\",\"0\",\"1\"],[\"64509.9\",\"86.55\",\"0\",\"4\"],[\"64510.4\",\"58.21\",\"0\",\"4\"],[\"64526.9\",\"40.21\",\"0\",\"5\"]],\"bids\":[[\"64482.9\",\"538.89\",\"0\",\"40\"],[\"64478.6\",\"48.1\",\"0\",\"2\"],[\"64477.9\",\"0\",\"0\",\"0\"],[\"64477.4\",\"0.01\",\"0\",\"1\"],[\"64477.2\",\"7.78\",\"0\",\"2\"],[\"64476.9\",\"16.43\",\"0\",\"4\"],[\"64473.3\",\"1.57\",\"0\",\"2\"],[\"64464.5\",\"85.42\",\"0\",\"3\"],[\"64464\",\"0.06\",\"0\",\"4\"],[\"64463.9\",\"0\",\"0\",\"0\"],[\"64463.4\",\"232.91\",\"0\",\"1\"],[\"64462.2\",\"58.22\",\"0\",\"1\"],[\"64461.5\",\"0.02\",\"0\",\"2\"]],\"ts\":\"1782016048405\",\"checksum\":-1897052255,\"seqId\":325070094784,\"prevSeqId\":325070094674}]}"}
{"action": "update", "capture_sequence": 393, "channel": "books", "connection_sequence": 3, "event": null, "instId": "BTC-USDT-SWAP", "local_receive_ts": "2026-06-21T04:27:28Z", "monotonic_ns": 1643604411261603, "raw": "{\"arg\":{\"channel\":\"books\",\"instId\":\"BTC-USDT-SWAP\"},\"action\":\"update\",\"data\":[{\"asks\":[[\"64483.1\",\"0.63\",\"0\",\"4\"],[\"64486.2\",\"13.52\",\"0\",\"6\"],[\"64489.3\",\"3.24\",\"0\",\"3\"],[\"64498.9\",\"18.93\",\"0\",\"3\"],[\"64499.5\",\"46.54\",\"0\",\"1\"],[\"64500.8\",\"233.14\",\"0\",\"2\"],[\"64501.5\",\"32.6\",\"0\",\"5\"],[\"64501.9\",\"0.08\",\"0\",\"1\"],[\"64502.7\",\"0.03\",\"0\",\"3\"],[\"64505.3\",\"1.16\",\"0\",\"2\"],[\"64505.9\",\"33.8\",\"0\",\"2\"],[\"64506\",\"10.07\",\"0\",\"5\"],[\"64506.4\",\"0.8\",\"0\",\"4\"],[\"64509.8\",\"58.19\",\"0\",\"2\"],[\"64509.9\",\"1.21\",\"0\",\"3\"],[\"64510.4\",\"0.03\",\"0\",\"3\"],[\"64510.9\",\"85.4\",\"0\",\"5\"]],\"bids\":[[\"64478.6\",\"46.54\",\"0\",\"1\"],[\"64477.2\",\"6.22\",\"0\",\"1\"],[\"64476.1\",\"262.49\",\"0\",\"2\"],[\"64475.7\",\"0\",\"0\",\"0\"],[\"64475.2\",\"0\",\"0\",\"0\"],[\"64474.7\",\"0.01\",\"0\",\"1\"],[\"64474.2\",\"46.54\",\"0\",\"1\"],[\"64468.8\",\"97.5\",\"0\",\"2\"],[\"64467.5\",\"0.8\",\"0\",\"3\"],[\"64467.4\",\"46.54\",\"0\",\"1\"],[\"64467.2\",\"69.9\",\"0\",\"1\"],[\"64467.1\",\"65.03\",\"0\",\"3\"],[\"64466.2\",\"0.01\",\"0\",\"1\"],[\"64465.5\",\"85.39\",\"0\",\"1\"],[\"64464.8\",\"0.01\",\"0\",\"1\"],[\"64464.5\",\"31.07\",\"0\",\"3\"],[\"64463.4\",\"0\",\"0\",\"0\"],[\"64462.2\",\"0\",\"0\",\"0\"],[\"64461.6\",\"232.92\",\"0\",\"1\"],[\"64461.5\",\"58.25\",\"0\",\"3\"],[\"64423\",\"1.59\",\"0\",\"6\"],[\"64422.8\",\"1.51\",\"0\",\"2\"]],\"ts\":\"1782016048505\",\"checksum\":1211385570,\"seqId\":325070094924,\"prevSeqId\":325070094784}]}"}
{"action": "update", "capture_sequence": 394, "channel": "books", "connection_sequence": 3, "event": null, "instId": "BTC-USDT-SWAP", "local_receive_ts": "2026-06-21T04:27:28Z", "monotonic_ns": 1643604510716194, "raw": "{\"arg\":{\"channel\":\"books\",\"instId\":\"BTC-USDT-SWAP\"},\"action\":\"update\",\"data\":[{\"asks\":[[\"64483\",\"474.13\",\"0\",\"45\"],[\"64490.1\",\"0.3\",\"0\",\"2\"],[\"64490.9\",\"0.08\",\"0\",\"3\"],[\"64498.9\",\"3.42\",\"0\",\"2\"],[\"64499.8\",\"16.59\",\"0\",\"3\"],[\"64500.8\",\"0.36\",\"0\",\"1\"],[\"64501.5\",\"1.57\",\"0\",\"4\"],[\"64502.1\",\"31.04\",\"0\",\"2\"],[\"64502.5\",\"232.97\",\"0\",\"4\"],[\"64502.6\",\"15.67\",\"0\",\"3\"],[\"64503\",\"15.95\",\"0\",\"3\"],[\"64504.9\",\"0.1\",\"0\",\"3\"],[\"64505.1\",\"0.33\",\"0\",\"3\"],[\"64509.8\",\"0.01\",\"0\",\"1\"],[\"64510.4\",\"58.21\",\"0\",\"4\"],[\"64510.6\",\"85.53\",\"0\",\"3\"],[\"64510.9\",\"0.07\",\"0\",\"4\"],[\"64515.8\",\"16.99\",\"0\",\"3\"],[\"64516.5\",\"217.97\",\"0\",\"4\"],[\"64522.2\",\"0.15\",\"0\",\"8\"],[\"64522.8\",\"15.72\",\"0\",\"5\"]],\"bids\":[[\"64474.1\",\"496.54\",\"0\",\"2\"],[\"64474\",\"0.03\",\"0\",\"2\"],[\"64472.6\",\"2.33\",\"0\",\"3\"],[\"64472\",\"0.02\",\"0\",\"2\"],[\"64465.7\",\"20.08\",\"0\",\"1\"],[\"64465.5\",\"0\",\"0\",\"0\"],[\"64465.4\",\"507.87\",\"0\",\"3\"],[\"64464.9\",\"85.39\",\"0\",\"1\"],[\"64464.8\",\"31.06\",\"0\",\"2\"],[\"64464.5\",\"0.02\",\"0\",\"2\"],[\"64464.2\",\"161.79\",\"0\",\"6\"],[\"64464.1\",\"0.02\",\"0\",\"1\"],[\"64463.5\",\"232.92\",\"0\",\"2\"],[\"64462.2\",\"58.22\",\"0\",\"1\"],[\"64461.6\",\"0\",\"0\",\"0\"],[\"64461.5\",\"0.02\",\"0\",\"2\"],[\"64423\",\"0\",\"0\",\"0\"],[\"64422.8\",\"0\",\"0\",\"0\"]],\"ts\":\"1782016048605\",\"checksum\":-1883578742,\"seqId\":325070095035,\"prevSeqId\":325070094924}]}"}
{"action": "update", "capture_sequence": 395, "channel": "books", "connection_sequence": 3, "event": null, "instId": "BTC-USDT-SWAP", "local_receive_ts": "2026-06-21T04:27:28Z", "monotonic_ns": 1643604610569439, "raw": "{\"arg\":{\"channel\":\"books\",\"instId\":\"BTC-USDT-SWAP\"},\"action\":\"update\",\"data\":[{\"asks\":[[\"64483\",\"484.11\",\"0\",\"45\"],[\"64483.1\",\"0.64\",\"0\",\"5\"],[\"64486.2\",\"13.53\",\"0\",\"7\"],[\"64489.3\",\"3.25\",\"0\",\"4\"]],\"bids\":[],\"ts\":\"1782016048705\",\"checksum\":280316529,\"seqId\":325070095103,\"prevSeqId\":325070095035}]}"}
{"action": "update", "capture_sequence": 396, "channel": "books", "connection_sequence": 3, "event": null, "instId": "BTC-USDT-SWAP", "local_receive_ts": "2026-06-21T04:27:28Z", "monotonic_ns": 1643604710456512, "raw": "{\"arg\":{\"channel\":\"books\",\"instId\":\"BTC-USDT-SWAP\"},\"action\":\"update\",\"data\":[{\"asks\":[[\"64483\",\"474.33\",\"0\",\"45\"]],\"bids\":[[\"64446.9\",\"118.84\",\"0\",\"1\"],[\"64423.1\",\"0\",\"0\",\"0\"]],\"ts\":\"1782016048805\",\"checksum\":-2080702350,\"seqId\":325070095178,\"prevSeqId\":325070095103}]}"}
{"action": "update", "capture_sequence": 397, "channel": "books", "connection_sequence": 3, "event": null, "instId": "BTC-USDT-SWAP", "local_receive_ts": "2026-06-21T04:27:29Z", "monotonic_ns": 1643604810467637, "raw": "{\"arg\":{\"channel\":\"books\",\"instId\":\"BTC-USDT-SWAP\"},\"action\":\"update\",\"data\":[{\"asks\":[[\"64483\",\"474.35\",\"0\",\"46\"],[\"64505.6\",\"91.7\",\"0\",\"5\"],[\"64505.9\",\"0.01\",\"0\",\"1\"]],\"bids\":[[\"64467.1\",\"31.22\",\"0\",\"2\"],[\"64466.2\",\"33.82\",\"0\",\"2\"],[\"64454.5\",\"0.01\",\"0\",\"1\"],[\"64438.1\",\"42.72\",\"0\",\"5\"]],\"ts\":\"1782016048905\",\"checksum\":72303608,\"seqId\":325070095258,\"prevSeqId\":325070095178}]}"}
{"action": null, "capture_sequence": 398, "channel": "trades", "connection_sequence": 3, "event": null, "instId": "BTC-USDT-SWAP", "local_receive_ts": "2026-06-21T04:27:29Z", "monotonic_ns": 1643604902441487, "raw": "{\"arg\":{\"channel\":\"trades\",\"instId\":\"BTC-USDT-SWAP\"},\"data\":[{\"instId\":\"BTC-USDT-SWAP\",\"tradeId\":\"2718750349\",\"px\":\"64482.9\",\"sz\":\"53.67\",\"side\":\"sell\",\"ts\":\"1782016048997\",\"count\":\"13\",\"source\":\"0\",\"seqId\":325070095357}]}"}
{"action": "update", "capture_sequence": 399, "channel": "books", "connection_sequence": 3, "event": null, "instId": "BTC-USDT-SWAP", "local_receive_ts": "2026-06-21T04:27:29Z", "monotonic_ns": 1643604910632161, "raw": "{\"arg\":{\"channel\":\"books\",\"instId\":\"BTC-USDT-SWAP\"},\"action\":\"update\",\"data\":[{\"asks\":[[\"64483\",\"492.96\",\"0\",\"48\"],[\"64485.4\",\"0\",\"0\",\"0\"],[\"64488.2\",\"4.73\",\"0\",\"3\"],[\"64504.1\",\"21.33\",\"0\",\"7\"],[\"64504.2\",\"512.65\",\"0\",\"7\"],[\"64526.8\",\"0.37\",\"0\",\"2\"],[\"64527\",\"0.17\",\"0\",\"3\"]],\"bids\":[[\"64482.9\",\"485.24\",\"0\",\"30\"],[\"64479.6\",\"0.02\",\"0\",\"2\"],[\"64477.5\",\"0.46\",\"0\",\"2\"],[\"64477.3\",\"77.54\",\"0\",\"1\"],[\"64468.8\",\"11.33\",\"0\",\"1\"],[\"64467.4\",\"132.71\",\"0\",\"2\"],[\"64435.1\",\"3.01\",\"0\",\"2\"],[\"64423.2\",\"0\",\"0\",\"0\"]],\"ts\":\"1782016049005\",\"checksum\":-416544074,\"seqId\":325070095376,\"prevSeqId\":325070095258}]}"}
{"action": null, "capture_sequence": 400, "channel": "trades", "connection_sequence": 3, "event": null, "instId": "BTC-USDT-SWAP", "local_receive_ts": "2026-06-21T04:27:29Z", "monotonic_ns": 1643604973950118, "raw": "{\"arg\":{\"channel\":\"trades\",\"instId\":\"BTC-USDT-SWAP\"},\"data\":[{\"instId\":\"BTC-USDT-SWAP\",\"tradeId\":\"2718750350\",\"px\":\"64482.9\",\"sz\":\"0.1\",\"side\":\"sell\",\"ts\":\"1782016049068\",\"count\":\"1\",\"source\":\"0\",\"seqId\":325070095467}]}"}
{"action": "update", "capture_sequence": 401, "channel": "books", "connection_sequence": 3, "event": null, "instId": "BTC-USDT-SWAP", "local_receive_ts": "2026-06-21T04:27:29Z", "monotonic_ns": 1643605010885289, "raw": "{\"arg\":{\"channel\":\"books\",\"instId\":\"BTC-USDT-SWAP\"},\"action\":\"update\",\"data\":[{\"asks\":[[\"64483\",\"492.8\",\"0\",\"47\"],[\"64483.1\",\"0.65\",\"0\",\"6\"],[\"64499.3\",\"15.51\",\"0\",\"1\"],[\"64499.8\",\"1.08\",\"0\",\"2\"],[\"64502.6\",\"15.66\",\"0\",\"2\"],[\"64502.7\",\"0.04\",\"0\",\"4\"],[\"64527\",\"0\",\"0\",\"0\"]],\"bids\":[[\"64482.9\",\"482.7\",\"0\",\"30\"],[\"64482.3\",\"0.03\",\"0\",\"2\"],[\"64480.7\",\"3.44\",\"0\",\"2\"],[\"64480.1\",\"3.44\",\"0\",\"2\"],[\"64479.9\",\"0.13\",\"0\",\"2\"],[\"64479.8\",\"0.01\",\"0\",\"1\"],[\"64477.9\",\"77.54\",\"0\",\"1\"],[\"64477.7\",\"1.58\",\"0\",\"3\"],[\"64477.3\",\"0\",\"0\",\"0\"],[\"64477\",\"1.57\",\"0\",\"2\"],[\"64476.6\",\"1.57\",\"0\",\"2\"],[\"64475.7\",\"1.56\",\"0\",\"1\"],[\"64475.2\",\"1.56\",\"0\",\"1\"],[\"64474.7\",\"1.57\",\"0\",\"2\"],[\"64474.2\",\"48.1\",\"0\",\"2\"],[\"64472.6\",\"2.02\",\"0\",\"2\"],[\"64472.3\",\"0.32\",\"0\",\"2\"],[\"64466.9\",\"0\",\"0\",\"0\"],[\"64465.6\",\"28.25\",\"0\",\"6\"],[\"64463.2\",\"0\",\"0\",\"0\"],[\"64462.1\",\"14.45\",\"0\",\"3\"],[\"64459.5\",\"15.65\",\"0\",\"1\"]],\"ts\":\"1782016049105\",\"checksum\":-1283021716,\"seqId\":325070095473,\"prevSeqId\":325070095376}]}"}
{"action": "update", "capture_sequence": 402, "channel": "books", "connection_sequence": 3, "event": null, "instId": "BTC-USDT-SWAP", "local_receive_ts": "2026-06-21T04:27:29Z", "monotonic_ns": 1643605110889838, "raw": "{\"arg\":{\"channel\":\"books\",\"instId\":\"BTC-USDT-SWAP\"},\"action\":\"update\",\"data\":[{\"asks\":[[\"64484\",\"7.09\",\"0\",\"6\"],[\"64484.1\",\"76.25\",\"0\",\"1\"],[\"64484.2\",\"0\",\"0\",\"0\"],[\"64484.3\",\"0\",\"0\",\"0\"],[\"64489.7\",\"38.04\",\"0\",\"3\"],[\"64490.9\",\"0.07\",\"0\",\"2\"],[\"64493.4\",\"21.5\",\"0\",\"9\"],[\"64493.8\",\"1.01\",\"0\",\"3\"],[\"64502.6\",\"15.67\",\"0\",\"3\"],[\"64502.7\",\"0.03\",\"0\",\"3\"],[\"64521.1\",\"0.02\",\"0\",\"2\"],[\"64522.8\",\"15.71\",\"0\",\"4\"],[\"64527\",\"0.17\",\"0\",\"3\"]],\"bids\":[[\"64482.9\",\"471.19\",\"0\",\"29\"],[\"64482.4\",\"0\",\"0\",\"0\"],[\"64482.1\",\"0.05\",\"0\",\"3\"],[\"64481.9\",\"0.77\",\"0\",\"1\"],[\"64480.8\",\"0.02\",\"0\",\"2\"],[\"64480.2\",\"0.01\",\"0\",\"1\"],[\"64480\",\"48.58\",\"0\",\"5\"],[\"64478.7\",\"0\",\"0\",\"0\"],[\"64478.6\",\"0\",\"0\",\"0\"],[\"64478\",\"0.02\",\"0\",\"2\"],[\"64477.9\",\"0\",\"0\",\"0\"],[\"64477.8\",\"120.22\",\"0\",\"1\"],[\"64477.7\",\"77.56\",\"0\",\"3\"],[\"64477.6\",\"1.57\",\"0\",\"2\"],[\"64465.6\",\"28.23\",\"0\",\"5\"],[\"64465.3\",\"46.58\",\"0\",\"4\"],[\"64423.2\",\"38.43\",\"0\",\"2\"]],\"ts\":\"1782016049205\",\"checksum\":-656132665,\"seqId\":325070095535,\"prevSeqId\":325070095473}]}"}
{"action": "update", "capture_sequence": 403, "channel": "books", "connection_sequence": 3, "event": null, "instId": "BTC-USDT-SWAP", "local_receive_ts": "2026-06-21T04:27:29Z", "monotonic_ns": 1643605211113258, "raw": "{\"arg\":{\"channel\":\"books\",\"instId\":\"BTC-USDT-SWAP\"},\"action\":\"update\",\"data\":[{\"asks\":[[\"64483\",\"495.07\",\"0\",\"48\"],[\"64489.7\",\"38.03\",\"0\",\"2\"],[\"64490.1\",\"0.31\",\"0\",\"3\"],[\"64497.4\",\"0.08\",\"0\",\"1\"],[\"64504.2\",\"511.1\",\"0\",\"6\"],[\"64504.3\",\"1.59\",\"0\",\"3\"],[\"64521.1\",\"0.01\",\"0\",\"1\"],[\"64522.8\",\"15.72\",\"0\",\"5\"]],\"bids\":[[\"64482.9\",\"482.66\",\"0\",\"30\"],[\"64479.6\",\"1.58\",\"0\",\"3\"],[\"64477.8\",\"77.54\",\"0\",\"1\"],[\"64477.7\",\"0.02\",\"0\",\"2\"],[\"64477.6\",\"0.01\",\"0\",\"1\"],[\"64468.8\",\"97.5\",\"0\",\"2\"],[\"64467.4\",\"46.54\",\"0\",\"1\"],[\"64465.6\",\"28.21\",\"0\",\"4\"],[\"64465.5\",\"0.02\",\"0\",\"1\"],[\"64464.4\",\"0.01\",\"0\",\"1\"],[\"64423.2\",\"0\",\"0\",\"0\"]],\"ts\":\"1782016049305\",\"checksum\":1544875031,\"seqId\":325070095635,\"prevSeqId\":325070095535}]}"}
{"action": null, "capture_sequence": 404, "channel": "trades", "connection_sequence": 3, "event": null, "instId": "BTC-USDT-SWAP", "local_receive_ts": "2026-06-21T04:27:29Z", "monotonic_ns": 1643605295089803, "raw": "{\"arg\":{\"channel\":\"trades\",\"instId\":\"BTC-USDT-SWAP\"},\"data\":[{\"instId\":\"BTC-USDT-SWAP\",\"tradeId\":\"2718750351\",\"px\":\"64482.9\",\"sz\":\"0.06\",\"side\":\"sell\",\"ts\":\"1782016049390\",\"count\":\"1\",\"source\":\"0\",\"seqId\":325070095702}]}"}
